WARNING django.request Not Found: /favicon.ico 2021-08-20 14:29:01,539
WARNING django.server "GET /favicon.ico HTTP/1.1" 404 3524 2021-08-20 14:29:01,539
ERROR django.request Internal Server Error: /migrant/word/1/ 2021-08-20 14:31:11,194
Traceback (most recent call last):
  File "C:\Users\user\OneDrive\Desktop\Projects\databases_v1\venv\lib\site-packages\django\core\handlers\exception.py", line 47, in inner
    response = get_response(request)
  File "C:\Users\user\OneDrive\Desktop\Projects\databases_v1\venv\lib\site-packages\django\core\handlers\base.py", line 181, in _get_response
    response = wrapped_callback(request, *callback_args, **callback_kwargs)
  File "C:\Users\user\OneDrive\Desktop\Projects\databases_v1\databases_v1\migrant\views.py", line 640, in generate_case_word
    tpl.render(context, jinja_env=jinja_env)
  File "C:\Users\user\OneDrive\Desktop\Projects\databases_v1\venv\lib\site-packages\docxtpl\__init__.py", line 316, in render
    xml_src = self.build_xml(context, jinja_env)
  File "C:\Users\user\OneDrive\Desktop\Projects\databases_v1\venv\lib\site-packages\docxtpl\__init__.py", line 271, in build_xml
    xml = self.render_xml_part(xml, self.docx._part, context, jinja_env)
  File "C:\Users\user\OneDrive\Desktop\Projects\databases_v1\venv\lib\site-packages\docxtpl\__init__.py", line 226, in render_xml_part
    raise exc
  File "C:\Users\user\OneDrive\Desktop\Projects\databases_v1\venv\lib\site-packages\docxtpl\__init__.py", line 217, in render_xml_part
    template = jinja_env.from_string(src_xml)
  File "C:\Users\user\OneDrive\Desktop\Projects\databases_v1\venv\lib\site-packages\jinja2\environment.py", line 1092, in from_string
    return cls.from_code(self, self.compile(source), gs, None)
  File "C:\Users\user\OneDrive\Desktop\Projects\databases_v1\venv\lib\site-packages\jinja2\environment.py", line 757, in compile
    self.handle_exception(source=source_hint)
  File "C:\Users\user\OneDrive\Desktop\Projects\databases_v1\venv\lib\site-packages\jinja2\environment.py", line 925, in handle_exception
    raise rewrite_traceback_stack(source=source)
  File "<unknown>", line 1, in template
jinja2.exceptions.TemplateSyntaxError: Expected an expression, got 'end of statement block'
ERROR django.server "GET /migrant/word/1/ HTTP/1.1" 500 149275 2021-08-20 14:31:11,197
ERROR django.request Internal Server Error: /migrant/get-pdf/1 2021-08-20 14:32:34,732
Traceback (most recent call last):
  File "C:\Users\user\OneDrive\Desktop\Projects\databases_v1\venv\lib\site-packages\reportlab\lib\utils.py", line 701, in open_for_read
    return open_for_read_by_name(name,mode)
  File "C:\Users\user\OneDrive\Desktop\Projects\databases_v1\venv\lib\site-packages\reportlab\lib\utils.py", line 636, in open_for_read_by_name
    return open(name,mode)
FileNotFoundError: [Errno 2] No such file or directory: 'Roboto-Black.ttf'

During handling of the above exception, another exception occurred:

Traceback (most recent call last):
  File "C:\Users\user\OneDrive\Desktop\Projects\databases_v1\venv\lib\site-packages\reportlab\lib\utils.py", line 708, in open_for_read
    return getBytesIO(datareader(name) if name[:5].lower()=='data:' else urlopen(name).read())
  File "C:\Users\user\AppData\Local\Programs\Python\Python39\lib\urllib\request.py", line 214, in urlopen
    return opener.open(url, data, timeout)
  File "C:\Users\user\AppData\Local\Programs\Python\Python39\lib\urllib\request.py", line 501, in open
    req = Request(fullurl, data)
  File "C:\Users\user\AppData\Local\Programs\Python\Python39\lib\urllib\request.py", line 320, in __init__
    self.full_url = url
  File "C:\Users\user\AppData\Local\Programs\Python\Python39\lib\urllib\request.py", line 346, in full_url
    self._parse()
  File "C:\Users\user\AppData\Local\Programs\Python\Python39\lib\urllib\request.py", line 375, in _parse
    raise ValueError("unknown url type: %r" % self.full_url)
ValueError: unknown url type: 'Roboto-Black.ttf'

During handling of the above exception, another exception occurred:

Traceback (most recent call last):
  File "C:\Users\user\OneDrive\Desktop\Projects\databases_v1\venv\lib\site-packages\reportlab\pdfbase\ttfonts.py", line 155, in TTFOpenFile
    f = open_for_read(fn,'rb')
  File "C:\Users\user\OneDrive\Desktop\Projects\databases_v1\venv\lib\site-packages\reportlab\lib\utils.py", line 712, in open_for_read
    return open_for_read(name,mode)
  File "C:\Users\user\OneDrive\Desktop\Projects\databases_v1\venv\lib\site-packages\reportlab\lib\utils.py", line 710, in open_for_read
    raise IOError('Cannot open resource "%s"' % name)
OSError: Cannot open resource "Roboto-Black.ttf"

During handling of the above exception, another exception occurred:

Traceback (most recent call last):
  File "C:\Users\user\OneDrive\Desktop\Projects\databases_v1\venv\lib\site-packages\django\core\handlers\exception.py", line 47, in inner
    response = get_response(request)
  File "C:\Users\user\OneDrive\Desktop\Projects\databases_v1\venv\lib\site-packages\django\core\handlers\base.py", line 181, in _get_response
    response = wrapped_callback(request, *callback_args, **callback_kwargs)
  File "C:\Users\user\OneDrive\Desktop\Projects\databases_v1\databases_v1\migrant\views.py", line 770, in pdf_table_generate
    pdfmetrics.registerFont(TTFont('Roboto', 'Roboto-Black.ttf'))
  File "C:\Users\user\OneDrive\Desktop\Projects\databases_v1\venv\lib\site-packages\reportlab\pdfbase\ttfonts.py", line 1196, in __init__
    self.face = TTFontFace(filename, validate=validate, subfontIndex=subfontIndex)
  File "C:\Users\user\OneDrive\Desktop\Projects\databases_v1\venv\lib\site-packages\reportlab\pdfbase\ttfonts.py", line 1090, in __init__
    TTFontFile.__init__(self, filename, validate=validate, subfontIndex=subfontIndex)
  File "C:\Users\user\OneDrive\Desktop\Projects\databases_v1\venv\lib\site-packages\reportlab\pdfbase\ttfonts.py", line 457, in __init__
    TTFontParser.__init__(self, file, validate=validate,subfontIndex=subfontIndex)
  File "C:\Users\user\OneDrive\Desktop\Projects\databases_v1\venv\lib\site-packages\reportlab\pdfbase\ttfonts.py", line 179, in __init__
    self.readFile(file)
  File "C:\Users\user\OneDrive\Desktop\Projects\databases_v1\venv\lib\site-packages\reportlab\pdfbase\ttfonts.py", line 255, in readFile
    self.filename, f = TTFOpenFile(f)
  File "C:\Users\user\OneDrive\Desktop\Projects\databases_v1\venv\lib\site-packages\reportlab\pdfbase\ttfonts.py", line 165, in TTFOpenFile
    raise TTFError('Can\'t open file "%s"' % fn)
reportlab.pdfbase.ttfonts.TTFError: Can't open file "Roboto-Black.ttf"
ERROR django.server "GET /migrant/get-pdf/1 HTTP/1.1" 500 150593 2021-08-20 14:32:34,736
ERROR django.request Internal Server Error: /migrant/get-pdf/1 2021-08-20 14:32:55,791
Traceback (most recent call last):
  File "C:\Users\user\OneDrive\Desktop\Projects\databases_v1\venv\lib\site-packages\reportlab\lib\utils.py", line 701, in open_for_read
    return open_for_read_by_name(name,mode)
  File "C:\Users\user\OneDrive\Desktop\Projects\databases_v1\venv\lib\site-packages\reportlab\lib\utils.py", line 636, in open_for_read_by_name
    return open(name,mode)
FileNotFoundError: [Errno 2] No such file or directory: 'Roboto-Black.ttf'

During handling of the above exception, another exception occurred:

Traceback (most recent call last):
  File "C:\Users\user\OneDrive\Desktop\Projects\databases_v1\venv\lib\site-packages\reportlab\lib\utils.py", line 708, in open_for_read
    return getBytesIO(datareader(name) if name[:5].lower()=='data:' else urlopen(name).read())
  File "C:\Users\user\AppData\Local\Programs\Python\Python39\lib\urllib\request.py", line 214, in urlopen
    return opener.open(url, data, timeout)
  File "C:\Users\user\AppData\Local\Programs\Python\Python39\lib\urllib\request.py", line 501, in open
    req = Request(fullurl, data)
  File "C:\Users\user\AppData\Local\Programs\Python\Python39\lib\urllib\request.py", line 320, in __init__
    self.full_url = url
  File "C:\Users\user\AppData\Local\Programs\Python\Python39\lib\urllib\request.py", line 346, in full_url
    self._parse()
  File "C:\Users\user\AppData\Local\Programs\Python\Python39\lib\urllib\request.py", line 375, in _parse
    raise ValueError("unknown url type: %r" % self.full_url)
ValueError: unknown url type: 'Roboto-Black.ttf'

During handling of the above exception, another exception occurred:

Traceback (most recent call last):
  File "C:\Users\user\OneDrive\Desktop\Projects\databases_v1\venv\lib\site-packages\reportlab\pdfbase\ttfonts.py", line 155, in TTFOpenFile
    f = open_for_read(fn,'rb')
  File "C:\Users\user\OneDrive\Desktop\Projects\databases_v1\venv\lib\site-packages\reportlab\lib\utils.py", line 712, in open_for_read
    return open_for_read(name,mode)
  File "C:\Users\user\OneDrive\Desktop\Projects\databases_v1\venv\lib\site-packages\reportlab\lib\utils.py", line 710, in open_for_read
    raise IOError('Cannot open resource "%s"' % name)
OSError: Cannot open resource "Roboto-Black.ttf"

During handling of the above exception, another exception occurred:

Traceback (most recent call last):
  File "C:\Users\user\OneDrive\Desktop\Projects\databases_v1\venv\lib\site-packages\django\core\handlers\exception.py", line 47, in inner
    response = get_response(request)
  File "C:\Users\user\OneDrive\Desktop\Projects\databases_v1\venv\lib\site-packages\django\core\handlers\base.py", line 181, in _get_response
    response = wrapped_callback(request, *callback_args, **callback_kwargs)
  File "C:\Users\user\OneDrive\Desktop\Projects\databases_v1\databases_v1\migrant\views.py", line 770, in pdf_table_generate
    pdfmetrics.registerFont(TTFont('Roboto', 'Roboto-Black.ttf'))
  File "C:\Users\user\OneDrive\Desktop\Projects\databases_v1\venv\lib\site-packages\reportlab\pdfbase\ttfonts.py", line 1196, in __init__
    self.face = TTFontFace(filename, validate=validate, subfontIndex=subfontIndex)
  File "C:\Users\user\OneDrive\Desktop\Projects\databases_v1\venv\lib\site-packages\reportlab\pdfbase\ttfonts.py", line 1090, in __init__
    TTFontFile.__init__(self, filename, validate=validate, subfontIndex=subfontIndex)
  File "C:\Users\user\OneDrive\Desktop\Projects\databases_v1\venv\lib\site-packages\reportlab\pdfbase\ttfonts.py", line 457, in __init__
    TTFontParser.__init__(self, file, validate=validate,subfontIndex=subfontIndex)
  File "C:\Users\user\OneDrive\Desktop\Projects\databases_v1\venv\lib\site-packages\reportlab\pdfbase\ttfonts.py", line 179, in __init__
    self.readFile(file)
  File "C:\Users\user\OneDrive\Desktop\Projects\databases_v1\venv\lib\site-packages\reportlab\pdfbase\ttfonts.py", line 255, in readFile
    self.filename, f = TTFOpenFile(f)
  File "C:\Users\user\OneDrive\Desktop\Projects\databases_v1\venv\lib\site-packages\reportlab\pdfbase\ttfonts.py", line 165, in TTFOpenFile
    raise TTFError('Can\'t open file "%s"' % fn)
reportlab.pdfbase.ttfonts.TTFError: Can't open file "Roboto-Black.ttf"
ERROR django.server "GET /migrant/get-pdf/1 HTTP/1.1" 500 150730 2021-08-20 14:32:55,795
ERROR django.request Internal Server Error: /migrant/get-pdf/1 2021-08-20 14:32:56,039
Traceback (most recent call last):
  File "C:\Users\user\OneDrive\Desktop\Projects\databases_v1\venv\lib\site-packages\reportlab\lib\utils.py", line 701, in open_for_read
    return open_for_read_by_name(name,mode)
  File "C:\Users\user\OneDrive\Desktop\Projects\databases_v1\venv\lib\site-packages\reportlab\lib\utils.py", line 636, in open_for_read_by_name
    return open(name,mode)
FileNotFoundError: [Errno 2] No such file or directory: 'Roboto-Black.ttf'

During handling of the above exception, another exception occurred:

Traceback (most recent call last):
  File "C:\Users\user\OneDrive\Desktop\Projects\databases_v1\venv\lib\site-packages\reportlab\lib\utils.py", line 708, in open_for_read
    return getBytesIO(datareader(name) if name[:5].lower()=='data:' else urlopen(name).read())
  File "C:\Users\user\AppData\Local\Programs\Python\Python39\lib\urllib\request.py", line 214, in urlopen
    return opener.open(url, data, timeout)
  File "C:\Users\user\AppData\Local\Programs\Python\Python39\lib\urllib\request.py", line 501, in open
    req = Request(fullurl, data)
  File "C:\Users\user\AppData\Local\Programs\Python\Python39\lib\urllib\request.py", line 320, in __init__
    self.full_url = url
  File "C:\Users\user\AppData\Local\Programs\Python\Python39\lib\urllib\request.py", line 346, in full_url
    self._parse()
  File "C:\Users\user\AppData\Local\Programs\Python\Python39\lib\urllib\request.py", line 375, in _parse
    raise ValueError("unknown url type: %r" % self.full_url)
ValueError: unknown url type: 'Roboto-Black.ttf'

During handling of the above exception, another exception occurred:

Traceback (most recent call last):
  File "C:\Users\user\OneDrive\Desktop\Projects\databases_v1\venv\lib\site-packages\reportlab\pdfbase\ttfonts.py", line 155, in TTFOpenFile
    f = open_for_read(fn,'rb')
  File "C:\Users\user\OneDrive\Desktop\Projects\databases_v1\venv\lib\site-packages\reportlab\lib\utils.py", line 710, in open_for_read
    raise IOError('Cannot open resource "%s"' % name)
OSError: Cannot open resource "Roboto-Black.ttf"

During handling of the above exception, another exception occurred:

Traceback (most recent call last):
  File "C:\Users\user\OneDrive\Desktop\Projects\databases_v1\venv\lib\site-packages\django\core\handlers\exception.py", line 47, in inner
    response = get_response(request)
  File "C:\Users\user\OneDrive\Desktop\Projects\databases_v1\venv\lib\site-packages\django\core\handlers\base.py", line 181, in _get_response
    response = wrapped_callback(request, *callback_args, **callback_kwargs)
  File "C:\Users\user\OneDrive\Desktop\Projects\databases_v1\databases_v1\migrant\views.py", line 770, in pdf_table_generate
    pdfmetrics.registerFont(TTFont('Roboto', 'Roboto-Black.ttf'))
  File "C:\Users\user\OneDrive\Desktop\Projects\databases_v1\venv\lib\site-packages\reportlab\pdfbase\ttfonts.py", line 1196, in __init__
    self.face = TTFontFace(filename, validate=validate, subfontIndex=subfontIndex)
  File "C:\Users\user\OneDrive\Desktop\Projects\databases_v1\venv\lib\site-packages\reportlab\pdfbase\ttfonts.py", line 1090, in __init__
    TTFontFile.__init__(self, filename, validate=validate, subfontIndex=subfontIndex)
  File "C:\Users\user\OneDrive\Desktop\Projects\databases_v1\venv\lib\site-packages\reportlab\pdfbase\ttfonts.py", line 457, in __init__
    TTFontParser.__init__(self, file, validate=validate,subfontIndex=subfontIndex)
  File "C:\Users\user\OneDrive\Desktop\Projects\databases_v1\venv\lib\site-packages\reportlab\pdfbase\ttfonts.py", line 179, in __init__
    self.readFile(file)
  File "C:\Users\user\OneDrive\Desktop\Projects\databases_v1\venv\lib\site-packages\reportlab\pdfbase\ttfonts.py", line 255, in readFile
    self.filename, f = TTFOpenFile(f)
  File "C:\Users\user\OneDrive\Desktop\Projects\databases_v1\venv\lib\site-packages\reportlab\pdfbase\ttfonts.py", line 165, in TTFOpenFile
    raise TTFError('Can\'t open file "%s"' % fn)
reportlab.pdfbase.ttfonts.TTFError: Can't open file "Roboto-Black.ttf"
ERROR django.server "GET /migrant/get-pdf/1 HTTP/1.1" 500 145153 2021-08-20 14:32:56,042
ERROR django.request Internal Server Error: /migrant/get-pdf/1 2021-08-20 14:32:56,740
Traceback (most recent call last):
  File "C:\Users\user\OneDrive\Desktop\Projects\databases_v1\venv\lib\site-packages\reportlab\lib\utils.py", line 701, in open_for_read
    return open_for_read_by_name(name,mode)
  File "C:\Users\user\OneDrive\Desktop\Projects\databases_v1\venv\lib\site-packages\reportlab\lib\utils.py", line 636, in open_for_read_by_name
    return open(name,mode)
FileNotFoundError: [Errno 2] No such file or directory: 'Roboto-Black.ttf'

During handling of the above exception, another exception occurred:

Traceback (most recent call last):
  File "C:\Users\user\OneDrive\Desktop\Projects\databases_v1\venv\lib\site-packages\reportlab\lib\utils.py", line 708, in open_for_read
    return getBytesIO(datareader(name) if name[:5].lower()=='data:' else urlopen(name).read())
  File "C:\Users\user\AppData\Local\Programs\Python\Python39\lib\urllib\request.py", line 214, in urlopen
    return opener.open(url, data, timeout)
  File "C:\Users\user\AppData\Local\Programs\Python\Python39\lib\urllib\request.py", line 501, in open
    req = Request(fullurl, data)
  File "C:\Users\user\AppData\Local\Programs\Python\Python39\lib\urllib\request.py", line 320, in __init__
    self.full_url = url
  File "C:\Users\user\AppData\Local\Programs\Python\Python39\lib\urllib\request.py", line 346, in full_url
    self._parse()
  File "C:\Users\user\AppData\Local\Programs\Python\Python39\lib\urllib\request.py", line 375, in _parse
    raise ValueError("unknown url type: %r" % self.full_url)
ValueError: unknown url type: 'Roboto-Black.ttf'

During handling of the above exception, another exception occurred:

Traceback (most recent call last):
  File "C:\Users\user\OneDrive\Desktop\Projects\databases_v1\venv\lib\site-packages\reportlab\pdfbase\ttfonts.py", line 155, in TTFOpenFile
    f = open_for_read(fn,'rb')
  File "C:\Users\user\OneDrive\Desktop\Projects\databases_v1\venv\lib\site-packages\reportlab\lib\utils.py", line 710, in open_for_read
    raise IOError('Cannot open resource "%s"' % name)
OSError: Cannot open resource "Roboto-Black.ttf"

During handling of the above exception, another exception occurred:

Traceback (most recent call last):
  File "C:\Users\user\OneDrive\Desktop\Projects\databases_v1\venv\lib\site-packages\django\core\handlers\exception.py", line 47, in inner
    response = get_response(request)
  File "C:\Users\user\OneDrive\Desktop\Projects\databases_v1\venv\lib\site-packages\django\core\handlers\base.py", line 181, in _get_response
    response = wrapped_callback(request, *callback_args, **callback_kwargs)
  File "C:\Users\user\OneDrive\Desktop\Projects\databases_v1\databases_v1\migrant\views.py", line 770, in pdf_table_generate
    pdfmetrics.registerFont(TTFont('Roboto', 'Roboto-Black.ttf'))
  File "C:\Users\user\OneDrive\Desktop\Projects\databases_v1\venv\lib\site-packages\reportlab\pdfbase\ttfonts.py", line 1196, in __init__
    self.face = TTFontFace(filename, validate=validate, subfontIndex=subfontIndex)
  File "C:\Users\user\OneDrive\Desktop\Projects\databases_v1\venv\lib\site-packages\reportlab\pdfbase\ttfonts.py", line 1090, in __init__
    TTFontFile.__init__(self, filename, validate=validate, subfontIndex=subfontIndex)
  File "C:\Users\user\OneDrive\Desktop\Projects\databases_v1\venv\lib\site-packages\reportlab\pdfbase\ttfonts.py", line 457, in __init__
    TTFontParser.__init__(self, file, validate=validate,subfontIndex=subfontIndex)
  File "C:\Users\user\OneDrive\Desktop\Projects\databases_v1\venv\lib\site-packages\reportlab\pdfbase\ttfonts.py", line 179, in __init__
    self.readFile(file)
  File "C:\Users\user\OneDrive\Desktop\Projects\databases_v1\venv\lib\site-packages\reportlab\pdfbase\ttfonts.py", line 255, in readFile
    self.filename, f = TTFOpenFile(f)
  File "C:\Users\user\OneDrive\Desktop\Projects\databases_v1\venv\lib\site-packages\reportlab\pdfbase\ttfonts.py", line 165, in TTFOpenFile
    raise TTFError('Can\'t open file "%s"' % fn)
reportlab.pdfbase.ttfonts.TTFError: Can't open file "Roboto-Black.ttf"
ERROR django.server "GET /migrant/get-pdf/1 HTTP/1.1" 500 145153 2021-08-20 14:32:56,743
ERROR django.request Internal Server Error: /migrant/word/1/ 2021-08-20 14:33:18,217
Traceback (most recent call last):
  File "C:\Users\user\OneDrive\Desktop\Projects\databases_v1\venv\lib\site-packages\django\core\handlers\exception.py", line 47, in inner
    response = get_response(request)
  File "C:\Users\user\OneDrive\Desktop\Projects\databases_v1\venv\lib\site-packages\django\core\handlers\base.py", line 181, in _get_response
    response = wrapped_callback(request, *callback_args, **callback_kwargs)
  File "C:\Users\user\OneDrive\Desktop\Projects\databases_v1\databases_v1\migrant\views.py", line 640, in generate_case_word
    tpl.render(context, jinja_env=jinja_env)
  File "C:\Users\user\OneDrive\Desktop\Projects\databases_v1\venv\lib\site-packages\docxtpl\__init__.py", line 316, in render
    xml_src = self.build_xml(context, jinja_env)
  File "C:\Users\user\OneDrive\Desktop\Projects\databases_v1\venv\lib\site-packages\docxtpl\__init__.py", line 271, in build_xml
    xml = self.render_xml_part(xml, self.docx._part, context, jinja_env)
  File "C:\Users\user\OneDrive\Desktop\Projects\databases_v1\venv\lib\site-packages\docxtpl\__init__.py", line 226, in render_xml_part
    raise exc
  File "C:\Users\user\OneDrive\Desktop\Projects\databases_v1\venv\lib\site-packages\docxtpl\__init__.py", line 217, in render_xml_part
    template = jinja_env.from_string(src_xml)
  File "C:\Users\user\OneDrive\Desktop\Projects\databases_v1\venv\lib\site-packages\jinja2\environment.py", line 1092, in from_string
    return cls.from_code(self, self.compile(source), gs, None)
  File "C:\Users\user\OneDrive\Desktop\Projects\databases_v1\venv\lib\site-packages\jinja2\environment.py", line 757, in compile
    self.handle_exception(source=source_hint)
  File "C:\Users\user\OneDrive\Desktop\Projects\databases_v1\venv\lib\site-packages\jinja2\environment.py", line 925, in handle_exception
    raise rewrite_traceback_stack(source=source)
  File "<unknown>", line 1, in template
jinja2.exceptions.TemplateSyntaxError: Expected an expression, got 'end of statement block'
ERROR django.server "GET /migrant/word/1/ HTTP/1.1" 500 149275 2021-08-20 14:33:18,220
ERROR django.request Internal Server Error: /migrant/get-pdf/1 2021-08-20 14:33:40,312
Traceback (most recent call last):
  File "C:\Users\user\OneDrive\Desktop\Projects\databases_v1\venv\lib\site-packages\reportlab\lib\utils.py", line 701, in open_for_read
    return open_for_read_by_name(name,mode)
  File "C:\Users\user\OneDrive\Desktop\Projects\databases_v1\venv\lib\site-packages\reportlab\lib\utils.py", line 636, in open_for_read_by_name
    return open(name,mode)
FileNotFoundError: [Errno 2] No such file or directory: 'Roboto-Black.ttf'

During handling of the above exception, another exception occurred:

Traceback (most recent call last):
  File "C:\Users\user\OneDrive\Desktop\Projects\databases_v1\venv\lib\site-packages\reportlab\lib\utils.py", line 708, in open_for_read
    return getBytesIO(datareader(name) if name[:5].lower()=='data:' else urlopen(name).read())
  File "C:\Users\user\AppData\Local\Programs\Python\Python39\lib\urllib\request.py", line 214, in urlopen
    return opener.open(url, data, timeout)
  File "C:\Users\user\AppData\Local\Programs\Python\Python39\lib\urllib\request.py", line 501, in open
    req = Request(fullurl, data)
  File "C:\Users\user\AppData\Local\Programs\Python\Python39\lib\urllib\request.py", line 320, in __init__
    self.full_url = url
  File "C:\Users\user\AppData\Local\Programs\Python\Python39\lib\urllib\request.py", line 346, in full_url
    self._parse()
  File "C:\Users\user\AppData\Local\Programs\Python\Python39\lib\urllib\request.py", line 375, in _parse
    raise ValueError("unknown url type: %r" % self.full_url)
ValueError: unknown url type: 'Roboto-Black.ttf'

During handling of the above exception, another exception occurred:

Traceback (most recent call last):
  File "C:\Users\user\OneDrive\Desktop\Projects\databases_v1\venv\lib\site-packages\reportlab\pdfbase\ttfonts.py", line 155, in TTFOpenFile
    f = open_for_read(fn,'rb')
  File "C:\Users\user\OneDrive\Desktop\Projects\databases_v1\venv\lib\site-packages\reportlab\lib\utils.py", line 712, in open_for_read
    return open_for_read(name,mode)
  File "C:\Users\user\OneDrive\Desktop\Projects\databases_v1\venv\lib\site-packages\reportlab\lib\utils.py", line 710, in open_for_read
    raise IOError('Cannot open resource "%s"' % name)
OSError: Cannot open resource "Roboto-Black.ttf"

During handling of the above exception, another exception occurred:

Traceback (most recent call last):
  File "C:\Users\user\OneDrive\Desktop\Projects\databases_v1\venv\lib\site-packages\django\core\handlers\exception.py", line 47, in inner
    response = get_response(request)
  File "C:\Users\user\OneDrive\Desktop\Projects\databases_v1\venv\lib\site-packages\django\core\handlers\base.py", line 181, in _get_response
    response = wrapped_callback(request, *callback_args, **callback_kwargs)
  File "C:\Users\user\OneDrive\Desktop\Projects\databases_v1\databases_v1\migrant\views.py", line 770, in pdf_table_generate
    pdfmetrics.registerFont(TTFont('Roboto', 'Roboto-Black.ttf'))
  File "C:\Users\user\OneDrive\Desktop\Projects\databases_v1\venv\lib\site-packages\reportlab\pdfbase\ttfonts.py", line 1196, in __init__
    self.face = TTFontFace(filename, validate=validate, subfontIndex=subfontIndex)
  File "C:\Users\user\OneDrive\Desktop\Projects\databases_v1\venv\lib\site-packages\reportlab\pdfbase\ttfonts.py", line 1090, in __init__
    TTFontFile.__init__(self, filename, validate=validate, subfontIndex=subfontIndex)
  File "C:\Users\user\OneDrive\Desktop\Projects\databases_v1\venv\lib\site-packages\reportlab\pdfbase\ttfonts.py", line 457, in __init__
    TTFontParser.__init__(self, file, validate=validate,subfontIndex=subfontIndex)
  File "C:\Users\user\OneDrive\Desktop\Projects\databases_v1\venv\lib\site-packages\reportlab\pdfbase\ttfonts.py", line 179, in __init__
    self.readFile(file)
  File "C:\Users\user\OneDrive\Desktop\Projects\databases_v1\venv\lib\site-packages\reportlab\pdfbase\ttfonts.py", line 255, in readFile
    self.filename, f = TTFOpenFile(f)
  File "C:\Users\user\OneDrive\Desktop\Projects\databases_v1\venv\lib\site-packages\reportlab\pdfbase\ttfonts.py", line 165, in TTFOpenFile
    raise TTFError('Can\'t open file "%s"' % fn)
reportlab.pdfbase.ttfonts.TTFError: Can't open file "Roboto-Black.ttf"
ERROR django.server "GET /migrant/get-pdf/1 HTTP/1.1" 500 150593 2021-08-20 14:33:40,316
ERROR django.request Internal Server Error: /strike/word/1/ 2021-08-20 15:26:25,120
Traceback (most recent call last):
  File "C:\Users\user\OneDrive\Desktop\Projects\databases_v1\venv\lib\site-packages\django\core\handlers\exception.py", line 47, in inner
    response = get_response(request)
  File "C:\Users\user\OneDrive\Desktop\Projects\databases_v1\venv\lib\site-packages\django\core\handlers\base.py", line 181, in _get_response
    response = wrapped_callback(request, *callback_args, **callback_kwargs)
  File "C:\Users\user\OneDrive\Desktop\Projects\databases_v1\databases_v1\strike\views.py", line 756, in generate_card_word
    tpl.render(context, jinja_env=jinja_env)
  File "C:\Users\user\OneDrive\Desktop\Projects\databases_v1\venv\lib\site-packages\docxtpl\__init__.py", line 316, in render
    xml_src = self.build_xml(context, jinja_env)
  File "C:\Users\user\OneDrive\Desktop\Projects\databases_v1\venv\lib\site-packages\docxtpl\__init__.py", line 271, in build_xml
    xml = self.render_xml_part(xml, self.docx._part, context, jinja_env)
  File "C:\Users\user\OneDrive\Desktop\Projects\databases_v1\venv\lib\site-packages\docxtpl\__init__.py", line 226, in render_xml_part
    raise exc
  File "C:\Users\user\OneDrive\Desktop\Projects\databases_v1\venv\lib\site-packages\docxtpl\__init__.py", line 217, in render_xml_part
    template = jinja_env.from_string(src_xml)
  File "C:\Users\user\OneDrive\Desktop\Projects\databases_v1\venv\lib\site-packages\jinja2\environment.py", line 1092, in from_string
    return cls.from_code(self, self.compile(source), gs, None)
  File "C:\Users\user\OneDrive\Desktop\Projects\databases_v1\venv\lib\site-packages\jinja2\environment.py", line 757, in compile
    self.handle_exception(source=source_hint)
  File "C:\Users\user\OneDrive\Desktop\Projects\databases_v1\venv\lib\site-packages\jinja2\environment.py", line 925, in handle_exception
    raise rewrite_traceback_stack(source=source)
  File "<unknown>", line 1, in template
jinja2.exceptions.TemplateSyntaxError: Encountered unknown tag 'endfor'. Jinja was looking for the following tags: 'elif' or 'else' or 'endif'. The innermost block that needs to be closed is 'if'.
ERROR django.server "GET /strike/word/1/ HTTP/1.1" 500 151612 2021-08-20 15:26:25,123
ERROR django.request Internal Server Error: /strike/word/1/ 2021-08-20 15:27:05,949
Traceback (most recent call last):
  File "C:\Users\user\OneDrive\Desktop\Projects\databases_v1\venv\lib\site-packages\django\core\handlers\exception.py", line 47, in inner
    response = get_response(request)
  File "C:\Users\user\OneDrive\Desktop\Projects\databases_v1\venv\lib\site-packages\django\core\handlers\base.py", line 181, in _get_response
    response = wrapped_callback(request, *callback_args, **callback_kwargs)
  File "C:\Users\user\OneDrive\Desktop\Projects\databases_v1\databases_v1\strike\views.py", line 756, in generate_card_word
    tpl.render(context, jinja_env=jinja_env)
  File "C:\Users\user\OneDrive\Desktop\Projects\databases_v1\venv\lib\site-packages\docxtpl\__init__.py", line 316, in render
    xml_src = self.build_xml(context, jinja_env)
  File "C:\Users\user\OneDrive\Desktop\Projects\databases_v1\venv\lib\site-packages\docxtpl\__init__.py", line 271, in build_xml
    xml = self.render_xml_part(xml, self.docx._part, context, jinja_env)
  File "C:\Users\user\OneDrive\Desktop\Projects\databases_v1\venv\lib\site-packages\docxtpl\__init__.py", line 226, in render_xml_part
    raise exc
  File "C:\Users\user\OneDrive\Desktop\Projects\databases_v1\venv\lib\site-packages\docxtpl\__init__.py", line 217, in render_xml_part
    template = jinja_env.from_string(src_xml)
  File "C:\Users\user\OneDrive\Desktop\Projects\databases_v1\venv\lib\site-packages\jinja2\environment.py", line 1092, in from_string
    return cls.from_code(self, self.compile(source), gs, None)
  File "C:\Users\user\OneDrive\Desktop\Projects\databases_v1\venv\lib\site-packages\jinja2\environment.py", line 757, in compile
    self.handle_exception(source=source_hint)
  File "C:\Users\user\OneDrive\Desktop\Projects\databases_v1\venv\lib\site-packages\jinja2\environment.py", line 925, in handle_exception
    raise rewrite_traceback_stack(source=source)
  File "<unknown>", line 1, in template
jinja2.exceptions.TemplateSyntaxError: Encountered unknown tag 'endfor'. Jinja was looking for the following tags: 'elif' or 'else' or 'endif'. The innermost block that needs to be closed is 'if'.
ERROR django.server "GET /strike/word/1/ HTTP/1.1" 500 151714 2021-08-20 15:27:05,952
ERROR django.request Internal Server Error: /strike/word/1/ 2021-08-20 15:28:37,762
Traceback (most recent call last):
  File "C:\Users\user\OneDrive\Desktop\Projects\databases_v1\venv\lib\site-packages\django\core\handlers\exception.py", line 47, in inner
    response = get_response(request)
  File "C:\Users\user\OneDrive\Desktop\Projects\databases_v1\venv\lib\site-packages\django\core\handlers\base.py", line 181, in _get_response
    response = wrapped_callback(request, *callback_args, **callback_kwargs)
  File "C:\Users\user\OneDrive\Desktop\Projects\databases_v1\databases_v1\strike\views.py", line 756, in generate_card_word
    tpl.render(context, jinja_env=jinja_env)
  File "C:\Users\user\OneDrive\Desktop\Projects\databases_v1\venv\lib\site-packages\docxtpl\__init__.py", line 316, in render
    xml_src = self.build_xml(context, jinja_env)
  File "C:\Users\user\OneDrive\Desktop\Projects\databases_v1\venv\lib\site-packages\docxtpl\__init__.py", line 271, in build_xml
    xml = self.render_xml_part(xml, self.docx._part, context, jinja_env)
  File "C:\Users\user\OneDrive\Desktop\Projects\databases_v1\venv\lib\site-packages\docxtpl\__init__.py", line 226, in render_xml_part
    raise exc
  File "C:\Users\user\OneDrive\Desktop\Projects\databases_v1\venv\lib\site-packages\docxtpl\__init__.py", line 217, in render_xml_part
    template = jinja_env.from_string(src_xml)
  File "C:\Users\user\OneDrive\Desktop\Projects\databases_v1\venv\lib\site-packages\jinja2\environment.py", line 1092, in from_string
    return cls.from_code(self, self.compile(source), gs, None)
  File "C:\Users\user\OneDrive\Desktop\Projects\databases_v1\venv\lib\site-packages\jinja2\environment.py", line 757, in compile
    self.handle_exception(source=source_hint)
  File "C:\Users\user\OneDrive\Desktop\Projects\databases_v1\venv\lib\site-packages\jinja2\environment.py", line 925, in handle_exception
    raise rewrite_traceback_stack(source=source)
  File "<unknown>", line 1, in template
jinja2.exceptions.TemplateSyntaxError: Encountered unknown tag 'endfor'. Jinja was looking for the following tags: 'elif' or 'else' or 'endif'. The innermost block that needs to be closed is 'if'.
ERROR django.server "GET /strike/word/1/ HTTP/1.1" 500 151577 2021-08-20 15:28:37,765
WARNING django.request Not Found: /favicon.ico 2021-08-20 16:26:35,191
WARNING django.server "GET /favicon.ico HTTP/1.1" 404 3524 2021-08-20 16:26:35,193
WARNING django.request Not Found: /debug 2021-08-20 16:26:53,894
WARNING django.server "GET /debug HTTP/1.1" 404 3506 2021-08-20 16:26:53,895
WARNING django.request Not Found: /__debug__/ 2021-08-20 16:26:59,254
WARNING django.server "GET /__debug__/ HTTP/1.1" 404 4758 2021-08-20 16:26:59,255
WARNING django.request Bad Request: / 2021-08-20 18:28:01,777
WARNING django.server "GET / HTTP/1.1" 400 71786 2021-08-20 18:28:01,778
WARNING django.request Bad Request: /favicon.ico 2021-08-20 18:28:02,042
WARNING django.server "GET /favicon.ico HTTP/1.1" 400 71711 2021-08-20 18:28:02,043
WARNING django.request Not Found: /favicon.ico 2021-08-20 18:28:23,239
WARNING django.server "GET /favicon.ico HTTP/1.1" 404 3524 2021-08-20 18:28:23,239
ERROR django.request Internal Server Error: /migrant/get-pdf/1 2021-08-20 18:28:28,686
Traceback (most recent call last):
  File "C:\Users\user\OneDrive\Desktop\Projects\databases_v1\venv\lib\site-packages\pdfkit\configuration.py", line 21, in __init__
    with open(self.wkhtmltopdf) as f:
FileNotFoundError: [Errno 2] No such file or directory: b''

During handling of the above exception, another exception occurred:

Traceback (most recent call last):
  File "C:\Users\user\OneDrive\Desktop\Projects\databases_v1\venv\lib\site-packages\django\core\handlers\exception.py", line 47, in inner
    response = get_response(request)
  File "C:\Users\user\OneDrive\Desktop\Projects\databases_v1\venv\lib\site-packages\django\core\handlers\base.py", line 181, in _get_response
    response = wrapped_callback(request, *callback_args, **callback_kwargs)
  File "C:\Users\user\OneDrive\Desktop\Projects\databases_v1\databases_v1\migrant\views.py", line 262, in case_render_pdf_view
    pdf = pdfkit.from_string(html, False)
  File "C:\Users\user\OneDrive\Desktop\Projects\databases_v1\venv\lib\site-packages\pdfkit\api.py", line 69, in from_string
    r = PDFKit(input, 'string', options=options, toc=toc, cover=cover, css=css,
  File "C:\Users\user\OneDrive\Desktop\Projects\databases_v1\venv\lib\site-packages\pdfkit\pdfkit.py", line 42, in __init__
    self.configuration = (Configuration() if configuration is None
  File "C:\Users\user\OneDrive\Desktop\Projects\databases_v1\venv\lib\site-packages\pdfkit\configuration.py", line 24, in __init__
    raise IOError('No wkhtmltopdf executable found: "%s"\n'
OSError: No wkhtmltopdf executable found: "b''"
If this file exists please check that this process can read it. Otherwise please install wkhtmltopdf - https://github.com/JazzCore/python-pdfkit/wiki/Installing-wkhtmltopdf
ERROR django.server "GET /migrant/get-pdf/1 HTTP/1.1" 500 110133 2021-08-20 18:28:28,688
