ERROR django.request Internal Server Error: /strike/add-comment/1 2021-10-22 08:23:08,446
Traceback (most recent call last):
  File "D:\Users\ntabyldieva\databases_v1\venv\lib\site-packages\django\core\handlers\exception.py", line 47, in inner
    response = get_response(request)
  File "D:\Users\ntabyldieva\databases_v1\venv\lib\site-packages\django\core\handlers\base.py", line 181, in _get_response
    response = wrapped_callback(request, *callback_args, **callback_kwargs)
  File "D:\Users\ntabyldieva\databases_v1\venv\lib\site-packages\django\contrib\auth\decorators.py", line 21, in _wrapped_view
    return view_func(request, *args, **kwargs)
  File "D:\Users\ntabyldieva\databases_v1\strike\views.py", line 332, in add_comment
    to_email = card.user.email
AttributeError: 'Card' object has no attribute 'user'
ERROR django.server "POST /strike/add-comment/1 HTTP/1.1" 500 74950 2021-10-22 08:23:08,448
ERROR django.request Internal Server Error: /strike/add-comment/1 2021-10-22 08:25:44,365
Traceback (most recent call last):
  File "D:\Users\ntabyldieva\databases_v1\venv\lib\site-packages\django\core\handlers\exception.py", line 47, in inner
    response = get_response(request)
  File "D:\Users\ntabyldieva\databases_v1\venv\lib\site-packages\django\core\handlers\base.py", line 181, in _get_response
    response = wrapped_callback(request, *callback_args, **callback_kwargs)
  File "D:\Users\ntabyldieva\databases_v1\venv\lib\site-packages\django\contrib\auth\decorators.py", line 21, in _wrapped_view
    return view_func(request, *args, **kwargs)
  File "D:\Users\ntabyldieva\databases_v1\strike\views.py", line 334, in add_comment
    print(card.card_name)
AttributeError: 'Card' object has no attribute 'card_name'
ERROR django.server "POST /strike/add-comment/1 HTTP/1.1" 500 75231 2021-10-22 08:25:44,367
ERROR django.request Internal Server Error: /strike/add-comment/1 2021-10-22 08:26:20,728
Traceback (most recent call last):
  File "D:\Users\ntabyldieva\databases_v1\venv\lib\site-packages\django\core\handlers\exception.py", line 47, in inner
    response = get_response(request)
  File "D:\Users\ntabyldieva\databases_v1\venv\lib\site-packages\django\core\handlers\base.py", line 181, in _get_response
    response = wrapped_callback(request, *callback_args, **callback_kwargs)
  File "D:\Users\ntabyldieva\databases_v1\venv\lib\site-packages\django\contrib\auth\decorators.py", line 21, in _wrapped_view
    return view_func(request, *args, **kwargs)
  File "D:\Users\ntabyldieva\databases_v1\strike\views.py", line 337, in add_comment
    message = f"На вашу карточку /'{card.card_name}'/ был оставлен слудующий комментарий : '{comment}', oт {from_email}"
AttributeError: 'Card' object has no attribute 'card_name'
ERROR django.server "POST /strike/add-comment/1 HTTP/1.1" 500 75821 2021-10-22 08:26:20,730
ERROR django.request Internal Server Error: /strike/add-comment/1 2021-10-22 08:26:30,452
Traceback (most recent call last):
  File "D:\Users\ntabyldieva\databases_v1\venv\lib\site-packages\django\core\handlers\exception.py", line 47, in inner
    response = get_response(request)
  File "D:\Users\ntabyldieva\databases_v1\venv\lib\site-packages\django\core\handlers\base.py", line 181, in _get_response
    response = wrapped_callback(request, *callback_args, **callback_kwargs)
  File "D:\Users\ntabyldieva\databases_v1\venv\lib\site-packages\django\contrib\auth\decorators.py", line 21, in _wrapped_view
    return view_func(request, *args, **kwargs)
  File "D:\Users\ntabyldieva\databases_v1\strike\views.py", line 337, in add_comment
    message = f"На вашу карточку /'{card.card_name}'/ был оставлен слудующий комментарий : '{comment}', oт {from_email}"
AttributeError: 'Card' object has no attribute 'card_name'
ERROR django.server "POST /strike/add-comment/1 HTTP/1.1" 500 75802 2021-10-22 08:26:30,454
WARNING django.request Bad Request: /admin 2021-10-22 08:29:09,136
WARNING django.server "GET /admin HTTP/1.1" 400 71840 2021-10-22 08:29:09,136
WARNING django.request Bad Request: /favicon.ico 2021-10-22 08:29:09,332
WARNING django.server "GET /favicon.ico HTTP/1.1" 400 71715 2021-10-22 08:29:09,333
ERROR django.request Internal Server Error: /strike/add-comment/1 2021-10-22 08:32:28,510
Traceback (most recent call last):
  File "D:\Users\ntabyldieva\databases_v1\venv\lib\site-packages\django\core\handlers\exception.py", line 47, in inner
    response = get_response(request)
  File "D:\Users\ntabyldieva\databases_v1\venv\lib\site-packages\django\core\handlers\base.py", line 181, in _get_response
    response = wrapped_callback(request, *callback_args, **callback_kwargs)
  File "D:\Users\ntabyldieva\databases_v1\venv\lib\site-packages\django\contrib\auth\decorators.py", line 21, in _wrapped_view
    return view_func(request, *args, **kwargs)
  File "D:\Users\ntabyldieva\databases_v1\strike\views.py", line 335, in add_comment
    send_mail(subject, message, settings.EMAIL_HOST_USER, [to_email, ], fail_silently=False)
  File "D:\Users\ntabyldieva\databases_v1\venv\lib\site-packages\django\core\mail\__init__.py", line 61, in send_mail
    return mail.send()
  File "D:\Users\ntabyldieva\databases_v1\venv\lib\site-packages\django\core\mail\message.py", line 284, in send
    return self.get_connection(fail_silently).send_messages([self])
  File "D:\Users\ntabyldieva\databases_v1\venv\lib\site-packages\django\core\mail\backends\smtp.py", line 102, in send_messages
    new_conn_created = self.open()
  File "D:\Users\ntabyldieva\databases_v1\venv\lib\site-packages\django\core\mail\backends\smtp.py", line 62, in open
    self.connection = self.connection_class(self.host, self.port, **connection_params)
  File "D:\Users\ntabyldieva\AppData\Local\Programs\Python\Python39\lib\smtplib.py", line 255, in __init__
    (code, msg) = self.connect(host, port)
  File "D:\Users\ntabyldieva\AppData\Local\Programs\Python\Python39\lib\smtplib.py", line 341, in connect
    self.sock = self._get_socket(host, port, self.timeout)
  File "D:\Users\ntabyldieva\AppData\Local\Programs\Python\Python39\lib\smtplib.py", line 312, in _get_socket
    return socket.create_connection((host, port), timeout,
  File "D:\Users\ntabyldieva\AppData\Local\Programs\Python\Python39\lib\socket.py", line 844, in create_connection
    raise err
  File "D:\Users\ntabyldieva\AppData\Local\Programs\Python\Python39\lib\socket.py", line 832, in create_connection
    sock.connect(sa)
TimeoutError: [WinError 10060] Попытка установить соединение была безуспешной, т.к. от другого компьютера за требуемое время не получен нужный отклик, или было разорвано уже установленное соединение из-за неверного отклика уже подключенного компьютера
ERROR django.server "POST /strike/add-comment/1 HTTP/1.1" 500 119825 2021-10-22 08:32:28,513
WARNING django.request Not Found: /favicon.ico 2021-10-22 14:26:59,433
WARNING django.server "GET /favicon.ico HTTP/1.1" 404 3524 2021-10-22 14:26:59,448
ERROR django.request Internal Server Error: /strike/data/get/ 2021-10-22 14:32:11,446
Traceback (most recent call last):
  File "D:\Users\ntabyldieva\databases_v1\venv\lib\site-packages\django\core\handlers\exception.py", line 47, in inner
    response = get_response(request)
  File "D:\Users\ntabyldieva\databases_v1\venv\lib\site-packages\django\core\handlers\base.py", line 181, in _get_response
    response = wrapped_callback(request, *callback_args, **callback_kwargs)
  File "D:\Users\ntabyldieva\databases_v1\venv\lib\site-packages\django\views\decorators\csrf.py", line 54, in wrapped_view
    return view_func(*args, **kwargs)
  File "D:\Users\ntabyldieva\databases_v1\venv\lib\site-packages\django\views\generic\base.py", line 70, in view
    return self.dispatch(request, *args, **kwargs)
  File "D:\Users\ntabyldieva\databases_v1\venv\lib\site-packages\rest_framework\views.py", line 511, in dispatch
    self.response = self.finalize_response(request, response, *args, **kwargs)
  File "D:\Users\ntabyldieva\databases_v1\venv\lib\site-packages\rest_framework\views.py", line 423, in finalize_response
    assert isinstance(response, HttpResponseBase), (
AssertionError: Expected a `Response`, `HttpResponse` or `HttpStreamingResponse` to be returned from the view, but received a `<class 'NoneType'>`
ERROR django.server "POST /strike/data/get/ HTTP/1.1" 500 81587 2021-10-22 14:32:11,446
ERROR django.request Internal Server Error: /strike/data/get/ 2021-10-22 14:32:13,519
Traceback (most recent call last):
  File "D:\Users\ntabyldieva\databases_v1\venv\lib\site-packages\django\core\handlers\exception.py", line 47, in inner
    response = get_response(request)
  File "D:\Users\ntabyldieva\databases_v1\venv\lib\site-packages\django\core\handlers\base.py", line 181, in _get_response
    response = wrapped_callback(request, *callback_args, **callback_kwargs)
  File "D:\Users\ntabyldieva\databases_v1\venv\lib\site-packages\django\views\decorators\csrf.py", line 54, in wrapped_view
    return view_func(*args, **kwargs)
  File "D:\Users\ntabyldieva\databases_v1\venv\lib\site-packages\django\views\generic\base.py", line 70, in view
    return self.dispatch(request, *args, **kwargs)
  File "D:\Users\ntabyldieva\databases_v1\venv\lib\site-packages\rest_framework\views.py", line 511, in dispatch
    self.response = self.finalize_response(request, response, *args, **kwargs)
  File "D:\Users\ntabyldieva\databases_v1\venv\lib\site-packages\rest_framework\views.py", line 423, in finalize_response
    assert isinstance(response, HttpResponseBase), (
AssertionError: Expected a `Response`, `HttpResponse` or `HttpStreamingResponse` to be returned from the view, but received a `<class 'NoneType'>`
ERROR django.server "POST /strike/data/get/ HTTP/1.1" 500 81587 2021-10-22 14:32:13,521
ERROR django.request Internal Server Error: /strike/data/get/ 2021-10-22 14:34:52,377
Traceback (most recent call last):
  File "D:\Users\ntabyldieva\databases_v1\venv\lib\site-packages\django\core\handlers\exception.py", line 47, in inner
    response = get_response(request)
  File "D:\Users\ntabyldieva\databases_v1\venv\lib\site-packages\django\core\handlers\base.py", line 181, in _get_response
    response = wrapped_callback(request, *callback_args, **callback_kwargs)
  File "D:\Users\ntabyldieva\databases_v1\venv\lib\site-packages\django\views\decorators\csrf.py", line 54, in wrapped_view
    return view_func(*args, **kwargs)
  File "D:\Users\ntabyldieva\databases_v1\venv\lib\site-packages\django\views\generic\base.py", line 70, in view
    return self.dispatch(request, *args, **kwargs)
  File "D:\Users\ntabyldieva\databases_v1\venv\lib\site-packages\rest_framework\views.py", line 511, in dispatch
    self.response = self.finalize_response(request, response, *args, **kwargs)
  File "D:\Users\ntabyldieva\databases_v1\venv\lib\site-packages\rest_framework\views.py", line 423, in finalize_response
    assert isinstance(response, HttpResponseBase), (
AssertionError: Expected a `Response`, `HttpResponse` or `HttpStreamingResponse` to be returned from the view, but received a `<class 'NoneType'>`
ERROR django.server "POST /strike/data/get/ HTTP/1.1" 500 81587 2021-10-22 14:34:52,377
ERROR django.request Internal Server Error: /strike/data/get/ 2021-10-22 14:50:30,103
Traceback (most recent call last):
  File "D:\Users\ntabyldieva\databases_v1\venv\lib\site-packages\django\core\handlers\exception.py", line 47, in inner
    response = get_response(request)
  File "D:\Users\ntabyldieva\databases_v1\venv\lib\site-packages\django\core\handlers\base.py", line 181, in _get_response
    response = wrapped_callback(request, *callback_args, **callback_kwargs)
  File "D:\Users\ntabyldieva\databases_v1\venv\lib\site-packages\django\views\decorators\csrf.py", line 54, in wrapped_view
    return view_func(*args, **kwargs)
  File "D:\Users\ntabyldieva\databases_v1\venv\lib\site-packages\django\views\generic\base.py", line 70, in view
    return self.dispatch(request, *args, **kwargs)
  File "D:\Users\ntabyldieva\databases_v1\venv\lib\site-packages\rest_framework\views.py", line 509, in dispatch
    response = self.handle_exception(exc)
  File "D:\Users\ntabyldieva\databases_v1\venv\lib\site-packages\rest_framework\views.py", line 469, in handle_exception
    self.raise_uncaught_exception(exc)
  File "D:\Users\ntabyldieva\databases_v1\venv\lib\site-packages\rest_framework\views.py", line 480, in raise_uncaught_exception
    raise exc
  File "D:\Users\ntabyldieva\databases_v1\venv\lib\site-packages\rest_framework\views.py", line 506, in dispatch
    response = handler(request, *args, **kwargs)
  File "D:\Users\ntabyldieva\databases_v1\strike\views.py", line 470, in post
    values_list = get_values(fields)
  File "D:\Users\ntabyldieva\databases_v1\strike\helpers.py", line 26, in get_values
    for i in data.keys():
AttributeError: 'list' object has no attribute 'keys'
ERROR django.server "POST /strike/data/get/ HTTP/1.1" 500 98380 2021-10-22 14:50:30,119
ERROR django.request Internal Server Error: /strike/data/get/ 2021-10-22 14:51:33,072
Traceback (most recent call last):
  File "D:\Users\ntabyldieva\databases_v1\venv\lib\site-packages\django\core\handlers\exception.py", line 47, in inner
    response = get_response(request)
  File "D:\Users\ntabyldieva\databases_v1\venv\lib\site-packages\django\core\handlers\base.py", line 181, in _get_response
    response = wrapped_callback(request, *callback_args, **callback_kwargs)
  File "D:\Users\ntabyldieva\databases_v1\venv\lib\site-packages\django\views\decorators\csrf.py", line 54, in wrapped_view
    return view_func(*args, **kwargs)
  File "D:\Users\ntabyldieva\databases_v1\venv\lib\site-packages\django\views\generic\base.py", line 70, in view
    return self.dispatch(request, *args, **kwargs)
  File "D:\Users\ntabyldieva\databases_v1\venv\lib\site-packages\rest_framework\views.py", line 509, in dispatch
    response = self.handle_exception(exc)
  File "D:\Users\ntabyldieva\databases_v1\venv\lib\site-packages\rest_framework\views.py", line 469, in handle_exception
    self.raise_uncaught_exception(exc)
  File "D:\Users\ntabyldieva\databases_v1\venv\lib\site-packages\rest_framework\views.py", line 480, in raise_uncaught_exception
    raise exc
  File "D:\Users\ntabyldieva\databases_v1\venv\lib\site-packages\rest_framework\views.py", line 506, in dispatch
    response = handler(request, *args, **kwargs)
  File "D:\Users\ntabyldieva\databases_v1\strike\views.py", line 476, in post
    fields = get_fields(fields)
  File "D:\Users\ntabyldieva\databases_v1\strike\helpers.py", line 48, in get_fields
    for i in data.keys():
AttributeError: 'list' object has no attribute 'keys'
ERROR django.server "POST /strike/data/get/ HTTP/1.1" 500 98785 2021-10-22 14:51:33,087
ERROR django.request Internal Server Error: /strike/data/get/ 2021-10-22 14:54:32,814
Traceback (most recent call last):
  File "D:\Users\ntabyldieva\databases_v1\venv\lib\site-packages\rest_framework\fields.py", line 457, in get_attribute
    return get_attribute(instance, self.source_attrs)
  File "D:\Users\ntabyldieva\databases_v1\venv\lib\site-packages\rest_framework\fields.py", line 95, in get_attribute
    instance = instance[attr]
KeyError: 'country'

During handling of the above exception, another exception occurred:

Traceback (most recent call last):
  File "D:\Users\ntabyldieva\databases_v1\venv\lib\site-packages\django\core\handlers\exception.py", line 47, in inner
    response = get_response(request)
  File "D:\Users\ntabyldieva\databases_v1\venv\lib\site-packages\django\core\handlers\base.py", line 181, in _get_response
    response = wrapped_callback(request, *callback_args, **callback_kwargs)
  File "D:\Users\ntabyldieva\databases_v1\venv\lib\site-packages\django\views\decorators\csrf.py", line 54, in wrapped_view
    return view_func(*args, **kwargs)
  File "D:\Users\ntabyldieva\databases_v1\venv\lib\site-packages\django\views\generic\base.py", line 70, in view
    return self.dispatch(request, *args, **kwargs)
  File "D:\Users\ntabyldieva\databases_v1\venv\lib\site-packages\rest_framework\views.py", line 509, in dispatch
    response = self.handle_exception(exc)
  File "D:\Users\ntabyldieva\databases_v1\venv\lib\site-packages\rest_framework\views.py", line 469, in handle_exception
    self.raise_uncaught_exception(exc)
  File "D:\Users\ntabyldieva\databases_v1\venv\lib\site-packages\rest_framework\views.py", line 480, in raise_uncaught_exception
    raise exc
  File "D:\Users\ntabyldieva\databases_v1\venv\lib\site-packages\rest_framework\views.py", line 506, in dispatch
    response = handler(request, *args, **kwargs)
  File "D:\Users\ntabyldieva\databases_v1\strike\views.py", line 479, in post
    return Response(serializers.data)
  File "D:\Users\ntabyldieva\databases_v1\venv\lib\site-packages\rest_framework\serializers.py", line 745, in data
    ret = super().data
  File "D:\Users\ntabyldieva\databases_v1\venv\lib\site-packages\rest_framework\serializers.py", line 246, in data
    self._data = self.to_representation(self.instance)
  File "D:\Users\ntabyldieva\databases_v1\venv\lib\site-packages\rest_framework\serializers.py", line 663, in to_representation
    return [
  File "D:\Users\ntabyldieva\databases_v1\venv\lib\site-packages\rest_framework\serializers.py", line 664, in <listcomp>
    self.child.to_representation(item) for item in iterable
  File "D:\Users\ntabyldieva\databases_v1\venv\lib\site-packages\rest_framework\serializers.py", line 502, in to_representation
    attribute = field.get_attribute(instance)
  File "D:\Users\ntabyldieva\databases_v1\venv\lib\site-packages\rest_framework\relations.py", line 190, in get_attribute
    return super().get_attribute(instance)
  File "D:\Users\ntabyldieva\databases_v1\venv\lib\site-packages\rest_framework\fields.py", line 490, in get_attribute
    raise type(exc)(msg)
KeyError: "Got KeyError when attempting to get a value for field `country` on serializer `FilterStrikeGroupSerializer`.\nThe serializer field might be named incorrectly and not match any attribute or key on the `dict` instance.\nOriginal exception text was: 'country'."
ERROR django.server "POST /strike/data/get/ HTTP/1.1" 500 139826 2021-10-22 14:54:32,819
ERROR django.request Internal Server Error: /strike/data/get/ 2021-10-22 14:54:34,157
Traceback (most recent call last):
  File "D:\Users\ntabyldieva\databases_v1\venv\lib\site-packages\rest_framework\fields.py", line 457, in get_attribute
    return get_attribute(instance, self.source_attrs)
  File "D:\Users\ntabyldieva\databases_v1\venv\lib\site-packages\rest_framework\fields.py", line 95, in get_attribute
    instance = instance[attr]
KeyError: 'country'

During handling of the above exception, another exception occurred:

Traceback (most recent call last):
  File "D:\Users\ntabyldieva\databases_v1\venv\lib\site-packages\django\core\handlers\exception.py", line 47, in inner
    response = get_response(request)
  File "D:\Users\ntabyldieva\databases_v1\venv\lib\site-packages\django\core\handlers\base.py", line 181, in _get_response
    response = wrapped_callback(request, *callback_args, **callback_kwargs)
  File "D:\Users\ntabyldieva\databases_v1\venv\lib\site-packages\django\views\decorators\csrf.py", line 54, in wrapped_view
    return view_func(*args, **kwargs)
  File "D:\Users\ntabyldieva\databases_v1\venv\lib\site-packages\django\views\generic\base.py", line 70, in view
    return self.dispatch(request, *args, **kwargs)
  File "D:\Users\ntabyldieva\databases_v1\venv\lib\site-packages\rest_framework\views.py", line 509, in dispatch
    response = self.handle_exception(exc)
  File "D:\Users\ntabyldieva\databases_v1\venv\lib\site-packages\rest_framework\views.py", line 469, in handle_exception
    self.raise_uncaught_exception(exc)
  File "D:\Users\ntabyldieva\databases_v1\venv\lib\site-packages\rest_framework\views.py", line 480, in raise_uncaught_exception
    raise exc
  File "D:\Users\ntabyldieva\databases_v1\venv\lib\site-packages\rest_framework\views.py", line 506, in dispatch
    response = handler(request, *args, **kwargs)
  File "D:\Users\ntabyldieva\databases_v1\strike\views.py", line 479, in post
    return Response(serializers.data)
  File "D:\Users\ntabyldieva\databases_v1\venv\lib\site-packages\rest_framework\serializers.py", line 745, in data
    ret = super().data
  File "D:\Users\ntabyldieva\databases_v1\venv\lib\site-packages\rest_framework\serializers.py", line 246, in data
    self._data = self.to_representation(self.instance)
  File "D:\Users\ntabyldieva\databases_v1\venv\lib\site-packages\rest_framework\serializers.py", line 663, in to_representation
    return [
  File "D:\Users\ntabyldieva\databases_v1\venv\lib\site-packages\rest_framework\serializers.py", line 664, in <listcomp>
    self.child.to_representation(item) for item in iterable
  File "D:\Users\ntabyldieva\databases_v1\venv\lib\site-packages\rest_framework\serializers.py", line 502, in to_representation
    attribute = field.get_attribute(instance)
  File "D:\Users\ntabyldieva\databases_v1\venv\lib\site-packages\rest_framework\relations.py", line 190, in get_attribute
    return super().get_attribute(instance)
  File "D:\Users\ntabyldieva\databases_v1\venv\lib\site-packages\rest_framework\fields.py", line 490, in get_attribute
    raise type(exc)(msg)
KeyError: "Got KeyError when attempting to get a value for field `country` on serializer `FilterStrikeGroupSerializer`.\nThe serializer field might be named incorrectly and not match any attribute or key on the `dict` instance.\nOriginal exception text was: 'country'."
ERROR django.server "POST /strike/data/get/ HTTP/1.1" 500 139826 2021-10-22 14:54:34,160
ERROR django.request Internal Server Error: /migrant/data/get/ 2021-10-22 15:07:33,487
Traceback (most recent call last):
  File "D:\Users\ntabyldieva\databases_v1\venv\lib\site-packages\django\core\handlers\exception.py", line 47, in inner
    response = get_response(request)
  File "D:\Users\ntabyldieva\databases_v1\venv\lib\site-packages\django\core\handlers\base.py", line 181, in _get_response
    response = wrapped_callback(request, *callback_args, **callback_kwargs)
  File "D:\Users\ntabyldieva\databases_v1\venv\lib\site-packages\django\views\decorators\csrf.py", line 54, in wrapped_view
    return view_func(*args, **kwargs)
  File "D:\Users\ntabyldieva\databases_v1\venv\lib\site-packages\django\views\generic\base.py", line 70, in view
    return self.dispatch(request, *args, **kwargs)
  File "D:\Users\ntabyldieva\databases_v1\venv\lib\site-packages\rest_framework\views.py", line 509, in dispatch
    response = self.handle_exception(exc)
  File "D:\Users\ntabyldieva\databases_v1\venv\lib\site-packages\rest_framework\views.py", line 469, in handle_exception
    self.raise_uncaught_exception(exc)
  File "D:\Users\ntabyldieva\databases_v1\venv\lib\site-packages\rest_framework\views.py", line 480, in raise_uncaught_exception
    raise exc
  File "D:\Users\ntabyldieva\databases_v1\venv\lib\site-packages\rest_framework\views.py", line 506, in dispatch
    response = handler(request, *args, **kwargs)
  File "D:\Users\ntabyldieva\databases_v1\migrant\views.py", line 389, in post
    serializers = FilterStrikeGroupSerializer(queryset, many=True, fields=fields)
NameError: name 'FilterStrikeGroupSerializer' is not defined
ERROR django.server "POST /migrant/data/get/ HTTP/1.1" 500 95643 2021-10-22 15:07:33,487
