WARNING django.request Not Found: /favicon.ico 2021-11-02 11:16:48,126
WARNING django.server "GET /favicon.ico HTTP/1.1" 404 3524 2021-11-02 11:16:48,126
ERROR django.request Internal Server Error: /analytic/work/search/ 2021-11-02 11:16:56,498
Traceback (most recent call last):
  File "D:\Users\ntabyldieva\Desktop\databases_v1\env\lib\site-packages\django\core\handlers\exception.py", line 47, in inner
    response = get_response(request)
  File "D:\Users\ntabyldieva\Desktop\databases_v1\env\lib\site-packages\django\core\handlers\base.py", line 181, in _get_response
    response = wrapped_callback(request, *callback_args, **callback_kwargs)
  File "D:\Users\ntabyldieva\Desktop\databases_v1\env\lib\site-packages\django\views\decorators\csrf.py", line 54, in wrapped_view
    return view_func(*args, **kwargs)
  File "D:\Users\ntabyldieva\Desktop\databases_v1\env\lib\site-packages\django\views\generic\base.py", line 70, in view
    return self.dispatch(request, *args, **kwargs)
  File "D:\Users\ntabyldieva\Desktop\databases_v1\env\lib\site-packages\rest_framework\views.py", line 509, in dispatch
    response = self.handle_exception(exc)
  File "D:\Users\ntabyldieva\Desktop\databases_v1\env\lib\site-packages\rest_framework\views.py", line 469, in handle_exception
    self.raise_uncaught_exception(exc)
  File "D:\Users\ntabyldieva\Desktop\databases_v1\env\lib\site-packages\rest_framework\views.py", line 480, in raise_uncaught_exception
    raise exc
  File "D:\Users\ntabyldieva\Desktop\databases_v1\env\lib\site-packages\rest_framework\views.py", line 506, in dispatch
    response = handler(request, *args, **kwargs)
  File "D:\Users\ntabyldieva\Desktop\databases_v1\statistica\views.py", line 106, in post
    workcases = WorkCase.objects.filter(**filters)
  File "D:\Users\ntabyldieva\Desktop\databases_v1\env\lib\site-packages\django\db\models\manager.py", line 85, in manager_method
    return getattr(self.get_queryset(), name)(*args, **kwargs)
  File "D:\Users\ntabyldieva\Desktop\databases_v1\env\lib\site-packages\django\db\models\query.py", line 941, in filter
    return self._filter_or_exclude(False, args, kwargs)
  File "D:\Users\ntabyldieva\Desktop\databases_v1\env\lib\site-packages\django\db\models\query.py", line 961, in _filter_or_exclude
    clone._filter_or_exclude_inplace(negate, args, kwargs)
  File "D:\Users\ntabyldieva\Desktop\databases_v1\env\lib\site-packages\django\db\models\query.py", line 968, in _filter_or_exclude_inplace
    self._query.add_q(Q(*args, **kwargs))
  File "D:\Users\ntabyldieva\Desktop\databases_v1\env\lib\site-packages\django\db\models\sql\query.py", line 1391, in add_q
    clause, _ = self._add_q(q_object, self.used_aliases)
  File "D:\Users\ntabyldieva\Desktop\databases_v1\env\lib\site-packages\django\db\models\sql\query.py", line 1410, in _add_q
    child_clause, needed_inner = self.build_filter(
  File "D:\Users\ntabyldieva\Desktop\databases_v1\env\lib\site-packages\django\db\models\sql\query.py", line 1284, in build_filter
    lookups, parts, reffed_expression = self.solve_lookup_type(arg)
  File "D:\Users\ntabyldieva\Desktop\databases_v1\env\lib\site-packages\django\db\models\sql\query.py", line 1110, in solve_lookup_type
    _, field, _, lookup_parts = self.names_to_path(lookup_splitted, self.get_meta())
  File "D:\Users\ntabyldieva\Desktop\databases_v1\env\lib\site-packages\django\db\models\sql\query.py", line 1537, in names_to_path
    raise FieldError("Cannot resolve keyword '%s' into field. "
django.core.exceptions.FieldError: Cannot resolve keyword 'groupofrights_id' into field. Choices are: active, antiTradeUnionDiscrimination, antiTradeUnionDiscriminationAnother, antiTradeUnionDiscrimination_id, case_company_name, case_description, case_name, case_result, case_text, casecomment, casefile, casephoto, childLabor, childLabor_id, city_name, comment, company, company_id, consultationRight, consultationRightAnother, consultationRight_id, convention182, convention182_id, conversationRight, conversationRightAnother, conversationRight_id, country, country_id, createOrganizationRight, createOrganizationRightAnother, createOrganizationRight_id, createStrikeRight, createStrikeRightAnother, createStrikeRight_id, createTradeUnionRight, createTradeUnionRightAnother, createTradeUnionRight_id, date_create, date_type, date_update, discriminatiOnVariousGrounds, discriminatiOnVariousGrounds_id, discriminationInVariousAreas, discriminationInVariousAreasAnother, discriminationInVariousAreas_id, electionsRight, electionsRightAnother, electionsRight_id, end_date, exact_data, failureSystemicMeasures, failureSystemicMeasures_id, governmentCoercion, governmentCoercion_id, government_agency_name, groupOfPersons, groupOfPersons_id, groupOfRights, groupOfRights_id, id, individualinfo, intruder, intruderAnother, local_agency_name, meetingsRight, meetingsRightAnother, meetingsRight_id, police_agency_name, principleOfNonDiscrimination, principleOfNonDiscrimination_id, prohibitionOfForcedLabor, prohibitionOfForcedLabor_id, publicPolicyDiscrimination, publicPolicyDiscrimination_id, region, region_id, rights_state, rights_state_another, rights_state_id, source, source_another, source_content, source_url, start_date, tradeUnionActivityRight, tradeUnionActivityRightAnother, tradeUnionActivityRight_id, tradeUnionBuildingsRight, tradeUnionBuildingsRightAnother, tradeUnionBuildingsRight_id, tradeUnionCount, tradeUnionCount_id, tradeUnionCrime, tradeUnionCrimeAnother, tradeUnionCrime_id, tradeUnionInfo, tradeUnionInfo_id, tradeUnionRight, tradeUnionRightAnother, tradeUnionRight_id, tradeUnionSituation, tradeUnionSituation_another, tradeUnionSituation_id, trade_union_activities, trade_union_activities_another, trade_union_activities_id, tradeunion_actions, useOfForcedLabor, useOfForcedLabor_id, user, user_id, victim, victim_id, victim_situation, victim_situation_another, victim_situation_id, violation_nature, violation_nature_id, violationsUsingCompulsoryLabor, violationsUsingCompulsoryLabor_id, ñonvention135, ñonvention135Another, ñonvention135_id, ñonvention138, ñonvention138_id, ñonvention87, ñonvention87_id, ñonvention98, ñonvention98_id
ERROR django.server "POST /analytic/work/search/ HTTP/1.1" 500 161359 2021-11-02 11:16:56,498
WARNING django.request Not Found: /favicon.ico 2021-11-02 11:17:56,779
WARNING django.server "GET /favicon.ico HTTP/1.1" 404 3524 2021-11-02 11:17:56,780
ERROR django.request Internal Server Error: /analytic/work/search/ 2021-11-02 11:18:04,332
Traceback (most recent call last):
  File "D:\Users\ntabyldieva\Desktop\databases_v1\env\lib\site-packages\django\core\handlers\exception.py", line 47, in inner
    response = get_response(request)
  File "D:\Users\ntabyldieva\Desktop\databases_v1\env\lib\site-packages\django\core\handlers\base.py", line 181, in _get_response
    response = wrapped_callback(request, *callback_args, **callback_kwargs)
  File "D:\Users\ntabyldieva\Desktop\databases_v1\env\lib\site-packages\django\views\decorators\csrf.py", line 54, in wrapped_view
    return view_func(*args, **kwargs)
  File "D:\Users\ntabyldieva\Desktop\databases_v1\env\lib\site-packages\django\views\generic\base.py", line 70, in view
    return self.dispatch(request, *args, **kwargs)
  File "D:\Users\ntabyldieva\Desktop\databases_v1\env\lib\site-packages\rest_framework\views.py", line 509, in dispatch
    response = self.handle_exception(exc)
  File "D:\Users\ntabyldieva\Desktop\databases_v1\env\lib\site-packages\rest_framework\views.py", line 469, in handle_exception
    self.raise_uncaught_exception(exc)
  File "D:\Users\ntabyldieva\Desktop\databases_v1\env\lib\site-packages\rest_framework\views.py", line 480, in raise_uncaught_exception
    raise exc
  File "D:\Users\ntabyldieva\Desktop\databases_v1\env\lib\site-packages\rest_framework\views.py", line 506, in dispatch
    response = handler(request, *args, **kwargs)
  File "D:\Users\ntabyldieva\Desktop\databases_v1\statistica\views.py", line 106, in post
    workcases = WorkCase.objects.filter(**filters)
  File "D:\Users\ntabyldieva\Desktop\databases_v1\env\lib\site-packages\django\db\models\manager.py", line 85, in manager_method
    return getattr(self.get_queryset(), name)(*args, **kwargs)
  File "D:\Users\ntabyldieva\Desktop\databases_v1\env\lib\site-packages\django\db\models\query.py", line 941, in filter
    return self._filter_or_exclude(False, args, kwargs)
  File "D:\Users\ntabyldieva\Desktop\databases_v1\env\lib\site-packages\django\db\models\query.py", line 961, in _filter_or_exclude
    clone._filter_or_exclude_inplace(negate, args, kwargs)
  File "D:\Users\ntabyldieva\Desktop\databases_v1\env\lib\site-packages\django\db\models\query.py", line 968, in _filter_or_exclude_inplace
    self._query.add_q(Q(*args, **kwargs))
  File "D:\Users\ntabyldieva\Desktop\databases_v1\env\lib\site-packages\django\db\models\sql\query.py", line 1391, in add_q
    clause, _ = self._add_q(q_object, self.used_aliases)
  File "D:\Users\ntabyldieva\Desktop\databases_v1\env\lib\site-packages\django\db\models\sql\query.py", line 1410, in _add_q
    child_clause, needed_inner = self.build_filter(
  File "D:\Users\ntabyldieva\Desktop\databases_v1\env\lib\site-packages\django\db\models\sql\query.py", line 1284, in build_filter
    lookups, parts, reffed_expression = self.solve_lookup_type(arg)
  File "D:\Users\ntabyldieva\Desktop\databases_v1\env\lib\site-packages\django\db\models\sql\query.py", line 1110, in solve_lookup_type
    _, field, _, lookup_parts = self.names_to_path(lookup_splitted, self.get_meta())
  File "D:\Users\ntabyldieva\Desktop\databases_v1\env\lib\site-packages\django\db\models\sql\query.py", line 1537, in names_to_path
    raise FieldError("Cannot resolve keyword '%s' into field. "
django.core.exceptions.FieldError: Cannot resolve keyword 'groupofrights_id' into field. Choices are: active, antiTradeUnionDiscrimination, antiTradeUnionDiscriminationAnother, antiTradeUnionDiscrimination_id, case_company_name, case_description, case_name, case_result, case_text, casecomment, casefile, casephoto, childLabor, childLabor_id, city_name, comment, company, company_id, consultationRight, consultationRightAnother, consultationRight_id, convention182, convention182_id, conversationRight, conversationRightAnother, conversationRight_id, country, country_id, createOrganizationRight, createOrganizationRightAnother, createOrganizationRight_id, createStrikeRight, createStrikeRightAnother, createStrikeRight_id, createTradeUnionRight, createTradeUnionRightAnother, createTradeUnionRight_id, date_create, date_type, date_update, discriminatiOnVariousGrounds, discriminatiOnVariousGrounds_id, discriminationInVariousAreas, discriminationInVariousAreasAnother, discriminationInVariousAreas_id, electionsRight, electionsRightAnother, electionsRight_id, end_date, exact_data, failureSystemicMeasures, failureSystemicMeasures_id, governmentCoercion, governmentCoercion_id, government_agency_name, groupOfPersons, groupOfPersons_id, groupOfRights, groupOfRights_id, id, individualinfo, intruder, intruderAnother, local_agency_name, meetingsRight, meetingsRightAnother, meetingsRight_id, police_agency_name, principleOfNonDiscrimination, principleOfNonDiscrimination_id, prohibitionOfForcedLabor, prohibitionOfForcedLabor_id, publicPolicyDiscrimination, publicPolicyDiscrimination_id, region, region_id, rights_state, rights_state_another, rights_state_id, source, source_another, source_content, source_url, start_date, tradeUnionActivityRight, tradeUnionActivityRightAnother, tradeUnionActivityRight_id, tradeUnionBuildingsRight, tradeUnionBuildingsRightAnother, tradeUnionBuildingsRight_id, tradeUnionCount, tradeUnionCount_id, tradeUnionCrime, tradeUnionCrimeAnother, tradeUnionCrime_id, tradeUnionInfo, tradeUnionInfo_id, tradeUnionRight, tradeUnionRightAnother, tradeUnionRight_id, tradeUnionSituation, tradeUnionSituation_another, tradeUnionSituation_id, trade_union_activities, trade_union_activities_another, trade_union_activities_id, tradeunion_actions, useOfForcedLabor, useOfForcedLabor_id, user, user_id, victim, victim_id, victim_situation, victim_situation_another, victim_situation_id, violation_nature, violation_nature_id, violationsUsingCompulsoryLabor, violationsUsingCompulsoryLabor_id, ñonvention135, ñonvention135Another, ñonvention135_id, ñonvention138, ñonvention138_id, ñonvention87, ñonvention87_id, ñonvention98, ñonvention98_id
ERROR django.server "POST /analytic/work/search/ HTTP/1.1" 500 161359 2021-11-02 11:18:04,332
ERROR django.request Internal Server Error: /analytic/work/search/ 2021-11-02 11:18:49,410
Traceback (most recent call last):
  File "D:\Users\ntabyldieva\Desktop\databases_v1\env\lib\site-packages\django\core\handlers\exception.py", line 47, in inner
    response = get_response(request)
  File "D:\Users\ntabyldieva\Desktop\databases_v1\env\lib\site-packages\django\core\handlers\base.py", line 181, in _get_response
    response = wrapped_callback(request, *callback_args, **callback_kwargs)
  File "D:\Users\ntabyldieva\Desktop\databases_v1\env\lib\site-packages\django\views\decorators\csrf.py", line 54, in wrapped_view
    return view_func(*args, **kwargs)
  File "D:\Users\ntabyldieva\Desktop\databases_v1\env\lib\site-packages\django\views\generic\base.py", line 70, in view
    return self.dispatch(request, *args, **kwargs)
  File "D:\Users\ntabyldieva\Desktop\databases_v1\env\lib\site-packages\rest_framework\views.py", line 509, in dispatch
    response = self.handle_exception(exc)
  File "D:\Users\ntabyldieva\Desktop\databases_v1\env\lib\site-packages\rest_framework\views.py", line 469, in handle_exception
    self.raise_uncaught_exception(exc)
  File "D:\Users\ntabyldieva\Desktop\databases_v1\env\lib\site-packages\rest_framework\views.py", line 480, in raise_uncaught_exception
    raise exc
  File "D:\Users\ntabyldieva\Desktop\databases_v1\env\lib\site-packages\rest_framework\views.py", line 506, in dispatch
    response = handler(request, *args, **kwargs)
  File "D:\Users\ntabyldieva\Desktop\databases_v1\statistica\views.py", line 106, in post
    workcases = WorkCase.objects.filter(**filters)
  File "D:\Users\ntabyldieva\Desktop\databases_v1\env\lib\site-packages\django\db\models\manager.py", line 85, in manager_method
    return getattr(self.get_queryset(), name)(*args, **kwargs)
  File "D:\Users\ntabyldieva\Desktop\databases_v1\env\lib\site-packages\django\db\models\query.py", line 941, in filter
    return self._filter_or_exclude(False, args, kwargs)
  File "D:\Users\ntabyldieva\Desktop\databases_v1\env\lib\site-packages\django\db\models\query.py", line 961, in _filter_or_exclude
    clone._filter_or_exclude_inplace(negate, args, kwargs)
  File "D:\Users\ntabyldieva\Desktop\databases_v1\env\lib\site-packages\django\db\models\query.py", line 968, in _filter_or_exclude_inplace
    self._query.add_q(Q(*args, **kwargs))
  File "D:\Users\ntabyldieva\Desktop\databases_v1\env\lib\site-packages\django\db\models\sql\query.py", line 1391, in add_q
    clause, _ = self._add_q(q_object, self.used_aliases)
  File "D:\Users\ntabyldieva\Desktop\databases_v1\env\lib\site-packages\django\db\models\sql\query.py", line 1410, in _add_q
    child_clause, needed_inner = self.build_filter(
  File "D:\Users\ntabyldieva\Desktop\databases_v1\env\lib\site-packages\django\db\models\sql\query.py", line 1284, in build_filter
    lookups, parts, reffed_expression = self.solve_lookup_type(arg)
  File "D:\Users\ntabyldieva\Desktop\databases_v1\env\lib\site-packages\django\db\models\sql\query.py", line 1110, in solve_lookup_type
    _, field, _, lookup_parts = self.names_to_path(lookup_splitted, self.get_meta())
  File "D:\Users\ntabyldieva\Desktop\databases_v1\env\lib\site-packages\django\db\models\sql\query.py", line 1537, in names_to_path
    raise FieldError("Cannot resolve keyword '%s' into field. "
django.core.exceptions.FieldError: Cannot resolve keyword 'groupofrights_id' into field. Choices are: active, antiTradeUnionDiscrimination, antiTradeUnionDiscriminationAnother, antiTradeUnionDiscrimination_id, case_company_name, case_description, case_name, case_result, case_text, casecomment, casefile, casephoto, childLabor, childLabor_id, city_name, comment, company, company_id, consultationRight, consultationRightAnother, consultationRight_id, convention182, convention182_id, conversationRight, conversationRightAnother, conversationRight_id, country, country_id, createOrganizationRight, createOrganizationRightAnother, createOrganizationRight_id, createStrikeRight, createStrikeRightAnother, createStrikeRight_id, createTradeUnionRight, createTradeUnionRightAnother, createTradeUnionRight_id, date_create, date_type, date_update, discriminatiOnVariousGrounds, discriminatiOnVariousGrounds_id, discriminationInVariousAreas, discriminationInVariousAreasAnother, discriminationInVariousAreas_id, electionsRight, electionsRightAnother, electionsRight_id, end_date, exact_data, failureSystemicMeasures, failureSystemicMeasures_id, governmentCoercion, governmentCoercion_id, government_agency_name, groupOfPersons, groupOfPersons_id, groupOfRights, groupOfRights_id, id, individualinfo, intruder, intruderAnother, local_agency_name, meetingsRight, meetingsRightAnother, meetingsRight_id, police_agency_name, principleOfNonDiscrimination, principleOfNonDiscrimination_id, prohibitionOfForcedLabor, prohibitionOfForcedLabor_id, publicPolicyDiscrimination, publicPolicyDiscrimination_id, region, region_id, rights_state, rights_state_another, rights_state_id, source, source_another, source_content, source_url, start_date, tradeUnionActivityRight, tradeUnionActivityRightAnother, tradeUnionActivityRight_id, tradeUnionBuildingsRight, tradeUnionBuildingsRightAnother, tradeUnionBuildingsRight_id, tradeUnionCount, tradeUnionCount_id, tradeUnionCrime, tradeUnionCrimeAnother, tradeUnionCrime_id, tradeUnionInfo, tradeUnionInfo_id, tradeUnionRight, tradeUnionRightAnother, tradeUnionRight_id, tradeUnionSituation, tradeUnionSituation_another, tradeUnionSituation_id, trade_union_activities, trade_union_activities_another, trade_union_activities_id, tradeunion_actions, useOfForcedLabor, useOfForcedLabor_id, user, user_id, victim, victim_id, victim_situation, victim_situation_another, victim_situation_id, violation_nature, violation_nature_id, violationsUsingCompulsoryLabor, violationsUsingCompulsoryLabor_id, ñonvention135, ñonvention135Another, ñonvention135_id, ñonvention138, ñonvention138_id, ñonvention87, ñonvention87_id, ñonvention98, ñonvention98_id
ERROR django.server "POST /analytic/work/search/ HTTP/1.1" 500 161380 2021-11-02 11:18:49,426
ERROR django.request Internal Server Error: /analytic/work/search/ 2021-11-02 11:21:29,822
Traceback (most recent call last):
  File "D:\Users\ntabyldieva\Desktop\databases_v1\env\lib\site-packages\django\core\handlers\exception.py", line 47, in inner
    response = get_response(request)
  File "D:\Users\ntabyldieva\Desktop\databases_v1\env\lib\site-packages\django\core\handlers\base.py", line 181, in _get_response
    response = wrapped_callback(request, *callback_args, **callback_kwargs)
  File "D:\Users\ntabyldieva\Desktop\databases_v1\env\lib\site-packages\django\views\decorators\csrf.py", line 54, in wrapped_view
    return view_func(*args, **kwargs)
  File "D:\Users\ntabyldieva\Desktop\databases_v1\env\lib\site-packages\django\views\generic\base.py", line 70, in view
    return self.dispatch(request, *args, **kwargs)
  File "D:\Users\ntabyldieva\Desktop\databases_v1\env\lib\site-packages\rest_framework\views.py", line 509, in dispatch
    response = self.handle_exception(exc)
  File "D:\Users\ntabyldieva\Desktop\databases_v1\env\lib\site-packages\rest_framework\views.py", line 469, in handle_exception
    self.raise_uncaught_exception(exc)
  File "D:\Users\ntabyldieva\Desktop\databases_v1\env\lib\site-packages\rest_framework\views.py", line 480, in raise_uncaught_exception
    raise exc
  File "D:\Users\ntabyldieva\Desktop\databases_v1\env\lib\site-packages\rest_framework\views.py", line 506, in dispatch
    response = handler(request, *args, **kwargs)
  File "D:\Users\ntabyldieva\Desktop\databases_v1\statistica\views.py", line 110, in post
    workcases = WorkCase.objects.filter(**filters)
  File "D:\Users\ntabyldieva\Desktop\databases_v1\env\lib\site-packages\django\db\models\manager.py", line 85, in manager_method
    return getattr(self.get_queryset(), name)(*args, **kwargs)
  File "D:\Users\ntabyldieva\Desktop\databases_v1\env\lib\site-packages\django\db\models\query.py", line 941, in filter
    return self._filter_or_exclude(False, args, kwargs)
  File "D:\Users\ntabyldieva\Desktop\databases_v1\env\lib\site-packages\django\db\models\query.py", line 961, in _filter_or_exclude
    clone._filter_or_exclude_inplace(negate, args, kwargs)
  File "D:\Users\ntabyldieva\Desktop\databases_v1\env\lib\site-packages\django\db\models\query.py", line 968, in _filter_or_exclude_inplace
    self._query.add_q(Q(*args, **kwargs))
  File "D:\Users\ntabyldieva\Desktop\databases_v1\env\lib\site-packages\django\db\models\sql\query.py", line 1391, in add_q
    clause, _ = self._add_q(q_object, self.used_aliases)
  File "D:\Users\ntabyldieva\Desktop\databases_v1\env\lib\site-packages\django\db\models\sql\query.py", line 1410, in _add_q
    child_clause, needed_inner = self.build_filter(
  File "D:\Users\ntabyldieva\Desktop\databases_v1\env\lib\site-packages\django\db\models\sql\query.py", line 1284, in build_filter
    lookups, parts, reffed_expression = self.solve_lookup_type(arg)
  File "D:\Users\ntabyldieva\Desktop\databases_v1\env\lib\site-packages\django\db\models\sql\query.py", line 1110, in solve_lookup_type
    _, field, _, lookup_parts = self.names_to_path(lookup_splitted, self.get_meta())
  File "D:\Users\ntabyldieva\Desktop\databases_v1\env\lib\site-packages\django\db\models\sql\query.py", line 1537, in names_to_path
    raise FieldError("Cannot resolve keyword '%s' into field. "
django.core.exceptions.FieldError: Cannot resolve keyword 'groupofrights' into field. Choices are: active, antiTradeUnionDiscrimination, antiTradeUnionDiscriminationAnother, antiTradeUnionDiscrimination_id, case_company_name, case_description, case_name, case_result, case_text, casecomment, casefile, casephoto, childLabor, childLabor_id, city_name, comment, company, company_id, consultationRight, consultationRightAnother, consultationRight_id, convention182, convention182_id, conversationRight, conversationRightAnother, conversationRight_id, country, country_id, createOrganizationRight, createOrganizationRightAnother, createOrganizationRight_id, createStrikeRight, createStrikeRightAnother, createStrikeRight_id, createTradeUnionRight, createTradeUnionRightAnother, createTradeUnionRight_id, date_create, date_type, date_update, discriminatiOnVariousGrounds, discriminatiOnVariousGrounds_id, discriminationInVariousAreas, discriminationInVariousAreasAnother, discriminationInVariousAreas_id, electionsRight, electionsRightAnother, electionsRight_id, end_date, exact_data, failureSystemicMeasures, failureSystemicMeasures_id, governmentCoercion, governmentCoercion_id, government_agency_name, groupOfPersons, groupOfPersons_id, groupOfRights, groupOfRights_id, id, individualinfo, intruder, intruderAnother, local_agency_name, meetingsRight, meetingsRightAnother, meetingsRight_id, police_agency_name, principleOfNonDiscrimination, principleOfNonDiscrimination_id, prohibitionOfForcedLabor, prohibitionOfForcedLabor_id, publicPolicyDiscrimination, publicPolicyDiscrimination_id, region, region_id, rights_state, rights_state_another, rights_state_id, source, source_another, source_content, source_url, start_date, tradeUnionActivityRight, tradeUnionActivityRightAnother, tradeUnionActivityRight_id, tradeUnionBuildingsRight, tradeUnionBuildingsRightAnother, tradeUnionBuildingsRight_id, tradeUnionCount, tradeUnionCount_id, tradeUnionCrime, tradeUnionCrimeAnother, tradeUnionCrime_id, tradeUnionInfo, tradeUnionInfo_id, tradeUnionRight, tradeUnionRightAnother, tradeUnionRight_id, tradeUnionSituation, tradeUnionSituation_another, tradeUnionSituation_id, trade_union_activities, trade_union_activities_another, trade_union_activities_id, tradeunion_actions, useOfForcedLabor, useOfForcedLabor_id, user, user_id, victim, victim_id, victim_situation, victim_situation_another, victim_situation_id, violation_nature, violation_nature_id, violationsUsingCompulsoryLabor, violationsUsingCompulsoryLabor_id, ñonvention135, ñonvention135Another, ñonvention135_id, ñonvention138, ñonvention138_id, ñonvention87, ñonvention87_id, ñonvention98, ñonvention98_id
ERROR django.server "POST /analytic/work/search/ HTTP/1.1" 500 161603 2021-11-02 11:21:29,838
WARNING django.request Not Found: /favicon.ico 2021-11-02 11:21:34,055
WARNING django.server "GET /favicon.ico HTTP/1.1" 404 3524 2021-11-02 11:21:34,056
ERROR django.request Internal Server Error: /analytic/work/search/ 2021-11-02 11:22:20,934
Traceback (most recent call last):
  File "D:\Users\ntabyldieva\Desktop\databases_v1\env\lib\site-packages\django\core\handlers\exception.py", line 47, in inner
    response = get_response(request)
  File "D:\Users\ntabyldieva\Desktop\databases_v1\env\lib\site-packages\django\core\handlers\base.py", line 181, in _get_response
    response = wrapped_callback(request, *callback_args, **callback_kwargs)
  File "D:\Users\ntabyldieva\Desktop\databases_v1\env\lib\site-packages\django\views\decorators\csrf.py", line 54, in wrapped_view
    return view_func(*args, **kwargs)
  File "D:\Users\ntabyldieva\Desktop\databases_v1\env\lib\site-packages\django\views\generic\base.py", line 70, in view
    return self.dispatch(request, *args, **kwargs)
  File "D:\Users\ntabyldieva\Desktop\databases_v1\env\lib\site-packages\rest_framework\views.py", line 509, in dispatch
    response = self.handle_exception(exc)
  File "D:\Users\ntabyldieva\Desktop\databases_v1\env\lib\site-packages\rest_framework\views.py", line 469, in handle_exception
    self.raise_uncaught_exception(exc)
  File "D:\Users\ntabyldieva\Desktop\databases_v1\env\lib\site-packages\rest_framework\views.py", line 480, in raise_uncaught_exception
    raise exc
  File "D:\Users\ntabyldieva\Desktop\databases_v1\env\lib\site-packages\rest_framework\views.py", line 506, in dispatch
    response = handler(request, *args, **kwargs)
  File "D:\Users\ntabyldieva\Desktop\databases_v1\statistica\views.py", line 110, in post
    workcases = WorkCase.objects.filter(**filters)
  File "D:\Users\ntabyldieva\Desktop\databases_v1\env\lib\site-packages\django\db\models\manager.py", line 85, in manager_method
    return getattr(self.get_queryset(), name)(*args, **kwargs)
  File "D:\Users\ntabyldieva\Desktop\databases_v1\env\lib\site-packages\django\db\models\query.py", line 941, in filter
    return self._filter_or_exclude(False, args, kwargs)
  File "D:\Users\ntabyldieva\Desktop\databases_v1\env\lib\site-packages\django\db\models\query.py", line 961, in _filter_or_exclude
    clone._filter_or_exclude_inplace(negate, args, kwargs)
  File "D:\Users\ntabyldieva\Desktop\databases_v1\env\lib\site-packages\django\db\models\query.py", line 968, in _filter_or_exclude_inplace
    self._query.add_q(Q(*args, **kwargs))
  File "D:\Users\ntabyldieva\Desktop\databases_v1\env\lib\site-packages\django\db\models\sql\query.py", line 1391, in add_q
    clause, _ = self._add_q(q_object, self.used_aliases)
  File "D:\Users\ntabyldieva\Desktop\databases_v1\env\lib\site-packages\django\db\models\sql\query.py", line 1410, in _add_q
    child_clause, needed_inner = self.build_filter(
  File "D:\Users\ntabyldieva\Desktop\databases_v1\env\lib\site-packages\django\db\models\sql\query.py", line 1284, in build_filter
    lookups, parts, reffed_expression = self.solve_lookup_type(arg)
  File "D:\Users\ntabyldieva\Desktop\databases_v1\env\lib\site-packages\django\db\models\sql\query.py", line 1110, in solve_lookup_type
    _, field, _, lookup_parts = self.names_to_path(lookup_splitted, self.get_meta())
  File "D:\Users\ntabyldieva\Desktop\databases_v1\env\lib\site-packages\django\db\models\sql\query.py", line 1537, in names_to_path
    raise FieldError("Cannot resolve keyword '%s' into field. "
django.core.exceptions.FieldError: Cannot resolve keyword 'groupofrights' into field. Choices are: active, antiTradeUnionDiscrimination, antiTradeUnionDiscriminationAnother, antiTradeUnionDiscrimination_id, case_company_name, case_description, case_name, case_result, case_text, casecomment, casefile, casephoto, childLabor, childLabor_id, city_name, comment, company, company_id, consultationRight, consultationRightAnother, consultationRight_id, convention182, convention182_id, conversationRight, conversationRightAnother, conversationRight_id, country, country_id, createOrganizationRight, createOrganizationRightAnother, createOrganizationRight_id, createStrikeRight, createStrikeRightAnother, createStrikeRight_id, createTradeUnionRight, createTradeUnionRightAnother, createTradeUnionRight_id, date_create, date_type, date_update, discriminatiOnVariousGrounds, discriminatiOnVariousGrounds_id, discriminationInVariousAreas, discriminationInVariousAreasAnother, discriminationInVariousAreas_id, electionsRight, electionsRightAnother, electionsRight_id, end_date, exact_data, failureSystemicMeasures, failureSystemicMeasures_id, governmentCoercion, governmentCoercion_id, government_agency_name, groupOfPersons, groupOfPersons_id, groupOfRights, groupOfRights_id, id, individualinfo, intruder, intruderAnother, local_agency_name, meetingsRight, meetingsRightAnother, meetingsRight_id, police_agency_name, principleOfNonDiscrimination, principleOfNonDiscrimination_id, prohibitionOfForcedLabor, prohibitionOfForcedLabor_id, publicPolicyDiscrimination, publicPolicyDiscrimination_id, region, region_id, rights_state, rights_state_another, rights_state_id, source, source_another, source_content, source_url, start_date, tradeUnionActivityRight, tradeUnionActivityRightAnother, tradeUnionActivityRight_id, tradeUnionBuildingsRight, tradeUnionBuildingsRightAnother, tradeUnionBuildingsRight_id, tradeUnionCount, tradeUnionCount_id, tradeUnionCrime, tradeUnionCrimeAnother, tradeUnionCrime_id, tradeUnionInfo, tradeUnionInfo_id, tradeUnionRight, tradeUnionRightAnother, tradeUnionRight_id, tradeUnionSituation, tradeUnionSituation_another, tradeUnionSituation_id, trade_union_activities, trade_union_activities_another, trade_union_activities_id, tradeunion_actions, useOfForcedLabor, useOfForcedLabor_id, user, user_id, victim, victim_id, victim_situation, victim_situation_another, victim_situation_id, violation_nature, violation_nature_id, violationsUsingCompulsoryLabor, violationsUsingCompulsoryLabor_id, ñonvention135, ñonvention135Another, ñonvention135_id, ñonvention138, ñonvention138_id, ñonvention87, ñonvention87_id, ñonvention98, ñonvention98_id
ERROR django.server "POST /analytic/work/search/ HTTP/1.1" 500 161926 2021-11-02 11:22:20,950
ERROR django.request Internal Server Error: /analytic/work/search/ 2021-11-02 11:22:42,691
Traceback (most recent call last):
  File "D:\Users\ntabyldieva\Desktop\databases_v1\env\lib\site-packages\django\core\handlers\exception.py", line 47, in inner
    response = get_response(request)
  File "D:\Users\ntabyldieva\Desktop\databases_v1\env\lib\site-packages\django\core\handlers\base.py", line 181, in _get_response
    response = wrapped_callback(request, *callback_args, **callback_kwargs)
  File "D:\Users\ntabyldieva\Desktop\databases_v1\env\lib\site-packages\django\views\decorators\csrf.py", line 54, in wrapped_view
    return view_func(*args, **kwargs)
  File "D:\Users\ntabyldieva\Desktop\databases_v1\env\lib\site-packages\django\views\generic\base.py", line 70, in view
    return self.dispatch(request, *args, **kwargs)
  File "D:\Users\ntabyldieva\Desktop\databases_v1\env\lib\site-packages\rest_framework\views.py", line 509, in dispatch
    response = self.handle_exception(exc)
  File "D:\Users\ntabyldieva\Desktop\databases_v1\env\lib\site-packages\rest_framework\views.py", line 469, in handle_exception
    self.raise_uncaught_exception(exc)
  File "D:\Users\ntabyldieva\Desktop\databases_v1\env\lib\site-packages\rest_framework\views.py", line 480, in raise_uncaught_exception
    raise exc
  File "D:\Users\ntabyldieva\Desktop\databases_v1\env\lib\site-packages\rest_framework\views.py", line 506, in dispatch
    response = handler(request, *args, **kwargs)
  File "D:\Users\ntabyldieva\Desktop\databases_v1\statistica\views.py", line 110, in post
    workcases = WorkCase.objects.filter(**filters)
  File "D:\Users\ntabyldieva\Desktop\databases_v1\env\lib\site-packages\django\db\models\manager.py", line 85, in manager_method
    return getattr(self.get_queryset(), name)(*args, **kwargs)
  File "D:\Users\ntabyldieva\Desktop\databases_v1\env\lib\site-packages\django\db\models\query.py", line 941, in filter
    return self._filter_or_exclude(False, args, kwargs)
  File "D:\Users\ntabyldieva\Desktop\databases_v1\env\lib\site-packages\django\db\models\query.py", line 961, in _filter_or_exclude
    clone._filter_or_exclude_inplace(negate, args, kwargs)
  File "D:\Users\ntabyldieva\Desktop\databases_v1\env\lib\site-packages\django\db\models\query.py", line 968, in _filter_or_exclude_inplace
    self._query.add_q(Q(*args, **kwargs))
  File "D:\Users\ntabyldieva\Desktop\databases_v1\env\lib\site-packages\django\db\models\sql\query.py", line 1391, in add_q
    clause, _ = self._add_q(q_object, self.used_aliases)
  File "D:\Users\ntabyldieva\Desktop\databases_v1\env\lib\site-packages\django\db\models\sql\query.py", line 1410, in _add_q
    child_clause, needed_inner = self.build_filter(
  File "D:\Users\ntabyldieva\Desktop\databases_v1\env\lib\site-packages\django\db\models\sql\query.py", line 1284, in build_filter
    lookups, parts, reffed_expression = self.solve_lookup_type(arg)
  File "D:\Users\ntabyldieva\Desktop\databases_v1\env\lib\site-packages\django\db\models\sql\query.py", line 1110, in solve_lookup_type
    _, field, _, lookup_parts = self.names_to_path(lookup_splitted, self.get_meta())
  File "D:\Users\ntabyldieva\Desktop\databases_v1\env\lib\site-packages\django\db\models\sql\query.py", line 1537, in names_to_path
    raise FieldError("Cannot resolve keyword '%s' into field. "
django.core.exceptions.FieldError: Cannot resolve keyword 'groupofrights' into field. Choices are: active, antiTradeUnionDiscrimination, antiTradeUnionDiscriminationAnother, antiTradeUnionDiscrimination_id, case_company_name, case_description, case_name, case_result, case_text, casecomment, casefile, casephoto, childLabor, childLabor_id, city_name, comment, company, company_id, consultationRight, consultationRightAnother, consultationRight_id, convention182, convention182_id, conversationRight, conversationRightAnother, conversationRight_id, country, country_id, createOrganizationRight, createOrganizationRightAnother, createOrganizationRight_id, createStrikeRight, createStrikeRightAnother, createStrikeRight_id, createTradeUnionRight, createTradeUnionRightAnother, createTradeUnionRight_id, date_create, date_type, date_update, discriminatiOnVariousGrounds, discriminatiOnVariousGrounds_id, discriminationInVariousAreas, discriminationInVariousAreasAnother, discriminationInVariousAreas_id, electionsRight, electionsRightAnother, electionsRight_id, end_date, exact_data, failureSystemicMeasures, failureSystemicMeasures_id, governmentCoercion, governmentCoercion_id, government_agency_name, groupOfPersons, groupOfPersons_id, groupOfRights, groupOfRights_id, id, individualinfo, intruder, intruderAnother, local_agency_name, meetingsRight, meetingsRightAnother, meetingsRight_id, police_agency_name, principleOfNonDiscrimination, principleOfNonDiscrimination_id, prohibitionOfForcedLabor, prohibitionOfForcedLabor_id, publicPolicyDiscrimination, publicPolicyDiscrimination_id, region, region_id, rights_state, rights_state_another, rights_state_id, source, source_another, source_content, source_url, start_date, tradeUnionActivityRight, tradeUnionActivityRightAnother, tradeUnionActivityRight_id, tradeUnionBuildingsRight, tradeUnionBuildingsRightAnother, tradeUnionBuildingsRight_id, tradeUnionCount, tradeUnionCount_id, tradeUnionCrime, tradeUnionCrimeAnother, tradeUnionCrime_id, tradeUnionInfo, tradeUnionInfo_id, tradeUnionRight, tradeUnionRightAnother, tradeUnionRight_id, tradeUnionSituation, tradeUnionSituation_another, tradeUnionSituation_id, trade_union_activities, trade_union_activities_another, trade_union_activities_id, tradeunion_actions, useOfForcedLabor, useOfForcedLabor_id, user, user_id, victim, victim_id, victim_situation, victim_situation_another, victim_situation_id, violation_nature, violation_nature_id, violationsUsingCompulsoryLabor, violationsUsingCompulsoryLabor_id, ñonvention135, ñonvention135Another, ñonvention135_id, ñonvention138, ñonvention138_id, ñonvention87, ñonvention87_id, ñonvention98, ñonvention98_id
ERROR django.server "POST /analytic/work/search/ HTTP/1.1" 500 161926 2021-11-02 11:22:42,691
WARNING django.request Not Found: /favicon.ico 2021-11-02 11:23:31,261
WARNING django.server "GET /favicon.ico HTTP/1.1" 404 3524 2021-11-02 11:23:31,261
ERROR django.request Internal Server Error: /analytic/work/search/ 2021-11-02 11:23:39,122
Traceback (most recent call last):
  File "D:\Users\ntabyldieva\Desktop\databases_v1\env\lib\site-packages\django\core\handlers\exception.py", line 47, in inner
    response = get_response(request)
  File "D:\Users\ntabyldieva\Desktop\databases_v1\env\lib\site-packages\django\core\handlers\base.py", line 181, in _get_response
    response = wrapped_callback(request, *callback_args, **callback_kwargs)
  File "D:\Users\ntabyldieva\Desktop\databases_v1\env\lib\site-packages\django\views\decorators\csrf.py", line 54, in wrapped_view
    return view_func(*args, **kwargs)
  File "D:\Users\ntabyldieva\Desktop\databases_v1\env\lib\site-packages\django\views\generic\base.py", line 70, in view
    return self.dispatch(request, *args, **kwargs)
  File "D:\Users\ntabyldieva\Desktop\databases_v1\env\lib\site-packages\rest_framework\views.py", line 509, in dispatch
    response = self.handle_exception(exc)
  File "D:\Users\ntabyldieva\Desktop\databases_v1\env\lib\site-packages\rest_framework\views.py", line 469, in handle_exception
    self.raise_uncaught_exception(exc)
  File "D:\Users\ntabyldieva\Desktop\databases_v1\env\lib\site-packages\rest_framework\views.py", line 480, in raise_uncaught_exception
    raise exc
  File "D:\Users\ntabyldieva\Desktop\databases_v1\env\lib\site-packages\rest_framework\views.py", line 506, in dispatch
    response = handler(request, *args, **kwargs)
  File "D:\Users\ntabyldieva\Desktop\databases_v1\statistica\views.py", line 112, in post
    workcases = WorkCase.objects.filter(**filters)
  File "D:\Users\ntabyldieva\Desktop\databases_v1\env\lib\site-packages\django\db\models\manager.py", line 85, in manager_method
    return getattr(self.get_queryset(), name)(*args, **kwargs)
  File "D:\Users\ntabyldieva\Desktop\databases_v1\env\lib\site-packages\django\db\models\query.py", line 941, in filter
    return self._filter_or_exclude(False, args, kwargs)
  File "D:\Users\ntabyldieva\Desktop\databases_v1\env\lib\site-packages\django\db\models\query.py", line 961, in _filter_or_exclude
    clone._filter_or_exclude_inplace(negate, args, kwargs)
  File "D:\Users\ntabyldieva\Desktop\databases_v1\env\lib\site-packages\django\db\models\query.py", line 968, in _filter_or_exclude_inplace
    self._query.add_q(Q(*args, **kwargs))
  File "D:\Users\ntabyldieva\Desktop\databases_v1\env\lib\site-packages\django\db\models\sql\query.py", line 1391, in add_q
    clause, _ = self._add_q(q_object, self.used_aliases)
  File "D:\Users\ntabyldieva\Desktop\databases_v1\env\lib\site-packages\django\db\models\sql\query.py", line 1410, in _add_q
    child_clause, needed_inner = self.build_filter(
  File "D:\Users\ntabyldieva\Desktop\databases_v1\env\lib\site-packages\django\db\models\sql\query.py", line 1284, in build_filter
    lookups, parts, reffed_expression = self.solve_lookup_type(arg)
  File "D:\Users\ntabyldieva\Desktop\databases_v1\env\lib\site-packages\django\db\models\sql\query.py", line 1110, in solve_lookup_type
    _, field, _, lookup_parts = self.names_to_path(lookup_splitted, self.get_meta())
  File "D:\Users\ntabyldieva\Desktop\databases_v1\env\lib\site-packages\django\db\models\sql\query.py", line 1537, in names_to_path
    raise FieldError("Cannot resolve keyword '%s' into field. "
django.core.exceptions.FieldError: Cannot resolve keyword 'groupofrights' into field. Choices are: active, antiTradeUnionDiscrimination, antiTradeUnionDiscriminationAnother, antiTradeUnionDiscrimination_id, case_company_name, case_description, case_name, case_result, case_text, casecomment, casefile, casephoto, childLabor, childLabor_id, city_name, comment, company, company_id, consultationRight, consultationRightAnother, consultationRight_id, convention182, convention182_id, conversationRight, conversationRightAnother, conversationRight_id, country, country_id, createOrganizationRight, createOrganizationRightAnother, createOrganizationRight_id, createStrikeRight, createStrikeRightAnother, createStrikeRight_id, createTradeUnionRight, createTradeUnionRightAnother, createTradeUnionRight_id, date_create, date_type, date_update, discriminatiOnVariousGrounds, discriminatiOnVariousGrounds_id, discriminationInVariousAreas, discriminationInVariousAreasAnother, discriminationInVariousAreas_id, electionsRight, electionsRightAnother, electionsRight_id, end_date, exact_data, failureSystemicMeasures, failureSystemicMeasures_id, governmentCoercion, governmentCoercion_id, government_agency_name, groupOfPersons, groupOfPersons_id, groupOfRights, groupOfRights_id, id, individualinfo, intruder, intruderAnother, local_agency_name, meetingsRight, meetingsRightAnother, meetingsRight_id, police_agency_name, principleOfNonDiscrimination, principleOfNonDiscrimination_id, prohibitionOfForcedLabor, prohibitionOfForcedLabor_id, publicPolicyDiscrimination, publicPolicyDiscrimination_id, region, region_id, rights_state, rights_state_another, rights_state_id, source, source_another, source_content, source_url, start_date, tradeUnionActivityRight, tradeUnionActivityRightAnother, tradeUnionActivityRight_id, tradeUnionBuildingsRight, tradeUnionBuildingsRightAnother, tradeUnionBuildingsRight_id, tradeUnionCount, tradeUnionCount_id, tradeUnionCrime, tradeUnionCrimeAnother, tradeUnionCrime_id, tradeUnionInfo, tradeUnionInfo_id, tradeUnionRight, tradeUnionRightAnother, tradeUnionRight_id, tradeUnionSituation, tradeUnionSituation_another, tradeUnionSituation_id, trade_union_activities, trade_union_activities_another, trade_union_activities_id, tradeunion_actions, useOfForcedLabor, useOfForcedLabor_id, user, user_id, victim, victim_id, victim_situation, victim_situation_another, victim_situation_id, violation_nature, violation_nature_id, violationsUsingCompulsoryLabor, violationsUsingCompulsoryLabor_id, ñonvention135, ñonvention135Another, ñonvention135_id, ñonvention138, ñonvention138_id, ñonvention87, ñonvention87_id, ñonvention98, ñonvention98_id
ERROR django.server "POST /analytic/work/search/ HTTP/1.1" 500 161557 2021-11-02 11:23:39,138
WARNING django.request Not Found: /favicon.ico 2021-11-02 11:25:06,889
WARNING django.server "GET /favicon.ico HTTP/1.1" 404 3524 2021-11-02 11:25:06,890
WARNING django.request Not Found: /favicon.ico 2021-11-02 11:25:07,546
WARNING django.server "GET /favicon.ico HTTP/1.1" 404 3524 2021-11-02 11:25:07,547
ERROR django.request Internal Server Error: /analytic/work/search/ 2021-11-02 11:25:15,588
Traceback (most recent call last):
  File "D:\Users\ntabyldieva\Desktop\databases_v1\env\lib\site-packages\django\core\handlers\exception.py", line 47, in inner
    response = get_response(request)
  File "D:\Users\ntabyldieva\Desktop\databases_v1\env\lib\site-packages\django\core\handlers\base.py", line 181, in _get_response
    response = wrapped_callback(request, *callback_args, **callback_kwargs)
  File "D:\Users\ntabyldieva\Desktop\databases_v1\env\lib\site-packages\django\views\decorators\csrf.py", line 54, in wrapped_view
    return view_func(*args, **kwargs)
  File "D:\Users\ntabyldieva\Desktop\databases_v1\env\lib\site-packages\django\views\generic\base.py", line 70, in view
    return self.dispatch(request, *args, **kwargs)
  File "D:\Users\ntabyldieva\Desktop\databases_v1\env\lib\site-packages\rest_framework\views.py", line 509, in dispatch
    response = self.handle_exception(exc)
  File "D:\Users\ntabyldieva\Desktop\databases_v1\env\lib\site-packages\rest_framework\views.py", line 469, in handle_exception
    self.raise_uncaught_exception(exc)
  File "D:\Users\ntabyldieva\Desktop\databases_v1\env\lib\site-packages\rest_framework\views.py", line 480, in raise_uncaught_exception
    raise exc
  File "D:\Users\ntabyldieva\Desktop\databases_v1\env\lib\site-packages\rest_framework\views.py", line 506, in dispatch
    response = handler(request, *args, **kwargs)
  File "D:\Users\ntabyldieva\Desktop\databases_v1\statistica\views.py", line 112, in post
    workcases = WorkCase.objects.filter(**filters)
  File "D:\Users\ntabyldieva\Desktop\databases_v1\env\lib\site-packages\django\db\models\manager.py", line 85, in manager_method
    return getattr(self.get_queryset(), name)(*args, **kwargs)
  File "D:\Users\ntabyldieva\Desktop\databases_v1\env\lib\site-packages\django\db\models\query.py", line 941, in filter
    return self._filter_or_exclude(False, args, kwargs)
  File "D:\Users\ntabyldieva\Desktop\databases_v1\env\lib\site-packages\django\db\models\query.py", line 961, in _filter_or_exclude
    clone._filter_or_exclude_inplace(negate, args, kwargs)
  File "D:\Users\ntabyldieva\Desktop\databases_v1\env\lib\site-packages\django\db\models\query.py", line 968, in _filter_or_exclude_inplace
    self._query.add_q(Q(*args, **kwargs))
  File "D:\Users\ntabyldieva\Desktop\databases_v1\env\lib\site-packages\django\db\models\sql\query.py", line 1391, in add_q
    clause, _ = self._add_q(q_object, self.used_aliases)
  File "D:\Users\ntabyldieva\Desktop\databases_v1\env\lib\site-packages\django\db\models\sql\query.py", line 1410, in _add_q
    child_clause, needed_inner = self.build_filter(
  File "D:\Users\ntabyldieva\Desktop\databases_v1\env\lib\site-packages\django\db\models\sql\query.py", line 1284, in build_filter
    lookups, parts, reffed_expression = self.solve_lookup_type(arg)
  File "D:\Users\ntabyldieva\Desktop\databases_v1\env\lib\site-packages\django\db\models\sql\query.py", line 1110, in solve_lookup_type
    _, field, _, lookup_parts = self.names_to_path(lookup_splitted, self.get_meta())
  File "D:\Users\ntabyldieva\Desktop\databases_v1\env\lib\site-packages\django\db\models\sql\query.py", line 1537, in names_to_path
    raise FieldError("Cannot resolve keyword '%s' into field. "
django.core.exceptions.FieldError: Cannot resolve keyword 'groupofrights' into field. Choices are: active, antiTradeUnionDiscrimination, antiTradeUnionDiscriminationAnother, antiTradeUnionDiscrimination_id, case_company_name, case_description, case_name, case_result, case_text, casecomment, casefile, casephoto, childLabor, childLabor_id, city_name, comment, company, company_id, consultationRight, consultationRightAnother, consultationRight_id, convention182, convention182_id, conversationRight, conversationRightAnother, conversationRight_id, country, country_id, createOrganizationRight, createOrganizationRightAnother, createOrganizationRight_id, createStrikeRight, createStrikeRightAnother, createStrikeRight_id, createTradeUnionRight, createTradeUnionRightAnother, createTradeUnionRight_id, date_create, date_type, date_update, discriminatiOnVariousGrounds, discriminatiOnVariousGrounds_id, discriminationInVariousAreas, discriminationInVariousAreasAnother, discriminationInVariousAreas_id, electionsRight, electionsRightAnother, electionsRight_id, end_date, exact_data, failureSystemicMeasures, failureSystemicMeasures_id, governmentCoercion, governmentCoercion_id, government_agency_name, groupOfPersons, groupOfPersons_id, groupOfRights, groupOfRights_id, id, individualinfo, intruder, intruderAnother, local_agency_name, meetingsRight, meetingsRightAnother, meetingsRight_id, police_agency_name, principleOfNonDiscrimination, principleOfNonDiscrimination_id, prohibitionOfForcedLabor, prohibitionOfForcedLabor_id, publicPolicyDiscrimination, publicPolicyDiscrimination_id, region, region_id, rights_state, rights_state_another, rights_state_id, source, source_another, source_content, source_url, start_date, tradeUnionActivityRight, tradeUnionActivityRightAnother, tradeUnionActivityRight_id, tradeUnionBuildingsRight, tradeUnionBuildingsRightAnother, tradeUnionBuildingsRight_id, tradeUnionCount, tradeUnionCount_id, tradeUnionCrime, tradeUnionCrimeAnother, tradeUnionCrime_id, tradeUnionInfo, tradeUnionInfo_id, tradeUnionRight, tradeUnionRightAnother, tradeUnionRight_id, tradeUnionSituation, tradeUnionSituation_another, tradeUnionSituation_id, trade_union_activities, trade_union_activities_another, trade_union_activities_id, tradeunion_actions, useOfForcedLabor, useOfForcedLabor_id, user, user_id, victim, victim_id, victim_situation, victim_situation_another, victim_situation_id, violation_nature, violation_nature_id, violationsUsingCompulsoryLabor, violationsUsingCompulsoryLabor_id, ñonvention135, ñonvention135Another, ñonvention135_id, ñonvention138, ñonvention138_id, ñonvention87, ñonvention87_id, ñonvention98, ñonvention98_id
ERROR django.server "POST /analytic/work/search/ HTTP/1.1" 500 161557 2021-11-02 11:25:15,590
WARNING django.request Not Found: /favicon.ico 2021-11-02 11:27:10,160
WARNING django.server "GET /favicon.ico HTTP/1.1" 404 3524 2021-11-02 11:27:10,160
ERROR django.request Internal Server Error: /analytic/work/search/ 2021-11-02 11:27:16,184
Traceback (most recent call last):
  File "D:\Users\ntabyldieva\Desktop\databases_v1\env\lib\site-packages\django\core\handlers\exception.py", line 47, in inner
    response = get_response(request)
  File "D:\Users\ntabyldieva\Desktop\databases_v1\env\lib\site-packages\django\core\handlers\base.py", line 181, in _get_response
    response = wrapped_callback(request, *callback_args, **callback_kwargs)
  File "D:\Users\ntabyldieva\Desktop\databases_v1\env\lib\site-packages\django\views\decorators\csrf.py", line 54, in wrapped_view
    return view_func(*args, **kwargs)
  File "D:\Users\ntabyldieva\Desktop\databases_v1\env\lib\site-packages\django\views\generic\base.py", line 70, in view
    return self.dispatch(request, *args, **kwargs)
  File "D:\Users\ntabyldieva\Desktop\databases_v1\env\lib\site-packages\rest_framework\views.py", line 509, in dispatch
    response = self.handle_exception(exc)
  File "D:\Users\ntabyldieva\Desktop\databases_v1\env\lib\site-packages\rest_framework\views.py", line 469, in handle_exception
    self.raise_uncaught_exception(exc)
  File "D:\Users\ntabyldieva\Desktop\databases_v1\env\lib\site-packages\rest_framework\views.py", line 480, in raise_uncaught_exception
    raise exc
  File "D:\Users\ntabyldieva\Desktop\databases_v1\env\lib\site-packages\rest_framework\views.py", line 506, in dispatch
    response = handler(request, *args, **kwargs)
  File "D:\Users\ntabyldieva\Desktop\databases_v1\statistica\views.py", line 112, in post
    workcases = WorkCase.objects.filter(**filters)
  File "D:\Users\ntabyldieva\Desktop\databases_v1\env\lib\site-packages\django\db\models\manager.py", line 85, in manager_method
    return getattr(self.get_queryset(), name)(*args, **kwargs)
  File "D:\Users\ntabyldieva\Desktop\databases_v1\env\lib\site-packages\django\db\models\query.py", line 941, in filter
    return self._filter_or_exclude(False, args, kwargs)
  File "D:\Users\ntabyldieva\Desktop\databases_v1\env\lib\site-packages\django\db\models\query.py", line 961, in _filter_or_exclude
    clone._filter_or_exclude_inplace(negate, args, kwargs)
  File "D:\Users\ntabyldieva\Desktop\databases_v1\env\lib\site-packages\django\db\models\query.py", line 968, in _filter_or_exclude_inplace
    self._query.add_q(Q(*args, **kwargs))
  File "D:\Users\ntabyldieva\Desktop\databases_v1\env\lib\site-packages\django\db\models\sql\query.py", line 1391, in add_q
    clause, _ = self._add_q(q_object, self.used_aliases)
  File "D:\Users\ntabyldieva\Desktop\databases_v1\env\lib\site-packages\django\db\models\sql\query.py", line 1410, in _add_q
    child_clause, needed_inner = self.build_filter(
  File "D:\Users\ntabyldieva\Desktop\databases_v1\env\lib\site-packages\django\db\models\sql\query.py", line 1284, in build_filter
    lookups, parts, reffed_expression = self.solve_lookup_type(arg)
  File "D:\Users\ntabyldieva\Desktop\databases_v1\env\lib\site-packages\django\db\models\sql\query.py", line 1110, in solve_lookup_type
    _, field, _, lookup_parts = self.names_to_path(lookup_splitted, self.get_meta())
  File "D:\Users\ntabyldieva\Desktop\databases_v1\env\lib\site-packages\django\db\models\sql\query.py", line 1537, in names_to_path
    raise FieldError("Cannot resolve keyword '%s' into field. "
django.core.exceptions.FieldError: Cannot resolve keyword 'groupofrights' into field. Choices are: active, antiTradeUnionDiscrimination, antiTradeUnionDiscriminationAnother, antiTradeUnionDiscrimination_id, case_company_name, case_description, case_name, case_result, case_text, casecomment, casefile, casephoto, childLabor, childLabor_id, city_name, comment, company, company_id, consultationRight, consultationRightAnother, consultationRight_id, convention182, convention182_id, conversationRight, conversationRightAnother, conversationRight_id, country, country_id, createOrganizationRight, createOrganizationRightAnother, createOrganizationRight_id, createStrikeRight, createStrikeRightAnother, createStrikeRight_id, createTradeUnionRight, createTradeUnionRightAnother, createTradeUnionRight_id, date_create, date_type, date_update, discriminatiOnVariousGrounds, discriminatiOnVariousGrounds_id, discriminationInVariousAreas, discriminationInVariousAreasAnother, discriminationInVariousAreas_id, electionsRight, electionsRightAnother, electionsRight_id, end_date, exact_data, failureSystemicMeasures, failureSystemicMeasures_id, governmentCoercion, governmentCoercion_id, government_agency_name, groupOfPersons, groupOfPersons_id, groupOfRights, groupOfRights_id, id, individualinfo, intruder, intruderAnother, local_agency_name, meetingsRight, meetingsRightAnother, meetingsRight_id, police_agency_name, principleOfNonDiscrimination, principleOfNonDiscrimination_id, prohibitionOfForcedLabor, prohibitionOfForcedLabor_id, publicPolicyDiscrimination, publicPolicyDiscrimination_id, region, region_id, rights_state, rights_state_another, rights_state_id, source, source_another, source_content, source_url, start_date, tradeUnionActivityRight, tradeUnionActivityRightAnother, tradeUnionActivityRight_id, tradeUnionBuildingsRight, tradeUnionBuildingsRightAnother, tradeUnionBuildingsRight_id, tradeUnionCount, tradeUnionCount_id, tradeUnionCrime, tradeUnionCrimeAnother, tradeUnionCrime_id, tradeUnionInfo, tradeUnionInfo_id, tradeUnionRight, tradeUnionRightAnother, tradeUnionRight_id, tradeUnionSituation, tradeUnionSituation_another, tradeUnionSituation_id, trade_union_activities, trade_union_activities_another, trade_union_activities_id, tradeunion_actions, useOfForcedLabor, useOfForcedLabor_id, user, user_id, victim, victim_id, victim_situation, victim_situation_another, victim_situation_id, violation_nature, violation_nature_id, violationsUsingCompulsoryLabor, violationsUsingCompulsoryLabor_id, ñonvention135, ñonvention135Another, ñonvention135_id, ñonvention138, ñonvention138_id, ñonvention87, ñonvention87_id, ñonvention98, ñonvention98_id
ERROR django.server "POST /analytic/work/search/ HTTP/1.1" 500 161557 2021-11-02 11:27:16,184
WARNING django.request Not Found: /favicon.ico 2021-11-02 11:28:11,045
WARNING django.server "GET /favicon.ico HTTP/1.1" 404 3524 2021-11-02 11:28:11,046
WARNING django.request Not Found: /favicon.ico 2021-11-02 11:28:11,847
WARNING django.server "GET /favicon.ico HTTP/1.1" 404 3524 2021-11-02 11:28:11,847
WARNING django.request Not Found: /favicon.ico 2021-11-02 11:28:12,268
WARNING django.server "GET /favicon.ico HTTP/1.1" 404 3524 2021-11-02 11:28:12,269
WARNING django.request Not Found: /favicon.ico 2021-11-02 11:29:48,341
WARNING django.server "GET /favicon.ico HTTP/1.1" 404 3524 2021-11-02 11:29:48,342
WARNING django.request Not Found: /favicon.ico 2021-11-02 11:29:49,366
WARNING django.server "GET /favicon.ico HTTP/1.1" 404 3524 2021-11-02 11:29:49,367
ERROR django.request Internal Server Error: /analytic/work/search/ 2021-11-02 11:30:23,934
Traceback (most recent call last):
  File "D:\Users\ntabyldieva\Desktop\databases_v1\env\lib\site-packages\django\core\handlers\exception.py", line 47, in inner
    response = get_response(request)
  File "D:\Users\ntabyldieva\Desktop\databases_v1\env\lib\site-packages\django\core\handlers\base.py", line 181, in _get_response
    response = wrapped_callback(request, *callback_args, **callback_kwargs)
  File "D:\Users\ntabyldieva\Desktop\databases_v1\env\lib\site-packages\django\views\decorators\csrf.py", line 54, in wrapped_view
    return view_func(*args, **kwargs)
  File "D:\Users\ntabyldieva\Desktop\databases_v1\env\lib\site-packages\django\views\generic\base.py", line 70, in view
    return self.dispatch(request, *args, **kwargs)
  File "D:\Users\ntabyldieva\Desktop\databases_v1\env\lib\site-packages\rest_framework\views.py", line 509, in dispatch
    response = self.handle_exception(exc)
  File "D:\Users\ntabyldieva\Desktop\databases_v1\env\lib\site-packages\rest_framework\views.py", line 469, in handle_exception
    self.raise_uncaught_exception(exc)
  File "D:\Users\ntabyldieva\Desktop\databases_v1\env\lib\site-packages\rest_framework\views.py", line 480, in raise_uncaught_exception
    raise exc
  File "D:\Users\ntabyldieva\Desktop\databases_v1\env\lib\site-packages\rest_framework\views.py", line 506, in dispatch
    response = handler(request, *args, **kwargs)
  File "D:\Users\ntabyldieva\Desktop\databases_v1\statistica\views.py", line 112, in post
    workcases = WorkCase.objects.filter(**filters)
  File "D:\Users\ntabyldieva\Desktop\databases_v1\env\lib\site-packages\django\db\models\manager.py", line 85, in manager_method
    return getattr(self.get_queryset(), name)(*args, **kwargs)
  File "D:\Users\ntabyldieva\Desktop\databases_v1\env\lib\site-packages\django\db\models\query.py", line 941, in filter
    return self._filter_or_exclude(False, args, kwargs)
  File "D:\Users\ntabyldieva\Desktop\databases_v1\env\lib\site-packages\django\db\models\query.py", line 961, in _filter_or_exclude
    clone._filter_or_exclude_inplace(negate, args, kwargs)
  File "D:\Users\ntabyldieva\Desktop\databases_v1\env\lib\site-packages\django\db\models\query.py", line 968, in _filter_or_exclude_inplace
    self._query.add_q(Q(*args, **kwargs))
  File "D:\Users\ntabyldieva\Desktop\databases_v1\env\lib\site-packages\django\db\models\sql\query.py", line 1391, in add_q
    clause, _ = self._add_q(q_object, self.used_aliases)
  File "D:\Users\ntabyldieva\Desktop\databases_v1\env\lib\site-packages\django\db\models\sql\query.py", line 1410, in _add_q
    child_clause, needed_inner = self.build_filter(
  File "D:\Users\ntabyldieva\Desktop\databases_v1\env\lib\site-packages\django\db\models\sql\query.py", line 1284, in build_filter
    lookups, parts, reffed_expression = self.solve_lookup_type(arg)
  File "D:\Users\ntabyldieva\Desktop\databases_v1\env\lib\site-packages\django\db\models\sql\query.py", line 1110, in solve_lookup_type
    _, field, _, lookup_parts = self.names_to_path(lookup_splitted, self.get_meta())
  File "D:\Users\ntabyldieva\Desktop\databases_v1\env\lib\site-packages\django\db\models\sql\query.py", line 1537, in names_to_path
    raise FieldError("Cannot resolve keyword '%s' into field. "
django.core.exceptions.FieldError: Cannot resolve keyword 'groupofrights' into field. Choices are: active, antiTradeUnionDiscrimination, antiTradeUnionDiscriminationAnother, antiTradeUnionDiscrimination_id, case_company_name, case_description, case_name, case_result, case_text, casecomment, casefile, casephoto, childLabor, childLabor_id, city_name, comment, company, company_id, consultationRight, consultationRightAnother, consultationRight_id, convention182, convention182_id, conversationRight, conversationRightAnother, conversationRight_id, country, country_id, createOrganizationRight, createOrganizationRightAnother, createOrganizationRight_id, createStrikeRight, createStrikeRightAnother, createStrikeRight_id, createTradeUnionRight, createTradeUnionRightAnother, createTradeUnionRight_id, date_create, date_type, date_update, discriminatiOnVariousGrounds, discriminatiOnVariousGrounds_id, discriminationInVariousAreas, discriminationInVariousAreasAnother, discriminationInVariousAreas_id, electionsRight, electionsRightAnother, electionsRight_id, end_date, exact_data, failureSystemicMeasures, failureSystemicMeasures_id, governmentCoercion, governmentCoercion_id, government_agency_name, groupOfPersons, groupOfPersons_id, groupOfRights, groupOfRights_id, id, individualinfo, intruder, intruderAnother, local_agency_name, meetingsRight, meetingsRightAnother, meetingsRight_id, police_agency_name, principleOfNonDiscrimination, principleOfNonDiscrimination_id, prohibitionOfForcedLabor, prohibitionOfForcedLabor_id, publicPolicyDiscrimination, publicPolicyDiscrimination_id, region, region_id, rights_state, rights_state_another, rights_state_id, source, source_another, source_content, source_url, start_date, tradeUnionActivityRight, tradeUnionActivityRightAnother, tradeUnionActivityRight_id, tradeUnionBuildingsRight, tradeUnionBuildingsRightAnother, tradeUnionBuildingsRight_id, tradeUnionCount, tradeUnionCount_id, tradeUnionCrime, tradeUnionCrimeAnother, tradeUnionCrime_id, tradeUnionInfo, tradeUnionInfo_id, tradeUnionRight, tradeUnionRightAnother, tradeUnionRight_id, tradeUnionSituation, tradeUnionSituation_another, tradeUnionSituation_id, trade_union_activities, trade_union_activities_another, trade_union_activities_id, tradeunion_actions, useOfForcedLabor, useOfForcedLabor_id, user, user_id, victim, victim_id, victim_situation, victim_situation_another, victim_situation_id, violation_nature, violation_nature_id, violationsUsingCompulsoryLabor, violationsUsingCompulsoryLabor_id, ñonvention135, ñonvention135Another, ñonvention135_id, ñonvention138, ñonvention138_id, ñonvention87, ñonvention87_id, ñonvention98, ñonvention98_id
ERROR django.server "POST /analytic/work/search/ HTTP/1.1" 500 161557 2021-11-02 11:30:23,934
WARNING django.request Not Found: /favicon.ico 2021-11-02 11:31:39,385
WARNING django.server "GET /favicon.ico HTTP/1.1" 404 3524 2021-11-02 11:31:39,385
ERROR django.request Internal Server Error: /analytic/work/search/ 2021-11-02 11:31:47,819
Traceback (most recent call last):
  File "D:\Users\ntabyldieva\Desktop\databases_v1\env\lib\site-packages\django\core\handlers\exception.py", line 47, in inner
    response = get_response(request)
  File "D:\Users\ntabyldieva\Desktop\databases_v1\env\lib\site-packages\django\core\handlers\base.py", line 181, in _get_response
    response = wrapped_callback(request, *callback_args, **callback_kwargs)
  File "D:\Users\ntabyldieva\Desktop\databases_v1\env\lib\site-packages\django\views\decorators\csrf.py", line 54, in wrapped_view
    return view_func(*args, **kwargs)
  File "D:\Users\ntabyldieva\Desktop\databases_v1\env\lib\site-packages\django\views\generic\base.py", line 70, in view
    return self.dispatch(request, *args, **kwargs)
  File "D:\Users\ntabyldieva\Desktop\databases_v1\env\lib\site-packages\rest_framework\views.py", line 509, in dispatch
    response = self.handle_exception(exc)
  File "D:\Users\ntabyldieva\Desktop\databases_v1\env\lib\site-packages\rest_framework\views.py", line 469, in handle_exception
    self.raise_uncaught_exception(exc)
  File "D:\Users\ntabyldieva\Desktop\databases_v1\env\lib\site-packages\rest_framework\views.py", line 480, in raise_uncaught_exception
    raise exc
  File "D:\Users\ntabyldieva\Desktop\databases_v1\env\lib\site-packages\rest_framework\views.py", line 506, in dispatch
    response = handler(request, *args, **kwargs)
  File "D:\Users\ntabyldieva\Desktop\databases_v1\statistica\views.py", line 112, in post
    workcases = WorkCase.objects.filter(**filters)
  File "D:\Users\ntabyldieva\Desktop\databases_v1\env\lib\site-packages\django\db\models\manager.py", line 85, in manager_method
    return getattr(self.get_queryset(), name)(*args, **kwargs)
  File "D:\Users\ntabyldieva\Desktop\databases_v1\env\lib\site-packages\django\db\models\query.py", line 941, in filter
    return self._filter_or_exclude(False, args, kwargs)
  File "D:\Users\ntabyldieva\Desktop\databases_v1\env\lib\site-packages\django\db\models\query.py", line 961, in _filter_or_exclude
    clone._filter_or_exclude_inplace(negate, args, kwargs)
  File "D:\Users\ntabyldieva\Desktop\databases_v1\env\lib\site-packages\django\db\models\query.py", line 968, in _filter_or_exclude_inplace
    self._query.add_q(Q(*args, **kwargs))
  File "D:\Users\ntabyldieva\Desktop\databases_v1\env\lib\site-packages\django\db\models\sql\query.py", line 1391, in add_q
    clause, _ = self._add_q(q_object, self.used_aliases)
  File "D:\Users\ntabyldieva\Desktop\databases_v1\env\lib\site-packages\django\db\models\sql\query.py", line 1410, in _add_q
    child_clause, needed_inner = self.build_filter(
  File "D:\Users\ntabyldieva\Desktop\databases_v1\env\lib\site-packages\django\db\models\sql\query.py", line 1284, in build_filter
    lookups, parts, reffed_expression = self.solve_lookup_type(arg)
  File "D:\Users\ntabyldieva\Desktop\databases_v1\env\lib\site-packages\django\db\models\sql\query.py", line 1110, in solve_lookup_type
    _, field, _, lookup_parts = self.names_to_path(lookup_splitted, self.get_meta())
  File "D:\Users\ntabyldieva\Desktop\databases_v1\env\lib\site-packages\django\db\models\sql\query.py", line 1537, in names_to_path
    raise FieldError("Cannot resolve keyword '%s' into field. "
django.core.exceptions.FieldError: Cannot resolve keyword 'groupofrights' into field. Choices are: active, antiTradeUnionDiscrimination, antiTradeUnionDiscriminationAnother, antiTradeUnionDiscrimination_id, case_company_name, case_description, case_name, case_result, case_text, casecomment, casefile, casephoto, childLabor, childLabor_id, city_name, comment, company, company_id, consultationRight, consultationRightAnother, consultationRight_id, convention182, convention182_id, conversationRight, conversationRightAnother, conversationRight_id, country, country_id, createOrganizationRight, createOrganizationRightAnother, createOrganizationRight_id, createStrikeRight, createStrikeRightAnother, createStrikeRight_id, createTradeUnionRight, createTradeUnionRightAnother, createTradeUnionRight_id, date_create, date_type, date_update, discriminatiOnVariousGrounds, discriminatiOnVariousGrounds_id, discriminationInVariousAreas, discriminationInVariousAreasAnother, discriminationInVariousAreas_id, electionsRight, electionsRightAnother, electionsRight_id, end_date, exact_data, failureSystemicMeasures, failureSystemicMeasures_id, governmentCoercion, governmentCoercion_id, government_agency_name, groupOfPersons, groupOfPersons_id, groupOfRights, groupOfRights_id, id, individualinfo, intruder, intruderAnother, local_agency_name, meetingsRight, meetingsRightAnother, meetingsRight_id, police_agency_name, principleOfNonDiscrimination, principleOfNonDiscrimination_id, prohibitionOfForcedLabor, prohibitionOfForcedLabor_id, publicPolicyDiscrimination, publicPolicyDiscrimination_id, region, region_id, rights_state, rights_state_another, rights_state_id, source, source_another, source_content, source_url, start_date, tradeUnionActivityRight, tradeUnionActivityRightAnother, tradeUnionActivityRight_id, tradeUnionBuildingsRight, tradeUnionBuildingsRightAnother, tradeUnionBuildingsRight_id, tradeUnionCount, tradeUnionCount_id, tradeUnionCrime, tradeUnionCrimeAnother, tradeUnionCrime_id, tradeUnionInfo, tradeUnionInfo_id, tradeUnionRight, tradeUnionRightAnother, tradeUnionRight_id, tradeUnionSituation, tradeUnionSituation_another, tradeUnionSituation_id, trade_union_activities, trade_union_activities_another, trade_union_activities_id, tradeunion_actions, useOfForcedLabor, useOfForcedLabor_id, user, user_id, victim, victim_id, victim_situation, victim_situation_another, victim_situation_id, violation_nature, violation_nature_id, violationsUsingCompulsoryLabor, violationsUsingCompulsoryLabor_id, ñonvention135, ñonvention135Another, ñonvention135_id, ñonvention138, ñonvention138_id, ñonvention87, ñonvention87_id, ñonvention98, ñonvention98_id
ERROR django.server "POST /analytic/work/search/ HTTP/1.1" 500 161557 2021-11-02 11:31:47,819
WARNING django.request Not Found: /favicon.ico 2021-11-02 11:32:13,753
WARNING django.server "GET /favicon.ico HTTP/1.1" 404 3524 2021-11-02 11:32:13,754
ERROR django.request Internal Server Error: /analytic/work/search/ 2021-11-02 11:32:20,399
Traceback (most recent call last):
  File "D:\Users\ntabyldieva\Desktop\databases_v1\env\lib\site-packages\django\core\handlers\exception.py", line 47, in inner
    response = get_response(request)
  File "D:\Users\ntabyldieva\Desktop\databases_v1\env\lib\site-packages\django\core\handlers\base.py", line 181, in _get_response
    response = wrapped_callback(request, *callback_args, **callback_kwargs)
  File "D:\Users\ntabyldieva\Desktop\databases_v1\env\lib\site-packages\django\views\decorators\csrf.py", line 54, in wrapped_view
    return view_func(*args, **kwargs)
  File "D:\Users\ntabyldieva\Desktop\databases_v1\env\lib\site-packages\django\views\generic\base.py", line 70, in view
    return self.dispatch(request, *args, **kwargs)
  File "D:\Users\ntabyldieva\Desktop\databases_v1\env\lib\site-packages\rest_framework\views.py", line 509, in dispatch
    response = self.handle_exception(exc)
  File "D:\Users\ntabyldieva\Desktop\databases_v1\env\lib\site-packages\rest_framework\views.py", line 469, in handle_exception
    self.raise_uncaught_exception(exc)
  File "D:\Users\ntabyldieva\Desktop\databases_v1\env\lib\site-packages\rest_framework\views.py", line 480, in raise_uncaught_exception
    raise exc
  File "D:\Users\ntabyldieva\Desktop\databases_v1\env\lib\site-packages\rest_framework\views.py", line 506, in dispatch
    response = handler(request, *args, **kwargs)
  File "D:\Users\ntabyldieva\Desktop\databases_v1\statistica\views.py", line 112, in post
    workcases = WorkCase.objects.filter(**filters)
  File "D:\Users\ntabyldieva\Desktop\databases_v1\env\lib\site-packages\django\db\models\manager.py", line 85, in manager_method
    return getattr(self.get_queryset(), name)(*args, **kwargs)
  File "D:\Users\ntabyldieva\Desktop\databases_v1\env\lib\site-packages\django\db\models\query.py", line 941, in filter
    return self._filter_or_exclude(False, args, kwargs)
  File "D:\Users\ntabyldieva\Desktop\databases_v1\env\lib\site-packages\django\db\models\query.py", line 961, in _filter_or_exclude
    clone._filter_or_exclude_inplace(negate, args, kwargs)
  File "D:\Users\ntabyldieva\Desktop\databases_v1\env\lib\site-packages\django\db\models\query.py", line 968, in _filter_or_exclude_inplace
    self._query.add_q(Q(*args, **kwargs))
  File "D:\Users\ntabyldieva\Desktop\databases_v1\env\lib\site-packages\django\db\models\sql\query.py", line 1391, in add_q
    clause, _ = self._add_q(q_object, self.used_aliases)
  File "D:\Users\ntabyldieva\Desktop\databases_v1\env\lib\site-packages\django\db\models\sql\query.py", line 1410, in _add_q
    child_clause, needed_inner = self.build_filter(
  File "D:\Users\ntabyldieva\Desktop\databases_v1\env\lib\site-packages\django\db\models\sql\query.py", line 1284, in build_filter
    lookups, parts, reffed_expression = self.solve_lookup_type(arg)
  File "D:\Users\ntabyldieva\Desktop\databases_v1\env\lib\site-packages\django\db\models\sql\query.py", line 1110, in solve_lookup_type
    _, field, _, lookup_parts = self.names_to_path(lookup_splitted, self.get_meta())
  File "D:\Users\ntabyldieva\Desktop\databases_v1\env\lib\site-packages\django\db\models\sql\query.py", line 1537, in names_to_path
    raise FieldError("Cannot resolve keyword '%s' into field. "
django.core.exceptions.FieldError: Cannot resolve keyword 'groupofrights' into field. Choices are: active, antiTradeUnionDiscrimination, antiTradeUnionDiscriminationAnother, antiTradeUnionDiscrimination_id, case_company_name, case_description, case_name, case_result, case_text, casecomment, casefile, casephoto, childLabor, childLabor_id, city_name, comment, company, company_id, consultationRight, consultationRightAnother, consultationRight_id, convention182, convention182_id, conversationRight, conversationRightAnother, conversationRight_id, country, country_id, createOrganizationRight, createOrganizationRightAnother, createOrganizationRight_id, createStrikeRight, createStrikeRightAnother, createStrikeRight_id, createTradeUnionRight, createTradeUnionRightAnother, createTradeUnionRight_id, date_create, date_type, date_update, discriminatiOnVariousGrounds, discriminatiOnVariousGrounds_id, discriminationInVariousAreas, discriminationInVariousAreasAnother, discriminationInVariousAreas_id, electionsRight, electionsRightAnother, electionsRight_id, end_date, exact_data, failureSystemicMeasures, failureSystemicMeasures_id, governmentCoercion, governmentCoercion_id, government_agency_name, groupOfPersons, groupOfPersons_id, groupOfRights, groupOfRights_id, id, individualinfo, intruder, intruderAnother, local_agency_name, meetingsRight, meetingsRightAnother, meetingsRight_id, police_agency_name, principleOfNonDiscrimination, principleOfNonDiscrimination_id, prohibitionOfForcedLabor, prohibitionOfForcedLabor_id, publicPolicyDiscrimination, publicPolicyDiscrimination_id, region, region_id, rights_state, rights_state_another, rights_state_id, source, source_another, source_content, source_url, start_date, tradeUnionActivityRight, tradeUnionActivityRightAnother, tradeUnionActivityRight_id, tradeUnionBuildingsRight, tradeUnionBuildingsRightAnother, tradeUnionBuildingsRight_id, tradeUnionCount, tradeUnionCount_id, tradeUnionCrime, tradeUnionCrimeAnother, tradeUnionCrime_id, tradeUnionInfo, tradeUnionInfo_id, tradeUnionRight, tradeUnionRightAnother, tradeUnionRight_id, tradeUnionSituation, tradeUnionSituation_another, tradeUnionSituation_id, trade_union_activities, trade_union_activities_another, trade_union_activities_id, tradeunion_actions, useOfForcedLabor, useOfForcedLabor_id, user, user_id, victim, victim_id, victim_situation, victim_situation_another, victim_situation_id, violation_nature, violation_nature_id, violationsUsingCompulsoryLabor, violationsUsingCompulsoryLabor_id, ñonvention135, ñonvention135Another, ñonvention135_id, ñonvention138, ñonvention138_id, ñonvention87, ñonvention87_id, ñonvention98, ñonvention98_id
ERROR django.server "POST /analytic/work/search/ HTTP/1.1" 500 161557 2021-11-02 11:32:20,414
ERROR django.request Internal Server Error: /analytic/work/search/ 2021-11-02 11:33:32,504
Traceback (most recent call last):
  File "D:\Users\ntabyldieva\Desktop\databases_v1\env\lib\site-packages\django\core\handlers\exception.py", line 47, in inner
    response = get_response(request)
  File "D:\Users\ntabyldieva\Desktop\databases_v1\env\lib\site-packages\django\core\handlers\base.py", line 181, in _get_response
    response = wrapped_callback(request, *callback_args, **callback_kwargs)
  File "D:\Users\ntabyldieva\Desktop\databases_v1\env\lib\site-packages\django\views\decorators\csrf.py", line 54, in wrapped_view
    return view_func(*args, **kwargs)
  File "D:\Users\ntabyldieva\Desktop\databases_v1\env\lib\site-packages\django\views\generic\base.py", line 70, in view
    return self.dispatch(request, *args, **kwargs)
  File "D:\Users\ntabyldieva\Desktop\databases_v1\env\lib\site-packages\rest_framework\views.py", line 509, in dispatch
    response = self.handle_exception(exc)
  File "D:\Users\ntabyldieva\Desktop\databases_v1\env\lib\site-packages\rest_framework\views.py", line 469, in handle_exception
    self.raise_uncaught_exception(exc)
  File "D:\Users\ntabyldieva\Desktop\databases_v1\env\lib\site-packages\rest_framework\views.py", line 480, in raise_uncaught_exception
    raise exc
  File "D:\Users\ntabyldieva\Desktop\databases_v1\env\lib\site-packages\rest_framework\views.py", line 506, in dispatch
    response = handler(request, *args, **kwargs)
  File "D:\Users\ntabyldieva\Desktop\databases_v1\statistica\views.py", line 100, in post
    filters.pop("card_demand_categories_id")
KeyError: 'card_demand_categories_id'
ERROR django.server "POST /analytic/work/search/ HTTP/1.1" 500 95867 2021-11-02 11:33:32,519
ERROR django.request Internal Server Error: /analytic/work/search/ 2021-11-02 11:34:58,371
Traceback (most recent call last):
  File "D:\Users\ntabyldieva\Desktop\databases_v1\env\lib\site-packages\django\core\handlers\exception.py", line 47, in inner
    response = get_response(request)
  File "D:\Users\ntabyldieva\Desktop\databases_v1\env\lib\site-packages\django\core\handlers\base.py", line 181, in _get_response
    response = wrapped_callback(request, *callback_args, **callback_kwargs)
  File "D:\Users\ntabyldieva\Desktop\databases_v1\env\lib\site-packages\django\views\decorators\csrf.py", line 54, in wrapped_view
    return view_func(*args, **kwargs)
  File "D:\Users\ntabyldieva\Desktop\databases_v1\env\lib\site-packages\django\views\generic\base.py", line 70, in view
    return self.dispatch(request, *args, **kwargs)
  File "D:\Users\ntabyldieva\Desktop\databases_v1\env\lib\site-packages\rest_framework\views.py", line 509, in dispatch
    response = self.handle_exception(exc)
  File "D:\Users\ntabyldieva\Desktop\databases_v1\env\lib\site-packages\rest_framework\views.py", line 469, in handle_exception
    self.raise_uncaught_exception(exc)
  File "D:\Users\ntabyldieva\Desktop\databases_v1\env\lib\site-packages\rest_framework\views.py", line 480, in raise_uncaught_exception
    raise exc
  File "D:\Users\ntabyldieva\Desktop\databases_v1\env\lib\site-packages\rest_framework\views.py", line 506, in dispatch
    response = handler(request, *args, **kwargs)
  File "D:\Users\ntabyldieva\Desktop\databases_v1\statistica\views.py", line 100, in post
    filters.pop("card_demand_categories_id")
KeyError: 'card_demand_categories_id'
ERROR django.server "POST /analytic/work/search/ HTTP/1.1" 500 95867 2021-11-02 11:34:58,371
WARNING django.request Not Found: /favicon.ico 2021-11-02 11:44:26,349
WARNING django.server "GET /favicon.ico HTTP/1.1" 404 3524 2021-11-02 11:44:26,350
WARNING django.request Not Found: /favicon.ico 2021-11-02 11:45:28,837
WARNING django.server "GET /favicon.ico HTTP/1.1" 404 3524 2021-11-02 11:45:28,837
ERROR django.request Internal Server Error: /analytic/work/search/ 2021-11-02 11:45:34,499
Traceback (most recent call last):
  File "D:\Users\ntabyldieva\Desktop\databases_v1\env\lib\site-packages\django\core\handlers\exception.py", line 47, in inner
    response = get_response(request)
  File "D:\Users\ntabyldieva\Desktop\databases_v1\env\lib\site-packages\django\core\handlers\base.py", line 181, in _get_response
    response = wrapped_callback(request, *callback_args, **callback_kwargs)
  File "D:\Users\ntabyldieva\Desktop\databases_v1\env\lib\site-packages\django\views\decorators\csrf.py", line 54, in wrapped_view
    return view_func(*args, **kwargs)
  File "D:\Users\ntabyldieva\Desktop\databases_v1\env\lib\site-packages\django\views\generic\base.py", line 70, in view
    return self.dispatch(request, *args, **kwargs)
  File "D:\Users\ntabyldieva\Desktop\databases_v1\env\lib\site-packages\rest_framework\views.py", line 509, in dispatch
    response = self.handle_exception(exc)
  File "D:\Users\ntabyldieva\Desktop\databases_v1\env\lib\site-packages\rest_framework\views.py", line 469, in handle_exception
    self.raise_uncaught_exception(exc)
  File "D:\Users\ntabyldieva\Desktop\databases_v1\env\lib\site-packages\rest_framework\views.py", line 480, in raise_uncaught_exception
    raise exc
  File "D:\Users\ntabyldieva\Desktop\databases_v1\env\lib\site-packages\rest_framework\views.py", line 506, in dispatch
    response = handler(request, *args, **kwargs)
  File "D:\Users\ntabyldieva\Desktop\databases_v1\statistica\views.py", line 112, in post
    workcases = WorkCase.objects.filter(**filters)
  File "D:\Users\ntabyldieva\Desktop\databases_v1\env\lib\site-packages\django\db\models\manager.py", line 85, in manager_method
    return getattr(self.get_queryset(), name)(*args, **kwargs)
  File "D:\Users\ntabyldieva\Desktop\databases_v1\env\lib\site-packages\django\db\models\query.py", line 941, in filter
    return self._filter_or_exclude(False, args, kwargs)
  File "D:\Users\ntabyldieva\Desktop\databases_v1\env\lib\site-packages\django\db\models\query.py", line 961, in _filter_or_exclude
    clone._filter_or_exclude_inplace(negate, args, kwargs)
  File "D:\Users\ntabyldieva\Desktop\databases_v1\env\lib\site-packages\django\db\models\query.py", line 968, in _filter_or_exclude_inplace
    self._query.add_q(Q(*args, **kwargs))
  File "D:\Users\ntabyldieva\Desktop\databases_v1\env\lib\site-packages\django\db\models\sql\query.py", line 1391, in add_q
    clause, _ = self._add_q(q_object, self.used_aliases)
  File "D:\Users\ntabyldieva\Desktop\databases_v1\env\lib\site-packages\django\db\models\sql\query.py", line 1410, in _add_q
    child_clause, needed_inner = self.build_filter(
  File "D:\Users\ntabyldieva\Desktop\databases_v1\env\lib\site-packages\django\db\models\sql\query.py", line 1284, in build_filter
    lookups, parts, reffed_expression = self.solve_lookup_type(arg)
  File "D:\Users\ntabyldieva\Desktop\databases_v1\env\lib\site-packages\django\db\models\sql\query.py", line 1110, in solve_lookup_type
    _, field, _, lookup_parts = self.names_to_path(lookup_splitted, self.get_meta())
  File "D:\Users\ntabyldieva\Desktop\databases_v1\env\lib\site-packages\django\db\models\sql\query.py", line 1537, in names_to_path
    raise FieldError("Cannot resolve keyword '%s' into field. "
django.core.exceptions.FieldError: Cannot resolve keyword 'groupofrights' into field. Choices are: active, antiTradeUnionDiscrimination, antiTradeUnionDiscriminationAnother, antiTradeUnionDiscrimination_id, case_company_name, case_description, case_name, case_result, case_text, casecomment, casefile, casephoto, childLabor, childLabor_id, city_name, comment, company, company_id, consultationRight, consultationRightAnother, consultationRight_id, convention182, convention182_id, conversationRight, conversationRightAnother, conversationRight_id, country, country_id, createOrganizationRight, createOrganizationRightAnother, createOrganizationRight_id, createStrikeRight, createStrikeRightAnother, createStrikeRight_id, createTradeUnionRight, createTradeUnionRightAnother, createTradeUnionRight_id, date_create, date_type, date_update, discriminatiOnVariousGrounds, discriminatiOnVariousGrounds_id, discriminationInVariousAreas, discriminationInVariousAreasAnother, discriminationInVariousAreas_id, electionsRight, electionsRightAnother, electionsRight_id, end_date, exact_data, failureSystemicMeasures, failureSystemicMeasures_id, governmentCoercion, governmentCoercion_id, government_agency_name, groupOfPersons, groupOfPersons_id, groupOfRights, groupOfRights_id, id, individualinfo, intruder, intruderAnother, local_agency_name, meetingsRight, meetingsRightAnother, meetingsRight_id, police_agency_name, principleOfNonDiscrimination, principleOfNonDiscrimination_id, prohibitionOfForcedLabor, prohibitionOfForcedLabor_id, publicPolicyDiscrimination, publicPolicyDiscrimination_id, region, region_id, rights_state, rights_state_another, rights_state_id, source, source_another, source_content, source_url, start_date, tradeUnionActivityRight, tradeUnionActivityRightAnother, tradeUnionActivityRight_id, tradeUnionBuildingsRight, tradeUnionBuildingsRightAnother, tradeUnionBuildingsRight_id, tradeUnionCount, tradeUnionCount_id, tradeUnionCrime, tradeUnionCrimeAnother, tradeUnionCrime_id, tradeUnionInfo, tradeUnionInfo_id, tradeUnionRight, tradeUnionRightAnother, tradeUnionRight_id, tradeUnionSituation, tradeUnionSituation_another, tradeUnionSituation_id, trade_union_activities, trade_union_activities_another, trade_union_activities_id, tradeunion_actions, useOfForcedLabor, useOfForcedLabor_id, user, user_id, victim, victim_id, victim_situation, victim_situation_another, victim_situation_id, violation_nature, violation_nature_id, violationsUsingCompulsoryLabor, violationsUsingCompulsoryLabor_id, ñonvention135, ñonvention135Another, ñonvention135_id, ñonvention138, ñonvention138_id, ñonvention87, ñonvention87_id, ñonvention98, ñonvention98_id
ERROR django.server "POST /analytic/work/search/ HTTP/1.1" 500 161557 2021-11-02 11:45:34,499
WARNING django.request Not Found: /favicon.ico 2021-11-02 11:46:13,073
WARNING django.server "GET /favicon.ico HTTP/1.1" 404 3524 2021-11-02 11:46:13,074
WARNING django.request Not Found: /favicon.ico 2021-11-02 11:46:13,808
WARNING django.server "GET /favicon.ico HTTP/1.1" 404 3524 2021-11-02 11:46:13,808
ERROR django.request Internal Server Error: /analytic/work/search/ 2021-11-02 11:46:23,584
Traceback (most recent call last):
  File "D:\Users\ntabyldieva\Desktop\databases_v1\env\lib\site-packages\django\core\handlers\exception.py", line 47, in inner
    response = get_response(request)
  File "D:\Users\ntabyldieva\Desktop\databases_v1\env\lib\site-packages\django\core\handlers\base.py", line 181, in _get_response
    response = wrapped_callback(request, *callback_args, **callback_kwargs)
  File "D:\Users\ntabyldieva\Desktop\databases_v1\env\lib\site-packages\django\views\decorators\csrf.py", line 54, in wrapped_view
    return view_func(*args, **kwargs)
  File "D:\Users\ntabyldieva\Desktop\databases_v1\env\lib\site-packages\django\views\generic\base.py", line 70, in view
    return self.dispatch(request, *args, **kwargs)
  File "D:\Users\ntabyldieva\Desktop\databases_v1\env\lib\site-packages\rest_framework\views.py", line 509, in dispatch
    response = self.handle_exception(exc)
  File "D:\Users\ntabyldieva\Desktop\databases_v1\env\lib\site-packages\rest_framework\views.py", line 469, in handle_exception
    self.raise_uncaught_exception(exc)
  File "D:\Users\ntabyldieva\Desktop\databases_v1\env\lib\site-packages\rest_framework\views.py", line 480, in raise_uncaught_exception
    raise exc
  File "D:\Users\ntabyldieva\Desktop\databases_v1\env\lib\site-packages\rest_framework\views.py", line 506, in dispatch
    response = handler(request, *args, **kwargs)
  File "D:\Users\ntabyldieva\Desktop\databases_v1\statistica\views.py", line 112, in post
    workcases = WorkCase.objects.filter(**filters)
  File "D:\Users\ntabyldieva\Desktop\databases_v1\env\lib\site-packages\django\db\models\manager.py", line 85, in manager_method
    return getattr(self.get_queryset(), name)(*args, **kwargs)
  File "D:\Users\ntabyldieva\Desktop\databases_v1\env\lib\site-packages\django\db\models\query.py", line 941, in filter
    return self._filter_or_exclude(False, args, kwargs)
  File "D:\Users\ntabyldieva\Desktop\databases_v1\env\lib\site-packages\django\db\models\query.py", line 961, in _filter_or_exclude
    clone._filter_or_exclude_inplace(negate, args, kwargs)
  File "D:\Users\ntabyldieva\Desktop\databases_v1\env\lib\site-packages\django\db\models\query.py", line 968, in _filter_or_exclude_inplace
    self._query.add_q(Q(*args, **kwargs))
  File "D:\Users\ntabyldieva\Desktop\databases_v1\env\lib\site-packages\django\db\models\sql\query.py", line 1391, in add_q
    clause, _ = self._add_q(q_object, self.used_aliases)
  File "D:\Users\ntabyldieva\Desktop\databases_v1\env\lib\site-packages\django\db\models\sql\query.py", line 1410, in _add_q
    child_clause, needed_inner = self.build_filter(
  File "D:\Users\ntabyldieva\Desktop\databases_v1\env\lib\site-packages\django\db\models\sql\query.py", line 1284, in build_filter
    lookups, parts, reffed_expression = self.solve_lookup_type(arg)
  File "D:\Users\ntabyldieva\Desktop\databases_v1\env\lib\site-packages\django\db\models\sql\query.py", line 1110, in solve_lookup_type
    _, field, _, lookup_parts = self.names_to_path(lookup_splitted, self.get_meta())
  File "D:\Users\ntabyldieva\Desktop\databases_v1\env\lib\site-packages\django\db\models\sql\query.py", line 1537, in names_to_path
    raise FieldError("Cannot resolve keyword '%s' into field. "
django.core.exceptions.FieldError: Cannot resolve keyword 'groupOfrights' into field. Choices are: active, antiTradeUnionDiscrimination, antiTradeUnionDiscriminationAnother, antiTradeUnionDiscrimination_id, case_company_name, case_description, case_name, case_result, case_text, casecomment, casefile, casephoto, childLabor, childLabor_id, city_name, comment, company, company_id, consultationRight, consultationRightAnother, consultationRight_id, convention182, convention182_id, conversationRight, conversationRightAnother, conversationRight_id, country, country_id, createOrganizationRight, createOrganizationRightAnother, createOrganizationRight_id, createStrikeRight, createStrikeRightAnother, createStrikeRight_id, createTradeUnionRight, createTradeUnionRightAnother, createTradeUnionRight_id, date_create, date_type, date_update, discriminatiOnVariousGrounds, discriminatiOnVariousGrounds_id, discriminationInVariousAreas, discriminationInVariousAreasAnother, discriminationInVariousAreas_id, electionsRight, electionsRightAnother, electionsRight_id, end_date, exact_data, failureSystemicMeasures, failureSystemicMeasures_id, governmentCoercion, governmentCoercion_id, government_agency_name, groupOfPersons, groupOfPersons_id, groupOfRights, groupOfRights_id, id, individualinfo, intruder, intruderAnother, local_agency_name, meetingsRight, meetingsRightAnother, meetingsRight_id, police_agency_name, principleOfNonDiscrimination, principleOfNonDiscrimination_id, prohibitionOfForcedLabor, prohibitionOfForcedLabor_id, publicPolicyDiscrimination, publicPolicyDiscrimination_id, region, region_id, rights_state, rights_state_another, rights_state_id, source, source_another, source_content, source_url, start_date, tradeUnionActivityRight, tradeUnionActivityRightAnother, tradeUnionActivityRight_id, tradeUnionBuildingsRight, tradeUnionBuildingsRightAnother, tradeUnionBuildingsRight_id, tradeUnionCount, tradeUnionCount_id, tradeUnionCrime, tradeUnionCrimeAnother, tradeUnionCrime_id, tradeUnionInfo, tradeUnionInfo_id, tradeUnionRight, tradeUnionRightAnother, tradeUnionRight_id, tradeUnionSituation, tradeUnionSituation_another, tradeUnionSituation_id, trade_union_activities, trade_union_activities_another, trade_union_activities_id, tradeunion_actions, useOfForcedLabor, useOfForcedLabor_id, user, user_id, victim, victim_id, victim_situation, victim_situation_another, victim_situation_id, violation_nature, violation_nature_id, violationsUsingCompulsoryLabor, violationsUsingCompulsoryLabor_id, ñonvention135, ñonvention135Another, ñonvention135_id, ñonvention138, ñonvention138_id, ñonvention87, ñonvention87_id, ñonvention98, ñonvention98_id
ERROR django.server "POST /analytic/work/search/ HTTP/1.1" 500 161557 2021-11-02 11:46:23,599
WARNING django.request Not Found: /favicon.ico 2021-11-02 11:46:57,904
WARNING django.server "GET /favicon.ico HTTP/1.1" 404 3524 2021-11-02 11:46:57,905
WARNING django.request Not Found: /favicon.ico 2021-11-02 11:47:18,241
WARNING django.server "GET /favicon.ico HTTP/1.1" 404 3524 2021-11-02 11:47:18,241
WARNING django.request Not Found: /favicon.ico 2021-11-02 11:55:53,483
WARNING django.server "GET /favicon.ico HTTP/1.1" 404 3524 2021-11-02 11:55:53,483
WARNING django.request Not Found: /favicon.ico 2021-11-02 11:58:32,906
WARNING django.server "GET /favicon.ico HTTP/1.1" 404 3524 2021-11-02 11:58:32,907
WARNING django.request Not Found: /favicon.ico 2021-11-02 11:59:36,741
WARNING django.server "GET /favicon.ico HTTP/1.1" 404 3524 2021-11-02 11:59:36,742
WARNING django.request Not Found: /favicon.ico 2021-11-02 12:03:24,561
WARNING django.server "GET /favicon.ico HTTP/1.1" 404 3524 2021-11-02 12:03:24,562
ERROR django.request Internal Server Error: /strike/data/get/ 2021-11-02 12:04:31,379
Traceback (most recent call last):
  File "D:\Users\ntabyldieva\Desktop\databases_v1\env\lib\site-packages\django\core\handlers\exception.py", line 47, in inner
    response = get_response(request)
  File "D:\Users\ntabyldieva\Desktop\databases_v1\env\lib\site-packages\django\core\handlers\base.py", line 181, in _get_response
    response = wrapped_callback(request, *callback_args, **callback_kwargs)
  File "D:\Users\ntabyldieva\Desktop\databases_v1\env\lib\site-packages\django\views\decorators\csrf.py", line 54, in wrapped_view
    return view_func(*args, **kwargs)
  File "D:\Users\ntabyldieva\Desktop\databases_v1\env\lib\site-packages\django\views\generic\base.py", line 70, in view
    return self.dispatch(request, *args, **kwargs)
  File "D:\Users\ntabyldieva\Desktop\databases_v1\env\lib\site-packages\rest_framework\views.py", line 509, in dispatch
    response = self.handle_exception(exc)
  File "D:\Users\ntabyldieva\Desktop\databases_v1\env\lib\site-packages\rest_framework\views.py", line 469, in handle_exception
    self.raise_uncaught_exception(exc)
  File "D:\Users\ntabyldieva\Desktop\databases_v1\env\lib\site-packages\rest_framework\views.py", line 480, in raise_uncaught_exception
    raise exc
  File "D:\Users\ntabyldieva\Desktop\databases_v1\env\lib\site-packages\rest_framework\views.py", line 506, in dispatch
    response = handler(request, *args, **kwargs)
  File "D:\Users\ntabyldieva\Desktop\databases_v1\strike\views.py", line 488, in post
    queryset = Card.objects.filter(**dicts).values(*values_list).annotate(count=Count('id'),
  File "D:\Users\ntabyldieva\Desktop\databases_v1\env\lib\site-packages\django\db\models\manager.py", line 85, in manager_method
    return getattr(self.get_queryset(), name)(*args, **kwargs)
  File "D:\Users\ntabyldieva\Desktop\databases_v1\env\lib\site-packages\django\db\models\query.py", line 941, in filter
    return self._filter_or_exclude(False, args, kwargs)
  File "D:\Users\ntabyldieva\Desktop\databases_v1\env\lib\site-packages\django\db\models\query.py", line 961, in _filter_or_exclude
    clone._filter_or_exclude_inplace(negate, args, kwargs)
  File "D:\Users\ntabyldieva\Desktop\databases_v1\env\lib\site-packages\django\db\models\query.py", line 968, in _filter_or_exclude_inplace
    self._query.add_q(Q(*args, **kwargs))
  File "D:\Users\ntabyldieva\Desktop\databases_v1\env\lib\site-packages\django\db\models\sql\query.py", line 1391, in add_q
    clause, _ = self._add_q(q_object, self.used_aliases)
  File "D:\Users\ntabyldieva\Desktop\databases_v1\env\lib\site-packages\django\db\models\sql\query.py", line 1410, in _add_q
    child_clause, needed_inner = self.build_filter(
  File "D:\Users\ntabyldieva\Desktop\databases_v1\env\lib\site-packages\django\db\models\sql\query.py", line 1284, in build_filter
    lookups, parts, reffed_expression = self.solve_lookup_type(arg)
  File "D:\Users\ntabyldieva\Desktop\databases_v1\env\lib\site-packages\django\db\models\sql\query.py", line 1110, in solve_lookup_type
    _, field, _, lookup_parts = self.names_to_path(lookup_splitted, self.get_meta())
  File "D:\Users\ntabyldieva\Desktop\databases_v1\env\lib\site-packages\django\db\models\sql\query.py", line 1537, in names_to_path
    raise FieldError("Cannot resolve keyword '%s' into field. "
django.core.exceptions.FieldError: Cannot resolve keyword 'employer' into field. Choices are: active, added_by, added_by_id, additional_information, card_demand_categories, card_sources, cardcomment, cardfile, cardphoto, case_text, change_number_participants, city_name, combo_another, combo_demands, comment, company_country_name, company_employees_count, company_employees_count_id, company_is_tnk_member, company_name, company_ownership_type, company_ownership_type_id, company_tnk_name, count_strike_participants, count_strike_participants_id, country, country_id, date_create, date_type, date_update, duration, duration_id, economic_another, economic_demands, employear, employear_id, end_date, id, individual, initiator, initiator_id, initiators_and_participants, meeting_requirements, meeting_requirements_id, name, personGroupInfo, personGroupInfo_id, politic_another, politic_demands, reasons_for_strike, region, region_id, results_so_far, source_content, source_url, start_date, state_position, story, tradeunionChoice, tradeunionChoiceAnother, tradeunionChoice_id, tradeunion_data, tradeunion_data_id
ERROR django.server "POST /strike/data/get/ HTTP/1.1" 500 149331 2021-11-02 12:04:31,386
WARNING django.request Not Found: /favicon.ico 2021-11-02 12:05:28,341
WARNING django.server "GET /favicon.ico HTTP/1.1" 404 3524 2021-11-02 12:05:28,341
ERROR django.request Internal Server Error: /strike/data/get/ 2021-11-02 12:05:33,463
Traceback (most recent call last):
  File "D:\Users\ntabyldieva\Desktop\databases_v1\env\lib\site-packages\django\db\models\sql\query.py", line 1642, in transform
    return self.try_transform(wrapped, name)
  File "D:\Users\ntabyldieva\Desktop\databases_v1\env\lib\site-packages\django\db\models\sql\query.py", line 1224, in try_transform
    raise FieldError(
django.core.exceptions.FieldError: Unsupported lookup 'name' for BigAutoField or join on the field not permitted.

During handling of the above exception, another exception occurred:

Traceback (most recent call last):
  File "D:\Users\ntabyldieva\Desktop\databases_v1\env\lib\site-packages\django\core\handlers\exception.py", line 47, in inner
    response = get_response(request)
  File "D:\Users\ntabyldieva\Desktop\databases_v1\env\lib\site-packages\django\core\handlers\base.py", line 181, in _get_response
    response = wrapped_callback(request, *callback_args, **callback_kwargs)
  File "D:\Users\ntabyldieva\Desktop\databases_v1\env\lib\site-packages\django\views\decorators\csrf.py", line 54, in wrapped_view
    return view_func(*args, **kwargs)
  File "D:\Users\ntabyldieva\Desktop\databases_v1\env\lib\site-packages\django\views\generic\base.py", line 70, in view
    return self.dispatch(request, *args, **kwargs)
  File "D:\Users\ntabyldieva\Desktop\databases_v1\env\lib\site-packages\rest_framework\views.py", line 509, in dispatch
    response = self.handle_exception(exc)
  File "D:\Users\ntabyldieva\Desktop\databases_v1\env\lib\site-packages\rest_framework\views.py", line 469, in handle_exception
    self.raise_uncaught_exception(exc)
  File "D:\Users\ntabyldieva\Desktop\databases_v1\env\lib\site-packages\rest_framework\views.py", line 480, in raise_uncaught_exception
    raise exc
  File "D:\Users\ntabyldieva\Desktop\databases_v1\env\lib\site-packages\rest_framework\views.py", line 506, in dispatch
    response = handler(request, *args, **kwargs)
  File "D:\Users\ntabyldieva\Desktop\databases_v1\strike\views.py", line 488, in post
    queryset = Card.objects.filter(**dicts).values(*values_list).annotate(count=Count('id'),
  File "D:\Users\ntabyldieva\Desktop\databases_v1\env\lib\site-packages\django\db\models\query.py", line 840, in values
    clone = self._values(*fields, **expressions)
  File "D:\Users\ntabyldieva\Desktop\databases_v1\env\lib\site-packages\django\db\models\query.py", line 835, in _values
    clone.query.set_values(fields)
  File "D:\Users\ntabyldieva\Desktop\databases_v1\env\lib\site-packages\django\db\models\sql\query.py", line 2246, in set_values
    self.add_fields(field_names, True)
  File "D:\Users\ntabyldieva\Desktop\databases_v1\env\lib\site-packages\django\db\models\sql\query.py", line 1937, in add_fields
    cols.append(join_info.transform_function(target, final_alias))
  File "D:\Users\ntabyldieva\Desktop\databases_v1\env\lib\site-packages\django\db\models\sql\query.py", line 1646, in transform
    raise last_field_exception
  File "D:\Users\ntabyldieva\Desktop\databases_v1\env\lib\site-packages\django\db\models\sql\query.py", line 1623, in setup_joins
    path, final_field, targets, rest = self.names_to_path(
  File "D:\Users\ntabyldieva\Desktop\databases_v1\env\lib\site-packages\django\db\models\sql\query.py", line 1537, in names_to_path
    raise FieldError("Cannot resolve keyword '%s' into field. "
django.core.exceptions.FieldError: Cannot resolve keyword 'name' into field. Choices are: card, emp_contacts, emp_name, id
ERROR django.server "POST /strike/data/get/ HTTP/1.1" 500 148754 2021-11-02 12:05:33,463
WARNING django.request Not Found: /favicon.ico 2021-11-02 12:08:11,279
WARNING django.server "GET /favicon.ico HTTP/1.1" 404 3524 2021-11-02 12:08:11,280
WARNING django.request Not Found: /favicon.ico 2021-11-02 12:08:11,757
WARNING django.server "GET /favicon.ico HTTP/1.1" 404 3524 2021-11-02 12:08:11,758
WARNING django.request Not Found: /favicon.ico 2021-11-02 12:09:20,812
WARNING django.server "GET /favicon.ico HTTP/1.1" 404 3524 2021-11-02 12:09:20,813
WARNING django.request Not Found: /favicon.ico 2021-11-02 13:38:48,736
WARNING django.server "GET /favicon.ico HTTP/1.1" 404 3524 2021-11-02 13:38:48,737
ERROR django.request Internal Server Error: /work/word/32/ 2021-11-02 13:44:40,468
Traceback (most recent call last):
  File "D:\Users\ntabyldieva\Desktop\databases_v1\env\lib\site-packages\django\core\handlers\exception.py", line 47, in inner
    response = get_response(request)
  File "D:\Users\ntabyldieva\Desktop\databases_v1\env\lib\site-packages\django\core\handlers\base.py", line 181, in _get_response
    response = wrapped_callback(request, *callback_args, **callback_kwargs)
  File "D:\Users\ntabyldieva\Desktop\databases_v1\work\views.py", line 600, in work_word_generate
    print(Case._meta.get_field())
TypeError: get_field() missing 1 required positional argument: 'field_name'
ERROR django.server "GET /work/word/32/ HTTP/1.1" 500 75828 2021-11-02 13:44:40,469
WARNING django.request Not Found: /favicon.ico 2021-11-02 14:08:37,832
WARNING django.server "GET /favicon.ico HTTP/1.1" 404 3524 2021-11-02 14:08:37,833
WARNING django.request Not Found: /favicon.ico 2021-11-02 14:19:44,440
WARNING django.server "GET /favicon.ico HTTP/1.1" 404 3524 2021-11-02 14:19:44,440
WARNING django.request Not Found: /favicon.ico 2021-11-02 15:41:39,577
WARNING django.server "GET /favicon.ico HTTP/1.1" 404 3524 2021-11-02 15:41:39,578
WARNING django.request Not Found: /favicon.ico 2021-11-02 15:44:21,117
WARNING django.server "GET /favicon.ico HTTP/1.1" 404 3524 2021-11-02 15:44:21,118
WARNING django.request Not Found: /favicon.ico 2021-11-02 15:45:07,087
WARNING django.server "GET /favicon.ico HTTP/1.1" 404 3524 2021-11-02 15:45:07,087
WARNING django.request Not Found: /favicon.ico 2021-11-02 15:46:24,530
WARNING django.server "GET /favicon.ico HTTP/1.1" 404 3524 2021-11-02 15:46:24,530
WARNING django.request Bad Request: /analytic/strike/search/ 2021-11-02 15:50:05,145
WARNING django.server "POST /analytic/strike/search/ HTTP/1.1" 400 82 2021-11-02 15:50:05,145
WARNING django.request Not Found: /favicon.ico 2021-11-02 15:54:24,782
WARNING django.server "GET /favicon.ico HTTP/1.1" 404 3524 2021-11-02 15:54:24,783
WARNING django.request Not Found: /favicon.ico 2021-11-02 16:03:28,950
WARNING django.server "GET /favicon.ico HTTP/1.1" 404 3524 2021-11-02 16:03:28,951
WARNING django.request Forbidden: /analytic/migrant/search/ 2021-11-02 16:03:41,947
WARNING django.server "POST /analytic/migrant/search/ HTTP/1.1" 403 58 2021-11-02 16:03:41,947
WARNING django.request Not Found: /favicon.ico 2021-11-02 16:04:23,736
WARNING django.server "GET /favicon.ico HTTP/1.1" 404 3524 2021-11-02 16:04:23,737
WARNING django.request Not Found: /favicon.ico 2021-11-02 16:29:26,891
WARNING django.server "GET /favicon.ico HTTP/1.1" 404 3524 2021-11-02 16:29:26,892
WARNING django.request Not Found: /favicon.ico 2021-11-02 16:30:27,183
WARNING django.server "GET /favicon.ico HTTP/1.1" 404 3524 2021-11-02 16:30:27,184
WARNING django.request Not Found: /favicon.ico 2021-11-02 16:32:47,695
WARNING django.server "GET /favicon.ico HTTP/1.1" 404 3524 2021-11-02 16:32:47,696
WARNING django.request Not Found: /favicon.ico 2021-11-02 16:35:45,258
WARNING django.server "GET /favicon.ico HTTP/1.1" 404 3524 2021-11-02 16:35:45,259
ERROR django.request Internal Server Error: /work/add/ 2021-11-02 16:59:35,204
Traceback (most recent call last):
  File "D:\Users\ntabyldieva\Desktop\databases_v1\env\lib\site-packages\django\core\handlers\exception.py", line 47, in inner
    response = get_response(request)
  File "D:\Users\ntabyldieva\Desktop\databases_v1\env\lib\site-packages\django\core\handlers\base.py", line 181, in _get_response
    response = wrapped_callback(request, *callback_args, **callback_kwargs)
  File "D:\Users\ntabyldieva\Desktop\databases_v1\env\lib\site-packages\django\contrib\auth\decorators.py", line 21, in _wrapped_view
    return view_func(request, *args, **kwargs)
  File "D:\Users\ntabyldieva\Desktop\databases_v1\work\views.py", line 150, in add_case
    ind.case_id = case.id
UnboundLocalError: local variable 'ind' referenced before assignment
ERROR django.server "POST /work/add/ HTTP/1.1" 500 93614 2021-11-02 16:59:35,206
WARNING django.request Not Found: /favicon.ico 2021-11-02 17:36:25,008
WARNING django.server "GET /favicon.ico HTTP/1.1" 404 3524 2021-11-02 17:36:25,009
WARNING django.request Not Found: /favicon.ico 2021-11-02 17:36:28,394
WARNING django.server "GET /favicon.ico HTTP/1.1" 404 3524 2021-11-02 17:36:28,394
WARNING django.request Not Found: /favicon.ico 2021-11-02 17:36:30,154
WARNING django.server "GET /favicon.ico HTTP/1.1" 404 3524 2021-11-02 17:36:30,155
WARNING django.request Not Found: /favicon.ico 2021-11-02 17:36:31,843
WARNING django.server "GET /favicon.ico HTTP/1.1" 404 3524 2021-11-02 17:36:31,844
ERROR django.request Internal Server Error: /work/add/ 2021-11-02 17:40:05,414
Traceback (most recent call last):
  File "D:\Users\ntabyldieva\Desktop\databases_v1\env\lib\site-packages\django\core\handlers\exception.py", line 47, in inner
    response = get_response(request)
  File "D:\Users\ntabyldieva\Desktop\databases_v1\env\lib\site-packages\django\core\handlers\base.py", line 181, in _get_response
    response = wrapped_callback(request, *callback_args, **callback_kwargs)
  File "D:\Users\ntabyldieva\Desktop\databases_v1\env\lib\site-packages\django\contrib\auth\decorators.py", line 21, in _wrapped_view
    return view_func(request, *args, **kwargs)
  File "D:\Users\ntabyldieva\Desktop\databases_v1\work\views.py", line 133, in add_case
    if individualFormSet.is_valid():
UnboundLocalError: local variable 'individualFormSet' referenced before assignment
ERROR django.server "POST /work/add/ HTTP/1.1" 500 93397 2021-11-02 17:40:05,417
ERROR django.request Internal Server Error: /work/add/ 2021-11-02 17:49:51,869
Traceback (most recent call last):
  File "D:\Users\ntabyldieva\Desktop\databases_v1\env\lib\site-packages\django\core\handlers\exception.py", line 47, in inner
    response = get_response(request)
  File "D:\Users\ntabyldieva\Desktop\databases_v1\env\lib\site-packages\django\core\handlers\base.py", line 181, in _get_response
    response = wrapped_callback(request, *callback_args, **callback_kwargs)
  File "D:\Users\ntabyldieva\Desktop\databases_v1\env\lib\site-packages\django\contrib\auth\decorators.py", line 21, in _wrapped_view
    return view_func(request, *args, **kwargs)
  File "D:\Users\ntabyldieva\Desktop\databases_v1\work\views.py", line 112, in add_case
    a = Case.nodes.all().reverse()[0]
AttributeError: type object 'Case' has no attribute 'nodes'
ERROR django.server "POST /work/add/ HTTP/1.1" 500 89756 2021-11-02 17:49:51,871
ERROR django.request Internal Server Error: /work/add/ 2021-11-02 17:52:33,005
Traceback (most recent call last):
  File "D:\Users\ntabyldieva\Desktop\databases_v1\env\lib\site-packages\django\core\handlers\exception.py", line 47, in inner
    response = get_response(request)
  File "D:\Users\ntabyldieva\Desktop\databases_v1\env\lib\site-packages\django\core\handlers\base.py", line 181, in _get_response
    response = wrapped_callback(request, *callback_args, **callback_kwargs)
  File "D:\Users\ntabyldieva\Desktop\databases_v1\env\lib\site-packages\django\contrib\auth\decorators.py", line 21, in _wrapped_view
    return view_func(request, *args, **kwargs)
  File "D:\Users\ntabyldieva\Desktop\databases_v1\work\views.py", line 113, in add_case
    print(int(a))
TypeError: int() argument must be a string, a bytes-like object or a number, not 'Case'
ERROR django.server "POST /work/add/ HTTP/1.1" 500 91018 2021-11-02 17:52:33,008
ERROR django.request Internal Server Error: /work/add/ 2021-11-02 17:54:31,233
Traceback (most recent call last):
  File "D:\Users\ntabyldieva\Desktop\databases_v1\env\lib\site-packages\django\core\handlers\exception.py", line 47, in inner
    response = get_response(request)
  File "D:\Users\ntabyldieva\Desktop\databases_v1\env\lib\site-packages\django\core\handlers\base.py", line 181, in _get_response
    response = wrapped_callback(request, *callback_args, **callback_kwargs)
  File "D:\Users\ntabyldieva\Desktop\databases_v1\env\lib\site-packages\django\contrib\auth\decorators.py", line 21, in _wrapped_view
    return view_func(request, *args, **kwargs)
  File "D:\Users\ntabyldieva\Desktop\databases_v1\work\views.py", line 113, in add_case
    print(a + 1)
TypeError: unsupported operand type(s) for +: 'Case' and 'int'
ERROR django.server "POST /work/add/ HTTP/1.1" 500 90956 2021-11-02 17:54:31,235
ERROR django.request Internal Server Error: /work/add/ 2021-11-02 18:00:20,790
Traceback (most recent call last):
  File "D:\Users\ntabyldieva\Desktop\databases_v1\env\lib\site-packages\django\core\handlers\exception.py", line 47, in inner
    response = get_response(request)
  File "D:\Users\ntabyldieva\Desktop\databases_v1\env\lib\site-packages\django\core\handlers\base.py", line 181, in _get_response
    response = wrapped_callback(request, *callback_args, **callback_kwargs)
  File "D:\Users\ntabyldieva\Desktop\databases_v1\env\lib\site-packages\django\contrib\auth\decorators.py", line 21, in _wrapped_view
    return view_func(request, *args, **kwargs)
  File "D:\Users\ntabyldieva\Desktop\databases_v1\work\views.py", line 112, in add_case
    a = Case.objects.latest()
  File "D:\Users\ntabyldieva\Desktop\databases_v1\env\lib\site-packages\django\db\models\manager.py", line 85, in manager_method
    return getattr(self.get_queryset(), name)(*args, **kwargs)
  File "D:\Users\ntabyldieva\Desktop\databases_v1\env\lib\site-packages\django\db\models\query.py", line 670, in latest
    return self.reverse()._earliest(*fields)
  File "D:\Users\ntabyldieva\Desktop\databases_v1\env\lib\site-packages\django\db\models\query.py", line 653, in _earliest
    raise ValueError(
ValueError: earliest() and latest() require either fields as positional arguments or 'get_latest_by' in the model's Meta.
ERROR django.server "POST /work/add/ HTTP/1.1" 500 103400 2021-11-02 18:00:20,795
ERROR django.request Internal Server Error: /admin/work/case/ 2021-11-02 18:11:23,861
Traceback (most recent call last):
  File "D:\Users\ntabyldieva\Desktop\databases_v1\env\lib\site-packages\django\core\handlers\exception.py", line 47, in inner
    response = get_response(request)
  File "D:\Users\ntabyldieva\Desktop\databases_v1\env\lib\site-packages\django\core\handlers\base.py", line 181, in _get_response
    response = wrapped_callback(request, *callback_args, **callback_kwargs)
  File "D:\Users\ntabyldieva\Desktop\databases_v1\env\lib\site-packages\django\contrib\admin\options.py", line 616, in wrapper
    return self.admin_site.admin_view(view)(*args, **kwargs)
  File "D:\Users\ntabyldieva\Desktop\databases_v1\env\lib\site-packages\django\utils\decorators.py", line 130, in _wrapped_view
    response = view_func(request, *args, **kwargs)
  File "D:\Users\ntabyldieva\Desktop\databases_v1\env\lib\site-packages\django\views\decorators\cache.py", line 44, in _wrapped_view_func
    response = view_func(request, *args, **kwargs)
  File "D:\Users\ntabyldieva\Desktop\databases_v1\env\lib\site-packages\django\contrib\admin\sites.py", line 232, in inner
    return view(request, *args, **kwargs)
  File "D:\Users\ntabyldieva\Desktop\databases_v1\env\lib\site-packages\import_export\admin.py", line 341, in changelist_view
    return super().changelist_view(request, extra_context)
  File "D:\Users\ntabyldieva\Desktop\databases_v1\env\lib\site-packages\import_export\admin.py", line 504, in changelist_view
    return super().changelist_view(request, extra_context)
  File "D:\Users\ntabyldieva\Desktop\databases_v1\env\lib\site-packages\django\utils\decorators.py", line 43, in _wrapper
    return bound_method(*args, **kwargs)
  File "D:\Users\ntabyldieva\Desktop\databases_v1\env\lib\site-packages\django\utils\decorators.py", line 130, in _wrapped_view
    response = view_func(request, *args, **kwargs)
  File "D:\Users\ntabyldieva\Desktop\databases_v1\env\lib\site-packages\django\contrib\admin\options.py", line 1723, in changelist_view
    response = self.response_action(request, queryset=cl.get_queryset(request))
  File "D:\Users\ntabyldieva\Desktop\databases_v1\env\lib\site-packages\django\contrib\admin\options.py", line 1408, in response_action
    response = func(self, request, queryset)
  File "D:\Users\ntabyldieva\Desktop\databases_v1\env\lib\site-packages\django\contrib\admin\actions.py", line 33, in delete_selected
    deletable_objects, model_count, perms_needed, protected = modeladmin.get_deleted_objects(queryset, request)
  File "D:\Users\ntabyldieva\Desktop\databases_v1\env\lib\site-packages\django\contrib\admin\options.py", line 1846, in get_deleted_objects
    return get_deleted_objects(objs, request, self.admin_site)
  File "D:\Users\ntabyldieva\Desktop\databases_v1\env\lib\site-packages\django\contrib\admin\utils.py", line 152, in get_deleted_objects
    to_delete = collector.nested(format_callback)
  File "D:\Users\ntabyldieva\Desktop\databases_v1\env\lib\site-packages\django\contrib\admin\utils.py", line 214, in nested
    roots.extend(self._nested(root, seen, format_callback))
  File "D:\Users\ntabyldieva\Desktop\databases_v1\env\lib\site-packages\django\contrib\admin\utils.py", line 198, in _nested
    children.extend(self._nested(child, seen, format_callback))
  File "D:\Users\ntabyldieva\Desktop\databases_v1\env\lib\site-packages\django\contrib\admin\utils.py", line 200, in _nested
    ret = [format_callback(obj)]
  File "D:\Users\ntabyldieva\Desktop\databases_v1\env\lib\site-packages\django\contrib\admin\utils.py", line 127, in format_callback
    no_edit_link = '%s: %s' % (capfirst(opts.verbose_name), obj)
TypeError: __str__ returned non-string (type NoneType)
ERROR django.server "POST /admin/work/case/ HTTP/1.1" 500 152638 2021-11-02 18:11:23,868
ERROR django.request Internal Server Error: /admin/work/case/ 2021-11-02 18:12:03,352
Traceback (most recent call last):
  File "D:\Users\ntabyldieva\Desktop\databases_v1\env\lib\site-packages\django\core\handlers\exception.py", line 47, in inner
    response = get_response(request)
  File "D:\Users\ntabyldieva\Desktop\databases_v1\env\lib\site-packages\django\core\handlers\base.py", line 181, in _get_response
    response = wrapped_callback(request, *callback_args, **callback_kwargs)
  File "D:\Users\ntabyldieva\Desktop\databases_v1\env\lib\site-packages\django\contrib\admin\options.py", line 616, in wrapper
    return self.admin_site.admin_view(view)(*args, **kwargs)
  File "D:\Users\ntabyldieva\Desktop\databases_v1\env\lib\site-packages\django\utils\decorators.py", line 130, in _wrapped_view
    response = view_func(request, *args, **kwargs)
  File "D:\Users\ntabyldieva\Desktop\databases_v1\env\lib\site-packages\django\views\decorators\cache.py", line 44, in _wrapped_view_func
    response = view_func(request, *args, **kwargs)
  File "D:\Users\ntabyldieva\Desktop\databases_v1\env\lib\site-packages\django\contrib\admin\sites.py", line 232, in inner
    return view(request, *args, **kwargs)
  File "D:\Users\ntabyldieva\Desktop\databases_v1\env\lib\site-packages\import_export\admin.py", line 341, in changelist_view
    return super().changelist_view(request, extra_context)
  File "D:\Users\ntabyldieva\Desktop\databases_v1\env\lib\site-packages\import_export\admin.py", line 504, in changelist_view
    return super().changelist_view(request, extra_context)
  File "D:\Users\ntabyldieva\Desktop\databases_v1\env\lib\site-packages\django\utils\decorators.py", line 43, in _wrapper
    return bound_method(*args, **kwargs)
  File "D:\Users\ntabyldieva\Desktop\databases_v1\env\lib\site-packages\django\utils\decorators.py", line 130, in _wrapped_view
    response = view_func(request, *args, **kwargs)
  File "D:\Users\ntabyldieva\Desktop\databases_v1\env\lib\site-packages\django\contrib\admin\options.py", line 1723, in changelist_view
    response = self.response_action(request, queryset=cl.get_queryset(request))
  File "D:\Users\ntabyldieva\Desktop\databases_v1\env\lib\site-packages\django\contrib\admin\options.py", line 1408, in response_action
    response = func(self, request, queryset)
  File "D:\Users\ntabyldieva\Desktop\databases_v1\env\lib\site-packages\django\contrib\admin\actions.py", line 33, in delete_selected
    deletable_objects, model_count, perms_needed, protected = modeladmin.get_deleted_objects(queryset, request)
  File "D:\Users\ntabyldieva\Desktop\databases_v1\env\lib\site-packages\django\contrib\admin\options.py", line 1846, in get_deleted_objects
    return get_deleted_objects(objs, request, self.admin_site)
  File "D:\Users\ntabyldieva\Desktop\databases_v1\env\lib\site-packages\django\contrib\admin\utils.py", line 152, in get_deleted_objects
    to_delete = collector.nested(format_callback)
  File "D:\Users\ntabyldieva\Desktop\databases_v1\env\lib\site-packages\django\contrib\admin\utils.py", line 214, in nested
    roots.extend(self._nested(root, seen, format_callback))
  File "D:\Users\ntabyldieva\Desktop\databases_v1\env\lib\site-packages\django\contrib\admin\utils.py", line 198, in _nested
    children.extend(self._nested(child, seen, format_callback))
  File "D:\Users\ntabyldieva\Desktop\databases_v1\env\lib\site-packages\django\contrib\admin\utils.py", line 200, in _nested
    ret = [format_callback(obj)]
  File "D:\Users\ntabyldieva\Desktop\databases_v1\env\lib\site-packages\django\contrib\admin\utils.py", line 127, in format_callback
    no_edit_link = '%s: %s' % (capfirst(opts.verbose_name), obj)
TypeError: __str__ returned non-string (type NoneType)
ERROR django.server "POST /admin/work/case/ HTTP/1.1" 500 146948 2021-11-02 18:12:03,357
ERROR django.request Internal Server Error: /admin/work/case/ 2021-11-02 18:12:08,303
Traceback (most recent call last):
  File "D:\Users\ntabyldieva\Desktop\databases_v1\env\lib\site-packages\django\core\handlers\exception.py", line 47, in inner
    response = get_response(request)
  File "D:\Users\ntabyldieva\Desktop\databases_v1\env\lib\site-packages\django\core\handlers\base.py", line 181, in _get_response
    response = wrapped_callback(request, *callback_args, **callback_kwargs)
  File "D:\Users\ntabyldieva\Desktop\databases_v1\env\lib\site-packages\django\contrib\admin\options.py", line 616, in wrapper
    return self.admin_site.admin_view(view)(*args, **kwargs)
  File "D:\Users\ntabyldieva\Desktop\databases_v1\env\lib\site-packages\django\utils\decorators.py", line 130, in _wrapped_view
    response = view_func(request, *args, **kwargs)
  File "D:\Users\ntabyldieva\Desktop\databases_v1\env\lib\site-packages\django\views\decorators\cache.py", line 44, in _wrapped_view_func
    response = view_func(request, *args, **kwargs)
  File "D:\Users\ntabyldieva\Desktop\databases_v1\env\lib\site-packages\django\contrib\admin\sites.py", line 232, in inner
    return view(request, *args, **kwargs)
  File "D:\Users\ntabyldieva\Desktop\databases_v1\env\lib\site-packages\import_export\admin.py", line 341, in changelist_view
    return super().changelist_view(request, extra_context)
  File "D:\Users\ntabyldieva\Desktop\databases_v1\env\lib\site-packages\import_export\admin.py", line 504, in changelist_view
    return super().changelist_view(request, extra_context)
  File "D:\Users\ntabyldieva\Desktop\databases_v1\env\lib\site-packages\django\utils\decorators.py", line 43, in _wrapper
    return bound_method(*args, **kwargs)
  File "D:\Users\ntabyldieva\Desktop\databases_v1\env\lib\site-packages\django\utils\decorators.py", line 130, in _wrapped_view
    response = view_func(request, *args, **kwargs)
  File "D:\Users\ntabyldieva\Desktop\databases_v1\env\lib\site-packages\django\contrib\admin\options.py", line 1723, in changelist_view
    response = self.response_action(request, queryset=cl.get_queryset(request))
  File "D:\Users\ntabyldieva\Desktop\databases_v1\env\lib\site-packages\django\contrib\admin\options.py", line 1408, in response_action
    response = func(self, request, queryset)
  File "D:\Users\ntabyldieva\Desktop\databases_v1\env\lib\site-packages\django\contrib\admin\actions.py", line 33, in delete_selected
    deletable_objects, model_count, perms_needed, protected = modeladmin.get_deleted_objects(queryset, request)
  File "D:\Users\ntabyldieva\Desktop\databases_v1\env\lib\site-packages\django\contrib\admin\options.py", line 1846, in get_deleted_objects
    return get_deleted_objects(objs, request, self.admin_site)
  File "D:\Users\ntabyldieva\Desktop\databases_v1\env\lib\site-packages\django\contrib\admin\utils.py", line 152, in get_deleted_objects
    to_delete = collector.nested(format_callback)
  File "D:\Users\ntabyldieva\Desktop\databases_v1\env\lib\site-packages\django\contrib\admin\utils.py", line 214, in nested
    roots.extend(self._nested(root, seen, format_callback))
  File "D:\Users\ntabyldieva\Desktop\databases_v1\env\lib\site-packages\django\contrib\admin\utils.py", line 198, in _nested
    children.extend(self._nested(child, seen, format_callback))
  File "D:\Users\ntabyldieva\Desktop\databases_v1\env\lib\site-packages\django\contrib\admin\utils.py", line 200, in _nested
    ret = [format_callback(obj)]
  File "D:\Users\ntabyldieva\Desktop\databases_v1\env\lib\site-packages\django\contrib\admin\utils.py", line 127, in format_callback
    no_edit_link = '%s: %s' % (capfirst(opts.verbose_name), obj)
TypeError: __str__ returned non-string (type NoneType)
ERROR django.server "POST /admin/work/case/ HTTP/1.1" 500 146948 2021-11-02 18:12:08,308
ERROR django.request Internal Server Error: /work/add/ 2021-11-02 18:20:45,063
Traceback (most recent call last):
  File "D:\Users\ntabyldieva\Desktop\databases_v1\env\lib\site-packages\django\core\handlers\exception.py", line 47, in inner
    response = get_response(request)
  File "D:\Users\ntabyldieva\Desktop\databases_v1\env\lib\site-packages\django\core\handlers\base.py", line 181, in _get_response
    response = wrapped_callback(request, *callback_args, **callback_kwargs)
  File "D:\Users\ntabyldieva\Desktop\databases_v1\env\lib\site-packages\django\contrib\auth\decorators.py", line 21, in _wrapped_view
    return view_func(request, *args, **kwargs)
  File "D:\Users\ntabyldieva\Desktop\databases_v1\work\views.py", line 138, in add_case
    individualForm.save(commit=False)
  File "D:\Users\ntabyldieva\Desktop\databases_v1\env\lib\site-packages\django\forms\models.py", line 460, in save
    raise ValueError(
ValueError: The IndividualInfo could not be created because the data didn't validate.
ERROR django.server "POST /work/add/ HTTP/1.1" 500 97956 2021-11-02 18:20:45,066
