ERROR django.request Internal Server Error: /work/data/get/ 2021-09-29 17:28:29,938
Traceback (most recent call last):
  File "D:\Users\ntabyldieva\databases_v1\env\lib\site-packages\django\db\backends\utils.py", line 82, in _execute
    return self.cursor.execute(sql)
  File "D:\Users\ntabyldieva\databases_v1\env\lib\site-packages\django\db\backends\sqlite3\base.py", line 421, in execute
    return Database.Cursor.execute(self, query)
sqlite3.OperationalError: near ",": syntax error

The above exception was the direct cause of the following exception:

Traceback (most recent call last):
  File "D:\Users\ntabyldieva\databases_v1\env\lib\site-packages\django\core\handlers\exception.py", line 47, in inner
    response = get_response(request)
  File "D:\Users\ntabyldieva\databases_v1\env\lib\site-packages\django\core\handlers\base.py", line 181, in _get_response
    response = wrapped_callback(request, *callback_args, **callback_kwargs)
  File "D:\Users\ntabyldieva\databases_v1\env\lib\site-packages\django\views\decorators\csrf.py", line 54, in wrapped_view
    return view_func(*args, **kwargs)
  File "D:\Users\ntabyldieva\databases_v1\env\lib\site-packages\django\views\generic\base.py", line 70, in view
    return self.dispatch(request, *args, **kwargs)
  File "D:\Users\ntabyldieva\databases_v1\env\lib\site-packages\rest_framework\views.py", line 509, in dispatch
    response = self.handle_exception(exc)
  File "D:\Users\ntabyldieva\databases_v1\env\lib\site-packages\rest_framework\views.py", line 469, in handle_exception
    self.raise_uncaught_exception(exc)
  File "D:\Users\ntabyldieva\databases_v1\env\lib\site-packages\rest_framework\views.py", line 480, in raise_uncaught_exception
    raise exc
  File "D:\Users\ntabyldieva\databases_v1\env\lib\site-packages\rest_framework\views.py", line 506, in dispatch
    response = handler(request, *args, **kwargs)
  File "D:\Users\ntabyldieva\databases_v1\work\views.py", line 992, in post
    cursor.execute(sql_query + where_query + group_by_query)
  File "D:\Users\ntabyldieva\databases_v1\env\lib\site-packages\django\db\backends\utils.py", line 98, in execute
    return super().execute(sql, params)
  File "D:\Users\ntabyldieva\databases_v1\env\lib\site-packages\django\db\backends\utils.py", line 66, in execute
    return self._execute_with_wrappers(sql, params, many=False, executor=self._execute)
  File "D:\Users\ntabyldieva\databases_v1\env\lib\site-packages\django\db\backends\utils.py", line 75, in _execute_with_wrappers
    return executor(sql, params, many, context)
  File "D:\Users\ntabyldieva\databases_v1\env\lib\site-packages\django\db\backends\utils.py", line 84, in _execute
    return self.cursor.execute(sql, params)
  File "D:\Users\ntabyldieva\databases_v1\env\lib\site-packages\django\db\utils.py", line 90, in __exit__
    raise dj_exc_value.with_traceback(traceback) from exc_value
  File "D:\Users\ntabyldieva\databases_v1\env\lib\site-packages\django\db\backends\utils.py", line 82, in _execute
    return self.cursor.execute(sql)
  File "D:\Users\ntabyldieva\databases_v1\env\lib\site-packages\django\db\backends\sqlite3\base.py", line 421, in execute
    return Database.Cursor.execute(self, query)
django.db.utils.OperationalError: near ",": syntax error
ERROR django.server "POST /work/data/get/ HTTP/1.1" 500 137487 2021-09-29 17:28:29,938
ERROR django.request Internal Server Error: /work/data/get/ 2021-09-29 17:32:43,525
Traceback (most recent call last):
  File "D:\Users\ntabyldieva\databases_v1\env\lib\site-packages\django\core\handlers\exception.py", line 47, in inner
    response = get_response(request)
  File "D:\Users\ntabyldieva\databases_v1\env\lib\site-packages\django\core\handlers\base.py", line 181, in _get_response
    response = wrapped_callback(request, *callback_args, **callback_kwargs)
  File "D:\Users\ntabyldieva\databases_v1\env\lib\site-packages\django\views\decorators\csrf.py", line 54, in wrapped_view
    return view_func(*args, **kwargs)
  File "D:\Users\ntabyldieva\databases_v1\env\lib\site-packages\django\views\generic\base.py", line 70, in view
    return self.dispatch(request, *args, **kwargs)
  File "D:\Users\ntabyldieva\databases_v1\env\lib\site-packages\rest_framework\views.py", line 509, in dispatch
    response = self.handle_exception(exc)
  File "D:\Users\ntabyldieva\databases_v1\env\lib\site-packages\rest_framework\views.py", line 469, in handle_exception
    self.raise_uncaught_exception(exc)
  File "D:\Users\ntabyldieva\databases_v1\env\lib\site-packages\rest_framework\views.py", line 480, in raise_uncaught_exception
    raise exc
  File "D:\Users\ntabyldieva\databases_v1\env\lib\site-packages\rest_framework\views.py", line 506, in dispatch
    response = handler(request, *args, **kwargs)
  File "D:\Users\ntabyldieva\databases_v1\work\views.py", line 941, in post
    where_query_list.append(f"{where_sql_query} ({where_list[0]}) ")
IndexError: list index out of range
ERROR django.server "POST /work/data/get/ HTTP/1.1" 500 97217 2021-09-29 17:32:43,527
WARNING django.request Not Found: /favicon.ico 2021-09-29 17:47:27,421
WARNING django.server "GET /favicon.ico HTTP/1.1" 404 3524 2021-09-29 17:47:27,422
WARNING django.request Not Found: /favicon.ico 2021-09-29 17:48:18,980
WARNING django.server "GET /favicon.ico HTTP/1.1" 404 3524 2021-09-29 17:48:18,982
WARNING django.request Not Found: /favicon.ico 2021-09-29 17:49:20,750
WARNING django.server "GET /favicon.ico HTTP/1.1" 404 3524 2021-09-29 17:49:20,751
WARNING django.request Not Found: /favicon.ico 2021-09-29 17:53:36,629
WARNING django.server "GET /favicon.ico HTTP/1.1" 404 3524 2021-09-29 17:53:36,631
WARNING django.request Not Found: /favicon.ico 2021-09-29 17:54:04,601
WARNING django.server "GET /favicon.ico HTTP/1.1" 404 3524 2021-09-29 17:54:04,603
WARNING django.request Not Found: /favicon.ico 2021-09-29 17:55:08,137
WARNING django.server "GET /favicon.ico HTTP/1.1" 404 3524 2021-09-29 17:55:08,139
WARNING django.request Not Found: /favicon.ico 2021-09-29 17:55:23,139
WARNING django.server "GET /favicon.ico HTTP/1.1" 404 3524 2021-09-29 17:55:23,141
WARNING django.request Not Found: /favicon.ico 2021-09-29 17:57:39,453
WARNING django.server "GET /favicon.ico HTTP/1.1" 404 3524 2021-09-29 17:57:39,456
