WARNING django.request Not Found: /favicon.ico 2021-09-09 12:52:16,725
WARNING django.server "GET /favicon.ico HTTP/1.1" 404 179 2021-09-09 12:52:16,726
WARNING django.request Not Found: /favicon.ico 2021-09-09 12:54:56,848
WARNING django.server "GET /favicon.ico HTTP/1.1" 404 179 2021-09-09 12:54:56,850
WARNING django.request Not Found: /favicon.ico 2021-09-09 14:52:54,020
WARNING django.server "GET /favicon.ico HTTP/1.1" 404 179 2021-09-09 14:52:54,021
WARNING django.request Not Found: /favicon.ico 2021-09-09 14:59:22,566
WARNING django.server "GET /favicon.ico HTTP/1.1" 404 179 2021-09-09 14:59:22,567
WARNING django.request Not Found: /favicon.ico 2021-09-09 14:59:23,703
WARNING django.server "GET /favicon.ico HTTP/1.1" 404 179 2021-09-09 14:59:23,704
WARNING django.request Not Found: /favicon.ico 2021-09-09 14:59:56,782
WARNING django.server "GET /favicon.ico HTTP/1.1" 404 179 2021-09-09 14:59:56,783
WARNING django.request Not Found: /favicon.ico 2021-09-09 15:02:58,435
WARNING django.server "GET /favicon.ico HTTP/1.1" 404 179 2021-09-09 15:02:58,435
WARNING django.request Not Found: /favicon.ico 2021-09-09 15:05:21,474
WARNING django.server "GET /favicon.ico HTTP/1.1" 404 179 2021-09-09 15:05:21,475
WARNING django.request Not Found: /favicon.ico 2021-09-09 15:06:34,761
WARNING django.server "GET /favicon.ico HTTP/1.1" 404 179 2021-09-09 15:06:34,761
WARNING django.request Not Found: /favicon.ico 2021-09-09 15:06:55,338
WARNING django.server "GET /favicon.ico HTTP/1.1" 404 179 2021-09-09 15:06:55,338
WARNING django.request Not Found: /favicon.ico 2021-09-09 15:07:13,527
WARNING django.server "GET /favicon.ico HTTP/1.1" 404 179 2021-09-09 15:07:13,528
WARNING django.request Not Found: /favicon.ico 2021-09-09 15:07:14,856
WARNING django.server "GET /favicon.ico HTTP/1.1" 404 179 2021-09-09 15:07:14,857
ERROR django.request Internal Server Error: /work/update/10/ 2021-09-09 15:13:01,117
Traceback (most recent call last):
  File "C:\Users\user\OneDrive\Desktop\Projects\databases_v1\venv\lib\site-packages\django\core\handlers\exception.py", line 47, in inner
    response = get_response(request)
  File "C:\Users\user\OneDrive\Desktop\Projects\databases_v1\venv\lib\site-packages\django\core\handlers\base.py", line 181, in _get_response
    response = wrapped_callback(request, *callback_args, **callback_kwargs)
  File "C:\Users\user\OneDrive\Desktop\Projects\databases_v1\venv\lib\site-packages\django\contrib\auth\decorators.py", line 21, in _wrapped_view
    return view_func(request, *args, **kwargs)
  File "C:\Users\user\OneDrive\Desktop\Projects\databases_v1\databases_v1\work\views.py", line 236, in update_case
    individualForm = IndividualForm(instance=individual_info)
  File "C:\Users\user\OneDrive\Desktop\Projects\databases_v1\venv\lib\site-packages\django\forms\models.py", line 302, in __init__
    object_data = model_to_dict(instance, opts.fields, opts.exclude)
  File "C:\Users\user\OneDrive\Desktop\Projects\databases_v1\venv\lib\site-packages\django\forms\models.py", line 85, in model_to_dict
    opts = instance._meta
AttributeError: 'QuerySet' object has no attribute '_meta'
ERROR django.server "GET /work/update/10/ HTTP/1.1" 500 145 2021-09-09 15:13:01,431
ERROR django.request Internal Server Error: /work/update/10/ 2021-09-09 15:13:51,241
Traceback (most recent call last):
  File "C:\Users\user\OneDrive\Desktop\Projects\databases_v1\venv\lib\site-packages\django\core\handlers\exception.py", line 47, in inner
    response = get_response(request)
  File "C:\Users\user\OneDrive\Desktop\Projects\databases_v1\venv\lib\site-packages\django\core\handlers\base.py", line 181, in _get_response
    response = wrapped_callback(request, *callback_args, **callback_kwargs)
  File "C:\Users\user\OneDrive\Desktop\Projects\databases_v1\venv\lib\site-packages\django\contrib\auth\decorators.py", line 21, in _wrapped_view
    return view_func(request, *args, **kwargs)
  File "C:\Users\user\OneDrive\Desktop\Projects\databases_v1\databases_v1\work\views.py", line 257, in update_case
    'individualForm':individualForm,
UnboundLocalError: local variable 'individualForm' referenced before assignment
ERROR django.server "GET /work/update/10/ HTTP/1.1" 500 145 2021-09-09 15:13:51,382
WARNING django.request Not Found: /favicon.ico 2021-09-09 15:13:51,601
WARNING django.server "GET /favicon.ico HTTP/1.1" 404 179 2021-09-09 15:13:51,601
ERROR django.request Internal Server Error: /work/update/10/ 2021-09-09 15:14:07,777
Traceback (most recent call last):
  File "C:\Users\user\OneDrive\Desktop\Projects\databases_v1\venv\lib\site-packages\django\core\handlers\exception.py", line 47, in inner
    response = get_response(request)
  File "C:\Users\user\OneDrive\Desktop\Projects\databases_v1\venv\lib\site-packages\django\core\handlers\base.py", line 181, in _get_response
    response = wrapped_callback(request, *callback_args, **callback_kwargs)
  File "C:\Users\user\OneDrive\Desktop\Projects\databases_v1\venv\lib\site-packages\django\contrib\auth\decorators.py", line 21, in _wrapped_view
    return view_func(request, *args, **kwargs)
  File "C:\Users\user\OneDrive\Desktop\Projects\databases_v1\databases_v1\work\views.py", line 257, in update_case
    'individualForm':individualForm,
UnboundLocalError: local variable 'individualForm' referenced before assignment
ERROR django.server "GET /work/update/10/ HTTP/1.1" 500 145 2021-09-09 15:14:07,970
WARNING django.request Not Found: /favicon.ico 2021-09-09 15:14:08,166
WARNING django.server "GET /favicon.ico HTTP/1.1" 404 179 2021-09-09 15:14:08,168
ERROR django.request Internal Server Error: /work/update/10/ 2021-09-09 15:14:21,394
Traceback (most recent call last):
  File "C:\Users\user\OneDrive\Desktop\Projects\databases_v1\venv\lib\site-packages\django\core\handlers\exception.py", line 47, in inner
    response = get_response(request)
  File "C:\Users\user\OneDrive\Desktop\Projects\databases_v1\venv\lib\site-packages\django\core\handlers\base.py", line 181, in _get_response
    response = wrapped_callback(request, *callback_args, **callback_kwargs)
  File "C:\Users\user\OneDrive\Desktop\Projects\databases_v1\venv\lib\site-packages\django\contrib\auth\decorators.py", line 21, in _wrapped_view
    return view_func(request, *args, **kwargs)
  File "C:\Users\user\OneDrive\Desktop\Projects\databases_v1\databases_v1\work\views.py", line 256, in update_case
    'individualForm':individualForm,
UnboundLocalError: local variable 'individualForm' referenced before assignment
ERROR django.server "GET /work/update/10/ HTTP/1.1" 500 145 2021-09-09 15:14:21,501
WARNING django.request Not Found: /favicon.ico 2021-09-09 15:14:21,657
WARNING django.server "GET /favicon.ico HTTP/1.1" 404 179 2021-09-09 15:14:21,657
ERROR django.request Internal Server Error: /work/update/10/ 2021-09-09 15:14:22,558
Traceback (most recent call last):
  File "C:\Users\user\OneDrive\Desktop\Projects\databases_v1\venv\lib\site-packages\django\core\handlers\exception.py", line 47, in inner
    response = get_response(request)
  File "C:\Users\user\OneDrive\Desktop\Projects\databases_v1\venv\lib\site-packages\django\core\handlers\base.py", line 181, in _get_response
    response = wrapped_callback(request, *callback_args, **callback_kwargs)
  File "C:\Users\user\OneDrive\Desktop\Projects\databases_v1\venv\lib\site-packages\django\contrib\auth\decorators.py", line 21, in _wrapped_view
    return view_func(request, *args, **kwargs)
  File "C:\Users\user\OneDrive\Desktop\Projects\databases_v1\databases_v1\work\views.py", line 256, in update_case
    'individualForm':individualForm,
UnboundLocalError: local variable 'individualForm' referenced before assignment
ERROR django.server "GET /work/update/10/ HTTP/1.1" 500 145 2021-09-09 15:14:22,580
WARNING django.request Not Found: /favicon.ico 2021-09-09 15:14:22,727
WARNING django.server "GET /favicon.ico HTTP/1.1" 404 179 2021-09-09 15:14:22,728
ERROR django.request Internal Server Error: /work/update/10/ 2021-09-09 15:14:34,216
Traceback (most recent call last):
  File "C:\Users\user\OneDrive\Desktop\Projects\databases_v1\venv\lib\site-packages\django\core\handlers\exception.py", line 47, in inner
    response = get_response(request)
  File "C:\Users\user\OneDrive\Desktop\Projects\databases_v1\venv\lib\site-packages\django\core\handlers\base.py", line 181, in _get_response
    response = wrapped_callback(request, *callback_args, **callback_kwargs)
  File "C:\Users\user\OneDrive\Desktop\Projects\databases_v1\venv\lib\site-packages\django\contrib\auth\decorators.py", line 21, in _wrapped_view
    return view_func(request, *args, **kwargs)
  File "C:\Users\user\OneDrive\Desktop\Projects\databases_v1\databases_v1\work\views.py", line 256, in update_case
    'individualForm':individualForm,
UnboundLocalError: local variable 'individualForm' referenced before assignment
ERROR django.server "GET /work/update/10/ HTTP/1.1" 500 77041 2021-09-09 15:14:34,219
WARNING django.request Not Found: /favicon.ico 2021-09-09 15:14:34,660
WARNING django.server "GET /favicon.ico HTTP/1.1" 404 3524 2021-09-09 15:14:34,661
WARNING django.request Not Found: /favicon.ico 2021-09-09 15:14:58,430
WARNING django.server "GET /favicon.ico HTTP/1.1" 404 3524 2021-09-09 15:14:58,432
WARNING django.request Not Found: /favicon.ico 2021-09-09 15:15:11,938
WARNING django.server "GET /favicon.ico HTTP/1.1" 404 3524 2021-09-09 15:15:11,939
WARNING django.request Not Found: /favicon.ico 2021-09-09 15:15:47,317
WARNING django.server "GET /favicon.ico HTTP/1.1" 404 3524 2021-09-09 15:15:47,319
ERROR django.request Internal Server Error: /work/update/10/ 2021-09-09 15:16:13,355
Traceback (most recent call last):
  File "C:\Users\user\OneDrive\Desktop\Projects\databases_v1\venv\lib\site-packages\django\core\handlers\exception.py", line 47, in inner
    response = get_response(request)
  File "C:\Users\user\OneDrive\Desktop\Projects\databases_v1\venv\lib\site-packages\django\core\handlers\base.py", line 181, in _get_response
    response = wrapped_callback(request, *callback_args, **callback_kwargs)
  File "C:\Users\user\OneDrive\Desktop\Projects\databases_v1\venv\lib\site-packages\django\contrib\auth\decorators.py", line 21, in _wrapped_view
    return view_func(request, *args, **kwargs)
  File "C:\Users\user\OneDrive\Desktop\Projects\databases_v1\databases_v1\work\views.py", line 255, in update_case
    print(individual_infos)
NameError: name 'i' is not defined
ERROR django.server "GET /work/update/10/ HTTP/1.1" 500 77104 2021-09-09 15:16:13,358
WARNING django.request Not Found: /favicon.ico 2021-09-09 15:16:13,749
WARNING django.server "GET /favicon.ico HTTP/1.1" 404 3524 2021-09-09 15:16:13,750
ERROR django.request Internal Server Error: /work/update/10/ 2021-09-09 15:16:50,801
Traceback (most recent call last):
  File "C:\Users\user\OneDrive\Desktop\Projects\databases_v1\venv\lib\site-packages\django\core\handlers\exception.py", line 47, in inner
    response = get_response(request)
  File "C:\Users\user\OneDrive\Desktop\Projects\databases_v1\venv\lib\site-packages\django\core\handlers\base.py", line 181, in _get_response
    response = wrapped_callback(request, *callback_args, **callback_kwargs)
  File "C:\Users\user\OneDrive\Desktop\Projects\databases_v1\venv\lib\site-packages\django\contrib\auth\decorators.py", line 21, in _wrapped_view
    return view_func(request, *args, **kwargs)
  File "C:\Users\user\OneDrive\Desktop\Projects\databases_v1\databases_v1\work\views.py", line 255, in update_case
    print(individual_infos)
NameError: name 'i' is not defined
ERROR django.server "GET /work/update/10/ HTTP/1.1" 500 77104 2021-09-09 15:16:50,802
WARNING django.request Not Found: /favicon.ico 2021-09-09 15:16:51,068
WARNING django.server "GET /favicon.ico HTTP/1.1" 404 3524 2021-09-09 15:16:51,069
WARNING django.request Not Found: /favicon.ico 2021-09-09 15:17:17,710
WARNING django.server "GET /favicon.ico HTTP/1.1" 404 3524 2021-09-09 15:17:17,712
WARNING django.request Not Found: /favicon.ico 2021-09-09 15:21:29,462
WARNING django.server "GET /favicon.ico HTTP/1.1" 404 3524 2021-09-09 15:21:29,464
WARNING django.request Not Found: /favicon.ico 2021-09-09 15:22:30,699
WARNING django.server "GET /favicon.ico HTTP/1.1" 404 3524 2021-09-09 15:22:30,700
WARNING django.request Not Found: /favicon.ico 2021-09-09 15:23:07,182
WARNING django.server "GET /favicon.ico HTTP/1.1" 404 13991 2021-09-09 15:23:07,183
WARNING django.request Not Found: /favicon.ico 2021-09-09 15:27:20,849
WARNING django.server "GET /favicon.ico HTTP/1.1" 404 13991 2021-09-09 15:27:20,850
ERROR django.request Internal Server Error: /__debug__/history_sidebar/ 2021-09-09 15:33:21,112
Traceback (most recent call last):
  File "C:\Users\user\OneDrive\Desktop\Projects\databases_v1\venv\lib\site-packages\django\core\handlers\exception.py", line 47, in inner
    response = get_response(request)
  File "C:\Users\user\OneDrive\Desktop\Projects\databases_v1\venv\lib\site-packages\django\core\handlers\base.py", line 181, in _get_response
    response = wrapped_callback(request, *callback_args, **callback_kwargs)
  File "C:\Users\user\OneDrive\Desktop\Projects\databases_v1\venv\lib\site-packages\debug_toolbar\decorators.py", line 15, in inner
    return view(request, *args, **kwargs)
  File "C:\Users\user\OneDrive\Desktop\Projects\databases_v1\venv\lib\site-packages\debug_toolbar\decorators.py", line 30, in inner
    return view(
  File "C:\Users\user\OneDrive\Desktop\Projects\databases_v1\venv\lib\site-packages\debug_toolbar\panels\history\views.py", line 19, in history_sidebar
    for panel in toolbar.panels:
AttributeError: 'NoneType' object has no attribute 'panels'
ERROR django.server "GET /__debug__/history_sidebar/?signed=%7B%22store_id%22%3A+%22442da93300df4a9bb6f9ef5f231a809e%22%7D%3AqrnX3BoaweJkZP8PtpxVGsU75RInP0uEXyHHGFBb_9c HTTP/1.1" 500 79772 2021-09-09 15:33:21,113
WARNING django.request Not Found: /favicon.ico 2021-09-09 15:33:27,246
WARNING django.server "GET /favicon.ico HTTP/1.1" 404 13991 2021-09-09 15:33:27,247
WARNING django.request Not Found: /favicon.ico 2021-09-09 15:33:31,025
WARNING django.server "GET /favicon.ico HTTP/1.1" 404 13991 2021-09-09 15:33:31,025
WARNING django.request Not Found: /favicon.ico 2021-09-09 15:34:26,965
WARNING django.server "GET /favicon.ico HTTP/1.1" 404 13991 2021-09-09 15:34:26,966
WARNING django.request Not Found: /favicon.ico 2021-09-09 15:38:12,235
WARNING django.server "GET /favicon.ico HTTP/1.1" 404 13991 2021-09-09 15:38:12,236
ERROR django.request Internal Server Error: /work/add/ 2021-09-09 15:47:56,768
Traceback (most recent call last):
  File "C:\Users\user\OneDrive\Desktop\Projects\databases_v1\venv\lib\site-packages\django\core\handlers\exception.py", line 47, in inner
    response = get_response(request)
  File "C:\Users\user\OneDrive\Desktop\Projects\databases_v1\venv\lib\site-packages\django\core\handlers\base.py", line 181, in _get_response
    response = wrapped_callback(request, *callback_args, **callback_kwargs)
  File "C:\Users\user\OneDrive\Desktop\Projects\databases_v1\venv\lib\site-packages\django\contrib\auth\decorators.py", line 21, in _wrapped_view
    return view_func(request, *args, **kwargs)
  File "C:\Users\user\OneDrive\Desktop\Projects\databases_v1\databases_v1\work\views.py", line 132, in add_case
    ind.save()
  File "C:\Users\user\OneDrive\Desktop\Projects\databases_v1\venv\lib\site-packages\django\db\models\base.py", line 682, in save
    self._prepare_related_fields_for_save(operation_name='save')
  File "C:\Users\user\OneDrive\Desktop\Projects\databases_v1\venv\lib\site-packages\django\db\models\base.py", line 932, in _prepare_related_fields_for_save
    raise ValueError(
ValueError: save() prohibited to prevent data loss due to unsaved related object 'case'.
ERROR django.server "POST /work/add/ HTTP/1.1" 500 116029 2021-09-09 15:47:56,904
WARNING django.request Not Found: /favicon.ico 2021-09-09 16:00:49,299
WARNING django.server "GET /favicon.ico HTTP/1.1" 404 13991 2021-09-09 16:00:49,300
ERROR django.request Internal Server Error: /work/save/ 2021-09-09 16:02:59,150
Traceback (most recent call last):
  File "C:\Users\user\OneDrive\Desktop\Projects\databases_v1\venv\lib\site-packages\django\template\base.py", line 470, in parse
    compile_func = self.tags[command]
KeyError: 'static'

During handling of the above exception, another exception occurred:

Traceback (most recent call last):
  File "C:\Users\user\OneDrive\Desktop\Projects\databases_v1\venv\lib\site-packages\django\core\handlers\exception.py", line 47, in inner
    response = get_response(request)
  File "C:\Users\user\OneDrive\Desktop\Projects\databases_v1\venv\lib\site-packages\django\core\handlers\base.py", line 181, in _get_response
    response = wrapped_callback(request, *callback_args, **callback_kwargs)
  File "C:\Users\user\OneDrive\Desktop\Projects\databases_v1\databases_v1\work\views.py", line 1159, in individual_info_test_form_save
    return render(request, 'save.html')
  File "C:\Users\user\OneDrive\Desktop\Projects\databases_v1\venv\lib\site-packages\django\shortcuts.py", line 19, in render
    content = loader.render_to_string(template_name, context, request, using=using)
  File "C:\Users\user\OneDrive\Desktop\Projects\databases_v1\venv\lib\site-packages\django\template\loader.py", line 61, in render_to_string
    template = get_template(template_name, using=using)
  File "C:\Users\user\OneDrive\Desktop\Projects\databases_v1\venv\lib\site-packages\django\template\loader.py", line 15, in get_template
    return engine.get_template(template_name)
  File "C:\Users\user\OneDrive\Desktop\Projects\databases_v1\venv\lib\site-packages\django\template\backends\django.py", line 34, in get_template
    return Template(self.engine.get_template(template_name), self)
  File "C:\Users\user\OneDrive\Desktop\Projects\databases_v1\venv\lib\site-packages\django\template\engine.py", line 143, in get_template
    template, origin = self.find_template(template_name)
  File "C:\Users\user\OneDrive\Desktop\Projects\databases_v1\venv\lib\site-packages\django\template\engine.py", line 125, in find_template
    template = loader.get_template(name, skip=skip)
  File "C:\Users\user\OneDrive\Desktop\Projects\databases_v1\venv\lib\site-packages\django\template\loaders\base.py", line 29, in get_template
    return Template(
  File "C:\Users\user\OneDrive\Desktop\Projects\databases_v1\venv\lib\site-packages\django\template\base.py", line 155, in __init__
    self.nodelist = self.compile_nodelist()
  File "C:\Users\user\OneDrive\Desktop\Projects\databases_v1\venv\lib\site-packages\django\template\base.py", line 193, in compile_nodelist
    return parser.parse()
  File "C:\Users\user\OneDrive\Desktop\Projects\databases_v1\venv\lib\site-packages\django\template\base.py", line 472, in parse
    self.invalid_block_tag(token, command, parse_until)
  File "C:\Users\user\OneDrive\Desktop\Projects\databases_v1\venv\lib\site-packages\django\template\base.py", line 531, in invalid_block_tag
    raise self.error(
django.template.exceptions.TemplateSyntaxError: Invalid block tag on line 21: 'static'. Did you forget to register or load this tag?
ERROR django.server "GET /work/save/ HTTP/1.1" 500 148766 2021-09-09 16:02:59,182
WARNING django.request Not Found: /favicon.ico 2021-09-09 16:02:59,503
WARNING django.server "GET /favicon.ico HTTP/1.1" 404 13991 2021-09-09 16:02:59,504
WARNING django.request Not Found: /favicon.ico 2021-09-09 16:03:15,074
WARNING django.server "GET /favicon.ico HTTP/1.1" 404 13991 2021-09-09 16:03:15,074
WARNING django.request Not Found: /favicon.ico 2021-09-09 16:04:29,798
WARNING django.server "GET /favicon.ico HTTP/1.1" 404 13991 2021-09-09 16:04:29,798
WARNING django.request Not Found: /favicon.ico 2021-09-09 16:08:30,500
WARNING django.server "GET /favicon.ico HTTP/1.1" 404 13991 2021-09-09 16:08:30,500
WARNING django.request Not Found: /favicon.ico 2021-09-09 16:09:09,944
WARNING django.server "GET /favicon.ico HTTP/1.1" 404 13991 2021-09-09 16:09:09,946
WARNING django.server "POST /work/save/ HTTP/1.1" 403 13016 2021-09-09 16:09:13,767
WARNING django.request Not Found: /favicon.ico 2021-09-09 16:09:29,893
WARNING django.server "GET /favicon.ico HTTP/1.1" 404 13991 2021-09-09 16:09:29,893
WARNING django.request Not Found: /favicon.ico 2021-09-09 16:10:11,546
WARNING django.server "GET /favicon.ico HTTP/1.1" 404 13991 2021-09-09 16:10:11,546
WARNING django.request Not Found: /favicon.ico 2021-09-09 16:10:47,511
WARNING django.server "GET /favicon.ico HTTP/1.1" 404 13991 2021-09-09 16:10:47,511
WARNING django.request Not Found: /favicon.ico 2021-09-09 16:11:32,900
WARNING django.server "GET /favicon.ico HTTP/1.1" 404 13991 2021-09-09 16:11:32,902
WARNING django.request Not Found: /favicon.ico 2021-09-09 16:11:50,587
WARNING django.server "GET /favicon.ico HTTP/1.1" 404 13991 2021-09-09 16:11:50,588
ERROR django.request Internal Server Error: /work/save/ 2021-09-09 16:12:13,389
Traceback (most recent call last):
  File "C:\Users\user\OneDrive\Desktop\Projects\databases_v1\venv\lib\site-packages\django\core\handlers\exception.py", line 47, in inner
    response = get_response(request)
  File "C:\Users\user\OneDrive\Desktop\Projects\databases_v1\venv\lib\site-packages\django\core\handlers\base.py", line 181, in _get_response
    response = wrapped_callback(request, *callback_args, **callback_kwargs)
  File "C:\Users\user\OneDrive\Desktop\Projects\databases_v1\databases_v1\work\views.py", line 1161, in individual_info_test_form_save
    print(individualFormSet.cleaned_data)
  File "C:\Users\user\OneDrive\Desktop\Projects\databases_v1\venv\lib\site-packages\django\forms\formsets.py", line 225, in cleaned_data
    raise AttributeError("'%s' object has no attribute 'cleaned_data'" % self.__class__.__name__)
AttributeError: 'IndividualInfoFormFormSet' object has no attribute 'cleaned_data'
ERROR django.server "POST /work/save/ HTTP/1.1" 500 85425 2021-09-09 16:12:13,431
WARNING django.request Not Found: /favicon.ico 2021-09-09 16:12:13,684
WARNING django.server "GET /favicon.ico HTTP/1.1" 404 13991 2021-09-09 16:12:13,684
WARNING django.request Not Found: /favicon.ico 2021-09-09 16:12:30,917
WARNING django.server "GET /favicon.ico HTTP/1.1" 404 13991 2021-09-09 16:12:30,917
WARNING django.request Not Found: /favicon.ico 2021-09-09 16:13:39,723
WARNING django.server "GET /favicon.ico HTTP/1.1" 404 13991 2021-09-09 16:13:39,723
WARNING django.request Not Found: /favicon.ico 2021-09-09 16:15:16,870
WARNING django.server "GET /favicon.ico HTTP/1.1" 404 13991 2021-09-09 16:15:16,870
ERROR django.request Internal Server Error: /work/save/ 2021-09-09 16:19:23,310
Traceback (most recent call last):
  File "C:\Users\user\OneDrive\Desktop\Projects\databases_v1\venv\lib\site-packages\django\core\handlers\exception.py", line 47, in inner
    response = get_response(request)
  File "C:\Users\user\OneDrive\Desktop\Projects\databases_v1\venv\lib\site-packages\django\core\handlers\base.py", line 181, in _get_response
    response = wrapped_callback(request, *callback_args, **callback_kwargs)
  File "C:\Users\user\OneDrive\Desktop\Projects\databases_v1\databases_v1\work\views.py", line 1168, in individual_info_test_form_save
    individualFormSet.extra_forms = 5
AttributeError: can't set attribute
ERROR django.server "POST /work/save/ HTTP/1.1" 500 87786 2021-09-09 16:19:23,354
WARNING django.request Not Found: /favicon.ico 2021-09-09 16:19:23,528
WARNING django.server "GET /favicon.ico HTTP/1.1" 404 13991 2021-09-09 16:19:23,530
WARNING django.request Not Found: /favicon.ico 2021-09-09 16:19:42,355
WARNING django.server "GET /favicon.ico HTTP/1.1" 404 13991 2021-09-09 16:19:42,356
WARNING django.request Not Found: /favicon.ico 2021-09-09 16:19:50,596
WARNING django.server "GET /favicon.ico HTTP/1.1" 404 13991 2021-09-09 16:19:50,597
WARNING django.request Not Found: /favicon.ico 2021-09-09 16:19:59,740
WARNING django.server "GET /favicon.ico HTTP/1.1" 404 13991 2021-09-09 16:19:59,742
WARNING django.request Not Found: /favicon.ico 2021-09-09 16:22:31,479
WARNING django.server "GET /favicon.ico HTTP/1.1" 404 13991 2021-09-09 16:22:31,479
WARNING django.request Not Found: /favicon.ico 2021-09-09 16:22:51,277
WARNING django.server "GET /favicon.ico HTTP/1.1" 404 13991 2021-09-09 16:22:51,278
WARNING django.request Not Found: /favicon.ico 2021-09-09 16:25:01,432
WARNING django.server "GET /favicon.ico HTTP/1.1" 404 13991 2021-09-09 16:25:01,433
WARNING django.request Not Found: /favicon.ico 2021-09-09 16:25:08,489
WARNING django.server "GET /favicon.ico HTTP/1.1" 404 13991 2021-09-09 16:25:08,490
WARNING django.request Not Found: /favicon.ico 2021-09-09 16:27:36,505
WARNING django.server "GET /favicon.ico HTTP/1.1" 404 13991 2021-09-09 16:27:36,505
WARNING django.request Not Found: /favicon.ico 2021-09-09 16:32:51,473
WARNING django.server "GET /favicon.ico HTTP/1.1" 404 13991 2021-09-09 16:32:51,473
WARNING django.request Not Found: /work/sa 2021-09-09 16:34:05,253
WARNING django.server "GET /work/sa HTTP/1.1" 404 17424 2021-09-09 16:34:05,253
ERROR django.request Internal Server Error: /work/add/ 2021-09-09 16:40:48,556
Traceback (most recent call last):
  File "C:\Users\user\OneDrive\Desktop\Projects\databases_v1\venv\lib\site-packages\django\core\handlers\exception.py", line 47, in inner
    response = get_response(request)
  File "C:\Users\user\OneDrive\Desktop\Projects\databases_v1\venv\lib\site-packages\django\core\handlers\base.py", line 181, in _get_response
    response = wrapped_callback(request, *callback_args, **callback_kwargs)
  File "C:\Users\user\OneDrive\Desktop\Projects\databases_v1\venv\lib\site-packages\django\contrib\auth\decorators.py", line 21, in _wrapped_view
    return view_func(request, *args, **kwargs)
  File "C:\Users\user\OneDrive\Desktop\Projects\databases_v1\databases_v1\work\views.py", line 126, in add_case
    ind.save()
  File "C:\Users\user\OneDrive\Desktop\Projects\databases_v1\venv\lib\site-packages\django\db\models\base.py", line 682, in save
    self._prepare_related_fields_for_save(operation_name='save')
  File "C:\Users\user\OneDrive\Desktop\Projects\databases_v1\venv\lib\site-packages\django\db\models\base.py", line 932, in _prepare_related_fields_for_save
    raise ValueError(
ValueError: save() prohibited to prevent data loss due to unsaved related object 'case'.
ERROR django.server "POST /work/add/ HTTP/1.1" 500 115751 2021-09-09 16:40:48,674
ERROR django.request Internal Server Error: /work/add/ 2021-09-09 16:41:07,544
Traceback (most recent call last):
  File "C:\Users\user\OneDrive\Desktop\Projects\databases_v1\venv\lib\site-packages\django\db\backends\utils.py", line 84, in _execute
    return self.cursor.execute(sql, params)
  File "C:\Users\user\OneDrive\Desktop\Projects\databases_v1\venv\lib\site-packages\django\db\backends\sqlite3\base.py", line 423, in execute
    return Database.Cursor.execute(self, query, params)
sqlite3.IntegrityError: NOT NULL constraint failed: work_individualinfo.is_official

The above exception was the direct cause of the following exception:

Traceback (most recent call last):
  File "C:\Users\user\OneDrive\Desktop\Projects\databases_v1\venv\lib\site-packages\django\core\handlers\exception.py", line 47, in inner
    response = get_response(request)
  File "C:\Users\user\OneDrive\Desktop\Projects\databases_v1\venv\lib\site-packages\django\core\handlers\base.py", line 181, in _get_response
    response = wrapped_callback(request, *callback_args, **callback_kwargs)
  File "C:\Users\user\OneDrive\Desktop\Projects\databases_v1\venv\lib\site-packages\django\contrib\auth\decorators.py", line 21, in _wrapped_view
    return view_func(request, *args, **kwargs)
  File "C:\Users\user\OneDrive\Desktop\Projects\databases_v1\databases_v1\work\views.py", line 126, in add_case
    ind.save()
  File "C:\Users\user\OneDrive\Desktop\Projects\databases_v1\venv\lib\site-packages\django\db\models\base.py", line 726, in save
    self.save_base(using=using, force_insert=force_insert,
  File "C:\Users\user\OneDrive\Desktop\Projects\databases_v1\venv\lib\site-packages\django\db\models\base.py", line 763, in save_base
    updated = self._save_table(
  File "C:\Users\user\OneDrive\Desktop\Projects\databases_v1\venv\lib\site-packages\django\db\models\base.py", line 868, in _save_table
    results = self._do_insert(cls._base_manager, using, fields, returning_fields, raw)
  File "C:\Users\user\OneDrive\Desktop\Projects\databases_v1\venv\lib\site-packages\django\db\models\base.py", line 906, in _do_insert
    return manager._insert(
  File "C:\Users\user\OneDrive\Desktop\Projects\databases_v1\venv\lib\site-packages\django\db\models\manager.py", line 85, in manager_method
    return getattr(self.get_queryset(), name)(*args, **kwargs)
  File "C:\Users\user\OneDrive\Desktop\Projects\databases_v1\venv\lib\site-packages\django\db\models\query.py", line 1270, in _insert
    return query.get_compiler(using=using).execute_sql(returning_fields)
  File "C:\Users\user\OneDrive\Desktop\Projects\databases_v1\venv\lib\site-packages\django\db\models\sql\compiler.py", line 1416, in execute_sql
    cursor.execute(sql, params)
  File "C:\Users\user\OneDrive\Desktop\Projects\databases_v1\venv\lib\site-packages\debug_toolbar\panels\sql\tracking.py", line 198, in execute
    return self._record(self.cursor.execute, sql, params)
  File "C:\Users\user\OneDrive\Desktop\Projects\databases_v1\venv\lib\site-packages\debug_toolbar\panels\sql\tracking.py", line 133, in _record
    return method(sql, params)
  File "C:\Users\user\OneDrive\Desktop\Projects\databases_v1\venv\lib\site-packages\django\db\backends\utils.py", line 98, in execute
    return super().execute(sql, params)
  File "C:\Users\user\OneDrive\Desktop\Projects\databases_v1\venv\lib\site-packages\django\db\backends\utils.py", line 66, in execute
    return self._execute_with_wrappers(sql, params, many=False, executor=self._execute)
  File "C:\Users\user\OneDrive\Desktop\Projects\databases_v1\venv\lib\site-packages\django\db\backends\utils.py", line 75, in _execute_with_wrappers
    return executor(sql, params, many, context)
  File "C:\Users\user\OneDrive\Desktop\Projects\databases_v1\venv\lib\site-packages\django\db\backends\utils.py", line 84, in _execute
    return self.cursor.execute(sql, params)
  File "C:\Users\user\OneDrive\Desktop\Projects\databases_v1\venv\lib\site-packages\django\db\utils.py", line 90, in __exit__
    raise dj_exc_value.with_traceback(traceback) from exc_value
  File "C:\Users\user\OneDrive\Desktop\Projects\databases_v1\venv\lib\site-packages\django\db\backends\utils.py", line 84, in _execute
    return self.cursor.execute(sql, params)
  File "C:\Users\user\OneDrive\Desktop\Projects\databases_v1\venv\lib\site-packages\django\db\backends\sqlite3\base.py", line 423, in execute
    return Database.Cursor.execute(self, query, params)
django.db.utils.IntegrityError: NOT NULL constraint failed: work_individualinfo.is_official
ERROR django.server "POST /work/add/ HTTP/1.1" 500 208199 2021-09-09 16:41:07,680
ERROR django.request Internal Server Error: /work/add/ 2021-09-09 16:41:44,416
Traceback (most recent call last):
  File "C:\Users\user\OneDrive\Desktop\Projects\databases_v1\venv\lib\site-packages\django\db\backends\utils.py", line 84, in _execute
    return self.cursor.execute(sql, params)
  File "C:\Users\user\OneDrive\Desktop\Projects\databases_v1\venv\lib\site-packages\django\db\backends\sqlite3\base.py", line 423, in execute
    return Database.Cursor.execute(self, query, params)
sqlite3.IntegrityError: NOT NULL constraint failed: work_individualinfo.case_id

The above exception was the direct cause of the following exception:

Traceback (most recent call last):
  File "C:\Users\user\OneDrive\Desktop\Projects\databases_v1\venv\lib\site-packages\django\core\handlers\exception.py", line 47, in inner
    response = get_response(request)
  File "C:\Users\user\OneDrive\Desktop\Projects\databases_v1\venv\lib\site-packages\django\core\handlers\base.py", line 181, in _get_response
    response = wrapped_callback(request, *callback_args, **callback_kwargs)
  File "C:\Users\user\OneDrive\Desktop\Projects\databases_v1\venv\lib\site-packages\django\contrib\auth\decorators.py", line 21, in _wrapped_view
    return view_func(request, *args, **kwargs)
  File "C:\Users\user\OneDrive\Desktop\Projects\databases_v1\databases_v1\work\views.py", line 126, in add_case
    ind.save()
  File "C:\Users\user\OneDrive\Desktop\Projects\databases_v1\venv\lib\site-packages\django\db\models\base.py", line 726, in save
    self.save_base(using=using, force_insert=force_insert,
  File "C:\Users\user\OneDrive\Desktop\Projects\databases_v1\venv\lib\site-packages\django\db\models\base.py", line 763, in save_base
    updated = self._save_table(
  File "C:\Users\user\OneDrive\Desktop\Projects\databases_v1\venv\lib\site-packages\django\db\models\base.py", line 868, in _save_table
    results = self._do_insert(cls._base_manager, using, fields, returning_fields, raw)
  File "C:\Users\user\OneDrive\Desktop\Projects\databases_v1\venv\lib\site-packages\django\db\models\base.py", line 906, in _do_insert
    return manager._insert(
  File "C:\Users\user\OneDrive\Desktop\Projects\databases_v1\venv\lib\site-packages\django\db\models\manager.py", line 85, in manager_method
    return getattr(self.get_queryset(), name)(*args, **kwargs)
  File "C:\Users\user\OneDrive\Desktop\Projects\databases_v1\venv\lib\site-packages\django\db\models\query.py", line 1270, in _insert
    return query.get_compiler(using=using).execute_sql(returning_fields)
  File "C:\Users\user\OneDrive\Desktop\Projects\databases_v1\venv\lib\site-packages\django\db\models\sql\compiler.py", line 1416, in execute_sql
    cursor.execute(sql, params)
  File "C:\Users\user\OneDrive\Desktop\Projects\databases_v1\venv\lib\site-packages\debug_toolbar\panels\sql\tracking.py", line 198, in execute
    return self._record(self.cursor.execute, sql, params)
  File "C:\Users\user\OneDrive\Desktop\Projects\databases_v1\venv\lib\site-packages\debug_toolbar\panels\sql\tracking.py", line 133, in _record
    return method(sql, params)
  File "C:\Users\user\OneDrive\Desktop\Projects\databases_v1\venv\lib\site-packages\django\db\backends\utils.py", line 98, in execute
    return super().execute(sql, params)
  File "C:\Users\user\OneDrive\Desktop\Projects\databases_v1\venv\lib\site-packages\django\db\backends\utils.py", line 66, in execute
    return self._execute_with_wrappers(sql, params, many=False, executor=self._execute)
  File "C:\Users\user\OneDrive\Desktop\Projects\databases_v1\venv\lib\site-packages\django\db\backends\utils.py", line 75, in _execute_with_wrappers
    return executor(sql, params, many, context)
  File "C:\Users\user\OneDrive\Desktop\Projects\databases_v1\venv\lib\site-packages\django\db\backends\utils.py", line 84, in _execute
    return self.cursor.execute(sql, params)
  File "C:\Users\user\OneDrive\Desktop\Projects\databases_v1\venv\lib\site-packages\django\db\utils.py", line 90, in __exit__
    raise dj_exc_value.with_traceback(traceback) from exc_value
  File "C:\Users\user\OneDrive\Desktop\Projects\databases_v1\venv\lib\site-packages\django\db\backends\utils.py", line 84, in _execute
    return self.cursor.execute(sql, params)
  File "C:\Users\user\OneDrive\Desktop\Projects\databases_v1\venv\lib\site-packages\django\db\backends\sqlite3\base.py", line 423, in execute
    return Database.Cursor.execute(self, query, params)
django.db.utils.IntegrityError: NOT NULL constraint failed: work_individualinfo.case_id
ERROR django.server "POST /work/add/ HTTP/1.1" 500 208165 2021-09-09 16:41:44,593
ERROR django.request Internal Server Error: /work/add/ 2021-09-09 16:42:17,231
Traceback (most recent call last):
  File "C:\Users\user\OneDrive\Desktop\Projects\databases_v1\venv\lib\site-packages\django\db\backends\utils.py", line 84, in _execute
    return self.cursor.execute(sql, params)
  File "C:\Users\user\OneDrive\Desktop\Projects\databases_v1\venv\lib\site-packages\django\db\backends\sqlite3\base.py", line 423, in execute
    return Database.Cursor.execute(self, query, params)
sqlite3.IntegrityError: NOT NULL constraint failed: work_individualinfo.case_id

The above exception was the direct cause of the following exception:

Traceback (most recent call last):
  File "C:\Users\user\OneDrive\Desktop\Projects\databases_v1\venv\lib\site-packages\django\core\handlers\exception.py", line 47, in inner
    response = get_response(request)
  File "C:\Users\user\OneDrive\Desktop\Projects\databases_v1\venv\lib\site-packages\django\core\handlers\base.py", line 181, in _get_response
    response = wrapped_callback(request, *callback_args, **callback_kwargs)
  File "C:\Users\user\OneDrive\Desktop\Projects\databases_v1\venv\lib\site-packages\django\contrib\auth\decorators.py", line 21, in _wrapped_view
    return view_func(request, *args, **kwargs)
  File "C:\Users\user\OneDrive\Desktop\Projects\databases_v1\databases_v1\work\views.py", line 127, in add_case
    ind.save()
  File "C:\Users\user\OneDrive\Desktop\Projects\databases_v1\venv\lib\site-packages\django\db\models\base.py", line 726, in save
    self.save_base(using=using, force_insert=force_insert,
  File "C:\Users\user\OneDrive\Desktop\Projects\databases_v1\venv\lib\site-packages\django\db\models\base.py", line 763, in save_base
    updated = self._save_table(
  File "C:\Users\user\OneDrive\Desktop\Projects\databases_v1\venv\lib\site-packages\django\db\models\base.py", line 868, in _save_table
    results = self._do_insert(cls._base_manager, using, fields, returning_fields, raw)
  File "C:\Users\user\OneDrive\Desktop\Projects\databases_v1\venv\lib\site-packages\django\db\models\base.py", line 906, in _do_insert
    return manager._insert(
  File "C:\Users\user\OneDrive\Desktop\Projects\databases_v1\venv\lib\site-packages\django\db\models\manager.py", line 85, in manager_method
    return getattr(self.get_queryset(), name)(*args, **kwargs)
  File "C:\Users\user\OneDrive\Desktop\Projects\databases_v1\venv\lib\site-packages\django\db\models\query.py", line 1270, in _insert
    return query.get_compiler(using=using).execute_sql(returning_fields)
  File "C:\Users\user\OneDrive\Desktop\Projects\databases_v1\venv\lib\site-packages\django\db\models\sql\compiler.py", line 1416, in execute_sql
    cursor.execute(sql, params)
  File "C:\Users\user\OneDrive\Desktop\Projects\databases_v1\venv\lib\site-packages\debug_toolbar\panels\sql\tracking.py", line 198, in execute
    return self._record(self.cursor.execute, sql, params)
  File "C:\Users\user\OneDrive\Desktop\Projects\databases_v1\venv\lib\site-packages\debug_toolbar\panels\sql\tracking.py", line 133, in _record
    return method(sql, params)
  File "C:\Users\user\OneDrive\Desktop\Projects\databases_v1\venv\lib\site-packages\django\db\backends\utils.py", line 98, in execute
    return super().execute(sql, params)
  File "C:\Users\user\OneDrive\Desktop\Projects\databases_v1\venv\lib\site-packages\django\db\backends\utils.py", line 66, in execute
    return self._execute_with_wrappers(sql, params, many=False, executor=self._execute)
  File "C:\Users\user\OneDrive\Desktop\Projects\databases_v1\venv\lib\site-packages\django\db\backends\utils.py", line 75, in _execute_with_wrappers
    return executor(sql, params, many, context)
  File "C:\Users\user\OneDrive\Desktop\Projects\databases_v1\venv\lib\site-packages\django\db\backends\utils.py", line 84, in _execute
    return self.cursor.execute(sql, params)
  File "C:\Users\user\OneDrive\Desktop\Projects\databases_v1\venv\lib\site-packages\django\db\utils.py", line 90, in __exit__
    raise dj_exc_value.with_traceback(traceback) from exc_value
  File "C:\Users\user\OneDrive\Desktop\Projects\databases_v1\venv\lib\site-packages\django\db\backends\utils.py", line 84, in _execute
    return self.cursor.execute(sql, params)
  File "C:\Users\user\OneDrive\Desktop\Projects\databases_v1\venv\lib\site-packages\django\db\backends\sqlite3\base.py", line 423, in execute
    return Database.Cursor.execute(self, query, params)
django.db.utils.IntegrityError: NOT NULL constraint failed: work_individualinfo.case_id
ERROR django.server "POST /work/add/ HTTP/1.1" 500 208193 2021-09-09 16:42:17,370
WARNING django.request Not Found: /favicon.ico 2021-09-09 16:44:11,373
WARNING django.server "GET /favicon.ico HTTP/1.1" 404 13991 2021-09-09 16:44:11,374
WARNING django.request Not Found: /favicon.ico 2021-09-09 16:46:19,751
WARNING django.server "GET /favicon.ico HTTP/1.1" 404 13991 2021-09-09 16:46:19,752
