ERROR django.request Internal Server Error: /work/test-data/ 2021-10-21 10:50:41,638
Traceback (most recent call last):
  File "D:\Users\ntabyldieva\databases_v1\venv\lib\site-packages\django\core\handlers\exception.py", line 47, in inner
    response = get_response(request)
  File "D:\Users\ntabyldieva\databases_v1\venv\lib\site-packages\django\core\handlers\base.py", line 181, in _get_response
    response = wrapped_callback(request, *callback_args, **callback_kwargs)
  File "D:\Users\ntabyldieva\databases_v1\venv\lib\site-packages\django\views\decorators\csrf.py", line 54, in wrapped_view
    return view_func(*args, **kwargs)
  File "D:\Users\ntabyldieva\databases_v1\venv\lib\site-packages\django\views\generic\base.py", line 70, in view
    return self.dispatch(request, *args, **kwargs)
  File "D:\Users\ntabyldieva\databases_v1\venv\lib\site-packages\rest_framework\views.py", line 509, in dispatch
    response = self.handle_exception(exc)
  File "D:\Users\ntabyldieva\databases_v1\venv\lib\site-packages\rest_framework\views.py", line 469, in handle_exception
    self.raise_uncaught_exception(exc)
  File "D:\Users\ntabyldieva\databases_v1\venv\lib\site-packages\rest_framework\views.py", line 480, in raise_uncaught_exception
    raise exc
  File "D:\Users\ntabyldieva\databases_v1\venv\lib\site-packages\rest_framework\views.py", line 506, in dispatch
    response = handler(request, *args, **kwargs)
  File "D:\Users\ntabyldieva\databases_v1\work\test_get_data.py", line 35, in get
    print(serializer.data)
  File "D:\Users\ntabyldieva\databases_v1\venv\lib\site-packages\rest_framework\serializers.py", line 745, in data
    ret = super().data
  File "D:\Users\ntabyldieva\databases_v1\venv\lib\site-packages\rest_framework\serializers.py", line 246, in data
    self._data = self.to_representation(self.instance)
  File "D:\Users\ntabyldieva\databases_v1\venv\lib\site-packages\rest_framework\serializers.py", line 663, in to_representation
    return [
  File "D:\Users\ntabyldieva\databases_v1\venv\lib\site-packages\rest_framework\serializers.py", line 664, in <listcomp>
    self.child.to_representation(item) for item in iterable
  File "D:\Users\ntabyldieva\databases_v1\work\test_serializers.py", line 158, in to_representation
    get_representation(representation, 8, ProhibitionOfForcedLaborSerializers, ProhibitionOfForcedLabor)
  File "D:\Users\ntabyldieva\databases_v1\work\test_serializers.py", line 23, in get_representation
    representation['child_item'] = serializer(model.objects.all(), many=True).data
  File "D:\Users\ntabyldieva\databases_v1\venv\lib\site-packages\rest_framework\serializers.py", line 745, in data
    ret = super().data
  File "D:\Users\ntabyldieva\databases_v1\venv\lib\site-packages\rest_framework\serializers.py", line 246, in data
    self._data = self.to_representation(self.instance)
  File "D:\Users\ntabyldieva\databases_v1\venv\lib\site-packages\rest_framework\serializers.py", line 663, in to_representation
    return [
  File "D:\Users\ntabyldieva\databases_v1\venv\lib\site-packages\rest_framework\serializers.py", line 664, in <listcomp>
    self.child.to_representation(item) for item in iterable
  File "D:\Users\ntabyldieva\databases_v1\work\test_serializers.py", line 127, in to_representation
    get_representation(representation, 2, "governmentCoercion", " освенное принуждение государством к труду",
TypeError: get_representation() takes 4 positional arguments but 6 were given
ERROR django.server "GET /work/test-data/ HTTP/1.1" 500 172465 2021-10-21 10:50:41,643
ERROR django.request Internal Server Error: /work/test-data/ 2021-10-21 10:50:43,189
Traceback (most recent call last):
  File "D:\Users\ntabyldieva\databases_v1\venv\lib\site-packages\django\core\handlers\exception.py", line 47, in inner
    response = get_response(request)
  File "D:\Users\ntabyldieva\databases_v1\venv\lib\site-packages\django\core\handlers\base.py", line 181, in _get_response
    response = wrapped_callback(request, *callback_args, **callback_kwargs)
  File "D:\Users\ntabyldieva\databases_v1\venv\lib\site-packages\django\views\decorators\csrf.py", line 54, in wrapped_view
    return view_func(*args, **kwargs)
  File "D:\Users\ntabyldieva\databases_v1\venv\lib\site-packages\django\views\generic\base.py", line 70, in view
    return self.dispatch(request, *args, **kwargs)
  File "D:\Users\ntabyldieva\databases_v1\venv\lib\site-packages\rest_framework\views.py", line 509, in dispatch
    response = self.handle_exception(exc)
  File "D:\Users\ntabyldieva\databases_v1\venv\lib\site-packages\rest_framework\views.py", line 469, in handle_exception
    self.raise_uncaught_exception(exc)
  File "D:\Users\ntabyldieva\databases_v1\venv\lib\site-packages\rest_framework\views.py", line 480, in raise_uncaught_exception
    raise exc
  File "D:\Users\ntabyldieva\databases_v1\venv\lib\site-packages\rest_framework\views.py", line 506, in dispatch
    response = handler(request, *args, **kwargs)
  File "D:\Users\ntabyldieva\databases_v1\work\test_get_data.py", line 35, in get
    print(serializer.data)
  File "D:\Users\ntabyldieva\databases_v1\venv\lib\site-packages\rest_framework\serializers.py", line 745, in data
    ret = super().data
  File "D:\Users\ntabyldieva\databases_v1\venv\lib\site-packages\rest_framework\serializers.py", line 246, in data
    self._data = self.to_representation(self.instance)
  File "D:\Users\ntabyldieva\databases_v1\venv\lib\site-packages\rest_framework\serializers.py", line 663, in to_representation
    return [
  File "D:\Users\ntabyldieva\databases_v1\venv\lib\site-packages\rest_framework\serializers.py", line 664, in <listcomp>
    self.child.to_representation(item) for item in iterable
  File "D:\Users\ntabyldieva\databases_v1\work\test_serializers.py", line 158, in to_representation
    get_representation(representation, 8, ProhibitionOfForcedLaborSerializers, ProhibitionOfForcedLabor)
  File "D:\Users\ntabyldieva\databases_v1\work\test_serializers.py", line 23, in get_representation
    representation['child_item'] = serializer(model.objects.all(), many=True).data
  File "D:\Users\ntabyldieva\databases_v1\venv\lib\site-packages\rest_framework\serializers.py", line 745, in data
    ret = super().data
  File "D:\Users\ntabyldieva\databases_v1\venv\lib\site-packages\rest_framework\serializers.py", line 246, in data
    self._data = self.to_representation(self.instance)
  File "D:\Users\ntabyldieva\databases_v1\venv\lib\site-packages\rest_framework\serializers.py", line 663, in to_representation
    return [
  File "D:\Users\ntabyldieva\databases_v1\venv\lib\site-packages\rest_framework\serializers.py", line 664, in <listcomp>
    self.child.to_representation(item) for item in iterable
  File "D:\Users\ntabyldieva\databases_v1\work\test_serializers.py", line 127, in to_representation
    get_representation(representation, 2, "governmentCoercion", " освенное принуждение государством к труду",
TypeError: get_representation() takes 4 positional arguments but 6 were given
ERROR django.server "GET /work/test-data/ HTTP/1.1" 500 172465 2021-10-21 10:50:43,192
ERROR django.request Internal Server Error: /work/test-data/ 2021-10-21 10:51:24,081
Traceback (most recent call last):
  File "D:\Users\ntabyldieva\databases_v1\venv\lib\site-packages\django\core\handlers\exception.py", line 47, in inner
    response = get_response(request)
  File "D:\Users\ntabyldieva\databases_v1\venv\lib\site-packages\django\core\handlers\base.py", line 181, in _get_response
    response = wrapped_callback(request, *callback_args, **callback_kwargs)
  File "D:\Users\ntabyldieva\databases_v1\venv\lib\site-packages\django\views\decorators\csrf.py", line 54, in wrapped_view
    return view_func(*args, **kwargs)
  File "D:\Users\ntabyldieva\databases_v1\venv\lib\site-packages\django\views\generic\base.py", line 70, in view
    return self.dispatch(request, *args, **kwargs)
  File "D:\Users\ntabyldieva\databases_v1\venv\lib\site-packages\rest_framework\views.py", line 509, in dispatch
    response = self.handle_exception(exc)
  File "D:\Users\ntabyldieva\databases_v1\venv\lib\site-packages\rest_framework\views.py", line 469, in handle_exception
    self.raise_uncaught_exception(exc)
  File "D:\Users\ntabyldieva\databases_v1\venv\lib\site-packages\rest_framework\views.py", line 480, in raise_uncaught_exception
    raise exc
  File "D:\Users\ntabyldieva\databases_v1\venv\lib\site-packages\rest_framework\views.py", line 506, in dispatch
    response = handler(request, *args, **kwargs)
  File "D:\Users\ntabyldieva\databases_v1\work\test_get_data.py", line 35, in get
    print(serializer.data)
  File "D:\Users\ntabyldieva\databases_v1\venv\lib\site-packages\rest_framework\serializers.py", line 745, in data
    ret = super().data
  File "D:\Users\ntabyldieva\databases_v1\venv\lib\site-packages\rest_framework\serializers.py", line 246, in data
    self._data = self.to_representation(self.instance)
  File "D:\Users\ntabyldieva\databases_v1\venv\lib\site-packages\rest_framework\serializers.py", line 663, in to_representation
    return [
  File "D:\Users\ntabyldieva\databases_v1\venv\lib\site-packages\rest_framework\serializers.py", line 664, in <listcomp>
    self.child.to_representation(item) for item in iterable
  File "D:\Users\ntabyldieva\databases_v1\work\test_serializers.py", line 158, in to_representation
    get_representation(representation, 8, ProhibitionOfForcedLaborSerializers, ProhibitionOfForcedLabor)
  File "D:\Users\ntabyldieva\databases_v1\work\test_serializers.py", line 23, in get_representation
    representation['child_item'] = serializer(model.objects.all(), many=True).data
  File "D:\Users\ntabyldieva\databases_v1\venv\lib\site-packages\rest_framework\serializers.py", line 745, in data
    ret = super().data
  File "D:\Users\ntabyldieva\databases_v1\venv\lib\site-packages\rest_framework\serializers.py", line 246, in data
    self._data = self.to_representation(self.instance)
  File "D:\Users\ntabyldieva\databases_v1\venv\lib\site-packages\rest_framework\serializers.py", line 663, in to_representation
    return [
  File "D:\Users\ntabyldieva\databases_v1\venv\lib\site-packages\rest_framework\serializers.py", line 664, in <listcomp>
    self.child.to_representation(item) for item in iterable
  File "D:\Users\ntabyldieva\databases_v1\work\test_serializers.py", line 127, in to_representation
    #     get_representation(representation, 2, "governmentCoercion", " освенное принуждение государством к труду",
TypeError: get_representation() takes 4 positional arguments but 6 were given
ERROR django.server "GET /work/test-data/ HTTP/1.1" 500 172491 2021-10-21 10:51:24,084
ERROR django.request Internal Server Error: /work/test-data/ 2021-10-21 11:15:36,912
Traceback (most recent call last):
  File "D:\Users\ntabyldieva\databases_v1\venv\lib\site-packages\django\core\handlers\exception.py", line 47, in inner
    response = get_response(request)
  File "D:\Users\ntabyldieva\databases_v1\venv\lib\site-packages\django\core\handlers\base.py", line 181, in _get_response
    response = wrapped_callback(request, *callback_args, **callback_kwargs)
  File "D:\Users\ntabyldieva\databases_v1\venv\lib\site-packages\django\views\decorators\csrf.py", line 54, in wrapped_view
    return view_func(*args, **kwargs)
  File "D:\Users\ntabyldieva\databases_v1\venv\lib\site-packages\django\views\generic\base.py", line 70, in view
    return self.dispatch(request, *args, **kwargs)
  File "D:\Users\ntabyldieva\databases_v1\venv\lib\site-packages\rest_framework\views.py", line 509, in dispatch
    response = self.handle_exception(exc)
  File "D:\Users\ntabyldieva\databases_v1\venv\lib\site-packages\rest_framework\views.py", line 469, in handle_exception
    self.raise_uncaught_exception(exc)
  File "D:\Users\ntabyldieva\databases_v1\venv\lib\site-packages\rest_framework\views.py", line 480, in raise_uncaught_exception
    raise exc
  File "D:\Users\ntabyldieva\databases_v1\venv\lib\site-packages\rest_framework\views.py", line 506, in dispatch
    response = handler(request, *args, **kwargs)
  File "D:\Users\ntabyldieva\databases_v1\work\test_get_data.py", line 35, in get
    print(serializer.data)
  File "D:\Users\ntabyldieva\databases_v1\venv\lib\site-packages\rest_framework\serializers.py", line 745, in data
    ret = super().data
  File "D:\Users\ntabyldieva\databases_v1\venv\lib\site-packages\rest_framework\serializers.py", line 246, in data
    self._data = self.to_representation(self.instance)
  File "D:\Users\ntabyldieva\databases_v1\venv\lib\site-packages\rest_framework\serializers.py", line 663, in to_representation
    return [
  File "D:\Users\ntabyldieva\databases_v1\venv\lib\site-packages\rest_framework\serializers.py", line 664, in <listcomp>
    self.child.to_representation(item) for item in iterable
  File "D:\Users\ntabyldieva\databases_v1\work\test_serializers.py", line 158, in to_representation
  File "D:\Users\ntabyldieva\databases_v1\work\test_serializers.py", line 23, in get_representation
    representation['child'] = True
  File "D:\Users\ntabyldieva\databases_v1\venv\lib\site-packages\rest_framework\serializers.py", line 745, in data
    ret = super().data
  File "D:\Users\ntabyldieva\databases_v1\venv\lib\site-packages\rest_framework\serializers.py", line 246, in data
    self._data = self.to_representation(self.instance)
  File "D:\Users\ntabyldieva\databases_v1\venv\lib\site-packages\rest_framework\serializers.py", line 663, in to_representation
    return [
  File "D:\Users\ntabyldieva\databases_v1\venv\lib\site-packages\rest_framework\serializers.py", line 664, in <listcomp>
    self.child.to_representation(item) for item in iterable
  File "D:\Users\ntabyldieva\databases_v1\work\test_serializers.py", line 127, in to_representation
TypeError: get_representation() takes 4 positional arguments but 6 were given
ERROR django.server "GET /work/test-data/ HTTP/1.1" 500 166350 2021-10-21 11:15:36,915
WARNING django.request Not Found: /favicon.ico 2021-10-21 12:14:29,867
WARNING django.server "GET /favicon.ico HTTP/1.1" 404 3524 2021-10-21 12:14:29,868
WARNING django.request Not Found: /favicon.ico 2021-10-21 12:14:35,436
WARNING django.server "GET /favicon.ico HTTP/1.1" 404 3524 2021-10-21 12:14:35,438
WARNING django.request Not Found: /favicon.ico 2021-10-21 12:14:37,045
WARNING django.server "GET /favicon.ico HTTP/1.1" 404 3524 2021-10-21 12:14:37,047
WARNING django.request Not Found: /favicon.ico 2021-10-21 12:14:49,208
WARNING django.server "GET /favicon.ico HTTP/1.1" 404 3524 2021-10-21 12:14:49,209
WARNING django.request Not Found: /favicon.ico 2021-10-21 12:14:50,159
WARNING django.server "GET /favicon.ico HTTP/1.1" 404 3524 2021-10-21 12:14:50,161
WARNING django.request Not Found: /favicon.ico 2021-10-21 12:14:50,855
WARNING django.server "GET /favicon.ico HTTP/1.1" 404 3524 2021-10-21 12:14:50,857
WARNING django.request Not Found: /favicon.ico 2021-10-21 12:14:51,918
WARNING django.server "GET /favicon.ico HTTP/1.1" 404 3524 2021-10-21 12:14:51,919
WARNING django.request Not Found: /favicon.ico 2021-10-21 12:14:52,230
WARNING django.server "GET /favicon.ico HTTP/1.1" 404 3524 2021-10-21 12:14:52,232
WARNING django.request Not Found: /favicon.ico 2021-10-21 12:14:52,494
WARNING django.server "GET /favicon.ico HTTP/1.1" 404 3524 2021-10-21 12:14:52,496
WARNING django.request Not Found: /favicon.ico 2021-10-21 12:14:52,676
WARNING django.server "GET /favicon.ico HTTP/1.1" 404 3524 2021-10-21 12:14:52,678
WARNING django.request Not Found: /favicon.ico 2021-10-21 12:14:52,877
WARNING django.server "GET /favicon.ico HTTP/1.1" 404 3524 2021-10-21 12:14:52,878
WARNING django.request Not Found: /favicon.ico 2021-10-21 12:14:53,070
WARNING django.server "GET /favicon.ico HTTP/1.1" 404 3524 2021-10-21 12:14:53,074
ERROR django.request Internal Server Error: /work/test-data/get/ 2021-10-21 13:50:53,750
Traceback (most recent call last):
  File "D:\Users\ntabyldieva\databases_v1\venv\lib\site-packages\django\db\models\fields\__init__.py", line 1823, in get_prep_value
    return int(value)
TypeError: int() argument must be a string, a bytes-like object or a number, not 'list'

The above exception was the direct cause of the following exception:

Traceback (most recent call last):
  File "D:\Users\ntabyldieva\databases_v1\venv\lib\site-packages\django\core\handlers\exception.py", line 47, in inner
    response = get_response(request)
  File "D:\Users\ntabyldieva\databases_v1\venv\lib\site-packages\django\core\handlers\base.py", line 181, in _get_response
    response = wrapped_callback(request, *callback_args, **callback_kwargs)
  File "D:\Users\ntabyldieva\databases_v1\venv\lib\site-packages\django\views\decorators\csrf.py", line 54, in wrapped_view
    return view_func(*args, **kwargs)
  File "D:\Users\ntabyldieva\databases_v1\venv\lib\site-packages\django\views\generic\base.py", line 70, in view
    return self.dispatch(request, *args, **kwargs)
  File "D:\Users\ntabyldieva\databases_v1\venv\lib\site-packages\rest_framework\views.py", line 509, in dispatch
    response = self.handle_exception(exc)
  File "D:\Users\ntabyldieva\databases_v1\venv\lib\site-packages\rest_framework\views.py", line 469, in handle_exception
    self.raise_uncaught_exception(exc)
  File "D:\Users\ntabyldieva\databases_v1\venv\lib\site-packages\rest_framework\views.py", line 480, in raise_uncaught_exception
    raise exc
  File "D:\Users\ntabyldieva\databases_v1\venv\lib\site-packages\rest_framework\views.py", line 506, in dispatch
    response = handler(request, *args, **kwargs)
  File "D:\Users\ntabyldieva\databases_v1\work\data_filter_api.py", line 68, in post
    queryset = Case.objects.filter(**dicts).values(*fields).annotate(count=Count('id'), procent=100 / Count('id'),)
  File "D:\Users\ntabyldieva\databases_v1\venv\lib\site-packages\django\db\models\manager.py", line 85, in manager_method
    return getattr(self.get_queryset(), name)(*args, **kwargs)
  File "D:\Users\ntabyldieva\databases_v1\venv\lib\site-packages\django\db\models\query.py", line 941, in filter
    return self._filter_or_exclude(False, args, kwargs)
  File "D:\Users\ntabyldieva\databases_v1\venv\lib\site-packages\django\db\models\query.py", line 961, in _filter_or_exclude
    clone._filter_or_exclude_inplace(negate, args, kwargs)
  File "D:\Users\ntabyldieva\databases_v1\venv\lib\site-packages\django\db\models\query.py", line 968, in _filter_or_exclude_inplace
    self._query.add_q(Q(*args, **kwargs))
  File "D:\Users\ntabyldieva\databases_v1\venv\lib\site-packages\django\db\models\sql\query.py", line 1391, in add_q
    clause, _ = self._add_q(q_object, self.used_aliases)
  File "D:\Users\ntabyldieva\databases_v1\venv\lib\site-packages\django\db\models\sql\query.py", line 1410, in _add_q
    child_clause, needed_inner = self.build_filter(
  File "D:\Users\ntabyldieva\databases_v1\venv\lib\site-packages\django\db\models\sql\query.py", line 1345, in build_filter
    condition = self.build_lookup(lookups, col, value)
  File "D:\Users\ntabyldieva\databases_v1\venv\lib\site-packages\django\db\models\sql\query.py", line 1191, in build_lookup
    lookup = lookup_class(lhs, rhs)
  File "D:\Users\ntabyldieva\databases_v1\venv\lib\site-packages\django\db\models\lookups.py", line 25, in __init__
    self.rhs = self.get_prep_lookup()
  File "D:\Users\ntabyldieva\databases_v1\venv\lib\site-packages\django\db\models\fields\related_lookups.py", line 117, in get_prep_lookup
    self.rhs = target_field.get_prep_value(self.rhs)
  File "D:\Users\ntabyldieva\databases_v1\venv\lib\site-packages\django\db\models\fields\__init__.py", line 1825, in get_prep_value
    raise e.__class__(
TypeError: Field 'id' expected a number but got [1].
ERROR django.server "POST /work/test-data/get/ HTTP/1.1" 500 152935 2021-10-21 13:50:53,756
WARNING django.request Not Found: /favicon.ico 2021-10-21 15:46:45,533
WARNING django.server "GET /favicon.ico HTTP/1.1" 404 3524 2021-10-21 15:46:45,550
WARNING django.request Not Found: /favicon.ico 2021-10-21 15:46:47,476
WARNING django.server "GET /favicon.ico HTTP/1.1" 404 3524 2021-10-21 15:46:47,478
ERROR django.request Internal Server Error: /work/test-data/get/ 2021-10-21 16:09:31,198
Traceback (most recent call last):
  File "D:\Users\ntabyldieva\databases_v1\venv\lib\site-packages\rest_framework\fields.py", line 457, in get_attribute
    return get_attribute(instance, self.source_attrs)
  File "D:\Users\ntabyldieva\databases_v1\venv\lib\site-packages\rest_framework\fields.py", line 95, in get_attribute
    instance = instance[attr]
KeyError: 'country'

During handling of the above exception, another exception occurred:

Traceback (most recent call last):
  File "D:\Users\ntabyldieva\databases_v1\venv\lib\site-packages\django\core\handlers\exception.py", line 47, in inner
    response = get_response(request)
  File "D:\Users\ntabyldieva\databases_v1\venv\lib\site-packages\django\core\handlers\base.py", line 181, in _get_response
    response = wrapped_callback(request, *callback_args, **callback_kwargs)
  File "D:\Users\ntabyldieva\databases_v1\venv\lib\site-packages\django\views\decorators\csrf.py", line 54, in wrapped_view
    return view_func(*args, **kwargs)
  File "D:\Users\ntabyldieva\databases_v1\venv\lib\site-packages\django\views\generic\base.py", line 70, in view
    return self.dispatch(request, *args, **kwargs)
  File "D:\Users\ntabyldieva\databases_v1\venv\lib\site-packages\rest_framework\views.py", line 509, in dispatch
    response = self.handle_exception(exc)
  File "D:\Users\ntabyldieva\databases_v1\venv\lib\site-packages\rest_framework\views.py", line 469, in handle_exception
    self.raise_uncaught_exception(exc)
  File "D:\Users\ntabyldieva\databases_v1\venv\lib\site-packages\rest_framework\views.py", line 480, in raise_uncaught_exception
    raise exc
  File "D:\Users\ntabyldieva\databases_v1\venv\lib\site-packages\rest_framework\views.py", line 506, in dispatch
    response = handler(request, *args, **kwargs)
  File "D:\Users\ntabyldieva\databases_v1\work\data_filter_api.py", line 75, in post
    return Response(serializer.data)
  File "D:\Users\ntabyldieva\databases_v1\venv\lib\site-packages\rest_framework\serializers.py", line 745, in data
    ret = super().data
  File "D:\Users\ntabyldieva\databases_v1\venv\lib\site-packages\rest_framework\serializers.py", line 246, in data
    self._data = self.to_representation(self.instance)
  File "D:\Users\ntabyldieva\databases_v1\venv\lib\site-packages\rest_framework\serializers.py", line 663, in to_representation
    return [
  File "D:\Users\ntabyldieva\databases_v1\venv\lib\site-packages\rest_framework\serializers.py", line 664, in <listcomp>
    self.child.to_representation(item) for item in iterable
  File "D:\Users\ntabyldieva\databases_v1\venv\lib\site-packages\rest_framework\serializers.py", line 502, in to_representation
    attribute = field.get_attribute(instance)
  File "D:\Users\ntabyldieva\databases_v1\venv\lib\site-packages\rest_framework\fields.py", line 490, in get_attribute
    raise type(exc)(msg)
KeyError: "Got KeyError when attempting to get a value for field `country` on serializer `DataFilterApiSerializer`.\nThe serializer field might be named incorrectly and not match any attribute or key on the `dict` instance.\nOriginal exception text was: 'country'."
ERROR django.server "POST /work/test-data/get/ HTTP/1.1" 500 131143 2021-10-21 16:09:31,202
ERROR django.request Internal Server Error: /work/test-data/get/ 2021-10-21 16:09:32,226
Traceback (most recent call last):
  File "D:\Users\ntabyldieva\databases_v1\venv\lib\site-packages\rest_framework\fields.py", line 457, in get_attribute
    return get_attribute(instance, self.source_attrs)
  File "D:\Users\ntabyldieva\databases_v1\venv\lib\site-packages\rest_framework\fields.py", line 95, in get_attribute
    instance = instance[attr]
KeyError: 'country'

During handling of the above exception, another exception occurred:

Traceback (most recent call last):
  File "D:\Users\ntabyldieva\databases_v1\venv\lib\site-packages\django\core\handlers\exception.py", line 47, in inner
    response = get_response(request)
  File "D:\Users\ntabyldieva\databases_v1\venv\lib\site-packages\django\core\handlers\base.py", line 181, in _get_response
    response = wrapped_callback(request, *callback_args, **callback_kwargs)
  File "D:\Users\ntabyldieva\databases_v1\venv\lib\site-packages\django\views\decorators\csrf.py", line 54, in wrapped_view
    return view_func(*args, **kwargs)
  File "D:\Users\ntabyldieva\databases_v1\venv\lib\site-packages\django\views\generic\base.py", line 70, in view
    return self.dispatch(request, *args, **kwargs)
  File "D:\Users\ntabyldieva\databases_v1\venv\lib\site-packages\rest_framework\views.py", line 509, in dispatch
    response = self.handle_exception(exc)
  File "D:\Users\ntabyldieva\databases_v1\venv\lib\site-packages\rest_framework\views.py", line 469, in handle_exception
    self.raise_uncaught_exception(exc)
  File "D:\Users\ntabyldieva\databases_v1\venv\lib\site-packages\rest_framework\views.py", line 480, in raise_uncaught_exception
    raise exc
  File "D:\Users\ntabyldieva\databases_v1\venv\lib\site-packages\rest_framework\views.py", line 506, in dispatch
    response = handler(request, *args, **kwargs)
  File "D:\Users\ntabyldieva\databases_v1\work\data_filter_api.py", line 75, in post
    return Response(serializer.data)
  File "D:\Users\ntabyldieva\databases_v1\venv\lib\site-packages\rest_framework\serializers.py", line 745, in data
    ret = super().data
  File "D:\Users\ntabyldieva\databases_v1\venv\lib\site-packages\rest_framework\serializers.py", line 246, in data
    self._data = self.to_representation(self.instance)
  File "D:\Users\ntabyldieva\databases_v1\venv\lib\site-packages\rest_framework\serializers.py", line 663, in to_representation
    return [
  File "D:\Users\ntabyldieva\databases_v1\venv\lib\site-packages\rest_framework\serializers.py", line 664, in <listcomp>
    self.child.to_representation(item) for item in iterable
  File "D:\Users\ntabyldieva\databases_v1\venv\lib\site-packages\rest_framework\serializers.py", line 502, in to_representation
    attribute = field.get_attribute(instance)
  File "D:\Users\ntabyldieva\databases_v1\venv\lib\site-packages\rest_framework\fields.py", line 490, in get_attribute
    raise type(exc)(msg)
KeyError: "Got KeyError when attempting to get a value for field `country` on serializer `DataFilterApiSerializer`.\nThe serializer field might be named incorrectly and not match any attribute or key on the `dict` instance.\nOriginal exception text was: 'country'."
ERROR django.server "POST /work/test-data/get/ HTTP/1.1" 500 131143 2021-10-21 16:09:32,230
ERROR django.request Internal Server Error: /work/test-data/get/ 2021-10-21 16:09:59,113
Traceback (most recent call last):
  File "D:\Users\ntabyldieva\databases_v1\venv\lib\site-packages\rest_framework\fields.py", line 457, in get_attribute
    return get_attribute(instance, self.source_attrs)
  File "D:\Users\ntabyldieva\databases_v1\venv\lib\site-packages\rest_framework\fields.py", line 95, in get_attribute
    instance = instance[attr]
KeyError: 'country'

During handling of the above exception, another exception occurred:

Traceback (most recent call last):
  File "D:\Users\ntabyldieva\databases_v1\venv\lib\site-packages\django\core\handlers\exception.py", line 47, in inner
    response = get_response(request)
  File "D:\Users\ntabyldieva\databases_v1\venv\lib\site-packages\django\core\handlers\base.py", line 181, in _get_response
    response = wrapped_callback(request, *callback_args, **callback_kwargs)
  File "D:\Users\ntabyldieva\databases_v1\venv\lib\site-packages\django\views\decorators\csrf.py", line 54, in wrapped_view
    return view_func(*args, **kwargs)
  File "D:\Users\ntabyldieva\databases_v1\venv\lib\site-packages\django\views\generic\base.py", line 70, in view
    return self.dispatch(request, *args, **kwargs)
  File "D:\Users\ntabyldieva\databases_v1\venv\lib\site-packages\rest_framework\views.py", line 509, in dispatch
    response = self.handle_exception(exc)
  File "D:\Users\ntabyldieva\databases_v1\venv\lib\site-packages\rest_framework\views.py", line 469, in handle_exception
    self.raise_uncaught_exception(exc)
  File "D:\Users\ntabyldieva\databases_v1\venv\lib\site-packages\rest_framework\views.py", line 480, in raise_uncaught_exception
    raise exc
  File "D:\Users\ntabyldieva\databases_v1\venv\lib\site-packages\rest_framework\views.py", line 506, in dispatch
    response = handler(request, *args, **kwargs)
  File "D:\Users\ntabyldieva\databases_v1\work\data_filter_api.py", line 75, in post
    return Response(serializer.data)
  File "D:\Users\ntabyldieva\databases_v1\venv\lib\site-packages\rest_framework\serializers.py", line 745, in data
    ret = super().data
  File "D:\Users\ntabyldieva\databases_v1\venv\lib\site-packages\rest_framework\serializers.py", line 246, in data
    self._data = self.to_representation(self.instance)
  File "D:\Users\ntabyldieva\databases_v1\venv\lib\site-packages\rest_framework\serializers.py", line 663, in to_representation
    return [
  File "D:\Users\ntabyldieva\databases_v1\venv\lib\site-packages\rest_framework\serializers.py", line 664, in <listcomp>
    self.child.to_representation(item) for item in iterable
  File "D:\Users\ntabyldieva\databases_v1\venv\lib\site-packages\rest_framework\serializers.py", line 502, in to_representation
    attribute = field.get_attribute(instance)
  File "D:\Users\ntabyldieva\databases_v1\venv\lib\site-packages\rest_framework\fields.py", line 490, in get_attribute
    raise type(exc)(msg)
KeyError: "Got KeyError when attempting to get a value for field `country` on serializer `DataFilterApiSerializer`.\nThe serializer field might be named incorrectly and not match any attribute or key on the `dict` instance.\nOriginal exception text was: 'country'."
ERROR django.server "POST /work/test-data/get/ HTTP/1.1" 500 131143 2021-10-21 16:09:59,116
ERROR django.request Internal Server Error: /work/test-data/get/ 2021-10-21 16:10:01,354
Traceback (most recent call last):
  File "D:\Users\ntabyldieva\databases_v1\venv\lib\site-packages\rest_framework\fields.py", line 457, in get_attribute
    return get_attribute(instance, self.source_attrs)
  File "D:\Users\ntabyldieva\databases_v1\venv\lib\site-packages\rest_framework\fields.py", line 95, in get_attribute
    instance = instance[attr]
KeyError: 'country'

During handling of the above exception, another exception occurred:

Traceback (most recent call last):
  File "D:\Users\ntabyldieva\databases_v1\venv\lib\site-packages\django\core\handlers\exception.py", line 47, in inner
    response = get_response(request)
  File "D:\Users\ntabyldieva\databases_v1\venv\lib\site-packages\django\core\handlers\base.py", line 181, in _get_response
    response = wrapped_callback(request, *callback_args, **callback_kwargs)
  File "D:\Users\ntabyldieva\databases_v1\venv\lib\site-packages\django\views\decorators\csrf.py", line 54, in wrapped_view
    return view_func(*args, **kwargs)
  File "D:\Users\ntabyldieva\databases_v1\venv\lib\site-packages\django\views\generic\base.py", line 70, in view
    return self.dispatch(request, *args, **kwargs)
  File "D:\Users\ntabyldieva\databases_v1\venv\lib\site-packages\rest_framework\views.py", line 509, in dispatch
    response = self.handle_exception(exc)
  File "D:\Users\ntabyldieva\databases_v1\venv\lib\site-packages\rest_framework\views.py", line 469, in handle_exception
    self.raise_uncaught_exception(exc)
  File "D:\Users\ntabyldieva\databases_v1\venv\lib\site-packages\rest_framework\views.py", line 480, in raise_uncaught_exception
    raise exc
  File "D:\Users\ntabyldieva\databases_v1\venv\lib\site-packages\rest_framework\views.py", line 506, in dispatch
    response = handler(request, *args, **kwargs)
  File "D:\Users\ntabyldieva\databases_v1\work\data_filter_api.py", line 75, in post
    return Response(serializer.data)
  File "D:\Users\ntabyldieva\databases_v1\venv\lib\site-packages\rest_framework\serializers.py", line 745, in data
    ret = super().data
  File "D:\Users\ntabyldieva\databases_v1\venv\lib\site-packages\rest_framework\serializers.py", line 246, in data
    self._data = self.to_representation(self.instance)
  File "D:\Users\ntabyldieva\databases_v1\venv\lib\site-packages\rest_framework\serializers.py", line 663, in to_representation
    return [
  File "D:\Users\ntabyldieva\databases_v1\venv\lib\site-packages\rest_framework\serializers.py", line 664, in <listcomp>
    self.child.to_representation(item) for item in iterable
  File "D:\Users\ntabyldieva\databases_v1\venv\lib\site-packages\rest_framework\serializers.py", line 502, in to_representation
    attribute = field.get_attribute(instance)
  File "D:\Users\ntabyldieva\databases_v1\venv\lib\site-packages\rest_framework\fields.py", line 490, in get_attribute
    raise type(exc)(msg)
KeyError: "Got KeyError when attempting to get a value for field `country` on serializer `DataFilterApiSerializer`.\nThe serializer field might be named incorrectly and not match any attribute or key on the `dict` instance.\nOriginal exception text was: 'country'."
ERROR django.server "POST /work/test-data/get/ HTTP/1.1" 500 130671 2021-10-21 16:10:01,359
ERROR django.request Internal Server Error: /work/test-data/get/ 2021-10-21 16:10:40,866
Traceback (most recent call last):
  File "D:\Users\ntabyldieva\databases_v1\venv\lib\site-packages\rest_framework\fields.py", line 457, in get_attribute
    return get_attribute(instance, self.source_attrs)
  File "D:\Users\ntabyldieva\databases_v1\venv\lib\site-packages\rest_framework\fields.py", line 95, in get_attribute
    instance = instance[attr]
KeyError: 'country'

During handling of the above exception, another exception occurred:

Traceback (most recent call last):
  File "D:\Users\ntabyldieva\databases_v1\venv\lib\site-packages\django\core\handlers\exception.py", line 47, in inner
    response = get_response(request)
  File "D:\Users\ntabyldieva\databases_v1\venv\lib\site-packages\django\core\handlers\base.py", line 181, in _get_response
    response = wrapped_callback(request, *callback_args, **callback_kwargs)
  File "D:\Users\ntabyldieva\databases_v1\venv\lib\site-packages\django\views\decorators\csrf.py", line 54, in wrapped_view
    return view_func(*args, **kwargs)
  File "D:\Users\ntabyldieva\databases_v1\venv\lib\site-packages\django\views\generic\base.py", line 70, in view
    return self.dispatch(request, *args, **kwargs)
  File "D:\Users\ntabyldieva\databases_v1\venv\lib\site-packages\rest_framework\views.py", line 509, in dispatch
    response = self.handle_exception(exc)
  File "D:\Users\ntabyldieva\databases_v1\venv\lib\site-packages\rest_framework\views.py", line 469, in handle_exception
    self.raise_uncaught_exception(exc)
  File "D:\Users\ntabyldieva\databases_v1\venv\lib\site-packages\rest_framework\views.py", line 480, in raise_uncaught_exception
    raise exc
  File "D:\Users\ntabyldieva\databases_v1\venv\lib\site-packages\rest_framework\views.py", line 506, in dispatch
    response = handler(request, *args, **kwargs)
  File "D:\Users\ntabyldieva\databases_v1\work\data_filter_api.py", line 75, in post
    return Response(serializer.data)
  File "D:\Users\ntabyldieva\databases_v1\venv\lib\site-packages\rest_framework\serializers.py", line 745, in data
    ret = super().data
  File "D:\Users\ntabyldieva\databases_v1\venv\lib\site-packages\rest_framework\serializers.py", line 246, in data
    self._data = self.to_representation(self.instance)
  File "D:\Users\ntabyldieva\databases_v1\venv\lib\site-packages\rest_framework\serializers.py", line 663, in to_representation
    return [
  File "D:\Users\ntabyldieva\databases_v1\venv\lib\site-packages\rest_framework\serializers.py", line 664, in <listcomp>
    self.child.to_representation(item) for item in iterable
  File "D:\Users\ntabyldieva\databases_v1\venv\lib\site-packages\rest_framework\serializers.py", line 502, in to_representation
    attribute = field.get_attribute(instance)
  File "D:\Users\ntabyldieva\databases_v1\venv\lib\site-packages\rest_framework\relations.py", line 190, in get_attribute
    return super().get_attribute(instance)
  File "D:\Users\ntabyldieva\databases_v1\venv\lib\site-packages\rest_framework\fields.py", line 490, in get_attribute
    raise type(exc)(msg)
KeyError: "Got KeyError when attempting to get a value for field `country` on serializer `DataFilterApiSerializer`.\nThe serializer field might be named incorrectly and not match any attribute or key on the `dict` instance.\nOriginal exception text was: 'country'."
ERROR django.server "POST /work/test-data/get/ HTTP/1.1" 500 135691 2021-10-21 16:10:40,870
ERROR django.request Internal Server Error: /work/test-data/get/ 2021-10-21 16:16:15,061
Traceback (most recent call last):
  File "D:\Users\ntabyldieva\databases_v1\venv\lib\site-packages\rest_framework\fields.py", line 457, in get_attribute
    return get_attribute(instance, self.source_attrs)
  File "D:\Users\ntabyldieva\databases_v1\venv\lib\site-packages\rest_framework\fields.py", line 95, in get_attribute
    instance = instance[attr]
KeyError: 'country_id'

During handling of the above exception, another exception occurred:

Traceback (most recent call last):
  File "D:\Users\ntabyldieva\databases_v1\venv\lib\site-packages\django\core\handlers\exception.py", line 47, in inner
    response = get_response(request)
  File "D:\Users\ntabyldieva\databases_v1\venv\lib\site-packages\django\core\handlers\base.py", line 181, in _get_response
    response = wrapped_callback(request, *callback_args, **callback_kwargs)
  File "D:\Users\ntabyldieva\databases_v1\venv\lib\site-packages\django\views\decorators\csrf.py", line 54, in wrapped_view
    return view_func(*args, **kwargs)
  File "D:\Users\ntabyldieva\databases_v1\venv\lib\site-packages\django\views\generic\base.py", line 70, in view
    return self.dispatch(request, *args, **kwargs)
  File "D:\Users\ntabyldieva\databases_v1\venv\lib\site-packages\rest_framework\views.py", line 509, in dispatch
    response = self.handle_exception(exc)
  File "D:\Users\ntabyldieva\databases_v1\venv\lib\site-packages\rest_framework\views.py", line 469, in handle_exception
    self.raise_uncaught_exception(exc)
  File "D:\Users\ntabyldieva\databases_v1\venv\lib\site-packages\rest_framework\views.py", line 480, in raise_uncaught_exception
    raise exc
  File "D:\Users\ntabyldieva\databases_v1\venv\lib\site-packages\rest_framework\views.py", line 506, in dispatch
    response = handler(request, *args, **kwargs)
  File "D:\Users\ntabyldieva\databases_v1\work\data_filter_api.py", line 75, in post
    return Response(serializer.data)
  File "D:\Users\ntabyldieva\databases_v1\venv\lib\site-packages\rest_framework\serializers.py", line 745, in data
    ret = super().data
  File "D:\Users\ntabyldieva\databases_v1\venv\lib\site-packages\rest_framework\serializers.py", line 246, in data
    self._data = self.to_representation(self.instance)
  File "D:\Users\ntabyldieva\databases_v1\venv\lib\site-packages\rest_framework\serializers.py", line 663, in to_representation
    return [
  File "D:\Users\ntabyldieva\databases_v1\venv\lib\site-packages\rest_framework\serializers.py", line 664, in <listcomp>
    self.child.to_representation(item) for item in iterable
  File "D:\Users\ntabyldieva\databases_v1\venv\lib\site-packages\rest_framework\serializers.py", line 502, in to_representation
    attribute = field.get_attribute(instance)
  File "D:\Users\ntabyldieva\databases_v1\venv\lib\site-packages\rest_framework\fields.py", line 490, in get_attribute
    raise type(exc)(msg)
KeyError: "Got KeyError when attempting to get a value for field `country_id` on serializer `DataFilterApiSerializer`.\nThe serializer field might be named incorrectly and not match any attribute or key on the `dict` instance.\nOriginal exception text was: 'country_id'."
ERROR django.server "POST /work/test-data/get/ HTTP/1.1" 500 132284 2021-10-21 16:16:15,065
ERROR django.request Internal Server Error: /work/test-data/get/ 2021-10-21 16:16:16,196
Traceback (most recent call last):
  File "D:\Users\ntabyldieva\databases_v1\venv\lib\site-packages\rest_framework\fields.py", line 457, in get_attribute
    return get_attribute(instance, self.source_attrs)
  File "D:\Users\ntabyldieva\databases_v1\venv\lib\site-packages\rest_framework\fields.py", line 95, in get_attribute
    instance = instance[attr]
KeyError: 'country_id'

During handling of the above exception, another exception occurred:

Traceback (most recent call last):
  File "D:\Users\ntabyldieva\databases_v1\venv\lib\site-packages\django\core\handlers\exception.py", line 47, in inner
    response = get_response(request)
  File "D:\Users\ntabyldieva\databases_v1\venv\lib\site-packages\django\core\handlers\base.py", line 181, in _get_response
    response = wrapped_callback(request, *callback_args, **callback_kwargs)
  File "D:\Users\ntabyldieva\databases_v1\venv\lib\site-packages\django\views\decorators\csrf.py", line 54, in wrapped_view
    return view_func(*args, **kwargs)
  File "D:\Users\ntabyldieva\databases_v1\venv\lib\site-packages\django\views\generic\base.py", line 70, in view
    return self.dispatch(request, *args, **kwargs)
  File "D:\Users\ntabyldieva\databases_v1\venv\lib\site-packages\rest_framework\views.py", line 509, in dispatch
    response = self.handle_exception(exc)
  File "D:\Users\ntabyldieva\databases_v1\venv\lib\site-packages\rest_framework\views.py", line 469, in handle_exception
    self.raise_uncaught_exception(exc)
  File "D:\Users\ntabyldieva\databases_v1\venv\lib\site-packages\rest_framework\views.py", line 480, in raise_uncaught_exception
    raise exc
  File "D:\Users\ntabyldieva\databases_v1\venv\lib\site-packages\rest_framework\views.py", line 506, in dispatch
    response = handler(request, *args, **kwargs)
  File "D:\Users\ntabyldieva\databases_v1\work\data_filter_api.py", line 75, in post
    return Response(serializer.data)
  File "D:\Users\ntabyldieva\databases_v1\venv\lib\site-packages\rest_framework\serializers.py", line 745, in data
    ret = super().data
  File "D:\Users\ntabyldieva\databases_v1\venv\lib\site-packages\rest_framework\serializers.py", line 246, in data
    self._data = self.to_representation(self.instance)
  File "D:\Users\ntabyldieva\databases_v1\venv\lib\site-packages\rest_framework\serializers.py", line 663, in to_representation
    return [
  File "D:\Users\ntabyldieva\databases_v1\venv\lib\site-packages\rest_framework\serializers.py", line 664, in <listcomp>
    self.child.to_representation(item) for item in iterable
  File "D:\Users\ntabyldieva\databases_v1\venv\lib\site-packages\rest_framework\serializers.py", line 502, in to_representation
    attribute = field.get_attribute(instance)
  File "D:\Users\ntabyldieva\databases_v1\venv\lib\site-packages\rest_framework\fields.py", line 490, in get_attribute
    raise type(exc)(msg)
KeyError: "Got KeyError when attempting to get a value for field `country_id` on serializer `DataFilterApiSerializer`.\nThe serializer field might be named incorrectly and not match any attribute or key on the `dict` instance.\nOriginal exception text was: 'country_id'."
ERROR django.server "POST /work/test-data/get/ HTTP/1.1" 500 132284 2021-10-21 16:16:16,200
ERROR django.request Internal Server Error: /work/test-data/get/ 2021-10-21 16:20:47,504
Traceback (most recent call last):
  File "D:\Users\ntabyldieva\databases_v1\venv\lib\site-packages\rest_framework\fields.py", line 457, in get_attribute
    return get_attribute(instance, self.source_attrs)
  File "D:\Users\ntabyldieva\databases_v1\venv\lib\site-packages\rest_framework\fields.py", line 95, in get_attribute
    instance = instance[attr]
KeyError: 'country_id'

During handling of the above exception, another exception occurred:

Traceback (most recent call last):
  File "D:\Users\ntabyldieva\databases_v1\venv\lib\site-packages\django\core\handlers\exception.py", line 47, in inner
    response = get_response(request)
  File "D:\Users\ntabyldieva\databases_v1\venv\lib\site-packages\django\core\handlers\base.py", line 181, in _get_response
    response = wrapped_callback(request, *callback_args, **callback_kwargs)
  File "D:\Users\ntabyldieva\databases_v1\venv\lib\site-packages\django\views\decorators\csrf.py", line 54, in wrapped_view
    return view_func(*args, **kwargs)
  File "D:\Users\ntabyldieva\databases_v1\venv\lib\site-packages\django\views\generic\base.py", line 70, in view
    return self.dispatch(request, *args, **kwargs)
  File "D:\Users\ntabyldieva\databases_v1\venv\lib\site-packages\rest_framework\views.py", line 509, in dispatch
    response = self.handle_exception(exc)
  File "D:\Users\ntabyldieva\databases_v1\venv\lib\site-packages\rest_framework\views.py", line 469, in handle_exception
    self.raise_uncaught_exception(exc)
  File "D:\Users\ntabyldieva\databases_v1\venv\lib\site-packages\rest_framework\views.py", line 480, in raise_uncaught_exception
    raise exc
  File "D:\Users\ntabyldieva\databases_v1\venv\lib\site-packages\rest_framework\views.py", line 506, in dispatch
    response = handler(request, *args, **kwargs)
  File "D:\Users\ntabyldieva\databases_v1\work\data_filter_api.py", line 74, in post
    return Response(serializer.data)
  File "D:\Users\ntabyldieva\databases_v1\venv\lib\site-packages\rest_framework\serializers.py", line 745, in data
    ret = super().data
  File "D:\Users\ntabyldieva\databases_v1\venv\lib\site-packages\rest_framework\serializers.py", line 246, in data
    self._data = self.to_representation(self.instance)
  File "D:\Users\ntabyldieva\databases_v1\venv\lib\site-packages\rest_framework\serializers.py", line 663, in to_representation
    return [
  File "D:\Users\ntabyldieva\databases_v1\venv\lib\site-packages\rest_framework\serializers.py", line 664, in <listcomp>
    self.child.to_representation(item) for item in iterable
  File "D:\Users\ntabyldieva\databases_v1\venv\lib\site-packages\rest_framework\serializers.py", line 502, in to_representation
    attribute = field.get_attribute(instance)
  File "D:\Users\ntabyldieva\databases_v1\venv\lib\site-packages\rest_framework\fields.py", line 490, in get_attribute
    raise type(exc)(msg)
KeyError: "Got KeyError when attempting to get a value for field `country_id` on serializer `DataFilterApiSerializer`.\nThe serializer field might be named incorrectly and not match any attribute or key on the `dict` instance.\nOriginal exception text was: 'country_id'."
ERROR django.server "POST /work/test-data/get/ HTTP/1.1" 500 132245 2021-10-21 16:20:47,509
ERROR django.request Internal Server Error: /work/test-data/get/ 2021-10-21 16:22:42,497
Traceback (most recent call last):
  File "D:\Users\ntabyldieva\databases_v1\venv\lib\site-packages\rest_framework\fields.py", line 457, in get_attribute
    return get_attribute(instance, self.source_attrs)
  File "D:\Users\ntabyldieva\databases_v1\venv\lib\site-packages\rest_framework\fields.py", line 95, in get_attribute
    instance = instance[attr]
KeyError: 'country'

During handling of the above exception, another exception occurred:

Traceback (most recent call last):
  File "D:\Users\ntabyldieva\databases_v1\venv\lib\site-packages\django\core\handlers\exception.py", line 47, in inner
    response = get_response(request)
  File "D:\Users\ntabyldieva\databases_v1\venv\lib\site-packages\django\core\handlers\base.py", line 181, in _get_response
    response = wrapped_callback(request, *callback_args, **callback_kwargs)
  File "D:\Users\ntabyldieva\databases_v1\venv\lib\site-packages\django\views\decorators\csrf.py", line 54, in wrapped_view
    return view_func(*args, **kwargs)
  File "D:\Users\ntabyldieva\databases_v1\venv\lib\site-packages\django\views\generic\base.py", line 70, in view
    return self.dispatch(request, *args, **kwargs)
  File "D:\Users\ntabyldieva\databases_v1\venv\lib\site-packages\rest_framework\views.py", line 509, in dispatch
    response = self.handle_exception(exc)
  File "D:\Users\ntabyldieva\databases_v1\venv\lib\site-packages\rest_framework\views.py", line 469, in handle_exception
    self.raise_uncaught_exception(exc)
  File "D:\Users\ntabyldieva\databases_v1\venv\lib\site-packages\rest_framework\views.py", line 480, in raise_uncaught_exception
    raise exc
  File "D:\Users\ntabyldieva\databases_v1\venv\lib\site-packages\rest_framework\views.py", line 506, in dispatch
    response = handler(request, *args, **kwargs)
  File "D:\Users\ntabyldieva\databases_v1\work\data_filter_api.py", line 74, in post
    return Response(serializer.data)
  File "D:\Users\ntabyldieva\databases_v1\venv\lib\site-packages\rest_framework\serializers.py", line 745, in data
    ret = super().data
  File "D:\Users\ntabyldieva\databases_v1\venv\lib\site-packages\rest_framework\serializers.py", line 246, in data
    self._data = self.to_representation(self.instance)
  File "D:\Users\ntabyldieva\databases_v1\venv\lib\site-packages\rest_framework\serializers.py", line 663, in to_representation
    return [
  File "D:\Users\ntabyldieva\databases_v1\venv\lib\site-packages\rest_framework\serializers.py", line 664, in <listcomp>
    self.child.to_representation(item) for item in iterable
  File "D:\Users\ntabyldieva\databases_v1\venv\lib\site-packages\rest_framework\serializers.py", line 502, in to_representation
    attribute = field.get_attribute(instance)
  File "D:\Users\ntabyldieva\databases_v1\venv\lib\site-packages\rest_framework\fields.py", line 490, in get_attribute
    raise type(exc)(msg)
KeyError: "Got KeyError when attempting to get a value for field `country_id` on serializer `DataFilterApiSerializer`.\nThe serializer field might be named incorrectly and not match any attribute or key on the `dict` instance.\nOriginal exception text was: 'country'."
ERROR django.server "POST /work/test-data/get/ HTTP/1.1" 500 132443 2021-10-21 16:22:42,502
ERROR django.request Internal Server Error: /work/test-data/get/ 2021-10-21 16:23:36,840
Traceback (most recent call last):
  File "D:\Users\ntabyldieva\databases_v1\venv\lib\site-packages\rest_framework\fields.py", line 457, in get_attribute
    return get_attribute(instance, self.source_attrs)
  File "D:\Users\ntabyldieva\databases_v1\venv\lib\site-packages\rest_framework\fields.py", line 95, in get_attribute
    instance = instance[attr]
KeyError: 'country__id'

During handling of the above exception, another exception occurred:

Traceback (most recent call last):
  File "D:\Users\ntabyldieva\databases_v1\venv\lib\site-packages\django\core\handlers\exception.py", line 47, in inner
    response = get_response(request)
  File "D:\Users\ntabyldieva\databases_v1\venv\lib\site-packages\django\core\handlers\base.py", line 181, in _get_response
    response = wrapped_callback(request, *callback_args, **callback_kwargs)
  File "D:\Users\ntabyldieva\databases_v1\venv\lib\site-packages\django\views\decorators\csrf.py", line 54, in wrapped_view
    return view_func(*args, **kwargs)
  File "D:\Users\ntabyldieva\databases_v1\venv\lib\site-packages\django\views\generic\base.py", line 70, in view
    return self.dispatch(request, *args, **kwargs)
  File "D:\Users\ntabyldieva\databases_v1\venv\lib\site-packages\rest_framework\views.py", line 509, in dispatch
    response = self.handle_exception(exc)
  File "D:\Users\ntabyldieva\databases_v1\venv\lib\site-packages\rest_framework\views.py", line 469, in handle_exception
    self.raise_uncaught_exception(exc)
  File "D:\Users\ntabyldieva\databases_v1\venv\lib\site-packages\rest_framework\views.py", line 480, in raise_uncaught_exception
    raise exc
  File "D:\Users\ntabyldieva\databases_v1\venv\lib\site-packages\rest_framework\views.py", line 506, in dispatch
    response = handler(request, *args, **kwargs)
  File "D:\Users\ntabyldieva\databases_v1\work\data_filter_api.py", line 74, in post
    return Response(serializer.data)
  File "D:\Users\ntabyldieva\databases_v1\venv\lib\site-packages\rest_framework\serializers.py", line 745, in data
    ret = super().data
  File "D:\Users\ntabyldieva\databases_v1\venv\lib\site-packages\rest_framework\serializers.py", line 246, in data
    self._data = self.to_representation(self.instance)
  File "D:\Users\ntabyldieva\databases_v1\venv\lib\site-packages\rest_framework\serializers.py", line 663, in to_representation
    return [
  File "D:\Users\ntabyldieva\databases_v1\venv\lib\site-packages\rest_framework\serializers.py", line 664, in <listcomp>
    self.child.to_representation(item) for item in iterable
  File "D:\Users\ntabyldieva\databases_v1\venv\lib\site-packages\rest_framework\serializers.py", line 502, in to_representation
    attribute = field.get_attribute(instance)
  File "D:\Users\ntabyldieva\databases_v1\venv\lib\site-packages\rest_framework\fields.py", line 490, in get_attribute
    raise type(exc)(msg)
KeyError: "Got KeyError when attempting to get a value for field `country_id` on serializer `DataFilterApiSerializer`.\nThe serializer field might be named incorrectly and not match any attribute or key on the `dict` instance.\nOriginal exception text was: 'country__id'."
ERROR django.server "POST /work/test-data/get/ HTTP/1.1" 500 132527 2021-10-21 16:23:36,844
ERROR django.request Internal Server Error: /work/test-data/get/ 2021-10-21 16:23:37,768
Traceback (most recent call last):
  File "D:\Users\ntabyldieva\databases_v1\venv\lib\site-packages\rest_framework\fields.py", line 457, in get_attribute
    return get_attribute(instance, self.source_attrs)
  File "D:\Users\ntabyldieva\databases_v1\venv\lib\site-packages\rest_framework\fields.py", line 95, in get_attribute
    instance = instance[attr]
KeyError: 'country__id'

During handling of the above exception, another exception occurred:

Traceback (most recent call last):
  File "D:\Users\ntabyldieva\databases_v1\venv\lib\site-packages\django\core\handlers\exception.py", line 47, in inner
    response = get_response(request)
  File "D:\Users\ntabyldieva\databases_v1\venv\lib\site-packages\django\core\handlers\base.py", line 181, in _get_response
    response = wrapped_callback(request, *callback_args, **callback_kwargs)
  File "D:\Users\ntabyldieva\databases_v1\venv\lib\site-packages\django\views\decorators\csrf.py", line 54, in wrapped_view
    return view_func(*args, **kwargs)
  File "D:\Users\ntabyldieva\databases_v1\venv\lib\site-packages\django\views\generic\base.py", line 70, in view
    return self.dispatch(request, *args, **kwargs)
  File "D:\Users\ntabyldieva\databases_v1\venv\lib\site-packages\rest_framework\views.py", line 509, in dispatch
    response = self.handle_exception(exc)
  File "D:\Users\ntabyldieva\databases_v1\venv\lib\site-packages\rest_framework\views.py", line 469, in handle_exception
    self.raise_uncaught_exception(exc)
  File "D:\Users\ntabyldieva\databases_v1\venv\lib\site-packages\rest_framework\views.py", line 480, in raise_uncaught_exception
    raise exc
  File "D:\Users\ntabyldieva\databases_v1\venv\lib\site-packages\rest_framework\views.py", line 506, in dispatch
    response = handler(request, *args, **kwargs)
  File "D:\Users\ntabyldieva\databases_v1\work\data_filter_api.py", line 74, in post
    return Response(serializer.data)
  File "D:\Users\ntabyldieva\databases_v1\venv\lib\site-packages\rest_framework\serializers.py", line 745, in data
    ret = super().data
  File "D:\Users\ntabyldieva\databases_v1\venv\lib\site-packages\rest_framework\serializers.py", line 246, in data
    self._data = self.to_representation(self.instance)
  File "D:\Users\ntabyldieva\databases_v1\venv\lib\site-packages\rest_framework\serializers.py", line 663, in to_representation
    return [
  File "D:\Users\ntabyldieva\databases_v1\venv\lib\site-packages\rest_framework\serializers.py", line 664, in <listcomp>
    self.child.to_representation(item) for item in iterable
  File "D:\Users\ntabyldieva\databases_v1\venv\lib\site-packages\rest_framework\serializers.py", line 502, in to_representation
    attribute = field.get_attribute(instance)
  File "D:\Users\ntabyldieva\databases_v1\venv\lib\site-packages\rest_framework\fields.py", line 490, in get_attribute
    raise type(exc)(msg)
KeyError: "Got KeyError when attempting to get a value for field `country_id` on serializer `DataFilterApiSerializer`.\nThe serializer field might be named incorrectly and not match any attribute or key on the `dict` instance.\nOriginal exception text was: 'country__id'."
ERROR django.server "POST /work/test-data/get/ HTTP/1.1" 500 132527 2021-10-21 16:23:37,771
ERROR django.request Internal Server Error: /work/test-data/get/ 2021-10-21 16:24:12,038
Traceback (most recent call last):
  File "D:\Users\ntabyldieva\databases_v1\venv\lib\site-packages\rest_framework\fields.py", line 457, in get_attribute
    return get_attribute(instance, self.source_attrs)
  File "D:\Users\ntabyldieva\databases_v1\venv\lib\site-packages\rest_framework\fields.py", line 95, in get_attribute
    instance = instance[attr]
KeyError: 'country__id'

During handling of the above exception, another exception occurred:

Traceback (most recent call last):
  File "D:\Users\ntabyldieva\databases_v1\venv\lib\site-packages\django\core\handlers\exception.py", line 47, in inner
    response = get_response(request)
  File "D:\Users\ntabyldieva\databases_v1\venv\lib\site-packages\django\core\handlers\base.py", line 181, in _get_response
    response = wrapped_callback(request, *callback_args, **callback_kwargs)
  File "D:\Users\ntabyldieva\databases_v1\venv\lib\site-packages\django\views\decorators\csrf.py", line 54, in wrapped_view
    return view_func(*args, **kwargs)
  File "D:\Users\ntabyldieva\databases_v1\venv\lib\site-packages\django\views\generic\base.py", line 70, in view
    return self.dispatch(request, *args, **kwargs)
  File "D:\Users\ntabyldieva\databases_v1\venv\lib\site-packages\rest_framework\views.py", line 509, in dispatch
    response = self.handle_exception(exc)
  File "D:\Users\ntabyldieva\databases_v1\venv\lib\site-packages\rest_framework\views.py", line 469, in handle_exception
    self.raise_uncaught_exception(exc)
  File "D:\Users\ntabyldieva\databases_v1\venv\lib\site-packages\rest_framework\views.py", line 480, in raise_uncaught_exception
    raise exc
  File "D:\Users\ntabyldieva\databases_v1\venv\lib\site-packages\rest_framework\views.py", line 506, in dispatch
    response = handler(request, *args, **kwargs)
  File "D:\Users\ntabyldieva\databases_v1\work\data_filter_api.py", line 74, in post
    return Response(serializer.data)
  File "D:\Users\ntabyldieva\databases_v1\venv\lib\site-packages\rest_framework\serializers.py", line 745, in data
    ret = super().data
  File "D:\Users\ntabyldieva\databases_v1\venv\lib\site-packages\rest_framework\serializers.py", line 246, in data
    self._data = self.to_representation(self.instance)
  File "D:\Users\ntabyldieva\databases_v1\venv\lib\site-packages\rest_framework\serializers.py", line 663, in to_representation
    return [
  File "D:\Users\ntabyldieva\databases_v1\venv\lib\site-packages\rest_framework\serializers.py", line 664, in <listcomp>
    self.child.to_representation(item) for item in iterable
  File "D:\Users\ntabyldieva\databases_v1\venv\lib\site-packages\rest_framework\serializers.py", line 502, in to_representation
    attribute = field.get_attribute(instance)
  File "D:\Users\ntabyldieva\databases_v1\venv\lib\site-packages\rest_framework\fields.py", line 490, in get_attribute
    raise type(exc)(msg)
KeyError: "Got KeyError when attempting to get a value for field `country_id` on serializer `DataFilterApiSerializer`.\nThe serializer field might be named incorrectly and not match any attribute or key on the `dict` instance.\nOriginal exception text was: 'country__id'."
ERROR django.server "POST /work/test-data/get/ HTTP/1.1" 500 132527 2021-10-21 16:24:12,041
ERROR django.request Internal Server Error: /work/test-data/get/ 2021-10-21 16:24:15,764
Traceback (most recent call last):
  File "D:\Users\ntabyldieva\databases_v1\venv\lib\site-packages\rest_framework\fields.py", line 457, in get_attribute
    return get_attribute(instance, self.source_attrs)
  File "D:\Users\ntabyldieva\databases_v1\venv\lib\site-packages\rest_framework\fields.py", line 95, in get_attribute
    instance = instance[attr]
KeyError: 'country__id'

During handling of the above exception, another exception occurred:

Traceback (most recent call last):
  File "D:\Users\ntabyldieva\databases_v1\venv\lib\site-packages\django\core\handlers\exception.py", line 47, in inner
    response = get_response(request)
  File "D:\Users\ntabyldieva\databases_v1\venv\lib\site-packages\django\core\handlers\base.py", line 181, in _get_response
    response = wrapped_callback(request, *callback_args, **callback_kwargs)
  File "D:\Users\ntabyldieva\databases_v1\venv\lib\site-packages\django\views\decorators\csrf.py", line 54, in wrapped_view
    return view_func(*args, **kwargs)
  File "D:\Users\ntabyldieva\databases_v1\venv\lib\site-packages\django\views\generic\base.py", line 70, in view
    return self.dispatch(request, *args, **kwargs)
  File "D:\Users\ntabyldieva\databases_v1\venv\lib\site-packages\rest_framework\views.py", line 509, in dispatch
    response = self.handle_exception(exc)
  File "D:\Users\ntabyldieva\databases_v1\venv\lib\site-packages\rest_framework\views.py", line 469, in handle_exception
    self.raise_uncaught_exception(exc)
  File "D:\Users\ntabyldieva\databases_v1\venv\lib\site-packages\rest_framework\views.py", line 480, in raise_uncaught_exception
    raise exc
  File "D:\Users\ntabyldieva\databases_v1\venv\lib\site-packages\rest_framework\views.py", line 506, in dispatch
    response = handler(request, *args, **kwargs)
  File "D:\Users\ntabyldieva\databases_v1\work\data_filter_api.py", line 74, in post
    return Response(serializer.data)
  File "D:\Users\ntabyldieva\databases_v1\venv\lib\site-packages\rest_framework\serializers.py", line 745, in data
    ret = super().data
  File "D:\Users\ntabyldieva\databases_v1\venv\lib\site-packages\rest_framework\serializers.py", line 246, in data
    self._data = self.to_representation(self.instance)
  File "D:\Users\ntabyldieva\databases_v1\venv\lib\site-packages\rest_framework\serializers.py", line 663, in to_representation
    return [
  File "D:\Users\ntabyldieva\databases_v1\venv\lib\site-packages\rest_framework\serializers.py", line 664, in <listcomp>
    self.child.to_representation(item) for item in iterable
  File "D:\Users\ntabyldieva\databases_v1\venv\lib\site-packages\rest_framework\serializers.py", line 502, in to_representation
    attribute = field.get_attribute(instance)
  File "D:\Users\ntabyldieva\databases_v1\venv\lib\site-packages\rest_framework\fields.py", line 490, in get_attribute
    raise type(exc)(msg)
KeyError: "Got KeyError when attempting to get a value for field `country_id` on serializer `DataFilterApiSerializer`.\nThe serializer field might be named incorrectly and not match any attribute or key on the `dict` instance.\nOriginal exception text was: 'country__id'."
ERROR django.server "POST /work/test-data/get/ HTTP/1.1" 500 132445 2021-10-21 16:24:15,768
ERROR django.request Internal Server Error: /work/test-data/get/ 2021-10-21 16:24:59,182
Traceback (most recent call last):
  File "D:\Users\ntabyldieva\databases_v1\venv\lib\site-packages\rest_framework\fields.py", line 457, in get_attribute
    return get_attribute(instance, self.source_attrs)
  File "D:\Users\ntabyldieva\databases_v1\venv\lib\site-packages\rest_framework\fields.py", line 95, in get_attribute
    instance = instance[attr]
KeyError: 'country__id'

During handling of the above exception, another exception occurred:

Traceback (most recent call last):
  File "D:\Users\ntabyldieva\databases_v1\venv\lib\site-packages\django\core\handlers\exception.py", line 47, in inner
    response = get_response(request)
  File "D:\Users\ntabyldieva\databases_v1\venv\lib\site-packages\django\core\handlers\base.py", line 181, in _get_response
    response = wrapped_callback(request, *callback_args, **callback_kwargs)
  File "D:\Users\ntabyldieva\databases_v1\venv\lib\site-packages\django\views\decorators\csrf.py", line 54, in wrapped_view
    return view_func(*args, **kwargs)
  File "D:\Users\ntabyldieva\databases_v1\venv\lib\site-packages\django\views\generic\base.py", line 70, in view
    return self.dispatch(request, *args, **kwargs)
  File "D:\Users\ntabyldieva\databases_v1\venv\lib\site-packages\rest_framework\views.py", line 509, in dispatch
    response = self.handle_exception(exc)
  File "D:\Users\ntabyldieva\databases_v1\venv\lib\site-packages\rest_framework\views.py", line 469, in handle_exception
    self.raise_uncaught_exception(exc)
  File "D:\Users\ntabyldieva\databases_v1\venv\lib\site-packages\rest_framework\views.py", line 480, in raise_uncaught_exception
    raise exc
  File "D:\Users\ntabyldieva\databases_v1\venv\lib\site-packages\rest_framework\views.py", line 506, in dispatch
    response = handler(request, *args, **kwargs)
  File "D:\Users\ntabyldieva\databases_v1\work\data_filter_api.py", line 75, in post
    return Response(serializer.data)
  File "D:\Users\ntabyldieva\databases_v1\venv\lib\site-packages\rest_framework\serializers.py", line 745, in data
    ret = super().data
  File "D:\Users\ntabyldieva\databases_v1\venv\lib\site-packages\rest_framework\serializers.py", line 246, in data
    self._data = self.to_representation(self.instance)
  File "D:\Users\ntabyldieva\databases_v1\venv\lib\site-packages\rest_framework\serializers.py", line 663, in to_representation
    return [
  File "D:\Users\ntabyldieva\databases_v1\venv\lib\site-packages\rest_framework\serializers.py", line 664, in <listcomp>
    self.child.to_representation(item) for item in iterable
  File "D:\Users\ntabyldieva\databases_v1\venv\lib\site-packages\rest_framework\serializers.py", line 502, in to_representation
    attribute = field.get_attribute(instance)
  File "D:\Users\ntabyldieva\databases_v1\venv\lib\site-packages\rest_framework\fields.py", line 490, in get_attribute
    raise type(exc)(msg)
KeyError: "Got KeyError when attempting to get a value for field `country_id` on serializer `DataFilterApiSerializer`.\nThe serializer field might be named incorrectly and not match any attribute or key on the `dict` instance.\nOriginal exception text was: 'country__id'."
ERROR django.server "POST /work/test-data/get/ HTTP/1.1" 500 132466 2021-10-21 16:24:59,186
ERROR django.request Internal Server Error: /work/test-data/get/ 2021-10-21 16:27:59,600
Traceback (most recent call last):
  File "D:\Users\ntabyldieva\databases_v1\venv\lib\site-packages\rest_framework\fields.py", line 457, in get_attribute
    return get_attribute(instance, self.source_attrs)
  File "D:\Users\ntabyldieva\databases_v1\venv\lib\site-packages\rest_framework\fields.py", line 95, in get_attribute
    instance = instance[attr]
KeyError: 'country_id'

During handling of the above exception, another exception occurred:

Traceback (most recent call last):
  File "D:\Users\ntabyldieva\databases_v1\venv\lib\site-packages\django\core\handlers\exception.py", line 47, in inner
    response = get_response(request)
  File "D:\Users\ntabyldieva\databases_v1\venv\lib\site-packages\django\core\handlers\base.py", line 181, in _get_response
    response = wrapped_callback(request, *callback_args, **callback_kwargs)
  File "D:\Users\ntabyldieva\databases_v1\venv\lib\site-packages\django\views\decorators\csrf.py", line 54, in wrapped_view
    return view_func(*args, **kwargs)
  File "D:\Users\ntabyldieva\databases_v1\venv\lib\site-packages\django\views\generic\base.py", line 70, in view
    return self.dispatch(request, *args, **kwargs)
  File "D:\Users\ntabyldieva\databases_v1\venv\lib\site-packages\rest_framework\views.py", line 509, in dispatch
    response = self.handle_exception(exc)
  File "D:\Users\ntabyldieva\databases_v1\venv\lib\site-packages\rest_framework\views.py", line 469, in handle_exception
    self.raise_uncaught_exception(exc)
  File "D:\Users\ntabyldieva\databases_v1\venv\lib\site-packages\rest_framework\views.py", line 480, in raise_uncaught_exception
    raise exc
  File "D:\Users\ntabyldieva\databases_v1\venv\lib\site-packages\rest_framework\views.py", line 506, in dispatch
    response = handler(request, *args, **kwargs)
  File "D:\Users\ntabyldieva\databases_v1\work\data_filter_api.py", line 75, in post
    return Response(serializer.data)
  File "D:\Users\ntabyldieva\databases_v1\venv\lib\site-packages\rest_framework\serializers.py", line 745, in data
    ret = super().data
  File "D:\Users\ntabyldieva\databases_v1\venv\lib\site-packages\rest_framework\serializers.py", line 246, in data
    self._data = self.to_representation(self.instance)
  File "D:\Users\ntabyldieva\databases_v1\venv\lib\site-packages\rest_framework\serializers.py", line 663, in to_representation
    return [
  File "D:\Users\ntabyldieva\databases_v1\venv\lib\site-packages\rest_framework\serializers.py", line 664, in <listcomp>
    self.child.to_representation(item) for item in iterable
  File "D:\Users\ntabyldieva\databases_v1\venv\lib\site-packages\rest_framework\serializers.py", line 502, in to_representation
    attribute = field.get_attribute(instance)
  File "D:\Users\ntabyldieva\databases_v1\venv\lib\site-packages\rest_framework\fields.py", line 490, in get_attribute
    raise type(exc)(msg)
KeyError: "Got KeyError when attempting to get a value for field `country_id` on serializer `DataFilterApiSerializer`.\nThe serializer field might be named incorrectly and not match any attribute or key on the `dict` instance.\nOriginal exception text was: 'country_id'."
ERROR django.server "POST /work/test-data/get/ HTTP/1.1" 500 132184 2021-10-21 16:27:59,604
ERROR django.request Internal Server Error: /work/test-data/get/ 2021-10-21 16:28:00,904
Traceback (most recent call last):
  File "D:\Users\ntabyldieva\databases_v1\venv\lib\site-packages\rest_framework\fields.py", line 457, in get_attribute
    return get_attribute(instance, self.source_attrs)
  File "D:\Users\ntabyldieva\databases_v1\venv\lib\site-packages\rest_framework\fields.py", line 95, in get_attribute
    instance = instance[attr]
KeyError: 'country_id'

During handling of the above exception, another exception occurred:

Traceback (most recent call last):
  File "D:\Users\ntabyldieva\databases_v1\venv\lib\site-packages\django\core\handlers\exception.py", line 47, in inner
    response = get_response(request)
  File "D:\Users\ntabyldieva\databases_v1\venv\lib\site-packages\django\core\handlers\base.py", line 181, in _get_response
    response = wrapped_callback(request, *callback_args, **callback_kwargs)
  File "D:\Users\ntabyldieva\databases_v1\venv\lib\site-packages\django\views\decorators\csrf.py", line 54, in wrapped_view
    return view_func(*args, **kwargs)
  File "D:\Users\ntabyldieva\databases_v1\venv\lib\site-packages\django\views\generic\base.py", line 70, in view
    return self.dispatch(request, *args, **kwargs)
  File "D:\Users\ntabyldieva\databases_v1\venv\lib\site-packages\rest_framework\views.py", line 509, in dispatch
    response = self.handle_exception(exc)
  File "D:\Users\ntabyldieva\databases_v1\venv\lib\site-packages\rest_framework\views.py", line 469, in handle_exception
    self.raise_uncaught_exception(exc)
  File "D:\Users\ntabyldieva\databases_v1\venv\lib\site-packages\rest_framework\views.py", line 480, in raise_uncaught_exception
    raise exc
  File "D:\Users\ntabyldieva\databases_v1\venv\lib\site-packages\rest_framework\views.py", line 506, in dispatch
    response = handler(request, *args, **kwargs)
  File "D:\Users\ntabyldieva\databases_v1\work\data_filter_api.py", line 75, in post
    return Response(serializer.data)
  File "D:\Users\ntabyldieva\databases_v1\venv\lib\site-packages\rest_framework\serializers.py", line 745, in data
    ret = super().data
  File "D:\Users\ntabyldieva\databases_v1\venv\lib\site-packages\rest_framework\serializers.py", line 246, in data
    self._data = self.to_representation(self.instance)
  File "D:\Users\ntabyldieva\databases_v1\venv\lib\site-packages\rest_framework\serializers.py", line 663, in to_representation
    return [
  File "D:\Users\ntabyldieva\databases_v1\venv\lib\site-packages\rest_framework\serializers.py", line 664, in <listcomp>
    self.child.to_representation(item) for item in iterable
  File "D:\Users\ntabyldieva\databases_v1\venv\lib\site-packages\rest_framework\serializers.py", line 502, in to_representation
    attribute = field.get_attribute(instance)
  File "D:\Users\ntabyldieva\databases_v1\venv\lib\site-packages\rest_framework\fields.py", line 490, in get_attribute
    raise type(exc)(msg)
KeyError: "Got KeyError when attempting to get a value for field `country_id` on serializer `DataFilterApiSerializer`.\nThe serializer field might be named incorrectly and not match any attribute or key on the `dict` instance.\nOriginal exception text was: 'country_id'."
ERROR django.server "POST /work/test-data/get/ HTTP/1.1" 500 132184 2021-10-21 16:28:00,908
ERROR django.request Internal Server Error: /work/test-data/get/ 2021-10-21 16:28:11,764
Traceback (most recent call last):
  File "D:\Users\ntabyldieva\databases_v1\venv\lib\site-packages\rest_framework\fields.py", line 457, in get_attribute
    return get_attribute(instance, self.source_attrs)
  File "D:\Users\ntabyldieva\databases_v1\venv\lib\site-packages\rest_framework\fields.py", line 95, in get_attribute
    instance = instance[attr]
KeyError: 'country_id'

During handling of the above exception, another exception occurred:

Traceback (most recent call last):
  File "D:\Users\ntabyldieva\databases_v1\venv\lib\site-packages\django\core\handlers\exception.py", line 47, in inner
    response = get_response(request)
  File "D:\Users\ntabyldieva\databases_v1\venv\lib\site-packages\django\core\handlers\base.py", line 181, in _get_response
    response = wrapped_callback(request, *callback_args, **callback_kwargs)
  File "D:\Users\ntabyldieva\databases_v1\venv\lib\site-packages\django\views\decorators\csrf.py", line 54, in wrapped_view
    return view_func(*args, **kwargs)
  File "D:\Users\ntabyldieva\databases_v1\venv\lib\site-packages\django\views\generic\base.py", line 70, in view
    return self.dispatch(request, *args, **kwargs)
  File "D:\Users\ntabyldieva\databases_v1\venv\lib\site-packages\rest_framework\views.py", line 509, in dispatch
    response = self.handle_exception(exc)
  File "D:\Users\ntabyldieva\databases_v1\venv\lib\site-packages\rest_framework\views.py", line 469, in handle_exception
    self.raise_uncaught_exception(exc)
  File "D:\Users\ntabyldieva\databases_v1\venv\lib\site-packages\rest_framework\views.py", line 480, in raise_uncaught_exception
    raise exc
  File "D:\Users\ntabyldieva\databases_v1\venv\lib\site-packages\rest_framework\views.py", line 506, in dispatch
    response = handler(request, *args, **kwargs)
  File "D:\Users\ntabyldieva\databases_v1\work\data_filter_api.py", line 75, in post
    return Response(serializer.data)
  File "D:\Users\ntabyldieva\databases_v1\venv\lib\site-packages\rest_framework\serializers.py", line 745, in data
    ret = super().data
  File "D:\Users\ntabyldieva\databases_v1\venv\lib\site-packages\rest_framework\serializers.py", line 246, in data
    self._data = self.to_representation(self.instance)
  File "D:\Users\ntabyldieva\databases_v1\venv\lib\site-packages\rest_framework\serializers.py", line 663, in to_representation
    return [
  File "D:\Users\ntabyldieva\databases_v1\venv\lib\site-packages\rest_framework\serializers.py", line 664, in <listcomp>
    self.child.to_representation(item) for item in iterable
  File "D:\Users\ntabyldieva\databases_v1\venv\lib\site-packages\rest_framework\serializers.py", line 502, in to_representation
    attribute = field.get_attribute(instance)
  File "D:\Users\ntabyldieva\databases_v1\venv\lib\site-packages\rest_framework\fields.py", line 490, in get_attribute
    raise type(exc)(msg)
KeyError: "Got KeyError when attempting to get a value for field `country_id` on serializer `DataFilterApiSerializer`.\nThe serializer field might be named incorrectly and not match any attribute or key on the `dict` instance.\nOriginal exception text was: 'country_id'."
ERROR django.server "POST /work/test-data/get/ HTTP/1.1" 500 132184 2021-10-21 16:28:11,768
ERROR django.request Internal Server Error: /work/test-data/get/ 2021-10-21 16:31:43,185
Traceback (most recent call last):
  File "D:\Users\ntabyldieva\databases_v1\venv\lib\site-packages\rest_framework\fields.py", line 457, in get_attribute
    return get_attribute(instance, self.source_attrs)
  File "D:\Users\ntabyldieva\databases_v1\venv\lib\site-packages\rest_framework\fields.py", line 95, in get_attribute
    instance = instance[attr]
KeyError: 'country_id'

During handling of the above exception, another exception occurred:

Traceback (most recent call last):
  File "D:\Users\ntabyldieva\databases_v1\venv\lib\site-packages\django\core\handlers\exception.py", line 47, in inner
    response = get_response(request)
  File "D:\Users\ntabyldieva\databases_v1\venv\lib\site-packages\django\core\handlers\base.py", line 181, in _get_response
    response = wrapped_callback(request, *callback_args, **callback_kwargs)
  File "D:\Users\ntabyldieva\databases_v1\venv\lib\site-packages\django\views\decorators\csrf.py", line 54, in wrapped_view
    return view_func(*args, **kwargs)
  File "D:\Users\ntabyldieva\databases_v1\venv\lib\site-packages\django\views\generic\base.py", line 70, in view
    return self.dispatch(request, *args, **kwargs)
  File "D:\Users\ntabyldieva\databases_v1\venv\lib\site-packages\rest_framework\views.py", line 509, in dispatch
    response = self.handle_exception(exc)
  File "D:\Users\ntabyldieva\databases_v1\venv\lib\site-packages\rest_framework\views.py", line 469, in handle_exception
    self.raise_uncaught_exception(exc)
  File "D:\Users\ntabyldieva\databases_v1\venv\lib\site-packages\rest_framework\views.py", line 480, in raise_uncaught_exception
    raise exc
  File "D:\Users\ntabyldieva\databases_v1\venv\lib\site-packages\rest_framework\views.py", line 506, in dispatch
    response = handler(request, *args, **kwargs)
  File "D:\Users\ntabyldieva\databases_v1\work\data_filter_api.py", line 75, in post
    return Response(serializer.data)
  File "D:\Users\ntabyldieva\databases_v1\venv\lib\site-packages\rest_framework\serializers.py", line 745, in data
    ret = super().data
  File "D:\Users\ntabyldieva\databases_v1\venv\lib\site-packages\rest_framework\serializers.py", line 246, in data
    self._data = self.to_representation(self.instance)
  File "D:\Users\ntabyldieva\databases_v1\venv\lib\site-packages\rest_framework\serializers.py", line 663, in to_representation
    return [
  File "D:\Users\ntabyldieva\databases_v1\venv\lib\site-packages\rest_framework\serializers.py", line 664, in <listcomp>
    self.child.to_representation(item) for item in iterable
  File "D:\Users\ntabyldieva\databases_v1\venv\lib\site-packages\rest_framework\serializers.py", line 502, in to_representation
    attribute = field.get_attribute(instance)
  File "D:\Users\ntabyldieva\databases_v1\venv\lib\site-packages\rest_framework\fields.py", line 490, in get_attribute
    raise type(exc)(msg)
KeyError: "Got KeyError when attempting to get a value for field `country_id` on serializer `DataFilterApiSerializer`.\nThe serializer field might be named incorrectly and not match any attribute or key on the `dict` instance.\nOriginal exception text was: 'country_id'."
ERROR django.server "POST /work/test-data/get/ HTTP/1.1" 500 132184 2021-10-21 16:31:43,190
ERROR django.request Internal Server Error: /work/test-data/get/ 2021-10-21 16:33:16,954
Traceback (most recent call last):
  File "D:\Users\ntabyldieva\databases_v1\venv\lib\site-packages\rest_framework\fields.py", line 457, in get_attribute
    return get_attribute(instance, self.source_attrs)
  File "D:\Users\ntabyldieva\databases_v1\venv\lib\site-packages\rest_framework\fields.py", line 95, in get_attribute
    instance = instance[attr]
KeyError: 'country_id'

During handling of the above exception, another exception occurred:

Traceback (most recent call last):
  File "D:\Users\ntabyldieva\databases_v1\venv\lib\site-packages\django\core\handlers\exception.py", line 47, in inner
    response = get_response(request)
  File "D:\Users\ntabyldieva\databases_v1\venv\lib\site-packages\django\core\handlers\base.py", line 181, in _get_response
    response = wrapped_callback(request, *callback_args, **callback_kwargs)
  File "D:\Users\ntabyldieva\databases_v1\venv\lib\site-packages\django\views\decorators\csrf.py", line 54, in wrapped_view
    return view_func(*args, **kwargs)
  File "D:\Users\ntabyldieva\databases_v1\venv\lib\site-packages\django\views\generic\base.py", line 70, in view
    return self.dispatch(request, *args, **kwargs)
  File "D:\Users\ntabyldieva\databases_v1\venv\lib\site-packages\rest_framework\views.py", line 509, in dispatch
    response = self.handle_exception(exc)
  File "D:\Users\ntabyldieva\databases_v1\venv\lib\site-packages\rest_framework\views.py", line 469, in handle_exception
    self.raise_uncaught_exception(exc)
  File "D:\Users\ntabyldieva\databases_v1\venv\lib\site-packages\rest_framework\views.py", line 480, in raise_uncaught_exception
    raise exc
  File "D:\Users\ntabyldieva\databases_v1\venv\lib\site-packages\rest_framework\views.py", line 506, in dispatch
    response = handler(request, *args, **kwargs)
  File "D:\Users\ntabyldieva\databases_v1\work\data_filter_api.py", line 75, in post
    return Response(serializer.data)
  File "D:\Users\ntabyldieva\databases_v1\venv\lib\site-packages\rest_framework\serializers.py", line 745, in data
    ret = super().data
  File "D:\Users\ntabyldieva\databases_v1\venv\lib\site-packages\rest_framework\serializers.py", line 246, in data
    self._data = self.to_representation(self.instance)
  File "D:\Users\ntabyldieva\databases_v1\venv\lib\site-packages\rest_framework\serializers.py", line 663, in to_representation
    return [
  File "D:\Users\ntabyldieva\databases_v1\venv\lib\site-packages\rest_framework\serializers.py", line 664, in <listcomp>
    self.child.to_representation(item) for item in iterable
  File "D:\Users\ntabyldieva\databases_v1\venv\lib\site-packages\rest_framework\serializers.py", line 502, in to_representation
    attribute = field.get_attribute(instance)
  File "D:\Users\ntabyldieva\databases_v1\venv\lib\site-packages\rest_framework\fields.py", line 490, in get_attribute
    raise type(exc)(msg)
KeyError: "Got KeyError when attempting to get a value for field `country_id` on serializer `DataFilterApiSerializer`.\nThe serializer field might be named incorrectly and not match any attribute or key on the `dict` instance.\nOriginal exception text was: 'country_id'."
ERROR django.server "POST /work/test-data/get/ HTTP/1.1" 500 132184 2021-10-21 16:33:16,958
ERROR django.request Internal Server Error: /work/test-data/get/ 2021-10-21 16:33:18,552
Traceback (most recent call last):
  File "D:\Users\ntabyldieva\databases_v1\venv\lib\site-packages\rest_framework\fields.py", line 457, in get_attribute
    return get_attribute(instance, self.source_attrs)
  File "D:\Users\ntabyldieva\databases_v1\venv\lib\site-packages\rest_framework\fields.py", line 95, in get_attribute
    instance = instance[attr]
KeyError: 'country'

During handling of the above exception, another exception occurred:

Traceback (most recent call last):
  File "D:\Users\ntabyldieva\databases_v1\venv\lib\site-packages\django\core\handlers\exception.py", line 47, in inner
    response = get_response(request)
  File "D:\Users\ntabyldieva\databases_v1\venv\lib\site-packages\django\core\handlers\base.py", line 181, in _get_response
    response = wrapped_callback(request, *callback_args, **callback_kwargs)
  File "D:\Users\ntabyldieva\databases_v1\venv\lib\site-packages\django\views\decorators\csrf.py", line 54, in wrapped_view
    return view_func(*args, **kwargs)
  File "D:\Users\ntabyldieva\databases_v1\venv\lib\site-packages\django\views\generic\base.py", line 70, in view
    return self.dispatch(request, *args, **kwargs)
  File "D:\Users\ntabyldieva\databases_v1\venv\lib\site-packages\rest_framework\views.py", line 509, in dispatch
    response = self.handle_exception(exc)
  File "D:\Users\ntabyldieva\databases_v1\venv\lib\site-packages\rest_framework\views.py", line 469, in handle_exception
    self.raise_uncaught_exception(exc)
  File "D:\Users\ntabyldieva\databases_v1\venv\lib\site-packages\rest_framework\views.py", line 480, in raise_uncaught_exception
    raise exc
  File "D:\Users\ntabyldieva\databases_v1\venv\lib\site-packages\rest_framework\views.py", line 506, in dispatch
    response = handler(request, *args, **kwargs)
  File "D:\Users\ntabyldieva\databases_v1\work\data_filter_api.py", line 75, in post
    return Response(serializer.data)
  File "D:\Users\ntabyldieva\databases_v1\venv\lib\site-packages\rest_framework\serializers.py", line 745, in data
    ret = super().data
  File "D:\Users\ntabyldieva\databases_v1\venv\lib\site-packages\rest_framework\serializers.py", line 246, in data
    self._data = self.to_representation(self.instance)
  File "D:\Users\ntabyldieva\databases_v1\venv\lib\site-packages\rest_framework\serializers.py", line 663, in to_representation
    return [
  File "D:\Users\ntabyldieva\databases_v1\venv\lib\site-packages\rest_framework\serializers.py", line 664, in <listcomp>
    self.child.to_representation(item) for item in iterable
  File "D:\Users\ntabyldieva\databases_v1\venv\lib\site-packages\rest_framework\serializers.py", line 502, in to_representation
    attribute = field.get_attribute(instance)
  File "D:\Users\ntabyldieva\databases_v1\venv\lib\site-packages\rest_framework\fields.py", line 490, in get_attribute
    raise type(exc)(msg)
KeyError: "Got KeyError when attempting to get a value for field `country` on serializer `DataFilterApiSerializer`.\nThe serializer field might be named incorrectly and not match any attribute or key on the `dict` instance.\nOriginal exception text was: 'country'."
ERROR django.server "POST /work/test-data/get/ HTTP/1.1" 500 131420 2021-10-21 16:33:18,558
ERROR django.request Internal Server Error: /work/test-data/get/ 2021-10-21 16:33:28,154
Traceback (most recent call last):
  File "D:\Users\ntabyldieva\databases_v1\venv\lib\site-packages\rest_framework\fields.py", line 457, in get_attribute
    return get_attribute(instance, self.source_attrs)
  File "D:\Users\ntabyldieva\databases_v1\venv\lib\site-packages\rest_framework\fields.py", line 95, in get_attribute
    instance = instance[attr]
KeyError: 'country'

During handling of the above exception, another exception occurred:

Traceback (most recent call last):
  File "D:\Users\ntabyldieva\databases_v1\venv\lib\site-packages\django\core\handlers\exception.py", line 47, in inner
    response = get_response(request)
  File "D:\Users\ntabyldieva\databases_v1\venv\lib\site-packages\django\core\handlers\base.py", line 181, in _get_response
    response = wrapped_callback(request, *callback_args, **callback_kwargs)
  File "D:\Users\ntabyldieva\databases_v1\venv\lib\site-packages\django\views\decorators\csrf.py", line 54, in wrapped_view
    return view_func(*args, **kwargs)
  File "D:\Users\ntabyldieva\databases_v1\venv\lib\site-packages\django\views\generic\base.py", line 70, in view
    return self.dispatch(request, *args, **kwargs)
  File "D:\Users\ntabyldieva\databases_v1\venv\lib\site-packages\rest_framework\views.py", line 509, in dispatch
    response = self.handle_exception(exc)
  File "D:\Users\ntabyldieva\databases_v1\venv\lib\site-packages\rest_framework\views.py", line 469, in handle_exception
    self.raise_uncaught_exception(exc)
  File "D:\Users\ntabyldieva\databases_v1\venv\lib\site-packages\rest_framework\views.py", line 480, in raise_uncaught_exception
    raise exc
  File "D:\Users\ntabyldieva\databases_v1\venv\lib\site-packages\rest_framework\views.py", line 506, in dispatch
    response = handler(request, *args, **kwargs)
  File "D:\Users\ntabyldieva\databases_v1\work\data_filter_api.py", line 75, in post
    return Response(serializer.data)
  File "D:\Users\ntabyldieva\databases_v1\venv\lib\site-packages\rest_framework\serializers.py", line 745, in data
    ret = super().data
  File "D:\Users\ntabyldieva\databases_v1\venv\lib\site-packages\rest_framework\serializers.py", line 246, in data
    self._data = self.to_representation(self.instance)
  File "D:\Users\ntabyldieva\databases_v1\venv\lib\site-packages\rest_framework\serializers.py", line 663, in to_representation
    return [
  File "D:\Users\ntabyldieva\databases_v1\venv\lib\site-packages\rest_framework\serializers.py", line 664, in <listcomp>
    self.child.to_representation(item) for item in iterable
  File "D:\Users\ntabyldieva\databases_v1\venv\lib\site-packages\rest_framework\serializers.py", line 502, in to_representation
    attribute = field.get_attribute(instance)
  File "D:\Users\ntabyldieva\databases_v1\venv\lib\site-packages\rest_framework\fields.py", line 490, in get_attribute
    raise type(exc)(msg)
KeyError: "Got KeyError when attempting to get a value for field `country` on serializer `DataFilterApiSerializer`.\nThe serializer field might be named incorrectly and not match any attribute or key on the `dict` instance.\nOriginal exception text was: 'country'."
ERROR django.server "POST /work/test-data/get/ HTTP/1.1" 500 131420 2021-10-21 16:33:28,157
ERROR django.request Internal Server Error: /work/test-data/get/ 2021-10-21 16:33:31,000
Traceback (most recent call last):
  File "D:\Users\ntabyldieva\databases_v1\venv\lib\site-packages\django\core\handlers\exception.py", line 47, in inner
    response = get_response(request)
  File "D:\Users\ntabyldieva\databases_v1\venv\lib\site-packages\django\core\handlers\base.py", line 181, in _get_response
    response = wrapped_callback(request, *callback_args, **callback_kwargs)
  File "D:\Users\ntabyldieva\databases_v1\venv\lib\site-packages\django\views\decorators\csrf.py", line 54, in wrapped_view
    return view_func(*args, **kwargs)
  File "D:\Users\ntabyldieva\databases_v1\venv\lib\site-packages\django\views\generic\base.py", line 70, in view
    return self.dispatch(request, *args, **kwargs)
  File "D:\Users\ntabyldieva\databases_v1\venv\lib\site-packages\rest_framework\views.py", line 509, in dispatch
    response = self.handle_exception(exc)
  File "D:\Users\ntabyldieva\databases_v1\venv\lib\site-packages\rest_framework\views.py", line 469, in handle_exception
    self.raise_uncaught_exception(exc)
  File "D:\Users\ntabyldieva\databases_v1\venv\lib\site-packages\rest_framework\views.py", line 480, in raise_uncaught_exception
    raise exc
  File "D:\Users\ntabyldieva\databases_v1\venv\lib\site-packages\rest_framework\views.py", line 506, in dispatch
    response = handler(request, *args, **kwargs)
  File "D:\Users\ntabyldieva\databases_v1\work\data_filter_api.py", line 74, in post
    serializer = DataFilterApiSerializer(queryset, many=True, fields=fields)
  File "D:\Users\ntabyldieva\databases_v1\venv\lib\site-packages\rest_framework\serializers.py", line 121, in __new__
    return cls.many_init(*args, **kwargs)
  File "D:\Users\ntabyldieva\databases_v1\venv\lib\site-packages\rest_framework\serializers.py", line 146, in many_init
    child_serializer = cls(*args, **kwargs)
  File "D:\Users\ntabyldieva\databases_v1\work\serializers.py", line 282, in __init__
    existing = set(self.fields)
  File "D:\Users\ntabyldieva\databases_v1\venv\lib\site-packages\django\utils\functional.py", line 48, in __get__
    res = instance.__dict__[self.name] = self.func(instance)
  File "D:\Users\ntabyldieva\databases_v1\venv\lib\site-packages\rest_framework\serializers.py", line 349, in fields
    for key, value in self.get_fields().items():
  File "D:\Users\ntabyldieva\databases_v1\venv\lib\site-packages\rest_framework\serializers.py", line 1029, in get_fields
    field_names = self.get_field_names(declared_fields, info)
  File "D:\Users\ntabyldieva\databases_v1\venv\lib\site-packages\rest_framework\serializers.py", line 1125, in get_field_names
    assert field_name in fields, (
AssertionError: The field 'country_' was declared on serializer DataFilterApiSerializer, but has not been included in the 'fields' option.
ERROR django.server "POST /work/test-data/get/ HTTP/1.1" 500 137705 2021-10-21 16:33:31,004
ERROR django.request Internal Server Error: /work/test-data/get/ 2021-10-21 16:33:38,129
Traceback (most recent call last):
  File "D:\Users\ntabyldieva\databases_v1\venv\lib\site-packages\django\core\handlers\exception.py", line 47, in inner
    response = get_response(request)
  File "D:\Users\ntabyldieva\databases_v1\venv\lib\site-packages\django\core\handlers\base.py", line 181, in _get_response
    response = wrapped_callback(request, *callback_args, **callback_kwargs)
  File "D:\Users\ntabyldieva\databases_v1\venv\lib\site-packages\django\views\decorators\csrf.py", line 54, in wrapped_view
    return view_func(*args, **kwargs)
  File "D:\Users\ntabyldieva\databases_v1\venv\lib\site-packages\django\views\generic\base.py", line 70, in view
    return self.dispatch(request, *args, **kwargs)
  File "D:\Users\ntabyldieva\databases_v1\venv\lib\site-packages\rest_framework\views.py", line 509, in dispatch
    response = self.handle_exception(exc)
  File "D:\Users\ntabyldieva\databases_v1\venv\lib\site-packages\rest_framework\views.py", line 469, in handle_exception
    self.raise_uncaught_exception(exc)
  File "D:\Users\ntabyldieva\databases_v1\venv\lib\site-packages\rest_framework\views.py", line 480, in raise_uncaught_exception
    raise exc
  File "D:\Users\ntabyldieva\databases_v1\venv\lib\site-packages\rest_framework\views.py", line 506, in dispatch
    response = handler(request, *args, **kwargs)
  File "D:\Users\ntabyldieva\databases_v1\work\data_filter_api.py", line 74, in post
    serializer = DataFilterApiSerializer(queryset, many=True, fields=fields)
  File "D:\Users\ntabyldieva\databases_v1\venv\lib\site-packages\rest_framework\serializers.py", line 121, in __new__
    return cls.many_init(*args, **kwargs)
  File "D:\Users\ntabyldieva\databases_v1\venv\lib\site-packages\rest_framework\serializers.py", line 146, in many_init
    child_serializer = cls(*args, **kwargs)
  File "D:\Users\ntabyldieva\databases_v1\work\serializers.py", line 282, in __init__
    existing = set(self.fields)
  File "D:\Users\ntabyldieva\databases_v1\venv\lib\site-packages\django\utils\functional.py", line 48, in __get__
    res = instance.__dict__[self.name] = self.func(instance)
  File "D:\Users\ntabyldieva\databases_v1\venv\lib\site-packages\rest_framework\serializers.py", line 349, in fields
    for key, value in self.get_fields().items():
  File "D:\Users\ntabyldieva\databases_v1\venv\lib\site-packages\rest_framework\serializers.py", line 1029, in get_fields
    field_names = self.get_field_names(declared_fields, info)
  File "D:\Users\ntabyldieva\databases_v1\venv\lib\site-packages\rest_framework\serializers.py", line 1125, in get_field_names
    assert field_name in fields, (
AssertionError: The field 'country_' was declared on serializer DataFilterApiSerializer, but has not been included in the 'fields' option.
ERROR django.server "POST /work/test-data/get/ HTTP/1.1" 500 137705 2021-10-21 16:33:38,132
ERROR django.request Internal Server Error: /work/test-data/get/ 2021-10-21 16:34:45,493
Traceback (most recent call last):
  File "D:\Users\ntabyldieva\databases_v1\venv\lib\site-packages\rest_framework\fields.py", line 457, in get_attribute
    return get_attribute(instance, self.source_attrs)
  File "D:\Users\ntabyldieva\databases_v1\venv\lib\site-packages\rest_framework\fields.py", line 95, in get_attribute
    instance = instance[attr]
KeyError: 'country_id'

During handling of the above exception, another exception occurred:

Traceback (most recent call last):
  File "D:\Users\ntabyldieva\databases_v1\venv\lib\site-packages\django\core\handlers\exception.py", line 47, in inner
    response = get_response(request)
  File "D:\Users\ntabyldieva\databases_v1\venv\lib\site-packages\django\core\handlers\base.py", line 181, in _get_response
    response = wrapped_callback(request, *callback_args, **callback_kwargs)
  File "D:\Users\ntabyldieva\databases_v1\venv\lib\site-packages\django\views\decorators\csrf.py", line 54, in wrapped_view
    return view_func(*args, **kwargs)
  File "D:\Users\ntabyldieva\databases_v1\venv\lib\site-packages\django\views\generic\base.py", line 70, in view
    return self.dispatch(request, *args, **kwargs)
  File "D:\Users\ntabyldieva\databases_v1\venv\lib\site-packages\rest_framework\views.py", line 509, in dispatch
    response = self.handle_exception(exc)
  File "D:\Users\ntabyldieva\databases_v1\venv\lib\site-packages\rest_framework\views.py", line 469, in handle_exception
    self.raise_uncaught_exception(exc)
  File "D:\Users\ntabyldieva\databases_v1\venv\lib\site-packages\rest_framework\views.py", line 480, in raise_uncaught_exception
    raise exc
  File "D:\Users\ntabyldieva\databases_v1\venv\lib\site-packages\rest_framework\views.py", line 506, in dispatch
    response = handler(request, *args, **kwargs)
  File "D:\Users\ntabyldieva\databases_v1\work\data_filter_api.py", line 75, in post
    return Response(serializer.data)
  File "D:\Users\ntabyldieva\databases_v1\venv\lib\site-packages\rest_framework\serializers.py", line 745, in data
    ret = super().data
  File "D:\Users\ntabyldieva\databases_v1\venv\lib\site-packages\rest_framework\serializers.py", line 246, in data
    self._data = self.to_representation(self.instance)
  File "D:\Users\ntabyldieva\databases_v1\venv\lib\site-packages\rest_framework\serializers.py", line 663, in to_representation
    return [
  File "D:\Users\ntabyldieva\databases_v1\venv\lib\site-packages\rest_framework\serializers.py", line 664, in <listcomp>
    self.child.to_representation(item) for item in iterable
  File "D:\Users\ntabyldieva\databases_v1\venv\lib\site-packages\rest_framework\serializers.py", line 502, in to_representation
    attribute = field.get_attribute(instance)
  File "D:\Users\ntabyldieva\databases_v1\venv\lib\site-packages\rest_framework\fields.py", line 490, in get_attribute
    raise type(exc)(msg)
KeyError: "Got KeyError when attempting to get a value for field `country_id` on serializer `DataFilterApiSerializer`.\nThe serializer field might be named incorrectly and not match any attribute or key on the `dict` instance.\nOriginal exception text was: 'country_id'."
ERROR django.server "POST /work/test-data/get/ HTTP/1.1" 500 132184 2021-10-21 16:34:45,497
ERROR django.request Internal Server Error: /work/test-data/get/ 2021-10-21 16:34:46,288
Traceback (most recent call last):
  File "D:\Users\ntabyldieva\databases_v1\venv\lib\site-packages\rest_framework\fields.py", line 457, in get_attribute
    return get_attribute(instance, self.source_attrs)
  File "D:\Users\ntabyldieva\databases_v1\venv\lib\site-packages\rest_framework\fields.py", line 95, in get_attribute
    instance = instance[attr]
KeyError: 'country_id'

During handling of the above exception, another exception occurred:

Traceback (most recent call last):
  File "D:\Users\ntabyldieva\databases_v1\venv\lib\site-packages\django\core\handlers\exception.py", line 47, in inner
    response = get_response(request)
  File "D:\Users\ntabyldieva\databases_v1\venv\lib\site-packages\django\core\handlers\base.py", line 181, in _get_response
    response = wrapped_callback(request, *callback_args, **callback_kwargs)
  File "D:\Users\ntabyldieva\databases_v1\venv\lib\site-packages\django\views\decorators\csrf.py", line 54, in wrapped_view
    return view_func(*args, **kwargs)
  File "D:\Users\ntabyldieva\databases_v1\venv\lib\site-packages\django\views\generic\base.py", line 70, in view
    return self.dispatch(request, *args, **kwargs)
  File "D:\Users\ntabyldieva\databases_v1\venv\lib\site-packages\rest_framework\views.py", line 509, in dispatch
    response = self.handle_exception(exc)
  File "D:\Users\ntabyldieva\databases_v1\venv\lib\site-packages\rest_framework\views.py", line 469, in handle_exception
    self.raise_uncaught_exception(exc)
  File "D:\Users\ntabyldieva\databases_v1\venv\lib\site-packages\rest_framework\views.py", line 480, in raise_uncaught_exception
    raise exc
  File "D:\Users\ntabyldieva\databases_v1\venv\lib\site-packages\rest_framework\views.py", line 506, in dispatch
    response = handler(request, *args, **kwargs)
  File "D:\Users\ntabyldieva\databases_v1\work\data_filter_api.py", line 75, in post
    return Response(serializer.data)
  File "D:\Users\ntabyldieva\databases_v1\venv\lib\site-packages\rest_framework\serializers.py", line 745, in data
    ret = super().data
  File "D:\Users\ntabyldieva\databases_v1\venv\lib\site-packages\rest_framework\serializers.py", line 246, in data
    self._data = self.to_representation(self.instance)
  File "D:\Users\ntabyldieva\databases_v1\venv\lib\site-packages\rest_framework\serializers.py", line 663, in to_representation
    return [
  File "D:\Users\ntabyldieva\databases_v1\venv\lib\site-packages\rest_framework\serializers.py", line 664, in <listcomp>
    self.child.to_representation(item) for item in iterable
  File "D:\Users\ntabyldieva\databases_v1\venv\lib\site-packages\rest_framework\serializers.py", line 502, in to_representation
    attribute = field.get_attribute(instance)
  File "D:\Users\ntabyldieva\databases_v1\venv\lib\site-packages\rest_framework\fields.py", line 490, in get_attribute
    raise type(exc)(msg)
KeyError: "Got KeyError when attempting to get a value for field `country_id` on serializer `DataFilterApiSerializer`.\nThe serializer field might be named incorrectly and not match any attribute or key on the `dict` instance.\nOriginal exception text was: 'country_id'."
ERROR django.server "POST /work/test-data/get/ HTTP/1.1" 500 132184 2021-10-21 16:34:46,291
ERROR django.request Internal Server Error: /work/test-data/get/ 2021-10-21 16:34:47,157
Traceback (most recent call last):
  File "D:\Users\ntabyldieva\databases_v1\venv\lib\site-packages\rest_framework\fields.py", line 457, in get_attribute
    return get_attribute(instance, self.source_attrs)
  File "D:\Users\ntabyldieva\databases_v1\venv\lib\site-packages\rest_framework\fields.py", line 95, in get_attribute
    instance = instance[attr]
KeyError: 'country_id'

During handling of the above exception, another exception occurred:

Traceback (most recent call last):
  File "D:\Users\ntabyldieva\databases_v1\venv\lib\site-packages\django\core\handlers\exception.py", line 47, in inner
    response = get_response(request)
  File "D:\Users\ntabyldieva\databases_v1\venv\lib\site-packages\django\core\handlers\base.py", line 181, in _get_response
    response = wrapped_callback(request, *callback_args, **callback_kwargs)
  File "D:\Users\ntabyldieva\databases_v1\venv\lib\site-packages\django\views\decorators\csrf.py", line 54, in wrapped_view
    return view_func(*args, **kwargs)
  File "D:\Users\ntabyldieva\databases_v1\venv\lib\site-packages\django\views\generic\base.py", line 70, in view
    return self.dispatch(request, *args, **kwargs)
  File "D:\Users\ntabyldieva\databases_v1\venv\lib\site-packages\rest_framework\views.py", line 509, in dispatch
    response = self.handle_exception(exc)
  File "D:\Users\ntabyldieva\databases_v1\venv\lib\site-packages\rest_framework\views.py", line 469, in handle_exception
    self.raise_uncaught_exception(exc)
  File "D:\Users\ntabyldieva\databases_v1\venv\lib\site-packages\rest_framework\views.py", line 480, in raise_uncaught_exception
    raise exc
  File "D:\Users\ntabyldieva\databases_v1\venv\lib\site-packages\rest_framework\views.py", line 506, in dispatch
    response = handler(request, *args, **kwargs)
  File "D:\Users\ntabyldieva\databases_v1\work\data_filter_api.py", line 75, in post
    return Response(serializer.data)
  File "D:\Users\ntabyldieva\databases_v1\venv\lib\site-packages\rest_framework\serializers.py", line 745, in data
    ret = super().data
  File "D:\Users\ntabyldieva\databases_v1\venv\lib\site-packages\rest_framework\serializers.py", line 246, in data
    self._data = self.to_representation(self.instance)
  File "D:\Users\ntabyldieva\databases_v1\venv\lib\site-packages\rest_framework\serializers.py", line 663, in to_representation
    return [
  File "D:\Users\ntabyldieva\databases_v1\venv\lib\site-packages\rest_framework\serializers.py", line 664, in <listcomp>
    self.child.to_representation(item) for item in iterable
  File "D:\Users\ntabyldieva\databases_v1\venv\lib\site-packages\rest_framework\serializers.py", line 502, in to_representation
    attribute = field.get_attribute(instance)
  File "D:\Users\ntabyldieva\databases_v1\venv\lib\site-packages\rest_framework\fields.py", line 490, in get_attribute
    raise type(exc)(msg)
KeyError: "Got KeyError when attempting to get a value for field `country_id` on serializer `DataFilterApiSerializer`.\nThe serializer field might be named incorrectly and not match any attribute or key on the `dict` instance.\nOriginal exception text was: 'country_id'."
ERROR django.server "POST /work/test-data/get/ HTTP/1.1" 500 132184 2021-10-21 16:34:47,160
ERROR django.request Internal Server Error: /work/test-data/get/ 2021-10-21 16:34:47,685
Traceback (most recent call last):
  File "D:\Users\ntabyldieva\databases_v1\venv\lib\site-packages\rest_framework\fields.py", line 457, in get_attribute
    return get_attribute(instance, self.source_attrs)
  File "D:\Users\ntabyldieva\databases_v1\venv\lib\site-packages\rest_framework\fields.py", line 95, in get_attribute
    instance = instance[attr]
KeyError: 'country_id'

During handling of the above exception, another exception occurred:

Traceback (most recent call last):
  File "D:\Users\ntabyldieva\databases_v1\venv\lib\site-packages\django\core\handlers\exception.py", line 47, in inner
    response = get_response(request)
  File "D:\Users\ntabyldieva\databases_v1\venv\lib\site-packages\django\core\handlers\base.py", line 181, in _get_response
    response = wrapped_callback(request, *callback_args, **callback_kwargs)
  File "D:\Users\ntabyldieva\databases_v1\venv\lib\site-packages\django\views\decorators\csrf.py", line 54, in wrapped_view
    return view_func(*args, **kwargs)
  File "D:\Users\ntabyldieva\databases_v1\venv\lib\site-packages\django\views\generic\base.py", line 70, in view
    return self.dispatch(request, *args, **kwargs)
  File "D:\Users\ntabyldieva\databases_v1\venv\lib\site-packages\rest_framework\views.py", line 509, in dispatch
    response = self.handle_exception(exc)
  File "D:\Users\ntabyldieva\databases_v1\venv\lib\site-packages\rest_framework\views.py", line 469, in handle_exception
    self.raise_uncaught_exception(exc)
  File "D:\Users\ntabyldieva\databases_v1\venv\lib\site-packages\rest_framework\views.py", line 480, in raise_uncaught_exception
    raise exc
  File "D:\Users\ntabyldieva\databases_v1\venv\lib\site-packages\rest_framework\views.py", line 506, in dispatch
    response = handler(request, *args, **kwargs)
  File "D:\Users\ntabyldieva\databases_v1\work\data_filter_api.py", line 75, in post
    return Response(serializer.data)
  File "D:\Users\ntabyldieva\databases_v1\venv\lib\site-packages\rest_framework\serializers.py", line 745, in data
    ret = super().data
  File "D:\Users\ntabyldieva\databases_v1\venv\lib\site-packages\rest_framework\serializers.py", line 246, in data
    self._data = self.to_representation(self.instance)
  File "D:\Users\ntabyldieva\databases_v1\venv\lib\site-packages\rest_framework\serializers.py", line 663, in to_representation
    return [
  File "D:\Users\ntabyldieva\databases_v1\venv\lib\site-packages\rest_framework\serializers.py", line 664, in <listcomp>
    self.child.to_representation(item) for item in iterable
  File "D:\Users\ntabyldieva\databases_v1\venv\lib\site-packages\rest_framework\serializers.py", line 502, in to_representation
    attribute = field.get_attribute(instance)
  File "D:\Users\ntabyldieva\databases_v1\venv\lib\site-packages\rest_framework\fields.py", line 490, in get_attribute
    raise type(exc)(msg)
KeyError: "Got KeyError when attempting to get a value for field `country_id` on serializer `DataFilterApiSerializer`.\nThe serializer field might be named incorrectly and not match any attribute or key on the `dict` instance.\nOriginal exception text was: 'country_id'."
ERROR django.server "POST /work/test-data/get/ HTTP/1.1" 500 132184 2021-10-21 16:34:47,688
ERROR django.request Internal Server Error: /work/test-data/get/ 2021-10-21 16:37:38,213
Traceback (most recent call last):
  File "D:\Users\ntabyldieva\databases_v1\venv\lib\site-packages\rest_framework\fields.py", line 457, in get_attribute
    return get_attribute(instance, self.source_attrs)
  File "D:\Users\ntabyldieva\databases_v1\venv\lib\site-packages\rest_framework\fields.py", line 95, in get_attribute
    instance = instance[attr]
KeyError: 'country__id'

During handling of the above exception, another exception occurred:

Traceback (most recent call last):
  File "D:\Users\ntabyldieva\databases_v1\venv\lib\site-packages\django\core\handlers\exception.py", line 47, in inner
    response = get_response(request)
  File "D:\Users\ntabyldieva\databases_v1\venv\lib\site-packages\django\core\handlers\base.py", line 181, in _get_response
    response = wrapped_callback(request, *callback_args, **callback_kwargs)
  File "D:\Users\ntabyldieva\databases_v1\venv\lib\site-packages\django\views\decorators\csrf.py", line 54, in wrapped_view
    return view_func(*args, **kwargs)
  File "D:\Users\ntabyldieva\databases_v1\venv\lib\site-packages\django\views\generic\base.py", line 70, in view
    return self.dispatch(request, *args, **kwargs)
  File "D:\Users\ntabyldieva\databases_v1\venv\lib\site-packages\rest_framework\views.py", line 509, in dispatch
    response = self.handle_exception(exc)
  File "D:\Users\ntabyldieva\databases_v1\venv\lib\site-packages\rest_framework\views.py", line 469, in handle_exception
    self.raise_uncaught_exception(exc)
  File "D:\Users\ntabyldieva\databases_v1\venv\lib\site-packages\rest_framework\views.py", line 480, in raise_uncaught_exception
    raise exc
  File "D:\Users\ntabyldieva\databases_v1\venv\lib\site-packages\rest_framework\views.py", line 506, in dispatch
    response = handler(request, *args, **kwargs)
  File "D:\Users\ntabyldieva\databases_v1\work\data_filter_api.py", line 75, in post
    return Response(serializer.data)
  File "D:\Users\ntabyldieva\databases_v1\venv\lib\site-packages\rest_framework\serializers.py", line 745, in data
    ret = super().data
  File "D:\Users\ntabyldieva\databases_v1\venv\lib\site-packages\rest_framework\serializers.py", line 246, in data
    self._data = self.to_representation(self.instance)
  File "D:\Users\ntabyldieva\databases_v1\venv\lib\site-packages\rest_framework\serializers.py", line 663, in to_representation
    return [
  File "D:\Users\ntabyldieva\databases_v1\venv\lib\site-packages\rest_framework\serializers.py", line 664, in <listcomp>
    self.child.to_representation(item) for item in iterable
  File "D:\Users\ntabyldieva\databases_v1\venv\lib\site-packages\rest_framework\serializers.py", line 502, in to_representation
    attribute = field.get_attribute(instance)
  File "D:\Users\ntabyldieva\databases_v1\venv\lib\site-packages\rest_framework\fields.py", line 490, in get_attribute
    raise type(exc)(msg)
KeyError: "Got KeyError when attempting to get a value for field `country_id` on serializer `DataFilterApiSerializer`.\nThe serializer field might be named incorrectly and not match any attribute or key on the `dict` instance.\nOriginal exception text was: 'country__id'."
ERROR django.server "POST /work/test-data/get/ HTTP/1.1" 500 132466 2021-10-21 16:37:38,218
ERROR django.request Internal Server Error: /work/test-data/get/ 2021-10-21 16:37:39,856
Traceback (most recent call last):
  File "D:\Users\ntabyldieva\databases_v1\venv\lib\site-packages\rest_framework\fields.py", line 457, in get_attribute
    return get_attribute(instance, self.source_attrs)
  File "D:\Users\ntabyldieva\databases_v1\venv\lib\site-packages\rest_framework\fields.py", line 95, in get_attribute
    instance = instance[attr]
KeyError: 'country__id'

During handling of the above exception, another exception occurred:

Traceback (most recent call last):
  File "D:\Users\ntabyldieva\databases_v1\venv\lib\site-packages\django\core\handlers\exception.py", line 47, in inner
    response = get_response(request)
  File "D:\Users\ntabyldieva\databases_v1\venv\lib\site-packages\django\core\handlers\base.py", line 181, in _get_response
    response = wrapped_callback(request, *callback_args, **callback_kwargs)
  File "D:\Users\ntabyldieva\databases_v1\venv\lib\site-packages\django\views\decorators\csrf.py", line 54, in wrapped_view
    return view_func(*args, **kwargs)
  File "D:\Users\ntabyldieva\databases_v1\venv\lib\site-packages\django\views\generic\base.py", line 70, in view
    return self.dispatch(request, *args, **kwargs)
  File "D:\Users\ntabyldieva\databases_v1\venv\lib\site-packages\rest_framework\views.py", line 509, in dispatch
    response = self.handle_exception(exc)
  File "D:\Users\ntabyldieva\databases_v1\venv\lib\site-packages\rest_framework\views.py", line 469, in handle_exception
    self.raise_uncaught_exception(exc)
  File "D:\Users\ntabyldieva\databases_v1\venv\lib\site-packages\rest_framework\views.py", line 480, in raise_uncaught_exception
    raise exc
  File "D:\Users\ntabyldieva\databases_v1\venv\lib\site-packages\rest_framework\views.py", line 506, in dispatch
    response = handler(request, *args, **kwargs)
  File "D:\Users\ntabyldieva\databases_v1\work\data_filter_api.py", line 75, in post
    return Response(serializer.data)
  File "D:\Users\ntabyldieva\databases_v1\venv\lib\site-packages\rest_framework\serializers.py", line 745, in data
    ret = super().data
  File "D:\Users\ntabyldieva\databases_v1\venv\lib\site-packages\rest_framework\serializers.py", line 246, in data
    self._data = self.to_representation(self.instance)
  File "D:\Users\ntabyldieva\databases_v1\venv\lib\site-packages\rest_framework\serializers.py", line 663, in to_representation
    return [
  File "D:\Users\ntabyldieva\databases_v1\venv\lib\site-packages\rest_framework\serializers.py", line 664, in <listcomp>
    self.child.to_representation(item) for item in iterable
  File "D:\Users\ntabyldieva\databases_v1\venv\lib\site-packages\rest_framework\serializers.py", line 502, in to_representation
    attribute = field.get_attribute(instance)
  File "D:\Users\ntabyldieva\databases_v1\venv\lib\site-packages\rest_framework\fields.py", line 490, in get_attribute
    raise type(exc)(msg)
KeyError: "Got KeyError when attempting to get a value for field `country_id` on serializer `DataFilterApiSerializer`.\nThe serializer field might be named incorrectly and not match any attribute or key on the `dict` instance.\nOriginal exception text was: 'country__id'."
ERROR django.server "POST /work/test-data/get/ HTTP/1.1" 500 132466 2021-10-21 16:37:39,860
ERROR django.request Internal Server Error: /work/test-data/get/ 2021-10-21 16:37:56,826
Traceback (most recent call last):
  File "D:\Users\ntabyldieva\databases_v1\venv\lib\site-packages\rest_framework\fields.py", line 457, in get_attribute
    return get_attribute(instance, self.source_attrs)
  File "D:\Users\ntabyldieva\databases_v1\venv\lib\site-packages\rest_framework\fields.py", line 95, in get_attribute
    instance = instance[attr]
KeyError: 'country__id'

During handling of the above exception, another exception occurred:

Traceback (most recent call last):
  File "D:\Users\ntabyldieva\databases_v1\venv\lib\site-packages\django\core\handlers\exception.py", line 47, in inner
    response = get_response(request)
  File "D:\Users\ntabyldieva\databases_v1\venv\lib\site-packages\django\core\handlers\base.py", line 181, in _get_response
    response = wrapped_callback(request, *callback_args, **callback_kwargs)
  File "D:\Users\ntabyldieva\databases_v1\venv\lib\site-packages\django\views\decorators\csrf.py", line 54, in wrapped_view
    return view_func(*args, **kwargs)
  File "D:\Users\ntabyldieva\databases_v1\venv\lib\site-packages\django\views\generic\base.py", line 70, in view
    return self.dispatch(request, *args, **kwargs)
  File "D:\Users\ntabyldieva\databases_v1\venv\lib\site-packages\rest_framework\views.py", line 509, in dispatch
    response = self.handle_exception(exc)
  File "D:\Users\ntabyldieva\databases_v1\venv\lib\site-packages\rest_framework\views.py", line 469, in handle_exception
    self.raise_uncaught_exception(exc)
  File "D:\Users\ntabyldieva\databases_v1\venv\lib\site-packages\rest_framework\views.py", line 480, in raise_uncaught_exception
    raise exc
  File "D:\Users\ntabyldieva\databases_v1\venv\lib\site-packages\rest_framework\views.py", line 506, in dispatch
    response = handler(request, *args, **kwargs)
  File "D:\Users\ntabyldieva\databases_v1\work\data_filter_api.py", line 75, in post
    return Response(serializer.data)
  File "D:\Users\ntabyldieva\databases_v1\venv\lib\site-packages\rest_framework\serializers.py", line 745, in data
    ret = super().data
  File "D:\Users\ntabyldieva\databases_v1\venv\lib\site-packages\rest_framework\serializers.py", line 246, in data
    self._data = self.to_representation(self.instance)
  File "D:\Users\ntabyldieva\databases_v1\venv\lib\site-packages\rest_framework\serializers.py", line 663, in to_representation
    return [
  File "D:\Users\ntabyldieva\databases_v1\venv\lib\site-packages\rest_framework\serializers.py", line 664, in <listcomp>
    self.child.to_representation(item) for item in iterable
  File "D:\Users\ntabyldieva\databases_v1\venv\lib\site-packages\rest_framework\serializers.py", line 502, in to_representation
    attribute = field.get_attribute(instance)
  File "D:\Users\ntabyldieva\databases_v1\venv\lib\site-packages\rest_framework\fields.py", line 490, in get_attribute
    raise type(exc)(msg)
KeyError: "Got KeyError when attempting to get a value for field `country_id` on serializer `DataFilterApiSerializer`.\nThe serializer field might be named incorrectly and not match any attribute or key on the `dict` instance.\nOriginal exception text was: 'country__id'."
ERROR django.server "POST /work/test-data/get/ HTTP/1.1" 500 132466 2021-10-21 16:37:56,829
ERROR django.request Internal Server Error: /work/test-data/get/ 2021-10-21 16:37:58,725
Traceback (most recent call last):
  File "D:\Users\ntabyldieva\databases_v1\venv\lib\site-packages\rest_framework\fields.py", line 457, in get_attribute
    return get_attribute(instance, self.source_attrs)
  File "D:\Users\ntabyldieva\databases_v1\venv\lib\site-packages\rest_framework\fields.py", line 95, in get_attribute
    instance = instance[attr]
KeyError: 'country_id'

During handling of the above exception, another exception occurred:

Traceback (most recent call last):
  File "D:\Users\ntabyldieva\databases_v1\venv\lib\site-packages\django\core\handlers\exception.py", line 47, in inner
    response = get_response(request)
  File "D:\Users\ntabyldieva\databases_v1\venv\lib\site-packages\django\core\handlers\base.py", line 181, in _get_response
    response = wrapped_callback(request, *callback_args, **callback_kwargs)
  File "D:\Users\ntabyldieva\databases_v1\venv\lib\site-packages\django\views\decorators\csrf.py", line 54, in wrapped_view
    return view_func(*args, **kwargs)
  File "D:\Users\ntabyldieva\databases_v1\venv\lib\site-packages\django\views\generic\base.py", line 70, in view
    return self.dispatch(request, *args, **kwargs)
  File "D:\Users\ntabyldieva\databases_v1\venv\lib\site-packages\rest_framework\views.py", line 509, in dispatch
    response = self.handle_exception(exc)
  File "D:\Users\ntabyldieva\databases_v1\venv\lib\site-packages\rest_framework\views.py", line 469, in handle_exception
    self.raise_uncaught_exception(exc)
  File "D:\Users\ntabyldieva\databases_v1\venv\lib\site-packages\rest_framework\views.py", line 480, in raise_uncaught_exception
    raise exc
  File "D:\Users\ntabyldieva\databases_v1\venv\lib\site-packages\rest_framework\views.py", line 506, in dispatch
    response = handler(request, *args, **kwargs)
  File "D:\Users\ntabyldieva\databases_v1\work\data_filter_api.py", line 75, in post
    return Response(serializer.data)
  File "D:\Users\ntabyldieva\databases_v1\venv\lib\site-packages\rest_framework\serializers.py", line 745, in data
    ret = super().data
  File "D:\Users\ntabyldieva\databases_v1\venv\lib\site-packages\rest_framework\serializers.py", line 246, in data
    self._data = self.to_representation(self.instance)
  File "D:\Users\ntabyldieva\databases_v1\venv\lib\site-packages\rest_framework\serializers.py", line 663, in to_representation
    return [
  File "D:\Users\ntabyldieva\databases_v1\venv\lib\site-packages\rest_framework\serializers.py", line 664, in <listcomp>
    self.child.to_representation(item) for item in iterable
  File "D:\Users\ntabyldieva\databases_v1\venv\lib\site-packages\rest_framework\serializers.py", line 502, in to_representation
    attribute = field.get_attribute(instance)
  File "D:\Users\ntabyldieva\databases_v1\venv\lib\site-packages\rest_framework\fields.py", line 490, in get_attribute
    raise type(exc)(msg)
KeyError: "Got KeyError when attempting to get a value for field `country_id` on serializer `DataFilterApiSerializer`.\nThe serializer field might be named incorrectly and not match any attribute or key on the `dict` instance.\nOriginal exception text was: 'country_id'."
ERROR django.server "POST /work/test-data/get/ HTTP/1.1" 500 132184 2021-10-21 16:37:58,731
ERROR django.request Internal Server Error: /work/test-data/get/ 2021-10-21 16:38:05,936
Traceback (most recent call last):
  File "D:\Users\ntabyldieva\databases_v1\venv\lib\site-packages\rest_framework\fields.py", line 457, in get_attribute
    return get_attribute(instance, self.source_attrs)
  File "D:\Users\ntabyldieva\databases_v1\venv\lib\site-packages\rest_framework\fields.py", line 95, in get_attribute
    instance = instance[attr]
KeyError: 'country_id'

During handling of the above exception, another exception occurred:

Traceback (most recent call last):
  File "D:\Users\ntabyldieva\databases_v1\venv\lib\site-packages\django\core\handlers\exception.py", line 47, in inner
    response = get_response(request)
  File "D:\Users\ntabyldieva\databases_v1\venv\lib\site-packages\django\core\handlers\base.py", line 181, in _get_response
    response = wrapped_callback(request, *callback_args, **callback_kwargs)
  File "D:\Users\ntabyldieva\databases_v1\venv\lib\site-packages\django\views\decorators\csrf.py", line 54, in wrapped_view
    return view_func(*args, **kwargs)
  File "D:\Users\ntabyldieva\databases_v1\venv\lib\site-packages\django\views\generic\base.py", line 70, in view
    return self.dispatch(request, *args, **kwargs)
  File "D:\Users\ntabyldieva\databases_v1\venv\lib\site-packages\rest_framework\views.py", line 509, in dispatch
    response = self.handle_exception(exc)
  File "D:\Users\ntabyldieva\databases_v1\venv\lib\site-packages\rest_framework\views.py", line 469, in handle_exception
    self.raise_uncaught_exception(exc)
  File "D:\Users\ntabyldieva\databases_v1\venv\lib\site-packages\rest_framework\views.py", line 480, in raise_uncaught_exception
    raise exc
  File "D:\Users\ntabyldieva\databases_v1\venv\lib\site-packages\rest_framework\views.py", line 506, in dispatch
    response = handler(request, *args, **kwargs)
  File "D:\Users\ntabyldieva\databases_v1\work\data_filter_api.py", line 75, in post
    return Response(serializer.data)
  File "D:\Users\ntabyldieva\databases_v1\venv\lib\site-packages\rest_framework\serializers.py", line 745, in data
    ret = super().data
  File "D:\Users\ntabyldieva\databases_v1\venv\lib\site-packages\rest_framework\serializers.py", line 246, in data
    self._data = self.to_representation(self.instance)
  File "D:\Users\ntabyldieva\databases_v1\venv\lib\site-packages\rest_framework\serializers.py", line 663, in to_representation
    return [
  File "D:\Users\ntabyldieva\databases_v1\venv\lib\site-packages\rest_framework\serializers.py", line 664, in <listcomp>
    self.child.to_representation(item) for item in iterable
  File "D:\Users\ntabyldieva\databases_v1\venv\lib\site-packages\rest_framework\serializers.py", line 502, in to_representation
    attribute = field.get_attribute(instance)
  File "D:\Users\ntabyldieva\databases_v1\venv\lib\site-packages\rest_framework\fields.py", line 490, in get_attribute
    raise type(exc)(msg)
KeyError: "Got KeyError when attempting to get a value for field `country_id` on serializer `DataFilterApiSerializer`.\nThe serializer field might be named incorrectly and not match any attribute or key on the `dict` instance.\nOriginal exception text was: 'country_id'."
ERROR django.server "POST /work/test-data/get/ HTTP/1.1" 500 132184 2021-10-21 16:38:05,939
ERROR django.request Internal Server Error: /work/test-data/get/ 2021-10-21 16:39:02,934
Traceback (most recent call last):
  File "D:\Users\ntabyldieva\databases_v1\venv\lib\site-packages\rest_framework\fields.py", line 457, in get_attribute
    return get_attribute(instance, self.source_attrs)
  File "D:\Users\ntabyldieva\databases_v1\venv\lib\site-packages\rest_framework\fields.py", line 95, in get_attribute
    instance = instance[attr]
KeyError: 'country_id'

During handling of the above exception, another exception occurred:

Traceback (most recent call last):
  File "D:\Users\ntabyldieva\databases_v1\venv\lib\site-packages\django\core\handlers\exception.py", line 47, in inner
    response = get_response(request)
  File "D:\Users\ntabyldieva\databases_v1\venv\lib\site-packages\django\core\handlers\base.py", line 181, in _get_response
    response = wrapped_callback(request, *callback_args, **callback_kwargs)
  File "D:\Users\ntabyldieva\databases_v1\venv\lib\site-packages\django\views\decorators\csrf.py", line 54, in wrapped_view
    return view_func(*args, **kwargs)
  File "D:\Users\ntabyldieva\databases_v1\venv\lib\site-packages\django\views\generic\base.py", line 70, in view
    return self.dispatch(request, *args, **kwargs)
  File "D:\Users\ntabyldieva\databases_v1\venv\lib\site-packages\rest_framework\views.py", line 509, in dispatch
    response = self.handle_exception(exc)
  File "D:\Users\ntabyldieva\databases_v1\venv\lib\site-packages\rest_framework\views.py", line 469, in handle_exception
    self.raise_uncaught_exception(exc)
  File "D:\Users\ntabyldieva\databases_v1\venv\lib\site-packages\rest_framework\views.py", line 480, in raise_uncaught_exception
    raise exc
  File "D:\Users\ntabyldieva\databases_v1\venv\lib\site-packages\rest_framework\views.py", line 506, in dispatch
    response = handler(request, *args, **kwargs)
  File "D:\Users\ntabyldieva\databases_v1\work\data_filter_api.py", line 75, in post
    return Response(serializer.data)
  File "D:\Users\ntabyldieva\databases_v1\venv\lib\site-packages\rest_framework\serializers.py", line 745, in data
    ret = super().data
  File "D:\Users\ntabyldieva\databases_v1\venv\lib\site-packages\rest_framework\serializers.py", line 246, in data
    self._data = self.to_representation(self.instance)
  File "D:\Users\ntabyldieva\databases_v1\venv\lib\site-packages\rest_framework\serializers.py", line 663, in to_representation
    return [
  File "D:\Users\ntabyldieva\databases_v1\venv\lib\site-packages\rest_framework\serializers.py", line 664, in <listcomp>
    self.child.to_representation(item) for item in iterable
  File "D:\Users\ntabyldieva\databases_v1\venv\lib\site-packages\rest_framework\serializers.py", line 502, in to_representation
    attribute = field.get_attribute(instance)
  File "D:\Users\ntabyldieva\databases_v1\venv\lib\site-packages\rest_framework\fields.py", line 490, in get_attribute
    raise type(exc)(msg)
KeyError: "Got KeyError when attempting to get a value for field `country_id` on serializer `DataFilterApiSerializer`.\nThe serializer field might be named incorrectly and not match any attribute or key on the `dict` instance.\nOriginal exception text was: 'country_id'."
ERROR django.server "POST /work/test-data/get/ HTTP/1.1" 500 132184 2021-10-21 16:39:02,939
ERROR django.request Internal Server Error: /work/test-data/get/ 2021-10-21 16:39:03,852
Traceback (most recent call last):
  File "D:\Users\ntabyldieva\databases_v1\venv\lib\site-packages\rest_framework\fields.py", line 457, in get_attribute
    return get_attribute(instance, self.source_attrs)
  File "D:\Users\ntabyldieva\databases_v1\venv\lib\site-packages\rest_framework\fields.py", line 95, in get_attribute
    instance = instance[attr]
KeyError: 'country_id'

During handling of the above exception, another exception occurred:

Traceback (most recent call last):
  File "D:\Users\ntabyldieva\databases_v1\venv\lib\site-packages\django\core\handlers\exception.py", line 47, in inner
    response = get_response(request)
  File "D:\Users\ntabyldieva\databases_v1\venv\lib\site-packages\django\core\handlers\base.py", line 181, in _get_response
    response = wrapped_callback(request, *callback_args, **callback_kwargs)
  File "D:\Users\ntabyldieva\databases_v1\venv\lib\site-packages\django\views\decorators\csrf.py", line 54, in wrapped_view
    return view_func(*args, **kwargs)
  File "D:\Users\ntabyldieva\databases_v1\venv\lib\site-packages\django\views\generic\base.py", line 70, in view
    return self.dispatch(request, *args, **kwargs)
  File "D:\Users\ntabyldieva\databases_v1\venv\lib\site-packages\rest_framework\views.py", line 509, in dispatch
    response = self.handle_exception(exc)
  File "D:\Users\ntabyldieva\databases_v1\venv\lib\site-packages\rest_framework\views.py", line 469, in handle_exception
    self.raise_uncaught_exception(exc)
  File "D:\Users\ntabyldieva\databases_v1\venv\lib\site-packages\rest_framework\views.py", line 480, in raise_uncaught_exception
    raise exc
  File "D:\Users\ntabyldieva\databases_v1\venv\lib\site-packages\rest_framework\views.py", line 506, in dispatch
    response = handler(request, *args, **kwargs)
  File "D:\Users\ntabyldieva\databases_v1\work\data_filter_api.py", line 75, in post
    return Response(serializer.data)
  File "D:\Users\ntabyldieva\databases_v1\venv\lib\site-packages\rest_framework\serializers.py", line 745, in data
    ret = super().data
  File "D:\Users\ntabyldieva\databases_v1\venv\lib\site-packages\rest_framework\serializers.py", line 246, in data
    self._data = self.to_representation(self.instance)
  File "D:\Users\ntabyldieva\databases_v1\venv\lib\site-packages\rest_framework\serializers.py", line 663, in to_representation
    return [
  File "D:\Users\ntabyldieva\databases_v1\venv\lib\site-packages\rest_framework\serializers.py", line 664, in <listcomp>
    self.child.to_representation(item) for item in iterable
  File "D:\Users\ntabyldieva\databases_v1\venv\lib\site-packages\rest_framework\serializers.py", line 502, in to_representation
    attribute = field.get_attribute(instance)
  File "D:\Users\ntabyldieva\databases_v1\venv\lib\site-packages\rest_framework\fields.py", line 490, in get_attribute
    raise type(exc)(msg)
KeyError: "Got KeyError when attempting to get a value for field `country_id` on serializer `DataFilterApiSerializer`.\nThe serializer field might be named incorrectly and not match any attribute or key on the `dict` instance.\nOriginal exception text was: 'country_id'."
ERROR django.server "POST /work/test-data/get/ HTTP/1.1" 500 132184 2021-10-21 16:39:03,855
ERROR django.request Internal Server Error: /work/test-data/get/ 2021-10-21 16:39:21,522
Traceback (most recent call last):
  File "D:\Users\ntabyldieva\databases_v1\venv\lib\site-packages\rest_framework\fields.py", line 457, in get_attribute
    return get_attribute(instance, self.source_attrs)
  File "D:\Users\ntabyldieva\databases_v1\venv\lib\site-packages\rest_framework\fields.py", line 95, in get_attribute
    instance = instance[attr]
KeyError: 'country_id'

During handling of the above exception, another exception occurred:

Traceback (most recent call last):
  File "D:\Users\ntabyldieva\databases_v1\venv\lib\site-packages\django\core\handlers\exception.py", line 47, in inner
    response = get_response(request)
  File "D:\Users\ntabyldieva\databases_v1\venv\lib\site-packages\django\core\handlers\base.py", line 181, in _get_response
    response = wrapped_callback(request, *callback_args, **callback_kwargs)
  File "D:\Users\ntabyldieva\databases_v1\venv\lib\site-packages\django\views\decorators\csrf.py", line 54, in wrapped_view
    return view_func(*args, **kwargs)
  File "D:\Users\ntabyldieva\databases_v1\venv\lib\site-packages\django\views\generic\base.py", line 70, in view
    return self.dispatch(request, *args, **kwargs)
  File "D:\Users\ntabyldieva\databases_v1\venv\lib\site-packages\rest_framework\views.py", line 509, in dispatch
    response = self.handle_exception(exc)
  File "D:\Users\ntabyldieva\databases_v1\venv\lib\site-packages\rest_framework\views.py", line 469, in handle_exception
    self.raise_uncaught_exception(exc)
  File "D:\Users\ntabyldieva\databases_v1\venv\lib\site-packages\rest_framework\views.py", line 480, in raise_uncaught_exception
    raise exc
  File "D:\Users\ntabyldieva\databases_v1\venv\lib\site-packages\rest_framework\views.py", line 506, in dispatch
    response = handler(request, *args, **kwargs)
  File "D:\Users\ntabyldieva\databases_v1\work\data_filter_api.py", line 75, in post
    return Response(serializer.data)
  File "D:\Users\ntabyldieva\databases_v1\venv\lib\site-packages\rest_framework\serializers.py", line 745, in data
    ret = super().data
  File "D:\Users\ntabyldieva\databases_v1\venv\lib\site-packages\rest_framework\serializers.py", line 246, in data
    self._data = self.to_representation(self.instance)
  File "D:\Users\ntabyldieva\databases_v1\venv\lib\site-packages\rest_framework\serializers.py", line 663, in to_representation
    return [
  File "D:\Users\ntabyldieva\databases_v1\venv\lib\site-packages\rest_framework\serializers.py", line 664, in <listcomp>
    self.child.to_representation(item) for item in iterable
  File "D:\Users\ntabyldieva\databases_v1\venv\lib\site-packages\rest_framework\serializers.py", line 502, in to_representation
    attribute = field.get_attribute(instance)
  File "D:\Users\ntabyldieva\databases_v1\venv\lib\site-packages\rest_framework\fields.py", line 490, in get_attribute
    raise type(exc)(msg)
KeyError: "Got KeyError when attempting to get a value for field `country_id` on serializer `DataFilterApiSerializer`.\nThe serializer field might be named incorrectly and not match any attribute or key on the `dict` instance.\nOriginal exception text was: 'country_id'."
ERROR django.server "POST /work/test-data/get/ HTTP/1.1" 500 132124 2021-10-21 16:39:21,526
ERROR django.request Internal Server Error: /work/test-data/get/ 2021-10-21 16:40:48,585
Traceback (most recent call last):
  File "D:\Users\ntabyldieva\databases_v1\venv\lib\site-packages\rest_framework\fields.py", line 457, in get_attribute
    return get_attribute(instance, self.source_attrs)
  File "D:\Users\ntabyldieva\databases_v1\venv\lib\site-packages\rest_framework\fields.py", line 95, in get_attribute
    instance = instance[attr]
KeyError: 'country_id'

During handling of the above exception, another exception occurred:

Traceback (most recent call last):
  File "D:\Users\ntabyldieva\databases_v1\venv\lib\site-packages\django\core\handlers\exception.py", line 47, in inner
    response = get_response(request)
  File "D:\Users\ntabyldieva\databases_v1\venv\lib\site-packages\django\core\handlers\base.py", line 181, in _get_response
    response = wrapped_callback(request, *callback_args, **callback_kwargs)
  File "D:\Users\ntabyldieva\databases_v1\venv\lib\site-packages\django\views\decorators\csrf.py", line 54, in wrapped_view
    return view_func(*args, **kwargs)
  File "D:\Users\ntabyldieva\databases_v1\venv\lib\site-packages\django\views\generic\base.py", line 70, in view
    return self.dispatch(request, *args, **kwargs)
  File "D:\Users\ntabyldieva\databases_v1\venv\lib\site-packages\rest_framework\views.py", line 509, in dispatch
    response = self.handle_exception(exc)
  File "D:\Users\ntabyldieva\databases_v1\venv\lib\site-packages\rest_framework\views.py", line 469, in handle_exception
    self.raise_uncaught_exception(exc)
  File "D:\Users\ntabyldieva\databases_v1\venv\lib\site-packages\rest_framework\views.py", line 480, in raise_uncaught_exception
    raise exc
  File "D:\Users\ntabyldieva\databases_v1\venv\lib\site-packages\rest_framework\views.py", line 506, in dispatch
    response = handler(request, *args, **kwargs)
  File "D:\Users\ntabyldieva\databases_v1\work\data_filter_api.py", line 75, in post
    return Response(serializer.data)
  File "D:\Users\ntabyldieva\databases_v1\venv\lib\site-packages\rest_framework\serializers.py", line 745, in data
    ret = super().data
  File "D:\Users\ntabyldieva\databases_v1\venv\lib\site-packages\rest_framework\serializers.py", line 246, in data
    self._data = self.to_representation(self.instance)
  File "D:\Users\ntabyldieva\databases_v1\venv\lib\site-packages\rest_framework\serializers.py", line 663, in to_representation
    return [
  File "D:\Users\ntabyldieva\databases_v1\venv\lib\site-packages\rest_framework\serializers.py", line 664, in <listcomp>
    self.child.to_representation(item) for item in iterable
  File "D:\Users\ntabyldieva\databases_v1\venv\lib\site-packages\rest_framework\serializers.py", line 502, in to_representation
    attribute = field.get_attribute(instance)
  File "D:\Users\ntabyldieva\databases_v1\venv\lib\site-packages\rest_framework\fields.py", line 490, in get_attribute
    raise type(exc)(msg)
KeyError: "Got KeyError when attempting to get a value for field `country_id` on serializer `DataFilterApiSerializer`.\nThe serializer field might be named incorrectly and not match any attribute or key on the `dict` instance.\nOriginal exception text was: 'country_id'."
ERROR django.server "POST /work/test-data/get/ HTTP/1.1" 500 130550 2021-10-21 16:40:48,589
ERROR django.request Internal Server Error: /work/test-data/get/ 2021-10-21 16:40:49,576
Traceback (most recent call last):
  File "D:\Users\ntabyldieva\databases_v1\venv\lib\site-packages\rest_framework\fields.py", line 457, in get_attribute
    return get_attribute(instance, self.source_attrs)
  File "D:\Users\ntabyldieva\databases_v1\venv\lib\site-packages\rest_framework\fields.py", line 95, in get_attribute
    instance = instance[attr]
KeyError: 'country_id'

During handling of the above exception, another exception occurred:

Traceback (most recent call last):
  File "D:\Users\ntabyldieva\databases_v1\venv\lib\site-packages\django\core\handlers\exception.py", line 47, in inner
    response = get_response(request)
  File "D:\Users\ntabyldieva\databases_v1\venv\lib\site-packages\django\core\handlers\base.py", line 181, in _get_response
    response = wrapped_callback(request, *callback_args, **callback_kwargs)
  File "D:\Users\ntabyldieva\databases_v1\venv\lib\site-packages\django\views\decorators\csrf.py", line 54, in wrapped_view
    return view_func(*args, **kwargs)
  File "D:\Users\ntabyldieva\databases_v1\venv\lib\site-packages\django\views\generic\base.py", line 70, in view
    return self.dispatch(request, *args, **kwargs)
  File "D:\Users\ntabyldieva\databases_v1\venv\lib\site-packages\rest_framework\views.py", line 509, in dispatch
    response = self.handle_exception(exc)
  File "D:\Users\ntabyldieva\databases_v1\venv\lib\site-packages\rest_framework\views.py", line 469, in handle_exception
    self.raise_uncaught_exception(exc)
  File "D:\Users\ntabyldieva\databases_v1\venv\lib\site-packages\rest_framework\views.py", line 480, in raise_uncaught_exception
    raise exc
  File "D:\Users\ntabyldieva\databases_v1\venv\lib\site-packages\rest_framework\views.py", line 506, in dispatch
    response = handler(request, *args, **kwargs)
  File "D:\Users\ntabyldieva\databases_v1\work\data_filter_api.py", line 75, in post
    return Response(serializer.data)
  File "D:\Users\ntabyldieva\databases_v1\venv\lib\site-packages\rest_framework\serializers.py", line 745, in data
    ret = super().data
  File "D:\Users\ntabyldieva\databases_v1\venv\lib\site-packages\rest_framework\serializers.py", line 246, in data
    self._data = self.to_representation(self.instance)
  File "D:\Users\ntabyldieva\databases_v1\venv\lib\site-packages\rest_framework\serializers.py", line 663, in to_representation
    return [
  File "D:\Users\ntabyldieva\databases_v1\venv\lib\site-packages\rest_framework\serializers.py", line 664, in <listcomp>
    self.child.to_representation(item) for item in iterable
  File "D:\Users\ntabyldieva\databases_v1\venv\lib\site-packages\rest_framework\serializers.py", line 502, in to_representation
    attribute = field.get_attribute(instance)
  File "D:\Users\ntabyldieva\databases_v1\venv\lib\site-packages\rest_framework\fields.py", line 490, in get_attribute
    raise type(exc)(msg)
KeyError: "Got KeyError when attempting to get a value for field `country_id` on serializer `DataFilterApiSerializer`.\nThe serializer field might be named incorrectly and not match any attribute or key on the `dict` instance.\nOriginal exception text was: 'country_id'."
ERROR django.server "POST /work/test-data/get/ HTTP/1.1" 500 130550 2021-10-21 16:40:49,579
