ERROR django.request Internal Server Error: /work/data/get/ 2021-10-13 14:29:16,061
Traceback (most recent call last):
  File "D:\Users\ntabyldieva\databases_v1\venv\lib\site-packages\django\db\backends\utils.py", line 82, in _execute
    return self.cursor.execute(sql)
psycopg2.errors.GroupingError: ОШИБКА:  столбец "work_case.start_date" должен фигурировать в предложении GROUP BY или использоваться в агрегатной функции
LINE 1: SELECT work_country.name,work_country.id,start_date,end_date...
                                                 ^


The above exception was the direct cause of the following exception:

Traceback (most recent call last):
  File "D:\Users\ntabyldieva\databases_v1\venv\lib\site-packages\django\core\handlers\exception.py", line 47, in inner
    response = get_response(request)
  File "D:\Users\ntabyldieva\databases_v1\venv\lib\site-packages\django\core\handlers\base.py", line 181, in _get_response
    response = wrapped_callback(request, *callback_args, **callback_kwargs)
  File "D:\Users\ntabyldieva\databases_v1\venv\lib\site-packages\django\views\decorators\csrf.py", line 54, in wrapped_view
    return view_func(*args, **kwargs)
  File "D:\Users\ntabyldieva\databases_v1\venv\lib\site-packages\django\views\generic\base.py", line 70, in view
    return self.dispatch(request, *args, **kwargs)
  File "D:\Users\ntabyldieva\databases_v1\venv\lib\site-packages\rest_framework\views.py", line 509, in dispatch
    response = self.handle_exception(exc)
  File "D:\Users\ntabyldieva\databases_v1\venv\lib\site-packages\rest_framework\views.py", line 469, in handle_exception
    self.raise_uncaught_exception(exc)
  File "D:\Users\ntabyldieva\databases_v1\venv\lib\site-packages\rest_framework\views.py", line 480, in raise_uncaught_exception
    raise exc
  File "D:\Users\ntabyldieva\databases_v1\venv\lib\site-packages\rest_framework\views.py", line 506, in dispatch
    response = handler(request, *args, **kwargs)
  File "D:\Users\ntabyldieva\databases_v1\work\views.py", line 1051, in post
    cursor.execute(sql_query + where_query + group_by_query)
  File "D:\Users\ntabyldieva\databases_v1\venv\lib\site-packages\django\db\backends\utils.py", line 98, in execute
    return super().execute(sql, params)
  File "D:\Users\ntabyldieva\databases_v1\venv\lib\site-packages\django\db\backends\utils.py", line 66, in execute
    return self._execute_with_wrappers(sql, params, many=False, executor=self._execute)
  File "D:\Users\ntabyldieva\databases_v1\venv\lib\site-packages\django\db\backends\utils.py", line 75, in _execute_with_wrappers
    return executor(sql, params, many, context)
  File "D:\Users\ntabyldieva\databases_v1\venv\lib\site-packages\django\db\backends\utils.py", line 84, in _execute
    return self.cursor.execute(sql, params)
  File "D:\Users\ntabyldieva\databases_v1\venv\lib\site-packages\django\db\utils.py", line 90, in __exit__
    raise dj_exc_value.with_traceback(traceback) from exc_value
  File "D:\Users\ntabyldieva\databases_v1\venv\lib\site-packages\django\db\backends\utils.py", line 82, in _execute
    return self.cursor.execute(sql)
django.db.utils.ProgrammingError: ОШИБКА:  столбец "work_case.start_date" должен фигурировать в предложении GROUP BY или использоваться в агрегатной функции
LINE 1: SELECT work_country.name,work_country.id,start_date,end_date...
                                                 ^

ERROR django.server "POST /work/data/get/ HTTP/1.1" 500 135922 2021-10-13 14:29:16,061
WARNING django.request Not Found: /favicon.ico 2021-10-13 16:24:11,877
WARNING django.server "GET /favicon.ico HTTP/1.1" 404 3524 2021-10-13 16:24:11,879
WARNING django.request Not Found: /favicon.ico 2021-10-13 16:24:12,599
WARNING django.server "GET /favicon.ico HTTP/1.1" 404 3524 2021-10-13 16:24:12,602
WARNING django.request Not Found: /favicon.ico 2021-10-13 16:24:13,356
WARNING django.server "GET /favicon.ico HTTP/1.1" 404 3524 2021-10-13 16:24:13,358
WARNING django.request Not Found: /favicon.ico 2021-10-13 16:24:13,562
WARNING django.server "GET /favicon.ico HTTP/1.1" 404 3524 2021-10-13 16:24:13,563
WARNING django.request Not Found: /favicon.ico 2021-10-13 16:24:13,730
WARNING django.server "GET /favicon.ico HTTP/1.1" 404 3524 2021-10-13 16:24:13,732
WARNING django.request Not Found: /favicon.ico 2021-10-13 16:24:13,901
WARNING django.server "GET /favicon.ico HTTP/1.1" 404 3524 2021-10-13 16:24:13,903
WARNING django.request Not Found: /favicon.ico 2021-10-13 16:24:14,063
WARNING django.server "GET /favicon.ico HTTP/1.1" 404 3524 2021-10-13 16:24:14,065
WARNING django.request Not Found: /favicon.ico 2021-10-13 16:24:14,225
WARNING django.server "GET /favicon.ico HTTP/1.1" 404 3524 2021-10-13 16:24:14,227
WARNING django.request Not Found: /favicon.ico 2021-10-13 16:24:14,393
WARNING django.server "GET /favicon.ico HTTP/1.1" 404 3524 2021-10-13 16:24:14,396
WARNING django.request Not Found: /favicon.ico 2021-10-13 16:24:14,685
WARNING django.server "GET /favicon.ico HTTP/1.1" 404 3524 2021-10-13 16:24:14,687
WARNING django.request Not Found: /favicon.ico 2021-10-13 16:24:14,864
WARNING django.server "GET /favicon.ico HTTP/1.1" 404 3524 2021-10-13 16:24:14,865
WARNING django.request Not Found: /favicon.ico 2021-10-13 18:25:38,575
WARNING django.server "GET /favicon.ico HTTP/1.1" 404 3524 2021-10-13 18:25:38,575
WARNING django.request Not Found: /favicon.ico 2021-10-13 18:28:03,890
WARNING django.server "GET /favicon.ico HTTP/1.1" 404 3524 2021-10-13 18:28:03,891
WARNING django.request Not Found: /favicon.ico 2021-10-13 18:29:20,188
WARNING django.server "GET /favicon.ico HTTP/1.1" 404 3524 2021-10-13 18:29:20,189
WARNING django.request Not Found: /favicon.ico 2021-10-13 18:31:10,181
WARNING django.server "GET /favicon.ico HTTP/1.1" 404 3524 2021-10-13 18:31:10,182
WARNING django.request Not Found: /favicon.ico 2021-10-13 18:35:41,174
WARNING django.server "GET /favicon.ico HTTP/1.1" 404 3524 2021-10-13 18:35:41,175
