ERROR django.request Internal Server Error: /migrant/delete-comments/1 2021-08-13 14:59:16,793
Traceback (most recent call last):
  File "C:\Users\user\OneDrive\Desktop\Projects\databases_v1\venv\lib\site-packages\django\core\handlers\exception.py", line 47, in inner
    response = get_response(request)
  File "C:\Users\user\OneDrive\Desktop\Projects\databases_v1\venv\lib\site-packages\django\core\handlers\base.py", line 181, in _get_response
    response = wrapped_callback(request, *callback_args, **callback_kwargs)
  File "C:\Users\user\OneDrive\Desktop\Projects\databases_v1\databases_v1\migrant\views.py", line 238, in delete_comment
    case_comment.save()
AttributeError: 'tuple' object has no attribute 'save'
ERROR django.server "GET /migrant/delete-comments/1 HTTP/1.1" 500 68685 2021-08-13 14:59:16,794
ERROR django.request Internal Server Error: /migrant/delete-comments/1 2021-08-13 15:01:28,792
Traceback (most recent call last):
  File "C:\Users\user\OneDrive\Desktop\Projects\databases_v1\venv\lib\site-packages\django\core\handlers\exception.py", line 47, in inner
    response = get_response(request)
  File "C:\Users\user\OneDrive\Desktop\Projects\databases_v1\venv\lib\site-packages\django\core\handlers\base.py", line 181, in _get_response
    response = wrapped_callback(request, *callback_args, **callback_kwargs)
  File "C:\Users\user\OneDrive\Desktop\Projects\databases_v1\databases_v1\migrant\views.py", line 237, in delete_comment
    case_comment = CaseComment.objects.get(id=pk).delete()
  File "C:\Users\user\OneDrive\Desktop\Projects\databases_v1\venv\lib\site-packages\django\db\models\manager.py", line 85, in manager_method
    return getattr(self.get_queryset(), name)(*args, **kwargs)
  File "C:\Users\user\OneDrive\Desktop\Projects\databases_v1\venv\lib\site-packages\django\db\models\query.py", line 435, in get
    raise self.model.DoesNotExist(
migrant.models.CaseComment.DoesNotExist: CaseComment matching query does not exist.
ERROR django.server "GET /migrant/delete-comments/1 HTTP/1.1" 500 77598 2021-08-13 15:01:28,794
WARNING django.request Not Found: /favicon.ico 2021-08-13 15:01:28,915
WARNING django.server "GET /favicon.ico HTTP/1.1" 404 3696 2021-08-13 15:01:28,915
ERROR django.request Internal Server Error: /migrant/delete-comments/2 2021-08-13 15:01:48,724
Traceback (most recent call last):
  File "C:\Users\user\OneDrive\Desktop\Projects\databases_v1\venv\lib\site-packages\django\core\handlers\exception.py", line 47, in inner
    response = get_response(request)
  File "C:\Users\user\OneDrive\Desktop\Projects\databases_v1\venv\lib\site-packages\django\core\handlers\base.py", line 181, in _get_response
    response = wrapped_callback(request, *callback_args, **callback_kwargs)
  File "C:\Users\user\OneDrive\Desktop\Projects\databases_v1\databases_v1\migrant\views.py", line 238, in delete_comment
    return redirect('migrant_case_show_comments', case_comment.case_id)
AttributeError: 'tuple' object has no attribute 'case_id'
ERROR django.server "GET /migrant/delete-comments/2 HTTP/1.1" 500 68783 2021-08-13 15:01:48,725
