ERROR django.request Internal Server Error: /analytic/work/search/ 2021-10-07 10:27:45,777
Traceback (most recent call last):
  File "D:\Users\ntabyldieva\databases_v1\env\lib\site-packages\rest_framework\request.py", line 416, in __getattr__
    return getattr(self._request, attr)
AttributeError: 'WSGIRequest' object has no attribute 'get'

During handling of the above exception, another exception occurred:

Traceback (most recent call last):
  File "D:\Users\ntabyldieva\databases_v1\env\lib\site-packages\django\core\handlers\exception.py", line 47, in inner
    response = get_response(request)
  File "D:\Users\ntabyldieva\databases_v1\env\lib\site-packages\django\core\handlers\base.py", line 181, in _get_response
    response = wrapped_callback(request, *callback_args, **callback_kwargs)
  File "D:\Users\ntabyldieva\databases_v1\env\lib\site-packages\django\views\decorators\csrf.py", line 54, in wrapped_view
    return view_func(*args, **kwargs)
  File "D:\Users\ntabyldieva\databases_v1\env\lib\site-packages\django\views\generic\base.py", line 70, in view
    return self.dispatch(request, *args, **kwargs)
  File "D:\Users\ntabyldieva\databases_v1\env\lib\site-packages\rest_framework\views.py", line 509, in dispatch
    response = self.handle_exception(exc)
  File "D:\Users\ntabyldieva\databases_v1\env\lib\site-packages\rest_framework\views.py", line 469, in handle_exception
    self.raise_uncaught_exception(exc)
  File "D:\Users\ntabyldieva\databases_v1\env\lib\site-packages\rest_framework\views.py", line 480, in raise_uncaught_exception
    raise exc
  File "D:\Users\ntabyldieva\databases_v1\env\lib\site-packages\rest_framework\views.py", line 506, in dispatch
    response = handler(request, *args, **kwargs)
  File "D:\Users\ntabyldieva\databases_v1\statistica\views.py", line 78, in post
    tradeunioncrime = request.get("tradeunioncrime")
  File "D:\Users\ntabyldieva\databases_v1\env\lib\site-packages\rest_framework\request.py", line 418, in __getattr__
    return self.__getattribute__(attr)
AttributeError: 'Request' object has no attribute 'get'
ERROR django.server "POST /analytic/work/search/ HTTP/1.1" 500 100344 2021-10-07 10:27:45,781
ERROR django.request Internal Server Error: /analytic/work/search/ 2021-10-07 10:27:46,834
Traceback (most recent call last):
  File "D:\Users\ntabyldieva\databases_v1\env\lib\site-packages\rest_framework\request.py", line 416, in __getattr__
    return getattr(self._request, attr)
AttributeError: 'WSGIRequest' object has no attribute 'get'

During handling of the above exception, another exception occurred:

Traceback (most recent call last):
  File "D:\Users\ntabyldieva\databases_v1\env\lib\site-packages\django\core\handlers\exception.py", line 47, in inner
    response = get_response(request)
  File "D:\Users\ntabyldieva\databases_v1\env\lib\site-packages\django\core\handlers\base.py", line 181, in _get_response
    response = wrapped_callback(request, *callback_args, **callback_kwargs)
  File "D:\Users\ntabyldieva\databases_v1\env\lib\site-packages\django\views\decorators\csrf.py", line 54, in wrapped_view
    return view_func(*args, **kwargs)
  File "D:\Users\ntabyldieva\databases_v1\env\lib\site-packages\django\views\generic\base.py", line 70, in view
    return self.dispatch(request, *args, **kwargs)
  File "D:\Users\ntabyldieva\databases_v1\env\lib\site-packages\rest_framework\views.py", line 509, in dispatch
    response = self.handle_exception(exc)
  File "D:\Users\ntabyldieva\databases_v1\env\lib\site-packages\rest_framework\views.py", line 469, in handle_exception
    self.raise_uncaught_exception(exc)
  File "D:\Users\ntabyldieva\databases_v1\env\lib\site-packages\rest_framework\views.py", line 480, in raise_uncaught_exception
    raise exc
  File "D:\Users\ntabyldieva\databases_v1\env\lib\site-packages\rest_framework\views.py", line 506, in dispatch
    response = handler(request, *args, **kwargs)
  File "D:\Users\ntabyldieva\databases_v1\statistica\views.py", line 78, in post
    tradeunioncrime = request.get("tradeunioncrime")
  File "D:\Users\ntabyldieva\databases_v1\env\lib\site-packages\rest_framework\request.py", line 418, in __getattr__
    return self.__getattribute__(attr)
AttributeError: 'Request' object has no attribute 'get'
ERROR django.server "POST /analytic/work/search/ HTTP/1.1" 500 100344 2021-10-07 10:27:46,837
WARNING django.request Forbidden: /analytic/work/search/ 2021-10-07 12:29:28,442
WARNING django.server "POST /analytic/work/search/ HTTP/1.1" 403 58 2021-10-07 12:29:28,442
WARNING django.request Forbidden: /analytic/work/search/ 2021-10-07 12:29:50,592
WARNING django.server "POST /analytic/work/search/ HTTP/1.1" 403 58 2021-10-07 12:29:50,593
ERROR django.request Internal Server Error: /work/data/get/ 2021-10-07 13:48:41,293
Traceback (most recent call last):
  File "D:\Users\ntabyldieva\databases_v1\env\lib\site-packages\django\core\handlers\exception.py", line 47, in inner
    response = get_response(request)
  File "D:\Users\ntabyldieva\databases_v1\env\lib\site-packages\django\core\handlers\base.py", line 181, in _get_response
    response = wrapped_callback(request, *callback_args, **callback_kwargs)
  File "D:\Users\ntabyldieva\databases_v1\env\lib\site-packages\django\views\decorators\csrf.py", line 54, in wrapped_view
    return view_func(*args, **kwargs)
  File "D:\Users\ntabyldieva\databases_v1\env\lib\site-packages\django\views\generic\base.py", line 70, in view
    return self.dispatch(request, *args, **kwargs)
  File "D:\Users\ntabyldieva\databases_v1\env\lib\site-packages\rest_framework\views.py", line 509, in dispatch
    response = self.handle_exception(exc)
  File "D:\Users\ntabyldieva\databases_v1\env\lib\site-packages\rest_framework\views.py", line 469, in handle_exception
    self.raise_uncaught_exception(exc)
  File "D:\Users\ntabyldieva\databases_v1\env\lib\site-packages\rest_framework\views.py", line 480, in raise_uncaught_exception
    raise exc
  File "D:\Users\ntabyldieva\databases_v1\env\lib\site-packages\rest_framework\views.py", line 506, in dispatch
    response = handler(request, *args, **kwargs)
  File "D:\Users\ntabyldieva\databases_v1\work\views.py", line 1001, in post
    where_query_list.append(f"{where_sql_query} ({where_list[0]}) ")
IndexError: list index out of range
ERROR django.server "POST /work/data/get/ HTTP/1.1" 500 97321 2021-10-07 13:48:41,296
ERROR django.request Internal Server Error: /work/data/get/ 2021-10-07 13:49:03,361
Traceback (most recent call last):
  File "D:\Users\ntabyldieva\databases_v1\env\lib\site-packages\django\core\handlers\exception.py", line 47, in inner
    response = get_response(request)
  File "D:\Users\ntabyldieva\databases_v1\env\lib\site-packages\django\core\handlers\base.py", line 181, in _get_response
    response = wrapped_callback(request, *callback_args, **callback_kwargs)
  File "D:\Users\ntabyldieva\databases_v1\env\lib\site-packages\django\views\decorators\csrf.py", line 54, in wrapped_view
    return view_func(*args, **kwargs)
  File "D:\Users\ntabyldieva\databases_v1\env\lib\site-packages\django\views\generic\base.py", line 70, in view
    return self.dispatch(request, *args, **kwargs)
  File "D:\Users\ntabyldieva\databases_v1\env\lib\site-packages\rest_framework\views.py", line 509, in dispatch
    response = self.handle_exception(exc)
  File "D:\Users\ntabyldieva\databases_v1\env\lib\site-packages\rest_framework\views.py", line 469, in handle_exception
    self.raise_uncaught_exception(exc)
  File "D:\Users\ntabyldieva\databases_v1\env\lib\site-packages\rest_framework\views.py", line 480, in raise_uncaught_exception
    raise exc
  File "D:\Users\ntabyldieva\databases_v1\env\lib\site-packages\rest_framework\views.py", line 506, in dispatch
    response = handler(request, *args, **kwargs)
  File "D:\Users\ntabyldieva\databases_v1\work\views.py", line 1001, in post
    where_query_list.append(f"{where_sql_query} ({where_list[0]}) ")
IndexError: list index out of range
ERROR django.server "POST /work/data/get/ HTTP/1.1" 500 97321 2021-10-07 13:49:03,363
ERROR django.request Internal Server Error: /work/data/get/ 2021-10-07 13:49:07,665
Traceback (most recent call last):
  File "D:\Users\ntabyldieva\databases_v1\env\lib\site-packages\django\core\handlers\exception.py", line 47, in inner
    response = get_response(request)
  File "D:\Users\ntabyldieva\databases_v1\env\lib\site-packages\django\core\handlers\base.py", line 181, in _get_response
    response = wrapped_callback(request, *callback_args, **callback_kwargs)
  File "D:\Users\ntabyldieva\databases_v1\env\lib\site-packages\django\views\decorators\csrf.py", line 54, in wrapped_view
    return view_func(*args, **kwargs)
  File "D:\Users\ntabyldieva\databases_v1\env\lib\site-packages\django\views\generic\base.py", line 70, in view
    return self.dispatch(request, *args, **kwargs)
  File "D:\Users\ntabyldieva\databases_v1\env\lib\site-packages\rest_framework\views.py", line 509, in dispatch
    response = self.handle_exception(exc)
  File "D:\Users\ntabyldieva\databases_v1\env\lib\site-packages\rest_framework\views.py", line 469, in handle_exception
    self.raise_uncaught_exception(exc)
  File "D:\Users\ntabyldieva\databases_v1\env\lib\site-packages\rest_framework\views.py", line 480, in raise_uncaught_exception
    raise exc
  File "D:\Users\ntabyldieva\databases_v1\env\lib\site-packages\rest_framework\views.py", line 506, in dispatch
    response = handler(request, *args, **kwargs)
  File "D:\Users\ntabyldieva\databases_v1\work\views.py", line 1001, in post
    where_query_list.append(f"{where_sql_query} ({where_list[0]}) ")
IndexError: list index out of range
ERROR django.server "POST /work/data/get/ HTTP/1.1" 500 97321 2021-10-07 13:49:07,667
ERROR django.request Internal Server Error: /work/data/get/ 2021-10-07 13:49:08,186
Traceback (most recent call last):
  File "D:\Users\ntabyldieva\databases_v1\env\lib\site-packages\django\core\handlers\exception.py", line 47, in inner
    response = get_response(request)
  File "D:\Users\ntabyldieva\databases_v1\env\lib\site-packages\django\core\handlers\base.py", line 181, in _get_response
    response = wrapped_callback(request, *callback_args, **callback_kwargs)
  File "D:\Users\ntabyldieva\databases_v1\env\lib\site-packages\django\views\decorators\csrf.py", line 54, in wrapped_view
    return view_func(*args, **kwargs)
  File "D:\Users\ntabyldieva\databases_v1\env\lib\site-packages\django\views\generic\base.py", line 70, in view
    return self.dispatch(request, *args, **kwargs)
  File "D:\Users\ntabyldieva\databases_v1\env\lib\site-packages\rest_framework\views.py", line 509, in dispatch
    response = self.handle_exception(exc)
  File "D:\Users\ntabyldieva\databases_v1\env\lib\site-packages\rest_framework\views.py", line 469, in handle_exception
    self.raise_uncaught_exception(exc)
  File "D:\Users\ntabyldieva\databases_v1\env\lib\site-packages\rest_framework\views.py", line 480, in raise_uncaught_exception
    raise exc
  File "D:\Users\ntabyldieva\databases_v1\env\lib\site-packages\rest_framework\views.py", line 506, in dispatch
    response = handler(request, *args, **kwargs)
  File "D:\Users\ntabyldieva\databases_v1\work\views.py", line 1001, in post
    where_query_list.append(f"{where_sql_query} ({where_list[0]}) ")
IndexError: list index out of range
ERROR django.server "POST /work/data/get/ HTTP/1.1" 500 97321 2021-10-07 13:49:08,188
ERROR django.request Internal Server Error: /work/data/get/ 2021-10-07 13:49:08,346
Traceback (most recent call last):
  File "D:\Users\ntabyldieva\databases_v1\env\lib\site-packages\django\core\handlers\exception.py", line 47, in inner
    response = get_response(request)
  File "D:\Users\ntabyldieva\databases_v1\env\lib\site-packages\django\core\handlers\base.py", line 181, in _get_response
    response = wrapped_callback(request, *callback_args, **callback_kwargs)
  File "D:\Users\ntabyldieva\databases_v1\env\lib\site-packages\django\views\decorators\csrf.py", line 54, in wrapped_view
    return view_func(*args, **kwargs)
  File "D:\Users\ntabyldieva\databases_v1\env\lib\site-packages\django\views\generic\base.py", line 70, in view
    return self.dispatch(request, *args, **kwargs)
  File "D:\Users\ntabyldieva\databases_v1\env\lib\site-packages\rest_framework\views.py", line 509, in dispatch
    response = self.handle_exception(exc)
  File "D:\Users\ntabyldieva\databases_v1\env\lib\site-packages\rest_framework\views.py", line 469, in handle_exception
    self.raise_uncaught_exception(exc)
  File "D:\Users\ntabyldieva\databases_v1\env\lib\site-packages\rest_framework\views.py", line 480, in raise_uncaught_exception
    raise exc
  File "D:\Users\ntabyldieva\databases_v1\env\lib\site-packages\rest_framework\views.py", line 506, in dispatch
    response = handler(request, *args, **kwargs)
  File "D:\Users\ntabyldieva\databases_v1\work\views.py", line 1001, in post
    where_query_list.append(f"{where_sql_query} ({where_list[0]}) ")
IndexError: list index out of range
ERROR django.server "POST /work/data/get/ HTTP/1.1" 500 97321 2021-10-07 13:49:08,349
ERROR django.request Internal Server Error: /work/data/get/ 2021-10-07 13:49:08,497
Traceback (most recent call last):
  File "D:\Users\ntabyldieva\databases_v1\env\lib\site-packages\django\core\handlers\exception.py", line 47, in inner
    response = get_response(request)
  File "D:\Users\ntabyldieva\databases_v1\env\lib\site-packages\django\core\handlers\base.py", line 181, in _get_response
    response = wrapped_callback(request, *callback_args, **callback_kwargs)
  File "D:\Users\ntabyldieva\databases_v1\env\lib\site-packages\django\views\decorators\csrf.py", line 54, in wrapped_view
    return view_func(*args, **kwargs)
  File "D:\Users\ntabyldieva\databases_v1\env\lib\site-packages\django\views\generic\base.py", line 70, in view
    return self.dispatch(request, *args, **kwargs)
  File "D:\Users\ntabyldieva\databases_v1\env\lib\site-packages\rest_framework\views.py", line 509, in dispatch
    response = self.handle_exception(exc)
  File "D:\Users\ntabyldieva\databases_v1\env\lib\site-packages\rest_framework\views.py", line 469, in handle_exception
    self.raise_uncaught_exception(exc)
  File "D:\Users\ntabyldieva\databases_v1\env\lib\site-packages\rest_framework\views.py", line 480, in raise_uncaught_exception
    raise exc
  File "D:\Users\ntabyldieva\databases_v1\env\lib\site-packages\rest_framework\views.py", line 506, in dispatch
    response = handler(request, *args, **kwargs)
  File "D:\Users\ntabyldieva\databases_v1\work\views.py", line 1001, in post
    where_query_list.append(f"{where_sql_query} ({where_list[0]}) ")
IndexError: list index out of range
ERROR django.server "POST /work/data/get/ HTTP/1.1" 500 97321 2021-10-07 13:49:08,498
ERROR django.request Internal Server Error: /work/data/get/ 2021-10-07 13:49:09,154
Traceback (most recent call last):
  File "D:\Users\ntabyldieva\databases_v1\env\lib\site-packages\django\core\handlers\exception.py", line 47, in inner
    response = get_response(request)
  File "D:\Users\ntabyldieva\databases_v1\env\lib\site-packages\django\core\handlers\base.py", line 181, in _get_response
    response = wrapped_callback(request, *callback_args, **callback_kwargs)
  File "D:\Users\ntabyldieva\databases_v1\env\lib\site-packages\django\views\decorators\csrf.py", line 54, in wrapped_view
    return view_func(*args, **kwargs)
  File "D:\Users\ntabyldieva\databases_v1\env\lib\site-packages\django\views\generic\base.py", line 70, in view
    return self.dispatch(request, *args, **kwargs)
  File "D:\Users\ntabyldieva\databases_v1\env\lib\site-packages\rest_framework\views.py", line 509, in dispatch
    response = self.handle_exception(exc)
  File "D:\Users\ntabyldieva\databases_v1\env\lib\site-packages\rest_framework\views.py", line 469, in handle_exception
    self.raise_uncaught_exception(exc)
  File "D:\Users\ntabyldieva\databases_v1\env\lib\site-packages\rest_framework\views.py", line 480, in raise_uncaught_exception
    raise exc
  File "D:\Users\ntabyldieva\databases_v1\env\lib\site-packages\rest_framework\views.py", line 506, in dispatch
    response = handler(request, *args, **kwargs)
  File "D:\Users\ntabyldieva\databases_v1\work\views.py", line 1001, in post
    where_query_list.append(f"{where_sql_query} ({where_list[0]}) ")
IndexError: list index out of range
ERROR django.server "POST /work/data/get/ HTTP/1.1" 500 97321 2021-10-07 13:49:09,157
WARNING django.request Not Found: /favicon.ico 2021-10-07 14:05:57,373
WARNING django.server "GET /favicon.ico HTTP/1.1" 404 3524 2021-10-07 14:05:57,376
WARNING django.request Not Found: /favicon.ico 2021-10-07 14:14:45,666
WARNING django.server "GET /favicon.ico HTTP/1.1" 404 3524 2021-10-07 14:14:45,667
WARNING django.request Not Found: /favicon.ico 2021-10-07 14:15:16,374
WARNING django.server "GET /favicon.ico HTTP/1.1" 404 3524 2021-10-07 14:15:16,375
WARNING django.request Not Found: /favicon.ico 2021-10-07 14:16:03,696
WARNING django.server "GET /favicon.ico HTTP/1.1" 404 3524 2021-10-07 14:16:03,698
WARNING django.request Not Found: /favicon.ico 2021-10-07 14:16:26,240
WARNING django.server "GET /favicon.ico HTTP/1.1" 404 3524 2021-10-07 14:16:26,243
WARNING django.request Not Found: /favicon.ico 2021-10-07 14:16:45,096
WARNING django.server "GET /favicon.ico HTTP/1.1" 404 3524 2021-10-07 14:16:45,096
WARNING django.request Not Found: /favicon.ico 2021-10-07 14:16:49,260
WARNING django.server "GET /favicon.ico HTTP/1.1" 404 3524 2021-10-07 14:16:49,261
WARNING django.request Not Found: /favicon.ico 2021-10-07 14:17:07,223
WARNING django.server "GET /favicon.ico HTTP/1.1" 404 3524 2021-10-07 14:17:07,226
WARNING django.request Not Found: /favicon.ico 2021-10-07 14:24:05,163
WARNING django.server "GET /favicon.ico HTTP/1.1" 404 3524 2021-10-07 14:24:05,165
WARNING django.request Not Found: /favicon.ico 2021-10-07 14:26:07,764
WARNING django.server "GET /favicon.ico HTTP/1.1" 404 3524 2021-10-07 14:26:07,767
WARNING django.request Not Found: /favicon.ico 2021-10-07 14:28:35,779
WARNING django.server "GET /favicon.ico HTTP/1.1" 404 3524 2021-10-07 14:28:35,781
WARNING django.request Not Found: /favicon.ico 2021-10-07 14:29:26,436
WARNING django.server "GET /favicon.ico HTTP/1.1" 404 3524 2021-10-07 14:29:26,439
ERROR django.request Internal Server Error: /work/data/get/ 2021-10-07 14:29:40,215
Traceback (most recent call last):
  File "D:\Users\ntabyldieva\databases_v1\env\lib\site-packages\django\db\backends\utils.py", line 82, in _execute
    return self.cursor.execute(sql)
  File "D:\Users\ntabyldieva\databases_v1\env\lib\site-packages\django\db\backends\sqlite3\base.py", line 421, in execute
    return Database.Cursor.execute(self, query)
sqlite3.OperationalError: near "group": syntax error

The above exception was the direct cause of the following exception:

Traceback (most recent call last):
  File "D:\Users\ntabyldieva\databases_v1\env\lib\site-packages\django\core\handlers\exception.py", line 47, in inner
    response = get_response(request)
  File "D:\Users\ntabyldieva\databases_v1\env\lib\site-packages\django\core\handlers\base.py", line 181, in _get_response
    response = wrapped_callback(request, *callback_args, **callback_kwargs)
  File "D:\Users\ntabyldieva\databases_v1\env\lib\site-packages\django\views\decorators\csrf.py", line 54, in wrapped_view
    return view_func(*args, **kwargs)
  File "D:\Users\ntabyldieva\databases_v1\env\lib\site-packages\django\views\generic\base.py", line 70, in view
    return self.dispatch(request, *args, **kwargs)
  File "D:\Users\ntabyldieva\databases_v1\env\lib\site-packages\rest_framework\views.py", line 509, in dispatch
    response = self.handle_exception(exc)
  File "D:\Users\ntabyldieva\databases_v1\env\lib\site-packages\rest_framework\views.py", line 469, in handle_exception
    self.raise_uncaught_exception(exc)
  File "D:\Users\ntabyldieva\databases_v1\env\lib\site-packages\rest_framework\views.py", line 480, in raise_uncaught_exception
    raise exc
  File "D:\Users\ntabyldieva\databases_v1\env\lib\site-packages\rest_framework\views.py", line 506, in dispatch
    response = handler(request, *args, **kwargs)
  File "D:\Users\ntabyldieva\databases_v1\work\views.py", line 1049, in post
    cursor.execute(sql_query + where_query + group_by_query)
  File "D:\Users\ntabyldieva\databases_v1\env\lib\site-packages\django\db\backends\utils.py", line 98, in execute
    return super().execute(sql, params)
  File "D:\Users\ntabyldieva\databases_v1\env\lib\site-packages\django\db\backends\utils.py", line 66, in execute
    return self._execute_with_wrappers(sql, params, many=False, executor=self._execute)
  File "D:\Users\ntabyldieva\databases_v1\env\lib\site-packages\django\db\backends\utils.py", line 75, in _execute_with_wrappers
    return executor(sql, params, many, context)
  File "D:\Users\ntabyldieva\databases_v1\env\lib\site-packages\django\db\backends\utils.py", line 84, in _execute
    return self.cursor.execute(sql, params)
  File "D:\Users\ntabyldieva\databases_v1\env\lib\site-packages\django\db\utils.py", line 90, in __exit__
    raise dj_exc_value.with_traceback(traceback) from exc_value
  File "D:\Users\ntabyldieva\databases_v1\env\lib\site-packages\django\db\backends\utils.py", line 82, in _execute
    return self.cursor.execute(sql)
  File "D:\Users\ntabyldieva\databases_v1\env\lib\site-packages\django\db\backends\sqlite3\base.py", line 421, in execute
    return Database.Cursor.execute(self, query)
django.db.utils.OperationalError: near "group": syntax error
ERROR django.server "POST /work/data/get/ HTTP/1.1" 500 137978 2021-10-07 14:29:40,230
WARNING django.request Not Found: /favicon.ico 2021-10-07 14:34:43,532
WARNING django.server "GET /favicon.ico HTTP/1.1" 404 3524 2021-10-07 14:34:43,533
WARNING django.request Not Found: /favicon.ico 2021-10-07 14:48:04,526
WARNING django.server "GET /favicon.ico HTTP/1.1" 404 3524 2021-10-07 14:48:04,528
WARNING django.request Not Found: /favicon.ico 2021-10-07 14:51:01,986
WARNING django.server "GET /favicon.ico HTTP/1.1" 404 3524 2021-10-07 14:51:01,989
WARNING django.request Not Found: /favicon.ico 2021-10-07 14:56:06,729
WARNING django.server "GET /favicon.ico HTTP/1.1" 404 3524 2021-10-07 14:56:06,733
WARNING django.request Not Found: /favicon.ico 2021-10-07 14:59:19,442
WARNING django.server "GET /favicon.ico HTTP/1.1" 404 3524 2021-10-07 14:59:19,444
WARNING django.request Not Found: /favicon.ico 2021-10-07 15:15:49,754
WARNING django.server "GET /favicon.ico HTTP/1.1" 404 3524 2021-10-07 15:15:49,754
WARNING django.request Not Found: /favicon.ico 2021-10-07 15:18:13,313
WARNING django.server "GET /favicon.ico HTTP/1.1" 404 3524 2021-10-07 15:18:13,316
WARNING django.request Not Found: /favicon.ico 2021-10-07 15:26:29,687
WARNING django.server "GET /favicon.ico HTTP/1.1" 404 3524 2021-10-07 15:26:29,689
WARNING django.request Not Found: /favicon.ico 2021-10-07 15:33:49,218
WARNING django.server "GET /favicon.ico HTTP/1.1" 404 3524 2021-10-07 15:33:49,219
