WARNING django.request Not Found: /favicon.ico 2021-12-01 11:45:28,221
WARNING django.server "GET /favicon.ico HTTP/1.1" 404 3524 2021-12-01 11:45:28,222
WARNING django.request Not Found: /favicon.ico 2021-12-01 11:45:28,754
WARNING django.server "GET /favicon.ico HTTP/1.1" 404 3524 2021-12-01 11:45:28,756
WARNING django.request Not Found: /favicon.ico 2021-12-01 11:45:29,557
WARNING django.server "GET /favicon.ico HTTP/1.1" 404 3524 2021-12-01 11:45:29,558
WARNING django.request Not Found: /work 2021-12-01 12:02:47,489
WARNING django.server "GET /work HTTP/1.1" 404 3503 2021-12-01 12:02:47,490
ERROR django.request Internal Server Error: /work/detail/1/ 2021-12-01 12:03:14,339
Traceback (most recent call last):
  File "D:\Users\ntabyldieva\Desktop\databases_v1\env\lib\site-packages\rest_framework\fields.py", line 457, in get_attribute
    return get_attribute(instance, self.source_attrs)
  File "D:\Users\ntabyldieva\Desktop\databases_v1\env\lib\site-packages\rest_framework\fields.py", line 97, in get_attribute
    instance = getattr(instance, attr)
AttributeError: 'Case' object has no attribute 'count'

During handling of the above exception, another exception occurred:

Traceback (most recent call last):
  File "D:\Users\ntabyldieva\Desktop\databases_v1\env\lib\site-packages\django\core\handlers\exception.py", line 47, in inner
    response = get_response(request)
  File "D:\Users\ntabyldieva\Desktop\databases_v1\env\lib\site-packages\django\core\handlers\base.py", line 181, in _get_response
    response = wrapped_callback(request, *callback_args, **callback_kwargs)
  File "D:\Users\ntabyldieva\Desktop\databases_v1\env\lib\site-packages\django\views\decorators\csrf.py", line 54, in wrapped_view
    return view_func(*args, **kwargs)
  File "D:\Users\ntabyldieva\Desktop\databases_v1\env\lib\site-packages\django\views\generic\base.py", line 70, in view
    return self.dispatch(request, *args, **kwargs)
  File "D:\Users\ntabyldieva\Desktop\databases_v1\env\lib\site-packages\rest_framework\views.py", line 509, in dispatch
    response = self.handle_exception(exc)
  File "D:\Users\ntabyldieva\Desktop\databases_v1\env\lib\site-packages\rest_framework\views.py", line 469, in handle_exception
    self.raise_uncaught_exception(exc)
  File "D:\Users\ntabyldieva\Desktop\databases_v1\env\lib\site-packages\rest_framework\views.py", line 480, in raise_uncaught_exception
    raise exc
  File "D:\Users\ntabyldieva\Desktop\databases_v1\env\lib\site-packages\rest_framework\views.py", line 506, in dispatch
    response = handler(request, *args, **kwargs)
  File "D:\Users\ntabyldieva\Desktop\databases_v1\env\lib\site-packages\rest_framework\generics.py", line 208, in get
    return self.retrieve(request, *args, **kwargs)
  File "D:\Users\ntabyldieva\Desktop\databases_v1\env\lib\site-packages\rest_framework\mixins.py", line 56, in retrieve
    return Response(serializer.data)
  File "D:\Users\ntabyldieva\Desktop\databases_v1\env\lib\site-packages\rest_framework\serializers.py", line 548, in data
    ret = super().data
  File "D:\Users\ntabyldieva\Desktop\databases_v1\env\lib\site-packages\rest_framework\serializers.py", line 246, in data
    self._data = self.to_representation(self.instance)
  File "D:\Users\ntabyldieva\Desktop\databases_v1\env\lib\site-packages\rest_framework\serializers.py", line 502, in to_representation
    attribute = field.get_attribute(instance)
  File "D:\Users\ntabyldieva\Desktop\databases_v1\env\lib\site-packages\rest_framework\fields.py", line 490, in get_attribute
    raise type(exc)(msg)
AttributeError: Got AttributeError when attempting to get a value for field `count` on serializer `DataFilterApiSerializer`.
The serializer field might be named incorrectly and not match any attribute or key on the `Case` instance.
Original exception text was: 'Case' object has no attribute 'count'.
ERROR django.server "GET /work/detail/1/ HTTP/1.1" 500 142848 2021-12-01 12:03:14,349
WARNING django.request Not Found: /work/detail/80/ 2021-12-01 15:25:58,184
WARNING django.server "GET /work/detail/80/ HTTP/1.1" 404 50 2021-12-01 15:25:58,185
WARNING django.request Not Found: /work/ 2021-12-01 16:00:51,524
WARNING django.server "GET /work/ HTTP/1.1" 404 7557 2021-12-01 16:00:51,525
WARNING django.request Not Found: /work/detail/80/ 2021-12-01 16:01:19,488
WARNING django.server "GET /work/detail/80/ HTTP/1.1" 404 7170 2021-12-01 16:01:19,488
WARNING django.request Not Found: /favicon.ico 2021-12-01 16:10:49,108
WARNING django.server "GET /favicon.ico HTTP/1.1" 404 3524 2021-12-01 16:10:49,109
WARNING django.request Not Found: /favicon.ico 2021-12-01 16:11:06,632
WARNING django.server "GET /favicon.ico HTTP/1.1" 404 3524 2021-12-01 16:11:06,632
WARNING django.request Not Found: /work/detail/80/ 2021-12-01 16:16:41,171
WARNING django.server "GET /work/detail/80/ HTTP/1.1" 404 7170 2021-12-01 16:16:41,172
WARNING django.request Not Found: /work/ 2021-12-01 16:16:42,005
WARNING django.server "GET /work/ HTTP/1.1" 404 7557 2021-12-01 16:16:42,007
ERROR django.request Internal Server Error: /analytic/work/ 2021-12-01 16:16:52,164
Traceback (most recent call last):
  File "D:\Users\ntabyldieva\Desktop\databases_v1\env\lib\site-packages\django\core\handlers\exception.py", line 47, in inner
    response = get_response(request)
  File "D:\Users\ntabyldieva\Desktop\databases_v1\env\lib\site-packages\django\core\handlers\base.py", line 181, in _get_response
    response = wrapped_callback(request, *callback_args, **callback_kwargs)
  File "D:\Users\ntabyldieva\Desktop\databases_v1\env\lib\site-packages\django\contrib\auth\decorators.py", line 21, in _wrapped_view
    return view_func(request, *args, **kwargs)
  File "D:\Users\ntabyldieva\Desktop\databases_v1\statistica\views.py", line 58, in work_analytic
    return render(request, 'statistica/work_search.html', {'url': f'{scheme}://{url}'})
  File "D:\Users\ntabyldieva\Desktop\databases_v1\env\lib\site-packages\django\shortcuts.py", line 19, in render
    content = loader.render_to_string(template_name, context, request, using=using)
  File "D:\Users\ntabyldieva\Desktop\databases_v1\env\lib\site-packages\django\template\loader.py", line 62, in render_to_string
    return template.render(context, request)
  File "D:\Users\ntabyldieva\Desktop\databases_v1\env\lib\site-packages\django\template\backends\django.py", line 61, in render
    return self.template.render(context)
  File "D:\Users\ntabyldieva\Desktop\databases_v1\env\lib\site-packages\django\template\base.py", line 170, in render
    return self._render(context)
  File "D:\Users\ntabyldieva\Desktop\databases_v1\env\lib\site-packages\django\test\utils.py", line 100, in instrumented_test_render
    return self.nodelist.render(context)
  File "D:\Users\ntabyldieva\Desktop\databases_v1\env\lib\site-packages\django\template\base.py", line 938, in render
    bit = node.render_annotated(context)
  File "D:\Users\ntabyldieva\Desktop\databases_v1\env\lib\site-packages\django\template\base.py", line 905, in render_annotated
    return self.render(context)
  File "D:\Users\ntabyldieva\Desktop\databases_v1\env\lib\site-packages\django\template\loader_tags.py", line 150, in render
    return compiled_parent._render(context)
  File "D:\Users\ntabyldieva\Desktop\databases_v1\env\lib\site-packages\django\test\utils.py", line 100, in instrumented_test_render
    return self.nodelist.render(context)
  File "D:\Users\ntabyldieva\Desktop\databases_v1\env\lib\site-packages\django\template\base.py", line 938, in render
    bit = node.render_annotated(context)
  File "D:\Users\ntabyldieva\Desktop\databases_v1\env\lib\site-packages\django\template\base.py", line 905, in render_annotated
    return self.render(context)
  File "D:\Users\ntabyldieva\Desktop\databases_v1\env\lib\site-packages\django\template\loader_tags.py", line 62, in render
    result = block.nodelist.render(context)
  File "D:\Users\ntabyldieva\Desktop\databases_v1\env\lib\site-packages\django\template\base.py", line 938, in render
    bit = node.render_annotated(context)
  File "D:\Users\ntabyldieva\Desktop\databases_v1\env\lib\site-packages\django\template\base.py", line 905, in render_annotated
    return self.render(context)
  File "D:\Users\ntabyldieva\Desktop\databases_v1\env\lib\site-packages\django\template\defaulttags.py", line 446, in render
    url = reverse(view_name, args=args, kwargs=kwargs, current_app=current_app)
  File "D:\Users\ntabyldieva\Desktop\databases_v1\env\lib\site-packages\django\urls\base.py", line 86, in reverse
    return resolver._reverse_with_prefix(view, prefix, *args, **kwargs)
  File "D:\Users\ntabyldieva\Desktop\databases_v1\env\lib\site-packages\django\urls\resolvers.py", line 694, in _reverse_with_prefix
    raise NoReverseMatch(msg)
django.urls.exceptions.NoReverseMatch: Reverse for 'detail_case' with no arguments not found. 1 pattern(s) tried: ['work/detail/(?P<pk>[0-9]+)/$']
ERROR django.server "GET /analytic/work/ HTTP/1.1" 500 163957 2021-12-01 16:16:52,174
ERROR django.request Internal Server Error: /analytic/work/ 2021-12-01 16:17:32,846
Traceback (most recent call last):
  File "D:\Users\ntabyldieva\Desktop\databases_v1\env\lib\site-packages\django\core\handlers\exception.py", line 47, in inner
    response = get_response(request)
  File "D:\Users\ntabyldieva\Desktop\databases_v1\env\lib\site-packages\django\core\handlers\base.py", line 181, in _get_response
    response = wrapped_callback(request, *callback_args, **callback_kwargs)
  File "D:\Users\ntabyldieva\Desktop\databases_v1\env\lib\site-packages\django\contrib\auth\decorators.py", line 21, in _wrapped_view
    return view_func(request, *args, **kwargs)
  File "D:\Users\ntabyldieva\Desktop\databases_v1\statistica\views.py", line 58, in work_analytic
    return render(request, 'statistica/work_search.html', {'url': f'{scheme}://{url}'})
  File "D:\Users\ntabyldieva\Desktop\databases_v1\env\lib\site-packages\django\shortcuts.py", line 19, in render
    content = loader.render_to_string(template_name, context, request, using=using)
  File "D:\Users\ntabyldieva\Desktop\databases_v1\env\lib\site-packages\django\template\loader.py", line 62, in render_to_string
    return template.render(context, request)
  File "D:\Users\ntabyldieva\Desktop\databases_v1\env\lib\site-packages\django\template\backends\django.py", line 61, in render
    return self.template.render(context)
  File "D:\Users\ntabyldieva\Desktop\databases_v1\env\lib\site-packages\django\template\base.py", line 170, in render
    return self._render(context)
  File "D:\Users\ntabyldieva\Desktop\databases_v1\env\lib\site-packages\django\test\utils.py", line 100, in instrumented_test_render
    return self.nodelist.render(context)
  File "D:\Users\ntabyldieva\Desktop\databases_v1\env\lib\site-packages\django\template\base.py", line 938, in render
    bit = node.render_annotated(context)
  File "D:\Users\ntabyldieva\Desktop\databases_v1\env\lib\site-packages\django\template\base.py", line 905, in render_annotated
    return self.render(context)
  File "D:\Users\ntabyldieva\Desktop\databases_v1\env\lib\site-packages\django\template\loader_tags.py", line 150, in render
    return compiled_parent._render(context)
  File "D:\Users\ntabyldieva\Desktop\databases_v1\env\lib\site-packages\django\test\utils.py", line 100, in instrumented_test_render
    return self.nodelist.render(context)
  File "D:\Users\ntabyldieva\Desktop\databases_v1\env\lib\site-packages\django\template\base.py", line 938, in render
    bit = node.render_annotated(context)
  File "D:\Users\ntabyldieva\Desktop\databases_v1\env\lib\site-packages\django\template\base.py", line 905, in render_annotated
    return self.render(context)
  File "D:\Users\ntabyldieva\Desktop\databases_v1\env\lib\site-packages\django\template\loader_tags.py", line 62, in render
    result = block.nodelist.render(context)
  File "D:\Users\ntabyldieva\Desktop\databases_v1\env\lib\site-packages\django\template\base.py", line 938, in render
    bit = node.render_annotated(context)
  File "D:\Users\ntabyldieva\Desktop\databases_v1\env\lib\site-packages\django\template\base.py", line 905, in render_annotated
    return self.render(context)
  File "D:\Users\ntabyldieva\Desktop\databases_v1\env\lib\site-packages\django\template\defaulttags.py", line 446, in render
    url = reverse(view_name, args=args, kwargs=kwargs, current_app=current_app)
  File "D:\Users\ntabyldieva\Desktop\databases_v1\env\lib\site-packages\django\urls\base.py", line 86, in reverse
    return resolver._reverse_with_prefix(view, prefix, *args, **kwargs)
  File "D:\Users\ntabyldieva\Desktop\databases_v1\env\lib\site-packages\django\urls\resolvers.py", line 694, in _reverse_with_prefix
    raise NoReverseMatch(msg)
django.urls.exceptions.NoReverseMatch: Reverse for 'detail_case' with no arguments not found. 1 pattern(s) tried: ['work/detail/(?P<pk>[0-9]+)/$']
ERROR django.server "GET /analytic/work/ HTTP/1.1" 500 164094 2021-12-01 16:17:32,856
ERROR django.request Internal Server Error: /analytic/work/ 2021-12-01 16:17:33,893
Traceback (most recent call last):
  File "D:\Users\ntabyldieva\Desktop\databases_v1\env\lib\site-packages\django\core\handlers\exception.py", line 47, in inner
    response = get_response(request)
  File "D:\Users\ntabyldieva\Desktop\databases_v1\env\lib\site-packages\django\core\handlers\base.py", line 181, in _get_response
    response = wrapped_callback(request, *callback_args, **callback_kwargs)
  File "D:\Users\ntabyldieva\Desktop\databases_v1\env\lib\site-packages\django\contrib\auth\decorators.py", line 21, in _wrapped_view
    return view_func(request, *args, **kwargs)
  File "D:\Users\ntabyldieva\Desktop\databases_v1\statistica\views.py", line 58, in work_analytic
    return render(request, 'statistica/work_search.html', {'url': f'{scheme}://{url}'})
  File "D:\Users\ntabyldieva\Desktop\databases_v1\env\lib\site-packages\django\shortcuts.py", line 19, in render
    content = loader.render_to_string(template_name, context, request, using=using)
  File "D:\Users\ntabyldieva\Desktop\databases_v1\env\lib\site-packages\django\template\loader.py", line 62, in render_to_string
    return template.render(context, request)
  File "D:\Users\ntabyldieva\Desktop\databases_v1\env\lib\site-packages\django\template\backends\django.py", line 61, in render
    return self.template.render(context)
  File "D:\Users\ntabyldieva\Desktop\databases_v1\env\lib\site-packages\django\template\base.py", line 170, in render
    return self._render(context)
  File "D:\Users\ntabyldieva\Desktop\databases_v1\env\lib\site-packages\django\test\utils.py", line 100, in instrumented_test_render
    return self.nodelist.render(context)
  File "D:\Users\ntabyldieva\Desktop\databases_v1\env\lib\site-packages\django\template\base.py", line 938, in render
    bit = node.render_annotated(context)
  File "D:\Users\ntabyldieva\Desktop\databases_v1\env\lib\site-packages\django\template\base.py", line 905, in render_annotated
    return self.render(context)
  File "D:\Users\ntabyldieva\Desktop\databases_v1\env\lib\site-packages\django\template\loader_tags.py", line 150, in render
    return compiled_parent._render(context)
  File "D:\Users\ntabyldieva\Desktop\databases_v1\env\lib\site-packages\django\test\utils.py", line 100, in instrumented_test_render
    return self.nodelist.render(context)
  File "D:\Users\ntabyldieva\Desktop\databases_v1\env\lib\site-packages\django\template\base.py", line 938, in render
    bit = node.render_annotated(context)
  File "D:\Users\ntabyldieva\Desktop\databases_v1\env\lib\site-packages\django\template\base.py", line 905, in render_annotated
    return self.render(context)
  File "D:\Users\ntabyldieva\Desktop\databases_v1\env\lib\site-packages\django\template\loader_tags.py", line 62, in render
    result = block.nodelist.render(context)
  File "D:\Users\ntabyldieva\Desktop\databases_v1\env\lib\site-packages\django\template\base.py", line 938, in render
    bit = node.render_annotated(context)
  File "D:\Users\ntabyldieva\Desktop\databases_v1\env\lib\site-packages\django\template\base.py", line 905, in render_annotated
    return self.render(context)
  File "D:\Users\ntabyldieva\Desktop\databases_v1\env\lib\site-packages\django\template\defaulttags.py", line 446, in render
    url = reverse(view_name, args=args, kwargs=kwargs, current_app=current_app)
  File "D:\Users\ntabyldieva\Desktop\databases_v1\env\lib\site-packages\django\urls\base.py", line 86, in reverse
    return resolver._reverse_with_prefix(view, prefix, *args, **kwargs)
  File "D:\Users\ntabyldieva\Desktop\databases_v1\env\lib\site-packages\django\urls\resolvers.py", line 694, in _reverse_with_prefix
    raise NoReverseMatch(msg)
django.urls.exceptions.NoReverseMatch: Reverse for 'detail_case' with no arguments not found. 1 pattern(s) tried: ['work/detail/(?P<pk>[0-9]+)/$']
ERROR django.server "GET /analytic/work/ HTTP/1.1" 500 164094 2021-12-01 16:17:33,902
ERROR django.request Internal Server Error: /analytic/work/ 2021-12-01 16:17:34,354
Traceback (most recent call last):
  File "D:\Users\ntabyldieva\Desktop\databases_v1\env\lib\site-packages\django\core\handlers\exception.py", line 47, in inner
    response = get_response(request)
  File "D:\Users\ntabyldieva\Desktop\databases_v1\env\lib\site-packages\django\core\handlers\base.py", line 181, in _get_response
    response = wrapped_callback(request, *callback_args, **callback_kwargs)
  File "D:\Users\ntabyldieva\Desktop\databases_v1\env\lib\site-packages\django\contrib\auth\decorators.py", line 21, in _wrapped_view
    return view_func(request, *args, **kwargs)
  File "D:\Users\ntabyldieva\Desktop\databases_v1\statistica\views.py", line 58, in work_analytic
    return render(request, 'statistica/work_search.html', {'url': f'{scheme}://{url}'})
  File "D:\Users\ntabyldieva\Desktop\databases_v1\env\lib\site-packages\django\shortcuts.py", line 19, in render
    content = loader.render_to_string(template_name, context, request, using=using)
  File "D:\Users\ntabyldieva\Desktop\databases_v1\env\lib\site-packages\django\template\loader.py", line 62, in render_to_string
    return template.render(context, request)
  File "D:\Users\ntabyldieva\Desktop\databases_v1\env\lib\site-packages\django\template\backends\django.py", line 61, in render
    return self.template.render(context)
  File "D:\Users\ntabyldieva\Desktop\databases_v1\env\lib\site-packages\django\template\base.py", line 170, in render
    return self._render(context)
  File "D:\Users\ntabyldieva\Desktop\databases_v1\env\lib\site-packages\django\test\utils.py", line 100, in instrumented_test_render
    return self.nodelist.render(context)
  File "D:\Users\ntabyldieva\Desktop\databases_v1\env\lib\site-packages\django\template\base.py", line 938, in render
    bit = node.render_annotated(context)
  File "D:\Users\ntabyldieva\Desktop\databases_v1\env\lib\site-packages\django\template\base.py", line 905, in render_annotated
    return self.render(context)
  File "D:\Users\ntabyldieva\Desktop\databases_v1\env\lib\site-packages\django\template\loader_tags.py", line 150, in render
    return compiled_parent._render(context)
  File "D:\Users\ntabyldieva\Desktop\databases_v1\env\lib\site-packages\django\test\utils.py", line 100, in instrumented_test_render
    return self.nodelist.render(context)
  File "D:\Users\ntabyldieva\Desktop\databases_v1\env\lib\site-packages\django\template\base.py", line 938, in render
    bit = node.render_annotated(context)
  File "D:\Users\ntabyldieva\Desktop\databases_v1\env\lib\site-packages\django\template\base.py", line 905, in render_annotated
    return self.render(context)
  File "D:\Users\ntabyldieva\Desktop\databases_v1\env\lib\site-packages\django\template\loader_tags.py", line 62, in render
    result = block.nodelist.render(context)
  File "D:\Users\ntabyldieva\Desktop\databases_v1\env\lib\site-packages\django\template\base.py", line 938, in render
    bit = node.render_annotated(context)
  File "D:\Users\ntabyldieva\Desktop\databases_v1\env\lib\site-packages\django\template\base.py", line 905, in render_annotated
    return self.render(context)
  File "D:\Users\ntabyldieva\Desktop\databases_v1\env\lib\site-packages\django\template\defaulttags.py", line 446, in render
    url = reverse(view_name, args=args, kwargs=kwargs, current_app=current_app)
  File "D:\Users\ntabyldieva\Desktop\databases_v1\env\lib\site-packages\django\urls\base.py", line 86, in reverse
    return resolver._reverse_with_prefix(view, prefix, *args, **kwargs)
  File "D:\Users\ntabyldieva\Desktop\databases_v1\env\lib\site-packages\django\urls\resolvers.py", line 694, in _reverse_with_prefix
    raise NoReverseMatch(msg)
django.urls.exceptions.NoReverseMatch: Reverse for 'detail_case' with no arguments not found. 1 pattern(s) tried: ['work/detail/(?P<pk>[0-9]+)/$']
ERROR django.server "GET /analytic/work/ HTTP/1.1" 500 164094 2021-12-01 16:17:34,365
ERROR django.request Internal Server Error: /analytic/work/ 2021-12-01 16:17:34,565
Traceback (most recent call last):
  File "D:\Users\ntabyldieva\Desktop\databases_v1\env\lib\site-packages\django\core\handlers\exception.py", line 47, in inner
    response = get_response(request)
  File "D:\Users\ntabyldieva\Desktop\databases_v1\env\lib\site-packages\django\core\handlers\base.py", line 181, in _get_response
    response = wrapped_callback(request, *callback_args, **callback_kwargs)
  File "D:\Users\ntabyldieva\Desktop\databases_v1\env\lib\site-packages\django\contrib\auth\decorators.py", line 21, in _wrapped_view
    return view_func(request, *args, **kwargs)
  File "D:\Users\ntabyldieva\Desktop\databases_v1\statistica\views.py", line 58, in work_analytic
    return render(request, 'statistica/work_search.html', {'url': f'{scheme}://{url}'})
  File "D:\Users\ntabyldieva\Desktop\databases_v1\env\lib\site-packages\django\shortcuts.py", line 19, in render
    content = loader.render_to_string(template_name, context, request, using=using)
  File "D:\Users\ntabyldieva\Desktop\databases_v1\env\lib\site-packages\django\template\loader.py", line 62, in render_to_string
    return template.render(context, request)
  File "D:\Users\ntabyldieva\Desktop\databases_v1\env\lib\site-packages\django\template\backends\django.py", line 61, in render
    return self.template.render(context)
  File "D:\Users\ntabyldieva\Desktop\databases_v1\env\lib\site-packages\django\template\base.py", line 170, in render
    return self._render(context)
  File "D:\Users\ntabyldieva\Desktop\databases_v1\env\lib\site-packages\django\test\utils.py", line 100, in instrumented_test_render
    return self.nodelist.render(context)
  File "D:\Users\ntabyldieva\Desktop\databases_v1\env\lib\site-packages\django\template\base.py", line 938, in render
    bit = node.render_annotated(context)
  File "D:\Users\ntabyldieva\Desktop\databases_v1\env\lib\site-packages\django\template\base.py", line 905, in render_annotated
    return self.render(context)
  File "D:\Users\ntabyldieva\Desktop\databases_v1\env\lib\site-packages\django\template\loader_tags.py", line 150, in render
    return compiled_parent._render(context)
  File "D:\Users\ntabyldieva\Desktop\databases_v1\env\lib\site-packages\django\test\utils.py", line 100, in instrumented_test_render
    return self.nodelist.render(context)
  File "D:\Users\ntabyldieva\Desktop\databases_v1\env\lib\site-packages\django\template\base.py", line 938, in render
    bit = node.render_annotated(context)
  File "D:\Users\ntabyldieva\Desktop\databases_v1\env\lib\site-packages\django\template\base.py", line 905, in render_annotated
    return self.render(context)
  File "D:\Users\ntabyldieva\Desktop\databases_v1\env\lib\site-packages\django\template\loader_tags.py", line 62, in render
    result = block.nodelist.render(context)
  File "D:\Users\ntabyldieva\Desktop\databases_v1\env\lib\site-packages\django\template\base.py", line 938, in render
    bit = node.render_annotated(context)
  File "D:\Users\ntabyldieva\Desktop\databases_v1\env\lib\site-packages\django\template\base.py", line 905, in render_annotated
    return self.render(context)
  File "D:\Users\ntabyldieva\Desktop\databases_v1\env\lib\site-packages\django\template\defaulttags.py", line 446, in render
    url = reverse(view_name, args=args, kwargs=kwargs, current_app=current_app)
  File "D:\Users\ntabyldieva\Desktop\databases_v1\env\lib\site-packages\django\urls\base.py", line 86, in reverse
    return resolver._reverse_with_prefix(view, prefix, *args, **kwargs)
  File "D:\Users\ntabyldieva\Desktop\databases_v1\env\lib\site-packages\django\urls\resolvers.py", line 694, in _reverse_with_prefix
    raise NoReverseMatch(msg)
django.urls.exceptions.NoReverseMatch: Reverse for 'detail_case' with no arguments not found. 1 pattern(s) tried: ['work/detail/(?P<pk>[0-9]+)/$']
ERROR django.server "GET /analytic/work/ HTTP/1.1" 500 164094 2021-12-01 16:17:34,575
ERROR django.request Internal Server Error: /analytic/work/ 2021-12-01 16:17:34,799
Traceback (most recent call last):
  File "D:\Users\ntabyldieva\Desktop\databases_v1\env\lib\site-packages\django\core\handlers\exception.py", line 47, in inner
    response = get_response(request)
  File "D:\Users\ntabyldieva\Desktop\databases_v1\env\lib\site-packages\django\core\handlers\base.py", line 181, in _get_response
    response = wrapped_callback(request, *callback_args, **callback_kwargs)
  File "D:\Users\ntabyldieva\Desktop\databases_v1\env\lib\site-packages\django\contrib\auth\decorators.py", line 21, in _wrapped_view
    return view_func(request, *args, **kwargs)
  File "D:\Users\ntabyldieva\Desktop\databases_v1\statistica\views.py", line 58, in work_analytic
    return render(request, 'statistica/work_search.html', {'url': f'{scheme}://{url}'})
  File "D:\Users\ntabyldieva\Desktop\databases_v1\env\lib\site-packages\django\shortcuts.py", line 19, in render
    content = loader.render_to_string(template_name, context, request, using=using)
  File "D:\Users\ntabyldieva\Desktop\databases_v1\env\lib\site-packages\django\template\loader.py", line 62, in render_to_string
    return template.render(context, request)
  File "D:\Users\ntabyldieva\Desktop\databases_v1\env\lib\site-packages\django\template\backends\django.py", line 61, in render
    return self.template.render(context)
  File "D:\Users\ntabyldieva\Desktop\databases_v1\env\lib\site-packages\django\template\base.py", line 170, in render
    return self._render(context)
  File "D:\Users\ntabyldieva\Desktop\databases_v1\env\lib\site-packages\django\test\utils.py", line 100, in instrumented_test_render
    return self.nodelist.render(context)
  File "D:\Users\ntabyldieva\Desktop\databases_v1\env\lib\site-packages\django\template\base.py", line 938, in render
    bit = node.render_annotated(context)
  File "D:\Users\ntabyldieva\Desktop\databases_v1\env\lib\site-packages\django\template\base.py", line 905, in render_annotated
    return self.render(context)
  File "D:\Users\ntabyldieva\Desktop\databases_v1\env\lib\site-packages\django\template\loader_tags.py", line 150, in render
    return compiled_parent._render(context)
  File "D:\Users\ntabyldieva\Desktop\databases_v1\env\lib\site-packages\django\test\utils.py", line 100, in instrumented_test_render
    return self.nodelist.render(context)
  File "D:\Users\ntabyldieva\Desktop\databases_v1\env\lib\site-packages\django\template\base.py", line 938, in render
    bit = node.render_annotated(context)
  File "D:\Users\ntabyldieva\Desktop\databases_v1\env\lib\site-packages\django\template\base.py", line 905, in render_annotated
    return self.render(context)
  File "D:\Users\ntabyldieva\Desktop\databases_v1\env\lib\site-packages\django\template\loader_tags.py", line 62, in render
    result = block.nodelist.render(context)
  File "D:\Users\ntabyldieva\Desktop\databases_v1\env\lib\site-packages\django\template\base.py", line 938, in render
    bit = node.render_annotated(context)
  File "D:\Users\ntabyldieva\Desktop\databases_v1\env\lib\site-packages\django\template\base.py", line 905, in render_annotated
    return self.render(context)
  File "D:\Users\ntabyldieva\Desktop\databases_v1\env\lib\site-packages\django\template\defaulttags.py", line 446, in render
    url = reverse(view_name, args=args, kwargs=kwargs, current_app=current_app)
  File "D:\Users\ntabyldieva\Desktop\databases_v1\env\lib\site-packages\django\urls\base.py", line 86, in reverse
    return resolver._reverse_with_prefix(view, prefix, *args, **kwargs)
  File "D:\Users\ntabyldieva\Desktop\databases_v1\env\lib\site-packages\django\urls\resolvers.py", line 694, in _reverse_with_prefix
    raise NoReverseMatch(msg)
django.urls.exceptions.NoReverseMatch: Reverse for 'detail_case' with no arguments not found. 1 pattern(s) tried: ['work/detail/(?P<pk>[0-9]+)/$']
ERROR django.server "GET /analytic/work/ HTTP/1.1" 500 164094 2021-12-01 16:17:34,808
WARNING django.request Not Found: /work/ 2021-12-01 16:18:10,621
WARNING django.server "GET /work/ HTTP/1.1" 404 7557 2021-12-01 16:18:10,622
ERROR django.request Internal Server Error: /analytic/work/ 2021-12-01 16:18:22,518
Traceback (most recent call last):
  File "D:\Users\ntabyldieva\Desktop\databases_v1\env\lib\site-packages\django\core\handlers\exception.py", line 47, in inner
    response = get_response(request)
  File "D:\Users\ntabyldieva\Desktop\databases_v1\env\lib\site-packages\django\core\handlers\base.py", line 181, in _get_response
    response = wrapped_callback(request, *callback_args, **callback_kwargs)
  File "D:\Users\ntabyldieva\Desktop\databases_v1\env\lib\site-packages\django\contrib\auth\decorators.py", line 21, in _wrapped_view
    return view_func(request, *args, **kwargs)
  File "D:\Users\ntabyldieva\Desktop\databases_v1\statistica\views.py", line 58, in work_analytic
    return render(request, 'statistica/work_search.html', {'url': f'{scheme}://{url}'})
  File "D:\Users\ntabyldieva\Desktop\databases_v1\env\lib\site-packages\django\shortcuts.py", line 19, in render
    content = loader.render_to_string(template_name, context, request, using=using)
  File "D:\Users\ntabyldieva\Desktop\databases_v1\env\lib\site-packages\django\template\loader.py", line 62, in render_to_string
    return template.render(context, request)
  File "D:\Users\ntabyldieva\Desktop\databases_v1\env\lib\site-packages\django\template\backends\django.py", line 61, in render
    return self.template.render(context)
  File "D:\Users\ntabyldieva\Desktop\databases_v1\env\lib\site-packages\django\template\base.py", line 170, in render
    return self._render(context)
  File "D:\Users\ntabyldieva\Desktop\databases_v1\env\lib\site-packages\django\test\utils.py", line 100, in instrumented_test_render
    return self.nodelist.render(context)
  File "D:\Users\ntabyldieva\Desktop\databases_v1\env\lib\site-packages\django\template\base.py", line 938, in render
    bit = node.render_annotated(context)
  File "D:\Users\ntabyldieva\Desktop\databases_v1\env\lib\site-packages\django\template\base.py", line 905, in render_annotated
    return self.render(context)
  File "D:\Users\ntabyldieva\Desktop\databases_v1\env\lib\site-packages\django\template\loader_tags.py", line 150, in render
    return compiled_parent._render(context)
  File "D:\Users\ntabyldieva\Desktop\databases_v1\env\lib\site-packages\django\test\utils.py", line 100, in instrumented_test_render
    return self.nodelist.render(context)
  File "D:\Users\ntabyldieva\Desktop\databases_v1\env\lib\site-packages\django\template\base.py", line 938, in render
    bit = node.render_annotated(context)
  File "D:\Users\ntabyldieva\Desktop\databases_v1\env\lib\site-packages\django\template\base.py", line 905, in render_annotated
    return self.render(context)
  File "D:\Users\ntabyldieva\Desktop\databases_v1\env\lib\site-packages\django\template\loader_tags.py", line 62, in render
    result = block.nodelist.render(context)
  File "D:\Users\ntabyldieva\Desktop\databases_v1\env\lib\site-packages\django\template\base.py", line 938, in render
    bit = node.render_annotated(context)
  File "D:\Users\ntabyldieva\Desktop\databases_v1\env\lib\site-packages\django\template\base.py", line 905, in render_annotated
    return self.render(context)
  File "D:\Users\ntabyldieva\Desktop\databases_v1\env\lib\site-packages\django\template\defaulttags.py", line 446, in render
    url = reverse(view_name, args=args, kwargs=kwargs, current_app=current_app)
  File "D:\Users\ntabyldieva\Desktop\databases_v1\env\lib\site-packages\django\urls\base.py", line 86, in reverse
    return resolver._reverse_with_prefix(view, prefix, *args, **kwargs)
  File "D:\Users\ntabyldieva\Desktop\databases_v1\env\lib\site-packages\django\urls\resolvers.py", line 694, in _reverse_with_prefix
    raise NoReverseMatch(msg)
django.urls.exceptions.NoReverseMatch: Reverse for 'detail_case' with no arguments not found. 1 pattern(s) tried: ['work/detail/(?P<pk>[0-9]+)/$']
ERROR django.server "GET /analytic/work/ HTTP/1.1" 500 163957 2021-12-01 16:18:22,526
ERROR django.request Internal Server Error: /analytic/work/ 2021-12-01 16:18:57,571
Traceback (most recent call last):
  File "D:\Users\ntabyldieva\Desktop\databases_v1\env\lib\site-packages\django\core\handlers\exception.py", line 47, in inner
    response = get_response(request)
  File "D:\Users\ntabyldieva\Desktop\databases_v1\env\lib\site-packages\django\core\handlers\base.py", line 181, in _get_response
    response = wrapped_callback(request, *callback_args, **callback_kwargs)
  File "D:\Users\ntabyldieva\Desktop\databases_v1\env\lib\site-packages\django\contrib\auth\decorators.py", line 21, in _wrapped_view
    return view_func(request, *args, **kwargs)
  File "D:\Users\ntabyldieva\Desktop\databases_v1\statistica\views.py", line 58, in work_analytic
    return render(request, 'statistica/work_search.html', {'url': f'{scheme}://{url}'})
  File "D:\Users\ntabyldieva\Desktop\databases_v1\env\lib\site-packages\django\shortcuts.py", line 19, in render
    content = loader.render_to_string(template_name, context, request, using=using)
  File "D:\Users\ntabyldieva\Desktop\databases_v1\env\lib\site-packages\django\template\loader.py", line 62, in render_to_string
    return template.render(context, request)
  File "D:\Users\ntabyldieva\Desktop\databases_v1\env\lib\site-packages\django\template\backends\django.py", line 61, in render
    return self.template.render(context)
  File "D:\Users\ntabyldieva\Desktop\databases_v1\env\lib\site-packages\django\template\base.py", line 170, in render
    return self._render(context)
  File "D:\Users\ntabyldieva\Desktop\databases_v1\env\lib\site-packages\django\test\utils.py", line 100, in instrumented_test_render
    return self.nodelist.render(context)
  File "D:\Users\ntabyldieva\Desktop\databases_v1\env\lib\site-packages\django\template\base.py", line 938, in render
    bit = node.render_annotated(context)
  File "D:\Users\ntabyldieva\Desktop\databases_v1\env\lib\site-packages\django\template\base.py", line 905, in render_annotated
    return self.render(context)
  File "D:\Users\ntabyldieva\Desktop\databases_v1\env\lib\site-packages\django\template\loader_tags.py", line 150, in render
    return compiled_parent._render(context)
  File "D:\Users\ntabyldieva\Desktop\databases_v1\env\lib\site-packages\django\test\utils.py", line 100, in instrumented_test_render
    return self.nodelist.render(context)
  File "D:\Users\ntabyldieva\Desktop\databases_v1\env\lib\site-packages\django\template\base.py", line 938, in render
    bit = node.render_annotated(context)
  File "D:\Users\ntabyldieva\Desktop\databases_v1\env\lib\site-packages\django\template\base.py", line 905, in render_annotated
    return self.render(context)
  File "D:\Users\ntabyldieva\Desktop\databases_v1\env\lib\site-packages\django\template\loader_tags.py", line 62, in render
    result = block.nodelist.render(context)
  File "D:\Users\ntabyldieva\Desktop\databases_v1\env\lib\site-packages\django\template\base.py", line 938, in render
    bit = node.render_annotated(context)
  File "D:\Users\ntabyldieva\Desktop\databases_v1\env\lib\site-packages\django\template\base.py", line 905, in render_annotated
    return self.render(context)
  File "D:\Users\ntabyldieva\Desktop\databases_v1\env\lib\site-packages\django\template\defaulttags.py", line 446, in render
    url = reverse(view_name, args=args, kwargs=kwargs, current_app=current_app)
  File "D:\Users\ntabyldieva\Desktop\databases_v1\env\lib\site-packages\django\urls\base.py", line 86, in reverse
    return resolver._reverse_with_prefix(view, prefix, *args, **kwargs)
  File "D:\Users\ntabyldieva\Desktop\databases_v1\env\lib\site-packages\django\urls\resolvers.py", line 694, in _reverse_with_prefix
    raise NoReverseMatch(msg)
django.urls.exceptions.NoReverseMatch: Reverse for 'detail_case' with no arguments not found. 1 pattern(s) tried: ['work/detail/(?P<pk>[0-9]+)/$']
ERROR django.server "GET /analytic/work/ HTTP/1.1" 500 163953 2021-12-01 16:18:57,581
ERROR django.request Internal Server Error: /analytic/work/ 2021-12-01 16:18:58,906
Traceback (most recent call last):
  File "D:\Users\ntabyldieva\Desktop\databases_v1\env\lib\site-packages\django\core\handlers\exception.py", line 47, in inner
    response = get_response(request)
  File "D:\Users\ntabyldieva\Desktop\databases_v1\env\lib\site-packages\django\core\handlers\base.py", line 181, in _get_response
    response = wrapped_callback(request, *callback_args, **callback_kwargs)
  File "D:\Users\ntabyldieva\Desktop\databases_v1\env\lib\site-packages\django\contrib\auth\decorators.py", line 21, in _wrapped_view
    return view_func(request, *args, **kwargs)
  File "D:\Users\ntabyldieva\Desktop\databases_v1\statistica\views.py", line 58, in work_analytic
    return render(request, 'statistica/work_search.html', {'url': f'{scheme}://{url}'})
  File "D:\Users\ntabyldieva\Desktop\databases_v1\env\lib\site-packages\django\shortcuts.py", line 19, in render
    content = loader.render_to_string(template_name, context, request, using=using)
  File "D:\Users\ntabyldieva\Desktop\databases_v1\env\lib\site-packages\django\template\loader.py", line 62, in render_to_string
    return template.render(context, request)
  File "D:\Users\ntabyldieva\Desktop\databases_v1\env\lib\site-packages\django\template\backends\django.py", line 61, in render
    return self.template.render(context)
  File "D:\Users\ntabyldieva\Desktop\databases_v1\env\lib\site-packages\django\template\base.py", line 170, in render
    return self._render(context)
  File "D:\Users\ntabyldieva\Desktop\databases_v1\env\lib\site-packages\django\test\utils.py", line 100, in instrumented_test_render
    return self.nodelist.render(context)
  File "D:\Users\ntabyldieva\Desktop\databases_v1\env\lib\site-packages\django\template\base.py", line 938, in render
    bit = node.render_annotated(context)
  File "D:\Users\ntabyldieva\Desktop\databases_v1\env\lib\site-packages\django\template\base.py", line 905, in render_annotated
    return self.render(context)
  File "D:\Users\ntabyldieva\Desktop\databases_v1\env\lib\site-packages\django\template\loader_tags.py", line 150, in render
    return compiled_parent._render(context)
  File "D:\Users\ntabyldieva\Desktop\databases_v1\env\lib\site-packages\django\test\utils.py", line 100, in instrumented_test_render
    return self.nodelist.render(context)
  File "D:\Users\ntabyldieva\Desktop\databases_v1\env\lib\site-packages\django\template\base.py", line 938, in render
    bit = node.render_annotated(context)
  File "D:\Users\ntabyldieva\Desktop\databases_v1\env\lib\site-packages\django\template\base.py", line 905, in render_annotated
    return self.render(context)
  File "D:\Users\ntabyldieva\Desktop\databases_v1\env\lib\site-packages\django\template\loader_tags.py", line 62, in render
    result = block.nodelist.render(context)
  File "D:\Users\ntabyldieva\Desktop\databases_v1\env\lib\site-packages\django\template\base.py", line 938, in render
    bit = node.render_annotated(context)
  File "D:\Users\ntabyldieva\Desktop\databases_v1\env\lib\site-packages\django\template\base.py", line 905, in render_annotated
    return self.render(context)
  File "D:\Users\ntabyldieva\Desktop\databases_v1\env\lib\site-packages\django\template\defaulttags.py", line 446, in render
    url = reverse(view_name, args=args, kwargs=kwargs, current_app=current_app)
  File "D:\Users\ntabyldieva\Desktop\databases_v1\env\lib\site-packages\django\urls\base.py", line 86, in reverse
    return resolver._reverse_with_prefix(view, prefix, *args, **kwargs)
  File "D:\Users\ntabyldieva\Desktop\databases_v1\env\lib\site-packages\django\urls\resolvers.py", line 694, in _reverse_with_prefix
    raise NoReverseMatch(msg)
django.urls.exceptions.NoReverseMatch: Reverse for 'detail_case' with no arguments not found. 1 pattern(s) tried: ['work/detail/(?P<pk>[0-9]+)/$']
ERROR django.server "GET /analytic/work/ HTTP/1.1" 500 163953 2021-12-01 16:18:58,916
ERROR django.request Internal Server Error: /analytic/work/ 2021-12-01 16:20:38,524
Traceback (most recent call last):
  File "D:\Users\ntabyldieva\Desktop\databases_v1\env\lib\site-packages\django\core\handlers\exception.py", line 47, in inner
    response = get_response(request)
  File "D:\Users\ntabyldieva\Desktop\databases_v1\env\lib\site-packages\django\core\handlers\base.py", line 181, in _get_response
    response = wrapped_callback(request, *callback_args, **callback_kwargs)
  File "D:\Users\ntabyldieva\Desktop\databases_v1\env\lib\site-packages\django\contrib\auth\decorators.py", line 21, in _wrapped_view
    return view_func(request, *args, **kwargs)
  File "D:\Users\ntabyldieva\Desktop\databases_v1\statistica\views.py", line 58, in work_analytic
    return render(request, 'statistica/work_search.html', {'url': f'{scheme}://{url}'})
  File "D:\Users\ntabyldieva\Desktop\databases_v1\env\lib\site-packages\django\shortcuts.py", line 19, in render
    content = loader.render_to_string(template_name, context, request, using=using)
  File "D:\Users\ntabyldieva\Desktop\databases_v1\env\lib\site-packages\django\template\loader.py", line 62, in render_to_string
    return template.render(context, request)
  File "D:\Users\ntabyldieva\Desktop\databases_v1\env\lib\site-packages\django\template\backends\django.py", line 61, in render
    return self.template.render(context)
  File "D:\Users\ntabyldieva\Desktop\databases_v1\env\lib\site-packages\django\template\base.py", line 170, in render
    return self._render(context)
  File "D:\Users\ntabyldieva\Desktop\databases_v1\env\lib\site-packages\django\test\utils.py", line 100, in instrumented_test_render
    return self.nodelist.render(context)
  File "D:\Users\ntabyldieva\Desktop\databases_v1\env\lib\site-packages\django\template\base.py", line 938, in render
    bit = node.render_annotated(context)
  File "D:\Users\ntabyldieva\Desktop\databases_v1\env\lib\site-packages\django\template\base.py", line 905, in render_annotated
    return self.render(context)
  File "D:\Users\ntabyldieva\Desktop\databases_v1\env\lib\site-packages\django\template\loader_tags.py", line 150, in render
    return compiled_parent._render(context)
  File "D:\Users\ntabyldieva\Desktop\databases_v1\env\lib\site-packages\django\test\utils.py", line 100, in instrumented_test_render
    return self.nodelist.render(context)
  File "D:\Users\ntabyldieva\Desktop\databases_v1\env\lib\site-packages\django\template\base.py", line 938, in render
    bit = node.render_annotated(context)
  File "D:\Users\ntabyldieva\Desktop\databases_v1\env\lib\site-packages\django\template\base.py", line 905, in render_annotated
    return self.render(context)
  File "D:\Users\ntabyldieva\Desktop\databases_v1\env\lib\site-packages\django\template\loader_tags.py", line 62, in render
    result = block.nodelist.render(context)
  File "D:\Users\ntabyldieva\Desktop\databases_v1\env\lib\site-packages\django\template\base.py", line 938, in render
    bit = node.render_annotated(context)
  File "D:\Users\ntabyldieva\Desktop\databases_v1\env\lib\site-packages\django\template\base.py", line 905, in render_annotated
    return self.render(context)
  File "D:\Users\ntabyldieva\Desktop\databases_v1\env\lib\site-packages\django\template\defaulttags.py", line 446, in render
    url = reverse(view_name, args=args, kwargs=kwargs, current_app=current_app)
  File "D:\Users\ntabyldieva\Desktop\databases_v1\env\lib\site-packages\django\urls\base.py", line 86, in reverse
    return resolver._reverse_with_prefix(view, prefix, *args, **kwargs)
  File "D:\Users\ntabyldieva\Desktop\databases_v1\env\lib\site-packages\django\urls\resolvers.py", line 694, in _reverse_with_prefix
    raise NoReverseMatch(msg)
django.urls.exceptions.NoReverseMatch: Reverse for 'detail_case' with no arguments not found. 1 pattern(s) tried: ['work/detail/(?P<pk>[0-9]+)/$']
ERROR django.server "GET /analytic/work/ HTTP/1.1" 500 163953 2021-12-01 16:20:38,533
ERROR django.request Internal Server Error: /analytic/work/ 2021-12-01 16:20:57,022
Traceback (most recent call last):
  File "D:\Users\ntabyldieva\Desktop\databases_v1\env\lib\site-packages\django\core\handlers\exception.py", line 47, in inner
    response = get_response(request)
  File "D:\Users\ntabyldieva\Desktop\databases_v1\env\lib\site-packages\django\core\handlers\base.py", line 181, in _get_response
    response = wrapped_callback(request, *callback_args, **callback_kwargs)
  File "D:\Users\ntabyldieva\Desktop\databases_v1\env\lib\site-packages\django\contrib\auth\decorators.py", line 21, in _wrapped_view
    return view_func(request, *args, **kwargs)
  File "D:\Users\ntabyldieva\Desktop\databases_v1\statistica\views.py", line 58, in work_analytic
    return render(request, 'statistica/work_search.html', {'url': f'{scheme}://{url}'})
  File "D:\Users\ntabyldieva\Desktop\databases_v1\env\lib\site-packages\django\shortcuts.py", line 19, in render
    content = loader.render_to_string(template_name, context, request, using=using)
  File "D:\Users\ntabyldieva\Desktop\databases_v1\env\lib\site-packages\django\template\loader.py", line 62, in render_to_string
    return template.render(context, request)
  File "D:\Users\ntabyldieva\Desktop\databases_v1\env\lib\site-packages\django\template\backends\django.py", line 61, in render
    return self.template.render(context)
  File "D:\Users\ntabyldieva\Desktop\databases_v1\env\lib\site-packages\django\template\base.py", line 170, in render
    return self._render(context)
  File "D:\Users\ntabyldieva\Desktop\databases_v1\env\lib\site-packages\django\test\utils.py", line 100, in instrumented_test_render
    return self.nodelist.render(context)
  File "D:\Users\ntabyldieva\Desktop\databases_v1\env\lib\site-packages\django\template\base.py", line 938, in render
    bit = node.render_annotated(context)
  File "D:\Users\ntabyldieva\Desktop\databases_v1\env\lib\site-packages\django\template\base.py", line 905, in render_annotated
    return self.render(context)
  File "D:\Users\ntabyldieva\Desktop\databases_v1\env\lib\site-packages\django\template\loader_tags.py", line 150, in render
    return compiled_parent._render(context)
  File "D:\Users\ntabyldieva\Desktop\databases_v1\env\lib\site-packages\django\test\utils.py", line 100, in instrumented_test_render
    return self.nodelist.render(context)
  File "D:\Users\ntabyldieva\Desktop\databases_v1\env\lib\site-packages\django\template\base.py", line 938, in render
    bit = node.render_annotated(context)
  File "D:\Users\ntabyldieva\Desktop\databases_v1\env\lib\site-packages\django\template\base.py", line 905, in render_annotated
    return self.render(context)
  File "D:\Users\ntabyldieva\Desktop\databases_v1\env\lib\site-packages\django\template\loader_tags.py", line 62, in render
    result = block.nodelist.render(context)
  File "D:\Users\ntabyldieva\Desktop\databases_v1\env\lib\site-packages\django\template\base.py", line 938, in render
    bit = node.render_annotated(context)
  File "D:\Users\ntabyldieva\Desktop\databases_v1\env\lib\site-packages\django\template\base.py", line 905, in render_annotated
    return self.render(context)
  File "D:\Users\ntabyldieva\Desktop\databases_v1\env\lib\site-packages\django\template\defaulttags.py", line 446, in render
    url = reverse(view_name, args=args, kwargs=kwargs, current_app=current_app)
  File "D:\Users\ntabyldieva\Desktop\databases_v1\env\lib\site-packages\django\urls\base.py", line 86, in reverse
    return resolver._reverse_with_prefix(view, prefix, *args, **kwargs)
  File "D:\Users\ntabyldieva\Desktop\databases_v1\env\lib\site-packages\django\urls\resolvers.py", line 694, in _reverse_with_prefix
    raise NoReverseMatch(msg)
django.urls.exceptions.NoReverseMatch: Reverse for 'detail_case' with no arguments not found. 1 pattern(s) tried: ['work/detail/(?P<pk>[0-9]+)/$']
ERROR django.server "GET /analytic/work/ HTTP/1.1" 500 163953 2021-12-01 16:20:57,031
ERROR django.request Internal Server Error: /analytic/work/ 2021-12-01 16:21:37,467
Traceback (most recent call last):
  File "D:\Users\ntabyldieva\Desktop\databases_v1\env\lib\site-packages\django\core\handlers\exception.py", line 47, in inner
    response = get_response(request)
  File "D:\Users\ntabyldieva\Desktop\databases_v1\env\lib\site-packages\django\core\handlers\base.py", line 181, in _get_response
    response = wrapped_callback(request, *callback_args, **callback_kwargs)
  File "D:\Users\ntabyldieva\Desktop\databases_v1\env\lib\site-packages\django\contrib\auth\decorators.py", line 21, in _wrapped_view
    return view_func(request, *args, **kwargs)
  File "D:\Users\ntabyldieva\Desktop\databases_v1\statistica\views.py", line 58, in work_analytic
    return render(request, 'statistica/work_search.html', {'url': f'{scheme}://{url}'})
  File "D:\Users\ntabyldieva\Desktop\databases_v1\env\lib\site-packages\django\shortcuts.py", line 19, in render
    content = loader.render_to_string(template_name, context, request, using=using)
  File "D:\Users\ntabyldieva\Desktop\databases_v1\env\lib\site-packages\django\template\loader.py", line 62, in render_to_string
    return template.render(context, request)
  File "D:\Users\ntabyldieva\Desktop\databases_v1\env\lib\site-packages\django\template\backends\django.py", line 61, in render
    return self.template.render(context)
  File "D:\Users\ntabyldieva\Desktop\databases_v1\env\lib\site-packages\django\template\base.py", line 170, in render
    return self._render(context)
  File "D:\Users\ntabyldieva\Desktop\databases_v1\env\lib\site-packages\django\test\utils.py", line 100, in instrumented_test_render
    return self.nodelist.render(context)
  File "D:\Users\ntabyldieva\Desktop\databases_v1\env\lib\site-packages\django\template\base.py", line 938, in render
    bit = node.render_annotated(context)
  File "D:\Users\ntabyldieva\Desktop\databases_v1\env\lib\site-packages\django\template\base.py", line 905, in render_annotated
    return self.render(context)
  File "D:\Users\ntabyldieva\Desktop\databases_v1\env\lib\site-packages\django\template\loader_tags.py", line 150, in render
    return compiled_parent._render(context)
  File "D:\Users\ntabyldieva\Desktop\databases_v1\env\lib\site-packages\django\test\utils.py", line 100, in instrumented_test_render
    return self.nodelist.render(context)
  File "D:\Users\ntabyldieva\Desktop\databases_v1\env\lib\site-packages\django\template\base.py", line 938, in render
    bit = node.render_annotated(context)
  File "D:\Users\ntabyldieva\Desktop\databases_v1\env\lib\site-packages\django\template\base.py", line 905, in render_annotated
    return self.render(context)
  File "D:\Users\ntabyldieva\Desktop\databases_v1\env\lib\site-packages\django\template\loader_tags.py", line 62, in render
    result = block.nodelist.render(context)
  File "D:\Users\ntabyldieva\Desktop\databases_v1\env\lib\site-packages\django\template\base.py", line 938, in render
    bit = node.render_annotated(context)
  File "D:\Users\ntabyldieva\Desktop\databases_v1\env\lib\site-packages\django\template\base.py", line 905, in render_annotated
    return self.render(context)
  File "D:\Users\ntabyldieva\Desktop\databases_v1\env\lib\site-packages\django\template\defaulttags.py", line 446, in render
    url = reverse(view_name, args=args, kwargs=kwargs, current_app=current_app)
  File "D:\Users\ntabyldieva\Desktop\databases_v1\env\lib\site-packages\django\urls\base.py", line 86, in reverse
    return resolver._reverse_with_prefix(view, prefix, *args, **kwargs)
  File "D:\Users\ntabyldieva\Desktop\databases_v1\env\lib\site-packages\django\urls\resolvers.py", line 694, in _reverse_with_prefix
    raise NoReverseMatch(msg)
django.urls.exceptions.NoReverseMatch: Reverse for 'detail_case' not found. 'detail_case' is not a valid view function or pattern name.
ERROR django.server "GET /analytic/work/ HTTP/1.1" 500 162230 2021-12-01 16:21:37,481
ERROR django.request Internal Server Error: /analytic/work/ 2021-12-01 16:21:37,539
Traceback (most recent call last):
  File "D:\Users\ntabyldieva\Desktop\databases_v1\env\lib\site-packages\django\core\handlers\exception.py", line 47, in inner
    response = get_response(request)
  File "D:\Users\ntabyldieva\Desktop\databases_v1\env\lib\site-packages\django\core\handlers\base.py", line 181, in _get_response
    response = wrapped_callback(request, *callback_args, **callback_kwargs)
  File "D:\Users\ntabyldieva\Desktop\databases_v1\env\lib\site-packages\django\contrib\auth\decorators.py", line 21, in _wrapped_view
    return view_func(request, *args, **kwargs)
  File "D:\Users\ntabyldieva\Desktop\databases_v1\statistica\views.py", line 58, in work_analytic
    return render(request, 'statistica/work_search.html', {'url': f'{scheme}://{url}'})
  File "D:\Users\ntabyldieva\Desktop\databases_v1\env\lib\site-packages\django\shortcuts.py", line 19, in render
    content = loader.render_to_string(template_name, context, request, using=using)
  File "D:\Users\ntabyldieva\Desktop\databases_v1\env\lib\site-packages\django\template\loader.py", line 62, in render_to_string
    return template.render(context, request)
  File "D:\Users\ntabyldieva\Desktop\databases_v1\env\lib\site-packages\django\template\backends\django.py", line 61, in render
    return self.template.render(context)
  File "D:\Users\ntabyldieva\Desktop\databases_v1\env\lib\site-packages\django\template\base.py", line 170, in render
    return self._render(context)
  File "D:\Users\ntabyldieva\Desktop\databases_v1\env\lib\site-packages\django\test\utils.py", line 100, in instrumented_test_render
    return self.nodelist.render(context)
  File "D:\Users\ntabyldieva\Desktop\databases_v1\env\lib\site-packages\django\template\base.py", line 938, in render
    bit = node.render_annotated(context)
  File "D:\Users\ntabyldieva\Desktop\databases_v1\env\lib\site-packages\django\template\base.py", line 905, in render_annotated
    return self.render(context)
  File "D:\Users\ntabyldieva\Desktop\databases_v1\env\lib\site-packages\django\template\loader_tags.py", line 150, in render
    return compiled_parent._render(context)
  File "D:\Users\ntabyldieva\Desktop\databases_v1\env\lib\site-packages\django\test\utils.py", line 100, in instrumented_test_render
    return self.nodelist.render(context)
  File "D:\Users\ntabyldieva\Desktop\databases_v1\env\lib\site-packages\django\template\base.py", line 938, in render
    bit = node.render_annotated(context)
  File "D:\Users\ntabyldieva\Desktop\databases_v1\env\lib\site-packages\django\template\base.py", line 905, in render_annotated
    return self.render(context)
  File "D:\Users\ntabyldieva\Desktop\databases_v1\env\lib\site-packages\django\template\loader_tags.py", line 62, in render
    result = block.nodelist.render(context)
  File "D:\Users\ntabyldieva\Desktop\databases_v1\env\lib\site-packages\django\template\base.py", line 938, in render
    bit = node.render_annotated(context)
  File "D:\Users\ntabyldieva\Desktop\databases_v1\env\lib\site-packages\django\template\base.py", line 905, in render_annotated
    return self.render(context)
  File "D:\Users\ntabyldieva\Desktop\databases_v1\env\lib\site-packages\django\template\defaulttags.py", line 446, in render
    url = reverse(view_name, args=args, kwargs=kwargs, current_app=current_app)
  File "D:\Users\ntabyldieva\Desktop\databases_v1\env\lib\site-packages\django\urls\base.py", line 86, in reverse
    return resolver._reverse_with_prefix(view, prefix, *args, **kwargs)
  File "D:\Users\ntabyldieva\Desktop\databases_v1\env\lib\site-packages\django\urls\resolvers.py", line 694, in _reverse_with_prefix
    raise NoReverseMatch(msg)
django.urls.exceptions.NoReverseMatch: Reverse for 'detail_case' not found. 'detail_case' is not a valid view function or pattern name.
ERROR django.server "GET /analytic/work/ HTTP/1.1" 500 162230 2021-12-01 16:21:37,548
ERROR django.request Internal Server Error: /analytic/work/ 2021-12-01 16:21:39,539
Traceback (most recent call last):
  File "D:\Users\ntabyldieva\Desktop\databases_v1\env\lib\site-packages\django\core\handlers\exception.py", line 47, in inner
    response = get_response(request)
  File "D:\Users\ntabyldieva\Desktop\databases_v1\env\lib\site-packages\django\core\handlers\base.py", line 181, in _get_response
    response = wrapped_callback(request, *callback_args, **callback_kwargs)
  File "D:\Users\ntabyldieva\Desktop\databases_v1\env\lib\site-packages\django\contrib\auth\decorators.py", line 21, in _wrapped_view
    return view_func(request, *args, **kwargs)
  File "D:\Users\ntabyldieva\Desktop\databases_v1\statistica\views.py", line 58, in work_analytic
    return render(request, 'statistica/work_search.html', {'url': f'{scheme}://{url}'})
  File "D:\Users\ntabyldieva\Desktop\databases_v1\env\lib\site-packages\django\shortcuts.py", line 19, in render
    content = loader.render_to_string(template_name, context, request, using=using)
  File "D:\Users\ntabyldieva\Desktop\databases_v1\env\lib\site-packages\django\template\loader.py", line 62, in render_to_string
    return template.render(context, request)
  File "D:\Users\ntabyldieva\Desktop\databases_v1\env\lib\site-packages\django\template\backends\django.py", line 61, in render
    return self.template.render(context)
  File "D:\Users\ntabyldieva\Desktop\databases_v1\env\lib\site-packages\django\template\base.py", line 170, in render
    return self._render(context)
  File "D:\Users\ntabyldieva\Desktop\databases_v1\env\lib\site-packages\django\test\utils.py", line 100, in instrumented_test_render
    return self.nodelist.render(context)
  File "D:\Users\ntabyldieva\Desktop\databases_v1\env\lib\site-packages\django\template\base.py", line 938, in render
    bit = node.render_annotated(context)
  File "D:\Users\ntabyldieva\Desktop\databases_v1\env\lib\site-packages\django\template\base.py", line 905, in render_annotated
    return self.render(context)
  File "D:\Users\ntabyldieva\Desktop\databases_v1\env\lib\site-packages\django\template\loader_tags.py", line 150, in render
    return compiled_parent._render(context)
  File "D:\Users\ntabyldieva\Desktop\databases_v1\env\lib\site-packages\django\test\utils.py", line 100, in instrumented_test_render
    return self.nodelist.render(context)
  File "D:\Users\ntabyldieva\Desktop\databases_v1\env\lib\site-packages\django\template\base.py", line 938, in render
    bit = node.render_annotated(context)
  File "D:\Users\ntabyldieva\Desktop\databases_v1\env\lib\site-packages\django\template\base.py", line 905, in render_annotated
    return self.render(context)
  File "D:\Users\ntabyldieva\Desktop\databases_v1\env\lib\site-packages\django\template\loader_tags.py", line 62, in render
    result = block.nodelist.render(context)
  File "D:\Users\ntabyldieva\Desktop\databases_v1\env\lib\site-packages\django\template\base.py", line 938, in render
    bit = node.render_annotated(context)
  File "D:\Users\ntabyldieva\Desktop\databases_v1\env\lib\site-packages\django\template\base.py", line 905, in render_annotated
    return self.render(context)
  File "D:\Users\ntabyldieva\Desktop\databases_v1\env\lib\site-packages\django\template\defaulttags.py", line 446, in render
    url = reverse(view_name, args=args, kwargs=kwargs, current_app=current_app)
  File "D:\Users\ntabyldieva\Desktop\databases_v1\env\lib\site-packages\django\urls\base.py", line 86, in reverse
    return resolver._reverse_with_prefix(view, prefix, *args, **kwargs)
  File "D:\Users\ntabyldieva\Desktop\databases_v1\env\lib\site-packages\django\urls\resolvers.py", line 694, in _reverse_with_prefix
    raise NoReverseMatch(msg)
django.urls.exceptions.NoReverseMatch: Reverse for 'detail_case' not found. 'detail_case' is not a valid view function or pattern name.
ERROR django.server "GET /analytic/work/ HTTP/1.1" 500 162230 2021-12-01 16:21:39,548
ERROR django.request Internal Server Error: /analytic/work/ 2021-12-01 16:22:01,897
Traceback (most recent call last):
  File "D:\Users\ntabyldieva\Desktop\databases_v1\env\lib\site-packages\django\core\handlers\exception.py", line 47, in inner
    response = get_response(request)
  File "D:\Users\ntabyldieva\Desktop\databases_v1\env\lib\site-packages\django\core\handlers\base.py", line 181, in _get_response
    response = wrapped_callback(request, *callback_args, **callback_kwargs)
  File "D:\Users\ntabyldieva\Desktop\databases_v1\env\lib\site-packages\django\contrib\auth\decorators.py", line 21, in _wrapped_view
    return view_func(request, *args, **kwargs)
  File "D:\Users\ntabyldieva\Desktop\databases_v1\statistica\views.py", line 58, in work_analytic
    return render(request, 'statistica/work_search.html', {'url': f'{scheme}://{url}'})
  File "D:\Users\ntabyldieva\Desktop\databases_v1\env\lib\site-packages\django\shortcuts.py", line 19, in render
    content = loader.render_to_string(template_name, context, request, using=using)
  File "D:\Users\ntabyldieva\Desktop\databases_v1\env\lib\site-packages\django\template\loader.py", line 62, in render_to_string
    return template.render(context, request)
  File "D:\Users\ntabyldieva\Desktop\databases_v1\env\lib\site-packages\django\template\backends\django.py", line 61, in render
    return self.template.render(context)
  File "D:\Users\ntabyldieva\Desktop\databases_v1\env\lib\site-packages\django\template\base.py", line 170, in render
    return self._render(context)
  File "D:\Users\ntabyldieva\Desktop\databases_v1\env\lib\site-packages\django\test\utils.py", line 100, in instrumented_test_render
    return self.nodelist.render(context)
  File "D:\Users\ntabyldieva\Desktop\databases_v1\env\lib\site-packages\django\template\base.py", line 938, in render
    bit = node.render_annotated(context)
  File "D:\Users\ntabyldieva\Desktop\databases_v1\env\lib\site-packages\django\template\base.py", line 905, in render_annotated
    return self.render(context)
  File "D:\Users\ntabyldieva\Desktop\databases_v1\env\lib\site-packages\django\template\loader_tags.py", line 150, in render
    return compiled_parent._render(context)
  File "D:\Users\ntabyldieva\Desktop\databases_v1\env\lib\site-packages\django\test\utils.py", line 100, in instrumented_test_render
    return self.nodelist.render(context)
  File "D:\Users\ntabyldieva\Desktop\databases_v1\env\lib\site-packages\django\template\base.py", line 938, in render
    bit = node.render_annotated(context)
  File "D:\Users\ntabyldieva\Desktop\databases_v1\env\lib\site-packages\django\template\base.py", line 905, in render_annotated
    return self.render(context)
  File "D:\Users\ntabyldieva\Desktop\databases_v1\env\lib\site-packages\django\template\loader_tags.py", line 62, in render
    result = block.nodelist.render(context)
  File "D:\Users\ntabyldieva\Desktop\databases_v1\env\lib\site-packages\django\template\base.py", line 938, in render
    bit = node.render_annotated(context)
  File "D:\Users\ntabyldieva\Desktop\databases_v1\env\lib\site-packages\django\template\base.py", line 905, in render_annotated
    return self.render(context)
  File "D:\Users\ntabyldieva\Desktop\databases_v1\env\lib\site-packages\django\template\defaulttags.py", line 446, in render
    url = reverse(view_name, args=args, kwargs=kwargs, current_app=current_app)
  File "D:\Users\ntabyldieva\Desktop\databases_v1\env\lib\site-packages\django\urls\base.py", line 86, in reverse
    return resolver._reverse_with_prefix(view, prefix, *args, **kwargs)
  File "D:\Users\ntabyldieva\Desktop\databases_v1\env\lib\site-packages\django\urls\resolvers.py", line 694, in _reverse_with_prefix
    raise NoReverseMatch(msg)
django.urls.exceptions.NoReverseMatch: Reverse for 'detail_case' not found. 'detail_case' is not a valid view function or pattern name.
ERROR django.server "GET /analytic/work/ HTTP/1.1" 500 162230 2021-12-01 16:22:01,906
ERROR django.request Internal Server Error: /analytic/work/ 2021-12-01 16:22:03,435
Traceback (most recent call last):
  File "D:\Users\ntabyldieva\Desktop\databases_v1\env\lib\site-packages\django\core\handlers\exception.py", line 47, in inner
    response = get_response(request)
  File "D:\Users\ntabyldieva\Desktop\databases_v1\env\lib\site-packages\django\core\handlers\base.py", line 181, in _get_response
    response = wrapped_callback(request, *callback_args, **callback_kwargs)
  File "D:\Users\ntabyldieva\Desktop\databases_v1\env\lib\site-packages\django\contrib\auth\decorators.py", line 21, in _wrapped_view
    return view_func(request, *args, **kwargs)
  File "D:\Users\ntabyldieva\Desktop\databases_v1\statistica\views.py", line 58, in work_analytic
    return render(request, 'statistica/work_search.html', {'url': f'{scheme}://{url}'})
  File "D:\Users\ntabyldieva\Desktop\databases_v1\env\lib\site-packages\django\shortcuts.py", line 19, in render
    content = loader.render_to_string(template_name, context, request, using=using)
  File "D:\Users\ntabyldieva\Desktop\databases_v1\env\lib\site-packages\django\template\loader.py", line 62, in render_to_string
    return template.render(context, request)
  File "D:\Users\ntabyldieva\Desktop\databases_v1\env\lib\site-packages\django\template\backends\django.py", line 61, in render
    return self.template.render(context)
  File "D:\Users\ntabyldieva\Desktop\databases_v1\env\lib\site-packages\django\template\base.py", line 170, in render
    return self._render(context)
  File "D:\Users\ntabyldieva\Desktop\databases_v1\env\lib\site-packages\django\test\utils.py", line 100, in instrumented_test_render
    return self.nodelist.render(context)
  File "D:\Users\ntabyldieva\Desktop\databases_v1\env\lib\site-packages\django\template\base.py", line 938, in render
    bit = node.render_annotated(context)
  File "D:\Users\ntabyldieva\Desktop\databases_v1\env\lib\site-packages\django\template\base.py", line 905, in render_annotated
    return self.render(context)
  File "D:\Users\ntabyldieva\Desktop\databases_v1\env\lib\site-packages\django\template\loader_tags.py", line 150, in render
    return compiled_parent._render(context)
  File "D:\Users\ntabyldieva\Desktop\databases_v1\env\lib\site-packages\django\test\utils.py", line 100, in instrumented_test_render
    return self.nodelist.render(context)
  File "D:\Users\ntabyldieva\Desktop\databases_v1\env\lib\site-packages\django\template\base.py", line 938, in render
    bit = node.render_annotated(context)
  File "D:\Users\ntabyldieva\Desktop\databases_v1\env\lib\site-packages\django\template\base.py", line 905, in render_annotated
    return self.render(context)
  File "D:\Users\ntabyldieva\Desktop\databases_v1\env\lib\site-packages\django\template\loader_tags.py", line 62, in render
    result = block.nodelist.render(context)
  File "D:\Users\ntabyldieva\Desktop\databases_v1\env\lib\site-packages\django\template\base.py", line 938, in render
    bit = node.render_annotated(context)
  File "D:\Users\ntabyldieva\Desktop\databases_v1\env\lib\site-packages\django\template\base.py", line 905, in render_annotated
    return self.render(context)
  File "D:\Users\ntabyldieva\Desktop\databases_v1\env\lib\site-packages\django\template\defaulttags.py", line 446, in render
    url = reverse(view_name, args=args, kwargs=kwargs, current_app=current_app)
  File "D:\Users\ntabyldieva\Desktop\databases_v1\env\lib\site-packages\django\urls\base.py", line 86, in reverse
    return resolver._reverse_with_prefix(view, prefix, *args, **kwargs)
  File "D:\Users\ntabyldieva\Desktop\databases_v1\env\lib\site-packages\django\urls\resolvers.py", line 694, in _reverse_with_prefix
    raise NoReverseMatch(msg)
django.urls.exceptions.NoReverseMatch: Reverse for 'detail_case' not found. 'detail_case' is not a valid view function or pattern name.
ERROR django.server "GET /analytic/work/ HTTP/1.1" 500 162230 2021-12-01 16:22:03,444
ERROR django.request Internal Server Error: /analytic/work/ 2021-12-01 16:23:03,010
Traceback (most recent call last):
  File "D:\Users\ntabyldieva\Desktop\databases_v1\env\lib\site-packages\django\core\handlers\exception.py", line 47, in inner
    response = get_response(request)
  File "D:\Users\ntabyldieva\Desktop\databases_v1\env\lib\site-packages\django\core\handlers\base.py", line 181, in _get_response
    response = wrapped_callback(request, *callback_args, **callback_kwargs)
  File "D:\Users\ntabyldieva\Desktop\databases_v1\env\lib\site-packages\django\contrib\auth\decorators.py", line 21, in _wrapped_view
    return view_func(request, *args, **kwargs)
  File "D:\Users\ntabyldieva\Desktop\databases_v1\statistica\views.py", line 58, in work_analytic
    return render(request, 'statistica/work_search.html', {'url': f'{scheme}://{url}'})
  File "D:\Users\ntabyldieva\Desktop\databases_v1\env\lib\site-packages\django\shortcuts.py", line 19, in render
    content = loader.render_to_string(template_name, context, request, using=using)
  File "D:\Users\ntabyldieva\Desktop\databases_v1\env\lib\site-packages\django\template\loader.py", line 62, in render_to_string
    return template.render(context, request)
  File "D:\Users\ntabyldieva\Desktop\databases_v1\env\lib\site-packages\django\template\backends\django.py", line 61, in render
    return self.template.render(context)
  File "D:\Users\ntabyldieva\Desktop\databases_v1\env\lib\site-packages\django\template\base.py", line 170, in render
    return self._render(context)
  File "D:\Users\ntabyldieva\Desktop\databases_v1\env\lib\site-packages\django\test\utils.py", line 100, in instrumented_test_render
    return self.nodelist.render(context)
  File "D:\Users\ntabyldieva\Desktop\databases_v1\env\lib\site-packages\django\template\base.py", line 938, in render
    bit = node.render_annotated(context)
  File "D:\Users\ntabyldieva\Desktop\databases_v1\env\lib\site-packages\django\template\base.py", line 905, in render_annotated
    return self.render(context)
  File "D:\Users\ntabyldieva\Desktop\databases_v1\env\lib\site-packages\django\template\loader_tags.py", line 150, in render
    return compiled_parent._render(context)
  File "D:\Users\ntabyldieva\Desktop\databases_v1\env\lib\site-packages\django\test\utils.py", line 100, in instrumented_test_render
    return self.nodelist.render(context)
  File "D:\Users\ntabyldieva\Desktop\databases_v1\env\lib\site-packages\django\template\base.py", line 938, in render
    bit = node.render_annotated(context)
  File "D:\Users\ntabyldieva\Desktop\databases_v1\env\lib\site-packages\django\template\base.py", line 905, in render_annotated
    return self.render(context)
  File "D:\Users\ntabyldieva\Desktop\databases_v1\env\lib\site-packages\django\template\loader_tags.py", line 62, in render
    result = block.nodelist.render(context)
  File "D:\Users\ntabyldieva\Desktop\databases_v1\env\lib\site-packages\django\template\base.py", line 938, in render
    bit = node.render_annotated(context)
  File "D:\Users\ntabyldieva\Desktop\databases_v1\env\lib\site-packages\django\template\base.py", line 905, in render_annotated
    return self.render(context)
  File "D:\Users\ntabyldieva\Desktop\databases_v1\env\lib\site-packages\django\template\defaulttags.py", line 446, in render
    url = reverse(view_name, args=args, kwargs=kwargs, current_app=current_app)
  File "D:\Users\ntabyldieva\Desktop\databases_v1\env\lib\site-packages\django\urls\base.py", line 86, in reverse
    return resolver._reverse_with_prefix(view, prefix, *args, **kwargs)
  File "D:\Users\ntabyldieva\Desktop\databases_v1\env\lib\site-packages\django\urls\resolvers.py", line 694, in _reverse_with_prefix
    raise NoReverseMatch(msg)
django.urls.exceptions.NoReverseMatch: Reverse for 'detail_case' with no arguments not found. 1 pattern(s) tried: ['work/detail/(?P<pk>[0-9]+)/$']
ERROR django.server "GET /analytic/work/ HTTP/1.1" 500 163953 2021-12-01 16:23:03,022
ERROR django.request Internal Server Error: /work/data/get/ 2021-12-01 16:23:26,154
Traceback (most recent call last):
  File "D:\Users\ntabyldieva\Desktop\databases_v1\env\lib\site-packages\django\core\handlers\exception.py", line 47, in inner
    response = get_response(request)
  File "D:\Users\ntabyldieva\Desktop\databases_v1\env\lib\site-packages\django\core\handlers\base.py", line 181, in _get_response
    response = wrapped_callback(request, *callback_args, **callback_kwargs)
  File "D:\Users\ntabyldieva\Desktop\databases_v1\env\lib\site-packages\django\views\decorators\csrf.py", line 54, in wrapped_view
    return view_func(*args, **kwargs)
  File "D:\Users\ntabyldieva\Desktop\databases_v1\env\lib\site-packages\django\views\generic\base.py", line 70, in view
    return self.dispatch(request, *args, **kwargs)
  File "D:\Users\ntabyldieva\Desktop\databases_v1\env\lib\site-packages\rest_framework\views.py", line 509, in dispatch
    response = self.handle_exception(exc)
  File "D:\Users\ntabyldieva\Desktop\databases_v1\env\lib\site-packages\rest_framework\views.py", line 469, in handle_exception
    self.raise_uncaught_exception(exc)
  File "D:\Users\ntabyldieva\Desktop\databases_v1\env\lib\site-packages\rest_framework\views.py", line 480, in raise_uncaught_exception
    raise exc
  File "D:\Users\ntabyldieva\Desktop\databases_v1\env\lib\site-packages\rest_framework\views.py", line 506, in dispatch
    response = handler(request, *args, **kwargs)
  File "D:\Users\ntabyldieva\Desktop\databases_v1\work\views\views.py", line 509, in post
    two = return_right_data(one)
  File "D:\Users\ntabyldieva\Desktop\databases_v1\strike\helpers.py", line 24, in return_right_data
    item.append(int(value['id']))
ValueError: invalid literal for int() with base 10: ''
ERROR django.server "POST /work/data/get/ HTTP/1.1" 500 99297 2021-12-01 16:23:26,159
WARNING django.request Not Found: /favicon.ico 2021-12-01 16:24:38,895
WARNING django.server "GET /favicon.ico HTTP/1.1" 404 3524 2021-12-01 16:24:38,896
ERROR django.request Internal Server Error: /work/get-pdf/7/ 2021-12-01 16:28:23,710
Traceback (most recent call last):
  File "D:\Users\ntabyldieva\Desktop\databases_v1\env\lib\site-packages\django\core\handlers\exception.py", line 47, in inner
    response = get_response(request)
  File "D:\Users\ntabyldieva\Desktop\databases_v1\env\lib\site-packages\django\core\handlers\base.py", line 181, in _get_response
    response = wrapped_callback(request, *callback_args, **callback_kwargs)
  File "D:\Users\ntabyldieva\Desktop\databases_v1\work\views\views.py", line 430, in case_render_pdf_view
    pdf = pdfkit.from_string(html, False)
  File "D:\Users\ntabyldieva\Desktop\databases_v1\env\lib\site-packages\pdfkit\api.py", line 72, in from_string
    return r.to_pdf(output_path)
  File "D:\Users\ntabyldieva\Desktop\databases_v1\env\lib\site-packages\pdfkit\pdfkit.py", line 156, in to_pdf
    raise IOError('wkhtmltopdf reported an error:\n' + stderr)
OSError: wkhtmltopdf reported an error:
Loading pages (1/6)
[>                                                           ] 0%[======>                                                     ] 10%[===================>                                        ] 33%Error: Failed to load https://cdn.jsdelivr.net/npm/bootstrap@5.0.2/dist/css/bootstrap.min.css, with network status code 1 and http status code 0 - Connection refused
[============================================================] 100%Counting pages (2/6)                                               
[============================================================] Object 1 of 1Resolving links (4/6)                                                       
[============================================================] Object 1 of 1Loading headers and footers (5/6)                                           
Printing pages (6/6)
[>                                                           ] Preparing[==============================>                             ] Page 1 of 2[============================================================] Page 2 of 2Done                                                                      
Exit with code 1 due to network error: ConnectionRefusedError

ERROR django.server "GET /work/get-pdf/7/ HTTP/1.1" 500 110365 2021-12-01 16:28:23,716
ERROR django.request Internal Server Error: /work/get-pdf/6/ 2021-12-01 16:28:28,924
Traceback (most recent call last):
  File "D:\Users\ntabyldieva\Desktop\databases_v1\env\lib\site-packages\django\core\handlers\exception.py", line 47, in inner
    response = get_response(request)
  File "D:\Users\ntabyldieva\Desktop\databases_v1\env\lib\site-packages\django\core\handlers\base.py", line 181, in _get_response
    response = wrapped_callback(request, *callback_args, **callback_kwargs)
  File "D:\Users\ntabyldieva\Desktop\databases_v1\work\views\views.py", line 430, in case_render_pdf_view
    pdf = pdfkit.from_string(html, False)
  File "D:\Users\ntabyldieva\Desktop\databases_v1\env\lib\site-packages\pdfkit\api.py", line 72, in from_string
    return r.to_pdf(output_path)
  File "D:\Users\ntabyldieva\Desktop\databases_v1\env\lib\site-packages\pdfkit\pdfkit.py", line 156, in to_pdf
    raise IOError('wkhtmltopdf reported an error:\n' + stderr)
OSError: wkhtmltopdf reported an error:
Loading pages (1/6)
[>                                                           ] 0%[======>                                                     ] 10%[===================>                                        ] 33%Error: Failed to load https://cdn.jsdelivr.net/npm/bootstrap@5.0.2/dist/css/bootstrap.min.css, with network status code 1 and http status code 0 - Connection refused
[============================================================] 100%Counting pages (2/6)                                               
[============================================================] Object 1 of 1Resolving links (4/6)                                                       
[============================================================] Object 1 of 1Loading headers and footers (5/6)                                           
Printing pages (6/6)
[>                                                           ] Preparing[==============================>                             ] Page 1 of 2[============================================================] Page 2 of 2Done                                                                      
Exit with code 1 due to network error: ConnectionRefusedError

ERROR django.server "GET /work/get-pdf/6/ HTTP/1.1" 500 110392 2021-12-01 16:28:28,929
ERROR django.request Internal Server Error: /work/get-pdf/7/ 2021-12-01 16:28:40,980
Traceback (most recent call last):
  File "D:\Users\ntabyldieva\Desktop\databases_v1\env\lib\site-packages\django\core\handlers\exception.py", line 47, in inner
    response = get_response(request)
  File "D:\Users\ntabyldieva\Desktop\databases_v1\env\lib\site-packages\django\core\handlers\base.py", line 181, in _get_response
    response = wrapped_callback(request, *callback_args, **callback_kwargs)
  File "D:\Users\ntabyldieva\Desktop\databases_v1\work\views\views.py", line 430, in case_render_pdf_view
    pdf = pdfkit.from_string(html, False)
  File "D:\Users\ntabyldieva\Desktop\databases_v1\env\lib\site-packages\pdfkit\api.py", line 72, in from_string
    return r.to_pdf(output_path)
  File "D:\Users\ntabyldieva\Desktop\databases_v1\env\lib\site-packages\pdfkit\pdfkit.py", line 156, in to_pdf
    raise IOError('wkhtmltopdf reported an error:\n' + stderr)
OSError: wkhtmltopdf reported an error:
Loading pages (1/6)
[>                                                           ] 0%[======>                                                     ] 10%[===================>                                        ] 33%Error: Failed to load https://cdn.jsdelivr.net/npm/bootstrap@5.0.2/dist/css/bootstrap.min.css, with network status code 1 and http status code 0 - Connection refused
[============================================================] 100%Counting pages (2/6)                                               
[============================================================] Object 1 of 1Resolving links (4/6)                                                       
[============================================================] Object 1 of 1Loading headers and footers (5/6)                                           
Printing pages (6/6)
[>                                                           ] Preparing[==============================>                             ] Page 1 of 2[============================================================] Page 2 of 2Done                                                                      
Exit with code 1 due to network error: ConnectionRefusedError

ERROR django.server "GET /work/get-pdf/7/ HTTP/1.1" 500 110365 2021-12-01 16:28:40,984
ERROR django.request Internal Server Error: /work/get-pdf/7/ 2021-12-01 16:28:46,890
Traceback (most recent call last):
  File "D:\Users\ntabyldieva\Desktop\databases_v1\env\lib\site-packages\django\core\handlers\exception.py", line 47, in inner
    response = get_response(request)
  File "D:\Users\ntabyldieva\Desktop\databases_v1\env\lib\site-packages\django\core\handlers\base.py", line 181, in _get_response
    response = wrapped_callback(request, *callback_args, **callback_kwargs)
  File "D:\Users\ntabyldieva\Desktop\databases_v1\work\views\views.py", line 430, in case_render_pdf_view
    pdf = pdfkit.from_string(html, False)
  File "D:\Users\ntabyldieva\Desktop\databases_v1\env\lib\site-packages\pdfkit\api.py", line 72, in from_string
    return r.to_pdf(output_path)
  File "D:\Users\ntabyldieva\Desktop\databases_v1\env\lib\site-packages\pdfkit\pdfkit.py", line 156, in to_pdf
    raise IOError('wkhtmltopdf reported an error:\n' + stderr)
OSError: wkhtmltopdf reported an error:
Loading pages (1/6)
[>                                                           ] 0%[======>                                                     ] 10%[===================>                                        ] 33%Error: Failed to load https://cdn.jsdelivr.net/npm/bootstrap@5.0.2/dist/css/bootstrap.min.css, with network status code 1 and http status code 0 - Connection refused
[============================================================] 100%Counting pages (2/6)                                               
[============================================================] Object 1 of 1Resolving links (4/6)                                                       
[============================================================] Object 1 of 1Loading headers and footers (5/6)                                           
Printing pages (6/6)
[>                                                           ] Preparing[==============================>                             ] Page 1 of 2[============================================================] Page 2 of 2Done                                                                      
Exit with code 1 due to network error: ConnectionRefusedError

ERROR django.server "GET /work/get-pdf/7/ HTTP/1.1" 500 110365 2021-12-01 16:28:46,897
ERROR django.request Internal Server Error: /work/get-pdf/50/ 2021-12-01 16:29:40,359
Traceback (most recent call last):
  File "D:\Users\ntabyldieva\Desktop\databases_v1\env\lib\site-packages\django\core\handlers\exception.py", line 47, in inner
    response = get_response(request)
  File "D:\Users\ntabyldieva\Desktop\databases_v1\env\lib\site-packages\django\core\handlers\base.py", line 181, in _get_response
    response = wrapped_callback(request, *callback_args, **callback_kwargs)
  File "D:\Users\ntabyldieva\Desktop\databases_v1\work\views\views.py", line 430, in case_render_pdf_view
    pdf = pdfkit.from_string(html, False)
  File "D:\Users\ntabyldieva\Desktop\databases_v1\env\lib\site-packages\pdfkit\api.py", line 72, in from_string
    return r.to_pdf(output_path)
  File "D:\Users\ntabyldieva\Desktop\databases_v1\env\lib\site-packages\pdfkit\pdfkit.py", line 156, in to_pdf
    raise IOError('wkhtmltopdf reported an error:\n' + stderr)
OSError: wkhtmltopdf reported an error:
Loading pages (1/6)
[>                                                           ] 0%[======>                                                     ] 10%[===================>                                        ] 33%Error: Failed to load https://cdn.jsdelivr.net/npm/bootstrap@5.0.2/dist/css/bootstrap.min.css, with network status code 1 and http status code 0 - Connection refused
[============================================================] 100%Counting pages (2/6)                                               
[============================================================] Object 1 of 1Resolving links (4/6)                                                       
[============================================================] Object 1 of 1Loading headers and footers (5/6)                                           
Printing pages (6/6)
[>                                                           ] Preparing[==============================>                             ] Page 1 of 2[============================================================] Page 2 of 2Done                                                                      
Exit with code 1 due to network error: ConnectionRefusedError

ERROR django.server "GET /work/get-pdf/50/ HTTP/1.1" 500 110773 2021-12-01 16:29:40,365
WARNING django.request Not Found: /analytyc/detail/2 2021-12-01 16:35:37,357
WARNING django.server "GET /analytyc/detail/2 HTTP/1.1" 404 3542 2021-12-01 16:35:37,358
WARNING django.request Not Found: /analytyc/detail/8 2021-12-01 16:36:05,243
WARNING django.server "GET /analytyc/detail/8 HTTP/1.1" 404 3542 2021-12-01 16:36:05,244
