ERROR django.request Internal Server Error: /migrant/data/get/ 2021-09-28 12:24:34,070
Traceback (most recent call last):
  File "D:\Users\ntabyldieva\databases_v1\env\lib\site-packages\django\core\handlers\exception.py", line 47, in inner
    response = get_response(request)
  File "D:\Users\ntabyldieva\databases_v1\env\lib\site-packages\django\core\handlers\base.py", line 181, in _get_response
    response = wrapped_callback(request, *callback_args, **callback_kwargs)
  File "D:\Users\ntabyldieva\databases_v1\env\lib\site-packages\django\views\decorators\csrf.py", line 54, in wrapped_view
    return view_func(*args, **kwargs)
  File "D:\Users\ntabyldieva\databases_v1\env\lib\site-packages\django\views\generic\base.py", line 70, in view
    return self.dispatch(request, *args, **kwargs)
  File "D:\Users\ntabyldieva\databases_v1\env\lib\site-packages\rest_framework\views.py", line 509, in dispatch
    response = self.handle_exception(exc)
  File "D:\Users\ntabyldieva\databases_v1\env\lib\site-packages\rest_framework\views.py", line 469, in handle_exception
    self.raise_uncaught_exception(exc)
  File "D:\Users\ntabyldieva\databases_v1\env\lib\site-packages\rest_framework\views.py", line 480, in raise_uncaught_exception
    raise exc
  File "D:\Users\ntabyldieva\databases_v1\env\lib\site-packages\rest_framework\views.py", line 506, in dispatch
    response = handler(request, *args, **kwargs)
  File "D:\Users\ntabyldieva\databases_v1\migrant\views.py", line 437, in post
    where_query_list.append(f"{where_sql_query} ({where_list[0]}) ")
IndexError: list index out of range
ERROR django.server "POST /migrant/data/get/ HTTP/1.1" 500 98350 2021-09-28 12:24:34,070
ERROR django.request Internal Server Error: /migrant/data/get/ 2021-09-28 13:43:26,191
Traceback (most recent call last):
  File "D:\Users\ntabyldieva\databases_v1\env\lib\site-packages\django\core\handlers\exception.py", line 47, in inner
    response = get_response(request)
  File "D:\Users\ntabyldieva\databases_v1\env\lib\site-packages\django\core\handlers\base.py", line 181, in _get_response
    response = wrapped_callback(request, *callback_args, **callback_kwargs)
  File "D:\Users\ntabyldieva\databases_v1\env\lib\site-packages\django\views\decorators\csrf.py", line 54, in wrapped_view
    return view_func(*args, **kwargs)
  File "D:\Users\ntabyldieva\databases_v1\env\lib\site-packages\django\views\generic\base.py", line 70, in view
    return self.dispatch(request, *args, **kwargs)
  File "D:\Users\ntabyldieva\databases_v1\env\lib\site-packages\rest_framework\views.py", line 509, in dispatch
    response = self.handle_exception(exc)
  File "D:\Users\ntabyldieva\databases_v1\env\lib\site-packages\rest_framework\views.py", line 469, in handle_exception
    self.raise_uncaught_exception(exc)
  File "D:\Users\ntabyldieva\databases_v1\env\lib\site-packages\rest_framework\views.py", line 480, in raise_uncaught_exception
    raise exc
  File "D:\Users\ntabyldieva\databases_v1\env\lib\site-packages\rest_framework\views.py", line 506, in dispatch
    response = handler(request, *args, **kwargs)
  File "D:\Users\ntabyldieva\databases_v1\migrant\views.py", line 437, in post
    where_query_list.append(f"{where_sql_query} ({where_list[0]}) ")
IndexError: list index out of range
ERROR django.server "POST /migrant/data/get/ HTTP/1.1" 500 98580 2021-09-28 13:43:26,191
ERROR django.request Internal Server Error: /migrant/data/get/ 2021-09-28 13:43:35,264
Traceback (most recent call last):
  File "D:\Users\ntabyldieva\databases_v1\env\lib\site-packages\django\core\handlers\exception.py", line 47, in inner
    response = get_response(request)
  File "D:\Users\ntabyldieva\databases_v1\env\lib\site-packages\django\core\handlers\base.py", line 181, in _get_response
    response = wrapped_callback(request, *callback_args, **callback_kwargs)
  File "D:\Users\ntabyldieva\databases_v1\env\lib\site-packages\django\views\decorators\csrf.py", line 54, in wrapped_view
    return view_func(*args, **kwargs)
  File "D:\Users\ntabyldieva\databases_v1\env\lib\site-packages\django\views\generic\base.py", line 70, in view
    return self.dispatch(request, *args, **kwargs)
  File "D:\Users\ntabyldieva\databases_v1\env\lib\site-packages\rest_framework\views.py", line 509, in dispatch
    response = self.handle_exception(exc)
  File "D:\Users\ntabyldieva\databases_v1\env\lib\site-packages\rest_framework\views.py", line 469, in handle_exception
    self.raise_uncaught_exception(exc)
  File "D:\Users\ntabyldieva\databases_v1\env\lib\site-packages\rest_framework\views.py", line 480, in raise_uncaught_exception
    raise exc
  File "D:\Users\ntabyldieva\databases_v1\env\lib\site-packages\rest_framework\views.py", line 506, in dispatch
    response = handler(request, *args, **kwargs)
  File "D:\Users\ntabyldieva\databases_v1\migrant\views.py", line 568, in post
    where_query_list.append(f"{where_sql_query} ({where_list[0]}) ")
IndexError: list index out of range
ERROR django.server "POST /migrant/data/get/ HTTP/1.1" 500 98582 2021-09-28 13:43:35,266
ERROR django.request Internal Server Error: /migrant/data/get/ 2021-09-28 13:43:36,304
Traceback (most recent call last):
  File "D:\Users\ntabyldieva\databases_v1\env\lib\site-packages\django\core\handlers\exception.py", line 47, in inner
    response = get_response(request)
  File "D:\Users\ntabyldieva\databases_v1\env\lib\site-packages\django\core\handlers\base.py", line 181, in _get_response
    response = wrapped_callback(request, *callback_args, **callback_kwargs)
  File "D:\Users\ntabyldieva\databases_v1\env\lib\site-packages\django\views\decorators\csrf.py", line 54, in wrapped_view
    return view_func(*args, **kwargs)
  File "D:\Users\ntabyldieva\databases_v1\env\lib\site-packages\django\views\generic\base.py", line 70, in view
    return self.dispatch(request, *args, **kwargs)
  File "D:\Users\ntabyldieva\databases_v1\env\lib\site-packages\rest_framework\views.py", line 509, in dispatch
    response = self.handle_exception(exc)
  File "D:\Users\ntabyldieva\databases_v1\env\lib\site-packages\rest_framework\views.py", line 469, in handle_exception
    self.raise_uncaught_exception(exc)
  File "D:\Users\ntabyldieva\databases_v1\env\lib\site-packages\rest_framework\views.py", line 480, in raise_uncaught_exception
    raise exc
  File "D:\Users\ntabyldieva\databases_v1\env\lib\site-packages\rest_framework\views.py", line 506, in dispatch
    response = handler(request, *args, **kwargs)
  File "D:\Users\ntabyldieva\databases_v1\migrant\views.py", line 568, in post
    where_query_list.append(f"{where_sql_query} ({where_list[0]}) ")
IndexError: list index out of range
ERROR django.server "POST /migrant/data/get/ HTTP/1.1" 500 98582 2021-09-28 13:43:36,306
ERROR django.request Internal Server Error: /migrant/data/get/ 2021-09-28 13:43:37,183
Traceback (most recent call last):
  File "D:\Users\ntabyldieva\databases_v1\env\lib\site-packages\django\core\handlers\exception.py", line 47, in inner
    response = get_response(request)
  File "D:\Users\ntabyldieva\databases_v1\env\lib\site-packages\django\core\handlers\base.py", line 181, in _get_response
    response = wrapped_callback(request, *callback_args, **callback_kwargs)
  File "D:\Users\ntabyldieva\databases_v1\env\lib\site-packages\django\views\decorators\csrf.py", line 54, in wrapped_view
    return view_func(*args, **kwargs)
  File "D:\Users\ntabyldieva\databases_v1\env\lib\site-packages\django\views\generic\base.py", line 70, in view
    return self.dispatch(request, *args, **kwargs)
  File "D:\Users\ntabyldieva\databases_v1\env\lib\site-packages\rest_framework\views.py", line 509, in dispatch
    response = self.handle_exception(exc)
  File "D:\Users\ntabyldieva\databases_v1\env\lib\site-packages\rest_framework\views.py", line 469, in handle_exception
    self.raise_uncaught_exception(exc)
  File "D:\Users\ntabyldieva\databases_v1\env\lib\site-packages\rest_framework\views.py", line 480, in raise_uncaught_exception
    raise exc
  File "D:\Users\ntabyldieva\databases_v1\env\lib\site-packages\rest_framework\views.py", line 506, in dispatch
    response = handler(request, *args, **kwargs)
  File "D:\Users\ntabyldieva\databases_v1\migrant\views.py", line 568, in post
    where_query_list.append(f"{where_sql_query} ({where_list[0]}) ")
IndexError: list index out of range
ERROR django.server "POST /migrant/data/get/ HTTP/1.1" 500 98582 2021-09-28 13:43:37,185
ERROR django.request Internal Server Error: /migrant/data/get/ 2021-09-28 13:43:37,432
Traceback (most recent call last):
  File "D:\Users\ntabyldieva\databases_v1\env\lib\site-packages\django\core\handlers\exception.py", line 47, in inner
    response = get_response(request)
  File "D:\Users\ntabyldieva\databases_v1\env\lib\site-packages\django\core\handlers\base.py", line 181, in _get_response
    response = wrapped_callback(request, *callback_args, **callback_kwargs)
  File "D:\Users\ntabyldieva\databases_v1\env\lib\site-packages\django\views\decorators\csrf.py", line 54, in wrapped_view
    return view_func(*args, **kwargs)
  File "D:\Users\ntabyldieva\databases_v1\env\lib\site-packages\django\views\generic\base.py", line 70, in view
    return self.dispatch(request, *args, **kwargs)
  File "D:\Users\ntabyldieva\databases_v1\env\lib\site-packages\rest_framework\views.py", line 509, in dispatch
    response = self.handle_exception(exc)
  File "D:\Users\ntabyldieva\databases_v1\env\lib\site-packages\rest_framework\views.py", line 469, in handle_exception
    self.raise_uncaught_exception(exc)
  File "D:\Users\ntabyldieva\databases_v1\env\lib\site-packages\rest_framework\views.py", line 480, in raise_uncaught_exception
    raise exc
  File "D:\Users\ntabyldieva\databases_v1\env\lib\site-packages\rest_framework\views.py", line 506, in dispatch
    response = handler(request, *args, **kwargs)
  File "D:\Users\ntabyldieva\databases_v1\migrant\views.py", line 568, in post
    where_query_list.append(f"{where_sql_query} ({where_list[0]}) ")
IndexError: list index out of range
ERROR django.server "POST /migrant/data/get/ HTTP/1.1" 500 98582 2021-09-28 13:43:37,433
ERROR django.request Internal Server Error: /migrant/data/get/ 2021-09-28 13:43:37,734
Traceback (most recent call last):
  File "D:\Users\ntabyldieva\databases_v1\env\lib\site-packages\django\core\handlers\exception.py", line 47, in inner
    response = get_response(request)
  File "D:\Users\ntabyldieva\databases_v1\env\lib\site-packages\django\core\handlers\base.py", line 181, in _get_response
    response = wrapped_callback(request, *callback_args, **callback_kwargs)
  File "D:\Users\ntabyldieva\databases_v1\env\lib\site-packages\django\views\decorators\csrf.py", line 54, in wrapped_view
    return view_func(*args, **kwargs)
  File "D:\Users\ntabyldieva\databases_v1\env\lib\site-packages\django\views\generic\base.py", line 70, in view
    return self.dispatch(request, *args, **kwargs)
  File "D:\Users\ntabyldieva\databases_v1\env\lib\site-packages\rest_framework\views.py", line 509, in dispatch
    response = self.handle_exception(exc)
  File "D:\Users\ntabyldieva\databases_v1\env\lib\site-packages\rest_framework\views.py", line 469, in handle_exception
    self.raise_uncaught_exception(exc)
  File "D:\Users\ntabyldieva\databases_v1\env\lib\site-packages\rest_framework\views.py", line 480, in raise_uncaught_exception
    raise exc
  File "D:\Users\ntabyldieva\databases_v1\env\lib\site-packages\rest_framework\views.py", line 506, in dispatch
    response = handler(request, *args, **kwargs)
  File "D:\Users\ntabyldieva\databases_v1\migrant\views.py", line 568, in post
    where_query_list.append(f"{where_sql_query} ({where_list[0]}) ")
IndexError: list index out of range
ERROR django.server "POST /migrant/data/get/ HTTP/1.1" 500 98582 2021-09-28 13:43:37,736
WARNING django.request Not Found: /migrant/result/ 2021-09-28 13:49:13,533
WARNING django.server "POST /migrant/result/ HTTP/1.1" 404 6899 2021-09-28 13:49:13,534
WARNING django.request Not Found: /migrant/result/ 2021-09-28 13:49:15,039
WARNING django.server "POST /migrant/result/ HTTP/1.1" 404 6899 2021-09-28 13:49:15,040
