ERROR django.request Internal Server Error: /analytic/migrant/isk/ 2021-10-04 10:58:46,041
Traceback (most recent call last):
  File "D:\Users\ntabyldieva\databases_v1\env\lib\site-packages\django\core\handlers\exception.py", line 47, in inner
    response = get_response(request)
  File "D:\Users\ntabyldieva\databases_v1\env\lib\site-packages\django\core\handlers\base.py", line 181, in _get_response
    response = wrapped_callback(request, *callback_args, **callback_kwargs)
  File "D:\Users\ntabyldieva\databases_v1\env\lib\site-packages\django\views\decorators\csrf.py", line 54, in wrapped_view
    return view_func(*args, **kwargs)
  File "D:\Users\ntabyldieva\databases_v1\env\lib\site-packages\django\views\generic\base.py", line 70, in view
    return self.dispatch(request, *args, **kwargs)
  File "D:\Users\ntabyldieva\databases_v1\env\lib\site-packages\rest_framework\views.py", line 509, in dispatch
    response = self.handle_exception(exc)
  File "D:\Users\ntabyldieva\databases_v1\env\lib\site-packages\rest_framework\views.py", line 469, in handle_exception
    self.raise_uncaught_exception(exc)
  File "D:\Users\ntabyldieva\databases_v1\env\lib\site-packages\rest_framework\views.py", line 480, in raise_uncaught_exception
    raise exc
  File "D:\Users\ntabyldieva\databases_v1\env\lib\site-packages\rest_framework\views.py", line 506, in dispatch
    response = handler(request, *args, **kwargs)
  File "D:\Users\ntabyldieva\databases_v1\statistica\views.py", line 78, in post
    cases = MigrantCase.objects.filter(Q(country=country)&
  File "D:\Users\ntabyldieva\databases_v1\env\lib\site-packages\django\db\models\manager.py", line 85, in manager_method
    return getattr(self.get_queryset(), name)(*args, **kwargs)
  File "D:\Users\ntabyldieva\databases_v1\env\lib\site-packages\django\db\models\query.py", line 941, in filter
    return self._filter_or_exclude(False, args, kwargs)
  File "D:\Users\ntabyldieva\databases_v1\env\lib\site-packages\django\db\models\query.py", line 961, in _filter_or_exclude
    clone._filter_or_exclude_inplace(negate, args, kwargs)
  File "D:\Users\ntabyldieva\databases_v1\env\lib\site-packages\django\db\models\query.py", line 968, in _filter_or_exclude_inplace
    self._query.add_q(Q(*args, **kwargs))
  File "D:\Users\ntabyldieva\databases_v1\env\lib\site-packages\django\db\models\sql\query.py", line 1391, in add_q
    clause, _ = self._add_q(q_object, self.used_aliases)
  File "D:\Users\ntabyldieva\databases_v1\env\lib\site-packages\django\db\models\sql\query.py", line 1410, in _add_q
    child_clause, needed_inner = self.build_filter(
  File "D:\Users\ntabyldieva\databases_v1\env\lib\site-packages\django\db\models\sql\query.py", line 1263, in build_filter
    return self._add_q(
  File "D:\Users\ntabyldieva\databases_v1\env\lib\site-packages\django\db\models\sql\query.py", line 1410, in _add_q
    child_clause, needed_inner = self.build_filter(
  File "D:\Users\ntabyldieva\databases_v1\env\lib\site-packages\django\db\models\sql\query.py", line 1284, in build_filter
    lookups, parts, reffed_expression = self.solve_lookup_type(arg)
  File "D:\Users\ntabyldieva\databases_v1\env\lib\site-packages\django\db\models\sql\query.py", line 1110, in solve_lookup_type
    _, field, _, lookup_parts = self.names_to_path(lookup_splitted, self.get_meta())
  File "D:\Users\ntabyldieva\databases_v1\env\lib\site-packages\django\db\models\sql\query.py", line 1537, in names_to_path
    raise FieldError("Cannot resolve keyword '%s' into field. "
django.core.exceptions.FieldError: Cannot resolve keyword 'right' into field. Choices are: actions, active, advice, banOnEntry, banOnEntryAnother, banOnEntry_id, banned_country, case_additional, case_additional_info, case_date, case_name, casecomment, casefile, casephoto, changesInSalary, changesInSalary_another, changesInSalary_id, comment, company, company_id, control_agency_name, country, country_id, date_create, date_type, date_update, decision, end_date, entrepreneur, entrepreneur_id, final, frequent_problems, government_agency_name, has_violation_in_covid, id, individualInfo, individualInfo_id, intruder, local_agency_name, personGroupInfo, personGroupInfo_id, police_agency_name, region, region_id, rights_state, rights_state_another, rights_state_id, source, source_content, source_url, start_date, story, tradeUnionCount, tradeUnionCount_id, tradeUnionSituation, tradeUnionSituation_another, tradeUnionSituation_id, user, user_id, victim, victim_id, victim_situation, victim_situation_another, victim_situation_id, victim_status, victim_status_id, violatedRightAnother, violated_right, violationType, violationType_another, violationType_id, violation_nature, violation_nature_id
ERROR django.server "POST /analytic/migrant/isk/ HTTP/1.1" 500 160960 2021-10-04 10:58:46,047
ERROR django.request Internal Server Error: /analytic/migrant/isk/ 2021-10-04 10:58:48,160
Traceback (most recent call last):
  File "D:\Users\ntabyldieva\databases_v1\env\lib\site-packages\django\core\handlers\exception.py", line 47, in inner
    response = get_response(request)
  File "D:\Users\ntabyldieva\databases_v1\env\lib\site-packages\django\core\handlers\base.py", line 181, in _get_response
    response = wrapped_callback(request, *callback_args, **callback_kwargs)
  File "D:\Users\ntabyldieva\databases_v1\env\lib\site-packages\django\views\decorators\csrf.py", line 54, in wrapped_view
    return view_func(*args, **kwargs)
  File "D:\Users\ntabyldieva\databases_v1\env\lib\site-packages\django\views\generic\base.py", line 70, in view
    return self.dispatch(request, *args, **kwargs)
  File "D:\Users\ntabyldieva\databases_v1\env\lib\site-packages\rest_framework\views.py", line 509, in dispatch
    response = self.handle_exception(exc)
  File "D:\Users\ntabyldieva\databases_v1\env\lib\site-packages\rest_framework\views.py", line 469, in handle_exception
    self.raise_uncaught_exception(exc)
  File "D:\Users\ntabyldieva\databases_v1\env\lib\site-packages\rest_framework\views.py", line 480, in raise_uncaught_exception
    raise exc
  File "D:\Users\ntabyldieva\databases_v1\env\lib\site-packages\rest_framework\views.py", line 506, in dispatch
    response = handler(request, *args, **kwargs)
  File "D:\Users\ntabyldieva\databases_v1\statistica\views.py", line 78, in post
    cases = MigrantCase.objects.filter(Q(country=country)&
  File "D:\Users\ntabyldieva\databases_v1\env\lib\site-packages\django\db\models\manager.py", line 85, in manager_method
    return getattr(self.get_queryset(), name)(*args, **kwargs)
  File "D:\Users\ntabyldieva\databases_v1\env\lib\site-packages\django\db\models\query.py", line 941, in filter
    return self._filter_or_exclude(False, args, kwargs)
  File "D:\Users\ntabyldieva\databases_v1\env\lib\site-packages\django\db\models\query.py", line 961, in _filter_or_exclude
    clone._filter_or_exclude_inplace(negate, args, kwargs)
  File "D:\Users\ntabyldieva\databases_v1\env\lib\site-packages\django\db\models\query.py", line 968, in _filter_or_exclude_inplace
    self._query.add_q(Q(*args, **kwargs))
  File "D:\Users\ntabyldieva\databases_v1\env\lib\site-packages\django\db\models\sql\query.py", line 1391, in add_q
    clause, _ = self._add_q(q_object, self.used_aliases)
  File "D:\Users\ntabyldieva\databases_v1\env\lib\site-packages\django\db\models\sql\query.py", line 1410, in _add_q
    child_clause, needed_inner = self.build_filter(
  File "D:\Users\ntabyldieva\databases_v1\env\lib\site-packages\django\db\models\sql\query.py", line 1263, in build_filter
    return self._add_q(
  File "D:\Users\ntabyldieva\databases_v1\env\lib\site-packages\django\db\models\sql\query.py", line 1410, in _add_q
    child_clause, needed_inner = self.build_filter(
  File "D:\Users\ntabyldieva\databases_v1\env\lib\site-packages\django\db\models\sql\query.py", line 1284, in build_filter
    lookups, parts, reffed_expression = self.solve_lookup_type(arg)
  File "D:\Users\ntabyldieva\databases_v1\env\lib\site-packages\django\db\models\sql\query.py", line 1110, in solve_lookup_type
    _, field, _, lookup_parts = self.names_to_path(lookup_splitted, self.get_meta())
  File "D:\Users\ntabyldieva\databases_v1\env\lib\site-packages\django\db\models\sql\query.py", line 1537, in names_to_path
    raise FieldError("Cannot resolve keyword '%s' into field. "
django.core.exceptions.FieldError: Cannot resolve keyword 'right' into field. Choices are: actions, active, advice, banOnEntry, banOnEntryAnother, banOnEntry_id, banned_country, case_additional, case_additional_info, case_date, case_name, casecomment, casefile, casephoto, changesInSalary, changesInSalary_another, changesInSalary_id, comment, company, company_id, control_agency_name, country, country_id, date_create, date_type, date_update, decision, end_date, entrepreneur, entrepreneur_id, final, frequent_problems, government_agency_name, has_violation_in_covid, id, individualInfo, individualInfo_id, intruder, local_agency_name, personGroupInfo, personGroupInfo_id, police_agency_name, region, region_id, rights_state, rights_state_another, rights_state_id, source, source_content, source_url, start_date, story, tradeUnionCount, tradeUnionCount_id, tradeUnionSituation, tradeUnionSituation_another, tradeUnionSituation_id, user, user_id, victim, victim_id, victim_situation, victim_situation_another, victim_situation_id, victim_status, victim_status_id, violatedRightAnother, violated_right, violationType, violationType_another, violationType_id, violation_nature, violation_nature_id
ERROR django.server "POST /analytic/migrant/isk/ HTTP/1.1" 500 160960 2021-10-04 10:58:48,163
ERROR django.request Internal Server Error: /analytic/migrant/isk/ 2021-10-04 10:59:22,957
Traceback (most recent call last):
  File "D:\Users\ntabyldieva\databases_v1\env\lib\site-packages\django\core\handlers\exception.py", line 47, in inner
    response = get_response(request)
  File "D:\Users\ntabyldieva\databases_v1\env\lib\site-packages\django\core\handlers\base.py", line 181, in _get_response
    response = wrapped_callback(request, *callback_args, **callback_kwargs)
  File "D:\Users\ntabyldieva\databases_v1\env\lib\site-packages\django\views\decorators\csrf.py", line 54, in wrapped_view
    return view_func(*args, **kwargs)
  File "D:\Users\ntabyldieva\databases_v1\env\lib\site-packages\django\views\generic\base.py", line 70, in view
    return self.dispatch(request, *args, **kwargs)
  File "D:\Users\ntabyldieva\databases_v1\env\lib\site-packages\rest_framework\views.py", line 509, in dispatch
    response = self.handle_exception(exc)
  File "D:\Users\ntabyldieva\databases_v1\env\lib\site-packages\rest_framework\views.py", line 469, in handle_exception
    self.raise_uncaught_exception(exc)
  File "D:\Users\ntabyldieva\databases_v1\env\lib\site-packages\rest_framework\views.py", line 480, in raise_uncaught_exception
    raise exc
  File "D:\Users\ntabyldieva\databases_v1\env\lib\site-packages\rest_framework\views.py", line 506, in dispatch
    response = handler(request, *args, **kwargs)
  File "D:\Users\ntabyldieva\databases_v1\statistica\views.py", line 78, in post
    cases = MigrantCase.objects.filter(Q(country=country)&
  File "D:\Users\ntabyldieva\databases_v1\env\lib\site-packages\django\db\models\manager.py", line 85, in manager_method
    return getattr(self.get_queryset(), name)(*args, **kwargs)
  File "D:\Users\ntabyldieva\databases_v1\env\lib\site-packages\django\db\models\query.py", line 941, in filter
    return self._filter_or_exclude(False, args, kwargs)
  File "D:\Users\ntabyldieva\databases_v1\env\lib\site-packages\django\db\models\query.py", line 961, in _filter_or_exclude
    clone._filter_or_exclude_inplace(negate, args, kwargs)
  File "D:\Users\ntabyldieva\databases_v1\env\lib\site-packages\django\db\models\query.py", line 968, in _filter_or_exclude_inplace
    self._query.add_q(Q(*args, **kwargs))
  File "D:\Users\ntabyldieva\databases_v1\env\lib\site-packages\django\db\models\sql\query.py", line 1391, in add_q
    clause, _ = self._add_q(q_object, self.used_aliases)
  File "D:\Users\ntabyldieva\databases_v1\env\lib\site-packages\django\db\models\sql\query.py", line 1410, in _add_q
    child_clause, needed_inner = self.build_filter(
  File "D:\Users\ntabyldieva\databases_v1\env\lib\site-packages\django\db\models\sql\query.py", line 1263, in build_filter
    return self._add_q(
  File "D:\Users\ntabyldieva\databases_v1\env\lib\site-packages\django\db\models\sql\query.py", line 1410, in _add_q
    child_clause, needed_inner = self.build_filter(
  File "D:\Users\ntabyldieva\databases_v1\env\lib\site-packages\django\db\models\sql\query.py", line 1284, in build_filter
    lookups, parts, reffed_expression = self.solve_lookup_type(arg)
  File "D:\Users\ntabyldieva\databases_v1\env\lib\site-packages\django\db\models\sql\query.py", line 1110, in solve_lookup_type
    _, field, _, lookup_parts = self.names_to_path(lookup_splitted, self.get_meta())
  File "D:\Users\ntabyldieva\databases_v1\env\lib\site-packages\django\db\models\sql\query.py", line 1537, in names_to_path
    raise FieldError("Cannot resolve keyword '%s' into field. "
django.core.exceptions.FieldError: Cannot resolve keyword 'right' into field. Choices are: actions, active, advice, banOnEntry, banOnEntryAnother, banOnEntry_id, banned_country, case_additional, case_additional_info, case_date, case_name, casecomment, casefile, casephoto, changesInSalary, changesInSalary_another, changesInSalary_id, comment, company, company_id, control_agency_name, country, country_id, date_create, date_type, date_update, decision, end_date, entrepreneur, entrepreneur_id, final, frequent_problems, government_agency_name, has_violation_in_covid, id, individualInfo, individualInfo_id, intruder, local_agency_name, personGroupInfo, personGroupInfo_id, police_agency_name, region, region_id, rights_state, rights_state_another, rights_state_id, source, source_content, source_url, start_date, story, tradeUnionCount, tradeUnionCount_id, tradeUnionSituation, tradeUnionSituation_another, tradeUnionSituation_id, user, user_id, victim, victim_id, victim_situation, victim_situation_another, victim_situation_id, victim_status, victim_status_id, violatedRightAnother, violated_right, violationType, violationType_another, violationType_id, violation_nature, violation_nature_id
ERROR django.server "POST /analytic/migrant/isk/ HTTP/1.1" 500 160960 2021-10-04 10:59:22,961
ERROR django.request Internal Server Error: /analytic/migrant/isk/ 2021-10-04 10:59:24,596
Traceback (most recent call last):
  File "D:\Users\ntabyldieva\databases_v1\env\lib\site-packages\django\core\handlers\exception.py", line 47, in inner
    response = get_response(request)
  File "D:\Users\ntabyldieva\databases_v1\env\lib\site-packages\django\core\handlers\base.py", line 181, in _get_response
    response = wrapped_callback(request, *callback_args, **callback_kwargs)
  File "D:\Users\ntabyldieva\databases_v1\env\lib\site-packages\django\views\decorators\csrf.py", line 54, in wrapped_view
    return view_func(*args, **kwargs)
  File "D:\Users\ntabyldieva\databases_v1\env\lib\site-packages\django\views\generic\base.py", line 70, in view
    return self.dispatch(request, *args, **kwargs)
  File "D:\Users\ntabyldieva\databases_v1\env\lib\site-packages\rest_framework\views.py", line 509, in dispatch
    response = self.handle_exception(exc)
  File "D:\Users\ntabyldieva\databases_v1\env\lib\site-packages\rest_framework\views.py", line 469, in handle_exception
    self.raise_uncaught_exception(exc)
  File "D:\Users\ntabyldieva\databases_v1\env\lib\site-packages\rest_framework\views.py", line 480, in raise_uncaught_exception
    raise exc
  File "D:\Users\ntabyldieva\databases_v1\env\lib\site-packages\rest_framework\views.py", line 506, in dispatch
    response = handler(request, *args, **kwargs)
  File "D:\Users\ntabyldieva\databases_v1\statistica\views.py", line 78, in post
    cases = MigrantCase.objects.filter(Q(country=country)&
  File "D:\Users\ntabyldieva\databases_v1\env\lib\site-packages\django\db\models\manager.py", line 85, in manager_method
    return getattr(self.get_queryset(), name)(*args, **kwargs)
  File "D:\Users\ntabyldieva\databases_v1\env\lib\site-packages\django\db\models\query.py", line 941, in filter
    return self._filter_or_exclude(False, args, kwargs)
  File "D:\Users\ntabyldieva\databases_v1\env\lib\site-packages\django\db\models\query.py", line 961, in _filter_or_exclude
    clone._filter_or_exclude_inplace(negate, args, kwargs)
  File "D:\Users\ntabyldieva\databases_v1\env\lib\site-packages\django\db\models\query.py", line 968, in _filter_or_exclude_inplace
    self._query.add_q(Q(*args, **kwargs))
  File "D:\Users\ntabyldieva\databases_v1\env\lib\site-packages\django\db\models\sql\query.py", line 1391, in add_q
    clause, _ = self._add_q(q_object, self.used_aliases)
  File "D:\Users\ntabyldieva\databases_v1\env\lib\site-packages\django\db\models\sql\query.py", line 1410, in _add_q
    child_clause, needed_inner = self.build_filter(
  File "D:\Users\ntabyldieva\databases_v1\env\lib\site-packages\django\db\models\sql\query.py", line 1263, in build_filter
    return self._add_q(
  File "D:\Users\ntabyldieva\databases_v1\env\lib\site-packages\django\db\models\sql\query.py", line 1410, in _add_q
    child_clause, needed_inner = self.build_filter(
  File "D:\Users\ntabyldieva\databases_v1\env\lib\site-packages\django\db\models\sql\query.py", line 1284, in build_filter
    lookups, parts, reffed_expression = self.solve_lookup_type(arg)
  File "D:\Users\ntabyldieva\databases_v1\env\lib\site-packages\django\db\models\sql\query.py", line 1110, in solve_lookup_type
    _, field, _, lookup_parts = self.names_to_path(lookup_splitted, self.get_meta())
  File "D:\Users\ntabyldieva\databases_v1\env\lib\site-packages\django\db\models\sql\query.py", line 1537, in names_to_path
    raise FieldError("Cannot resolve keyword '%s' into field. "
django.core.exceptions.FieldError: Cannot resolve keyword 'right' into field. Choices are: actions, active, advice, banOnEntry, banOnEntryAnother, banOnEntry_id, banned_country, case_additional, case_additional_info, case_date, case_name, casecomment, casefile, casephoto, changesInSalary, changesInSalary_another, changesInSalary_id, comment, company, company_id, control_agency_name, country, country_id, date_create, date_type, date_update, decision, end_date, entrepreneur, entrepreneur_id, final, frequent_problems, government_agency_name, has_violation_in_covid, id, individualInfo, individualInfo_id, intruder, local_agency_name, personGroupInfo, personGroupInfo_id, police_agency_name, region, region_id, rights_state, rights_state_another, rights_state_id, source, source_content, source_url, start_date, story, tradeUnionCount, tradeUnionCount_id, tradeUnionSituation, tradeUnionSituation_another, tradeUnionSituation_id, user, user_id, victim, victim_id, victim_situation, victim_situation_another, victim_situation_id, victim_status, victim_status_id, violatedRightAnother, violated_right, violationType, violationType_another, violationType_id, violation_nature, violation_nature_id
ERROR django.server "POST /analytic/migrant/isk/ HTTP/1.1" 500 160960 2021-10-04 10:59:24,599
WARNING django.request Bad Request: /analytic/migrant/isk/ 2021-10-04 11:08:44,106
WARNING django.server "POST /analytic/migrant/isk/ HTTP/1.1" 400 108 2021-10-04 11:08:44,106
WARNING django.request Bad Request: /analytic/migrant/isk/ 2021-10-04 11:08:45,283
WARNING django.server "POST /analytic/migrant/isk/ HTTP/1.1" 400 108 2021-10-04 11:08:45,283
ERROR django.request Internal Server Error: /analytic/migrant/isk/ 2021-10-04 12:08:23,904
Traceback (most recent call last):
  File "D:\Users\ntabyldieva\databases_v1\env\lib\site-packages\django\core\handlers\exception.py", line 47, in inner
    response = get_response(request)
  File "D:\Users\ntabyldieva\databases_v1\env\lib\site-packages\django\core\handlers\base.py", line 181, in _get_response
    response = wrapped_callback(request, *callback_args, **callback_kwargs)
  File "D:\Users\ntabyldieva\databases_v1\env\lib\site-packages\django\views\decorators\csrf.py", line 54, in wrapped_view
    return view_func(*args, **kwargs)
  File "D:\Users\ntabyldieva\databases_v1\env\lib\site-packages\django\views\generic\base.py", line 70, in view
    return self.dispatch(request, *args, **kwargs)
  File "D:\Users\ntabyldieva\databases_v1\env\lib\site-packages\rest_framework\views.py", line 509, in dispatch
    response = self.handle_exception(exc)
  File "D:\Users\ntabyldieva\databases_v1\env\lib\site-packages\rest_framework\views.py", line 469, in handle_exception
    self.raise_uncaught_exception(exc)
  File "D:\Users\ntabyldieva\databases_v1\env\lib\site-packages\rest_framework\views.py", line 480, in raise_uncaught_exception
    raise exc
  File "D:\Users\ntabyldieva\databases_v1\env\lib\site-packages\rest_framework\views.py", line 506, in dispatch
    response = handler(request, *args, **kwargs)
  File "D:\Users\ntabyldieva\databases_v1\statistica\views.py", line 80, in post
    cases = MigrantCase.objects.filter(Q(country=country)&
  File "D:\Users\ntabyldieva\databases_v1\env\lib\site-packages\django\db\models\query_utils.py", line 91, in __and__
    return self._combine(other, self.AND)
  File "D:\Users\ntabyldieva\databases_v1\env\lib\site-packages\django\db\models\query_utils.py", line 72, in _combine
    if not(isinstance(other, Q) or getattr(other, 'conditional', False) is True):
  File "D:\Users\ntabyldieva\databases_v1\env\lib\site-packages\django\db\models\expressions.py", line 256, in conditional
    return isinstance(self.output_field, fields.BooleanField)
  File "D:\Users\ntabyldieva\databases_v1\env\lib\site-packages\django\utils\functional.py", line 48, in __get__
    res = instance.__dict__[self.name] = self.func(instance)
  File "D:\Users\ntabyldieva\databases_v1\env\lib\site-packages\django\db\models\expressions.py", line 268, in output_field
    raise FieldError('Cannot resolve expression type, unknown output_field')
django.core.exceptions.FieldError: Cannot resolve expression type, unknown output_field
ERROR django.server "POST /analytic/migrant/isk/ HTTP/1.1" 500 114141 2021-10-04 12:08:23,908
ERROR django.request Internal Server Error: /analytic/migrant/isk/ 2021-10-04 12:12:07,072
Traceback (most recent call last):
  File "D:\Users\ntabyldieva\databases_v1\env\lib\site-packages\django\core\handlers\exception.py", line 47, in inner
    response = get_response(request)
  File "D:\Users\ntabyldieva\databases_v1\env\lib\site-packages\django\core\handlers\base.py", line 181, in _get_response
    response = wrapped_callback(request, *callback_args, **callback_kwargs)
  File "D:\Users\ntabyldieva\databases_v1\env\lib\site-packages\django\views\decorators\csrf.py", line 54, in wrapped_view
    return view_func(*args, **kwargs)
  File "D:\Users\ntabyldieva\databases_v1\env\lib\site-packages\django\views\generic\base.py", line 70, in view
    return self.dispatch(request, *args, **kwargs)
  File "D:\Users\ntabyldieva\databases_v1\env\lib\site-packages\rest_framework\views.py", line 509, in dispatch
    response = self.handle_exception(exc)
  File "D:\Users\ntabyldieva\databases_v1\env\lib\site-packages\rest_framework\views.py", line 469, in handle_exception
    self.raise_uncaught_exception(exc)
  File "D:\Users\ntabyldieva\databases_v1\env\lib\site-packages\rest_framework\views.py", line 480, in raise_uncaught_exception
    raise exc
  File "D:\Users\ntabyldieva\databases_v1\env\lib\site-packages\rest_framework\views.py", line 506, in dispatch
    response = handler(request, *args, **kwargs)
  File "D:\Users\ntabyldieva\databases_v1\statistica\views.py", line 80, in post
    cases = MigrantCase.objects.filter(Q(country=country)&
  File "D:\Users\ntabyldieva\databases_v1\env\lib\site-packages\django\db\models\query_utils.py", line 91, in __and__
    return self._combine(other, self.AND)
  File "D:\Users\ntabyldieva\databases_v1\env\lib\site-packages\django\db\models\query_utils.py", line 72, in _combine
    if not(isinstance(other, Q) or getattr(other, 'conditional', False) is True):
  File "D:\Users\ntabyldieva\databases_v1\env\lib\site-packages\django\db\models\expressions.py", line 256, in conditional
    return isinstance(self.output_field, fields.BooleanField)
  File "D:\Users\ntabyldieva\databases_v1\env\lib\site-packages\django\utils\functional.py", line 48, in __get__
    res = instance.__dict__[self.name] = self.func(instance)
  File "D:\Users\ntabyldieva\databases_v1\env\lib\site-packages\django\db\models\expressions.py", line 268, in output_field
    raise FieldError('Cannot resolve expression type, unknown output_field')
django.core.exceptions.FieldError: Cannot resolve expression type, unknown output_field
ERROR django.server "POST /analytic/migrant/isk/ HTTP/1.1" 500 114142 2021-10-04 12:12:07,075
WARNING django.request Bad Request: /analytic/migrant/isk/ 2021-10-04 12:25:55,121
WARNING django.server "POST /analytic/migrant/isk/ HTTP/1.1" 400 110 2021-10-04 12:25:55,122
WARNING django.request Bad Request: /analytic/migrant/isk/ 2021-10-04 12:25:56,185
WARNING django.server "POST /analytic/migrant/isk/ HTTP/1.1" 400 110 2021-10-04 12:25:56,186
WARNING django.request Bad Request: /analytic/migrant/isk/ 2021-10-04 12:28:15,176
WARNING django.server "POST /analytic/migrant/isk/ HTTP/1.1" 400 110 2021-10-04 12:28:15,177
WARNING django.request Bad Request: /analytic/migrant/isk/ 2021-10-04 12:28:16,079
WARNING django.server "POST /analytic/migrant/isk/ HTTP/1.1" 400 110 2021-10-04 12:28:16,080
ERROR django.request Internal Server Error: /analytic/migrant/isk/ 2021-10-04 12:28:52,755
Traceback (most recent call last):
  File "D:\Users\ntabyldieva\databases_v1\env\lib\site-packages\django\core\handlers\exception.py", line 47, in inner
    response = get_response(request)
  File "D:\Users\ntabyldieva\databases_v1\env\lib\site-packages\django\core\handlers\base.py", line 181, in _get_response
    response = wrapped_callback(request, *callback_args, **callback_kwargs)
  File "D:\Users\ntabyldieva\databases_v1\env\lib\site-packages\django\views\decorators\csrf.py", line 54, in wrapped_view
    return view_func(*args, **kwargs)
  File "D:\Users\ntabyldieva\databases_v1\env\lib\site-packages\django\views\generic\base.py", line 70, in view
    return self.dispatch(request, *args, **kwargs)
  File "D:\Users\ntabyldieva\databases_v1\env\lib\site-packages\rest_framework\views.py", line 509, in dispatch
    response = self.handle_exception(exc)
  File "D:\Users\ntabyldieva\databases_v1\env\lib\site-packages\rest_framework\views.py", line 469, in handle_exception
    self.raise_uncaught_exception(exc)
  File "D:\Users\ntabyldieva\databases_v1\env\lib\site-packages\rest_framework\views.py", line 480, in raise_uncaught_exception
    raise exc
  File "D:\Users\ntabyldieva\databases_v1\env\lib\site-packages\rest_framework\views.py", line 506, in dispatch
    response = handler(request, *args, **kwargs)
  File "D:\Users\ntabyldieva\databases_v1\statistica\views.py", line 81, in post
    cases = MigrantCase.objects.filter(Q(country=country)& (True|Q(region=region)))
TypeError: unsupported operand type(s) for |: 'bool' and 'Q'
ERROR django.server "POST /analytic/migrant/isk/ HTTP/1.1" 500 94495 2021-10-04 12:28:52,758
ERROR django.request Internal Server Error: /analytic/migrant/isk/ 2021-10-04 12:28:53,485
Traceback (most recent call last):
  File "D:\Users\ntabyldieva\databases_v1\env\lib\site-packages\django\core\handlers\exception.py", line 47, in inner
    response = get_response(request)
  File "D:\Users\ntabyldieva\databases_v1\env\lib\site-packages\django\core\handlers\base.py", line 181, in _get_response
    response = wrapped_callback(request, *callback_args, **callback_kwargs)
  File "D:\Users\ntabyldieva\databases_v1\env\lib\site-packages\django\views\decorators\csrf.py", line 54, in wrapped_view
    return view_func(*args, **kwargs)
  File "D:\Users\ntabyldieva\databases_v1\env\lib\site-packages\django\views\generic\base.py", line 70, in view
    return self.dispatch(request, *args, **kwargs)
  File "D:\Users\ntabyldieva\databases_v1\env\lib\site-packages\rest_framework\views.py", line 509, in dispatch
    response = self.handle_exception(exc)
  File "D:\Users\ntabyldieva\databases_v1\env\lib\site-packages\rest_framework\views.py", line 469, in handle_exception
    self.raise_uncaught_exception(exc)
  File "D:\Users\ntabyldieva\databases_v1\env\lib\site-packages\rest_framework\views.py", line 480, in raise_uncaught_exception
    raise exc
  File "D:\Users\ntabyldieva\databases_v1\env\lib\site-packages\rest_framework\views.py", line 506, in dispatch
    response = handler(request, *args, **kwargs)
  File "D:\Users\ntabyldieva\databases_v1\statistica\views.py", line 81, in post
    cases = MigrantCase.objects.filter(Q(country=country)& (True|Q(region=region)))
TypeError: unsupported operand type(s) for |: 'bool' and 'Q'
ERROR django.server "POST /analytic/migrant/isk/ HTTP/1.1" 500 94495 2021-10-04 12:28:53,486
ERROR django.request Internal Server Error: /analytic/migrant/isk/ 2021-10-04 12:28:54,117
Traceback (most recent call last):
  File "D:\Users\ntabyldieva\databases_v1\env\lib\site-packages\django\core\handlers\exception.py", line 47, in inner
    response = get_response(request)
  File "D:\Users\ntabyldieva\databases_v1\env\lib\site-packages\django\core\handlers\base.py", line 181, in _get_response
    response = wrapped_callback(request, *callback_args, **callback_kwargs)
  File "D:\Users\ntabyldieva\databases_v1\env\lib\site-packages\django\views\decorators\csrf.py", line 54, in wrapped_view
    return view_func(*args, **kwargs)
  File "D:\Users\ntabyldieva\databases_v1\env\lib\site-packages\django\views\generic\base.py", line 70, in view
    return self.dispatch(request, *args, **kwargs)
  File "D:\Users\ntabyldieva\databases_v1\env\lib\site-packages\rest_framework\views.py", line 509, in dispatch
    response = self.handle_exception(exc)
  File "D:\Users\ntabyldieva\databases_v1\env\lib\site-packages\rest_framework\views.py", line 469, in handle_exception
    self.raise_uncaught_exception(exc)
  File "D:\Users\ntabyldieva\databases_v1\env\lib\site-packages\rest_framework\views.py", line 480, in raise_uncaught_exception
    raise exc
  File "D:\Users\ntabyldieva\databases_v1\env\lib\site-packages\rest_framework\views.py", line 506, in dispatch
    response = handler(request, *args, **kwargs)
  File "D:\Users\ntabyldieva\databases_v1\statistica\views.py", line 81, in post
    cases = MigrantCase.objects.filter(Q(country=country)& (True|Q(region=region)))
TypeError: unsupported operand type(s) for |: 'bool' and 'Q'
ERROR django.server "POST /analytic/migrant/isk/ HTTP/1.1" 500 94495 2021-10-04 12:28:54,120
ERROR django.request Internal Server Error: /analytic/migrant/isk/ 2021-10-04 12:29:15,458
Traceback (most recent call last):
  File "D:\Users\ntabyldieva\databases_v1\env\lib\site-packages\django\core\handlers\exception.py", line 47, in inner
    response = get_response(request)
  File "D:\Users\ntabyldieva\databases_v1\env\lib\site-packages\django\core\handlers\base.py", line 181, in _get_response
    response = wrapped_callback(request, *callback_args, **callback_kwargs)
  File "D:\Users\ntabyldieva\databases_v1\env\lib\site-packages\django\views\decorators\csrf.py", line 54, in wrapped_view
    return view_func(*args, **kwargs)
  File "D:\Users\ntabyldieva\databases_v1\env\lib\site-packages\django\views\generic\base.py", line 70, in view
    return self.dispatch(request, *args, **kwargs)
  File "D:\Users\ntabyldieva\databases_v1\env\lib\site-packages\rest_framework\views.py", line 509, in dispatch
    response = self.handle_exception(exc)
  File "D:\Users\ntabyldieva\databases_v1\env\lib\site-packages\rest_framework\views.py", line 469, in handle_exception
    self.raise_uncaught_exception(exc)
  File "D:\Users\ntabyldieva\databases_v1\env\lib\site-packages\rest_framework\views.py", line 480, in raise_uncaught_exception
    raise exc
  File "D:\Users\ntabyldieva\databases_v1\env\lib\site-packages\rest_framework\views.py", line 506, in dispatch
    response = handler(request, *args, **kwargs)
  File "D:\Users\ntabyldieva\databases_v1\statistica\views.py", line 81, in post
    cases = MigrantCase.objects.filter(Q(country=country)& (1|Q(region=region)))
TypeError: unsupported operand type(s) for |: 'int' and 'Q'
ERROR django.server "POST /analytic/migrant/isk/ HTTP/1.1" 500 94483 2021-10-04 12:29:15,460
ERROR django.request Internal Server Error: /analytic/migrant/isk/ 2021-10-04 12:29:16,246
Traceback (most recent call last):
  File "D:\Users\ntabyldieva\databases_v1\env\lib\site-packages\django\core\handlers\exception.py", line 47, in inner
    response = get_response(request)
  File "D:\Users\ntabyldieva\databases_v1\env\lib\site-packages\django\core\handlers\base.py", line 181, in _get_response
    response = wrapped_callback(request, *callback_args, **callback_kwargs)
  File "D:\Users\ntabyldieva\databases_v1\env\lib\site-packages\django\views\decorators\csrf.py", line 54, in wrapped_view
    return view_func(*args, **kwargs)
  File "D:\Users\ntabyldieva\databases_v1\env\lib\site-packages\django\views\generic\base.py", line 70, in view
    return self.dispatch(request, *args, **kwargs)
  File "D:\Users\ntabyldieva\databases_v1\env\lib\site-packages\rest_framework\views.py", line 509, in dispatch
    response = self.handle_exception(exc)
  File "D:\Users\ntabyldieva\databases_v1\env\lib\site-packages\rest_framework\views.py", line 469, in handle_exception
    self.raise_uncaught_exception(exc)
  File "D:\Users\ntabyldieva\databases_v1\env\lib\site-packages\rest_framework\views.py", line 480, in raise_uncaught_exception
    raise exc
  File "D:\Users\ntabyldieva\databases_v1\env\lib\site-packages\rest_framework\views.py", line 506, in dispatch
    response = handler(request, *args, **kwargs)
  File "D:\Users\ntabyldieva\databases_v1\statistica\views.py", line 81, in post
    cases = MigrantCase.objects.filter(Q(country=country)& (1|Q(region=region)))
TypeError: unsupported operand type(s) for |: 'int' and 'Q'
ERROR django.server "POST /analytic/migrant/isk/ HTTP/1.1" 500 94483 2021-10-04 12:29:16,248
WARNING django.request Bad Request: /analytic/migrant/search/ 2021-10-04 13:36:55,544
WARNING django.server "POST /analytic/migrant/search/ HTTP/1.1" 400 107 2021-10-04 13:36:55,544
ERROR django.request Internal Server Error: /analytic/strike/search/ 2021-10-04 13:46:38,574
Traceback (most recent call last):
  File "D:\Users\ntabyldieva\databases_v1\env\lib\site-packages\django\core\handlers\exception.py", line 47, in inner
    response = get_response(request)
  File "D:\Users\ntabyldieva\databases_v1\env\lib\site-packages\django\core\handlers\base.py", line 181, in _get_response
    response = wrapped_callback(request, *callback_args, **callback_kwargs)
  File "D:\Users\ntabyldieva\databases_v1\env\lib\site-packages\django\views\decorators\csrf.py", line 54, in wrapped_view
    return view_func(*args, **kwargs)
  File "D:\Users\ntabyldieva\databases_v1\env\lib\site-packages\django\views\generic\base.py", line 70, in view
    return self.dispatch(request, *args, **kwargs)
  File "D:\Users\ntabyldieva\databases_v1\env\lib\site-packages\rest_framework\views.py", line 509, in dispatch
    response = self.handle_exception(exc)
  File "D:\Users\ntabyldieva\databases_v1\env\lib\site-packages\rest_framework\views.py", line 469, in handle_exception
    self.raise_uncaught_exception(exc)
  File "D:\Users\ntabyldieva\databases_v1\env\lib\site-packages\rest_framework\views.py", line 480, in raise_uncaught_exception
    raise exc
  File "D:\Users\ntabyldieva\databases_v1\env\lib\site-packages\rest_framework\views.py", line 506, in dispatch
    response = handler(request, *args, **kwargs)
  File "D:\Users\ntabyldieva\databases_v1\statistica\views.py", line 89, in post
    return Response({serializer.data})
TypeError: unhashable type: 'ReturnList'
ERROR django.server "POST /analytic/strike/search/ HTTP/1.1" 500 97644 2021-10-04 13:46:38,577
ERROR django.request Internal Server Error: /analytic/strike/search/ 2021-10-04 13:46:39,889
Traceback (most recent call last):
  File "D:\Users\ntabyldieva\databases_v1\env\lib\site-packages\django\core\handlers\exception.py", line 47, in inner
    response = get_response(request)
  File "D:\Users\ntabyldieva\databases_v1\env\lib\site-packages\django\core\handlers\base.py", line 181, in _get_response
    response = wrapped_callback(request, *callback_args, **callback_kwargs)
  File "D:\Users\ntabyldieva\databases_v1\env\lib\site-packages\django\views\decorators\csrf.py", line 54, in wrapped_view
    return view_func(*args, **kwargs)
  File "D:\Users\ntabyldieva\databases_v1\env\lib\site-packages\django\views\generic\base.py", line 70, in view
    return self.dispatch(request, *args, **kwargs)
  File "D:\Users\ntabyldieva\databases_v1\env\lib\site-packages\rest_framework\views.py", line 509, in dispatch
    response = self.handle_exception(exc)
  File "D:\Users\ntabyldieva\databases_v1\env\lib\site-packages\rest_framework\views.py", line 469, in handle_exception
    self.raise_uncaught_exception(exc)
  File "D:\Users\ntabyldieva\databases_v1\env\lib\site-packages\rest_framework\views.py", line 480, in raise_uncaught_exception
    raise exc
  File "D:\Users\ntabyldieva\databases_v1\env\lib\site-packages\rest_framework\views.py", line 506, in dispatch
    response = handler(request, *args, **kwargs)
  File "D:\Users\ntabyldieva\databases_v1\statistica\views.py", line 89, in post
    return Response({serializer.data})
TypeError: unhashable type: 'ReturnList'
ERROR django.server "POST /analytic/strike/search/ HTTP/1.1" 500 97644 2021-10-04 13:46:39,890
