ERROR django.request Internal Server Error: /migrant/delete-comments/1 2021-08-13 14:59:16,793
Traceback (most recent call last):
  File "C:\Users\user\OneDrive\Desktop\Projects\databases_v1\venv\lib\site-packages\django\core\handlers\exception.py", line 47, in inner
    response = get_response(request)
  File "C:\Users\user\OneDrive\Desktop\Projects\databases_v1\venv\lib\site-packages\django\core\handlers\base.py", line 181, in _get_response
    response = wrapped_callback(request, *callback_args, **callback_kwargs)
  File "C:\Users\user\OneDrive\Desktop\Projects\databases_v1\databases_v1\migrant\views.py", line 238, in delete_comment
    case_comment.save()
AttributeError: 'tuple' object has no attribute 'save'
ERROR django.server "GET /migrant/delete-comments/1 HTTP/1.1" 500 68685 2021-08-13 14:59:16,794
ERROR django.request Internal Server Error: /migrant/delete-comments/1 2021-08-13 15:01:28,792
Traceback (most recent call last):
  File "C:\Users\user\OneDrive\Desktop\Projects\databases_v1\venv\lib\site-packages\django\core\handlers\exception.py", line 47, in inner
    response = get_response(request)
  File "C:\Users\user\OneDrive\Desktop\Projects\databases_v1\venv\lib\site-packages\django\core\handlers\base.py", line 181, in _get_response
    response = wrapped_callback(request, *callback_args, **callback_kwargs)
  File "C:\Users\user\OneDrive\Desktop\Projects\databases_v1\databases_v1\migrant\views.py", line 237, in delete_comment
    case_comment = CaseComment.objects.get(id=pk).delete()
  File "C:\Users\user\OneDrive\Desktop\Projects\databases_v1\venv\lib\site-packages\django\db\models\manager.py", line 85, in manager_method
    return getattr(self.get_queryset(), name)(*args, **kwargs)
  File "C:\Users\user\OneDrive\Desktop\Projects\databases_v1\venv\lib\site-packages\django\db\models\query.py", line 435, in get
    raise self.model.DoesNotExist(
migrant.models.CaseComment.DoesNotExist: CaseComment matching query does not exist.
ERROR django.server "GET /migrant/delete-comments/1 HTTP/1.1" 500 77598 2021-08-13 15:01:28,794
WARNING django.request Not Found: /favicon.ico 2021-08-13 15:01:28,915
WARNING django.server "GET /favicon.ico HTTP/1.1" 404 3696 2021-08-13 15:01:28,915
ERROR django.request Internal Server Error: /migrant/delete-comments/2 2021-08-13 15:01:48,724
Traceback (most recent call last):
  File "C:\Users\user\OneDrive\Desktop\Projects\databases_v1\venv\lib\site-packages\django\core\handlers\exception.py", line 47, in inner
    response = get_response(request)
  File "C:\Users\user\OneDrive\Desktop\Projects\databases_v1\venv\lib\site-packages\django\core\handlers\base.py", line 181, in _get_response
    response = wrapped_callback(request, *callback_args, **callback_kwargs)
  File "C:\Users\user\OneDrive\Desktop\Projects\databases_v1\databases_v1\migrant\views.py", line 238, in delete_comment
    return redirect('migrant_case_show_comments', case_comment.case_id)
AttributeError: 'tuple' object has no attribute 'case_id'
ERROR django.server "GET /migrant/delete-comments/2 HTTP/1.1" 500 68783 2021-08-13 15:01:48,725
WARNING django.request Not Found: /work/add/ohjj 2021-08-13 15:09:39,461
WARNING django.server "GET /work/add/ohjj HTTP/1.1" 404 6562 2021-08-13 15:09:39,462
ERROR django.request Internal Server Error: /migrant/update/1 2021-08-13 15:15:07,886
Traceback (most recent call last):
  File "C:\Users\user\OneDrive\Desktop\Projects\databases_v1\venv\lib\site-packages\django\core\handlers\exception.py", line 47, in inner
    response = get_response(request)
  File "C:\Users\user\OneDrive\Desktop\Projects\databases_v1\venv\lib\site-packages\django\core\handlers\base.py", line 181, in _get_response
    response = wrapped_callback(request, *callback_args, **callback_kwargs)
  File "C:\Users\user\OneDrive\Desktop\Projects\databases_v1\venv\lib\site-packages\django\contrib\auth\decorators.py", line 21, in _wrapped_view
    return view_func(request, *args, **kwargs)
  File "C:\Users\user\OneDrive\Desktop\Projects\databases_v1\databases_v1\migrant\views.py", line 132, in update_case
    form.save_m2m()
AttributeError: 'CaseForm' object has no attribute 'save_m2m'
ERROR django.server "POST /migrant/update/1 HTTP/1.1" 500 90772 2021-08-13 15:15:07,888
ERROR django.request Internal Server Error: /migrant/update/1 2021-08-13 15:16:14,641
Traceback (most recent call last):
  File "C:\Users\user\OneDrive\Desktop\Projects\databases_v1\venv\lib\site-packages\django\core\handlers\exception.py", line 47, in inner
    response = get_response(request)
  File "C:\Users\user\OneDrive\Desktop\Projects\databases_v1\venv\lib\site-packages\django\core\handlers\base.py", line 181, in _get_response
    response = wrapped_callback(request, *callback_args, **callback_kwargs)
  File "C:\Users\user\OneDrive\Desktop\Projects\databases_v1\venv\lib\site-packages\django\contrib\auth\decorators.py", line 21, in _wrapped_view
    return view_func(request, *args, **kwargs)
  File "C:\Users\user\OneDrive\Desktop\Projects\databases_v1\databases_v1\migrant\views.py", line 132, in update_case
    form.save_m2m()
AttributeError: 'CaseForm' object has no attribute 'save_m2m'
ERROR django.server "POST /migrant/update/1 HTTP/1.1" 500 90900 2021-08-13 15:16:14,643
WARNING django.request Not Found: /favicon.ico 2021-08-13 15:16:14,756
WARNING django.server "GET /favicon.ico HTTP/1.1" 404 3696 2021-08-13 15:16:14,757
WARNING django.request Not Found: /favicon.ico 2021-08-13 15:16:30,049
WARNING django.server "GET /favicon.ico HTTP/1.1" 404 3696 2021-08-13 15:16:30,050
ERROR django.request Internal Server Error: /Z8XxfX6A92QrcZ6GSUtDJNgkn 2021-08-13 15:19:48,530
Traceback (most recent call last):
  File "C:\Users\user\OneDrive\Desktop\Projects\databases_v1\databases_v1\main\views.py", line 16, in create_super_user
    manager.get(id=1)
  File "C:\Users\user\OneDrive\Desktop\Projects\databases_v1\venv\lib\site-packages\django\db\models\manager.py", line 85, in manager_method
    return getattr(self.get_queryset(), name)(*args, **kwargs)
  File "C:\Users\user\OneDrive\Desktop\Projects\databases_v1\venv\lib\site-packages\django\db\models\query.py", line 435, in get
    raise self.model.DoesNotExist(
django.contrib.auth.models.User.DoesNotExist: User matching query does not exist.

During handling of the above exception, another exception occurred:

Traceback (most recent call last):
  File "C:\Users\user\OneDrive\Desktop\Projects\databases_v1\venv\lib\site-packages\django\core\handlers\exception.py", line 47, in inner
    response = get_response(request)
  File "C:\Users\user\OneDrive\Desktop\Projects\databases_v1\venv\lib\site-packages\django\core\handlers\base.py", line 181, in _get_response
    response = wrapped_callback(request, *callback_args, **callback_kwargs)
  File "C:\Users\user\OneDrive\Desktop\Projects\databases_v1\databases_v1\main\views.py", line 21, in create_super_user
    user.position.role_id = 1
  File "C:\Users\user\OneDrive\Desktop\Projects\databases_v1\venv\lib\site-packages\django\db\models\fields\related_descriptors.py", line 421, in __get__
    raise self.RelatedObjectDoesNotExist(
django.contrib.auth.models.User.position.RelatedObjectDoesNotExist: User has no position.
ERROR django.server "GET /Z8XxfX6A92QrcZ6GSUtDJNgkn HTTP/1.1" 500 86943 2021-08-13 15:19:48,532
WARNING django.request Not Found: /favicon.ico 2021-08-13 15:20:10,257
WARNING django.server "GET /favicon.ico HTTP/1.1" 404 3696 2021-08-13 15:20:10,257
ERROR django.request Internal Server Error: /analytic/ 2021-08-13 15:20:30,220
Traceback (most recent call last):
  File "C:\Users\user\OneDrive\Desktop\Projects\databases_v1\venv\lib\site-packages\django\core\handlers\exception.py", line 47, in inner
    response = get_response(request)
  File "C:\Users\user\OneDrive\Desktop\Projects\databases_v1\venv\lib\site-packages\django\core\handlers\base.py", line 181, in _get_response
    response = wrapped_callback(request, *callback_args, **callback_kwargs)
  File "C:\Users\user\OneDrive\Desktop\Projects\databases_v1\venv\lib\site-packages\django\contrib\auth\decorators.py", line 21, in _wrapped_view
    return view_func(request, *args, **kwargs)
  File "C:\Users\user\OneDrive\Desktop\Projects\databases_v1\databases_v1\statistica\views.py", line 9, in home
    if request.user.position.role_id == 1 or request.user.position.role_id == 2:
  File "C:\Users\user\OneDrive\Desktop\Projects\databases_v1\venv\lib\site-packages\django\utils\functional.py", line 247, in inner
    return func(self._wrapped, *args)
  File "C:\Users\user\OneDrive\Desktop\Projects\databases_v1\venv\lib\site-packages\django\db\models\fields\related_descriptors.py", line 421, in __get__
    raise self.RelatedObjectDoesNotExist(
django.contrib.auth.models.User.position.RelatedObjectDoesNotExist: User has no position.
ERROR django.server "GET /analytic/ HTTP/1.1" 500 81687 2021-08-13 15:20:30,224
ERROR django.request Internal Server Error: /work/cases/ 2021-08-13 15:20:52,951
Traceback (most recent call last):
  File "C:\Users\user\OneDrive\Desktop\Projects\databases_v1\venv\lib\site-packages\django\core\handlers\exception.py", line 47, in inner
    response = get_response(request)
  File "C:\Users\user\OneDrive\Desktop\Projects\databases_v1\venv\lib\site-packages\django\core\handlers\base.py", line 181, in _get_response
    response = wrapped_callback(request, *callback_args, **callback_kwargs)
  File "C:\Users\user\OneDrive\Desktop\Projects\databases_v1\venv\lib\site-packages\django\contrib\auth\decorators.py", line 21, in _wrapped_view
    return view_func(request, *args, **kwargs)
  File "C:\Users\user\OneDrive\Desktop\Projects\databases_v1\databases_v1\work\views.py", line 284, in cases
    if request.user.position.role_id == 1:
  File "C:\Users\user\OneDrive\Desktop\Projects\databases_v1\venv\lib\site-packages\django\utils\functional.py", line 247, in inner
    return func(self._wrapped, *args)
  File "C:\Users\user\OneDrive\Desktop\Projects\databases_v1\venv\lib\site-packages\django\db\models\fields\related_descriptors.py", line 421, in __get__
    raise self.RelatedObjectDoesNotExist(
django.contrib.auth.models.User.position.RelatedObjectDoesNotExist: User has no position.
ERROR django.server "GET /work/cases/ HTTP/1.1" 500 81831 2021-08-13 15:20:52,952
