WARNING django.request Not Found: /favicon.ico 2021-08-24 09:15:39,254
WARNING django.server "GET /favicon.ico HTTP/1.1" 404 3524 2021-08-24 09:15:39,267
WARNING django.request Not Found: /favicon.ico 2021-08-24 09:17:12,006
WARNING django.server "GET /favicon.ico HTTP/1.1" 404 3524 2021-08-24 09:17:12,009
WARNING django.request Not Found: /favicon.ico 2021-08-24 13:27:20,919
WARNING django.server "GET /favicon.ico HTTP/1.1" 404 3524 2021-08-24 13:27:20,921
WARNING django.request Not Found: /favicon.ico 2021-08-24 13:28:30,611
WARNING django.server "GET /favicon.ico HTTP/1.1" 404 3524 2021-08-24 13:28:30,611
WARNING django.request Not Found: /favicon.ico 2021-08-24 13:32:01,423
WARNING django.server "GET /favicon.ico HTTP/1.1" 404 3524 2021-08-24 13:32:01,426
WARNING django.request Not Found: /favicon.ico 2021-08-24 13:35:41,138
WARNING django.server "GET /favicon.ico HTTP/1.1" 404 3524 2021-08-24 13:35:41,139
ERROR django.request Internal Server Error: /strike/get-pdf/1 2021-08-24 13:50:01,311
Traceback (most recent call last):
  File "C:\Users\user\OneDrive\Desktop\Projects\databases_v1\venv\lib\site-packages\pdfkit\configuration.py", line 21, in __init__
    with open(self.wkhtmltopdf) as f:
FileNotFoundError: [Errno 2] No such file or directory: b''

During handling of the above exception, another exception occurred:

Traceback (most recent call last):
  File "C:\Users\user\OneDrive\Desktop\Projects\databases_v1\venv\lib\site-packages\django\core\handlers\exception.py", line 47, in inner
    response = get_response(request)
  File "C:\Users\user\OneDrive\Desktop\Projects\databases_v1\venv\lib\site-packages\django\core\handlers\base.py", line 181, in _get_response
    response = wrapped_callback(request, *callback_args, **callback_kwargs)
  File "C:\Users\user\OneDrive\Desktop\Projects\databases_v1\databases_v1\strike\views.py", line 356, in case_render_pdf_view
    pdf = pdfkit.from_string(html, False)
  File "C:\Users\user\OneDrive\Desktop\Projects\databases_v1\venv\lib\site-packages\pdfkit\api.py", line 69, in from_string
    r = PDFKit(input, 'string', options=options, toc=toc, cover=cover, css=css,
  File "C:\Users\user\OneDrive\Desktop\Projects\databases_v1\venv\lib\site-packages\pdfkit\pdfkit.py", line 42, in __init__
    self.configuration = (Configuration() if configuration is None
  File "C:\Users\user\OneDrive\Desktop\Projects\databases_v1\venv\lib\site-packages\pdfkit\configuration.py", line 24, in __init__
    raise IOError('No wkhtmltopdf executable found: "%s"\n'
OSError: No wkhtmltopdf executable found: "b''"
If this file exists please check that this process can read it. Otherwise please install wkhtmltopdf - https://github.com/JazzCore/python-pdfkit/wiki/Installing-wkhtmltopdf
ERROR django.server "GET /strike/get-pdf/1 HTTP/1.1" 500 110579 2021-08-24 13:50:01,313
WARNING django.request Not Found: /favicon.ico 2021-08-24 14:08:07,812
WARNING django.server "GET /favicon.ico HTTP/1.1" 404 3524 2021-08-24 14:08:07,812
ERROR django.request Internal Server Error: /strike/update/1 2021-08-24 14:08:15,495
Traceback (most recent call last):
  File "C:\Users\user\OneDrive\Desktop\Projects\databases_v1\venv\lib\site-packages\django\core\handlers\exception.py", line 47, in inner
    response = get_response(request)
  File "C:\Users\user\OneDrive\Desktop\Projects\databases_v1\venv\lib\site-packages\django\core\handlers\base.py", line 181, in _get_response
    response = wrapped_callback(request, *callback_args, **callback_kwargs)
  File "C:\Users\user\OneDrive\Desktop\Projects\databases_v1\venv\lib\site-packages\django\contrib\auth\decorators.py", line 21, in _wrapped_view
    return view_func(request, *args, **kwargs)
  File "C:\Users\user\OneDrive\Desktop\Projects\databases_v1\databases_v1\strike\views.py", line 298, in update_case
    'individualForm': individualFormSet,
UnboundLocalError: local variable 'individualFormSet' referenced before assignment
ERROR django.server "GET /strike/update/1 HTTP/1.1" 500 77428 2021-08-24 14:08:15,498
ERROR django.request Internal Server Error: /strike/update/1 2021-08-24 14:08:25,619
Traceback (most recent call last):
  File "C:\Users\user\OneDrive\Desktop\Projects\databases_v1\venv\lib\site-packages\django\core\handlers\exception.py", line 47, in inner
    response = get_response(request)
  File "C:\Users\user\OneDrive\Desktop\Projects\databases_v1\venv\lib\site-packages\django\core\handlers\base.py", line 181, in _get_response
    response = wrapped_callback(request, *callback_args, **callback_kwargs)
  File "C:\Users\user\OneDrive\Desktop\Projects\databases_v1\venv\lib\site-packages\django\contrib\auth\decorators.py", line 21, in _wrapped_view
    return view_func(request, *args, **kwargs)
  File "C:\Users\user\OneDrive\Desktop\Projects\databases_v1\databases_v1\strike\views.py", line 298, in update_case
    'individualForm': individualForm,
NameError: name 'individualForm' is not defined
ERROR django.server "GET /strike/update/1 HTTP/1.1" 500 77403 2021-08-24 14:08:25,621
ERROR django.request Internal Server Error: /strike/update/1 2021-08-24 14:08:26,253
Traceback (most recent call last):
  File "C:\Users\user\OneDrive\Desktop\Projects\databases_v1\venv\lib\site-packages\django\core\handlers\exception.py", line 47, in inner
    response = get_response(request)
  File "C:\Users\user\OneDrive\Desktop\Projects\databases_v1\venv\lib\site-packages\django\core\handlers\base.py", line 181, in _get_response
    response = wrapped_callback(request, *callback_args, **callback_kwargs)
  File "C:\Users\user\OneDrive\Desktop\Projects\databases_v1\venv\lib\site-packages\django\contrib\auth\decorators.py", line 21, in _wrapped_view
    return view_func(request, *args, **kwargs)
  File "C:\Users\user\OneDrive\Desktop\Projects\databases_v1\databases_v1\strike\views.py", line 298, in update_case
    'individualForm': individualForm,
NameError: name 'individualForm' is not defined
ERROR django.server "GET /strike/update/1 HTTP/1.1" 500 77403 2021-08-24 14:08:26,253
ERROR django.request Internal Server Error: /strike/update/1 2021-08-24 14:08:46,525
Traceback (most recent call last):
  File "C:\Users\user\OneDrive\Desktop\Projects\databases_v1\venv\lib\site-packages\django\core\handlers\exception.py", line 47, in inner
    response = get_response(request)
  File "C:\Users\user\OneDrive\Desktop\Projects\databases_v1\venv\lib\site-packages\django\core\handlers\base.py", line 181, in _get_response
    response = wrapped_callback(request, *callback_args, **callback_kwargs)
  File "C:\Users\user\OneDrive\Desktop\Projects\databases_v1\venv\lib\site-packages\django\contrib\auth\decorators.py", line 21, in _wrapped_view
    return view_func(request, *args, **kwargs)
  File "C:\Users\user\OneDrive\Desktop\Projects\databases_v1\databases_v1\strike\views.py", line 298, in update_case
    'individualForm': individualForm,
UnboundLocalError: local variable 'individualForm' referenced before assignment
ERROR django.server "POST /strike/update/1 HTTP/1.1" 500 85312 2021-08-24 14:08:46,528
ERROR django.request Internal Server Error: /strike/update/1 2021-08-24 14:09:27,967
Traceback (most recent call last):
  File "C:\Users\user\OneDrive\Desktop\Projects\databases_v1\venv\lib\site-packages\django\core\handlers\exception.py", line 47, in inner
    response = get_response(request)
  File "C:\Users\user\OneDrive\Desktop\Projects\databases_v1\venv\lib\site-packages\django\core\handlers\base.py", line 181, in _get_response
    response = wrapped_callback(request, *callback_args, **callback_kwargs)
  File "C:\Users\user\OneDrive\Desktop\Projects\databases_v1\venv\lib\site-packages\django\contrib\auth\decorators.py", line 21, in _wrapped_view
    return view_func(request, *args, **kwargs)
  File "C:\Users\user\OneDrive\Desktop\Projects\databases_v1\databases_v1\strike\views.py", line 298, in update_case
    'individualForm': individualFormSet,
UnboundLocalError: local variable 'individualFormSet' referenced before assignment
ERROR django.server "GET /strike/update/1 HTTP/1.1" 500 77643 2021-08-24 14:09:27,969
