WARNING django.request Not Found: /favicon.ico 2021-09-08 13:14:12,115
WARNING django.server "GET /favicon.ico HTTP/1.1" 404 179 2021-09-08 13:14:12,117
WARNING django.request Not Found: /favicon.ico 2021-09-08 13:14:39,284
WARNING django.server "GET /favicon.ico HTTP/1.1" 404 179 2021-09-08 13:14:39,284
WARNING django.request Not Found: /favicon.ico 2021-09-08 13:20:23,666
WARNING django.server "GET /favicon.ico HTTP/1.1" 404 179 2021-09-08 13:20:23,667
WARNING django.request Not Found: /favicon.ico 2021-09-08 13:20:59,821
WARNING django.server "GET /favicon.ico HTTP/1.1" 404 179 2021-09-08 13:20:59,822
WARNING django.request Not Found: /favicon.ico 2021-09-08 13:21:23,403
WARNING django.server "GET /favicon.ico HTTP/1.1" 404 179 2021-09-08 13:21:23,404
WARNING django.request Not Found: /favicon.ico 2021-09-08 13:27:01,542
WARNING django.server "GET /favicon.ico HTTP/1.1" 404 179 2021-09-08 13:27:01,542
WARNING django.request Not Found: /favicon.ico 2021-09-08 13:31:46,487
WARNING django.server "GET /favicon.ico HTTP/1.1" 404 179 2021-09-08 13:31:46,487
ERROR django.request Internal Server Error: /work/dict/regions/ 2021-09-08 13:35:12,136
Traceback (most recent call last):
  File "C:\Users\user\OneDrive\Desktop\Projects\databases_v1\venv\lib\site-packages\django\db\models\fields\__init__.py", line 1823, in get_prep_value
    return int(value)
ValueError: invalid literal for int() with base 10: ''

The above exception was the direct cause of the following exception:

Traceback (most recent call last):
  File "C:\Users\user\OneDrive\Desktop\Projects\databases_v1\venv\lib\site-packages\django\core\handlers\exception.py", line 47, in inner
    response = get_response(request)
  File "C:\Users\user\OneDrive\Desktop\Projects\databases_v1\venv\lib\site-packages\django\core\handlers\base.py", line 181, in _get_response
    response = wrapped_callback(request, *callback_args, **callback_kwargs)
  File "C:\Users\user\OneDrive\Desktop\Projects\databases_v1\databases_v1\work\views.py", line 297, in load_regions
    regions = Region.objects.filter(country=country_id).all()
  File "C:\Users\user\OneDrive\Desktop\Projects\databases_v1\venv\lib\site-packages\django\db\models\manager.py", line 85, in manager_method
    return getattr(self.get_queryset(), name)(*args, **kwargs)
  File "C:\Users\user\OneDrive\Desktop\Projects\databases_v1\venv\lib\site-packages\django\db\models\query.py", line 941, in filter
    return self._filter_or_exclude(False, args, kwargs)
  File "C:\Users\user\OneDrive\Desktop\Projects\databases_v1\venv\lib\site-packages\django\db\models\query.py", line 961, in _filter_or_exclude
    clone._filter_or_exclude_inplace(negate, args, kwargs)
  File "C:\Users\user\OneDrive\Desktop\Projects\databases_v1\venv\lib\site-packages\django\db\models\query.py", line 968, in _filter_or_exclude_inplace
    self._query.add_q(Q(*args, **kwargs))
  File "C:\Users\user\OneDrive\Desktop\Projects\databases_v1\venv\lib\site-packages\django\db\models\sql\query.py", line 1391, in add_q
    clause, _ = self._add_q(q_object, self.used_aliases)
  File "C:\Users\user\OneDrive\Desktop\Projects\databases_v1\venv\lib\site-packages\django\db\models\sql\query.py", line 1410, in _add_q
    child_clause, needed_inner = self.build_filter(
  File "C:\Users\user\OneDrive\Desktop\Projects\databases_v1\venv\lib\site-packages\django\db\models\sql\query.py", line 1345, in build_filter
    condition = self.build_lookup(lookups, col, value)
  File "C:\Users\user\OneDrive\Desktop\Projects\databases_v1\venv\lib\site-packages\django\db\models\sql\query.py", line 1191, in build_lookup
    lookup = lookup_class(lhs, rhs)
  File "C:\Users\user\OneDrive\Desktop\Projects\databases_v1\venv\lib\site-packages\django\db\models\lookups.py", line 25, in __init__
    self.rhs = self.get_prep_lookup()
  File "C:\Users\user\OneDrive\Desktop\Projects\databases_v1\venv\lib\site-packages\django\db\models\fields\related_lookups.py", line 117, in get_prep_lookup
    self.rhs = target_field.get_prep_value(self.rhs)
  File "C:\Users\user\OneDrive\Desktop\Projects\databases_v1\venv\lib\site-packages\django\db\models\fields\__init__.py", line 1825, in get_prep_value
    raise e.__class__(
ValueError: Field 'id' expected a number but got ''.
ERROR django.server "GET /work/dict/regions/?country_id= HTTP/1.1" 500 145 2021-09-08 13:35:12,299
ERROR django.request Internal Server Error: /work/dict/regions/ 2021-09-08 13:35:12,300
Traceback (most recent call last):
  File "C:\Users\user\OneDrive\Desktop\Projects\databases_v1\venv\lib\site-packages\django\db\models\fields\__init__.py", line 1823, in get_prep_value
    return int(value)
ValueError: invalid literal for int() with base 10: ''

The above exception was the direct cause of the following exception:

Traceback (most recent call last):
  File "C:\Users\user\OneDrive\Desktop\Projects\databases_v1\venv\lib\site-packages\django\core\handlers\exception.py", line 47, in inner
    response = get_response(request)
  File "C:\Users\user\OneDrive\Desktop\Projects\databases_v1\venv\lib\site-packages\django\core\handlers\base.py", line 181, in _get_response
    response = wrapped_callback(request, *callback_args, **callback_kwargs)
  File "C:\Users\user\OneDrive\Desktop\Projects\databases_v1\databases_v1\work\views.py", line 297, in load_regions
    regions = Region.objects.filter(country=country_id).all()
  File "C:\Users\user\OneDrive\Desktop\Projects\databases_v1\venv\lib\site-packages\django\db\models\manager.py", line 85, in manager_method
    return getattr(self.get_queryset(), name)(*args, **kwargs)
  File "C:\Users\user\OneDrive\Desktop\Projects\databases_v1\venv\lib\site-packages\django\db\models\query.py", line 941, in filter
    return self._filter_or_exclude(False, args, kwargs)
  File "C:\Users\user\OneDrive\Desktop\Projects\databases_v1\venv\lib\site-packages\django\db\models\query.py", line 961, in _filter_or_exclude
    clone._filter_or_exclude_inplace(negate, args, kwargs)
  File "C:\Users\user\OneDrive\Desktop\Projects\databases_v1\venv\lib\site-packages\django\db\models\query.py", line 968, in _filter_or_exclude_inplace
    self._query.add_q(Q(*args, **kwargs))
  File "C:\Users\user\OneDrive\Desktop\Projects\databases_v1\venv\lib\site-packages\django\db\models\sql\query.py", line 1391, in add_q
    clause, _ = self._add_q(q_object, self.used_aliases)
  File "C:\Users\user\OneDrive\Desktop\Projects\databases_v1\venv\lib\site-packages\django\db\models\sql\query.py", line 1410, in _add_q
    child_clause, needed_inner = self.build_filter(
  File "C:\Users\user\OneDrive\Desktop\Projects\databases_v1\venv\lib\site-packages\django\db\models\sql\query.py", line 1345, in build_filter
    condition = self.build_lookup(lookups, col, value)
  File "C:\Users\user\OneDrive\Desktop\Projects\databases_v1\venv\lib\site-packages\django\db\models\sql\query.py", line 1191, in build_lookup
    lookup = lookup_class(lhs, rhs)
  File "C:\Users\user\OneDrive\Desktop\Projects\databases_v1\venv\lib\site-packages\django\db\models\lookups.py", line 25, in __init__
    self.rhs = self.get_prep_lookup()
  File "C:\Users\user\OneDrive\Desktop\Projects\databases_v1\venv\lib\site-packages\django\db\models\fields\related_lookups.py", line 117, in get_prep_lookup
    self.rhs = target_field.get_prep_value(self.rhs)
  File "C:\Users\user\OneDrive\Desktop\Projects\databases_v1\venv\lib\site-packages\django\db\models\fields\__init__.py", line 1825, in get_prep_value
    raise e.__class__(
ValueError: Field 'id' expected a number but got ''.
ERROR django.server "GET /work/dict/regions/?country_id= HTTP/1.1" 500 145 2021-09-08 13:35:12,318
WARNING django.request Not Found: /favicon.ico 2021-09-08 13:36:13,448
WARNING django.server "GET /favicon.ico HTTP/1.1" 404 179 2021-09-08 13:36:13,448
WARNING django.request Not Found: /favicon.ico 2021-09-08 13:36:54,241
WARNING django.server "GET /favicon.ico HTTP/1.1" 404 179 2021-09-08 13:36:54,243
WARNING django.request Not Found: /favicon.ico 2021-09-08 13:37:12,373
WARNING django.server "GET /favicon.ico HTTP/1.1" 404 179 2021-09-08 13:37:12,374
WARNING django.request Not Found: /favicon.ico 2021-09-08 13:48:22,816
WARNING django.server "GET /favicon.ico HTTP/1.1" 404 179 2021-09-08 13:48:22,817
WARNING django.request Not Found: /favicon.ico 2021-09-08 13:49:25,622
WARNING django.server "GET /favicon.ico HTTP/1.1" 404 179 2021-09-08 13:49:25,623
WARNING django.request Not Found: /favicon.ico 2021-09-08 13:49:54,862
WARNING django.server "GET /favicon.ico HTTP/1.1" 404 179 2021-09-08 13:49:54,863
WARNING django.request Not Found: /favicon.ico 2021-09-08 13:50:12,621
WARNING django.server "GET /favicon.ico HTTP/1.1" 404 179 2021-09-08 13:50:12,622
WARNING django.request Not Found: /favicon.ico 2021-09-08 13:54:51,289
WARNING django.server "GET /favicon.ico HTTP/1.1" 404 179 2021-09-08 13:54:51,290
WARNING django.request Not Found: /favicon.ico 2021-09-08 14:02:56,941
WARNING django.server "GET /favicon.ico HTTP/1.1" 404 179 2021-09-08 14:02:56,941
