WARNING django.request Not Found: /favicon.ico 2021-10-18 15:52:54,358
WARNING django.server "GET /favicon.ico HTTP/1.1" 404 3524 2021-10-18 15:52:54,359
WARNING django.request Not Found: /favicon.ico 2021-10-18 15:52:55,643
WARNING django.server "GET /favicon.ico HTTP/1.1" 404 3524 2021-10-18 15:52:55,644
WARNING django.request Not Found: /favicon.ico 2021-10-18 15:54:29,500
WARNING django.server "GET /favicon.ico HTTP/1.1" 404 3524 2021-10-18 15:54:29,501
WARNING django.request Not Found: /favicon.ico 2021-10-18 15:54:29,865
WARNING django.server "GET /favicon.ico HTTP/1.1" 404 3524 2021-10-18 15:54:29,866
WARNING django.request Not Found: /favicon.ico 2021-10-18 15:54:30,244
WARNING django.server "GET /favicon.ico HTTP/1.1" 404 3524 2021-10-18 15:54:30,245
ERROR django.request Internal Server Error: /work/test-data/get/ 2021-10-18 15:56:21,040
Traceback (most recent call last):
  File "D:\Users\ntabyldieva\databases_v1\venv\lib\site-packages\django\core\handlers\exception.py", line 47, in inner
    response = get_response(request)
  File "D:\Users\ntabyldieva\databases_v1\venv\lib\site-packages\django\core\handlers\base.py", line 181, in _get_response
    response = wrapped_callback(request, *callback_args, **callback_kwargs)
  File "D:\Users\ntabyldieva\databases_v1\venv\lib\site-packages\django\views\decorators\csrf.py", line 54, in wrapped_view
    return view_func(*args, **kwargs)
  File "D:\Users\ntabyldieva\databases_v1\venv\lib\site-packages\django\views\generic\base.py", line 70, in view
    return self.dispatch(request, *args, **kwargs)
  File "D:\Users\ntabyldieva\databases_v1\venv\lib\site-packages\rest_framework\views.py", line 509, in dispatch
    response = self.handle_exception(exc)
  File "D:\Users\ntabyldieva\databases_v1\venv\lib\site-packages\rest_framework\views.py", line 469, in handle_exception
    self.raise_uncaught_exception(exc)
  File "D:\Users\ntabyldieva\databases_v1\venv\lib\site-packages\rest_framework\views.py", line 480, in raise_uncaught_exception
    raise exc
  File "D:\Users\ntabyldieva\databases_v1\venv\lib\site-packages\rest_framework\views.py", line 506, in dispatch
    response = handler(request, *args, **kwargs)
  File "D:\Users\ntabyldieva\databases_v1\work\data_filter_api.py", line 59, in post
    queryset = Case.objects.filter(**dicts).values(*fields).annotate(count=Count('id'), procent=100 / Count('id'))
NameError: name 'Count' is not defined
ERROR django.server "POST /work/test-data/get/ HTTP/1.1" 500 94038 2021-10-18 15:56:21,042
ERROR django.request Internal Server Error: /work/test-data/get/ 2021-10-18 15:56:22,189
Traceback (most recent call last):
  File "D:\Users\ntabyldieva\databases_v1\venv\lib\site-packages\django\core\handlers\exception.py", line 47, in inner
    response = get_response(request)
  File "D:\Users\ntabyldieva\databases_v1\venv\lib\site-packages\django\core\handlers\base.py", line 181, in _get_response
    response = wrapped_callback(request, *callback_args, **callback_kwargs)
  File "D:\Users\ntabyldieva\databases_v1\venv\lib\site-packages\django\views\decorators\csrf.py", line 54, in wrapped_view
    return view_func(*args, **kwargs)
  File "D:\Users\ntabyldieva\databases_v1\venv\lib\site-packages\django\views\generic\base.py", line 70, in view
    return self.dispatch(request, *args, **kwargs)
  File "D:\Users\ntabyldieva\databases_v1\venv\lib\site-packages\rest_framework\views.py", line 509, in dispatch
    response = self.handle_exception(exc)
  File "D:\Users\ntabyldieva\databases_v1\venv\lib\site-packages\rest_framework\views.py", line 469, in handle_exception
    self.raise_uncaught_exception(exc)
  File "D:\Users\ntabyldieva\databases_v1\venv\lib\site-packages\rest_framework\views.py", line 480, in raise_uncaught_exception
    raise exc
  File "D:\Users\ntabyldieva\databases_v1\venv\lib\site-packages\rest_framework\views.py", line 506, in dispatch
    response = handler(request, *args, **kwargs)
  File "D:\Users\ntabyldieva\databases_v1\work\data_filter_api.py", line 59, in post
    queryset = Case.objects.filter(**dicts).values(*fields).annotate(count=Count('id'), procent=100 / Count('id'))
NameError: name 'Count' is not defined
ERROR django.server "POST /work/test-data/get/ HTTP/1.1" 500 94038 2021-10-18 15:56:22,191
ERROR django.request Internal Server Error: /work/test-data/get/ 2021-10-18 15:56:32,774
Traceback (most recent call last):
  File "D:\Users\ntabyldieva\databases_v1\venv\lib\site-packages\django\core\handlers\exception.py", line 47, in inner
    response = get_response(request)
  File "D:\Users\ntabyldieva\databases_v1\venv\lib\site-packages\django\core\handlers\base.py", line 181, in _get_response
    response = wrapped_callback(request, *callback_args, **callback_kwargs)
  File "D:\Users\ntabyldieva\databases_v1\venv\lib\site-packages\django\views\decorators\csrf.py", line 54, in wrapped_view
    return view_func(*args, **kwargs)
  File "D:\Users\ntabyldieva\databases_v1\venv\lib\site-packages\django\views\generic\base.py", line 70, in view
    return self.dispatch(request, *args, **kwargs)
  File "D:\Users\ntabyldieva\databases_v1\venv\lib\site-packages\rest_framework\views.py", line 509, in dispatch
    response = self.handle_exception(exc)
  File "D:\Users\ntabyldieva\databases_v1\venv\lib\site-packages\rest_framework\views.py", line 469, in handle_exception
    self.raise_uncaught_exception(exc)
  File "D:\Users\ntabyldieva\databases_v1\venv\lib\site-packages\rest_framework\views.py", line 480, in raise_uncaught_exception
    raise exc
  File "D:\Users\ntabyldieva\databases_v1\venv\lib\site-packages\rest_framework\views.py", line 506, in dispatch
    response = handler(request, *args, **kwargs)
  File "D:\Users\ntabyldieva\databases_v1\work\data_filter_api.py", line 64, in post
    serializer = DataFilterApiSerializer(queryset, many=True, fields=fields)
  File "D:\Users\ntabyldieva\databases_v1\venv\lib\site-packages\rest_framework\serializers.py", line 121, in __new__
    return cls.many_init(*args, **kwargs)
  File "D:\Users\ntabyldieva\databases_v1\venv\lib\site-packages\rest_framework\serializers.py", line 146, in many_init
    child_serializer = cls(*args, **kwargs)
  File "D:\Users\ntabyldieva\databases_v1\venv\lib\site-packages\rest_framework\serializers.py", line 115, in __init__
    super().__init__(**kwargs)
TypeError: __init__() got an unexpected keyword argument 'fields'
ERROR django.server "POST /work/test-data/get/ HTTP/1.1" 500 113108 2021-10-18 15:56:32,777
ERROR django.request Internal Server Error: /work/test-data/get/ 2021-10-18 15:56:33,683
Traceback (most recent call last):
  File "D:\Users\ntabyldieva\databases_v1\venv\lib\site-packages\django\core\handlers\exception.py", line 47, in inner
    response = get_response(request)
  File "D:\Users\ntabyldieva\databases_v1\venv\lib\site-packages\django\core\handlers\base.py", line 181, in _get_response
    response = wrapped_callback(request, *callback_args, **callback_kwargs)
  File "D:\Users\ntabyldieva\databases_v1\venv\lib\site-packages\django\views\decorators\csrf.py", line 54, in wrapped_view
    return view_func(*args, **kwargs)
  File "D:\Users\ntabyldieva\databases_v1\venv\lib\site-packages\django\views\generic\base.py", line 70, in view
    return self.dispatch(request, *args, **kwargs)
  File "D:\Users\ntabyldieva\databases_v1\venv\lib\site-packages\rest_framework\views.py", line 509, in dispatch
    response = self.handle_exception(exc)
  File "D:\Users\ntabyldieva\databases_v1\venv\lib\site-packages\rest_framework\views.py", line 469, in handle_exception
    self.raise_uncaught_exception(exc)
  File "D:\Users\ntabyldieva\databases_v1\venv\lib\site-packages\rest_framework\views.py", line 480, in raise_uncaught_exception
    raise exc
  File "D:\Users\ntabyldieva\databases_v1\venv\lib\site-packages\rest_framework\views.py", line 506, in dispatch
    response = handler(request, *args, **kwargs)
  File "D:\Users\ntabyldieva\databases_v1\work\data_filter_api.py", line 64, in post
    serializer = DataFilterApiSerializer(queryset, many=True, fields=fields)
  File "D:\Users\ntabyldieva\databases_v1\venv\lib\site-packages\rest_framework\serializers.py", line 121, in __new__
    return cls.many_init(*args, **kwargs)
  File "D:\Users\ntabyldieva\databases_v1\venv\lib\site-packages\rest_framework\serializers.py", line 146, in many_init
    child_serializer = cls(*args, **kwargs)
  File "D:\Users\ntabyldieva\databases_v1\venv\lib\site-packages\rest_framework\serializers.py", line 115, in __init__
    super().__init__(**kwargs)
TypeError: __init__() got an unexpected keyword argument 'fields'
ERROR django.server "POST /work/test-data/get/ HTTP/1.1" 500 113108 2021-10-18 15:56:33,686
ERROR django.request Internal Server Error: /work/test-data/get/ 2021-10-18 15:57:14,627
Traceback (most recent call last):
  File "D:\Users\ntabyldieva\databases_v1\venv\lib\site-packages\django\core\handlers\exception.py", line 47, in inner
    response = get_response(request)
  File "D:\Users\ntabyldieva\databases_v1\venv\lib\site-packages\django\core\handlers\base.py", line 181, in _get_response
    response = wrapped_callback(request, *callback_args, **callback_kwargs)
  File "D:\Users\ntabyldieva\databases_v1\venv\lib\site-packages\django\views\decorators\csrf.py", line 54, in wrapped_view
    return view_func(*args, **kwargs)
  File "D:\Users\ntabyldieva\databases_v1\venv\lib\site-packages\django\views\generic\base.py", line 70, in view
    return self.dispatch(request, *args, **kwargs)
  File "D:\Users\ntabyldieva\databases_v1\venv\lib\site-packages\rest_framework\views.py", line 509, in dispatch
    response = self.handle_exception(exc)
  File "D:\Users\ntabyldieva\databases_v1\venv\lib\site-packages\rest_framework\views.py", line 469, in handle_exception
    self.raise_uncaught_exception(exc)
  File "D:\Users\ntabyldieva\databases_v1\venv\lib\site-packages\rest_framework\views.py", line 480, in raise_uncaught_exception
    raise exc
  File "D:\Users\ntabyldieva\databases_v1\venv\lib\site-packages\rest_framework\views.py", line 506, in dispatch
    response = handler(request, *args, **kwargs)
  File "D:\Users\ntabyldieva\databases_v1\work\data_filter_api.py", line 64, in post
    serializer = DataFilterApiSerializer(queryset, many=True, fields=fields)
  File "D:\Users\ntabyldieva\databases_v1\venv\lib\site-packages\rest_framework\serializers.py", line 121, in __new__
    return cls.many_init(*args, **kwargs)
  File "D:\Users\ntabyldieva\databases_v1\venv\lib\site-packages\rest_framework\serializers.py", line 146, in many_init
    child_serializer = cls(*args, **kwargs)
  File "D:\Users\ntabyldieva\databases_v1\work\serializers.py", line 281, in __init__
    existing = set(self.fields)
  File "D:\Users\ntabyldieva\databases_v1\venv\lib\site-packages\django\utils\functional.py", line 48, in __get__
    res = instance.__dict__[self.name] = self.func(instance)
  File "D:\Users\ntabyldieva\databases_v1\venv\lib\site-packages\rest_framework\serializers.py", line 349, in fields
    for key, value in self.get_fields().items():
  File "D:\Users\ntabyldieva\databases_v1\venv\lib\site-packages\rest_framework\serializers.py", line 1004, in get_fields
    assert hasattr(self, 'Meta'), (
AssertionError: Class DataFilterApiSerializer missing "Meta" attribute
ERROR django.server "POST /work/test-data/get/ HTTP/1.1" 500 119867 2021-10-18 15:57:14,630
ERROR django.request Internal Server Error: /work/test-data/get/ 2021-10-18 15:57:15,464
Traceback (most recent call last):
  File "D:\Users\ntabyldieva\databases_v1\venv\lib\site-packages\django\core\handlers\exception.py", line 47, in inner
    response = get_response(request)
  File "D:\Users\ntabyldieva\databases_v1\venv\lib\site-packages\django\core\handlers\base.py", line 181, in _get_response
    response = wrapped_callback(request, *callback_args, **callback_kwargs)
  File "D:\Users\ntabyldieva\databases_v1\venv\lib\site-packages\django\views\decorators\csrf.py", line 54, in wrapped_view
    return view_func(*args, **kwargs)
  File "D:\Users\ntabyldieva\databases_v1\venv\lib\site-packages\django\views\generic\base.py", line 70, in view
    return self.dispatch(request, *args, **kwargs)
  File "D:\Users\ntabyldieva\databases_v1\venv\lib\site-packages\rest_framework\views.py", line 509, in dispatch
    response = self.handle_exception(exc)
  File "D:\Users\ntabyldieva\databases_v1\venv\lib\site-packages\rest_framework\views.py", line 469, in handle_exception
    self.raise_uncaught_exception(exc)
  File "D:\Users\ntabyldieva\databases_v1\venv\lib\site-packages\rest_framework\views.py", line 480, in raise_uncaught_exception
    raise exc
  File "D:\Users\ntabyldieva\databases_v1\venv\lib\site-packages\rest_framework\views.py", line 506, in dispatch
    response = handler(request, *args, **kwargs)
  File "D:\Users\ntabyldieva\databases_v1\work\data_filter_api.py", line 64, in post
    serializer = DataFilterApiSerializer(queryset, many=True, fields=fields)
  File "D:\Users\ntabyldieva\databases_v1\venv\lib\site-packages\rest_framework\serializers.py", line 121, in __new__
    return cls.many_init(*args, **kwargs)
  File "D:\Users\ntabyldieva\databases_v1\venv\lib\site-packages\rest_framework\serializers.py", line 146, in many_init
    child_serializer = cls(*args, **kwargs)
  File "D:\Users\ntabyldieva\databases_v1\work\serializers.py", line 281, in __init__
    existing = set(self.fields)
  File "D:\Users\ntabyldieva\databases_v1\venv\lib\site-packages\django\utils\functional.py", line 48, in __get__
    res = instance.__dict__[self.name] = self.func(instance)
  File "D:\Users\ntabyldieva\databases_v1\venv\lib\site-packages\rest_framework\serializers.py", line 349, in fields
    for key, value in self.get_fields().items():
  File "D:\Users\ntabyldieva\databases_v1\venv\lib\site-packages\rest_framework\serializers.py", line 1004, in get_fields
    assert hasattr(self, 'Meta'), (
AssertionError: Class DataFilterApiSerializer missing "Meta" attribute
ERROR django.server "POST /work/test-data/get/ HTTP/1.1" 500 119867 2021-10-18 15:57:15,467
