ERROR django.request Internal Server Error: /strike/add/ 2021-11-24 11:50:35,824
Traceback (most recent call last):
  File "D:\Users\ntabyldieva\Desktop\databases_v1\env\lib\site-packages\django\db\backends\utils.py", line 84, in _execute
    return self.cursor.execute(sql, params)
psycopg2.errors.NotNullViolation: ОШИБКА:  значение NULL в столбце "card_id" отношения "strike_individual" нарушает ограничение NOT NULL
DETAIL:  Ошибочная строка содержит (1, YES, , MALE, Профессия:, 2, null).


The above exception was the direct cause of the following exception:

Traceback (most recent call last):
  File "D:\Users\ntabyldieva\Desktop\databases_v1\env\lib\site-packages\django\core\handlers\exception.py", line 47, in inner
    response = get_response(request)
  File "D:\Users\ntabyldieva\Desktop\databases_v1\env\lib\site-packages\django\core\handlers\base.py", line 181, in _get_response
    response = wrapped_callback(request, *callback_args, **callback_kwargs)
  File "D:\Users\ntabyldieva\Desktop\databases_v1\env\lib\site-packages\django\contrib\auth\decorators.py", line 21, in _wrapped_view
    return view_func(request, *args, **kwargs)
  File "D:\Users\ntabyldieva\Desktop\databases_v1\strike\views.py", line 111, in add_case
    ind.save()
  File "D:\Users\ntabyldieva\Desktop\databases_v1\env\lib\site-packages\django\db\models\base.py", line 726, in save
    self.save_base(using=using, force_insert=force_insert,
  File "D:\Users\ntabyldieva\Desktop\databases_v1\env\lib\site-packages\django\db\models\base.py", line 763, in save_base
    updated = self._save_table(
  File "D:\Users\ntabyldieva\Desktop\databases_v1\env\lib\site-packages\django\db\models\base.py", line 868, in _save_table
    results = self._do_insert(cls._base_manager, using, fields, returning_fields, raw)
  File "D:\Users\ntabyldieva\Desktop\databases_v1\env\lib\site-packages\django\db\models\base.py", line 906, in _do_insert
    return manager._insert(
  File "D:\Users\ntabyldieva\Desktop\databases_v1\env\lib\site-packages\django\db\models\manager.py", line 85, in manager_method
    return getattr(self.get_queryset(), name)(*args, **kwargs)
  File "D:\Users\ntabyldieva\Desktop\databases_v1\env\lib\site-packages\django\db\models\query.py", line 1270, in _insert
    return query.get_compiler(using=using).execute_sql(returning_fields)
  File "D:\Users\ntabyldieva\Desktop\databases_v1\env\lib\site-packages\django\db\models\sql\compiler.py", line 1416, in execute_sql
    cursor.execute(sql, params)
  File "D:\Users\ntabyldieva\Desktop\databases_v1\env\lib\site-packages\django\db\backends\utils.py", line 98, in execute
    return super().execute(sql, params)
  File "D:\Users\ntabyldieva\Desktop\databases_v1\env\lib\site-packages\django\db\backends\utils.py", line 66, in execute
    return self._execute_with_wrappers(sql, params, many=False, executor=self._execute)
  File "D:\Users\ntabyldieva\Desktop\databases_v1\env\lib\site-packages\django\db\backends\utils.py", line 75, in _execute_with_wrappers
    return executor(sql, params, many, context)
  File "D:\Users\ntabyldieva\Desktop\databases_v1\env\lib\site-packages\django\db\backends\utils.py", line 84, in _execute
    return self.cursor.execute(sql, params)
  File "D:\Users\ntabyldieva\Desktop\databases_v1\env\lib\site-packages\django\db\utils.py", line 90, in __exit__
    raise dj_exc_value.with_traceback(traceback) from exc_value
  File "D:\Users\ntabyldieva\Desktop\databases_v1\env\lib\site-packages\django\db\backends\utils.py", line 84, in _execute
    return self.cursor.execute(sql, params)
django.db.utils.IntegrityError: ОШИБКА:  значение NULL в столбце "card_id" отношения "strike_individual" нарушает ограничение NOT NULL
DETAIL:  Ошибочная строка содержит (1, YES, , MALE, Профессия:, 2, null).

ERROR django.server "POST /strike/add/ HTTP/1.1" 500 160602 2021-11-24 11:50:35,832
ERROR django.request Internal Server Error: /strike/add/ 2021-11-24 11:56:15,462
Traceback (most recent call last):
  File "D:\Users\ntabyldieva\Desktop\databases_v1\env\lib\site-packages\django\db\backends\utils.py", line 84, in _execute
    return self.cursor.execute(sql, params)
psycopg2.errors.NotNullViolation: ОШИБКА:  значение NULL в столбце "age_id" отношения "strike_individual" нарушает ограничение NOT NULL
DETAIL:  Ошибочная строка содержит (3, , , , , null, null).


The above exception was the direct cause of the following exception:

Traceback (most recent call last):
  File "D:\Users\ntabyldieva\Desktop\databases_v1\env\lib\site-packages\django\core\handlers\exception.py", line 47, in inner
    response = get_response(request)
  File "D:\Users\ntabyldieva\Desktop\databases_v1\env\lib\site-packages\django\core\handlers\base.py", line 181, in _get_response
    response = wrapped_callback(request, *callback_args, **callback_kwargs)
  File "D:\Users\ntabyldieva\Desktop\databases_v1\env\lib\site-packages\django\contrib\auth\decorators.py", line 21, in _wrapped_view
    return view_func(request, *args, **kwargs)
  File "D:\Users\ntabyldieva\Desktop\databases_v1\strike\views.py", line 113, in add_case
    ind.save()
  File "D:\Users\ntabyldieva\Desktop\databases_v1\env\lib\site-packages\django\db\models\base.py", line 726, in save
    self.save_base(using=using, force_insert=force_insert,
  File "D:\Users\ntabyldieva\Desktop\databases_v1\env\lib\site-packages\django\db\models\base.py", line 763, in save_base
    updated = self._save_table(
  File "D:\Users\ntabyldieva\Desktop\databases_v1\env\lib\site-packages\django\db\models\base.py", line 868, in _save_table
    results = self._do_insert(cls._base_manager, using, fields, returning_fields, raw)
  File "D:\Users\ntabyldieva\Desktop\databases_v1\env\lib\site-packages\django\db\models\base.py", line 906, in _do_insert
    return manager._insert(
  File "D:\Users\ntabyldieva\Desktop\databases_v1\env\lib\site-packages\django\db\models\manager.py", line 85, in manager_method
    return getattr(self.get_queryset(), name)(*args, **kwargs)
  File "D:\Users\ntabyldieva\Desktop\databases_v1\env\lib\site-packages\django\db\models\query.py", line 1270, in _insert
    return query.get_compiler(using=using).execute_sql(returning_fields)
  File "D:\Users\ntabyldieva\Desktop\databases_v1\env\lib\site-packages\django\db\models\sql\compiler.py", line 1416, in execute_sql
    cursor.execute(sql, params)
  File "D:\Users\ntabyldieva\Desktop\databases_v1\env\lib\site-packages\django\db\backends\utils.py", line 98, in execute
    return super().execute(sql, params)
  File "D:\Users\ntabyldieva\Desktop\databases_v1\env\lib\site-packages\django\db\backends\utils.py", line 66, in execute
    return self._execute_with_wrappers(sql, params, many=False, executor=self._execute)
  File "D:\Users\ntabyldieva\Desktop\databases_v1\env\lib\site-packages\django\db\backends\utils.py", line 75, in _execute_with_wrappers
    return executor(sql, params, many, context)
  File "D:\Users\ntabyldieva\Desktop\databases_v1\env\lib\site-packages\django\db\backends\utils.py", line 84, in _execute
    return self.cursor.execute(sql, params)
  File "D:\Users\ntabyldieva\Desktop\databases_v1\env\lib\site-packages\django\db\utils.py", line 90, in __exit__
    raise dj_exc_value.with_traceback(traceback) from exc_value
  File "D:\Users\ntabyldieva\Desktop\databases_v1\env\lib\site-packages\django\db\backends\utils.py", line 84, in _execute
    return self.cursor.execute(sql, params)
django.db.utils.IntegrityError: ОШИБКА:  значение NULL в столбце "age_id" отношения "strike_individual" нарушает ограничение NOT NULL
DETAIL:  Ошибочная строка содержит (3, , , , , null, null).

ERROR django.server "POST /strike/add/ HTTP/1.1" 500 160331 2021-11-24 11:56:15,470
ERROR django.request Internal Server Error: /strike/add/ 2021-11-24 12:05:46,579
Traceback (most recent call last):
  File "D:\Users\ntabyldieva\Desktop\databases_v1\env\lib\site-packages\django\core\handlers\exception.py", line 47, in inner
    response = get_response(request)
  File "D:\Users\ntabyldieva\Desktop\databases_v1\env\lib\site-packages\django\core\handlers\base.py", line 181, in _get_response
    response = wrapped_callback(request, *callback_args, **callback_kwargs)
  File "D:\Users\ntabyldieva\Desktop\databases_v1\env\lib\site-packages\django\contrib\auth\decorators.py", line 21, in _wrapped_view
    return view_func(request, *args, **kwargs)
  File "D:\Users\ntabyldieva\Desktop\databases_v1\strike\views.py", line 101, in add_case
    data0 = form_formset(request.POST)
  File "D:\Users\ntabyldieva\Desktop\databases_v1\strike\views.py", line 29, in form_formset
    for i , y in data.items():
NameError: name 'data' is not defined
ERROR django.server "POST /strike/add/ HTTP/1.1" 500 90058 2021-11-24 12:05:46,582
ERROR django.request Internal Server Error: /admin/migrant/case/12/change/ 2021-11-24 12:42:48,705
Traceback (most recent call last):
  File "D:\Users\ntabyldieva\Desktop\databases_v1\env\lib\site-packages\django\core\handlers\exception.py", line 47, in inner
    response = get_response(request)
  File "D:\Users\ntabyldieva\Desktop\databases_v1\env\lib\site-packages\django\core\handlers\base.py", line 204, in _get_response
    response = response.render()
  File "D:\Users\ntabyldieva\Desktop\databases_v1\env\lib\site-packages\django\template\response.py", line 105, in render
    self.content = self.rendered_content
  File "D:\Users\ntabyldieva\Desktop\databases_v1\env\lib\site-packages\django\template\response.py", line 83, in rendered_content
    return template.render(context, self._request)
  File "D:\Users\ntabyldieva\Desktop\databases_v1\env\lib\site-packages\django\template\backends\django.py", line 61, in render
    return self.template.render(context)
  File "D:\Users\ntabyldieva\Desktop\databases_v1\env\lib\site-packages\django\template\base.py", line 170, in render
    return self._render(context)
  File "D:\Users\ntabyldieva\Desktop\databases_v1\env\lib\site-packages\django\test\utils.py", line 100, in instrumented_test_render
    return self.nodelist.render(context)
  File "D:\Users\ntabyldieva\Desktop\databases_v1\env\lib\site-packages\django\template\base.py", line 938, in render
    bit = node.render_annotated(context)
  File "D:\Users\ntabyldieva\Desktop\databases_v1\env\lib\site-packages\django\template\base.py", line 905, in render_annotated
    return self.render(context)
  File "D:\Users\ntabyldieva\Desktop\databases_v1\env\lib\site-packages\django\template\loader_tags.py", line 150, in render
    return compiled_parent._render(context)
  File "D:\Users\ntabyldieva\Desktop\databases_v1\env\lib\site-packages\django\test\utils.py", line 100, in instrumented_test_render
    return self.nodelist.render(context)
  File "D:\Users\ntabyldieva\Desktop\databases_v1\env\lib\site-packages\django\template\base.py", line 938, in render
    bit = node.render_annotated(context)
  File "D:\Users\ntabyldieva\Desktop\databases_v1\env\lib\site-packages\django\template\base.py", line 905, in render_annotated
    return self.render(context)
  File "D:\Users\ntabyldieva\Desktop\databases_v1\env\lib\site-packages\django\template\loader_tags.py", line 150, in render
    return compiled_parent._render(context)
  File "D:\Users\ntabyldieva\Desktop\databases_v1\env\lib\site-packages\django\test\utils.py", line 100, in instrumented_test_render
    return self.nodelist.render(context)
  File "D:\Users\ntabyldieva\Desktop\databases_v1\env\lib\site-packages\django\template\base.py", line 938, in render
    bit = node.render_annotated(context)
  File "D:\Users\ntabyldieva\Desktop\databases_v1\env\lib\site-packages\django\template\base.py", line 905, in render_annotated
    return self.render(context)
  File "D:\Users\ntabyldieva\Desktop\databases_v1\env\lib\site-packages\django\template\loader_tags.py", line 62, in render
    result = block.nodelist.render(context)
  File "D:\Users\ntabyldieva\Desktop\databases_v1\env\lib\site-packages\django\template\base.py", line 938, in render
    bit = node.render_annotated(context)
  File "D:\Users\ntabyldieva\Desktop\databases_v1\env\lib\site-packages\django\template\base.py", line 905, in render_annotated
    return self.render(context)
  File "D:\Users\ntabyldieva\Desktop\databases_v1\env\lib\site-packages\django\template\loader_tags.py", line 62, in render
    result = block.nodelist.render(context)
  File "D:\Users\ntabyldieva\Desktop\databases_v1\env\lib\site-packages\django\template\base.py", line 938, in render
    bit = node.render_annotated(context)
  File "D:\Users\ntabyldieva\Desktop\databases_v1\env\lib\site-packages\django\template\base.py", line 905, in render_annotated
    return self.render(context)
  File "D:\Users\ntabyldieva\Desktop\databases_v1\env\lib\site-packages\django\template\defaulttags.py", line 211, in render
    nodelist.append(node.render_annotated(context))
  File "D:\Users\ntabyldieva\Desktop\databases_v1\env\lib\site-packages\django\template\base.py", line 905, in render_annotated
    return self.render(context)
  File "D:\Users\ntabyldieva\Desktop\databases_v1\env\lib\site-packages\django\template\loader_tags.py", line 195, in render
    return template.render(context)
  File "D:\Users\ntabyldieva\Desktop\databases_v1\env\lib\site-packages\django\template\base.py", line 172, in render
    return self._render(context)
  File "D:\Users\ntabyldieva\Desktop\databases_v1\env\lib\site-packages\django\test\utils.py", line 100, in instrumented_test_render
    return self.nodelist.render(context)
  File "D:\Users\ntabyldieva\Desktop\databases_v1\env\lib\site-packages\django\template\base.py", line 938, in render
    bit = node.render_annotated(context)
  File "D:\Users\ntabyldieva\Desktop\databases_v1\env\lib\site-packages\django\template\base.py", line 905, in render_annotated
    return self.render(context)
  File "D:\Users\ntabyldieva\Desktop\databases_v1\env\lib\site-packages\django\template\defaulttags.py", line 211, in render
    nodelist.append(node.render_annotated(context))
  File "D:\Users\ntabyldieva\Desktop\databases_v1\env\lib\site-packages\django\template\base.py", line 905, in render_annotated
    return self.render(context)
  File "D:\Users\ntabyldieva\Desktop\databases_v1\env\lib\site-packages\django\template\defaulttags.py", line 211, in render
    nodelist.append(node.render_annotated(context))
  File "D:\Users\ntabyldieva\Desktop\databases_v1\env\lib\site-packages\django\template\base.py", line 905, in render_annotated
    return self.render(context)
  File "D:\Users\ntabyldieva\Desktop\databases_v1\env\lib\site-packages\django\template\defaulttags.py", line 312, in render
    return nodelist.render(context)
  File "D:\Users\ntabyldieva\Desktop\databases_v1\env\lib\site-packages\django\template\base.py", line 938, in render
    bit = node.render_annotated(context)
  File "D:\Users\ntabyldieva\Desktop\databases_v1\env\lib\site-packages\django\template\base.py", line 905, in render_annotated
    return self.render(context)
  File "D:\Users\ntabyldieva\Desktop\databases_v1\env\lib\site-packages\django\template\defaulttags.py", line 312, in render
    return nodelist.render(context)
  File "D:\Users\ntabyldieva\Desktop\databases_v1\env\lib\site-packages\django\template\base.py", line 938, in render
    bit = node.render_annotated(context)
  File "D:\Users\ntabyldieva\Desktop\databases_v1\env\lib\site-packages\django\template\base.py", line 905, in render_annotated
    return self.render(context)
  File "D:\Users\ntabyldieva\Desktop\databases_v1\env\lib\site-packages\django\template\base.py", line 994, in render
    return render_value_in_context(output, context)
  File "D:\Users\ntabyldieva\Desktop\databases_v1\env\lib\site-packages\django\template\base.py", line 973, in render_value_in_context
    value = str(value)
  File "D:\Users\ntabyldieva\Desktop\databases_v1\env\lib\site-packages\django\utils\html.py", line 376, in <lambda>
    klass.__str__ = lambda self: mark_safe(klass_str(self))
  File "D:\Users\ntabyldieva\Desktop\databases_v1\env\lib\site-packages\django\forms\boundfield.py", line 34, in __str__
    return self.as_widget()
  File "D:\Users\ntabyldieva\Desktop\databases_v1\env\lib\site-packages\django\forms\boundfield.py", line 93, in as_widget
    return widget.render(
  File "D:\Users\ntabyldieva\Desktop\databases_v1\env\lib\site-packages\django\forms\widgets.py", line 246, in render
    context = self.get_context(name, value, attrs)
  File "D:\Users\ntabyldieva\Desktop\databases_v1\env\lib\site-packages\django\contrib\admin\widgets.py", line 283, in get_context
    'rendered_widget': self.widget.render(name, value, attrs),
  File "D:\Users\ntabyldieva\Desktop\databases_v1\env\lib\site-packages\django\forms\widgets.py", line 246, in render
    context = self.get_context(name, value, attrs)
  File "D:\Users\ntabyldieva\Desktop\databases_v1\env\lib\site-packages\django\forms\widgets.py", line 683, in get_context
    context = super().get_context(name, value, attrs)
  File "D:\Users\ntabyldieva\Desktop\databases_v1\env\lib\site-packages\django\forms\widgets.py", line 644, in get_context
    context['widget']['optgroups'] = self.optgroups(name, context['widget']['value'], attrs)
  File "D:\Users\ntabyldieva\Desktop\databases_v1\env\lib\site-packages\django\forms\widgets.py", line 592, in optgroups
    for index, (option_value, option_label) in enumerate(self.choices):
  File "D:\Users\ntabyldieva\Desktop\databases_v1\env\lib\site-packages\django\forms\models.py", line 1170, in __iter__
    yield self.choice(obj)
  File "D:\Users\ntabyldieva\Desktop\databases_v1\env\lib\site-packages\django\forms\models.py", line 1184, in choice
    self.field.label_from_instance(obj),
  File "D:\Users\ntabyldieva\Desktop\databases_v1\env\lib\site-packages\django\forms\models.py", line 1253, in label_from_instance
    return str(obj)
TypeError: __str__ returned non-string (type NoneType)
ERROR django.server "GET /admin/migrant/case/12/change/ HTTP/1.1" 500 563688 2021-11-24 12:42:48,726
ERROR django.request Internal Server Error: /admin/migrant/case/12/change/ 2021-11-24 14:10:39,140
Traceback (most recent call last):
  File "D:\Users\ntabyldieva\Desktop\databases_v1\env\lib\site-packages\django\core\handlers\exception.py", line 47, in inner
    response = get_response(request)
  File "D:\Users\ntabyldieva\Desktop\databases_v1\env\lib\site-packages\django\core\handlers\base.py", line 204, in _get_response
    response = response.render()
  File "D:\Users\ntabyldieva\Desktop\databases_v1\env\lib\site-packages\django\template\response.py", line 105, in render
    self.content = self.rendered_content
  File "D:\Users\ntabyldieva\Desktop\databases_v1\env\lib\site-packages\django\template\response.py", line 83, in rendered_content
    return template.render(context, self._request)
  File "D:\Users\ntabyldieva\Desktop\databases_v1\env\lib\site-packages\django\template\backends\django.py", line 61, in render
    return self.template.render(context)
  File "D:\Users\ntabyldieva\Desktop\databases_v1\env\lib\site-packages\django\template\base.py", line 170, in render
    return self._render(context)
  File "D:\Users\ntabyldieva\Desktop\databases_v1\env\lib\site-packages\django\test\utils.py", line 100, in instrumented_test_render
    return self.nodelist.render(context)
  File "D:\Users\ntabyldieva\Desktop\databases_v1\env\lib\site-packages\django\template\base.py", line 938, in render
    bit = node.render_annotated(context)
  File "D:\Users\ntabyldieva\Desktop\databases_v1\env\lib\site-packages\django\template\base.py", line 905, in render_annotated
    return self.render(context)
  File "D:\Users\ntabyldieva\Desktop\databases_v1\env\lib\site-packages\django\template\loader_tags.py", line 150, in render
    return compiled_parent._render(context)
  File "D:\Users\ntabyldieva\Desktop\databases_v1\env\lib\site-packages\django\test\utils.py", line 100, in instrumented_test_render
    return self.nodelist.render(context)
  File "D:\Users\ntabyldieva\Desktop\databases_v1\env\lib\site-packages\django\template\base.py", line 938, in render
    bit = node.render_annotated(context)
  File "D:\Users\ntabyldieva\Desktop\databases_v1\env\lib\site-packages\django\template\base.py", line 905, in render_annotated
    return self.render(context)
  File "D:\Users\ntabyldieva\Desktop\databases_v1\env\lib\site-packages\django\template\loader_tags.py", line 150, in render
    return compiled_parent._render(context)
  File "D:\Users\ntabyldieva\Desktop\databases_v1\env\lib\site-packages\django\test\utils.py", line 100, in instrumented_test_render
    return self.nodelist.render(context)
  File "D:\Users\ntabyldieva\Desktop\databases_v1\env\lib\site-packages\django\template\base.py", line 938, in render
    bit = node.render_annotated(context)
  File "D:\Users\ntabyldieva\Desktop\databases_v1\env\lib\site-packages\django\template\base.py", line 905, in render_annotated
    return self.render(context)
  File "D:\Users\ntabyldieva\Desktop\databases_v1\env\lib\site-packages\django\template\loader_tags.py", line 62, in render
    result = block.nodelist.render(context)
  File "D:\Users\ntabyldieva\Desktop\databases_v1\env\lib\site-packages\django\template\base.py", line 938, in render
    bit = node.render_annotated(context)
  File "D:\Users\ntabyldieva\Desktop\databases_v1\env\lib\site-packages\django\template\base.py", line 905, in render_annotated
    return self.render(context)
  File "D:\Users\ntabyldieva\Desktop\databases_v1\env\lib\site-packages\django\template\loader_tags.py", line 62, in render
    result = block.nodelist.render(context)
  File "D:\Users\ntabyldieva\Desktop\databases_v1\env\lib\site-packages\django\template\base.py", line 938, in render
    bit = node.render_annotated(context)
  File "D:\Users\ntabyldieva\Desktop\databases_v1\env\lib\site-packages\django\template\base.py", line 905, in render_annotated
    return self.render(context)
  File "D:\Users\ntabyldieva\Desktop\databases_v1\env\lib\site-packages\django\template\defaulttags.py", line 211, in render
    nodelist.append(node.render_annotated(context))
  File "D:\Users\ntabyldieva\Desktop\databases_v1\env\lib\site-packages\django\template\base.py", line 905, in render_annotated
    return self.render(context)
  File "D:\Users\ntabyldieva\Desktop\databases_v1\env\lib\site-packages\django\template\loader_tags.py", line 195, in render
    return template.render(context)
  File "D:\Users\ntabyldieva\Desktop\databases_v1\env\lib\site-packages\django\template\base.py", line 172, in render
    return self._render(context)
  File "D:\Users\ntabyldieva\Desktop\databases_v1\env\lib\site-packages\django\test\utils.py", line 100, in instrumented_test_render
    return self.nodelist.render(context)
  File "D:\Users\ntabyldieva\Desktop\databases_v1\env\lib\site-packages\django\template\base.py", line 938, in render
    bit = node.render_annotated(context)
  File "D:\Users\ntabyldieva\Desktop\databases_v1\env\lib\site-packages\django\template\base.py", line 905, in render_annotated
    return self.render(context)
  File "D:\Users\ntabyldieva\Desktop\databases_v1\env\lib\site-packages\django\template\defaulttags.py", line 211, in render
    nodelist.append(node.render_annotated(context))
  File "D:\Users\ntabyldieva\Desktop\databases_v1\env\lib\site-packages\django\template\base.py", line 905, in render_annotated
    return self.render(context)
  File "D:\Users\ntabyldieva\Desktop\databases_v1\env\lib\site-packages\django\template\defaulttags.py", line 211, in render
    nodelist.append(node.render_annotated(context))
  File "D:\Users\ntabyldieva\Desktop\databases_v1\env\lib\site-packages\django\template\base.py", line 905, in render_annotated
    return self.render(context)
  File "D:\Users\ntabyldieva\Desktop\databases_v1\env\lib\site-packages\django\template\defaulttags.py", line 312, in render
    return nodelist.render(context)
  File "D:\Users\ntabyldieva\Desktop\databases_v1\env\lib\site-packages\django\template\base.py", line 938, in render
    bit = node.render_annotated(context)
  File "D:\Users\ntabyldieva\Desktop\databases_v1\env\lib\site-packages\django\template\base.py", line 905, in render_annotated
    return self.render(context)
  File "D:\Users\ntabyldieva\Desktop\databases_v1\env\lib\site-packages\django\template\defaulttags.py", line 312, in render
    return nodelist.render(context)
  File "D:\Users\ntabyldieva\Desktop\databases_v1\env\lib\site-packages\django\template\base.py", line 938, in render
    bit = node.render_annotated(context)
  File "D:\Users\ntabyldieva\Desktop\databases_v1\env\lib\site-packages\django\template\base.py", line 905, in render_annotated
    return self.render(context)
  File "D:\Users\ntabyldieva\Desktop\databases_v1\env\lib\site-packages\django\template\base.py", line 994, in render
    return render_value_in_context(output, context)
  File "D:\Users\ntabyldieva\Desktop\databases_v1\env\lib\site-packages\django\template\base.py", line 973, in render_value_in_context
    value = str(value)
  File "D:\Users\ntabyldieva\Desktop\databases_v1\env\lib\site-packages\django\utils\html.py", line 376, in <lambda>
    klass.__str__ = lambda self: mark_safe(klass_str(self))
  File "D:\Users\ntabyldieva\Desktop\databases_v1\env\lib\site-packages\django\forms\boundfield.py", line 34, in __str__
    return self.as_widget()
  File "D:\Users\ntabyldieva\Desktop\databases_v1\env\lib\site-packages\django\forms\boundfield.py", line 93, in as_widget
    return widget.render(
  File "D:\Users\ntabyldieva\Desktop\databases_v1\env\lib\site-packages\django\forms\widgets.py", line 246, in render
    context = self.get_context(name, value, attrs)
  File "D:\Users\ntabyldieva\Desktop\databases_v1\env\lib\site-packages\django\contrib\admin\widgets.py", line 283, in get_context
    'rendered_widget': self.widget.render(name, value, attrs),
  File "D:\Users\ntabyldieva\Desktop\databases_v1\env\lib\site-packages\django\forms\widgets.py", line 246, in render
    context = self.get_context(name, value, attrs)
  File "D:\Users\ntabyldieva\Desktop\databases_v1\env\lib\site-packages\django\forms\widgets.py", line 683, in get_context
    context = super().get_context(name, value, attrs)
  File "D:\Users\ntabyldieva\Desktop\databases_v1\env\lib\site-packages\django\forms\widgets.py", line 644, in get_context
    context['widget']['optgroups'] = self.optgroups(name, context['widget']['value'], attrs)
  File "D:\Users\ntabyldieva\Desktop\databases_v1\env\lib\site-packages\django\forms\widgets.py", line 592, in optgroups
    for index, (option_value, option_label) in enumerate(self.choices):
  File "D:\Users\ntabyldieva\Desktop\databases_v1\env\lib\site-packages\django\forms\models.py", line 1170, in __iter__
    yield self.choice(obj)
  File "D:\Users\ntabyldieva\Desktop\databases_v1\env\lib\site-packages\django\forms\models.py", line 1184, in choice
    self.field.label_from_instance(obj),
  File "D:\Users\ntabyldieva\Desktop\databases_v1\env\lib\site-packages\django\forms\models.py", line 1253, in label_from_instance
    return str(obj)
TypeError: __str__ returned non-string (type NoneType)
ERROR django.server "GET /admin/migrant/case/12/change/ HTTP/1.1" 500 563688 2021-11-24 14:10:39,160
WARNING django.request Not Found: /favicon.ico 2021-11-24 14:26:05,354
WARNING django.server "GET /favicon.ico HTTP/1.1" 404 3524 2021-11-24 14:26:05,355
WARNING django.request Not Found: /favicon.ico 2021-11-24 14:26:42,247
WARNING django.server "GET /favicon.ico HTTP/1.1" 404 3524 2021-11-24 14:26:42,248
WARNING django.request Not Found: /favicon.ico 2021-11-24 14:27:29,089
WARNING django.server "GET /favicon.ico HTTP/1.1" 404 3524 2021-11-24 14:27:29,090
WARNING django.request Not Found: /favicon.ico 2021-11-24 14:27:29,760
WARNING django.server "GET /favicon.ico HTTP/1.1" 404 3524 2021-11-24 14:27:29,761
WARNING django.request Not Found: /favicon.ico 2021-11-24 14:27:30,568
WARNING django.server "GET /favicon.ico HTTP/1.1" 404 3524 2021-11-24 14:27:30,569
WARNING django.request Bad Request: /admin 2021-11-24 14:56:13,758
WARNING django.server "GET /admin HTTP/1.1" 400 72160 2021-11-24 14:56:13,758
WARNING django.request Not Found: /favicon.ico 2021-11-24 17:26:22,380
WARNING django.server "GET /favicon.ico HTTP/1.1" 404 3524 2021-11-24 17:26:22,383
WARNING django.request Not Found: /favicon.ico 2021-11-24 17:27:40,965
WARNING django.server "GET /favicon.ico HTTP/1.1" 404 3524 2021-11-24 17:27:40,966
WARNING django.request Not Found: /favicon.ico 2021-11-24 17:33:50,836
WARNING django.server "GET /favicon.ico HTTP/1.1" 404 3524 2021-11-24 17:33:50,836
WARNING django.request Not Found: /favicon.ico 2021-11-24 17:33:54,348
WARNING django.server "GET /favicon.ico HTTP/1.1" 404 3524 2021-11-24 17:33:54,349
WARNING django.request Not Found: /favicon.ico 2021-11-24 17:34:04,157
WARNING django.server "GET /favicon.ico HTTP/1.1" 404 3524 2021-11-24 17:34:04,158
ERROR django.request Internal Server Error: /analytic/migrant/search/ 2021-11-24 17:34:34,585
Traceback (most recent call last):
  File "D:\Users\ntabyldieva\Desktop\databases_v1\env\lib\site-packages\django\core\handlers\exception.py", line 47, in inner
    response = get_response(request)
  File "D:\Users\ntabyldieva\Desktop\databases_v1\env\lib\site-packages\django\core\handlers\base.py", line 181, in _get_response
    response = wrapped_callback(request, *callback_args, **callback_kwargs)
  File "D:\Users\ntabyldieva\Desktop\databases_v1\env\lib\site-packages\django\views\decorators\csrf.py", line 54, in wrapped_view
    return view_func(*args, **kwargs)
  File "D:\Users\ntabyldieva\Desktop\databases_v1\env\lib\site-packages\django\views\generic\base.py", line 70, in view
    return self.dispatch(request, *args, **kwargs)
  File "D:\Users\ntabyldieva\Desktop\databases_v1\env\lib\site-packages\rest_framework\views.py", line 509, in dispatch
    response = self.handle_exception(exc)
  File "D:\Users\ntabyldieva\Desktop\databases_v1\env\lib\site-packages\rest_framework\views.py", line 469, in handle_exception
    self.raise_uncaught_exception(exc)
  File "D:\Users\ntabyldieva\Desktop\databases_v1\env\lib\site-packages\rest_framework\views.py", line 480, in raise_uncaught_exception
    raise exc
  File "D:\Users\ntabyldieva\Desktop\databases_v1\env\lib\site-packages\rest_framework\views.py", line 506, in dispatch
    response = handler(request, *args, **kwargs)
  File "D:\Users\ntabyldieva\Desktop\databases_v1\statistica\views.py", line 83, in post
    cases = MigrantCase.objects.filter(**filters).order_by('id')
  File "D:\Users\ntabyldieva\Desktop\databases_v1\env\lib\site-packages\django\db\models\manager.py", line 85, in manager_method
    return getattr(self.get_queryset(), name)(*args, **kwargs)
  File "D:\Users\ntabyldieva\Desktop\databases_v1\env\lib\site-packages\django\db\models\query.py", line 941, in filter
    return self._filter_or_exclude(False, args, kwargs)
  File "D:\Users\ntabyldieva\Desktop\databases_v1\env\lib\site-packages\django\db\models\query.py", line 961, in _filter_or_exclude
    clone._filter_or_exclude_inplace(negate, args, kwargs)
  File "D:\Users\ntabyldieva\Desktop\databases_v1\env\lib\site-packages\django\db\models\query.py", line 968, in _filter_or_exclude_inplace
    self._query.add_q(Q(*args, **kwargs))
  File "D:\Users\ntabyldieva\Desktop\databases_v1\env\lib\site-packages\django\db\models\sql\query.py", line 1391, in add_q
    clause, _ = self._add_q(q_object, self.used_aliases)
  File "D:\Users\ntabyldieva\Desktop\databases_v1\env\lib\site-packages\django\db\models\sql\query.py", line 1410, in _add_q
    child_clause, needed_inner = self.build_filter(
  File "D:\Users\ntabyldieva\Desktop\databases_v1\env\lib\site-packages\django\db\models\sql\query.py", line 1284, in build_filter
    lookups, parts, reffed_expression = self.solve_lookup_type(arg)
  File "D:\Users\ntabyldieva\Desktop\databases_v1\env\lib\site-packages\django\db\models\sql\query.py", line 1110, in solve_lookup_type
    _, field, _, lookup_parts = self.names_to_path(lookup_splitted, self.get_meta())
  File "D:\Users\ntabyldieva\Desktop\databases_v1\env\lib\site-packages\django\db\models\sql\query.py", line 1537, in names_to_path
    raise FieldError("Cannot resolve keyword '%s' into field. "
django.core.exceptions.FieldError: Cannot resolve keyword 'n1' into field. Choices are: actions, active, advice, banOnEntry, banOnEntryAnother, banOnEntry_id, banned_country, case_additional, case_additional_info, case_date, case_name, casecomment, casefile, casephoto, changesInSalary, changesInSalary_another, changesInSalary_id, comment, company, company_id, control_agency_name, country, country_id, date_create, date_type, date_update, decision, end_date, entrepreneur, entrepreneur_id, final, frequent_problems, government_agency_name, has_violation_in_covid, id, individualInfo, individualInfo_id, intruder, local_agency_name, personGroupInfo, personGroupInfo_id, police_agency_name, region, region_id, rights_state, rights_state_another, rights_state_id, source, source_content, source_url, start_date, story, tradeUnionCount, tradeUnionCount_id, tradeUnionSituation, tradeUnionSituation_another, tradeUnionSituation_id, user, user_id, victim, victim_id, victim_situation, victim_situation_another, victim_situation_id, victim_status, victim_status_id, violatedRightAnother, violated_right, violationType, violationType_another, violationType_id, violation_nature, violation_nature_id
ERROR django.request Internal Server Error: /analytic/migrant/search/ 2021-11-24 17:34:34,587
Traceback (most recent call last):
  File "D:\Users\ntabyldieva\Desktop\databases_v1\env\lib\site-packages\django\core\handlers\exception.py", line 47, in inner
    response = get_response(request)
  File "D:\Users\ntabyldieva\Desktop\databases_v1\env\lib\site-packages\django\core\handlers\base.py", line 181, in _get_response
    response = wrapped_callback(request, *callback_args, **callback_kwargs)
  File "D:\Users\ntabyldieva\Desktop\databases_v1\env\lib\site-packages\django\views\decorators\csrf.py", line 54, in wrapped_view
    return view_func(*args, **kwargs)
  File "D:\Users\ntabyldieva\Desktop\databases_v1\env\lib\site-packages\django\views\generic\base.py", line 70, in view
    return self.dispatch(request, *args, **kwargs)
  File "D:\Users\ntabyldieva\Desktop\databases_v1\env\lib\site-packages\rest_framework\views.py", line 509, in dispatch
    response = self.handle_exception(exc)
  File "D:\Users\ntabyldieva\Desktop\databases_v1\env\lib\site-packages\rest_framework\views.py", line 469, in handle_exception
    self.raise_uncaught_exception(exc)
  File "D:\Users\ntabyldieva\Desktop\databases_v1\env\lib\site-packages\rest_framework\views.py", line 480, in raise_uncaught_exception
    raise exc
  File "D:\Users\ntabyldieva\Desktop\databases_v1\env\lib\site-packages\rest_framework\views.py", line 506, in dispatch
    response = handler(request, *args, **kwargs)
  File "D:\Users\ntabyldieva\Desktop\databases_v1\statistica\views.py", line 83, in post
    cases = MigrantCase.objects.filter(**filters).order_by('id')
  File "D:\Users\ntabyldieva\Desktop\databases_v1\env\lib\site-packages\django\db\models\manager.py", line 85, in manager_method
    return getattr(self.get_queryset(), name)(*args, **kwargs)
  File "D:\Users\ntabyldieva\Desktop\databases_v1\env\lib\site-packages\django\db\models\query.py", line 941, in filter
    return self._filter_or_exclude(False, args, kwargs)
  File "D:\Users\ntabyldieva\Desktop\databases_v1\env\lib\site-packages\django\db\models\query.py", line 961, in _filter_or_exclude
    clone._filter_or_exclude_inplace(negate, args, kwargs)
  File "D:\Users\ntabyldieva\Desktop\databases_v1\env\lib\site-packages\django\db\models\query.py", line 968, in _filter_or_exclude_inplace
    self._query.add_q(Q(*args, **kwargs))
  File "D:\Users\ntabyldieva\Desktop\databases_v1\env\lib\site-packages\django\db\models\sql\query.py", line 1391, in add_q
    clause, _ = self._add_q(q_object, self.used_aliases)
  File "D:\Users\ntabyldieva\Desktop\databases_v1\env\lib\site-packages\django\db\models\sql\query.py", line 1410, in _add_q
    child_clause, needed_inner = self.build_filter(
  File "D:\Users\ntabyldieva\Desktop\databases_v1\env\lib\site-packages\django\db\models\sql\query.py", line 1284, in build_filter
    lookups, parts, reffed_expression = self.solve_lookup_type(arg)
  File "D:\Users\ntabyldieva\Desktop\databases_v1\env\lib\site-packages\django\db\models\sql\query.py", line 1110, in solve_lookup_type
    _, field, _, lookup_parts = self.names_to_path(lookup_splitted, self.get_meta())
  File "D:\Users\ntabyldieva\Desktop\databases_v1\env\lib\site-packages\django\db\models\sql\query.py", line 1537, in names_to_path
    raise FieldError("Cannot resolve keyword '%s' into field. "
django.core.exceptions.FieldError: Cannot resolve keyword 'n1' into field. Choices are: actions, active, advice, banOnEntry, banOnEntryAnother, banOnEntry_id, banned_country, case_additional, case_additional_info, case_date, case_name, casecomment, casefile, casephoto, changesInSalary, changesInSalary_another, changesInSalary_id, comment, company, company_id, control_agency_name, country, country_id, date_create, date_type, date_update, decision, end_date, entrepreneur, entrepreneur_id, final, frequent_problems, government_agency_name, has_violation_in_covid, id, individualInfo, individualInfo_id, intruder, local_agency_name, personGroupInfo, personGroupInfo_id, police_agency_name, region, region_id, rights_state, rights_state_another, rights_state_id, source, source_content, source_url, start_date, story, tradeUnionCount, tradeUnionCount_id, tradeUnionSituation, tradeUnionSituation_another, tradeUnionSituation_id, user, user_id, victim, victim_id, victim_situation, victim_situation_another, victim_situation_id, victim_status, victim_status_id, violatedRightAnother, violated_right, violationType, violationType_another, violationType_id, violation_nature, violation_nature_id
ERROR django.server "POST /analytic/migrant/search/ HTTP/1.1" 500 151037 2021-11-24 17:34:34,595
ERROR django.server "POST /analytic/migrant/search/ HTTP/1.1" 500 151037 2021-11-24 17:34:34,603
ERROR django.request Internal Server Error: /analytic/migrant/search/ 2021-11-24 17:34:39,659
Traceback (most recent call last):
  File "D:\Users\ntabyldieva\Desktop\databases_v1\env\lib\site-packages\django\core\handlers\exception.py", line 47, in inner
    response = get_response(request)
  File "D:\Users\ntabyldieva\Desktop\databases_v1\env\lib\site-packages\django\core\handlers\base.py", line 181, in _get_response
    response = wrapped_callback(request, *callback_args, **callback_kwargs)
  File "D:\Users\ntabyldieva\Desktop\databases_v1\env\lib\site-packages\django\views\decorators\csrf.py", line 54, in wrapped_view
    return view_func(*args, **kwargs)
  File "D:\Users\ntabyldieva\Desktop\databases_v1\env\lib\site-packages\django\views\generic\base.py", line 70, in view
    return self.dispatch(request, *args, **kwargs)
  File "D:\Users\ntabyldieva\Desktop\databases_v1\env\lib\site-packages\rest_framework\views.py", line 509, in dispatch
    response = self.handle_exception(exc)
  File "D:\Users\ntabyldieva\Desktop\databases_v1\env\lib\site-packages\rest_framework\views.py", line 469, in handle_exception
    self.raise_uncaught_exception(exc)
  File "D:\Users\ntabyldieva\Desktop\databases_v1\env\lib\site-packages\rest_framework\views.py", line 480, in raise_uncaught_exception
    raise exc
  File "D:\Users\ntabyldieva\Desktop\databases_v1\env\lib\site-packages\rest_framework\views.py", line 506, in dispatch
    response = handler(request, *args, **kwargs)
  File "D:\Users\ntabyldieva\Desktop\databases_v1\statistica\views.py", line 83, in post
    cases = MigrantCase.objects.filter(**filters).order_by('id')
  File "D:\Users\ntabyldieva\Desktop\databases_v1\env\lib\site-packages\django\db\models\manager.py", line 85, in manager_method
    return getattr(self.get_queryset(), name)(*args, **kwargs)
  File "D:\Users\ntabyldieva\Desktop\databases_v1\env\lib\site-packages\django\db\models\query.py", line 941, in filter
    return self._filter_or_exclude(False, args, kwargs)
  File "D:\Users\ntabyldieva\Desktop\databases_v1\env\lib\site-packages\django\db\models\query.py", line 961, in _filter_or_exclude
    clone._filter_or_exclude_inplace(negate, args, kwargs)
  File "D:\Users\ntabyldieva\Desktop\databases_v1\env\lib\site-packages\django\db\models\query.py", line 968, in _filter_or_exclude_inplace
    self._query.add_q(Q(*args, **kwargs))
  File "D:\Users\ntabyldieva\Desktop\databases_v1\env\lib\site-packages\django\db\models\sql\query.py", line 1391, in add_q
    clause, _ = self._add_q(q_object, self.used_aliases)
  File "D:\Users\ntabyldieva\Desktop\databases_v1\env\lib\site-packages\django\db\models\sql\query.py", line 1410, in _add_q
    child_clause, needed_inner = self.build_filter(
  File "D:\Users\ntabyldieva\Desktop\databases_v1\env\lib\site-packages\django\db\models\sql\query.py", line 1284, in build_filter
    lookups, parts, reffed_expression = self.solve_lookup_type(arg)
  File "D:\Users\ntabyldieva\Desktop\databases_v1\env\lib\site-packages\django\db\models\sql\query.py", line 1110, in solve_lookup_type
    _, field, _, lookup_parts = self.names_to_path(lookup_splitted, self.get_meta())
  File "D:\Users\ntabyldieva\Desktop\databases_v1\env\lib\site-packages\django\db\models\sql\query.py", line 1537, in names_to_path
    raise FieldError("Cannot resolve keyword '%s' into field. "
django.core.exceptions.FieldError: Cannot resolve keyword 'n1' into field. Choices are: actions, active, advice, banOnEntry, banOnEntryAnother, banOnEntry_id, banned_country, case_additional, case_additional_info, case_date, case_name, casecomment, casefile, casephoto, changesInSalary, changesInSalary_another, changesInSalary_id, comment, company, company_id, control_agency_name, country, country_id, date_create, date_type, date_update, decision, end_date, entrepreneur, entrepreneur_id, final, frequent_problems, government_agency_name, has_violation_in_covid, id, individualInfo, individualInfo_id, intruder, local_agency_name, personGroupInfo, personGroupInfo_id, police_agency_name, region, region_id, rights_state, rights_state_another, rights_state_id, source, source_content, source_url, start_date, story, tradeUnionCount, tradeUnionCount_id, tradeUnionSituation, tradeUnionSituation_another, tradeUnionSituation_id, user, user_id, victim, victim_id, victim_situation, victim_situation_another, victim_situation_id, victim_status, victim_status_id, violatedRightAnother, violated_right, violationType, violationType_another, violationType_id, violation_nature, violation_nature_id
ERROR django.server "POST /analytic/migrant/search/ HTTP/1.1" 500 151037 2021-11-24 17:34:39,666
ERROR django.request Internal Server Error: /analytic/strike/search/ 2021-11-24 17:35:53,725
Traceback (most recent call last):
  File "D:\Users\ntabyldieva\Desktop\databases_v1\env\lib\site-packages\django\core\handlers\exception.py", line 47, in inner
    response = get_response(request)
  File "D:\Users\ntabyldieva\Desktop\databases_v1\env\lib\site-packages\django\core\handlers\base.py", line 181, in _get_response
    response = wrapped_callback(request, *callback_args, **callback_kwargs)
  File "D:\Users\ntabyldieva\Desktop\databases_v1\env\lib\site-packages\django\views\decorators\csrf.py", line 54, in wrapped_view
    return view_func(*args, **kwargs)
  File "D:\Users\ntabyldieva\Desktop\databases_v1\env\lib\site-packages\django\views\generic\base.py", line 70, in view
    return self.dispatch(request, *args, **kwargs)
  File "D:\Users\ntabyldieva\Desktop\databases_v1\env\lib\site-packages\rest_framework\views.py", line 509, in dispatch
    response = self.handle_exception(exc)
  File "D:\Users\ntabyldieva\Desktop\databases_v1\env\lib\site-packages\rest_framework\views.py", line 469, in handle_exception
    self.raise_uncaught_exception(exc)
  File "D:\Users\ntabyldieva\Desktop\databases_v1\env\lib\site-packages\rest_framework\views.py", line 480, in raise_uncaught_exception
    raise exc
  File "D:\Users\ntabyldieva\Desktop\databases_v1\env\lib\site-packages\rest_framework\views.py", line 506, in dispatch
    response = handler(request, *args, **kwargs)
  File "D:\Users\ntabyldieva\Desktop\databases_v1\statistica\views.py", line 156, in post
    cards = Card.objects.filter(**filters).order_by('id')
  File "D:\Users\ntabyldieva\Desktop\databases_v1\env\lib\site-packages\django\db\models\manager.py", line 85, in manager_method
    return getattr(self.get_queryset(), name)(*args, **kwargs)
  File "D:\Users\ntabyldieva\Desktop\databases_v1\env\lib\site-packages\django\db\models\query.py", line 941, in filter
    return self._filter_or_exclude(False, args, kwargs)
  File "D:\Users\ntabyldieva\Desktop\databases_v1\env\lib\site-packages\django\db\models\query.py", line 961, in _filter_or_exclude
    clone._filter_or_exclude_inplace(negate, args, kwargs)
  File "D:\Users\ntabyldieva\Desktop\databases_v1\env\lib\site-packages\django\db\models\query.py", line 968, in _filter_or_exclude_inplace
    self._query.add_q(Q(*args, **kwargs))
  File "D:\Users\ntabyldieva\Desktop\databases_v1\env\lib\site-packages\django\db\models\sql\query.py", line 1391, in add_q
    clause, _ = self._add_q(q_object, self.used_aliases)
  File "D:\Users\ntabyldieva\Desktop\databases_v1\env\lib\site-packages\django\db\models\sql\query.py", line 1410, in _add_q
    child_clause, needed_inner = self.build_filter(
  File "D:\Users\ntabyldieva\Desktop\databases_v1\env\lib\site-packages\django\db\models\sql\query.py", line 1284, in build_filter
    lookups, parts, reffed_expression = self.solve_lookup_type(arg)
  File "D:\Users\ntabyldieva\Desktop\databases_v1\env\lib\site-packages\django\db\models\sql\query.py", line 1110, in solve_lookup_type
    _, field, _, lookup_parts = self.names_to_path(lookup_splitted, self.get_meta())
  File "D:\Users\ntabyldieva\Desktop\databases_v1\env\lib\site-packages\django\db\models\sql\query.py", line 1537, in names_to_path
    raise FieldError("Cannot resolve keyword '%s' into field. "
django.core.exceptions.FieldError: Cannot resolve keyword 'n1' into field. Choices are: active, added_by, added_by_id, additional_information, card_demand_categories, card_sources, cardcomment, cardfile, cardphoto, case_text, change_number_participants, city_name, combo_another, combo_demands, comment, company_country_name, company_employees_count, company_employees_count_id, company_is_tnk_member, company_name, company_ownership_type, company_ownership_type_id, company_tnk_name, count_strike_participants, count_strike_participants_id, country, country_id, date_create, date_type, date_update, duration, duration_id, economic_another, economic_demands, employear, employear_id, end_date, id, individual, initiator, initiator_id, initiators_and_participants, meeting_requirements, meeting_requirements_id, name, personGroupInfo, personGroupInfo_id, politic_another, politic_demands, reasons_for_strike, region, region_id, results_so_far, source_content, source_url, start_date, state_position, story, tradeunionChoice, tradeunionChoiceAnother, tradeunionChoice_id, tradeunion_data, tradeunion_data_id
ERROR django.server "POST /analytic/strike/search/ HTTP/1.1" 500 149426 2021-11-24 17:35:53,732
WARNING django.request Not Found: /favicon.ico 2021-11-24 17:38:17,949
WARNING django.server "GET /favicon.ico HTTP/1.1" 404 3524 2021-11-24 17:38:17,949
ERROR django.request Internal Server Error: /analytic/strike/search/ 2021-11-24 17:38:56,384
Traceback (most recent call last):
  File "D:\Users\ntabyldieva\Desktop\databases_v1\env\lib\site-packages\django\core\handlers\exception.py", line 47, in inner
    response = get_response(request)
  File "D:\Users\ntabyldieva\Desktop\databases_v1\env\lib\site-packages\django\core\handlers\base.py", line 181, in _get_response
    response = wrapped_callback(request, *callback_args, **callback_kwargs)
  File "D:\Users\ntabyldieva\Desktop\databases_v1\env\lib\site-packages\django\views\decorators\csrf.py", line 54, in wrapped_view
    return view_func(*args, **kwargs)
  File "D:\Users\ntabyldieva\Desktop\databases_v1\env\lib\site-packages\django\views\generic\base.py", line 70, in view
    return self.dispatch(request, *args, **kwargs)
  File "D:\Users\ntabyldieva\Desktop\databases_v1\env\lib\site-packages\rest_framework\views.py", line 509, in dispatch
    response = self.handle_exception(exc)
  File "D:\Users\ntabyldieva\Desktop\databases_v1\env\lib\site-packages\rest_framework\views.py", line 469, in handle_exception
    self.raise_uncaught_exception(exc)
  File "D:\Users\ntabyldieva\Desktop\databases_v1\env\lib\site-packages\rest_framework\views.py", line 480, in raise_uncaught_exception
    raise exc
  File "D:\Users\ntabyldieva\Desktop\databases_v1\env\lib\site-packages\rest_framework\views.py", line 506, in dispatch
    response = handler(request, *args, **kwargs)
  File "D:\Users\ntabyldieva\Desktop\databases_v1\statistica\views.py", line 156, in post
    cards = Card.objects.filter(**filters).order_by('id')
  File "D:\Users\ntabyldieva\Desktop\databases_v1\env\lib\site-packages\django\db\models\manager.py", line 85, in manager_method
    return getattr(self.get_queryset(), name)(*args, **kwargs)
  File "D:\Users\ntabyldieva\Desktop\databases_v1\env\lib\site-packages\django\db\models\query.py", line 941, in filter
    return self._filter_or_exclude(False, args, kwargs)
  File "D:\Users\ntabyldieva\Desktop\databases_v1\env\lib\site-packages\django\db\models\query.py", line 961, in _filter_or_exclude
    clone._filter_or_exclude_inplace(negate, args, kwargs)
  File "D:\Users\ntabyldieva\Desktop\databases_v1\env\lib\site-packages\django\db\models\query.py", line 968, in _filter_or_exclude_inplace
    self._query.add_q(Q(*args, **kwargs))
  File "D:\Users\ntabyldieva\Desktop\databases_v1\env\lib\site-packages\django\db\models\sql\query.py", line 1391, in add_q
    clause, _ = self._add_q(q_object, self.used_aliases)
  File "D:\Users\ntabyldieva\Desktop\databases_v1\env\lib\site-packages\django\db\models\sql\query.py", line 1410, in _add_q
    child_clause, needed_inner = self.build_filter(
  File "D:\Users\ntabyldieva\Desktop\databases_v1\env\lib\site-packages\django\db\models\sql\query.py", line 1284, in build_filter
    lookups, parts, reffed_expression = self.solve_lookup_type(arg)
  File "D:\Users\ntabyldieva\Desktop\databases_v1\env\lib\site-packages\django\db\models\sql\query.py", line 1110, in solve_lookup_type
    _, field, _, lookup_parts = self.names_to_path(lookup_splitted, self.get_meta())
  File "D:\Users\ntabyldieva\Desktop\databases_v1\env\lib\site-packages\django\db\models\sql\query.py", line 1537, in names_to_path
    raise FieldError("Cannot resolve keyword '%s' into field. "
django.core.exceptions.FieldError: Cannot resolve keyword 'n1' into field. Choices are: active, added_by, added_by_id, additional_information, card_demand_categories, card_sources, cardcomment, cardfile, cardphoto, case_text, change_number_participants, city_name, combo_another, combo_demands, comment, company_country_name, company_employees_count, company_employees_count_id, company_is_tnk_member, company_name, company_ownership_type, company_ownership_type_id, company_tnk_name, count_strike_participants, count_strike_participants_id, country, country_id, date_create, date_type, date_update, duration, duration_id, economic_another, economic_demands, employear, employear_id, end_date, id, individual, initiator, initiator_id, initiators_and_participants, meeting_requirements, meeting_requirements_id, name, personGroupInfo, personGroupInfo_id, politic_another, politic_demands, reasons_for_strike, region, region_id, results_so_far, source_content, source_url, start_date, state_position, story, tradeunionChoice, tradeunionChoiceAnother, tradeunionChoice_id, tradeunion_data, tradeunion_data_id
ERROR django.server "POST /analytic/strike/search/ HTTP/1.1" 500 149426 2021-11-24 17:38:56,393
WARNING django.request Not Found: /favicon.ico 2021-11-24 17:39:35,312
WARNING django.server "GET /favicon.ico HTTP/1.1" 404 3524 2021-11-24 17:39:35,313
ERROR django.request Internal Server Error: /analytic/migrant/search/ 2021-11-24 17:39:57,948
Traceback (most recent call last):
  File "D:\Users\ntabyldieva\Desktop\databases_v1\env\lib\site-packages\django\core\handlers\exception.py", line 47, in inner
    response = get_response(request)
  File "D:\Users\ntabyldieva\Desktop\databases_v1\env\lib\site-packages\django\core\handlers\base.py", line 181, in _get_response
    response = wrapped_callback(request, *callback_args, **callback_kwargs)
  File "D:\Users\ntabyldieva\Desktop\databases_v1\env\lib\site-packages\django\views\decorators\csrf.py", line 54, in wrapped_view
    return view_func(*args, **kwargs)
  File "D:\Users\ntabyldieva\Desktop\databases_v1\env\lib\site-packages\django\views\generic\base.py", line 70, in view
    return self.dispatch(request, *args, **kwargs)
  File "D:\Users\ntabyldieva\Desktop\databases_v1\env\lib\site-packages\rest_framework\views.py", line 509, in dispatch
    response = self.handle_exception(exc)
  File "D:\Users\ntabyldieva\Desktop\databases_v1\env\lib\site-packages\rest_framework\views.py", line 469, in handle_exception
    self.raise_uncaught_exception(exc)
  File "D:\Users\ntabyldieva\Desktop\databases_v1\env\lib\site-packages\rest_framework\views.py", line 480, in raise_uncaught_exception
    raise exc
  File "D:\Users\ntabyldieva\Desktop\databases_v1\env\lib\site-packages\rest_framework\views.py", line 506, in dispatch
    response = handler(request, *args, **kwargs)
  File "D:\Users\ntabyldieva\Desktop\databases_v1\statistica\views.py", line 83, in post
    cases = MigrantCase.objects.filter(**filters).order_by('id')
  File "D:\Users\ntabyldieva\Desktop\databases_v1\env\lib\site-packages\django\db\models\manager.py", line 85, in manager_method
    return getattr(self.get_queryset(), name)(*args, **kwargs)
  File "D:\Users\ntabyldieva\Desktop\databases_v1\env\lib\site-packages\django\db\models\query.py", line 941, in filter
    return self._filter_or_exclude(False, args, kwargs)
  File "D:\Users\ntabyldieva\Desktop\databases_v1\env\lib\site-packages\django\db\models\query.py", line 961, in _filter_or_exclude
    clone._filter_or_exclude_inplace(negate, args, kwargs)
  File "D:\Users\ntabyldieva\Desktop\databases_v1\env\lib\site-packages\django\db\models\query.py", line 968, in _filter_or_exclude_inplace
    self._query.add_q(Q(*args, **kwargs))
  File "D:\Users\ntabyldieva\Desktop\databases_v1\env\lib\site-packages\django\db\models\sql\query.py", line 1391, in add_q
    clause, _ = self._add_q(q_object, self.used_aliases)
  File "D:\Users\ntabyldieva\Desktop\databases_v1\env\lib\site-packages\django\db\models\sql\query.py", line 1410, in _add_q
    child_clause, needed_inner = self.build_filter(
  File "D:\Users\ntabyldieva\Desktop\databases_v1\env\lib\site-packages\django\db\models\sql\query.py", line 1284, in build_filter
    lookups, parts, reffed_expression = self.solve_lookup_type(arg)
  File "D:\Users\ntabyldieva\Desktop\databases_v1\env\lib\site-packages\django\db\models\sql\query.py", line 1110, in solve_lookup_type
    _, field, _, lookup_parts = self.names_to_path(lookup_splitted, self.get_meta())
  File "D:\Users\ntabyldieva\Desktop\databases_v1\env\lib\site-packages\django\db\models\sql\query.py", line 1537, in names_to_path
    raise FieldError("Cannot resolve keyword '%s' into field. "
django.core.exceptions.FieldError: Cannot resolve keyword 'n1' into field. Choices are: actions, active, advice, banOnEntry, banOnEntryAnother, banOnEntry_id, banned_country, case_additional, case_additional_info, case_date, case_name, casecomment, casefile, casephoto, changesInSalary, changesInSalary_another, changesInSalary_id, comment, company, company_id, control_agency_name, country, country_id, date_create, date_type, date_update, decision, end_date, entrepreneur, entrepreneur_id, final, frequent_problems, government_agency_name, has_violation_in_covid, id, individualInfo, individualInfo_id, intruder, local_agency_name, personGroupInfo, personGroupInfo_id, police_agency_name, region, region_id, rights_state, rights_state_another, rights_state_id, source, source_content, source_url, start_date, story, tradeUnionCount, tradeUnionCount_id, tradeUnionSituation, tradeUnionSituation_another, tradeUnionSituation_id, user, user_id, victim, victim_id, victim_situation, victim_situation_another, victim_situation_id, victim_status, victim_status_id, violatedRightAnother, violated_right, violationType, violationType_another, violationType_id, violation_nature, violation_nature_id
ERROR django.server "POST /analytic/migrant/search/ HTTP/1.1" 500 151037 2021-11-24 17:39:57,955
WARNING django.request Not Found: /favicon.ico 2021-11-24 17:40:37,947
WARNING django.server "GET /favicon.ico HTTP/1.1" 404 3524 2021-11-24 17:40:37,948
ERROR django.request Internal Server Error: /analytic/migrant/search/ 2021-11-24 17:41:20,916
Traceback (most recent call last):
  File "D:\Users\ntabyldieva\Desktop\databases_v1\env\lib\site-packages\django\core\handlers\exception.py", line 47, in inner
    response = get_response(request)
  File "D:\Users\ntabyldieva\Desktop\databases_v1\env\lib\site-packages\django\core\handlers\base.py", line 181, in _get_response
    response = wrapped_callback(request, *callback_args, **callback_kwargs)
  File "D:\Users\ntabyldieva\Desktop\databases_v1\env\lib\site-packages\django\views\decorators\csrf.py", line 54, in wrapped_view
    return view_func(*args, **kwargs)
  File "D:\Users\ntabyldieva\Desktop\databases_v1\env\lib\site-packages\django\views\generic\base.py", line 70, in view
    return self.dispatch(request, *args, **kwargs)
  File "D:\Users\ntabyldieva\Desktop\databases_v1\env\lib\site-packages\rest_framework\views.py", line 509, in dispatch
    response = self.handle_exception(exc)
  File "D:\Users\ntabyldieva\Desktop\databases_v1\env\lib\site-packages\rest_framework\views.py", line 469, in handle_exception
    self.raise_uncaught_exception(exc)
  File "D:\Users\ntabyldieva\Desktop\databases_v1\env\lib\site-packages\rest_framework\views.py", line 480, in raise_uncaught_exception
    raise exc
  File "D:\Users\ntabyldieva\Desktop\databases_v1\env\lib\site-packages\rest_framework\views.py", line 506, in dispatch
    response = handler(request, *args, **kwargs)
  File "D:\Users\ntabyldieva\Desktop\databases_v1\statistica\views.py", line 75, in post
    filters.pop("card_demand_categories_id")
KeyError: 'card_demand_categories_id'
ERROR django.server "POST /analytic/migrant/search/ HTTP/1.1" 500 95615 2021-11-24 17:41:20,920
ERROR django.request Internal Server Error: /analytic/migrant/search/ 2021-11-24 17:43:10,683
Traceback (most recent call last):
  File "D:\Users\ntabyldieva\Desktop\databases_v1\env\lib\site-packages\django\core\handlers\exception.py", line 47, in inner
    response = get_response(request)
  File "D:\Users\ntabyldieva\Desktop\databases_v1\env\lib\site-packages\django\core\handlers\base.py", line 181, in _get_response
    response = wrapped_callback(request, *callback_args, **callback_kwargs)
  File "D:\Users\ntabyldieva\Desktop\databases_v1\env\lib\site-packages\django\views\decorators\csrf.py", line 54, in wrapped_view
    return view_func(*args, **kwargs)
  File "D:\Users\ntabyldieva\Desktop\databases_v1\env\lib\site-packages\django\views\generic\base.py", line 70, in view
    return self.dispatch(request, *args, **kwargs)
  File "D:\Users\ntabyldieva\Desktop\databases_v1\env\lib\site-packages\rest_framework\views.py", line 509, in dispatch
    response = self.handle_exception(exc)
  File "D:\Users\ntabyldieva\Desktop\databases_v1\env\lib\site-packages\rest_framework\views.py", line 469, in handle_exception
    self.raise_uncaught_exception(exc)
  File "D:\Users\ntabyldieva\Desktop\databases_v1\env\lib\site-packages\rest_framework\views.py", line 480, in raise_uncaught_exception
    raise exc
  File "D:\Users\ntabyldieva\Desktop\databases_v1\env\lib\site-packages\rest_framework\views.py", line 506, in dispatch
    response = handler(request, *args, **kwargs)
  File "D:\Users\ntabyldieva\Desktop\databases_v1\statistica\views.py", line 75, in post
    filters.pop("card_demand_categories_id")
KeyError: 'card_demand_categories_id'
ERROR django.server "POST /analytic/migrant/search/ HTTP/1.1" 500 95615 2021-11-24 17:43:10,686
WARNING django.request Method Not Allowed: /analytic/migrant/search/ 2021-11-24 17:44:29,832
WARNING django.server "GET /analytic/migrant/search/ HTTP/1.1" 405 6021 2021-11-24 17:44:29,833
WARNING django.request Not Found: /favicon.ico 2021-11-24 18:02:57,188
WARNING django.server "GET /favicon.ico HTTP/1.1" 404 3524 2021-11-24 18:02:57,188
WARNING django.request Not Found: /favicon.ico 2021-11-24 18:08:40,245
WARNING django.server "GET /favicon.ico HTTP/1.1" 404 3524 2021-11-24 18:08:40,246
WARNING django.request Not Found: /favicon.ico 2021-11-24 18:09:26,662
WARNING django.server "GET /favicon.ico HTTP/1.1" 404 3524 2021-11-24 18:09:26,662
WARNING django.request Not Found: /favicon.ico 2021-11-24 18:10:43,092
WARNING django.server "GET /favicon.ico HTTP/1.1" 404 3524 2021-11-24 18:10:43,093
WARNING django.request Not Found: /favicon.ico 2021-11-24 18:12:07,150
WARNING django.server "GET /favicon.ico HTTP/1.1" 404 3524 2021-11-24 18:12:07,151
WARNING django.request Not Found: /favicon.ico 2021-11-24 18:12:50,049
WARNING django.server "GET /favicon.ico HTTP/1.1" 404 3524 2021-11-24 18:12:50,050
WARNING django.request Not Found: /favicon.ico 2021-11-24 18:14:57,804
WARNING django.server "GET /favicon.ico HTTP/1.1" 404 3524 2021-11-24 18:14:57,805
WARNING django.request Not Found: /favicon.ico 2021-11-24 18:15:21,863
WARNING django.server "GET /favicon.ico HTTP/1.1" 404 3524 2021-11-24 18:15:21,864
WARNING django.request Not Found: /favicon.ico 2021-11-24 18:34:23,041
WARNING django.server "GET /favicon.ico HTTP/1.1" 404 3524 2021-11-24 18:34:23,042
WARNING django.request Not Found: /favicon.ico 2021-11-24 18:36:06,671
WARNING django.server "GET /favicon.ico HTTP/1.1" 404 3524 2021-11-24 18:36:06,672
ERROR django.request Internal Server Error: /analytic/migrant/search/ 2021-11-24 18:36:16,906
Traceback (most recent call last):
  File "D:\Users\ntabyldieva\Desktop\databases_v1\env\lib\site-packages\django\core\handlers\exception.py", line 47, in inner
    response = get_response(request)
  File "D:\Users\ntabyldieva\Desktop\databases_v1\env\lib\site-packages\django\core\handlers\base.py", line 181, in _get_response
    response = wrapped_callback(request, *callback_args, **callback_kwargs)
  File "D:\Users\ntabyldieva\Desktop\databases_v1\env\lib\site-packages\django\views\decorators\csrf.py", line 54, in wrapped_view
    return view_func(*args, **kwargs)
  File "D:\Users\ntabyldieva\Desktop\databases_v1\env\lib\site-packages\django\views\generic\base.py", line 70, in view
    return self.dispatch(request, *args, **kwargs)
  File "D:\Users\ntabyldieva\Desktop\databases_v1\env\lib\site-packages\rest_framework\views.py", line 509, in dispatch
    response = self.handle_exception(exc)
  File "D:\Users\ntabyldieva\Desktop\databases_v1\env\lib\site-packages\rest_framework\views.py", line 469, in handle_exception
    self.raise_uncaught_exception(exc)
  File "D:\Users\ntabyldieva\Desktop\databases_v1\env\lib\site-packages\rest_framework\views.py", line 480, in raise_uncaught_exception
    raise exc
  File "D:\Users\ntabyldieva\Desktop\databases_v1\env\lib\site-packages\rest_framework\views.py", line 506, in dispatch
    response = handler(request, *args, **kwargs)
  File "D:\Users\ntabyldieva\Desktop\databases_v1\statistica\views.py", line 75, in post
    filters.pop("card_demand_categories_id")
KeyError: 'card_demand_categories_id'
ERROR django.server "POST /analytic/migrant/search/ HTTP/1.1" 500 95615 2021-11-24 18:36:16,911
WARNING django.request Not Found: /favicon.ico 2021-11-24 18:38:38,438
WARNING django.server "GET /favicon.ico HTTP/1.1" 404 3524 2021-11-24 18:38:38,439
ERROR django.request Internal Server Error: /analytic/migrant/search/ 2021-11-24 18:38:48,440
Traceback (most recent call last):
  File "D:\Users\ntabyldieva\Desktop\databases_v1\env\lib\site-packages\django\core\handlers\exception.py", line 47, in inner
    response = get_response(request)
  File "D:\Users\ntabyldieva\Desktop\databases_v1\env\lib\site-packages\django\core\handlers\base.py", line 181, in _get_response
    response = wrapped_callback(request, *callback_args, **callback_kwargs)
  File "D:\Users\ntabyldieva\Desktop\databases_v1\env\lib\site-packages\django\views\decorators\csrf.py", line 54, in wrapped_view
    return view_func(*args, **kwargs)
  File "D:\Users\ntabyldieva\Desktop\databases_v1\env\lib\site-packages\django\views\generic\base.py", line 70, in view
    return self.dispatch(request, *args, **kwargs)
  File "D:\Users\ntabyldieva\Desktop\databases_v1\env\lib\site-packages\rest_framework\views.py", line 509, in dispatch
    response = self.handle_exception(exc)
  File "D:\Users\ntabyldieva\Desktop\databases_v1\env\lib\site-packages\rest_framework\views.py", line 469, in handle_exception
    self.raise_uncaught_exception(exc)
  File "D:\Users\ntabyldieva\Desktop\databases_v1\env\lib\site-packages\rest_framework\views.py", line 480, in raise_uncaught_exception
    raise exc
  File "D:\Users\ntabyldieva\Desktop\databases_v1\env\lib\site-packages\rest_framework\views.py", line 506, in dispatch
    response = handler(request, *args, **kwargs)
  File "D:\Users\ntabyldieva\Desktop\databases_v1\statistica\views.py", line 75, in post
    filters.pop("card_demand_categories_id")
KeyError: 'card_demand_categories_id'
ERROR django.server "POST /analytic/migrant/search/ HTTP/1.1" 500 95615 2021-11-24 18:38:48,444
WARNING django.request Method Not Allowed: /analytic/migrant/search/ 2021-11-24 18:40:41,406
WARNING django.server "GET /analytic/migrant/search/ HTTP/1.1" 405 6021 2021-11-24 18:40:41,407
WARNING django.request Not Found: /favicon.ico 2021-11-24 18:42:13,789
WARNING django.server "GET /favicon.ico HTTP/1.1" 404 3524 2021-11-24 18:42:13,790
ERROR django.request Internal Server Error: /analytic/migrant/search/ 2021-11-24 18:42:23,029
Traceback (most recent call last):
  File "D:\Users\ntabyldieva\Desktop\databases_v1\env\lib\site-packages\django\core\handlers\exception.py", line 47, in inner
    response = get_response(request)
  File "D:\Users\ntabyldieva\Desktop\databases_v1\env\lib\site-packages\django\core\handlers\base.py", line 181, in _get_response
    response = wrapped_callback(request, *callback_args, **callback_kwargs)
  File "D:\Users\ntabyldieva\Desktop\databases_v1\env\lib\site-packages\django\views\decorators\csrf.py", line 54, in wrapped_view
    return view_func(*args, **kwargs)
  File "D:\Users\ntabyldieva\Desktop\databases_v1\env\lib\site-packages\django\views\generic\base.py", line 70, in view
    return self.dispatch(request, *args, **kwargs)
  File "D:\Users\ntabyldieva\Desktop\databases_v1\env\lib\site-packages\rest_framework\views.py", line 509, in dispatch
    response = self.handle_exception(exc)
  File "D:\Users\ntabyldieva\Desktop\databases_v1\env\lib\site-packages\rest_framework\views.py", line 469, in handle_exception
    self.raise_uncaught_exception(exc)
  File "D:\Users\ntabyldieva\Desktop\databases_v1\env\lib\site-packages\rest_framework\views.py", line 480, in raise_uncaught_exception
    raise exc
  File "D:\Users\ntabyldieva\Desktop\databases_v1\env\lib\site-packages\rest_framework\views.py", line 506, in dispatch
    response = handler(request, *args, **kwargs)
  File "D:\Users\ntabyldieva\Desktop\databases_v1\statistica\views.py", line 75, in post
    filters.pop("card_demand_categories_id")
KeyError: 'card_demand_categories_id'
ERROR django.server "POST /analytic/migrant/search/ HTTP/1.1" 500 95615 2021-11-24 18:42:23,033
ERROR django.request Internal Server Error: /analytic/migrant/search/ 2021-11-24 18:45:50,964
Traceback (most recent call last):
  File "D:\Users\ntabyldieva\Desktop\databases_v1\env\lib\site-packages\django\core\handlers\exception.py", line 47, in inner
    response = get_response(request)
  File "D:\Users\ntabyldieva\Desktop\databases_v1\env\lib\site-packages\django\core\handlers\base.py", line 181, in _get_response
    response = wrapped_callback(request, *callback_args, **callback_kwargs)
  File "D:\Users\ntabyldieva\Desktop\databases_v1\env\lib\site-packages\django\views\decorators\csrf.py", line 54, in wrapped_view
    return view_func(*args, **kwargs)
  File "D:\Users\ntabyldieva\Desktop\databases_v1\env\lib\site-packages\django\views\generic\base.py", line 70, in view
    return self.dispatch(request, *args, **kwargs)
  File "D:\Users\ntabyldieva\Desktop\databases_v1\env\lib\site-packages\rest_framework\views.py", line 509, in dispatch
    response = self.handle_exception(exc)
  File "D:\Users\ntabyldieva\Desktop\databases_v1\env\lib\site-packages\rest_framework\views.py", line 469, in handle_exception
    self.raise_uncaught_exception(exc)
  File "D:\Users\ntabyldieva\Desktop\databases_v1\env\lib\site-packages\rest_framework\views.py", line 480, in raise_uncaught_exception
    raise exc
  File "D:\Users\ntabyldieva\Desktop\databases_v1\env\lib\site-packages\rest_framework\views.py", line 506, in dispatch
    response = handler(request, *args, **kwargs)
  File "D:\Users\ntabyldieva\Desktop\databases_v1\statistica\views.py", line 75, in post
    filters.pop("card_demand_categories_id")
KeyError: 'card_demand_categories_id'
ERROR django.server "POST /analytic/migrant/search/ HTTP/1.1" 500 95615 2021-11-24 18:45:50,968
WARNING django.request Not Found: /favicon.ico 2021-11-24 18:46:22,732
WARNING django.server "GET /favicon.ico HTTP/1.1" 404 3524 2021-11-24 18:46:22,733
ERROR django.request Internal Server Error: /analytic/migrant/search/ 2021-11-24 18:46:31,826
Traceback (most recent call last):
  File "D:\Users\ntabyldieva\Desktop\databases_v1\env\lib\site-packages\django\core\handlers\exception.py", line 47, in inner
    response = get_response(request)
  File "D:\Users\ntabyldieva\Desktop\databases_v1\env\lib\site-packages\django\core\handlers\base.py", line 181, in _get_response
    response = wrapped_callback(request, *callback_args, **callback_kwargs)
  File "D:\Users\ntabyldieva\Desktop\databases_v1\env\lib\site-packages\django\views\decorators\csrf.py", line 54, in wrapped_view
    return view_func(*args, **kwargs)
  File "D:\Users\ntabyldieva\Desktop\databases_v1\env\lib\site-packages\django\views\generic\base.py", line 70, in view
    return self.dispatch(request, *args, **kwargs)
  File "D:\Users\ntabyldieva\Desktop\databases_v1\env\lib\site-packages\rest_framework\views.py", line 509, in dispatch
    response = self.handle_exception(exc)
  File "D:\Users\ntabyldieva\Desktop\databases_v1\env\lib\site-packages\rest_framework\views.py", line 469, in handle_exception
    self.raise_uncaught_exception(exc)
  File "D:\Users\ntabyldieva\Desktop\databases_v1\env\lib\site-packages\rest_framework\views.py", line 480, in raise_uncaught_exception
    raise exc
  File "D:\Users\ntabyldieva\Desktop\databases_v1\env\lib\site-packages\rest_framework\views.py", line 506, in dispatch
    response = handler(request, *args, **kwargs)
  File "D:\Users\ntabyldieva\Desktop\databases_v1\statistica\views.py", line 75, in post
    filters.pop("card_demand_categories_id")
KeyError: 'card_demand_categories_id'
ERROR django.server "POST /analytic/migrant/search/ HTTP/1.1" 500 95615 2021-11-24 18:46:31,830
WARNING django.request Method Not Allowed: /analytic/migrant/search/ 2021-11-24 18:47:45,293
WARNING django.server "GET /analytic/migrant/search/ HTTP/1.1" 405 6021 2021-11-24 18:47:45,294
WARNING django.request Not Found: /favicon.ico 2021-11-24 18:48:17,596
WARNING django.server "GET /favicon.ico HTTP/1.1" 404 3524 2021-11-24 18:48:17,597
