ERROR django.request Internal Server Error: /work/data/get/ 2021-08-30 11:33:35,831
Traceback (most recent call last):
  File "C:\Users\user\OneDrive\Desktop\Projects\databases_v1\venv\lib\site-packages\django\db\backends\utils.py", line 82, in _execute
    return self.cursor.execute(sql)
  File "C:\Users\user\OneDrive\Desktop\Projects\databases_v1\venv\lib\site-packages\django\db\backends\sqlite3\base.py", line 421, in execute
    return Database.Cursor.execute(self, query)
sqlite3.OperationalError: no such table: work_casewhere

The above exception was the direct cause of the following exception:

Traceback (most recent call last):
  File "C:\Users\user\OneDrive\Desktop\Projects\databases_v1\venv\lib\site-packages\django\core\handlers\exception.py", line 47, in inner
    response = get_response(request)
  File "C:\Users\user\OneDrive\Desktop\Projects\databases_v1\venv\lib\site-packages\django\core\handlers\base.py", line 181, in _get_response
    response = wrapped_callback(request, *callback_args, **callback_kwargs)
  File "C:\Users\user\OneDrive\Desktop\Projects\databases_v1\venv\lib\site-packages\django\views\decorators\csrf.py", line 54, in wrapped_view
    return view_func(*args, **kwargs)
  File "C:\Users\user\OneDrive\Desktop\Projects\databases_v1\venv\lib\site-packages\django\views\generic\base.py", line 70, in view
    return self.dispatch(request, *args, **kwargs)
  File "C:\Users\user\OneDrive\Desktop\Projects\databases_v1\venv\lib\site-packages\rest_framework\views.py", line 509, in dispatch
    response = self.handle_exception(exc)
  File "C:\Users\user\OneDrive\Desktop\Projects\databases_v1\venv\lib\site-packages\rest_framework\views.py", line 469, in handle_exception
    self.raise_uncaught_exception(exc)
  File "C:\Users\user\OneDrive\Desktop\Projects\databases_v1\venv\lib\site-packages\rest_framework\views.py", line 480, in raise_uncaught_exception
    raise exc
  File "C:\Users\user\OneDrive\Desktop\Projects\databases_v1\venv\lib\site-packages\rest_framework\views.py", line 506, in dispatch
    response = handler(request, *args, **kwargs)
  File "C:\Users\user\OneDrive\Desktop\Projects\databases_v1\databases_v1\work\views.py", line 980, in post
    cursor.execute(sql_query + where_query + group_by_query)
  File "C:\Users\user\OneDrive\Desktop\Projects\databases_v1\venv\lib\site-packages\django\db\backends\utils.py", line 98, in execute
    return super().execute(sql, params)
  File "C:\Users\user\OneDrive\Desktop\Projects\databases_v1\venv\lib\site-packages\django\db\backends\utils.py", line 66, in execute
    return self._execute_with_wrappers(sql, params, many=False, executor=self._execute)
  File "C:\Users\user\OneDrive\Desktop\Projects\databases_v1\venv\lib\site-packages\django\db\backends\utils.py", line 75, in _execute_with_wrappers
    return executor(sql, params, many, context)
  File "C:\Users\user\OneDrive\Desktop\Projects\databases_v1\venv\lib\site-packages\django\db\backends\utils.py", line 84, in _execute
    return self.cursor.execute(sql, params)
  File "C:\Users\user\OneDrive\Desktop\Projects\databases_v1\venv\lib\site-packages\django\db\utils.py", line 90, in __exit__
    raise dj_exc_value.with_traceback(traceback) from exc_value
  File "C:\Users\user\OneDrive\Desktop\Projects\databases_v1\venv\lib\site-packages\django\db\backends\utils.py", line 82, in _execute
    return self.cursor.execute(sql)
  File "C:\Users\user\OneDrive\Desktop\Projects\databases_v1\venv\lib\site-packages\django\db\backends\sqlite3\base.py", line 421, in execute
    return Database.Cursor.execute(self, query)
django.db.utils.OperationalError: no such table: work_casewhere
ERROR django.server "POST /work/data/get/ HTTP/1.1" 500 140746 2021-08-30 11:33:35,835
ERROR django.request Internal Server Error: /work/data/get/ 2021-08-30 11:35:22,255
Traceback (most recent call last):
  File "C:\Users\user\OneDrive\Desktop\Projects\databases_v1\venv\lib\site-packages\django\db\backends\utils.py", line 82, in _execute
    return self.cursor.execute(sql)
  File "C:\Users\user\OneDrive\Desktop\Projects\databases_v1\venv\lib\site-packages\django\db\backends\sqlite3\base.py", line 421, in execute
    return Database.Cursor.execute(self, query)
sqlite3.OperationalError: no such column: work_tradeunionactivities.name

The above exception was the direct cause of the following exception:

Traceback (most recent call last):
  File "C:\Users\user\OneDrive\Desktop\Projects\databases_v1\venv\lib\site-packages\django\core\handlers\exception.py", line 47, in inner
    response = get_response(request)
  File "C:\Users\user\OneDrive\Desktop\Projects\databases_v1\venv\lib\site-packages\django\core\handlers\base.py", line 181, in _get_response
    response = wrapped_callback(request, *callback_args, **callback_kwargs)
  File "C:\Users\user\OneDrive\Desktop\Projects\databases_v1\venv\lib\site-packages\django\views\decorators\csrf.py", line 54, in wrapped_view
    return view_func(*args, **kwargs)
  File "C:\Users\user\OneDrive\Desktop\Projects\databases_v1\venv\lib\site-packages\django\views\generic\base.py", line 70, in view
    return self.dispatch(request, *args, **kwargs)
  File "C:\Users\user\OneDrive\Desktop\Projects\databases_v1\venv\lib\site-packages\rest_framework\views.py", line 509, in dispatch
    response = self.handle_exception(exc)
  File "C:\Users\user\OneDrive\Desktop\Projects\databases_v1\venv\lib\site-packages\rest_framework\views.py", line 469, in handle_exception
    self.raise_uncaught_exception(exc)
  File "C:\Users\user\OneDrive\Desktop\Projects\databases_v1\venv\lib\site-packages\rest_framework\views.py", line 480, in raise_uncaught_exception
    raise exc
  File "C:\Users\user\OneDrive\Desktop\Projects\databases_v1\venv\lib\site-packages\rest_framework\views.py", line 506, in dispatch
    response = handler(request, *args, **kwargs)
  File "C:\Users\user\OneDrive\Desktop\Projects\databases_v1\databases_v1\work\views.py", line 980, in post
    cursor.execute(sql_query + where_query + group_by_query)
  File "C:\Users\user\OneDrive\Desktop\Projects\databases_v1\venv\lib\site-packages\django\db\backends\utils.py", line 98, in execute
    return super().execute(sql, params)
  File "C:\Users\user\OneDrive\Desktop\Projects\databases_v1\venv\lib\site-packages\django\db\backends\utils.py", line 66, in execute
    return self._execute_with_wrappers(sql, params, many=False, executor=self._execute)
  File "C:\Users\user\OneDrive\Desktop\Projects\databases_v1\venv\lib\site-packages\django\db\backends\utils.py", line 75, in _execute_with_wrappers
    return executor(sql, params, many, context)
  File "C:\Users\user\OneDrive\Desktop\Projects\databases_v1\venv\lib\site-packages\django\db\backends\utils.py", line 84, in _execute
    return self.cursor.execute(sql, params)
  File "C:\Users\user\OneDrive\Desktop\Projects\databases_v1\venv\lib\site-packages\django\db\utils.py", line 90, in __exit__
    raise dj_exc_value.with_traceback(traceback) from exc_value
  File "C:\Users\user\OneDrive\Desktop\Projects\databases_v1\venv\lib\site-packages\django\db\backends\utils.py", line 82, in _execute
    return self.cursor.execute(sql)
  File "C:\Users\user\OneDrive\Desktop\Projects\databases_v1\venv\lib\site-packages\django\db\backends\sqlite3\base.py", line 421, in execute
    return Database.Cursor.execute(self, query)
django.db.utils.OperationalError: no such column: work_tradeunionactivities.name
ERROR django.server "POST /work/data/get/ HTTP/1.1" 500 143446 2021-08-30 11:35:22,259
ERROR django.request Internal Server Error: /work/data/get/ 2021-08-30 11:39:44,452
Traceback (most recent call last):
  File "C:\Users\user\OneDrive\Desktop\Projects\databases_v1\venv\lib\site-packages\django\db\backends\utils.py", line 82, in _execute
    return self.cursor.execute(sql)
  File "C:\Users\user\OneDrive\Desktop\Projects\databases_v1\venv\lib\site-packages\django\db\backends\sqlite3\base.py", line 421, in execute
    return Database.Cursor.execute(self, query)
sqlite3.OperationalError: no such column: work_tradeunionactivities.name

The above exception was the direct cause of the following exception:

Traceback (most recent call last):
  File "C:\Users\user\OneDrive\Desktop\Projects\databases_v1\venv\lib\site-packages\django\core\handlers\exception.py", line 47, in inner
    response = get_response(request)
  File "C:\Users\user\OneDrive\Desktop\Projects\databases_v1\venv\lib\site-packages\django\core\handlers\base.py", line 181, in _get_response
    response = wrapped_callback(request, *callback_args, **callback_kwargs)
  File "C:\Users\user\OneDrive\Desktop\Projects\databases_v1\venv\lib\site-packages\django\views\decorators\csrf.py", line 54, in wrapped_view
    return view_func(*args, **kwargs)
  File "C:\Users\user\OneDrive\Desktop\Projects\databases_v1\venv\lib\site-packages\django\views\generic\base.py", line 70, in view
    return self.dispatch(request, *args, **kwargs)
  File "C:\Users\user\OneDrive\Desktop\Projects\databases_v1\venv\lib\site-packages\rest_framework\views.py", line 509, in dispatch
    response = self.handle_exception(exc)
  File "C:\Users\user\OneDrive\Desktop\Projects\databases_v1\venv\lib\site-packages\rest_framework\views.py", line 469, in handle_exception
    self.raise_uncaught_exception(exc)
  File "C:\Users\user\OneDrive\Desktop\Projects\databases_v1\venv\lib\site-packages\rest_framework\views.py", line 480, in raise_uncaught_exception
    raise exc
  File "C:\Users\user\OneDrive\Desktop\Projects\databases_v1\venv\lib\site-packages\rest_framework\views.py", line 506, in dispatch
    response = handler(request, *args, **kwargs)
  File "C:\Users\user\OneDrive\Desktop\Projects\databases_v1\databases_v1\work\views.py", line 980, in post
    cursor.execute(sql_query + where_query + group_by_query)
  File "C:\Users\user\OneDrive\Desktop\Projects\databases_v1\venv\lib\site-packages\django\db\backends\utils.py", line 98, in execute
    return super().execute(sql, params)
  File "C:\Users\user\OneDrive\Desktop\Projects\databases_v1\venv\lib\site-packages\django\db\backends\utils.py", line 66, in execute
    return self._execute_with_wrappers(sql, params, many=False, executor=self._execute)
  File "C:\Users\user\OneDrive\Desktop\Projects\databases_v1\venv\lib\site-packages\django\db\backends\utils.py", line 75, in _execute_with_wrappers
    return executor(sql, params, many, context)
  File "C:\Users\user\OneDrive\Desktop\Projects\databases_v1\venv\lib\site-packages\django\db\backends\utils.py", line 84, in _execute
    return self.cursor.execute(sql, params)
  File "C:\Users\user\OneDrive\Desktop\Projects\databases_v1\venv\lib\site-packages\django\db\utils.py", line 90, in __exit__
    raise dj_exc_value.with_traceback(traceback) from exc_value
  File "C:\Users\user\OneDrive\Desktop\Projects\databases_v1\venv\lib\site-packages\django\db\backends\utils.py", line 82, in _execute
    return self.cursor.execute(sql)
  File "C:\Users\user\OneDrive\Desktop\Projects\databases_v1\venv\lib\site-packages\django\db\backends\sqlite3\base.py", line 421, in execute
    return Database.Cursor.execute(self, query)
django.db.utils.OperationalError: no such column: work_tradeunionactivities.name
ERROR django.server "POST /work/data/get/ HTTP/1.1" 500 144770 2021-08-30 11:39:44,456
ERROR django.request Internal Server Error: /work/data/get/ 2021-08-30 11:46:25,165
Traceback (most recent call last):
  File "C:\Users\user\OneDrive\Desktop\Projects\databases_v1\venv\lib\site-packages\django\db\backends\utils.py", line 82, in _execute
    return self.cursor.execute(sql)
  File "C:\Users\user\OneDrive\Desktop\Projects\databases_v1\venv\lib\site-packages\django\db\backends\sqlite3\base.py", line 421, in execute
    return Database.Cursor.execute(self, query)
sqlite3.OperationalError: no such column: work_tradeunionactivities.name

The above exception was the direct cause of the following exception:

Traceback (most recent call last):
  File "C:\Users\user\OneDrive\Desktop\Projects\databases_v1\venv\lib\site-packages\django\core\handlers\exception.py", line 47, in inner
    response = get_response(request)
  File "C:\Users\user\OneDrive\Desktop\Projects\databases_v1\venv\lib\site-packages\django\core\handlers\base.py", line 181, in _get_response
    response = wrapped_callback(request, *callback_args, **callback_kwargs)
  File "C:\Users\user\OneDrive\Desktop\Projects\databases_v1\venv\lib\site-packages\django\views\decorators\csrf.py", line 54, in wrapped_view
    return view_func(*args, **kwargs)
  File "C:\Users\user\OneDrive\Desktop\Projects\databases_v1\venv\lib\site-packages\django\views\generic\base.py", line 70, in view
    return self.dispatch(request, *args, **kwargs)
  File "C:\Users\user\OneDrive\Desktop\Projects\databases_v1\venv\lib\site-packages\rest_framework\views.py", line 509, in dispatch
    response = self.handle_exception(exc)
  File "C:\Users\user\OneDrive\Desktop\Projects\databases_v1\venv\lib\site-packages\rest_framework\views.py", line 469, in handle_exception
    self.raise_uncaught_exception(exc)
  File "C:\Users\user\OneDrive\Desktop\Projects\databases_v1\venv\lib\site-packages\rest_framework\views.py", line 480, in raise_uncaught_exception
    raise exc
  File "C:\Users\user\OneDrive\Desktop\Projects\databases_v1\venv\lib\site-packages\rest_framework\views.py", line 506, in dispatch
    response = handler(request, *args, **kwargs)
  File "C:\Users\user\OneDrive\Desktop\Projects\databases_v1\databases_v1\work\views.py", line 981, in post
    cursor.execute(sql_query + where_query + group_by_query)
  File "C:\Users\user\OneDrive\Desktop\Projects\databases_v1\venv\lib\site-packages\django\db\backends\utils.py", line 98, in execute
    return super().execute(sql, params)
  File "C:\Users\user\OneDrive\Desktop\Projects\databases_v1\venv\lib\site-packages\django\db\backends\utils.py", line 66, in execute
    return self._execute_with_wrappers(sql, params, many=False, executor=self._execute)
  File "C:\Users\user\OneDrive\Desktop\Projects\databases_v1\venv\lib\site-packages\django\db\backends\utils.py", line 75, in _execute_with_wrappers
    return executor(sql, params, many, context)
  File "C:\Users\user\OneDrive\Desktop\Projects\databases_v1\venv\lib\site-packages\django\db\backends\utils.py", line 84, in _execute
    return self.cursor.execute(sql, params)
  File "C:\Users\user\OneDrive\Desktop\Projects\databases_v1\venv\lib\site-packages\django\db\utils.py", line 90, in __exit__
    raise dj_exc_value.with_traceback(traceback) from exc_value
  File "C:\Users\user\OneDrive\Desktop\Projects\databases_v1\venv\lib\site-packages\django\db\backends\utils.py", line 82, in _execute
    return self.cursor.execute(sql)
  File "C:\Users\user\OneDrive\Desktop\Projects\databases_v1\venv\lib\site-packages\django\db\backends\sqlite3\base.py", line 421, in execute
    return Database.Cursor.execute(self, query)
django.db.utils.OperationalError: no such column: work_tradeunionactivities.name
ERROR django.request Internal Server Error: /work/data/get/ 2021-08-30 11:46:25,165
Traceback (most recent call last):
  File "C:\Users\user\OneDrive\Desktop\Projects\databases_v1\venv\lib\site-packages\django\db\backends\utils.py", line 82, in _execute
    return self.cursor.execute(sql)
  File "C:\Users\user\OneDrive\Desktop\Projects\databases_v1\venv\lib\site-packages\django\db\backends\sqlite3\base.py", line 421, in execute
    return Database.Cursor.execute(self, query)
sqlite3.OperationalError: no such column: work_tradeunionactivities.name

The above exception was the direct cause of the following exception:

Traceback (most recent call last):
  File "C:\Users\user\OneDrive\Desktop\Projects\databases_v1\venv\lib\site-packages\django\core\handlers\exception.py", line 47, in inner
    response = get_response(request)
  File "C:\Users\user\OneDrive\Desktop\Projects\databases_v1\venv\lib\site-packages\django\core\handlers\base.py", line 181, in _get_response
    response = wrapped_callback(request, *callback_args, **callback_kwargs)
  File "C:\Users\user\OneDrive\Desktop\Projects\databases_v1\venv\lib\site-packages\django\views\decorators\csrf.py", line 54, in wrapped_view
    return view_func(*args, **kwargs)
  File "C:\Users\user\OneDrive\Desktop\Projects\databases_v1\venv\lib\site-packages\django\views\generic\base.py", line 70, in view
    return self.dispatch(request, *args, **kwargs)
  File "C:\Users\user\OneDrive\Desktop\Projects\databases_v1\venv\lib\site-packages\rest_framework\views.py", line 509, in dispatch
    response = self.handle_exception(exc)
  File "C:\Users\user\OneDrive\Desktop\Projects\databases_v1\venv\lib\site-packages\rest_framework\views.py", line 469, in handle_exception
    self.raise_uncaught_exception(exc)
  File "C:\Users\user\OneDrive\Desktop\Projects\databases_v1\venv\lib\site-packages\rest_framework\views.py", line 480, in raise_uncaught_exception
    raise exc
  File "C:\Users\user\OneDrive\Desktop\Projects\databases_v1\venv\lib\site-packages\rest_framework\views.py", line 506, in dispatch
    response = handler(request, *args, **kwargs)
  File "C:\Users\user\OneDrive\Desktop\Projects\databases_v1\databases_v1\work\views.py", line 981, in post
    cursor.execute(sql_query + where_query + group_by_query)
  File "C:\Users\user\OneDrive\Desktop\Projects\databases_v1\venv\lib\site-packages\django\db\backends\utils.py", line 98, in execute
    return super().execute(sql, params)
  File "C:\Users\user\OneDrive\Desktop\Projects\databases_v1\venv\lib\site-packages\django\db\backends\utils.py", line 66, in execute
    return self._execute_with_wrappers(sql, params, many=False, executor=self._execute)
  File "C:\Users\user\OneDrive\Desktop\Projects\databases_v1\venv\lib\site-packages\django\db\backends\utils.py", line 75, in _execute_with_wrappers
    return executor(sql, params, many, context)
  File "C:\Users\user\OneDrive\Desktop\Projects\databases_v1\venv\lib\site-packages\django\db\backends\utils.py", line 84, in _execute
    return self.cursor.execute(sql, params)
  File "C:\Users\user\OneDrive\Desktop\Projects\databases_v1\venv\lib\site-packages\django\db\utils.py", line 90, in __exit__
    raise dj_exc_value.with_traceback(traceback) from exc_value
  File "C:\Users\user\OneDrive\Desktop\Projects\databases_v1\venv\lib\site-packages\django\db\backends\utils.py", line 82, in _execute
    return self.cursor.execute(sql)
  File "C:\Users\user\OneDrive\Desktop\Projects\databases_v1\venv\lib\site-packages\django\db\backends\sqlite3\base.py", line 421, in execute
    return Database.Cursor.execute(self, query)
django.db.utils.OperationalError: no such column: work_tradeunionactivities.name
ERROR django.server "POST /work/data/get/ HTTP/1.1" 500 144770 2021-08-30 11:46:25,177
ERROR django.server "POST /work/data/get/ HTTP/1.1" 500 144770 2021-08-30 11:46:25,177
ERROR django.request Internal Server Error: /work/data/get/ 2021-08-30 11:52:01,422
Traceback (most recent call last):
  File "C:\Users\user\OneDrive\Desktop\Projects\databases_v1\venv\lib\site-packages\django\db\backends\utils.py", line 82, in _execute
    return self.cursor.execute(sql)
  File "C:\Users\user\OneDrive\Desktop\Projects\databases_v1\venv\lib\site-packages\django\db\backends\sqlite3\base.py", line 421, in execute
    return Database.Cursor.execute(self, query)
sqlite3.OperationalError: no such column: work_tradeunionactivities.name

The above exception was the direct cause of the following exception:

Traceback (most recent call last):
  File "C:\Users\user\OneDrive\Desktop\Projects\databases_v1\venv\lib\site-packages\django\core\handlers\exception.py", line 47, in inner
    response = get_response(request)
  File "C:\Users\user\OneDrive\Desktop\Projects\databases_v1\venv\lib\site-packages\django\core\handlers\base.py", line 181, in _get_response
    response = wrapped_callback(request, *callback_args, **callback_kwargs)
  File "C:\Users\user\OneDrive\Desktop\Projects\databases_v1\venv\lib\site-packages\django\views\decorators\csrf.py", line 54, in wrapped_view
    return view_func(*args, **kwargs)
  File "C:\Users\user\OneDrive\Desktop\Projects\databases_v1\venv\lib\site-packages\django\views\generic\base.py", line 70, in view
    return self.dispatch(request, *args, **kwargs)
  File "C:\Users\user\OneDrive\Desktop\Projects\databases_v1\venv\lib\site-packages\rest_framework\views.py", line 509, in dispatch
    response = self.handle_exception(exc)
  File "C:\Users\user\OneDrive\Desktop\Projects\databases_v1\venv\lib\site-packages\rest_framework\views.py", line 469, in handle_exception
    self.raise_uncaught_exception(exc)
  File "C:\Users\user\OneDrive\Desktop\Projects\databases_v1\venv\lib\site-packages\rest_framework\views.py", line 480, in raise_uncaught_exception
    raise exc
  File "C:\Users\user\OneDrive\Desktop\Projects\databases_v1\venv\lib\site-packages\rest_framework\views.py", line 506, in dispatch
    response = handler(request, *args, **kwargs)
  File "C:\Users\user\OneDrive\Desktop\Projects\databases_v1\databases_v1\work\views.py", line 981, in post
    cursor.execute(sql_query + where_query + group_by_query)
  File "C:\Users\user\OneDrive\Desktop\Projects\databases_v1\venv\lib\site-packages\django\db\backends\utils.py", line 98, in execute
    return super().execute(sql, params)
  File "C:\Users\user\OneDrive\Desktop\Projects\databases_v1\venv\lib\site-packages\django\db\backends\utils.py", line 66, in execute
    return self._execute_with_wrappers(sql, params, many=False, executor=self._execute)
  File "C:\Users\user\OneDrive\Desktop\Projects\databases_v1\venv\lib\site-packages\django\db\backends\utils.py", line 75, in _execute_with_wrappers
    return executor(sql, params, many, context)
  File "C:\Users\user\OneDrive\Desktop\Projects\databases_v1\venv\lib\site-packages\django\db\backends\utils.py", line 84, in _execute
    return self.cursor.execute(sql, params)
  File "C:\Users\user\OneDrive\Desktop\Projects\databases_v1\venv\lib\site-packages\django\db\utils.py", line 90, in __exit__
    raise dj_exc_value.with_traceback(traceback) from exc_value
  File "C:\Users\user\OneDrive\Desktop\Projects\databases_v1\venv\lib\site-packages\django\db\backends\utils.py", line 82, in _execute
    return self.cursor.execute(sql)
  File "C:\Users\user\OneDrive\Desktop\Projects\databases_v1\venv\lib\site-packages\django\db\backends\sqlite3\base.py", line 421, in execute
    return Database.Cursor.execute(self, query)
django.db.utils.OperationalError: no such column: work_tradeunionactivities.name
ERROR django.server "POST /work/data/get/ HTTP/1.1" 500 141699 2021-08-30 11:52:01,430
ERROR django.request Internal Server Error: /work/data/get/ 2021-08-30 11:53:18,602
Traceback (most recent call last):
  File "C:\Users\user\OneDrive\Desktop\Projects\databases_v1\venv\lib\site-packages\django\db\backends\utils.py", line 82, in _execute
    return self.cursor.execute(sql)
  File "C:\Users\user\OneDrive\Desktop\Projects\databases_v1\venv\lib\site-packages\django\db\backends\sqlite3\base.py", line 421, in execute
    return Database.Cursor.execute(self, query)
sqlite3.OperationalError: no such column: work_tradeunionactivities.name

The above exception was the direct cause of the following exception:

Traceback (most recent call last):
  File "C:\Users\user\OneDrive\Desktop\Projects\databases_v1\venv\lib\site-packages\django\core\handlers\exception.py", line 47, in inner
    response = get_response(request)
  File "C:\Users\user\OneDrive\Desktop\Projects\databases_v1\venv\lib\site-packages\django\core\handlers\base.py", line 181, in _get_response
    response = wrapped_callback(request, *callback_args, **callback_kwargs)
  File "C:\Users\user\OneDrive\Desktop\Projects\databases_v1\venv\lib\site-packages\django\views\decorators\csrf.py", line 54, in wrapped_view
    return view_func(*args, **kwargs)
  File "C:\Users\user\OneDrive\Desktop\Projects\databases_v1\venv\lib\site-packages\django\views\generic\base.py", line 70, in view
    return self.dispatch(request, *args, **kwargs)
  File "C:\Users\user\OneDrive\Desktop\Projects\databases_v1\venv\lib\site-packages\rest_framework\views.py", line 509, in dispatch
    response = self.handle_exception(exc)
  File "C:\Users\user\OneDrive\Desktop\Projects\databases_v1\venv\lib\site-packages\rest_framework\views.py", line 469, in handle_exception
    self.raise_uncaught_exception(exc)
  File "C:\Users\user\OneDrive\Desktop\Projects\databases_v1\venv\lib\site-packages\rest_framework\views.py", line 480, in raise_uncaught_exception
    raise exc
  File "C:\Users\user\OneDrive\Desktop\Projects\databases_v1\venv\lib\site-packages\rest_framework\views.py", line 506, in dispatch
    response = handler(request, *args, **kwargs)
  File "C:\Users\user\OneDrive\Desktop\Projects\databases_v1\databases_v1\work\views.py", line 981, in post
    cursor.execute(sql_query + where_query + group_by_query)
  File "C:\Users\user\OneDrive\Desktop\Projects\databases_v1\venv\lib\site-packages\django\db\backends\utils.py", line 98, in execute
    return super().execute(sql, params)
  File "C:\Users\user\OneDrive\Desktop\Projects\databases_v1\venv\lib\site-packages\django\db\backends\utils.py", line 66, in execute
    return self._execute_with_wrappers(sql, params, many=False, executor=self._execute)
  File "C:\Users\user\OneDrive\Desktop\Projects\databases_v1\venv\lib\site-packages\django\db\backends\utils.py", line 75, in _execute_with_wrappers
    return executor(sql, params, many, context)
  File "C:\Users\user\OneDrive\Desktop\Projects\databases_v1\venv\lib\site-packages\django\db\backends\utils.py", line 84, in _execute
    return self.cursor.execute(sql, params)
  File "C:\Users\user\OneDrive\Desktop\Projects\databases_v1\venv\lib\site-packages\django\db\utils.py", line 90, in __exit__
    raise dj_exc_value.with_traceback(traceback) from exc_value
  File "C:\Users\user\OneDrive\Desktop\Projects\databases_v1\venv\lib\site-packages\django\db\backends\utils.py", line 82, in _execute
    return self.cursor.execute(sql)
  File "C:\Users\user\OneDrive\Desktop\Projects\databases_v1\venv\lib\site-packages\django\db\backends\sqlite3\base.py", line 421, in execute
    return Database.Cursor.execute(self, query)
django.db.utils.OperationalError: no such column: work_tradeunionactivities.name
ERROR django.server "POST /work/data/get/ HTTP/1.1" 500 141699 2021-08-30 11:53:18,606
ERROR django.request Internal Server Error: /work/data/get/ 2021-08-30 11:53:45,688
Traceback (most recent call last):
  File "C:\Users\user\OneDrive\Desktop\Projects\databases_v1\venv\lib\site-packages\django\db\backends\utils.py", line 82, in _execute
    return self.cursor.execute(sql)
  File "C:\Users\user\OneDrive\Desktop\Projects\databases_v1\venv\lib\site-packages\django\db\backends\sqlite3\base.py", line 421, in execute
    return Database.Cursor.execute(self, query)
sqlite3.OperationalError: no such column: work_tradeunionactivities.name

The above exception was the direct cause of the following exception:

Traceback (most recent call last):
  File "C:\Users\user\OneDrive\Desktop\Projects\databases_v1\venv\lib\site-packages\django\core\handlers\exception.py", line 47, in inner
    response = get_response(request)
  File "C:\Users\user\OneDrive\Desktop\Projects\databases_v1\venv\lib\site-packages\django\core\handlers\base.py", line 181, in _get_response
    response = wrapped_callback(request, *callback_args, **callback_kwargs)
  File "C:\Users\user\OneDrive\Desktop\Projects\databases_v1\venv\lib\site-packages\django\views\decorators\csrf.py", line 54, in wrapped_view
    return view_func(*args, **kwargs)
  File "C:\Users\user\OneDrive\Desktop\Projects\databases_v1\venv\lib\site-packages\django\views\generic\base.py", line 70, in view
    return self.dispatch(request, *args, **kwargs)
  File "C:\Users\user\OneDrive\Desktop\Projects\databases_v1\venv\lib\site-packages\rest_framework\views.py", line 509, in dispatch
    response = self.handle_exception(exc)
  File "C:\Users\user\OneDrive\Desktop\Projects\databases_v1\venv\lib\site-packages\rest_framework\views.py", line 469, in handle_exception
    self.raise_uncaught_exception(exc)
  File "C:\Users\user\OneDrive\Desktop\Projects\databases_v1\venv\lib\site-packages\rest_framework\views.py", line 480, in raise_uncaught_exception
    raise exc
  File "C:\Users\user\OneDrive\Desktop\Projects\databases_v1\venv\lib\site-packages\rest_framework\views.py", line 506, in dispatch
    response = handler(request, *args, **kwargs)
  File "C:\Users\user\OneDrive\Desktop\Projects\databases_v1\databases_v1\work\views.py", line 981, in post
    cursor.execute(sql_query + where_query + group_by_query)
  File "C:\Users\user\OneDrive\Desktop\Projects\databases_v1\venv\lib\site-packages\django\db\backends\utils.py", line 98, in execute
    return super().execute(sql, params)
  File "C:\Users\user\OneDrive\Desktop\Projects\databases_v1\venv\lib\site-packages\django\db\backends\utils.py", line 66, in execute
    return self._execute_with_wrappers(sql, params, many=False, executor=self._execute)
  File "C:\Users\user\OneDrive\Desktop\Projects\databases_v1\venv\lib\site-packages\django\db\backends\utils.py", line 75, in _execute_with_wrappers
    return executor(sql, params, many, context)
  File "C:\Users\user\OneDrive\Desktop\Projects\databases_v1\venv\lib\site-packages\django\db\backends\utils.py", line 84, in _execute
    return self.cursor.execute(sql, params)
  File "C:\Users\user\OneDrive\Desktop\Projects\databases_v1\venv\lib\site-packages\django\db\utils.py", line 90, in __exit__
    raise dj_exc_value.with_traceback(traceback) from exc_value
  File "C:\Users\user\OneDrive\Desktop\Projects\databases_v1\venv\lib\site-packages\django\db\backends\utils.py", line 82, in _execute
    return self.cursor.execute(sql)
  File "C:\Users\user\OneDrive\Desktop\Projects\databases_v1\venv\lib\site-packages\django\db\backends\sqlite3\base.py", line 421, in execute
    return Database.Cursor.execute(self, query)
django.db.utils.OperationalError: no such column: work_tradeunionactivities.name
ERROR django.server "POST /work/data/get/ HTTP/1.1" 500 141699 2021-08-30 11:53:45,696
ERROR django.request Internal Server Error: /work/data/get/ 2021-08-30 11:54:30,356
Traceback (most recent call last):
  File "C:\Users\user\OneDrive\Desktop\Projects\databases_v1\venv\lib\site-packages\django\db\backends\utils.py", line 82, in _execute
    return self.cursor.execute(sql)
  File "C:\Users\user\OneDrive\Desktop\Projects\databases_v1\venv\lib\site-packages\django\db\backends\sqlite3\base.py", line 421, in execute
    return Database.Cursor.execute(self, query)
sqlite3.OperationalError: no such column: work_tradeunionactivities.name

The above exception was the direct cause of the following exception:

Traceback (most recent call last):
  File "C:\Users\user\OneDrive\Desktop\Projects\databases_v1\venv\lib\site-packages\django\core\handlers\exception.py", line 47, in inner
    response = get_response(request)
  File "C:\Users\user\OneDrive\Desktop\Projects\databases_v1\venv\lib\site-packages\django\core\handlers\base.py", line 181, in _get_response
    response = wrapped_callback(request, *callback_args, **callback_kwargs)
  File "C:\Users\user\OneDrive\Desktop\Projects\databases_v1\venv\lib\site-packages\django\views\decorators\csrf.py", line 54, in wrapped_view
    return view_func(*args, **kwargs)
  File "C:\Users\user\OneDrive\Desktop\Projects\databases_v1\venv\lib\site-packages\django\views\generic\base.py", line 70, in view
    return self.dispatch(request, *args, **kwargs)
  File "C:\Users\user\OneDrive\Desktop\Projects\databases_v1\venv\lib\site-packages\rest_framework\views.py", line 509, in dispatch
    response = self.handle_exception(exc)
  File "C:\Users\user\OneDrive\Desktop\Projects\databases_v1\venv\lib\site-packages\rest_framework\views.py", line 469, in handle_exception
    self.raise_uncaught_exception(exc)
  File "C:\Users\user\OneDrive\Desktop\Projects\databases_v1\venv\lib\site-packages\rest_framework\views.py", line 480, in raise_uncaught_exception
    raise exc
  File "C:\Users\user\OneDrive\Desktop\Projects\databases_v1\venv\lib\site-packages\rest_framework\views.py", line 506, in dispatch
    response = handler(request, *args, **kwargs)
  File "C:\Users\user\OneDrive\Desktop\Projects\databases_v1\databases_v1\work\views.py", line 981, in post
    cursor.execute(sql_query + where_query + group_by_query)
  File "C:\Users\user\OneDrive\Desktop\Projects\databases_v1\venv\lib\site-packages\django\db\backends\utils.py", line 98, in execute
    return super().execute(sql, params)
  File "C:\Users\user\OneDrive\Desktop\Projects\databases_v1\venv\lib\site-packages\django\db\backends\utils.py", line 66, in execute
    return self._execute_with_wrappers(sql, params, many=False, executor=self._execute)
  File "C:\Users\user\OneDrive\Desktop\Projects\databases_v1\venv\lib\site-packages\django\db\backends\utils.py", line 75, in _execute_with_wrappers
    return executor(sql, params, many, context)
  File "C:\Users\user\OneDrive\Desktop\Projects\databases_v1\venv\lib\site-packages\django\db\backends\utils.py", line 84, in _execute
    return self.cursor.execute(sql, params)
  File "C:\Users\user\OneDrive\Desktop\Projects\databases_v1\venv\lib\site-packages\django\db\utils.py", line 90, in __exit__
    raise dj_exc_value.with_traceback(traceback) from exc_value
  File "C:\Users\user\OneDrive\Desktop\Projects\databases_v1\venv\lib\site-packages\django\db\backends\utils.py", line 82, in _execute
    return self.cursor.execute(sql)
  File "C:\Users\user\OneDrive\Desktop\Projects\databases_v1\venv\lib\site-packages\django\db\backends\sqlite3\base.py", line 421, in execute
    return Database.Cursor.execute(self, query)
django.db.utils.OperationalError: no such column: work_tradeunionactivities.name
ERROR django.server "POST /work/data/get/ HTTP/1.1" 500 141703 2021-08-30 11:54:30,360
ERROR django.request Internal Server Error: /work/data/get/ 2021-08-30 11:55:05,609
Traceback (most recent call last):
  File "C:\Users\user\OneDrive\Desktop\Projects\databases_v1\venv\lib\site-packages\django\db\backends\utils.py", line 82, in _execute
    return self.cursor.execute(sql)
  File "C:\Users\user\OneDrive\Desktop\Projects\databases_v1\venv\lib\site-packages\django\db\backends\sqlite3\base.py", line 421, in execute
    return Database.Cursor.execute(self, query)
sqlite3.OperationalError: no such column: work_tradeunionactivities.name

The above exception was the direct cause of the following exception:

Traceback (most recent call last):
  File "C:\Users\user\OneDrive\Desktop\Projects\databases_v1\venv\lib\site-packages\django\core\handlers\exception.py", line 47, in inner
    response = get_response(request)
  File "C:\Users\user\OneDrive\Desktop\Projects\databases_v1\venv\lib\site-packages\django\core\handlers\base.py", line 181, in _get_response
    response = wrapped_callback(request, *callback_args, **callback_kwargs)
  File "C:\Users\user\OneDrive\Desktop\Projects\databases_v1\venv\lib\site-packages\django\views\decorators\csrf.py", line 54, in wrapped_view
    return view_func(*args, **kwargs)
  File "C:\Users\user\OneDrive\Desktop\Projects\databases_v1\venv\lib\site-packages\django\views\generic\base.py", line 70, in view
    return self.dispatch(request, *args, **kwargs)
  File "C:\Users\user\OneDrive\Desktop\Projects\databases_v1\venv\lib\site-packages\rest_framework\views.py", line 509, in dispatch
    response = self.handle_exception(exc)
  File "C:\Users\user\OneDrive\Desktop\Projects\databases_v1\venv\lib\site-packages\rest_framework\views.py", line 469, in handle_exception
    self.raise_uncaught_exception(exc)
  File "C:\Users\user\OneDrive\Desktop\Projects\databases_v1\venv\lib\site-packages\rest_framework\views.py", line 480, in raise_uncaught_exception
    raise exc
  File "C:\Users\user\OneDrive\Desktop\Projects\databases_v1\venv\lib\site-packages\rest_framework\views.py", line 506, in dispatch
    response = handler(request, *args, **kwargs)
  File "C:\Users\user\OneDrive\Desktop\Projects\databases_v1\databases_v1\work\views.py", line 981, in post
    cursor.execute(sql_query + where_query + group_by_query)
  File "C:\Users\user\OneDrive\Desktop\Projects\databases_v1\venv\lib\site-packages\django\db\backends\utils.py", line 98, in execute
    return super().execute(sql, params)
  File "C:\Users\user\OneDrive\Desktop\Projects\databases_v1\venv\lib\site-packages\django\db\backends\utils.py", line 66, in execute
    return self._execute_with_wrappers(sql, params, many=False, executor=self._execute)
  File "C:\Users\user\OneDrive\Desktop\Projects\databases_v1\venv\lib\site-packages\django\db\backends\utils.py", line 75, in _execute_with_wrappers
    return executor(sql, params, many, context)
  File "C:\Users\user\OneDrive\Desktop\Projects\databases_v1\venv\lib\site-packages\django\db\backends\utils.py", line 84, in _execute
    return self.cursor.execute(sql, params)
  File "C:\Users\user\OneDrive\Desktop\Projects\databases_v1\venv\lib\site-packages\django\db\utils.py", line 90, in __exit__
    raise dj_exc_value.with_traceback(traceback) from exc_value
  File "C:\Users\user\OneDrive\Desktop\Projects\databases_v1\venv\lib\site-packages\django\db\backends\utils.py", line 82, in _execute
    return self.cursor.execute(sql)
  File "C:\Users\user\OneDrive\Desktop\Projects\databases_v1\venv\lib\site-packages\django\db\backends\sqlite3\base.py", line 421, in execute
    return Database.Cursor.execute(self, query)
django.db.utils.OperationalError: no such column: work_tradeunionactivities.name
ERROR django.server "POST /work/data/get/ HTTP/1.1" 500 141703 2021-08-30 11:55:05,613
ERROR django.request Internal Server Error: /work/data/get/ 2021-08-30 11:55:40,380
Traceback (most recent call last):
  File "C:\Users\user\OneDrive\Desktop\Projects\databases_v1\venv\lib\site-packages\django\db\backends\utils.py", line 82, in _execute
    return self.cursor.execute(sql)
  File "C:\Users\user\OneDrive\Desktop\Projects\databases_v1\venv\lib\site-packages\django\db\backends\sqlite3\base.py", line 421, in execute
    return Database.Cursor.execute(self, query)
sqlite3.OperationalError: no such column: work_tradeunionactivities.name

The above exception was the direct cause of the following exception:

Traceback (most recent call last):
  File "C:\Users\user\OneDrive\Desktop\Projects\databases_v1\venv\lib\site-packages\django\core\handlers\exception.py", line 47, in inner
    response = get_response(request)
  File "C:\Users\user\OneDrive\Desktop\Projects\databases_v1\venv\lib\site-packages\django\core\handlers\base.py", line 181, in _get_response
    response = wrapped_callback(request, *callback_args, **callback_kwargs)
  File "C:\Users\user\OneDrive\Desktop\Projects\databases_v1\venv\lib\site-packages\django\views\decorators\csrf.py", line 54, in wrapped_view
    return view_func(*args, **kwargs)
  File "C:\Users\user\OneDrive\Desktop\Projects\databases_v1\venv\lib\site-packages\django\views\generic\base.py", line 70, in view
    return self.dispatch(request, *args, **kwargs)
  File "C:\Users\user\OneDrive\Desktop\Projects\databases_v1\venv\lib\site-packages\rest_framework\views.py", line 509, in dispatch
    response = self.handle_exception(exc)
  File "C:\Users\user\OneDrive\Desktop\Projects\databases_v1\venv\lib\site-packages\rest_framework\views.py", line 469, in handle_exception
    self.raise_uncaught_exception(exc)
  File "C:\Users\user\OneDrive\Desktop\Projects\databases_v1\venv\lib\site-packages\rest_framework\views.py", line 480, in raise_uncaught_exception
    raise exc
  File "C:\Users\user\OneDrive\Desktop\Projects\databases_v1\venv\lib\site-packages\rest_framework\views.py", line 506, in dispatch
    response = handler(request, *args, **kwargs)
  File "C:\Users\user\OneDrive\Desktop\Projects\databases_v1\databases_v1\work\views.py", line 981, in post
    cursor.execute(sql_query + where_query + group_by_query)
  File "C:\Users\user\OneDrive\Desktop\Projects\databases_v1\venv\lib\site-packages\django\db\backends\utils.py", line 98, in execute
    return super().execute(sql, params)
  File "C:\Users\user\OneDrive\Desktop\Projects\databases_v1\venv\lib\site-packages\django\db\backends\utils.py", line 66, in execute
    return self._execute_with_wrappers(sql, params, many=False, executor=self._execute)
  File "C:\Users\user\OneDrive\Desktop\Projects\databases_v1\venv\lib\site-packages\django\db\backends\utils.py", line 75, in _execute_with_wrappers
    return executor(sql, params, many, context)
  File "C:\Users\user\OneDrive\Desktop\Projects\databases_v1\venv\lib\site-packages\django\db\backends\utils.py", line 84, in _execute
    return self.cursor.execute(sql, params)
  File "C:\Users\user\OneDrive\Desktop\Projects\databases_v1\venv\lib\site-packages\django\db\utils.py", line 90, in __exit__
    raise dj_exc_value.with_traceback(traceback) from exc_value
  File "C:\Users\user\OneDrive\Desktop\Projects\databases_v1\venv\lib\site-packages\django\db\backends\utils.py", line 82, in _execute
    return self.cursor.execute(sql)
  File "C:\Users\user\OneDrive\Desktop\Projects\databases_v1\venv\lib\site-packages\django\db\backends\sqlite3\base.py", line 421, in execute
    return Database.Cursor.execute(self, query)
django.db.utils.OperationalError: no such column: work_tradeunionactivities.name
ERROR django.server "POST /work/data/get/ HTTP/1.1" 500 141703 2021-08-30 11:55:40,396
ERROR django.request Internal Server Error: /work/data/get/ 2021-08-30 11:56:04,658
Traceback (most recent call last):
  File "C:\Users\user\OneDrive\Desktop\Projects\databases_v1\venv\lib\site-packages\django\db\backends\utils.py", line 82, in _execute
    return self.cursor.execute(sql)
  File "C:\Users\user\OneDrive\Desktop\Projects\databases_v1\venv\lib\site-packages\django\db\backends\sqlite3\base.py", line 421, in execute
    return Database.Cursor.execute(self, query)
sqlite3.OperationalError: no such column: work_tradeunionactivities.name

The above exception was the direct cause of the following exception:

Traceback (most recent call last):
  File "C:\Users\user\OneDrive\Desktop\Projects\databases_v1\venv\lib\site-packages\django\core\handlers\exception.py", line 47, in inner
    response = get_response(request)
  File "C:\Users\user\OneDrive\Desktop\Projects\databases_v1\venv\lib\site-packages\django\core\handlers\base.py", line 181, in _get_response
    response = wrapped_callback(request, *callback_args, **callback_kwargs)
  File "C:\Users\user\OneDrive\Desktop\Projects\databases_v1\venv\lib\site-packages\django\views\decorators\csrf.py", line 54, in wrapped_view
    return view_func(*args, **kwargs)
  File "C:\Users\user\OneDrive\Desktop\Projects\databases_v1\venv\lib\site-packages\django\views\generic\base.py", line 70, in view
    return self.dispatch(request, *args, **kwargs)
  File "C:\Users\user\OneDrive\Desktop\Projects\databases_v1\venv\lib\site-packages\rest_framework\views.py", line 509, in dispatch
    response = self.handle_exception(exc)
  File "C:\Users\user\OneDrive\Desktop\Projects\databases_v1\venv\lib\site-packages\rest_framework\views.py", line 469, in handle_exception
    self.raise_uncaught_exception(exc)
  File "C:\Users\user\OneDrive\Desktop\Projects\databases_v1\venv\lib\site-packages\rest_framework\views.py", line 480, in raise_uncaught_exception
    raise exc
  File "C:\Users\user\OneDrive\Desktop\Projects\databases_v1\venv\lib\site-packages\rest_framework\views.py", line 506, in dispatch
    response = handler(request, *args, **kwargs)
  File "C:\Users\user\OneDrive\Desktop\Projects\databases_v1\databases_v1\work\views.py", line 982, in post
    cursor.execute(sql_query + where_query + group_by_query)
  File "C:\Users\user\OneDrive\Desktop\Projects\databases_v1\venv\lib\site-packages\django\db\backends\utils.py", line 98, in execute
    return super().execute(sql, params)
  File "C:\Users\user\OneDrive\Desktop\Projects\databases_v1\venv\lib\site-packages\django\db\backends\utils.py", line 66, in execute
    return self._execute_with_wrappers(sql, params, many=False, executor=self._execute)
  File "C:\Users\user\OneDrive\Desktop\Projects\databases_v1\venv\lib\site-packages\django\db\backends\utils.py", line 75, in _execute_with_wrappers
    return executor(sql, params, many, context)
  File "C:\Users\user\OneDrive\Desktop\Projects\databases_v1\venv\lib\site-packages\django\db\backends\utils.py", line 84, in _execute
    return self.cursor.execute(sql, params)
  File "C:\Users\user\OneDrive\Desktop\Projects\databases_v1\venv\lib\site-packages\django\db\utils.py", line 90, in __exit__
    raise dj_exc_value.with_traceback(traceback) from exc_value
  File "C:\Users\user\OneDrive\Desktop\Projects\databases_v1\venv\lib\site-packages\django\db\backends\utils.py", line 82, in _execute
    return self.cursor.execute(sql)
  File "C:\Users\user\OneDrive\Desktop\Projects\databases_v1\venv\lib\site-packages\django\db\backends\sqlite3\base.py", line 421, in execute
    return Database.Cursor.execute(self, query)
django.db.utils.OperationalError: no such column: work_tradeunionactivities.name
ERROR django.server "POST /work/data/get/ HTTP/1.1" 500 141703 2021-08-30 11:56:04,662
ERROR django.request Internal Server Error: /work/data/get/ 2021-08-30 11:56:41,346
Traceback (most recent call last):
  File "C:\Users\user\OneDrive\Desktop\Projects\databases_v1\venv\lib\site-packages\django\db\backends\utils.py", line 82, in _execute
    return self.cursor.execute(sql)
  File "C:\Users\user\OneDrive\Desktop\Projects\databases_v1\venv\lib\site-packages\django\db\backends\sqlite3\base.py", line 421, in execute
    return Database.Cursor.execute(self, query)
sqlite3.OperationalError: no such column: work_tradeunionactivities.name

The above exception was the direct cause of the following exception:

Traceback (most recent call last):
  File "C:\Users\user\OneDrive\Desktop\Projects\databases_v1\venv\lib\site-packages\django\core\handlers\exception.py", line 47, in inner
    response = get_response(request)
  File "C:\Users\user\OneDrive\Desktop\Projects\databases_v1\venv\lib\site-packages\django\core\handlers\base.py", line 181, in _get_response
    response = wrapped_callback(request, *callback_args, **callback_kwargs)
  File "C:\Users\user\OneDrive\Desktop\Projects\databases_v1\venv\lib\site-packages\django\views\decorators\csrf.py", line 54, in wrapped_view
    return view_func(*args, **kwargs)
  File "C:\Users\user\OneDrive\Desktop\Projects\databases_v1\venv\lib\site-packages\django\views\generic\base.py", line 70, in view
    return self.dispatch(request, *args, **kwargs)
  File "C:\Users\user\OneDrive\Desktop\Projects\databases_v1\venv\lib\site-packages\rest_framework\views.py", line 509, in dispatch
    response = self.handle_exception(exc)
  File "C:\Users\user\OneDrive\Desktop\Projects\databases_v1\venv\lib\site-packages\rest_framework\views.py", line 469, in handle_exception
    self.raise_uncaught_exception(exc)
  File "C:\Users\user\OneDrive\Desktop\Projects\databases_v1\venv\lib\site-packages\rest_framework\views.py", line 480, in raise_uncaught_exception
    raise exc
  File "C:\Users\user\OneDrive\Desktop\Projects\databases_v1\venv\lib\site-packages\rest_framework\views.py", line 506, in dispatch
    response = handler(request, *args, **kwargs)
  File "C:\Users\user\OneDrive\Desktop\Projects\databases_v1\databases_v1\work\views.py", line 982, in post
    cursor.execute(sql_query + where_query + group_by_query)
  File "C:\Users\user\OneDrive\Desktop\Projects\databases_v1\venv\lib\site-packages\django\db\backends\utils.py", line 98, in execute
    return super().execute(sql, params)
  File "C:\Users\user\OneDrive\Desktop\Projects\databases_v1\venv\lib\site-packages\django\db\backends\utils.py", line 66, in execute
    return self._execute_with_wrappers(sql, params, many=False, executor=self._execute)
  File "C:\Users\user\OneDrive\Desktop\Projects\databases_v1\venv\lib\site-packages\django\db\backends\utils.py", line 75, in _execute_with_wrappers
    return executor(sql, params, many, context)
  File "C:\Users\user\OneDrive\Desktop\Projects\databases_v1\venv\lib\site-packages\django\db\backends\utils.py", line 84, in _execute
    return self.cursor.execute(sql, params)
  File "C:\Users\user\OneDrive\Desktop\Projects\databases_v1\venv\lib\site-packages\django\db\utils.py", line 90, in __exit__
    raise dj_exc_value.with_traceback(traceback) from exc_value
  File "C:\Users\user\OneDrive\Desktop\Projects\databases_v1\venv\lib\site-packages\django\db\backends\utils.py", line 82, in _execute
    return self.cursor.execute(sql)
  File "C:\Users\user\OneDrive\Desktop\Projects\databases_v1\venv\lib\site-packages\django\db\backends\sqlite3\base.py", line 421, in execute
    return Database.Cursor.execute(self, query)
django.db.utils.OperationalError: no such column: work_tradeunionactivities.name
ERROR django.server "POST /work/data/get/ HTTP/1.1" 500 141703 2021-08-30 11:56:41,358
ERROR django.request Internal Server Error: /work/data/get/ 2021-08-30 11:56:58,586
Traceback (most recent call last):
  File "C:\Users\user\OneDrive\Desktop\Projects\databases_v1\venv\lib\site-packages\django\db\backends\utils.py", line 82, in _execute
    return self.cursor.execute(sql)
  File "C:\Users\user\OneDrive\Desktop\Projects\databases_v1\venv\lib\site-packages\django\db\backends\sqlite3\base.py", line 421, in execute
    return Database.Cursor.execute(self, query)
sqlite3.OperationalError: no such column: work_tradeunionactivities.name

The above exception was the direct cause of the following exception:

Traceback (most recent call last):
  File "C:\Users\user\OneDrive\Desktop\Projects\databases_v1\venv\lib\site-packages\django\core\handlers\exception.py", line 47, in inner
    response = get_response(request)
  File "C:\Users\user\OneDrive\Desktop\Projects\databases_v1\venv\lib\site-packages\django\core\handlers\base.py", line 181, in _get_response
    response = wrapped_callback(request, *callback_args, **callback_kwargs)
  File "C:\Users\user\OneDrive\Desktop\Projects\databases_v1\venv\lib\site-packages\django\views\decorators\csrf.py", line 54, in wrapped_view
    return view_func(*args, **kwargs)
  File "C:\Users\user\OneDrive\Desktop\Projects\databases_v1\venv\lib\site-packages\django\views\generic\base.py", line 70, in view
    return self.dispatch(request, *args, **kwargs)
  File "C:\Users\user\OneDrive\Desktop\Projects\databases_v1\venv\lib\site-packages\rest_framework\views.py", line 509, in dispatch
    response = self.handle_exception(exc)
  File "C:\Users\user\OneDrive\Desktop\Projects\databases_v1\venv\lib\site-packages\rest_framework\views.py", line 469, in handle_exception
    self.raise_uncaught_exception(exc)
  File "C:\Users\user\OneDrive\Desktop\Projects\databases_v1\venv\lib\site-packages\rest_framework\views.py", line 480, in raise_uncaught_exception
    raise exc
  File "C:\Users\user\OneDrive\Desktop\Projects\databases_v1\venv\lib\site-packages\rest_framework\views.py", line 506, in dispatch
    response = handler(request, *args, **kwargs)
  File "C:\Users\user\OneDrive\Desktop\Projects\databases_v1\databases_v1\work\views.py", line 982, in post
    cursor.execute(sql_query + where_query + group_by_query)
  File "C:\Users\user\OneDrive\Desktop\Projects\databases_v1\venv\lib\site-packages\django\db\backends\utils.py", line 98, in execute
    return super().execute(sql, params)
  File "C:\Users\user\OneDrive\Desktop\Projects\databases_v1\venv\lib\site-packages\django\db\backends\utils.py", line 66, in execute
    return self._execute_with_wrappers(sql, params, many=False, executor=self._execute)
  File "C:\Users\user\OneDrive\Desktop\Projects\databases_v1\venv\lib\site-packages\django\db\backends\utils.py", line 75, in _execute_with_wrappers
    return executor(sql, params, many, context)
  File "C:\Users\user\OneDrive\Desktop\Projects\databases_v1\venv\lib\site-packages\django\db\backends\utils.py", line 84, in _execute
    return self.cursor.execute(sql, params)
  File "C:\Users\user\OneDrive\Desktop\Projects\databases_v1\venv\lib\site-packages\django\db\utils.py", line 90, in __exit__
    raise dj_exc_value.with_traceback(traceback) from exc_value
  File "C:\Users\user\OneDrive\Desktop\Projects\databases_v1\venv\lib\site-packages\django\db\backends\utils.py", line 82, in _execute
    return self.cursor.execute(sql)
  File "C:\Users\user\OneDrive\Desktop\Projects\databases_v1\venv\lib\site-packages\django\db\backends\sqlite3\base.py", line 421, in execute
    return Database.Cursor.execute(self, query)
django.db.utils.OperationalError: no such column: work_tradeunionactivities.name
ERROR django.server "POST /work/data/get/ HTTP/1.1" 500 141703 2021-08-30 11:56:58,598
ERROR django.request Internal Server Error: /work/data/get/ 2021-08-30 11:57:52,947
Traceback (most recent call last):
  File "C:\Users\user\OneDrive\Desktop\Projects\databases_v1\venv\lib\site-packages\django\db\backends\utils.py", line 82, in _execute
    return self.cursor.execute(sql)
  File "C:\Users\user\OneDrive\Desktop\Projects\databases_v1\venv\lib\site-packages\django\db\backends\sqlite3\base.py", line 421, in execute
    return Database.Cursor.execute(self, query)
sqlite3.OperationalError: no such column: work_tradeunionactivities.name

The above exception was the direct cause of the following exception:

Traceback (most recent call last):
  File "C:\Users\user\OneDrive\Desktop\Projects\databases_v1\venv\lib\site-packages\django\core\handlers\exception.py", line 47, in inner
    response = get_response(request)
  File "C:\Users\user\OneDrive\Desktop\Projects\databases_v1\venv\lib\site-packages\django\core\handlers\base.py", line 181, in _get_response
    response = wrapped_callback(request, *callback_args, **callback_kwargs)
  File "C:\Users\user\OneDrive\Desktop\Projects\databases_v1\venv\lib\site-packages\django\views\decorators\csrf.py", line 54, in wrapped_view
    return view_func(*args, **kwargs)
  File "C:\Users\user\OneDrive\Desktop\Projects\databases_v1\venv\lib\site-packages\django\views\generic\base.py", line 70, in view
    return self.dispatch(request, *args, **kwargs)
  File "C:\Users\user\OneDrive\Desktop\Projects\databases_v1\venv\lib\site-packages\rest_framework\views.py", line 509, in dispatch
    response = self.handle_exception(exc)
  File "C:\Users\user\OneDrive\Desktop\Projects\databases_v1\venv\lib\site-packages\rest_framework\views.py", line 469, in handle_exception
    self.raise_uncaught_exception(exc)
  File "C:\Users\user\OneDrive\Desktop\Projects\databases_v1\venv\lib\site-packages\rest_framework\views.py", line 480, in raise_uncaught_exception
    raise exc
  File "C:\Users\user\OneDrive\Desktop\Projects\databases_v1\venv\lib\site-packages\rest_framework\views.py", line 506, in dispatch
    response = handler(request, *args, **kwargs)
  File "C:\Users\user\OneDrive\Desktop\Projects\databases_v1\databases_v1\work\views.py", line 982, in post
    cursor.execute(sql_query + where_query + group_by_query)
  File "C:\Users\user\OneDrive\Desktop\Projects\databases_v1\venv\lib\site-packages\django\db\backends\utils.py", line 98, in execute
    return super().execute(sql, params)
  File "C:\Users\user\OneDrive\Desktop\Projects\databases_v1\venv\lib\site-packages\django\db\backends\utils.py", line 66, in execute
    return self._execute_with_wrappers(sql, params, many=False, executor=self._execute)
  File "C:\Users\user\OneDrive\Desktop\Projects\databases_v1\venv\lib\site-packages\django\db\backends\utils.py", line 75, in _execute_with_wrappers
    return executor(sql, params, many, context)
  File "C:\Users\user\OneDrive\Desktop\Projects\databases_v1\venv\lib\site-packages\django\db\backends\utils.py", line 84, in _execute
    return self.cursor.execute(sql, params)
  File "C:\Users\user\OneDrive\Desktop\Projects\databases_v1\venv\lib\site-packages\django\db\utils.py", line 90, in __exit__
    raise dj_exc_value.with_traceback(traceback) from exc_value
  File "C:\Users\user\OneDrive\Desktop\Projects\databases_v1\venv\lib\site-packages\django\db\backends\utils.py", line 82, in _execute
    return self.cursor.execute(sql)
  File "C:\Users\user\OneDrive\Desktop\Projects\databases_v1\venv\lib\site-packages\django\db\backends\sqlite3\base.py", line 421, in execute
    return Database.Cursor.execute(self, query)
django.db.utils.OperationalError: no such column: work_tradeunionactivities.name
ERROR django.server "POST /work/data/get/ HTTP/1.1" 500 141703 2021-08-30 11:57:52,951
ERROR django.request Internal Server Error: /work/data/get/ 2021-08-30 11:58:39,074
Traceback (most recent call last):
  File "C:\Users\user\OneDrive\Desktop\Projects\databases_v1\venv\lib\site-packages\django\db\backends\utils.py", line 82, in _execute
    return self.cursor.execute(sql)
  File "C:\Users\user\OneDrive\Desktop\Projects\databases_v1\venv\lib\site-packages\django\db\backends\sqlite3\base.py", line 421, in execute
    return Database.Cursor.execute(self, query)
sqlite3.OperationalError: no such column: work_tradeunionactivities.name

The above exception was the direct cause of the following exception:

Traceback (most recent call last):
  File "C:\Users\user\OneDrive\Desktop\Projects\databases_v1\venv\lib\site-packages\django\core\handlers\exception.py", line 47, in inner
    response = get_response(request)
  File "C:\Users\user\OneDrive\Desktop\Projects\databases_v1\venv\lib\site-packages\django\core\handlers\base.py", line 181, in _get_response
    response = wrapped_callback(request, *callback_args, **callback_kwargs)
  File "C:\Users\user\OneDrive\Desktop\Projects\databases_v1\venv\lib\site-packages\django\views\decorators\csrf.py", line 54, in wrapped_view
    return view_func(*args, **kwargs)
  File "C:\Users\user\OneDrive\Desktop\Projects\databases_v1\venv\lib\site-packages\django\views\generic\base.py", line 70, in view
    return self.dispatch(request, *args, **kwargs)
  File "C:\Users\user\OneDrive\Desktop\Projects\databases_v1\venv\lib\site-packages\rest_framework\views.py", line 509, in dispatch
    response = self.handle_exception(exc)
  File "C:\Users\user\OneDrive\Desktop\Projects\databases_v1\venv\lib\site-packages\rest_framework\views.py", line 469, in handle_exception
    self.raise_uncaught_exception(exc)
  File "C:\Users\user\OneDrive\Desktop\Projects\databases_v1\venv\lib\site-packages\rest_framework\views.py", line 480, in raise_uncaught_exception
    raise exc
  File "C:\Users\user\OneDrive\Desktop\Projects\databases_v1\venv\lib\site-packages\rest_framework\views.py", line 506, in dispatch
    response = handler(request, *args, **kwargs)
  File "C:\Users\user\OneDrive\Desktop\Projects\databases_v1\databases_v1\work\views.py", line 982, in post
    cursor.execute(sql_query + where_query + group_by_query)
  File "C:\Users\user\OneDrive\Desktop\Projects\databases_v1\venv\lib\site-packages\django\db\backends\utils.py", line 98, in execute
    return super().execute(sql, params)
  File "C:\Users\user\OneDrive\Desktop\Projects\databases_v1\venv\lib\site-packages\django\db\backends\utils.py", line 66, in execute
    return self._execute_with_wrappers(sql, params, many=False, executor=self._execute)
  File "C:\Users\user\OneDrive\Desktop\Projects\databases_v1\venv\lib\site-packages\django\db\backends\utils.py", line 75, in _execute_with_wrappers
    return executor(sql, params, many, context)
  File "C:\Users\user\OneDrive\Desktop\Projects\databases_v1\venv\lib\site-packages\django\db\backends\utils.py", line 84, in _execute
    return self.cursor.execute(sql, params)
  File "C:\Users\user\OneDrive\Desktop\Projects\databases_v1\venv\lib\site-packages\django\db\utils.py", line 90, in __exit__
    raise dj_exc_value.with_traceback(traceback) from exc_value
  File "C:\Users\user\OneDrive\Desktop\Projects\databases_v1\venv\lib\site-packages\django\db\backends\utils.py", line 82, in _execute
    return self.cursor.execute(sql)
  File "C:\Users\user\OneDrive\Desktop\Projects\databases_v1\venv\lib\site-packages\django\db\backends\sqlite3\base.py", line 421, in execute
    return Database.Cursor.execute(self, query)
django.db.utils.OperationalError: no such column: work_tradeunionactivities.name
ERROR django.server "POST /work/data/get/ HTTP/1.1" 500 141703 2021-08-30 11:58:39,098
ERROR django.request Internal Server Error: /work/data/get/ 2021-08-30 11:59:07,390
Traceback (most recent call last):
  File "C:\Users\user\OneDrive\Desktop\Projects\databases_v1\venv\lib\site-packages\django\db\backends\utils.py", line 82, in _execute
    return self.cursor.execute(sql)
  File "C:\Users\user\OneDrive\Desktop\Projects\databases_v1\venv\lib\site-packages\django\db\backends\sqlite3\base.py", line 421, in execute
    return Database.Cursor.execute(self, query)
sqlite3.OperationalError: no such column: work_tradeunionactivities.name

The above exception was the direct cause of the following exception:

Traceback (most recent call last):
  File "C:\Users\user\OneDrive\Desktop\Projects\databases_v1\venv\lib\site-packages\django\core\handlers\exception.py", line 47, in inner
    response = get_response(request)
  File "C:\Users\user\OneDrive\Desktop\Projects\databases_v1\venv\lib\site-packages\django\core\handlers\base.py", line 181, in _get_response
    response = wrapped_callback(request, *callback_args, **callback_kwargs)
  File "C:\Users\user\OneDrive\Desktop\Projects\databases_v1\venv\lib\site-packages\django\views\decorators\csrf.py", line 54, in wrapped_view
    return view_func(*args, **kwargs)
  File "C:\Users\user\OneDrive\Desktop\Projects\databases_v1\venv\lib\site-packages\django\views\generic\base.py", line 70, in view
    return self.dispatch(request, *args, **kwargs)
  File "C:\Users\user\OneDrive\Desktop\Projects\databases_v1\venv\lib\site-packages\rest_framework\views.py", line 509, in dispatch
    response = self.handle_exception(exc)
  File "C:\Users\user\OneDrive\Desktop\Projects\databases_v1\venv\lib\site-packages\rest_framework\views.py", line 469, in handle_exception
    self.raise_uncaught_exception(exc)
  File "C:\Users\user\OneDrive\Desktop\Projects\databases_v1\venv\lib\site-packages\rest_framework\views.py", line 480, in raise_uncaught_exception
    raise exc
  File "C:\Users\user\OneDrive\Desktop\Projects\databases_v1\venv\lib\site-packages\rest_framework\views.py", line 506, in dispatch
    response = handler(request, *args, **kwargs)
  File "C:\Users\user\OneDrive\Desktop\Projects\databases_v1\databases_v1\work\views.py", line 982, in post
    cursor.execute(sql_query + where_query + group_by_query)
  File "C:\Users\user\OneDrive\Desktop\Projects\databases_v1\venv\lib\site-packages\django\db\backends\utils.py", line 98, in execute
    return super().execute(sql, params)
  File "C:\Users\user\OneDrive\Desktop\Projects\databases_v1\venv\lib\site-packages\django\db\backends\utils.py", line 66, in execute
    return self._execute_with_wrappers(sql, params, many=False, executor=self._execute)
  File "C:\Users\user\OneDrive\Desktop\Projects\databases_v1\venv\lib\site-packages\django\db\backends\utils.py", line 75, in _execute_with_wrappers
    return executor(sql, params, many, context)
  File "C:\Users\user\OneDrive\Desktop\Projects\databases_v1\venv\lib\site-packages\django\db\backends\utils.py", line 84, in _execute
    return self.cursor.execute(sql, params)
  File "C:\Users\user\OneDrive\Desktop\Projects\databases_v1\venv\lib\site-packages\django\db\utils.py", line 90, in __exit__
    raise dj_exc_value.with_traceback(traceback) from exc_value
  File "C:\Users\user\OneDrive\Desktop\Projects\databases_v1\venv\lib\site-packages\django\db\backends\utils.py", line 82, in _execute
    return self.cursor.execute(sql)
  File "C:\Users\user\OneDrive\Desktop\Projects\databases_v1\venv\lib\site-packages\django\db\backends\sqlite3\base.py", line 421, in execute
    return Database.Cursor.execute(self, query)
django.db.utils.OperationalError: no such column: work_tradeunionactivities.name
ERROR django.server "POST /work/data/get/ HTTP/1.1" 500 141703 2021-08-30 11:59:07,394
ERROR django.request Internal Server Error: /work/data/get/ 2021-08-30 11:59:33,182
Traceback (most recent call last):
  File "C:\Users\user\OneDrive\Desktop\Projects\databases_v1\venv\lib\site-packages\django\db\backends\utils.py", line 82, in _execute
    return self.cursor.execute(sql)
  File "C:\Users\user\OneDrive\Desktop\Projects\databases_v1\venv\lib\site-packages\django\db\backends\sqlite3\base.py", line 421, in execute
    return Database.Cursor.execute(self, query)
sqlite3.OperationalError: no such column: work_tradeunionactivities.name

The above exception was the direct cause of the following exception:

Traceback (most recent call last):
  File "C:\Users\user\OneDrive\Desktop\Projects\databases_v1\venv\lib\site-packages\django\core\handlers\exception.py", line 47, in inner
    response = get_response(request)
  File "C:\Users\user\OneDrive\Desktop\Projects\databases_v1\venv\lib\site-packages\django\core\handlers\base.py", line 181, in _get_response
    response = wrapped_callback(request, *callback_args, **callback_kwargs)
  File "C:\Users\user\OneDrive\Desktop\Projects\databases_v1\venv\lib\site-packages\django\views\decorators\csrf.py", line 54, in wrapped_view
    return view_func(*args, **kwargs)
  File "C:\Users\user\OneDrive\Desktop\Projects\databases_v1\venv\lib\site-packages\django\views\generic\base.py", line 70, in view
    return self.dispatch(request, *args, **kwargs)
  File "C:\Users\user\OneDrive\Desktop\Projects\databases_v1\venv\lib\site-packages\rest_framework\views.py", line 509, in dispatch
    response = self.handle_exception(exc)
  File "C:\Users\user\OneDrive\Desktop\Projects\databases_v1\venv\lib\site-packages\rest_framework\views.py", line 469, in handle_exception
    self.raise_uncaught_exception(exc)
  File "C:\Users\user\OneDrive\Desktop\Projects\databases_v1\venv\lib\site-packages\rest_framework\views.py", line 480, in raise_uncaught_exception
    raise exc
  File "C:\Users\user\OneDrive\Desktop\Projects\databases_v1\venv\lib\site-packages\rest_framework\views.py", line 506, in dispatch
    response = handler(request, *args, **kwargs)
  File "C:\Users\user\OneDrive\Desktop\Projects\databases_v1\databases_v1\work\views.py", line 982, in post
    cursor.execute(sql_query + where_query + group_by_query)
  File "C:\Users\user\OneDrive\Desktop\Projects\databases_v1\venv\lib\site-packages\django\db\backends\utils.py", line 98, in execute
    return super().execute(sql, params)
  File "C:\Users\user\OneDrive\Desktop\Projects\databases_v1\venv\lib\site-packages\django\db\backends\utils.py", line 66, in execute
    return self._execute_with_wrappers(sql, params, many=False, executor=self._execute)
  File "C:\Users\user\OneDrive\Desktop\Projects\databases_v1\venv\lib\site-packages\django\db\backends\utils.py", line 75, in _execute_with_wrappers
    return executor(sql, params, many, context)
  File "C:\Users\user\OneDrive\Desktop\Projects\databases_v1\venv\lib\site-packages\django\db\backends\utils.py", line 84, in _execute
    return self.cursor.execute(sql, params)
  File "C:\Users\user\OneDrive\Desktop\Projects\databases_v1\venv\lib\site-packages\django\db\utils.py", line 90, in __exit__
    raise dj_exc_value.with_traceback(traceback) from exc_value
  File "C:\Users\user\OneDrive\Desktop\Projects\databases_v1\venv\lib\site-packages\django\db\backends\utils.py", line 82, in _execute
    return self.cursor.execute(sql)
  File "C:\Users\user\OneDrive\Desktop\Projects\databases_v1\venv\lib\site-packages\django\db\backends\sqlite3\base.py", line 421, in execute
    return Database.Cursor.execute(self, query)
django.db.utils.OperationalError: no such column: work_tradeunionactivities.name
ERROR django.server "POST /work/data/get/ HTTP/1.1" 500 141703 2021-08-30 11:59:33,186
ERROR django.request Internal Server Error: /work/data/get/ 2021-08-30 12:00:16,794
Traceback (most recent call last):
  File "C:\Users\user\OneDrive\Desktop\Projects\databases_v1\venv\lib\site-packages\django\db\backends\utils.py", line 82, in _execute
    return self.cursor.execute(sql)
  File "C:\Users\user\OneDrive\Desktop\Projects\databases_v1\venv\lib\site-packages\django\db\backends\sqlite3\base.py", line 421, in execute
    return Database.Cursor.execute(self, query)
sqlite3.OperationalError: no such column: work_tradeunionactivities.name

The above exception was the direct cause of the following exception:

Traceback (most recent call last):
  File "C:\Users\user\OneDrive\Desktop\Projects\databases_v1\venv\lib\site-packages\django\core\handlers\exception.py", line 47, in inner
    response = get_response(request)
  File "C:\Users\user\OneDrive\Desktop\Projects\databases_v1\venv\lib\site-packages\django\core\handlers\base.py", line 181, in _get_response
    response = wrapped_callback(request, *callback_args, **callback_kwargs)
  File "C:\Users\user\OneDrive\Desktop\Projects\databases_v1\venv\lib\site-packages\django\views\decorators\csrf.py", line 54, in wrapped_view
    return view_func(*args, **kwargs)
  File "C:\Users\user\OneDrive\Desktop\Projects\databases_v1\venv\lib\site-packages\django\views\generic\base.py", line 70, in view
    return self.dispatch(request, *args, **kwargs)
  File "C:\Users\user\OneDrive\Desktop\Projects\databases_v1\venv\lib\site-packages\rest_framework\views.py", line 509, in dispatch
    response = self.handle_exception(exc)
  File "C:\Users\user\OneDrive\Desktop\Projects\databases_v1\venv\lib\site-packages\rest_framework\views.py", line 469, in handle_exception
    self.raise_uncaught_exception(exc)
  File "C:\Users\user\OneDrive\Desktop\Projects\databases_v1\venv\lib\site-packages\rest_framework\views.py", line 480, in raise_uncaught_exception
    raise exc
  File "C:\Users\user\OneDrive\Desktop\Projects\databases_v1\venv\lib\site-packages\rest_framework\views.py", line 506, in dispatch
    response = handler(request, *args, **kwargs)
  File "C:\Users\user\OneDrive\Desktop\Projects\databases_v1\databases_v1\work\views.py", line 982, in post
    cursor.execute(sql_query + where_query + group_by_query)
  File "C:\Users\user\OneDrive\Desktop\Projects\databases_v1\venv\lib\site-packages\django\db\backends\utils.py", line 98, in execute
    return super().execute(sql, params)
  File "C:\Users\user\OneDrive\Desktop\Projects\databases_v1\venv\lib\site-packages\django\db\backends\utils.py", line 66, in execute
    return self._execute_with_wrappers(sql, params, many=False, executor=self._execute)
  File "C:\Users\user\OneDrive\Desktop\Projects\databases_v1\venv\lib\site-packages\django\db\backends\utils.py", line 75, in _execute_with_wrappers
    return executor(sql, params, many, context)
  File "C:\Users\user\OneDrive\Desktop\Projects\databases_v1\venv\lib\site-packages\django\db\backends\utils.py", line 84, in _execute
    return self.cursor.execute(sql, params)
  File "C:\Users\user\OneDrive\Desktop\Projects\databases_v1\venv\lib\site-packages\django\db\utils.py", line 90, in __exit__
    raise dj_exc_value.with_traceback(traceback) from exc_value
  File "C:\Users\user\OneDrive\Desktop\Projects\databases_v1\venv\lib\site-packages\django\db\backends\utils.py", line 82, in _execute
    return self.cursor.execute(sql)
  File "C:\Users\user\OneDrive\Desktop\Projects\databases_v1\venv\lib\site-packages\django\db\backends\sqlite3\base.py", line 421, in execute
    return Database.Cursor.execute(self, query)
django.db.utils.OperationalError: no such column: work_tradeunionactivities.name
ERROR django.server "POST /work/data/get/ HTTP/1.1" 500 141703 2021-08-30 12:00:16,802
ERROR django.request Internal Server Error: /work/data/get/ 2021-08-30 12:00:46,661
Traceback (most recent call last):
  File "C:\Users\user\OneDrive\Desktop\Projects\databases_v1\venv\lib\site-packages\django\db\backends\utils.py", line 82, in _execute
    return self.cursor.execute(sql)
  File "C:\Users\user\OneDrive\Desktop\Projects\databases_v1\venv\lib\site-packages\django\db\backends\sqlite3\base.py", line 421, in execute
    return Database.Cursor.execute(self, query)
sqlite3.OperationalError: no such column: work_tradeunionactivities.name

The above exception was the direct cause of the following exception:

Traceback (most recent call last):
  File "C:\Users\user\OneDrive\Desktop\Projects\databases_v1\venv\lib\site-packages\django\core\handlers\exception.py", line 47, in inner
    response = get_response(request)
  File "C:\Users\user\OneDrive\Desktop\Projects\databases_v1\venv\lib\site-packages\django\core\handlers\base.py", line 181, in _get_response
    response = wrapped_callback(request, *callback_args, **callback_kwargs)
  File "C:\Users\user\OneDrive\Desktop\Projects\databases_v1\venv\lib\site-packages\django\views\decorators\csrf.py", line 54, in wrapped_view
    return view_func(*args, **kwargs)
  File "C:\Users\user\OneDrive\Desktop\Projects\databases_v1\venv\lib\site-packages\django\views\generic\base.py", line 70, in view
    return self.dispatch(request, *args, **kwargs)
  File "C:\Users\user\OneDrive\Desktop\Projects\databases_v1\venv\lib\site-packages\rest_framework\views.py", line 509, in dispatch
    response = self.handle_exception(exc)
  File "C:\Users\user\OneDrive\Desktop\Projects\databases_v1\venv\lib\site-packages\rest_framework\views.py", line 469, in handle_exception
    self.raise_uncaught_exception(exc)
  File "C:\Users\user\OneDrive\Desktop\Projects\databases_v1\venv\lib\site-packages\rest_framework\views.py", line 480, in raise_uncaught_exception
    raise exc
  File "C:\Users\user\OneDrive\Desktop\Projects\databases_v1\venv\lib\site-packages\rest_framework\views.py", line 506, in dispatch
    response = handler(request, *args, **kwargs)
  File "C:\Users\user\OneDrive\Desktop\Projects\databases_v1\databases_v1\work\views.py", line 984, in post
    cursor.execute(sql_query + where_query + group_by_query)
  File "C:\Users\user\OneDrive\Desktop\Projects\databases_v1\venv\lib\site-packages\django\db\backends\utils.py", line 98, in execute
    return super().execute(sql, params)
  File "C:\Users\user\OneDrive\Desktop\Projects\databases_v1\venv\lib\site-packages\django\db\backends\utils.py", line 66, in execute
    return self._execute_with_wrappers(sql, params, many=False, executor=self._execute)
  File "C:\Users\user\OneDrive\Desktop\Projects\databases_v1\venv\lib\site-packages\django\db\backends\utils.py", line 75, in _execute_with_wrappers
    return executor(sql, params, many, context)
  File "C:\Users\user\OneDrive\Desktop\Projects\databases_v1\venv\lib\site-packages\django\db\backends\utils.py", line 84, in _execute
    return self.cursor.execute(sql, params)
  File "C:\Users\user\OneDrive\Desktop\Projects\databases_v1\venv\lib\site-packages\django\db\utils.py", line 90, in __exit__
    raise dj_exc_value.with_traceback(traceback) from exc_value
  File "C:\Users\user\OneDrive\Desktop\Projects\databases_v1\venv\lib\site-packages\django\db\backends\utils.py", line 82, in _execute
    return self.cursor.execute(sql)
  File "C:\Users\user\OneDrive\Desktop\Projects\databases_v1\venv\lib\site-packages\django\db\backends\sqlite3\base.py", line 421, in execute
    return Database.Cursor.execute(self, query)
django.db.utils.OperationalError: no such column: work_tradeunionactivities.name
ERROR django.server "POST /work/data/get/ HTTP/1.1" 500 141703 2021-08-30 12:00:46,667
ERROR django.request Internal Server Error: /work/data/get/ 2021-08-30 12:00:55,944
Traceback (most recent call last):
  File "C:\Users\user\OneDrive\Desktop\Projects\databases_v1\venv\lib\site-packages\django\db\backends\utils.py", line 82, in _execute
    return self.cursor.execute(sql)
  File "C:\Users\user\OneDrive\Desktop\Projects\databases_v1\venv\lib\site-packages\django\db\backends\sqlite3\base.py", line 421, in execute
    return Database.Cursor.execute(self, query)
sqlite3.OperationalError: no such table: work_casewhere

The above exception was the direct cause of the following exception:

Traceback (most recent call last):
  File "C:\Users\user\OneDrive\Desktop\Projects\databases_v1\venv\lib\site-packages\django\core\handlers\exception.py", line 47, in inner
    response = get_response(request)
  File "C:\Users\user\OneDrive\Desktop\Projects\databases_v1\venv\lib\site-packages\django\core\handlers\base.py", line 181, in _get_response
    response = wrapped_callback(request, *callback_args, **callback_kwargs)
  File "C:\Users\user\OneDrive\Desktop\Projects\databases_v1\venv\lib\site-packages\django\views\decorators\csrf.py", line 54, in wrapped_view
    return view_func(*args, **kwargs)
  File "C:\Users\user\OneDrive\Desktop\Projects\databases_v1\venv\lib\site-packages\django\views\generic\base.py", line 70, in view
    return self.dispatch(request, *args, **kwargs)
  File "C:\Users\user\OneDrive\Desktop\Projects\databases_v1\venv\lib\site-packages\rest_framework\views.py", line 509, in dispatch
    response = self.handle_exception(exc)
  File "C:\Users\user\OneDrive\Desktop\Projects\databases_v1\venv\lib\site-packages\rest_framework\views.py", line 469, in handle_exception
    self.raise_uncaught_exception(exc)
  File "C:\Users\user\OneDrive\Desktop\Projects\databases_v1\venv\lib\site-packages\rest_framework\views.py", line 480, in raise_uncaught_exception
    raise exc
  File "C:\Users\user\OneDrive\Desktop\Projects\databases_v1\venv\lib\site-packages\rest_framework\views.py", line 506, in dispatch
    response = handler(request, *args, **kwargs)
  File "C:\Users\user\OneDrive\Desktop\Projects\databases_v1\databases_v1\work\views.py", line 984, in post
    cursor.execute(sql_query + where_query + group_by_query)
  File "C:\Users\user\OneDrive\Desktop\Projects\databases_v1\venv\lib\site-packages\django\db\backends\utils.py", line 98, in execute
    return super().execute(sql, params)
  File "C:\Users\user\OneDrive\Desktop\Projects\databases_v1\venv\lib\site-packages\django\db\backends\utils.py", line 66, in execute
    return self._execute_with_wrappers(sql, params, many=False, executor=self._execute)
  File "C:\Users\user\OneDrive\Desktop\Projects\databases_v1\venv\lib\site-packages\django\db\backends\utils.py", line 75, in _execute_with_wrappers
    return executor(sql, params, many, context)
  File "C:\Users\user\OneDrive\Desktop\Projects\databases_v1\venv\lib\site-packages\django\db\backends\utils.py", line 84, in _execute
    return self.cursor.execute(sql, params)
  File "C:\Users\user\OneDrive\Desktop\Projects\databases_v1\venv\lib\site-packages\django\db\utils.py", line 90, in __exit__
    raise dj_exc_value.with_traceback(traceback) from exc_value
  File "C:\Users\user\OneDrive\Desktop\Projects\databases_v1\venv\lib\site-packages\django\db\backends\utils.py", line 82, in _execute
    return self.cursor.execute(sql)
  File "C:\Users\user\OneDrive\Desktop\Projects\databases_v1\venv\lib\site-packages\django\db\backends\sqlite3\base.py", line 421, in execute
    return Database.Cursor.execute(self, query)
django.db.utils.OperationalError: no such table: work_casewhere
ERROR django.server "POST /work/data/get/ HTTP/1.1" 500 140750 2021-08-30 12:00:55,948
ERROR django.request Internal Server Error: /work/data/get/ 2021-08-30 12:01:55,648
Traceback (most recent call last):
  File "C:\Users\user\OneDrive\Desktop\Projects\databases_v1\venv\lib\site-packages\django\db\backends\utils.py", line 82, in _execute
    return self.cursor.execute(sql)
  File "C:\Users\user\OneDrive\Desktop\Projects\databases_v1\venv\lib\site-packages\django\db\backends\sqlite3\base.py", line 421, in execute
    return Database.Cursor.execute(self, query)
sqlite3.OperationalError: no such table: work_casewhere

The above exception was the direct cause of the following exception:

Traceback (most recent call last):
  File "C:\Users\user\OneDrive\Desktop\Projects\databases_v1\venv\lib\site-packages\django\core\handlers\exception.py", line 47, in inner
    response = get_response(request)
  File "C:\Users\user\OneDrive\Desktop\Projects\databases_v1\venv\lib\site-packages\django\core\handlers\base.py", line 181, in _get_response
    response = wrapped_callback(request, *callback_args, **callback_kwargs)
  File "C:\Users\user\OneDrive\Desktop\Projects\databases_v1\venv\lib\site-packages\django\views\decorators\csrf.py", line 54, in wrapped_view
    return view_func(*args, **kwargs)
  File "C:\Users\user\OneDrive\Desktop\Projects\databases_v1\venv\lib\site-packages\django\views\generic\base.py", line 70, in view
    return self.dispatch(request, *args, **kwargs)
  File "C:\Users\user\OneDrive\Desktop\Projects\databases_v1\venv\lib\site-packages\rest_framework\views.py", line 509, in dispatch
    response = self.handle_exception(exc)
  File "C:\Users\user\OneDrive\Desktop\Projects\databases_v1\venv\lib\site-packages\rest_framework\views.py", line 469, in handle_exception
    self.raise_uncaught_exception(exc)
  File "C:\Users\user\OneDrive\Desktop\Projects\databases_v1\venv\lib\site-packages\rest_framework\views.py", line 480, in raise_uncaught_exception
    raise exc
  File "C:\Users\user\OneDrive\Desktop\Projects\databases_v1\venv\lib\site-packages\rest_framework\views.py", line 506, in dispatch
    response = handler(request, *args, **kwargs)
  File "C:\Users\user\OneDrive\Desktop\Projects\databases_v1\databases_v1\work\views.py", line 986, in post
    cursor.execute(sql_query + where_query + group_by_query)
  File "C:\Users\user\OneDrive\Desktop\Projects\databases_v1\venv\lib\site-packages\django\db\backends\utils.py", line 98, in execute
    return super().execute(sql, params)
  File "C:\Users\user\OneDrive\Desktop\Projects\databases_v1\venv\lib\site-packages\django\db\backends\utils.py", line 66, in execute
    return self._execute_with_wrappers(sql, params, many=False, executor=self._execute)
  File "C:\Users\user\OneDrive\Desktop\Projects\databases_v1\venv\lib\site-packages\django\db\backends\utils.py", line 75, in _execute_with_wrappers
    return executor(sql, params, many, context)
  File "C:\Users\user\OneDrive\Desktop\Projects\databases_v1\venv\lib\site-packages\django\db\backends\utils.py", line 84, in _execute
    return self.cursor.execute(sql, params)
  File "C:\Users\user\OneDrive\Desktop\Projects\databases_v1\venv\lib\site-packages\django\db\utils.py", line 90, in __exit__
    raise dj_exc_value.with_traceback(traceback) from exc_value
  File "C:\Users\user\OneDrive\Desktop\Projects\databases_v1\venv\lib\site-packages\django\db\backends\utils.py", line 82, in _execute
    return self.cursor.execute(sql)
  File "C:\Users\user\OneDrive\Desktop\Projects\databases_v1\venv\lib\site-packages\django\db\backends\sqlite3\base.py", line 421, in execute
    return Database.Cursor.execute(self, query)
django.db.utils.OperationalError: no such table: work_casewhere
ERROR django.server "POST /work/data/get/ HTTP/1.1" 500 140750 2021-08-30 12:01:55,656
ERROR django.request Internal Server Error: /work/data/get/ 2021-08-30 12:02:46,506
Traceback (most recent call last):
  File "C:\Users\user\OneDrive\Desktop\Projects\databases_v1\venv\lib\site-packages\django\db\backends\utils.py", line 82, in _execute
    return self.cursor.execute(sql)
  File "C:\Users\user\OneDrive\Desktop\Projects\databases_v1\venv\lib\site-packages\django\db\backends\sqlite3\base.py", line 421, in execute
    return Database.Cursor.execute(self, query)
sqlite3.OperationalError: no such table: work_casewhere

The above exception was the direct cause of the following exception:

Traceback (most recent call last):
  File "C:\Users\user\OneDrive\Desktop\Projects\databases_v1\venv\lib\site-packages\django\core\handlers\exception.py", line 47, in inner
    response = get_response(request)
  File "C:\Users\user\OneDrive\Desktop\Projects\databases_v1\venv\lib\site-packages\django\core\handlers\base.py", line 181, in _get_response
    response = wrapped_callback(request, *callback_args, **callback_kwargs)
  File "C:\Users\user\OneDrive\Desktop\Projects\databases_v1\venv\lib\site-packages\django\views\decorators\csrf.py", line 54, in wrapped_view
    return view_func(*args, **kwargs)
  File "C:\Users\user\OneDrive\Desktop\Projects\databases_v1\venv\lib\site-packages\django\views\generic\base.py", line 70, in view
    return self.dispatch(request, *args, **kwargs)
  File "C:\Users\user\OneDrive\Desktop\Projects\databases_v1\venv\lib\site-packages\rest_framework\views.py", line 509, in dispatch
    response = self.handle_exception(exc)
  File "C:\Users\user\OneDrive\Desktop\Projects\databases_v1\venv\lib\site-packages\rest_framework\views.py", line 469, in handle_exception
    self.raise_uncaught_exception(exc)
  File "C:\Users\user\OneDrive\Desktop\Projects\databases_v1\venv\lib\site-packages\rest_framework\views.py", line 480, in raise_uncaught_exception
    raise exc
  File "C:\Users\user\OneDrive\Desktop\Projects\databases_v1\venv\lib\site-packages\rest_framework\views.py", line 506, in dispatch
    response = handler(request, *args, **kwargs)
  File "C:\Users\user\OneDrive\Desktop\Projects\databases_v1\databases_v1\work\views.py", line 987, in post
    cursor.execute(sql_query + where_query + group_by_query)
  File "C:\Users\user\OneDrive\Desktop\Projects\databases_v1\venv\lib\site-packages\django\db\backends\utils.py", line 98, in execute
    return super().execute(sql, params)
  File "C:\Users\user\OneDrive\Desktop\Projects\databases_v1\venv\lib\site-packages\django\db\backends\utils.py", line 66, in execute
    return self._execute_with_wrappers(sql, params, many=False, executor=self._execute)
  File "C:\Users\user\OneDrive\Desktop\Projects\databases_v1\venv\lib\site-packages\django\db\backends\utils.py", line 75, in _execute_with_wrappers
    return executor(sql, params, many, context)
  File "C:\Users\user\OneDrive\Desktop\Projects\databases_v1\venv\lib\site-packages\django\db\backends\utils.py", line 84, in _execute
    return self.cursor.execute(sql, params)
  File "C:\Users\user\OneDrive\Desktop\Projects\databases_v1\venv\lib\site-packages\django\db\utils.py", line 90, in __exit__
    raise dj_exc_value.with_traceback(traceback) from exc_value
  File "C:\Users\user\OneDrive\Desktop\Projects\databases_v1\venv\lib\site-packages\django\db\backends\utils.py", line 82, in _execute
    return self.cursor.execute(sql)
  File "C:\Users\user\OneDrive\Desktop\Projects\databases_v1\venv\lib\site-packages\django\db\backends\sqlite3\base.py", line 421, in execute
    return Database.Cursor.execute(self, query)
django.db.utils.OperationalError: no such table: work_casewhere
ERROR django.server "POST /work/data/get/ HTTP/1.1" 500 140750 2021-08-30 12:02:46,509
ERROR django.request Internal Server Error: /work/data/get/ 2021-08-30 12:04:18,308
Traceback (most recent call last):
  File "C:\Users\user\OneDrive\Desktop\Projects\databases_v1\venv\lib\site-packages\django\core\handlers\exception.py", line 47, in inner
    response = get_response(request)
  File "C:\Users\user\OneDrive\Desktop\Projects\databases_v1\venv\lib\site-packages\django\core\handlers\base.py", line 181, in _get_response
    response = wrapped_callback(request, *callback_args, **callback_kwargs)
  File "C:\Users\user\OneDrive\Desktop\Projects\databases_v1\venv\lib\site-packages\django\views\decorators\csrf.py", line 54, in wrapped_view
    return view_func(*args, **kwargs)
  File "C:\Users\user\OneDrive\Desktop\Projects\databases_v1\venv\lib\site-packages\django\views\generic\base.py", line 70, in view
    return self.dispatch(request, *args, **kwargs)
  File "C:\Users\user\OneDrive\Desktop\Projects\databases_v1\venv\lib\site-packages\rest_framework\views.py", line 509, in dispatch
    response = self.handle_exception(exc)
  File "C:\Users\user\OneDrive\Desktop\Projects\databases_v1\venv\lib\site-packages\rest_framework\views.py", line 469, in handle_exception
    self.raise_uncaught_exception(exc)
  File "C:\Users\user\OneDrive\Desktop\Projects\databases_v1\venv\lib\site-packages\rest_framework\views.py", line 480, in raise_uncaught_exception
    raise exc
  File "C:\Users\user\OneDrive\Desktop\Projects\databases_v1\venv\lib\site-packages\rest_framework\views.py", line 506, in dispatch
    response = handler(request, *args, **kwargs)
  File "C:\Users\user\OneDrive\Desktop\Projects\databases_v1\databases_v1\work\views.py", line 980, in post
    print(id)
UnboundLocalError: local variable 'id' referenced before assignment
ERROR django.server "POST /work/data/get/ HTTP/1.1" 500 98386 2021-08-30 12:04:18,311
ERROR django.request Internal Server Error: /work/data/get/ 2021-08-30 12:04:52,817
Traceback (most recent call last):
  File "C:\Users\user\OneDrive\Desktop\Projects\databases_v1\venv\lib\site-packages\django\db\backends\utils.py", line 82, in _execute
    return self.cursor.execute(sql)
  File "C:\Users\user\OneDrive\Desktop\Projects\databases_v1\venv\lib\site-packages\django\db\backends\sqlite3\base.py", line 421, in execute
    return Database.Cursor.execute(self, query)
sqlite3.OperationalError: no such table: work_casewhere

The above exception was the direct cause of the following exception:

Traceback (most recent call last):
  File "C:\Users\user\OneDrive\Desktop\Projects\databases_v1\venv\lib\site-packages\django\core\handlers\exception.py", line 47, in inner
    response = get_response(request)
  File "C:\Users\user\OneDrive\Desktop\Projects\databases_v1\venv\lib\site-packages\django\core\handlers\base.py", line 181, in _get_response
    response = wrapped_callback(request, *callback_args, **callback_kwargs)
  File "C:\Users\user\OneDrive\Desktop\Projects\databases_v1\venv\lib\site-packages\django\views\decorators\csrf.py", line 54, in wrapped_view
    return view_func(*args, **kwargs)
  File "C:\Users\user\OneDrive\Desktop\Projects\databases_v1\venv\lib\site-packages\django\views\generic\base.py", line 70, in view
    return self.dispatch(request, *args, **kwargs)
  File "C:\Users\user\OneDrive\Desktop\Projects\databases_v1\venv\lib\site-packages\rest_framework\views.py", line 509, in dispatch
    response = self.handle_exception(exc)
  File "C:\Users\user\OneDrive\Desktop\Projects\databases_v1\venv\lib\site-packages\rest_framework\views.py", line 469, in handle_exception
    self.raise_uncaught_exception(exc)
  File "C:\Users\user\OneDrive\Desktop\Projects\databases_v1\venv\lib\site-packages\rest_framework\views.py", line 480, in raise_uncaught_exception
    raise exc
  File "C:\Users\user\OneDrive\Desktop\Projects\databases_v1\venv\lib\site-packages\rest_framework\views.py", line 506, in dispatch
    response = handler(request, *args, **kwargs)
  File "C:\Users\user\OneDrive\Desktop\Projects\databases_v1\databases_v1\work\views.py", line 988, in post
    cursor.execute(sql_query + where_query + group_by_query)
  File "C:\Users\user\OneDrive\Desktop\Projects\databases_v1\venv\lib\site-packages\django\db\backends\utils.py", line 98, in execute
    return super().execute(sql, params)
  File "C:\Users\user\OneDrive\Desktop\Projects\databases_v1\venv\lib\site-packages\django\db\backends\utils.py", line 66, in execute
    return self._execute_with_wrappers(sql, params, many=False, executor=self._execute)
  File "C:\Users\user\OneDrive\Desktop\Projects\databases_v1\venv\lib\site-packages\django\db\backends\utils.py", line 75, in _execute_with_wrappers
    return executor(sql, params, many, context)
  File "C:\Users\user\OneDrive\Desktop\Projects\databases_v1\venv\lib\site-packages\django\db\backends\utils.py", line 84, in _execute
    return self.cursor.execute(sql, params)
  File "C:\Users\user\OneDrive\Desktop\Projects\databases_v1\venv\lib\site-packages\django\db\utils.py", line 90, in __exit__
    raise dj_exc_value.with_traceback(traceback) from exc_value
  File "C:\Users\user\OneDrive\Desktop\Projects\databases_v1\venv\lib\site-packages\django\db\backends\utils.py", line 82, in _execute
    return self.cursor.execute(sql)
  File "C:\Users\user\OneDrive\Desktop\Projects\databases_v1\venv\lib\site-packages\django\db\backends\sqlite3\base.py", line 421, in execute
    return Database.Cursor.execute(self, query)
django.db.utils.OperationalError: no such table: work_casewhere
ERROR django.server "POST /work/data/get/ HTTP/1.1" 500 140750 2021-08-30 12:04:52,820
ERROR django.request Internal Server Error: /work/data/get/ 2021-08-30 12:05:13,393
Traceback (most recent call last):
  File "C:\Users\user\OneDrive\Desktop\Projects\databases_v1\venv\lib\site-packages\django\db\backends\utils.py", line 82, in _execute
    return self.cursor.execute(sql)
  File "C:\Users\user\OneDrive\Desktop\Projects\databases_v1\venv\lib\site-packages\django\db\backends\sqlite3\base.py", line 421, in execute
    return Database.Cursor.execute(self, query)
sqlite3.OperationalError: no such table: work_casewhere

The above exception was the direct cause of the following exception:

Traceback (most recent call last):
  File "C:\Users\user\OneDrive\Desktop\Projects\databases_v1\venv\lib\site-packages\django\core\handlers\exception.py", line 47, in inner
    response = get_response(request)
  File "C:\Users\user\OneDrive\Desktop\Projects\databases_v1\venv\lib\site-packages\django\core\handlers\base.py", line 181, in _get_response
    response = wrapped_callback(request, *callback_args, **callback_kwargs)
  File "C:\Users\user\OneDrive\Desktop\Projects\databases_v1\venv\lib\site-packages\django\views\decorators\csrf.py", line 54, in wrapped_view
    return view_func(*args, **kwargs)
  File "C:\Users\user\OneDrive\Desktop\Projects\databases_v1\venv\lib\site-packages\django\views\generic\base.py", line 70, in view
    return self.dispatch(request, *args, **kwargs)
  File "C:\Users\user\OneDrive\Desktop\Projects\databases_v1\venv\lib\site-packages\rest_framework\views.py", line 509, in dispatch
    response = self.handle_exception(exc)
  File "C:\Users\user\OneDrive\Desktop\Projects\databases_v1\venv\lib\site-packages\rest_framework\views.py", line 469, in handle_exception
    self.raise_uncaught_exception(exc)
  File "C:\Users\user\OneDrive\Desktop\Projects\databases_v1\venv\lib\site-packages\rest_framework\views.py", line 480, in raise_uncaught_exception
    raise exc
  File "C:\Users\user\OneDrive\Desktop\Projects\databases_v1\venv\lib\site-packages\rest_framework\views.py", line 506, in dispatch
    response = handler(request, *args, **kwargs)
  File "C:\Users\user\OneDrive\Desktop\Projects\databases_v1\databases_v1\work\views.py", line 989, in post
    cursor.execute(sql_query + where_query + group_by_query)
  File "C:\Users\user\OneDrive\Desktop\Projects\databases_v1\venv\lib\site-packages\django\db\backends\utils.py", line 98, in execute
    return super().execute(sql, params)
  File "C:\Users\user\OneDrive\Desktop\Projects\databases_v1\venv\lib\site-packages\django\db\backends\utils.py", line 66, in execute
    return self._execute_with_wrappers(sql, params, many=False, executor=self._execute)
  File "C:\Users\user\OneDrive\Desktop\Projects\databases_v1\venv\lib\site-packages\django\db\backends\utils.py", line 75, in _execute_with_wrappers
    return executor(sql, params, many, context)
  File "C:\Users\user\OneDrive\Desktop\Projects\databases_v1\venv\lib\site-packages\django\db\backends\utils.py", line 84, in _execute
    return self.cursor.execute(sql, params)
  File "C:\Users\user\OneDrive\Desktop\Projects\databases_v1\venv\lib\site-packages\django\db\utils.py", line 90, in __exit__
    raise dj_exc_value.with_traceback(traceback) from exc_value
  File "C:\Users\user\OneDrive\Desktop\Projects\databases_v1\venv\lib\site-packages\django\db\backends\utils.py", line 82, in _execute
    return self.cursor.execute(sql)
  File "C:\Users\user\OneDrive\Desktop\Projects\databases_v1\venv\lib\site-packages\django\db\backends\sqlite3\base.py", line 421, in execute
    return Database.Cursor.execute(self, query)
django.db.utils.OperationalError: no such table: work_casewhere
ERROR django.server "POST /work/data/get/ HTTP/1.1" 500 140750 2021-08-30 12:05:13,398
ERROR django.request Internal Server Error: /work/data/get/ 2021-08-30 12:05:35,945
Traceback (most recent call last):
  File "C:\Users\user\OneDrive\Desktop\Projects\databases_v1\venv\lib\site-packages\django\db\backends\utils.py", line 82, in _execute
    return self.cursor.execute(sql)
  File "C:\Users\user\OneDrive\Desktop\Projects\databases_v1\venv\lib\site-packages\django\db\backends\sqlite3\base.py", line 421, in execute
    return Database.Cursor.execute(self, query)
sqlite3.OperationalError: no such column: work_tradeunionactivities.name

The above exception was the direct cause of the following exception:

Traceback (most recent call last):
  File "C:\Users\user\OneDrive\Desktop\Projects\databases_v1\venv\lib\site-packages\django\core\handlers\exception.py", line 47, in inner
    response = get_response(request)
  File "C:\Users\user\OneDrive\Desktop\Projects\databases_v1\venv\lib\site-packages\django\core\handlers\base.py", line 181, in _get_response
    response = wrapped_callback(request, *callback_args, **callback_kwargs)
  File "C:\Users\user\OneDrive\Desktop\Projects\databases_v1\venv\lib\site-packages\django\views\decorators\csrf.py", line 54, in wrapped_view
    return view_func(*args, **kwargs)
  File "C:\Users\user\OneDrive\Desktop\Projects\databases_v1\venv\lib\site-packages\django\views\generic\base.py", line 70, in view
    return self.dispatch(request, *args, **kwargs)
  File "C:\Users\user\OneDrive\Desktop\Projects\databases_v1\venv\lib\site-packages\rest_framework\views.py", line 509, in dispatch
    response = self.handle_exception(exc)
  File "C:\Users\user\OneDrive\Desktop\Projects\databases_v1\venv\lib\site-packages\rest_framework\views.py", line 469, in handle_exception
    self.raise_uncaught_exception(exc)
  File "C:\Users\user\OneDrive\Desktop\Projects\databases_v1\venv\lib\site-packages\rest_framework\views.py", line 480, in raise_uncaught_exception
    raise exc
  File "C:\Users\user\OneDrive\Desktop\Projects\databases_v1\venv\lib\site-packages\rest_framework\views.py", line 506, in dispatch
    response = handler(request, *args, **kwargs)
  File "C:\Users\user\OneDrive\Desktop\Projects\databases_v1\databases_v1\work\views.py", line 989, in post
    cursor.execute(sql_query + where_query + group_by_query)
  File "C:\Users\user\OneDrive\Desktop\Projects\databases_v1\venv\lib\site-packages\django\db\backends\utils.py", line 98, in execute
    return super().execute(sql, params)
  File "C:\Users\user\OneDrive\Desktop\Projects\databases_v1\venv\lib\site-packages\django\db\backends\utils.py", line 66, in execute
    return self._execute_with_wrappers(sql, params, many=False, executor=self._execute)
  File "C:\Users\user\OneDrive\Desktop\Projects\databases_v1\venv\lib\site-packages\django\db\backends\utils.py", line 75, in _execute_with_wrappers
    return executor(sql, params, many, context)
  File "C:\Users\user\OneDrive\Desktop\Projects\databases_v1\venv\lib\site-packages\django\db\backends\utils.py", line 84, in _execute
    return self.cursor.execute(sql, params)
  File "C:\Users\user\OneDrive\Desktop\Projects\databases_v1\venv\lib\site-packages\django\db\utils.py", line 90, in __exit__
    raise dj_exc_value.with_traceback(traceback) from exc_value
  File "C:\Users\user\OneDrive\Desktop\Projects\databases_v1\venv\lib\site-packages\django\db\backends\utils.py", line 82, in _execute
    return self.cursor.execute(sql)
  File "C:\Users\user\OneDrive\Desktop\Projects\databases_v1\venv\lib\site-packages\django\db\backends\sqlite3\base.py", line 421, in execute
    return Database.Cursor.execute(self, query)
django.db.utils.OperationalError: no such column: work_tradeunionactivities.name
ERROR django.server "POST /work/data/get/ HTTP/1.1" 500 141703 2021-08-30 12:05:35,947
ERROR django.request Internal Server Error: /work/data/get/ 2021-08-30 12:06:24,492
Traceback (most recent call last):
  File "C:\Users\user\OneDrive\Desktop\Projects\databases_v1\venv\lib\site-packages\django\db\backends\utils.py", line 82, in _execute
    return self.cursor.execute(sql)
  File "C:\Users\user\OneDrive\Desktop\Projects\databases_v1\venv\lib\site-packages\django\db\backends\sqlite3\base.py", line 421, in execute
    return Database.Cursor.execute(self, query)
sqlite3.OperationalError: no such column: work_tradeunionactivities.name

The above exception was the direct cause of the following exception:

Traceback (most recent call last):
  File "C:\Users\user\OneDrive\Desktop\Projects\databases_v1\venv\lib\site-packages\django\core\handlers\exception.py", line 47, in inner
    response = get_response(request)
  File "C:\Users\user\OneDrive\Desktop\Projects\databases_v1\venv\lib\site-packages\django\core\handlers\base.py", line 181, in _get_response
    response = wrapped_callback(request, *callback_args, **callback_kwargs)
  File "C:\Users\user\OneDrive\Desktop\Projects\databases_v1\venv\lib\site-packages\django\views\decorators\csrf.py", line 54, in wrapped_view
    return view_func(*args, **kwargs)
  File "C:\Users\user\OneDrive\Desktop\Projects\databases_v1\venv\lib\site-packages\django\views\generic\base.py", line 70, in view
    return self.dispatch(request, *args, **kwargs)
  File "C:\Users\user\OneDrive\Desktop\Projects\databases_v1\venv\lib\site-packages\rest_framework\views.py", line 509, in dispatch
    response = self.handle_exception(exc)
  File "C:\Users\user\OneDrive\Desktop\Projects\databases_v1\venv\lib\site-packages\rest_framework\views.py", line 469, in handle_exception
    self.raise_uncaught_exception(exc)
  File "C:\Users\user\OneDrive\Desktop\Projects\databases_v1\venv\lib\site-packages\rest_framework\views.py", line 480, in raise_uncaught_exception
    raise exc
  File "C:\Users\user\OneDrive\Desktop\Projects\databases_v1\venv\lib\site-packages\rest_framework\views.py", line 506, in dispatch
    response = handler(request, *args, **kwargs)
  File "C:\Users\user\OneDrive\Desktop\Projects\databases_v1\databases_v1\work\views.py", line 988, in post
    cursor.execute(sql_query + where_query + group_by_query)
  File "C:\Users\user\OneDrive\Desktop\Projects\databases_v1\venv\lib\site-packages\django\db\backends\utils.py", line 98, in execute
    return super().execute(sql, params)
  File "C:\Users\user\OneDrive\Desktop\Projects\databases_v1\venv\lib\site-packages\django\db\backends\utils.py", line 66, in execute
    return self._execute_with_wrappers(sql, params, many=False, executor=self._execute)
  File "C:\Users\user\OneDrive\Desktop\Projects\databases_v1\venv\lib\site-packages\django\db\backends\utils.py", line 75, in _execute_with_wrappers
    return executor(sql, params, many, context)
  File "C:\Users\user\OneDrive\Desktop\Projects\databases_v1\venv\lib\site-packages\django\db\backends\utils.py", line 84, in _execute
    return self.cursor.execute(sql, params)
  File "C:\Users\user\OneDrive\Desktop\Projects\databases_v1\venv\lib\site-packages\django\db\utils.py", line 90, in __exit__
    raise dj_exc_value.with_traceback(traceback) from exc_value
  File "C:\Users\user\OneDrive\Desktop\Projects\databases_v1\venv\lib\site-packages\django\db\backends\utils.py", line 82, in _execute
    return self.cursor.execute(sql)
  File "C:\Users\user\OneDrive\Desktop\Projects\databases_v1\venv\lib\site-packages\django\db\backends\sqlite3\base.py", line 421, in execute
    return Database.Cursor.execute(self, query)
django.db.utils.OperationalError: no such column: work_tradeunionactivities.name
ERROR django.server "POST /work/data/get/ HTTP/1.1" 500 141703 2021-08-30 12:06:24,496
ERROR django.request Internal Server Error: /work/data/get/ 2021-08-30 12:06:41,989
Traceback (most recent call last):
  File "C:\Users\user\OneDrive\Desktop\Projects\databases_v1\venv\lib\site-packages\django\db\backends\utils.py", line 82, in _execute
    return self.cursor.execute(sql)
  File "C:\Users\user\OneDrive\Desktop\Projects\databases_v1\venv\lib\site-packages\django\db\backends\sqlite3\base.py", line 421, in execute
    return Database.Cursor.execute(self, query)
sqlite3.OperationalError: no such table: work_casewhere

The above exception was the direct cause of the following exception:

Traceback (most recent call last):
  File "C:\Users\user\OneDrive\Desktop\Projects\databases_v1\venv\lib\site-packages\django\core\handlers\exception.py", line 47, in inner
    response = get_response(request)
  File "C:\Users\user\OneDrive\Desktop\Projects\databases_v1\venv\lib\site-packages\django\core\handlers\base.py", line 181, in _get_response
    response = wrapped_callback(request, *callback_args, **callback_kwargs)
  File "C:\Users\user\OneDrive\Desktop\Projects\databases_v1\venv\lib\site-packages\django\views\decorators\csrf.py", line 54, in wrapped_view
    return view_func(*args, **kwargs)
  File "C:\Users\user\OneDrive\Desktop\Projects\databases_v1\venv\lib\site-packages\django\views\generic\base.py", line 70, in view
    return self.dispatch(request, *args, **kwargs)
  File "C:\Users\user\OneDrive\Desktop\Projects\databases_v1\venv\lib\site-packages\rest_framework\views.py", line 509, in dispatch
    response = self.handle_exception(exc)
  File "C:\Users\user\OneDrive\Desktop\Projects\databases_v1\venv\lib\site-packages\rest_framework\views.py", line 469, in handle_exception
    self.raise_uncaught_exception(exc)
  File "C:\Users\user\OneDrive\Desktop\Projects\databases_v1\venv\lib\site-packages\rest_framework\views.py", line 480, in raise_uncaught_exception
    raise exc
  File "C:\Users\user\OneDrive\Desktop\Projects\databases_v1\venv\lib\site-packages\rest_framework\views.py", line 506, in dispatch
    response = handler(request, *args, **kwargs)
  File "C:\Users\user\OneDrive\Desktop\Projects\databases_v1\databases_v1\work\views.py", line 988, in post
    cursor.execute(sql_query + where_query + group_by_query)
  File "C:\Users\user\OneDrive\Desktop\Projects\databases_v1\venv\lib\site-packages\django\db\backends\utils.py", line 98, in execute
    return super().execute(sql, params)
  File "C:\Users\user\OneDrive\Desktop\Projects\databases_v1\venv\lib\site-packages\django\db\backends\utils.py", line 66, in execute
    return self._execute_with_wrappers(sql, params, many=False, executor=self._execute)
  File "C:\Users\user\OneDrive\Desktop\Projects\databases_v1\venv\lib\site-packages\django\db\backends\utils.py", line 75, in _execute_with_wrappers
    return executor(sql, params, many, context)
  File "C:\Users\user\OneDrive\Desktop\Projects\databases_v1\venv\lib\site-packages\django\db\backends\utils.py", line 84, in _execute
    return self.cursor.execute(sql, params)
  File "C:\Users\user\OneDrive\Desktop\Projects\databases_v1\venv\lib\site-packages\django\db\utils.py", line 90, in __exit__
    raise dj_exc_value.with_traceback(traceback) from exc_value
  File "C:\Users\user\OneDrive\Desktop\Projects\databases_v1\venv\lib\site-packages\django\db\backends\utils.py", line 82, in _execute
    return self.cursor.execute(sql)
  File "C:\Users\user\OneDrive\Desktop\Projects\databases_v1\venv\lib\site-packages\django\db\backends\sqlite3\base.py", line 421, in execute
    return Database.Cursor.execute(self, query)
django.db.utils.OperationalError: no such table: work_casewhere
ERROR django.server "POST /work/data/get/ HTTP/1.1" 500 140750 2021-08-30 12:06:41,991
ERROR django.request Internal Server Error: /work/data/get/ 2021-08-30 12:06:59,424
Traceback (most recent call last):
  File "C:\Users\user\OneDrive\Desktop\Projects\databases_v1\venv\lib\site-packages\django\db\backends\utils.py", line 82, in _execute
    return self.cursor.execute(sql)
  File "C:\Users\user\OneDrive\Desktop\Projects\databases_v1\venv\lib\site-packages\django\db\backends\sqlite3\base.py", line 421, in execute
    return Database.Cursor.execute(self, query)
sqlite3.OperationalError: no such table: work_casewhere

The above exception was the direct cause of the following exception:

Traceback (most recent call last):
  File "C:\Users\user\OneDrive\Desktop\Projects\databases_v1\venv\lib\site-packages\django\core\handlers\exception.py", line 47, in inner
    response = get_response(request)
  File "C:\Users\user\OneDrive\Desktop\Projects\databases_v1\venv\lib\site-packages\django\core\handlers\base.py", line 181, in _get_response
    response = wrapped_callback(request, *callback_args, **callback_kwargs)
  File "C:\Users\user\OneDrive\Desktop\Projects\databases_v1\venv\lib\site-packages\django\views\decorators\csrf.py", line 54, in wrapped_view
    return view_func(*args, **kwargs)
  File "C:\Users\user\OneDrive\Desktop\Projects\databases_v1\venv\lib\site-packages\django\views\generic\base.py", line 70, in view
    return self.dispatch(request, *args, **kwargs)
  File "C:\Users\user\OneDrive\Desktop\Projects\databases_v1\venv\lib\site-packages\rest_framework\views.py", line 509, in dispatch
    response = self.handle_exception(exc)
  File "C:\Users\user\OneDrive\Desktop\Projects\databases_v1\venv\lib\site-packages\rest_framework\views.py", line 469, in handle_exception
    self.raise_uncaught_exception(exc)
  File "C:\Users\user\OneDrive\Desktop\Projects\databases_v1\venv\lib\site-packages\rest_framework\views.py", line 480, in raise_uncaught_exception
    raise exc
  File "C:\Users\user\OneDrive\Desktop\Projects\databases_v1\venv\lib\site-packages\rest_framework\views.py", line 506, in dispatch
    response = handler(request, *args, **kwargs)
  File "C:\Users\user\OneDrive\Desktop\Projects\databases_v1\databases_v1\work\views.py", line 988, in post
    cursor.execute(sql_query + where_query + group_by_query)
  File "C:\Users\user\OneDrive\Desktop\Projects\databases_v1\venv\lib\site-packages\django\db\backends\utils.py", line 98, in execute
    return super().execute(sql, params)
  File "C:\Users\user\OneDrive\Desktop\Projects\databases_v1\venv\lib\site-packages\django\db\backends\utils.py", line 66, in execute
    return self._execute_with_wrappers(sql, params, many=False, executor=self._execute)
  File "C:\Users\user\OneDrive\Desktop\Projects\databases_v1\venv\lib\site-packages\django\db\backends\utils.py", line 75, in _execute_with_wrappers
    return executor(sql, params, many, context)
  File "C:\Users\user\OneDrive\Desktop\Projects\databases_v1\venv\lib\site-packages\django\db\backends\utils.py", line 84, in _execute
    return self.cursor.execute(sql, params)
  File "C:\Users\user\OneDrive\Desktop\Projects\databases_v1\venv\lib\site-packages\django\db\utils.py", line 90, in __exit__
    raise dj_exc_value.with_traceback(traceback) from exc_value
  File "C:\Users\user\OneDrive\Desktop\Projects\databases_v1\venv\lib\site-packages\django\db\backends\utils.py", line 82, in _execute
    return self.cursor.execute(sql)
  File "C:\Users\user\OneDrive\Desktop\Projects\databases_v1\venv\lib\site-packages\django\db\backends\sqlite3\base.py", line 421, in execute
    return Database.Cursor.execute(self, query)
django.db.utils.OperationalError: no such table: work_casewhere
ERROR django.server "POST /work/data/get/ HTTP/1.1" 500 140750 2021-08-30 12:06:59,429
ERROR django.request Internal Server Error: /work/data/get/ 2021-08-30 12:08:05,900
Traceback (most recent call last):
  File "C:\Users\user\OneDrive\Desktop\Projects\databases_v1\venv\lib\site-packages\django\db\backends\utils.py", line 82, in _execute
    return self.cursor.execute(sql)
  File "C:\Users\user\OneDrive\Desktop\Projects\databases_v1\venv\lib\site-packages\django\db\backends\sqlite3\base.py", line 421, in execute
    return Database.Cursor.execute(self, query)
sqlite3.OperationalError: no such table: work_casewhere

The above exception was the direct cause of the following exception:

Traceback (most recent call last):
  File "C:\Users\user\OneDrive\Desktop\Projects\databases_v1\venv\lib\site-packages\django\core\handlers\exception.py", line 47, in inner
    response = get_response(request)
  File "C:\Users\user\OneDrive\Desktop\Projects\databases_v1\venv\lib\site-packages\django\core\handlers\base.py", line 181, in _get_response
    response = wrapped_callback(request, *callback_args, **callback_kwargs)
  File "C:\Users\user\OneDrive\Desktop\Projects\databases_v1\venv\lib\site-packages\django\views\decorators\csrf.py", line 54, in wrapped_view
    return view_func(*args, **kwargs)
  File "C:\Users\user\OneDrive\Desktop\Projects\databases_v1\venv\lib\site-packages\django\views\generic\base.py", line 70, in view
    return self.dispatch(request, *args, **kwargs)
  File "C:\Users\user\OneDrive\Desktop\Projects\databases_v1\venv\lib\site-packages\rest_framework\views.py", line 509, in dispatch
    response = self.handle_exception(exc)
  File "C:\Users\user\OneDrive\Desktop\Projects\databases_v1\venv\lib\site-packages\rest_framework\views.py", line 469, in handle_exception
    self.raise_uncaught_exception(exc)
  File "C:\Users\user\OneDrive\Desktop\Projects\databases_v1\venv\lib\site-packages\rest_framework\views.py", line 480, in raise_uncaught_exception
    raise exc
  File "C:\Users\user\OneDrive\Desktop\Projects\databases_v1\venv\lib\site-packages\rest_framework\views.py", line 506, in dispatch
    response = handler(request, *args, **kwargs)
  File "C:\Users\user\OneDrive\Desktop\Projects\databases_v1\databases_v1\work\views.py", line 988, in post
    cursor.execute(sql_query + where_query + group_by_query)
  File "C:\Users\user\OneDrive\Desktop\Projects\databases_v1\venv\lib\site-packages\django\db\backends\utils.py", line 98, in execute
    return super().execute(sql, params)
  File "C:\Users\user\OneDrive\Desktop\Projects\databases_v1\venv\lib\site-packages\django\db\backends\utils.py", line 66, in execute
    return self._execute_with_wrappers(sql, params, many=False, executor=self._execute)
  File "C:\Users\user\OneDrive\Desktop\Projects\databases_v1\venv\lib\site-packages\django\db\backends\utils.py", line 75, in _execute_with_wrappers
    return executor(sql, params, many, context)
  File "C:\Users\user\OneDrive\Desktop\Projects\databases_v1\venv\lib\site-packages\django\db\backends\utils.py", line 84, in _execute
    return self.cursor.execute(sql, params)
  File "C:\Users\user\OneDrive\Desktop\Projects\databases_v1\venv\lib\site-packages\django\db\utils.py", line 90, in __exit__
    raise dj_exc_value.with_traceback(traceback) from exc_value
  File "C:\Users\user\OneDrive\Desktop\Projects\databases_v1\venv\lib\site-packages\django\db\backends\utils.py", line 82, in _execute
    return self.cursor.execute(sql)
  File "C:\Users\user\OneDrive\Desktop\Projects\databases_v1\venv\lib\site-packages\django\db\backends\sqlite3\base.py", line 421, in execute
    return Database.Cursor.execute(self, query)
django.db.utils.OperationalError: no such table: work_casewhere
ERROR django.server "POST /work/data/get/ HTTP/1.1" 500 140750 2021-08-30 12:08:05,904
ERROR django.request Internal Server Error: /work/data/get/ 2021-08-30 12:08:17,968
Traceback (most recent call last):
  File "C:\Users\user\OneDrive\Desktop\Projects\databases_v1\venv\lib\site-packages\django\db\backends\utils.py", line 82, in _execute
    return self.cursor.execute(sql)
  File "C:\Users\user\OneDrive\Desktop\Projects\databases_v1\venv\lib\site-packages\django\db\backends\sqlite3\base.py", line 421, in execute
    return Database.Cursor.execute(self, query)
sqlite3.OperationalError: no such column: work_tradeunionactivities.name

The above exception was the direct cause of the following exception:

Traceback (most recent call last):
  File "C:\Users\user\OneDrive\Desktop\Projects\databases_v1\venv\lib\site-packages\django\core\handlers\exception.py", line 47, in inner
    response = get_response(request)
  File "C:\Users\user\OneDrive\Desktop\Projects\databases_v1\venv\lib\site-packages\django\core\handlers\base.py", line 181, in _get_response
    response = wrapped_callback(request, *callback_args, **callback_kwargs)
  File "C:\Users\user\OneDrive\Desktop\Projects\databases_v1\venv\lib\site-packages\django\views\decorators\csrf.py", line 54, in wrapped_view
    return view_func(*args, **kwargs)
  File "C:\Users\user\OneDrive\Desktop\Projects\databases_v1\venv\lib\site-packages\django\views\generic\base.py", line 70, in view
    return self.dispatch(request, *args, **kwargs)
  File "C:\Users\user\OneDrive\Desktop\Projects\databases_v1\venv\lib\site-packages\rest_framework\views.py", line 509, in dispatch
    response = self.handle_exception(exc)
  File "C:\Users\user\OneDrive\Desktop\Projects\databases_v1\venv\lib\site-packages\rest_framework\views.py", line 469, in handle_exception
    self.raise_uncaught_exception(exc)
  File "C:\Users\user\OneDrive\Desktop\Projects\databases_v1\venv\lib\site-packages\rest_framework\views.py", line 480, in raise_uncaught_exception
    raise exc
  File "C:\Users\user\OneDrive\Desktop\Projects\databases_v1\venv\lib\site-packages\rest_framework\views.py", line 506, in dispatch
    response = handler(request, *args, **kwargs)
  File "C:\Users\user\OneDrive\Desktop\Projects\databases_v1\databases_v1\work\views.py", line 988, in post
    cursor.execute(sql_query + where_query + group_by_query)
  File "C:\Users\user\OneDrive\Desktop\Projects\databases_v1\venv\lib\site-packages\django\db\backends\utils.py", line 98, in execute
    return super().execute(sql, params)
  File "C:\Users\user\OneDrive\Desktop\Projects\databases_v1\venv\lib\site-packages\django\db\backends\utils.py", line 66, in execute
    return self._execute_with_wrappers(sql, params, many=False, executor=self._execute)
  File "C:\Users\user\OneDrive\Desktop\Projects\databases_v1\venv\lib\site-packages\django\db\backends\utils.py", line 75, in _execute_with_wrappers
    return executor(sql, params, many, context)
  File "C:\Users\user\OneDrive\Desktop\Projects\databases_v1\venv\lib\site-packages\django\db\backends\utils.py", line 84, in _execute
    return self.cursor.execute(sql, params)
  File "C:\Users\user\OneDrive\Desktop\Projects\databases_v1\venv\lib\site-packages\django\db\utils.py", line 90, in __exit__
    raise dj_exc_value.with_traceback(traceback) from exc_value
  File "C:\Users\user\OneDrive\Desktop\Projects\databases_v1\venv\lib\site-packages\django\db\backends\utils.py", line 82, in _execute
    return self.cursor.execute(sql)
  File "C:\Users\user\OneDrive\Desktop\Projects\databases_v1\venv\lib\site-packages\django\db\backends\sqlite3\base.py", line 421, in execute
    return Database.Cursor.execute(self, query)
django.db.utils.OperationalError: no such column: work_tradeunionactivities.name
ERROR django.server "POST /work/data/get/ HTTP/1.1" 500 141703 2021-08-30 12:08:17,970
ERROR django.request Internal Server Error: /work/data/get/ 2021-08-30 12:08:38,066
Traceback (most recent call last):
  File "C:\Users\user\OneDrive\Desktop\Projects\databases_v1\venv\lib\site-packages\django\db\backends\utils.py", line 82, in _execute
    return self.cursor.execute(sql)
  File "C:\Users\user\OneDrive\Desktop\Projects\databases_v1\venv\lib\site-packages\django\db\backends\sqlite3\base.py", line 421, in execute
    return Database.Cursor.execute(self, query)
sqlite3.OperationalError: no such column: work_tradeunionactivities.name

The above exception was the direct cause of the following exception:

Traceback (most recent call last):
  File "C:\Users\user\OneDrive\Desktop\Projects\databases_v1\venv\lib\site-packages\django\core\handlers\exception.py", line 47, in inner
    response = get_response(request)
  File "C:\Users\user\OneDrive\Desktop\Projects\databases_v1\venv\lib\site-packages\django\core\handlers\base.py", line 181, in _get_response
    response = wrapped_callback(request, *callback_args, **callback_kwargs)
  File "C:\Users\user\OneDrive\Desktop\Projects\databases_v1\venv\lib\site-packages\django\views\decorators\csrf.py", line 54, in wrapped_view
    return view_func(*args, **kwargs)
  File "C:\Users\user\OneDrive\Desktop\Projects\databases_v1\venv\lib\site-packages\django\views\generic\base.py", line 70, in view
    return self.dispatch(request, *args, **kwargs)
  File "C:\Users\user\OneDrive\Desktop\Projects\databases_v1\venv\lib\site-packages\rest_framework\views.py", line 509, in dispatch
    response = self.handle_exception(exc)
  File "C:\Users\user\OneDrive\Desktop\Projects\databases_v1\venv\lib\site-packages\rest_framework\views.py", line 469, in handle_exception
    self.raise_uncaught_exception(exc)
  File "C:\Users\user\OneDrive\Desktop\Projects\databases_v1\venv\lib\site-packages\rest_framework\views.py", line 480, in raise_uncaught_exception
    raise exc
  File "C:\Users\user\OneDrive\Desktop\Projects\databases_v1\venv\lib\site-packages\rest_framework\views.py", line 506, in dispatch
    response = handler(request, *args, **kwargs)
  File "C:\Users\user\OneDrive\Desktop\Projects\databases_v1\databases_v1\work\views.py", line 988, in post
    cursor.execute(sql_query + where_query + group_by_query)
  File "C:\Users\user\OneDrive\Desktop\Projects\databases_v1\venv\lib\site-packages\django\db\backends\utils.py", line 98, in execute
    return super().execute(sql, params)
  File "C:\Users\user\OneDrive\Desktop\Projects\databases_v1\venv\lib\site-packages\django\db\backends\utils.py", line 66, in execute
    return self._execute_with_wrappers(sql, params, many=False, executor=self._execute)
  File "C:\Users\user\OneDrive\Desktop\Projects\databases_v1\venv\lib\site-packages\django\db\backends\utils.py", line 75, in _execute_with_wrappers
    return executor(sql, params, many, context)
  File "C:\Users\user\OneDrive\Desktop\Projects\databases_v1\venv\lib\site-packages\django\db\backends\utils.py", line 84, in _execute
    return self.cursor.execute(sql, params)
  File "C:\Users\user\OneDrive\Desktop\Projects\databases_v1\venv\lib\site-packages\django\db\utils.py", line 90, in __exit__
    raise dj_exc_value.with_traceback(traceback) from exc_value
  File "C:\Users\user\OneDrive\Desktop\Projects\databases_v1\venv\lib\site-packages\django\db\backends\utils.py", line 82, in _execute
    return self.cursor.execute(sql)
  File "C:\Users\user\OneDrive\Desktop\Projects\databases_v1\venv\lib\site-packages\django\db\backends\sqlite3\base.py", line 421, in execute
    return Database.Cursor.execute(self, query)
django.db.utils.OperationalError: no such column: work_tradeunionactivities.name
ERROR django.server "POST /work/data/get/ HTTP/1.1" 500 144530 2021-08-30 12:08:38,070
ERROR django.request Internal Server Error: /work/data/get/ 2021-08-30 12:12:15,909
Traceback (most recent call last):
  File "C:\Users\user\OneDrive\Desktop\Projects\databases_v1\venv\lib\site-packages\django\db\backends\utils.py", line 82, in _execute
    return self.cursor.execute(sql)
  File "C:\Users\user\OneDrive\Desktop\Projects\databases_v1\venv\lib\site-packages\django\db\backends\sqlite3\base.py", line 421, in execute
    return Database.Cursor.execute(self, query)
sqlite3.OperationalError: no such column: work_work_tradeunionactivities.name

The above exception was the direct cause of the following exception:

Traceback (most recent call last):
  File "C:\Users\user\OneDrive\Desktop\Projects\databases_v1\venv\lib\site-packages\django\core\handlers\exception.py", line 47, in inner
    response = get_response(request)
  File "C:\Users\user\OneDrive\Desktop\Projects\databases_v1\venv\lib\site-packages\django\core\handlers\base.py", line 181, in _get_response
    response = wrapped_callback(request, *callback_args, **callback_kwargs)
  File "C:\Users\user\OneDrive\Desktop\Projects\databases_v1\venv\lib\site-packages\django\views\decorators\csrf.py", line 54, in wrapped_view
    return view_func(*args, **kwargs)
  File "C:\Users\user\OneDrive\Desktop\Projects\databases_v1\venv\lib\site-packages\django\views\generic\base.py", line 70, in view
    return self.dispatch(request, *args, **kwargs)
  File "C:\Users\user\OneDrive\Desktop\Projects\databases_v1\venv\lib\site-packages\rest_framework\views.py", line 509, in dispatch
    response = self.handle_exception(exc)
  File "C:\Users\user\OneDrive\Desktop\Projects\databases_v1\venv\lib\site-packages\rest_framework\views.py", line 469, in handle_exception
    self.raise_uncaught_exception(exc)
  File "C:\Users\user\OneDrive\Desktop\Projects\databases_v1\venv\lib\site-packages\rest_framework\views.py", line 480, in raise_uncaught_exception
    raise exc
  File "C:\Users\user\OneDrive\Desktop\Projects\databases_v1\venv\lib\site-packages\rest_framework\views.py", line 506, in dispatch
    response = handler(request, *args, **kwargs)
  File "C:\Users\user\OneDrive\Desktop\Projects\databases_v1\databases_v1\work\views.py", line 987, in post
    cursor.execute(sql_query + where_query + group_by_query)
  File "C:\Users\user\OneDrive\Desktop\Projects\databases_v1\venv\lib\site-packages\django\db\backends\utils.py", line 98, in execute
    return super().execute(sql, params)
  File "C:\Users\user\OneDrive\Desktop\Projects\databases_v1\venv\lib\site-packages\django\db\backends\utils.py", line 66, in execute
    return self._execute_with_wrappers(sql, params, many=False, executor=self._execute)
  File "C:\Users\user\OneDrive\Desktop\Projects\databases_v1\venv\lib\site-packages\django\db\backends\utils.py", line 75, in _execute_with_wrappers
    return executor(sql, params, many, context)
  File "C:\Users\user\OneDrive\Desktop\Projects\databases_v1\venv\lib\site-packages\django\db\backends\utils.py", line 84, in _execute
    return self.cursor.execute(sql, params)
  File "C:\Users\user\OneDrive\Desktop\Projects\databases_v1\venv\lib\site-packages\django\db\utils.py", line 90, in __exit__
    raise dj_exc_value.with_traceback(traceback) from exc_value
  File "C:\Users\user\OneDrive\Desktop\Projects\databases_v1\venv\lib\site-packages\django\db\backends\utils.py", line 82, in _execute
    return self.cursor.execute(sql)
  File "C:\Users\user\OneDrive\Desktop\Projects\databases_v1\venv\lib\site-packages\django\db\backends\sqlite3\base.py", line 421, in execute
    return Database.Cursor.execute(self, query)
django.db.utils.OperationalError: no such column: work_work_tradeunionactivities.name
ERROR django.server "POST /work/data/get/ HTTP/1.1" 500 143452 2021-08-30 12:12:15,913
ERROR django.request Internal Server Error: /work/data/get/ 2021-08-30 12:12:37,283
Traceback (most recent call last):
  File "C:\Users\user\OneDrive\Desktop\Projects\databases_v1\venv\lib\site-packages\django\db\backends\utils.py", line 82, in _execute
    return self.cursor.execute(sql)
  File "C:\Users\user\OneDrive\Desktop\Projects\databases_v1\venv\lib\site-packages\django\db\backends\sqlite3\base.py", line 421, in execute
    return Database.Cursor.execute(self, query)
sqlite3.OperationalError: no such column: work_work_tradeunionactivities.name

The above exception was the direct cause of the following exception:

Traceback (most recent call last):
  File "C:\Users\user\OneDrive\Desktop\Projects\databases_v1\venv\lib\site-packages\django\core\handlers\exception.py", line 47, in inner
    response = get_response(request)
  File "C:\Users\user\OneDrive\Desktop\Projects\databases_v1\venv\lib\site-packages\django\core\handlers\base.py", line 181, in _get_response
    response = wrapped_callback(request, *callback_args, **callback_kwargs)
  File "C:\Users\user\OneDrive\Desktop\Projects\databases_v1\venv\lib\site-packages\django\views\decorators\csrf.py", line 54, in wrapped_view
    return view_func(*args, **kwargs)
  File "C:\Users\user\OneDrive\Desktop\Projects\databases_v1\venv\lib\site-packages\django\views\generic\base.py", line 70, in view
    return self.dispatch(request, *args, **kwargs)
  File "C:\Users\user\OneDrive\Desktop\Projects\databases_v1\venv\lib\site-packages\rest_framework\views.py", line 509, in dispatch
    response = self.handle_exception(exc)
  File "C:\Users\user\OneDrive\Desktop\Projects\databases_v1\venv\lib\site-packages\rest_framework\views.py", line 469, in handle_exception
    self.raise_uncaught_exception(exc)
  File "C:\Users\user\OneDrive\Desktop\Projects\databases_v1\venv\lib\site-packages\rest_framework\views.py", line 480, in raise_uncaught_exception
    raise exc
  File "C:\Users\user\OneDrive\Desktop\Projects\databases_v1\venv\lib\site-packages\rest_framework\views.py", line 506, in dispatch
    response = handler(request, *args, **kwargs)
  File "C:\Users\user\OneDrive\Desktop\Projects\databases_v1\databases_v1\work\views.py", line 987, in post
    cursor.execute(sql_query + where_query + group_by_query)
  File "C:\Users\user\OneDrive\Desktop\Projects\databases_v1\venv\lib\site-packages\django\db\backends\utils.py", line 98, in execute
    return super().execute(sql, params)
  File "C:\Users\user\OneDrive\Desktop\Projects\databases_v1\venv\lib\site-packages\django\db\backends\utils.py", line 66, in execute
    return self._execute_with_wrappers(sql, params, many=False, executor=self._execute)
  File "C:\Users\user\OneDrive\Desktop\Projects\databases_v1\venv\lib\site-packages\django\db\backends\utils.py", line 75, in _execute_with_wrappers
    return executor(sql, params, many, context)
  File "C:\Users\user\OneDrive\Desktop\Projects\databases_v1\venv\lib\site-packages\django\db\backends\utils.py", line 84, in _execute
    return self.cursor.execute(sql, params)
  File "C:\Users\user\OneDrive\Desktop\Projects\databases_v1\venv\lib\site-packages\django\db\utils.py", line 90, in __exit__
    raise dj_exc_value.with_traceback(traceback) from exc_value
  File "C:\Users\user\OneDrive\Desktop\Projects\databases_v1\venv\lib\site-packages\django\db\backends\utils.py", line 82, in _execute
    return self.cursor.execute(sql)
  File "C:\Users\user\OneDrive\Desktop\Projects\databases_v1\venv\lib\site-packages\django\db\backends\sqlite3\base.py", line 421, in execute
    return Database.Cursor.execute(self, query)
django.db.utils.OperationalError: no such column: work_work_tradeunionactivities.name
ERROR django.server "POST /work/data/get/ HTTP/1.1" 500 143452 2021-08-30 12:12:37,286
ERROR django.request Internal Server Error: /work/data/get/ 2021-08-30 12:13:00,230
Traceback (most recent call last):
  File "C:\Users\user\OneDrive\Desktop\Projects\databases_v1\venv\lib\site-packages\django\db\backends\utils.py", line 82, in _execute
    return self.cursor.execute(sql)
  File "C:\Users\user\OneDrive\Desktop\Projects\databases_v1\venv\lib\site-packages\django\db\backends\sqlite3\base.py", line 421, in execute
    return Database.Cursor.execute(self, query)
sqlite3.OperationalError: no such column: work_work_tradeunionactivities.name

The above exception was the direct cause of the following exception:

Traceback (most recent call last):
  File "C:\Users\user\OneDrive\Desktop\Projects\databases_v1\venv\lib\site-packages\django\core\handlers\exception.py", line 47, in inner
    response = get_response(request)
  File "C:\Users\user\OneDrive\Desktop\Projects\databases_v1\venv\lib\site-packages\django\core\handlers\base.py", line 181, in _get_response
    response = wrapped_callback(request, *callback_args, **callback_kwargs)
  File "C:\Users\user\OneDrive\Desktop\Projects\databases_v1\venv\lib\site-packages\django\views\decorators\csrf.py", line 54, in wrapped_view
    return view_func(*args, **kwargs)
  File "C:\Users\user\OneDrive\Desktop\Projects\databases_v1\venv\lib\site-packages\django\views\generic\base.py", line 70, in view
    return self.dispatch(request, *args, **kwargs)
  File "C:\Users\user\OneDrive\Desktop\Projects\databases_v1\venv\lib\site-packages\rest_framework\views.py", line 509, in dispatch
    response = self.handle_exception(exc)
  File "C:\Users\user\OneDrive\Desktop\Projects\databases_v1\venv\lib\site-packages\rest_framework\views.py", line 469, in handle_exception
    self.raise_uncaught_exception(exc)
  File "C:\Users\user\OneDrive\Desktop\Projects\databases_v1\venv\lib\site-packages\rest_framework\views.py", line 480, in raise_uncaught_exception
    raise exc
  File "C:\Users\user\OneDrive\Desktop\Projects\databases_v1\venv\lib\site-packages\rest_framework\views.py", line 506, in dispatch
    response = handler(request, *args, **kwargs)
  File "C:\Users\user\OneDrive\Desktop\Projects\databases_v1\databases_v1\work\views.py", line 987, in post
    cursor.execute(sql_query + where_query + group_by_query)
  File "C:\Users\user\OneDrive\Desktop\Projects\databases_v1\venv\lib\site-packages\django\db\backends\utils.py", line 98, in execute
    return super().execute(sql, params)
  File "C:\Users\user\OneDrive\Desktop\Projects\databases_v1\venv\lib\site-packages\django\db\backends\utils.py", line 66, in execute
    return self._execute_with_wrappers(sql, params, many=False, executor=self._execute)
  File "C:\Users\user\OneDrive\Desktop\Projects\databases_v1\venv\lib\site-packages\django\db\backends\utils.py", line 75, in _execute_with_wrappers
    return executor(sql, params, many, context)
  File "C:\Users\user\OneDrive\Desktop\Projects\databases_v1\venv\lib\site-packages\django\db\backends\utils.py", line 84, in _execute
    return self.cursor.execute(sql, params)
  File "C:\Users\user\OneDrive\Desktop\Projects\databases_v1\venv\lib\site-packages\django\db\utils.py", line 90, in __exit__
    raise dj_exc_value.with_traceback(traceback) from exc_value
  File "C:\Users\user\OneDrive\Desktop\Projects\databases_v1\venv\lib\site-packages\django\db\backends\utils.py", line 82, in _execute
    return self.cursor.execute(sql)
  File "C:\Users\user\OneDrive\Desktop\Projects\databases_v1\venv\lib\site-packages\django\db\backends\sqlite3\base.py", line 421, in execute
    return Database.Cursor.execute(self, query)
django.db.utils.OperationalError: no such column: work_work_tradeunionactivities.name
ERROR django.server "POST /work/data/get/ HTTP/1.1" 500 143452 2021-08-30 12:13:00,234
ERROR django.request Internal Server Error: /work/data/get/ 2021-08-30 12:13:56,980
Traceback (most recent call last):
  File "C:\Users\user\OneDrive\Desktop\Projects\databases_v1\venv\lib\site-packages\django\db\backends\utils.py", line 82, in _execute
    return self.cursor.execute(sql)
  File "C:\Users\user\OneDrive\Desktop\Projects\databases_v1\venv\lib\site-packages\django\db\backends\sqlite3\base.py", line 421, in execute
    return Database.Cursor.execute(self, query)
sqlite3.OperationalError: no such column: work_work_tradeunionactivities.name

The above exception was the direct cause of the following exception:

Traceback (most recent call last):
  File "C:\Users\user\OneDrive\Desktop\Projects\databases_v1\venv\lib\site-packages\django\core\handlers\exception.py", line 47, in inner
    response = get_response(request)
  File "C:\Users\user\OneDrive\Desktop\Projects\databases_v1\venv\lib\site-packages\django\core\handlers\base.py", line 181, in _get_response
    response = wrapped_callback(request, *callback_args, **callback_kwargs)
  File "C:\Users\user\OneDrive\Desktop\Projects\databases_v1\venv\lib\site-packages\django\views\decorators\csrf.py", line 54, in wrapped_view
    return view_func(*args, **kwargs)
  File "C:\Users\user\OneDrive\Desktop\Projects\databases_v1\venv\lib\site-packages\django\views\generic\base.py", line 70, in view
    return self.dispatch(request, *args, **kwargs)
  File "C:\Users\user\OneDrive\Desktop\Projects\databases_v1\venv\lib\site-packages\rest_framework\views.py", line 509, in dispatch
    response = self.handle_exception(exc)
  File "C:\Users\user\OneDrive\Desktop\Projects\databases_v1\venv\lib\site-packages\rest_framework\views.py", line 469, in handle_exception
    self.raise_uncaught_exception(exc)
  File "C:\Users\user\OneDrive\Desktop\Projects\databases_v1\venv\lib\site-packages\rest_framework\views.py", line 480, in raise_uncaught_exception
    raise exc
  File "C:\Users\user\OneDrive\Desktop\Projects\databases_v1\venv\lib\site-packages\rest_framework\views.py", line 506, in dispatch
    response = handler(request, *args, **kwargs)
  File "C:\Users\user\OneDrive\Desktop\Projects\databases_v1\databases_v1\work\views.py", line 987, in post
    cursor.execute(sql_query + where_query + group_by_query)
  File "C:\Users\user\OneDrive\Desktop\Projects\databases_v1\venv\lib\site-packages\django\db\backends\utils.py", line 98, in execute
    return super().execute(sql, params)
  File "C:\Users\user\OneDrive\Desktop\Projects\databases_v1\venv\lib\site-packages\django\db\backends\utils.py", line 66, in execute
    return self._execute_with_wrappers(sql, params, many=False, executor=self._execute)
  File "C:\Users\user\OneDrive\Desktop\Projects\databases_v1\venv\lib\site-packages\django\db\backends\utils.py", line 75, in _execute_with_wrappers
    return executor(sql, params, many, context)
  File "C:\Users\user\OneDrive\Desktop\Projects\databases_v1\venv\lib\site-packages\django\db\backends\utils.py", line 84, in _execute
    return self.cursor.execute(sql, params)
  File "C:\Users\user\OneDrive\Desktop\Projects\databases_v1\venv\lib\site-packages\django\db\utils.py", line 90, in __exit__
    raise dj_exc_value.with_traceback(traceback) from exc_value
  File "C:\Users\user\OneDrive\Desktop\Projects\databases_v1\venv\lib\site-packages\django\db\backends\utils.py", line 82, in _execute
    return self.cursor.execute(sql)
  File "C:\Users\user\OneDrive\Desktop\Projects\databases_v1\venv\lib\site-packages\django\db\backends\sqlite3\base.py", line 421, in execute
    return Database.Cursor.execute(self, query)
django.db.utils.OperationalError: no such column: work_work_tradeunionactivities.name
ERROR django.server "POST /work/data/get/ HTTP/1.1" 500 144323 2021-08-30 12:13:56,984
