WARNING django.request Not Found: /favicon.ico 2021-10-27 16:08:14,172
WARNING django.server "GET /favicon.ico HTTP/1.1" 404 3524 2021-10-27 16:08:14,176
WARNING django.request Not Found: /favicon.ico 2021-10-27 16:08:15,773
WARNING django.server "GET /favicon.ico HTTP/1.1" 404 3524 2021-10-27 16:08:15,776
WARNING django.request Not Found: /favicon.ico 2021-10-27 16:37:27,395
WARNING django.server "GET /favicon.ico HTTP/1.1" 404 3524 2021-10-27 16:37:27,396
ERROR django.request Internal Server Error: /work/add-comment/1/ 2021-10-27 16:42:48,889
Traceback (most recent call last):
  File "D:\Users\ntabyldieva\Desktop\databases_v1\env\lib\site-packages\django\core\handlers\exception.py", line 47, in inner
    response = get_response(request)
  File "D:\Users\ntabyldieva\Desktop\databases_v1\env\lib\site-packages\django\core\handlers\base.py", line 181, in _get_response
    response = wrapped_callback(request, *callback_args, **callback_kwargs)
  File "D:\Users\ntabyldieva\Desktop\databases_v1\env\lib\site-packages\django\contrib\auth\decorators.py", line 21, in _wrapped_view
    return view_func(request, *args, **kwargs)
  File "D:\Users\ntabyldieva\Desktop\databases_v1\work\views.py", line 338, in add_comment
    send_mail(subject, message, settings.EMAIL_HOST_USER, [to_email, ], fail_silently=False)
  File "D:\Users\ntabyldieva\Desktop\databases_v1\env\lib\site-packages\django\core\mail\__init__.py", line 61, in send_mail
    return mail.send()
  File "D:\Users\ntabyldieva\Desktop\databases_v1\env\lib\site-packages\django\core\mail\message.py", line 284, in send
    return self.get_connection(fail_silently).send_messages([self])
  File "D:\Users\ntabyldieva\Desktop\databases_v1\env\lib\site-packages\django\core\mail\backends\smtp.py", line 102, in send_messages
    new_conn_created = self.open()
  File "D:\Users\ntabyldieva\Desktop\databases_v1\env\lib\site-packages\django\core\mail\backends\smtp.py", line 62, in open
    self.connection = self.connection_class(self.host, self.port, **connection_params)
  File "D:\Users\ntabyldieva\AppData\Local\Programs\Python\Python39\lib\smtplib.py", line 255, in __init__
    (code, msg) = self.connect(host, port)
  File "D:\Users\ntabyldieva\AppData\Local\Programs\Python\Python39\lib\smtplib.py", line 341, in connect
    self.sock = self._get_socket(host, port, self.timeout)
  File "D:\Users\ntabyldieva\AppData\Local\Programs\Python\Python39\lib\smtplib.py", line 312, in _get_socket
    return socket.create_connection((host, port), timeout,
  File "D:\Users\ntabyldieva\AppData\Local\Programs\Python\Python39\lib\socket.py", line 844, in create_connection
    raise err
  File "D:\Users\ntabyldieva\AppData\Local\Programs\Python\Python39\lib\socket.py", line 832, in create_connection
    sock.connect(sa)
TimeoutError: [WinError 10060] Попытка установить соединение была безуспешной, т.к. от другого компьютера за требуемое время не получен нужный отклик, или было разорвано уже установленное соединение из-за неверного отклика уже подключенного компьютера
ERROR django.server "POST /work/add-comment/1/ HTTP/1.1" 500 120428 2021-10-27 16:42:48,905
WARNING django.request Not Found: /favicon.ico 2021-10-27 18:19:53,040
WARNING django.server "GET /favicon.ico HTTP/1.1" 404 3524 2021-10-27 18:19:53,040
