WARNING django.request Not Found: /favicon.ico 2021-09-07 13:07:43,821
WARNING django.server "GET /favicon.ico HTTP/1.1" 404 3524 2021-09-07 13:07:43,823
ERROR django.request Internal Server Error: /accounts/login/ 2021-09-07 13:07:52,317
Traceback (most recent call last):
  File "C:\Users\user\OneDrive\Desktop\Projects\databases_v1\venv\lib\site-packages\django\utils\module_loading.py", line 13, in import_string
    module_path, class_name = dotted_path.rsplit('.', 1)
ValueError: not enough values to unpack (expected 2, got 1)

The above exception was the direct cause of the following exception:

Traceback (most recent call last):
  File "C:\Users\user\OneDrive\Desktop\Projects\databases_v1\venv\lib\site-packages\django\core\handlers\exception.py", line 47, in inner
    response = get_response(request)
  File "C:\Users\user\OneDrive\Desktop\Projects\databases_v1\venv\lib\site-packages\django\core\handlers\base.py", line 181, in _get_response
    response = wrapped_callback(request, *callback_args, **callback_kwargs)
  File "C:\Users\user\OneDrive\Desktop\Projects\databases_v1\venv\lib\site-packages\django\views\generic\base.py", line 70, in view
    return self.dispatch(request, *args, **kwargs)
  File "C:\Users\user\OneDrive\Desktop\Projects\databases_v1\venv\lib\site-packages\django\utils\decorators.py", line 43, in _wrapper
    return bound_method(*args, **kwargs)
  File "C:\Users\user\OneDrive\Desktop\Projects\databases_v1\venv\lib\site-packages\django\views\decorators\debug.py", line 89, in sensitive_post_parameters_wrapper
    return view(request, *args, **kwargs)
  File "C:\Users\user\OneDrive\Desktop\Projects\databases_v1\venv\lib\site-packages\django\utils\decorators.py", line 43, in _wrapper
    return bound_method(*args, **kwargs)
  File "C:\Users\user\OneDrive\Desktop\Projects\databases_v1\venv\lib\site-packages\django\utils\decorators.py", line 130, in _wrapped_view
    response = view_func(request, *args, **kwargs)
  File "C:\Users\user\OneDrive\Desktop\Projects\databases_v1\venv\lib\site-packages\django\utils\decorators.py", line 43, in _wrapper
    return bound_method(*args, **kwargs)
  File "C:\Users\user\OneDrive\Desktop\Projects\databases_v1\venv\lib\site-packages\django\views\decorators\cache.py", line 44, in _wrapped_view_func
    response = view_func(request, *args, **kwargs)
  File "C:\Users\user\OneDrive\Desktop\Projects\databases_v1\venv\lib\site-packages\django\contrib\auth\views.py", line 63, in dispatch
    return super().dispatch(request, *args, **kwargs)
  File "C:\Users\user\OneDrive\Desktop\Projects\databases_v1\venv\lib\site-packages\django\views\generic\base.py", line 98, in dispatch
    return handler(request, *args, **kwargs)
  File "C:\Users\user\OneDrive\Desktop\Projects\databases_v1\venv\lib\site-packages\django\views\generic\edit.py", line 141, in post
    if form.is_valid():
  File "C:\Users\user\OneDrive\Desktop\Projects\databases_v1\venv\lib\site-packages\django\forms\forms.py", line 175, in is_valid
    return self.is_bound and not self.errors
  File "C:\Users\user\OneDrive\Desktop\Projects\databases_v1\venv\lib\site-packages\django\forms\forms.py", line 170, in errors
    self.full_clean()
  File "C:\Users\user\OneDrive\Desktop\Projects\databases_v1\venv\lib\site-packages\django\forms\forms.py", line 373, in full_clean
    self._clean_form()
  File "C:\Users\user\OneDrive\Desktop\Projects\databases_v1\venv\lib\site-packages\django\forms\forms.py", line 400, in _clean_form
    cleaned_data = self.clean()
  File "C:\Users\user\OneDrive\Desktop\Projects\databases_v1\venv\lib\site-packages\django\contrib\auth\forms.py", line 202, in clean
    self.user_cache = authenticate(self.request, username=username, password=password)
  File "C:\Users\user\OneDrive\Desktop\Projects\databases_v1\venv\lib\site-packages\django\views\decorators\debug.py", line 42, in sensitive_variables_wrapper
    return func(*func_args, **func_kwargs)
  File "C:\Users\user\OneDrive\Desktop\Projects\databases_v1\venv\lib\site-packages\django\contrib\auth\__init__.py", line 68, in authenticate
    for backend, backend_path in _get_backends(return_tuples=True):
  File "C:\Users\user\OneDrive\Desktop\Projects\databases_v1\venv\lib\site-packages\django\contrib\auth\__init__.py", line 27, in _get_backends
    backend = load_backend(backend_path)
  File "C:\Users\user\OneDrive\Desktop\Projects\databases_v1\venv\lib\site-packages\django\contrib\auth\__init__.py", line 21, in load_backend
    return import_string(path)()
  File "C:\Users\user\OneDrive\Desktop\Projects\databases_v1\venv\lib\site-packages\django\utils\module_loading.py", line 15, in import_string
    raise ImportError("%s doesn't look like a module path" % dotted_path) from err
ImportError: d doesn't look like a module path
ERROR django.server "POST /accounts/login/ HTTP/1.1" 500 155861 2021-09-07 13:07:52,322
ERROR django.request Internal Server Error: /accounts/login/ 2021-09-07 13:08:22,609
Traceback (most recent call last):
  File "C:\Users\user\OneDrive\Desktop\Projects\databases_v1\venv\lib\site-packages\django\utils\module_loading.py", line 13, in import_string
    module_path, class_name = dotted_path.rsplit('.', 1)
ValueError: not enough values to unpack (expected 2, got 1)

The above exception was the direct cause of the following exception:

Traceback (most recent call last):
  File "C:\Users\user\OneDrive\Desktop\Projects\databases_v1\venv\lib\site-packages\django\core\handlers\exception.py", line 47, in inner
    response = get_response(request)
  File "C:\Users\user\OneDrive\Desktop\Projects\databases_v1\venv\lib\site-packages\django\core\handlers\base.py", line 181, in _get_response
    response = wrapped_callback(request, *callback_args, **callback_kwargs)
  File "C:\Users\user\OneDrive\Desktop\Projects\databases_v1\venv\lib\site-packages\django\views\generic\base.py", line 70, in view
    return self.dispatch(request, *args, **kwargs)
  File "C:\Users\user\OneDrive\Desktop\Projects\databases_v1\venv\lib\site-packages\django\utils\decorators.py", line 43, in _wrapper
    return bound_method(*args, **kwargs)
  File "C:\Users\user\OneDrive\Desktop\Projects\databases_v1\venv\lib\site-packages\django\views\decorators\debug.py", line 89, in sensitive_post_parameters_wrapper
    return view(request, *args, **kwargs)
  File "C:\Users\user\OneDrive\Desktop\Projects\databases_v1\venv\lib\site-packages\django\utils\decorators.py", line 43, in _wrapper
    return bound_method(*args, **kwargs)
  File "C:\Users\user\OneDrive\Desktop\Projects\databases_v1\venv\lib\site-packages\django\utils\decorators.py", line 130, in _wrapped_view
    response = view_func(request, *args, **kwargs)
  File "C:\Users\user\OneDrive\Desktop\Projects\databases_v1\venv\lib\site-packages\django\utils\decorators.py", line 43, in _wrapper
    return bound_method(*args, **kwargs)
  File "C:\Users\user\OneDrive\Desktop\Projects\databases_v1\venv\lib\site-packages\django\views\decorators\cache.py", line 44, in _wrapped_view_func
    response = view_func(request, *args, **kwargs)
  File "C:\Users\user\OneDrive\Desktop\Projects\databases_v1\venv\lib\site-packages\django\contrib\auth\views.py", line 63, in dispatch
    return super().dispatch(request, *args, **kwargs)
  File "C:\Users\user\OneDrive\Desktop\Projects\databases_v1\venv\lib\site-packages\django\views\generic\base.py", line 98, in dispatch
    return handler(request, *args, **kwargs)
  File "C:\Users\user\OneDrive\Desktop\Projects\databases_v1\venv\lib\site-packages\django\views\generic\edit.py", line 141, in post
    if form.is_valid():
  File "C:\Users\user\OneDrive\Desktop\Projects\databases_v1\venv\lib\site-packages\django\forms\forms.py", line 175, in is_valid
    return self.is_bound and not self.errors
  File "C:\Users\user\OneDrive\Desktop\Projects\databases_v1\venv\lib\site-packages\django\forms\forms.py", line 170, in errors
    self.full_clean()
  File "C:\Users\user\OneDrive\Desktop\Projects\databases_v1\venv\lib\site-packages\django\forms\forms.py", line 373, in full_clean
    self._clean_form()
  File "C:\Users\user\OneDrive\Desktop\Projects\databases_v1\venv\lib\site-packages\django\forms\forms.py", line 400, in _clean_form
    cleaned_data = self.clean()
  File "C:\Users\user\OneDrive\Desktop\Projects\databases_v1\venv\lib\site-packages\django\contrib\auth\forms.py", line 202, in clean
    self.user_cache = authenticate(self.request, username=username, password=password)
  File "C:\Users\user\OneDrive\Desktop\Projects\databases_v1\venv\lib\site-packages\django\views\decorators\debug.py", line 42, in sensitive_variables_wrapper
    return func(*func_args, **func_kwargs)
  File "C:\Users\user\OneDrive\Desktop\Projects\databases_v1\venv\lib\site-packages\django\contrib\auth\__init__.py", line 68, in authenticate
    for backend, backend_path in _get_backends(return_tuples=True):
  File "C:\Users\user\OneDrive\Desktop\Projects\databases_v1\venv\lib\site-packages\django\contrib\auth\__init__.py", line 27, in _get_backends
    backend = load_backend(backend_path)
  File "C:\Users\user\OneDrive\Desktop\Projects\databases_v1\venv\lib\site-packages\django\contrib\auth\__init__.py", line 21, in load_backend
    return import_string(path)()
  File "C:\Users\user\OneDrive\Desktop\Projects\databases_v1\venv\lib\site-packages\django\utils\module_loading.py", line 15, in import_string
    raise ImportError("%s doesn't look like a module path" % dotted_path) from err
ImportError: m doesn't look like a module path
ERROR django.server "POST /accounts/login/ HTTP/1.1" 500 155853 2021-09-07 13:08:22,616
ERROR django.request Internal Server Error: /accounts/login/ 2021-09-07 13:08:36,922
Traceback (most recent call last):
  File "C:\Users\user\OneDrive\Desktop\Projects\databases_v1\venv\lib\site-packages\django\utils\module_loading.py", line 13, in import_string
    module_path, class_name = dotted_path.rsplit('.', 1)
ValueError: not enough values to unpack (expected 2, got 1)

The above exception was the direct cause of the following exception:

Traceback (most recent call last):
  File "C:\Users\user\OneDrive\Desktop\Projects\databases_v1\venv\lib\site-packages\django\core\handlers\exception.py", line 47, in inner
    response = get_response(request)
  File "C:\Users\user\OneDrive\Desktop\Projects\databases_v1\venv\lib\site-packages\django\core\handlers\base.py", line 181, in _get_response
    response = wrapped_callback(request, *callback_args, **callback_kwargs)
  File "C:\Users\user\OneDrive\Desktop\Projects\databases_v1\venv\lib\site-packages\django\views\generic\base.py", line 70, in view
    return self.dispatch(request, *args, **kwargs)
  File "C:\Users\user\OneDrive\Desktop\Projects\databases_v1\venv\lib\site-packages\django\utils\decorators.py", line 43, in _wrapper
    return bound_method(*args, **kwargs)
  File "C:\Users\user\OneDrive\Desktop\Projects\databases_v1\venv\lib\site-packages\django\views\decorators\debug.py", line 89, in sensitive_post_parameters_wrapper
    return view(request, *args, **kwargs)
  File "C:\Users\user\OneDrive\Desktop\Projects\databases_v1\venv\lib\site-packages\django\utils\decorators.py", line 43, in _wrapper
    return bound_method(*args, **kwargs)
  File "C:\Users\user\OneDrive\Desktop\Projects\databases_v1\venv\lib\site-packages\django\utils\decorators.py", line 130, in _wrapped_view
    response = view_func(request, *args, **kwargs)
  File "C:\Users\user\OneDrive\Desktop\Projects\databases_v1\venv\lib\site-packages\django\utils\decorators.py", line 43, in _wrapper
    return bound_method(*args, **kwargs)
  File "C:\Users\user\OneDrive\Desktop\Projects\databases_v1\venv\lib\site-packages\django\views\decorators\cache.py", line 44, in _wrapped_view_func
    response = view_func(request, *args, **kwargs)
  File "C:\Users\user\OneDrive\Desktop\Projects\databases_v1\venv\lib\site-packages\django\contrib\auth\views.py", line 63, in dispatch
    return super().dispatch(request, *args, **kwargs)
  File "C:\Users\user\OneDrive\Desktop\Projects\databases_v1\venv\lib\site-packages\django\views\generic\base.py", line 98, in dispatch
    return handler(request, *args, **kwargs)
  File "C:\Users\user\OneDrive\Desktop\Projects\databases_v1\venv\lib\site-packages\django\views\generic\edit.py", line 141, in post
    if form.is_valid():
  File "C:\Users\user\OneDrive\Desktop\Projects\databases_v1\venv\lib\site-packages\django\forms\forms.py", line 175, in is_valid
    return self.is_bound and not self.errors
  File "C:\Users\user\OneDrive\Desktop\Projects\databases_v1\venv\lib\site-packages\django\forms\forms.py", line 170, in errors
    self.full_clean()
  File "C:\Users\user\OneDrive\Desktop\Projects\databases_v1\venv\lib\site-packages\django\forms\forms.py", line 373, in full_clean
    self._clean_form()
  File "C:\Users\user\OneDrive\Desktop\Projects\databases_v1\venv\lib\site-packages\django\forms\forms.py", line 400, in _clean_form
    cleaned_data = self.clean()
  File "C:\Users\user\OneDrive\Desktop\Projects\databases_v1\venv\lib\site-packages\django\contrib\auth\forms.py", line 202, in clean
    self.user_cache = authenticate(self.request, username=username, password=password)
  File "C:\Users\user\OneDrive\Desktop\Projects\databases_v1\venv\lib\site-packages\django\views\decorators\debug.py", line 42, in sensitive_variables_wrapper
    return func(*func_args, **func_kwargs)
  File "C:\Users\user\OneDrive\Desktop\Projects\databases_v1\venv\lib\site-packages\django\contrib\auth\__init__.py", line 68, in authenticate
    for backend, backend_path in _get_backends(return_tuples=True):
  File "C:\Users\user\OneDrive\Desktop\Projects\databases_v1\venv\lib\site-packages\django\contrib\auth\__init__.py", line 27, in _get_backends
    backend = load_backend(backend_path)
  File "C:\Users\user\OneDrive\Desktop\Projects\databases_v1\venv\lib\site-packages\django\contrib\auth\__init__.py", line 21, in load_backend
    return import_string(path)()
  File "C:\Users\user\OneDrive\Desktop\Projects\databases_v1\venv\lib\site-packages\django\utils\module_loading.py", line 15, in import_string
    raise ImportError("%s doesn't look like a module path" % dotted_path) from err
ImportError: m doesn't look like a module path
ERROR django.server "POST /accounts/login/ HTTP/1.1" 500 155799 2021-09-07 13:08:36,926
ERROR django.request Internal Server Error: /admin/login/ 2021-09-07 13:14:33,309
Traceback (most recent call last):
  File "C:\Users\user\OneDrive\Desktop\Projects\databases_v1\venv\lib\site-packages\django\utils\module_loading.py", line 13, in import_string
    module_path, class_name = dotted_path.rsplit('.', 1)
ValueError: not enough values to unpack (expected 2, got 1)

The above exception was the direct cause of the following exception:

Traceback (most recent call last):
  File "C:\Users\user\OneDrive\Desktop\Projects\databases_v1\venv\lib\site-packages\django\core\handlers\exception.py", line 47, in inner
    response = get_response(request)
  File "C:\Users\user\OneDrive\Desktop\Projects\databases_v1\venv\lib\site-packages\django\core\handlers\base.py", line 181, in _get_response
    response = wrapped_callback(request, *callback_args, **callback_kwargs)
  File "C:\Users\user\OneDrive\Desktop\Projects\databases_v1\venv\lib\site-packages\django\views\decorators\cache.py", line 44, in _wrapped_view_func
    response = view_func(request, *args, **kwargs)
  File "C:\Users\user\OneDrive\Desktop\Projects\databases_v1\venv\lib\site-packages\django\contrib\admin\sites.py", line 398, in login
    **self.each_context(request),
  File "C:\Users\user\OneDrive\Desktop\Projects\databases_v1\venv\lib\site-packages\django\contrib\admin\sites.py", line 316, in each_context
    'available_apps': self.get_app_list(request),
  File "C:\Users\user\OneDrive\Desktop\Projects\databases_v1\venv\lib\site-packages\django\contrib\admin\sites.py", line 506, in get_app_list
    app_dict = self._build_app_dict(request)
  File "C:\Users\user\OneDrive\Desktop\Projects\databases_v1\venv\lib\site-packages\django\contrib\admin\sites.py", line 451, in _build_app_dict
    has_module_perms = model_admin.has_module_permission(request)
  File "C:\Users\user\OneDrive\Desktop\Projects\databases_v1\venv\lib\site-packages\django\contrib\admin\options.py", line 548, in has_module_permission
    return request.user.has_module_perms(self.opts.app_label)
  File "C:\Users\user\OneDrive\Desktop\Projects\databases_v1\venv\lib\site-packages\django\contrib\auth\models.py", line 458, in has_module_perms
    return _user_has_module_perms(self, module)
  File "C:\Users\user\OneDrive\Desktop\Projects\databases_v1\venv\lib\site-packages\django\contrib\auth\models.py", line 221, in _user_has_module_perms
    for backend in auth.get_backends():
  File "C:\Users\user\OneDrive\Desktop\Projects\databases_v1\venv\lib\site-packages\django\contrib\auth\__init__.py", line 38, in get_backends
    return _get_backends(return_tuples=False)
  File "C:\Users\user\OneDrive\Desktop\Projects\databases_v1\venv\lib\site-packages\django\contrib\auth\__init__.py", line 27, in _get_backends
    backend = load_backend(backend_path)
  File "C:\Users\user\OneDrive\Desktop\Projects\databases_v1\venv\lib\site-packages\django\contrib\auth\__init__.py", line 21, in load_backend
    return import_string(path)()
  File "C:\Users\user\OneDrive\Desktop\Projects\databases_v1\venv\lib\site-packages\django\utils\module_loading.py", line 15, in import_string
    raise ImportError("%s doesn't look like a module path" % dotted_path) from err
ImportError: m doesn't look like a module path
ERROR django.server "GET /admin/login/?next=/admin/ HTTP/1.1" 500 117336 2021-09-07 13:14:33,314
ERROR django.request Internal Server Error: /admin/login/ 2021-09-07 13:14:45,906
Traceback (most recent call last):
  File "C:\Users\user\OneDrive\Desktop\Projects\databases_v1\venv\lib\site-packages\django\utils\module_loading.py", line 13, in import_string
    module_path, class_name = dotted_path.rsplit('.', 1)
ValueError: not enough values to unpack (expected 2, got 1)

The above exception was the direct cause of the following exception:

Traceback (most recent call last):
  File "C:\Users\user\OneDrive\Desktop\Projects\databases_v1\venv\lib\site-packages\django\core\handlers\exception.py", line 47, in inner
    response = get_response(request)
  File "C:\Users\user\OneDrive\Desktop\Projects\databases_v1\venv\lib\site-packages\django\core\handlers\base.py", line 181, in _get_response
    response = wrapped_callback(request, *callback_args, **callback_kwargs)
  File "C:\Users\user\OneDrive\Desktop\Projects\databases_v1\venv\lib\site-packages\django\views\decorators\cache.py", line 44, in _wrapped_view_func
    response = view_func(request, *args, **kwargs)
  File "C:\Users\user\OneDrive\Desktop\Projects\databases_v1\venv\lib\site-packages\django\contrib\admin\sites.py", line 398, in login
    **self.each_context(request),
  File "C:\Users\user\OneDrive\Desktop\Projects\databases_v1\venv\lib\site-packages\django\contrib\admin\sites.py", line 316, in each_context
    'available_apps': self.get_app_list(request),
  File "C:\Users\user\OneDrive\Desktop\Projects\databases_v1\venv\lib\site-packages\django\contrib\admin\sites.py", line 506, in get_app_list
    app_dict = self._build_app_dict(request)
  File "C:\Users\user\OneDrive\Desktop\Projects\databases_v1\venv\lib\site-packages\django\contrib\admin\sites.py", line 451, in _build_app_dict
    has_module_perms = model_admin.has_module_permission(request)
  File "C:\Users\user\OneDrive\Desktop\Projects\databases_v1\venv\lib\site-packages\django\contrib\admin\options.py", line 548, in has_module_permission
    return request.user.has_module_perms(self.opts.app_label)
  File "C:\Users\user\OneDrive\Desktop\Projects\databases_v1\venv\lib\site-packages\django\contrib\auth\models.py", line 458, in has_module_perms
    return _user_has_module_perms(self, module)
  File "C:\Users\user\OneDrive\Desktop\Projects\databases_v1\venv\lib\site-packages\django\contrib\auth\models.py", line 221, in _user_has_module_perms
    for backend in auth.get_backends():
  File "C:\Users\user\OneDrive\Desktop\Projects\databases_v1\venv\lib\site-packages\django\contrib\auth\__init__.py", line 38, in get_backends
    return _get_backends(return_tuples=False)
  File "C:\Users\user\OneDrive\Desktop\Projects\databases_v1\venv\lib\site-packages\django\contrib\auth\__init__.py", line 27, in _get_backends
    backend = load_backend(backend_path)
  File "C:\Users\user\OneDrive\Desktop\Projects\databases_v1\venv\lib\site-packages\django\contrib\auth\__init__.py", line 21, in load_backend
    return import_string(path)()
  File "C:\Users\user\OneDrive\Desktop\Projects\databases_v1\venv\lib\site-packages\django\utils\module_loading.py", line 15, in import_string
    raise ImportError("%s doesn't look like a module path" % dotted_path) from err
ImportError: m doesn't look like a module path
ERROR django.server "GET /admin/login/?next=/admin/ HTTP/1.1" 500 117473 2021-09-07 13:14:45,913
ERROR django.request Internal Server Error: /admin/login/ 2021-09-07 13:15:32,750
Traceback (most recent call last):
  File "C:\Users\user\OneDrive\Desktop\Projects\databases_v1\venv\lib\site-packages\django\utils\module_loading.py", line 13, in import_string
    module_path, class_name = dotted_path.rsplit('.', 1)
ValueError: not enough values to unpack (expected 2, got 1)

The above exception was the direct cause of the following exception:

Traceback (most recent call last):
  File "C:\Users\user\OneDrive\Desktop\Projects\databases_v1\venv\lib\site-packages\django\core\handlers\exception.py", line 47, in inner
    response = get_response(request)
  File "C:\Users\user\OneDrive\Desktop\Projects\databases_v1\venv\lib\site-packages\django\core\handlers\base.py", line 181, in _get_response
    response = wrapped_callback(request, *callback_args, **callback_kwargs)
  File "C:\Users\user\OneDrive\Desktop\Projects\databases_v1\venv\lib\site-packages\django\views\decorators\cache.py", line 44, in _wrapped_view_func
    response = view_func(request, *args, **kwargs)
  File "C:\Users\user\OneDrive\Desktop\Projects\databases_v1\venv\lib\site-packages\django\contrib\admin\sites.py", line 398, in login
    **self.each_context(request),
  File "C:\Users\user\OneDrive\Desktop\Projects\databases_v1\venv\lib\site-packages\django\contrib\admin\sites.py", line 316, in each_context
    'available_apps': self.get_app_list(request),
  File "C:\Users\user\OneDrive\Desktop\Projects\databases_v1\venv\lib\site-packages\django\contrib\admin\sites.py", line 506, in get_app_list
    app_dict = self._build_app_dict(request)
  File "C:\Users\user\OneDrive\Desktop\Projects\databases_v1\venv\lib\site-packages\django\contrib\admin\sites.py", line 451, in _build_app_dict
    has_module_perms = model_admin.has_module_permission(request)
  File "C:\Users\user\OneDrive\Desktop\Projects\databases_v1\venv\lib\site-packages\django\contrib\admin\options.py", line 548, in has_module_permission
    return request.user.has_module_perms(self.opts.app_label)
  File "C:\Users\user\OneDrive\Desktop\Projects\databases_v1\venv\lib\site-packages\django\contrib\auth\models.py", line 458, in has_module_perms
    return _user_has_module_perms(self, module)
  File "C:\Users\user\OneDrive\Desktop\Projects\databases_v1\venv\lib\site-packages\django\contrib\auth\models.py", line 221, in _user_has_module_perms
    for backend in auth.get_backends():
  File "C:\Users\user\OneDrive\Desktop\Projects\databases_v1\venv\lib\site-packages\django\contrib\auth\__init__.py", line 38, in get_backends
    return _get_backends(return_tuples=False)
  File "C:\Users\user\OneDrive\Desktop\Projects\databases_v1\venv\lib\site-packages\django\contrib\auth\__init__.py", line 27, in _get_backends
    backend = load_backend(backend_path)
  File "C:\Users\user\OneDrive\Desktop\Projects\databases_v1\venv\lib\site-packages\django\contrib\auth\__init__.py", line 21, in load_backend
    return import_string(path)()
  File "C:\Users\user\OneDrive\Desktop\Projects\databases_v1\venv\lib\site-packages\django\utils\module_loading.py", line 15, in import_string
    raise ImportError("%s doesn't look like a module path" % dotted_path) from err
ImportError: m doesn't look like a module path
ERROR django.server "GET /admin/login/?next=/admin/ HTTP/1.1" 500 117473 2021-09-07 13:15:32,762
ERROR django.request Internal Server Error: /admin/login/ 2021-09-07 13:16:30,756
Traceback (most recent call last):
  File "C:\Users\user\OneDrive\Desktop\Projects\databases_v1\venv\lib\site-packages\django\utils\module_loading.py", line 13, in import_string
    module_path, class_name = dotted_path.rsplit('.', 1)
ValueError: not enough values to unpack (expected 2, got 1)

The above exception was the direct cause of the following exception:

Traceback (most recent call last):
  File "C:\Users\user\OneDrive\Desktop\Projects\databases_v1\venv\lib\site-packages\django\core\handlers\exception.py", line 47, in inner
    response = get_response(request)
  File "C:\Users\user\OneDrive\Desktop\Projects\databases_v1\venv\lib\site-packages\django\core\handlers\base.py", line 181, in _get_response
    response = wrapped_callback(request, *callback_args, **callback_kwargs)
  File "C:\Users\user\OneDrive\Desktop\Projects\databases_v1\venv\lib\site-packages\django\views\decorators\cache.py", line 44, in _wrapped_view_func
    response = view_func(request, *args, **kwargs)
  File "C:\Users\user\OneDrive\Desktop\Projects\databases_v1\venv\lib\site-packages\django\contrib\admin\sites.py", line 398, in login
    **self.each_context(request),
  File "C:\Users\user\OneDrive\Desktop\Projects\databases_v1\venv\lib\site-packages\django\contrib\admin\sites.py", line 316, in each_context
    'available_apps': self.get_app_list(request),
  File "C:\Users\user\OneDrive\Desktop\Projects\databases_v1\venv\lib\site-packages\django\contrib\admin\sites.py", line 506, in get_app_list
    app_dict = self._build_app_dict(request)
  File "C:\Users\user\OneDrive\Desktop\Projects\databases_v1\venv\lib\site-packages\django\contrib\admin\sites.py", line 451, in _build_app_dict
    has_module_perms = model_admin.has_module_permission(request)
  File "C:\Users\user\OneDrive\Desktop\Projects\databases_v1\venv\lib\site-packages\django\contrib\admin\options.py", line 548, in has_module_permission
    return request.user.has_module_perms(self.opts.app_label)
  File "C:\Users\user\OneDrive\Desktop\Projects\databases_v1\venv\lib\site-packages\django\contrib\auth\models.py", line 458, in has_module_perms
    return _user_has_module_perms(self, module)
  File "C:\Users\user\OneDrive\Desktop\Projects\databases_v1\venv\lib\site-packages\django\contrib\auth\models.py", line 221, in _user_has_module_perms
    for backend in auth.get_backends():
  File "C:\Users\user\OneDrive\Desktop\Projects\databases_v1\venv\lib\site-packages\django\contrib\auth\__init__.py", line 38, in get_backends
    return _get_backends(return_tuples=False)
  File "C:\Users\user\OneDrive\Desktop\Projects\databases_v1\venv\lib\site-packages\django\contrib\auth\__init__.py", line 27, in _get_backends
    backend = load_backend(backend_path)
  File "C:\Users\user\OneDrive\Desktop\Projects\databases_v1\venv\lib\site-packages\django\contrib\auth\__init__.py", line 21, in load_backend
    return import_string(path)()
  File "C:\Users\user\OneDrive\Desktop\Projects\databases_v1\venv\lib\site-packages\django\utils\module_loading.py", line 15, in import_string
    raise ImportError("%s doesn't look like a module path" % dotted_path) from err
ImportError: a doesn't look like a module path
ERROR django.server "GET /admin/login/?next=/admin/ HTTP/1.1" 500 117477 2021-09-07 13:16:30,767
ERROR django.request Internal Server Error: /admin/login/ 2021-09-07 13:16:42,163
Traceback (most recent call last):
  File "C:\Users\user\OneDrive\Desktop\Projects\databases_v1\venv\lib\site-packages\django\utils\module_loading.py", line 13, in import_string
    module_path, class_name = dotted_path.rsplit('.', 1)
ValueError: not enough values to unpack (expected 2, got 1)

The above exception was the direct cause of the following exception:

Traceback (most recent call last):
  File "C:\Users\user\OneDrive\Desktop\Projects\databases_v1\venv\lib\site-packages\django\core\handlers\exception.py", line 47, in inner
    response = get_response(request)
  File "C:\Users\user\OneDrive\Desktop\Projects\databases_v1\venv\lib\site-packages\django\core\handlers\base.py", line 181, in _get_response
    response = wrapped_callback(request, *callback_args, **callback_kwargs)
  File "C:\Users\user\OneDrive\Desktop\Projects\databases_v1\venv\lib\site-packages\django\views\decorators\cache.py", line 44, in _wrapped_view_func
    response = view_func(request, *args, **kwargs)
  File "C:\Users\user\OneDrive\Desktop\Projects\databases_v1\venv\lib\site-packages\django\contrib\admin\sites.py", line 398, in login
    **self.each_context(request),
  File "C:\Users\user\OneDrive\Desktop\Projects\databases_v1\venv\lib\site-packages\django\contrib\admin\sites.py", line 316, in each_context
    'available_apps': self.get_app_list(request),
  File "C:\Users\user\OneDrive\Desktop\Projects\databases_v1\venv\lib\site-packages\django\contrib\admin\sites.py", line 506, in get_app_list
    app_dict = self._build_app_dict(request)
  File "C:\Users\user\OneDrive\Desktop\Projects\databases_v1\venv\lib\site-packages\django\contrib\admin\sites.py", line 451, in _build_app_dict
    has_module_perms = model_admin.has_module_permission(request)
  File "C:\Users\user\OneDrive\Desktop\Projects\databases_v1\venv\lib\site-packages\django\contrib\admin\options.py", line 548, in has_module_permission
    return request.user.has_module_perms(self.opts.app_label)
  File "C:\Users\user\OneDrive\Desktop\Projects\databases_v1\venv\lib\site-packages\django\contrib\auth\models.py", line 458, in has_module_perms
    return _user_has_module_perms(self, module)
  File "C:\Users\user\OneDrive\Desktop\Projects\databases_v1\venv\lib\site-packages\django\contrib\auth\models.py", line 221, in _user_has_module_perms
    for backend in auth.get_backends():
  File "C:\Users\user\OneDrive\Desktop\Projects\databases_v1\venv\lib\site-packages\django\contrib\auth\__init__.py", line 38, in get_backends
    return _get_backends(return_tuples=False)
  File "C:\Users\user\OneDrive\Desktop\Projects\databases_v1\venv\lib\site-packages\django\contrib\auth\__init__.py", line 27, in _get_backends
    backend = load_backend(backend_path)
  File "C:\Users\user\OneDrive\Desktop\Projects\databases_v1\venv\lib\site-packages\django\contrib\auth\__init__.py", line 21, in load_backend
    return import_string(path)()
  File "C:\Users\user\OneDrive\Desktop\Projects\databases_v1\venv\lib\site-packages\django\utils\module_loading.py", line 15, in import_string
    raise ImportError("%s doesn't look like a module path" % dotted_path) from err
ImportError: a doesn't look like a module path
ERROR django.server "GET /admin/login/?next=/admin/ HTTP/1.1" 500 117477 2021-09-07 13:16:42,170
ERROR django.request Internal Server Error: /admin/login/ 2021-09-07 13:16:42,768
Traceback (most recent call last):
  File "C:\Users\user\OneDrive\Desktop\Projects\databases_v1\venv\lib\site-packages\django\utils\module_loading.py", line 13, in import_string
    module_path, class_name = dotted_path.rsplit('.', 1)
ValueError: not enough values to unpack (expected 2, got 1)

The above exception was the direct cause of the following exception:

Traceback (most recent call last):
  File "C:\Users\user\OneDrive\Desktop\Projects\databases_v1\venv\lib\site-packages\django\core\handlers\exception.py", line 47, in inner
    response = get_response(request)
  File "C:\Users\user\OneDrive\Desktop\Projects\databases_v1\venv\lib\site-packages\django\core\handlers\base.py", line 181, in _get_response
    response = wrapped_callback(request, *callback_args, **callback_kwargs)
  File "C:\Users\user\OneDrive\Desktop\Projects\databases_v1\venv\lib\site-packages\django\views\decorators\cache.py", line 44, in _wrapped_view_func
    response = view_func(request, *args, **kwargs)
  File "C:\Users\user\OneDrive\Desktop\Projects\databases_v1\venv\lib\site-packages\django\contrib\admin\sites.py", line 398, in login
    **self.each_context(request),
  File "C:\Users\user\OneDrive\Desktop\Projects\databases_v1\venv\lib\site-packages\django\contrib\admin\sites.py", line 316, in each_context
    'available_apps': self.get_app_list(request),
  File "C:\Users\user\OneDrive\Desktop\Projects\databases_v1\venv\lib\site-packages\django\contrib\admin\sites.py", line 506, in get_app_list
    app_dict = self._build_app_dict(request)
  File "C:\Users\user\OneDrive\Desktop\Projects\databases_v1\venv\lib\site-packages\django\contrib\admin\sites.py", line 451, in _build_app_dict
    has_module_perms = model_admin.has_module_permission(request)
  File "C:\Users\user\OneDrive\Desktop\Projects\databases_v1\venv\lib\site-packages\django\contrib\admin\options.py", line 548, in has_module_permission
    return request.user.has_module_perms(self.opts.app_label)
  File "C:\Users\user\OneDrive\Desktop\Projects\databases_v1\venv\lib\site-packages\django\contrib\auth\models.py", line 458, in has_module_perms
    return _user_has_module_perms(self, module)
  File "C:\Users\user\OneDrive\Desktop\Projects\databases_v1\venv\lib\site-packages\django\contrib\auth\models.py", line 221, in _user_has_module_perms
    for backend in auth.get_backends():
  File "C:\Users\user\OneDrive\Desktop\Projects\databases_v1\venv\lib\site-packages\django\contrib\auth\__init__.py", line 38, in get_backends
    return _get_backends(return_tuples=False)
  File "C:\Users\user\OneDrive\Desktop\Projects\databases_v1\venv\lib\site-packages\django\contrib\auth\__init__.py", line 27, in _get_backends
    backend = load_backend(backend_path)
  File "C:\Users\user\OneDrive\Desktop\Projects\databases_v1\venv\lib\site-packages\django\contrib\auth\__init__.py", line 21, in load_backend
    return import_string(path)()
  File "C:\Users\user\OneDrive\Desktop\Projects\databases_v1\venv\lib\site-packages\django\utils\module_loading.py", line 15, in import_string
    raise ImportError("%s doesn't look like a module path" % dotted_path) from err
ImportError: a doesn't look like a module path
ERROR django.server "GET /admin/login/?next=/admin/ HTTP/1.1" 500 117477 2021-09-07 13:16:42,772
ERROR django.request Internal Server Error: /admin/login/ 2021-09-07 13:16:44,332
Traceback (most recent call last):
  File "C:\Users\user\OneDrive\Desktop\Projects\databases_v1\venv\lib\site-packages\django\utils\module_loading.py", line 13, in import_string
    module_path, class_name = dotted_path.rsplit('.', 1)
ValueError: not enough values to unpack (expected 2, got 1)

The above exception was the direct cause of the following exception:

Traceback (most recent call last):
  File "C:\Users\user\OneDrive\Desktop\Projects\databases_v1\venv\lib\site-packages\django\core\handlers\exception.py", line 47, in inner
    response = get_response(request)
  File "C:\Users\user\OneDrive\Desktop\Projects\databases_v1\venv\lib\site-packages\django\core\handlers\base.py", line 181, in _get_response
    response = wrapped_callback(request, *callback_args, **callback_kwargs)
  File "C:\Users\user\OneDrive\Desktop\Projects\databases_v1\venv\lib\site-packages\django\views\decorators\cache.py", line 44, in _wrapped_view_func
    response = view_func(request, *args, **kwargs)
  File "C:\Users\user\OneDrive\Desktop\Projects\databases_v1\venv\lib\site-packages\django\contrib\admin\sites.py", line 398, in login
    **self.each_context(request),
  File "C:\Users\user\OneDrive\Desktop\Projects\databases_v1\venv\lib\site-packages\django\contrib\admin\sites.py", line 316, in each_context
    'available_apps': self.get_app_list(request),
  File "C:\Users\user\OneDrive\Desktop\Projects\databases_v1\venv\lib\site-packages\django\contrib\admin\sites.py", line 506, in get_app_list
    app_dict = self._build_app_dict(request)
  File "C:\Users\user\OneDrive\Desktop\Projects\databases_v1\venv\lib\site-packages\django\contrib\admin\sites.py", line 451, in _build_app_dict
    has_module_perms = model_admin.has_module_permission(request)
  File "C:\Users\user\OneDrive\Desktop\Projects\databases_v1\venv\lib\site-packages\django\contrib\admin\options.py", line 548, in has_module_permission
    return request.user.has_module_perms(self.opts.app_label)
  File "C:\Users\user\OneDrive\Desktop\Projects\databases_v1\venv\lib\site-packages\django\contrib\auth\models.py", line 458, in has_module_perms
    return _user_has_module_perms(self, module)
  File "C:\Users\user\OneDrive\Desktop\Projects\databases_v1\venv\lib\site-packages\django\contrib\auth\models.py", line 221, in _user_has_module_perms
    for backend in auth.get_backends():
  File "C:\Users\user\OneDrive\Desktop\Projects\databases_v1\venv\lib\site-packages\django\contrib\auth\__init__.py", line 38, in get_backends
    return _get_backends(return_tuples=False)
  File "C:\Users\user\OneDrive\Desktop\Projects\databases_v1\venv\lib\site-packages\django\contrib\auth\__init__.py", line 27, in _get_backends
    backend = load_backend(backend_path)
  File "C:\Users\user\OneDrive\Desktop\Projects\databases_v1\venv\lib\site-packages\django\contrib\auth\__init__.py", line 21, in load_backend
    return import_string(path)()
  File "C:\Users\user\OneDrive\Desktop\Projects\databases_v1\venv\lib\site-packages\django\utils\module_loading.py", line 15, in import_string
    raise ImportError("%s doesn't look like a module path" % dotted_path) from err
ImportError: a doesn't look like a module path
ERROR django.server "GET /admin/login/?next=/admin/ HTTP/1.1" 500 117477 2021-09-07 13:16:44,338
ERROR django.request Internal Server Error: /admin/login/ 2021-09-07 13:16:45,628
Traceback (most recent call last):
  File "C:\Users\user\OneDrive\Desktop\Projects\databases_v1\venv\lib\site-packages\django\utils\module_loading.py", line 13, in import_string
    module_path, class_name = dotted_path.rsplit('.', 1)
ValueError: not enough values to unpack (expected 2, got 1)

The above exception was the direct cause of the following exception:

Traceback (most recent call last):
  File "C:\Users\user\OneDrive\Desktop\Projects\databases_v1\venv\lib\site-packages\django\core\handlers\exception.py", line 47, in inner
    response = get_response(request)
  File "C:\Users\user\OneDrive\Desktop\Projects\databases_v1\venv\lib\site-packages\django\core\handlers\base.py", line 181, in _get_response
    response = wrapped_callback(request, *callback_args, **callback_kwargs)
  File "C:\Users\user\OneDrive\Desktop\Projects\databases_v1\venv\lib\site-packages\django\views\decorators\cache.py", line 44, in _wrapped_view_func
    response = view_func(request, *args, **kwargs)
  File "C:\Users\user\OneDrive\Desktop\Projects\databases_v1\venv\lib\site-packages\django\contrib\admin\sites.py", line 398, in login
    **self.each_context(request),
  File "C:\Users\user\OneDrive\Desktop\Projects\databases_v1\venv\lib\site-packages\django\contrib\admin\sites.py", line 316, in each_context
    'available_apps': self.get_app_list(request),
  File "C:\Users\user\OneDrive\Desktop\Projects\databases_v1\venv\lib\site-packages\django\contrib\admin\sites.py", line 506, in get_app_list
    app_dict = self._build_app_dict(request)
  File "C:\Users\user\OneDrive\Desktop\Projects\databases_v1\venv\lib\site-packages\django\contrib\admin\sites.py", line 451, in _build_app_dict
    has_module_perms = model_admin.has_module_permission(request)
  File "C:\Users\user\OneDrive\Desktop\Projects\databases_v1\venv\lib\site-packages\django\contrib\admin\options.py", line 548, in has_module_permission
    return request.user.has_module_perms(self.opts.app_label)
  File "C:\Users\user\OneDrive\Desktop\Projects\databases_v1\venv\lib\site-packages\django\contrib\auth\models.py", line 458, in has_module_perms
    return _user_has_module_perms(self, module)
  File "C:\Users\user\OneDrive\Desktop\Projects\databases_v1\venv\lib\site-packages\django\contrib\auth\models.py", line 221, in _user_has_module_perms
    for backend in auth.get_backends():
  File "C:\Users\user\OneDrive\Desktop\Projects\databases_v1\venv\lib\site-packages\django\contrib\auth\__init__.py", line 38, in get_backends
    return _get_backends(return_tuples=False)
  File "C:\Users\user\OneDrive\Desktop\Projects\databases_v1\venv\lib\site-packages\django\contrib\auth\__init__.py", line 27, in _get_backends
    backend = load_backend(backend_path)
  File "C:\Users\user\OneDrive\Desktop\Projects\databases_v1\venv\lib\site-packages\django\contrib\auth\__init__.py", line 21, in load_backend
    return import_string(path)()
  File "C:\Users\user\OneDrive\Desktop\Projects\databases_v1\venv\lib\site-packages\django\utils\module_loading.py", line 15, in import_string
    raise ImportError("%s doesn't look like a module path" % dotted_path) from err
ImportError: a doesn't look like a module path
ERROR django.server "GET /admin/login/?next=/admin/ HTTP/1.1" 500 117477 2021-09-07 13:16:45,637
ERROR django.request Internal Server Error: /admin/login/ 2021-09-07 13:17:05,830
Traceback (most recent call last):
  File "C:\Users\user\OneDrive\Desktop\Projects\databases_v1\venv\lib\site-packages\django\utils\module_loading.py", line 13, in import_string
    module_path, class_name = dotted_path.rsplit('.', 1)
ValueError: not enough values to unpack (expected 2, got 1)

The above exception was the direct cause of the following exception:

Traceback (most recent call last):
  File "C:\Users\user\OneDrive\Desktop\Projects\databases_v1\venv\lib\site-packages\django\core\handlers\exception.py", line 47, in inner
    response = get_response(request)
  File "C:\Users\user\OneDrive\Desktop\Projects\databases_v1\venv\lib\site-packages\django\core\handlers\base.py", line 181, in _get_response
    response = wrapped_callback(request, *callback_args, **callback_kwargs)
  File "C:\Users\user\OneDrive\Desktop\Projects\databases_v1\venv\lib\site-packages\django\views\decorators\cache.py", line 44, in _wrapped_view_func
    response = view_func(request, *args, **kwargs)
  File "C:\Users\user\OneDrive\Desktop\Projects\databases_v1\venv\lib\site-packages\django\contrib\admin\sites.py", line 398, in login
    **self.each_context(request),
  File "C:\Users\user\OneDrive\Desktop\Projects\databases_v1\venv\lib\site-packages\django\contrib\admin\sites.py", line 316, in each_context
    'available_apps': self.get_app_list(request),
  File "C:\Users\user\OneDrive\Desktop\Projects\databases_v1\venv\lib\site-packages\django\contrib\admin\sites.py", line 506, in get_app_list
    app_dict = self._build_app_dict(request)
  File "C:\Users\user\OneDrive\Desktop\Projects\databases_v1\venv\lib\site-packages\django\contrib\admin\sites.py", line 451, in _build_app_dict
    has_module_perms = model_admin.has_module_permission(request)
  File "C:\Users\user\OneDrive\Desktop\Projects\databases_v1\venv\lib\site-packages\django\contrib\admin\options.py", line 548, in has_module_permission
    return request.user.has_module_perms(self.opts.app_label)
  File "C:\Users\user\OneDrive\Desktop\Projects\databases_v1\venv\lib\site-packages\django\contrib\auth\models.py", line 458, in has_module_perms
    return _user_has_module_perms(self, module)
  File "C:\Users\user\OneDrive\Desktop\Projects\databases_v1\venv\lib\site-packages\django\contrib\auth\models.py", line 221, in _user_has_module_perms
    for backend in auth.get_backends():
  File "C:\Users\user\OneDrive\Desktop\Projects\databases_v1\venv\lib\site-packages\django\contrib\auth\__init__.py", line 38, in get_backends
    return _get_backends(return_tuples=False)
  File "C:\Users\user\OneDrive\Desktop\Projects\databases_v1\venv\lib\site-packages\django\contrib\auth\__init__.py", line 27, in _get_backends
    backend = load_backend(backend_path)
  File "C:\Users\user\OneDrive\Desktop\Projects\databases_v1\venv\lib\site-packages\django\contrib\auth\__init__.py", line 21, in load_backend
    return import_string(path)()
  File "C:\Users\user\OneDrive\Desktop\Projects\databases_v1\venv\lib\site-packages\django\utils\module_loading.py", line 15, in import_string
    raise ImportError("%s doesn't look like a module path" % dotted_path) from err
ImportError: a doesn't look like a module path
ERROR django.server "GET /admin/login/?next=/admin/ HTTP/1.1" 500 117477 2021-09-07 13:17:05,843
ERROR django.request Internal Server Error: /admin/login/ 2021-09-07 13:17:35,799
Traceback (most recent call last):
  File "C:\Users\user\OneDrive\Desktop\Projects\databases_v1\venv\lib\site-packages\django\utils\module_loading.py", line 13, in import_string
    module_path, class_name = dotted_path.rsplit('.', 1)
ValueError: not enough values to unpack (expected 2, got 1)

The above exception was the direct cause of the following exception:

Traceback (most recent call last):
  File "C:\Users\user\OneDrive\Desktop\Projects\databases_v1\venv\lib\site-packages\django\core\handlers\exception.py", line 47, in inner
    response = get_response(request)
  File "C:\Users\user\OneDrive\Desktop\Projects\databases_v1\venv\lib\site-packages\django\core\handlers\base.py", line 181, in _get_response
    response = wrapped_callback(request, *callback_args, **callback_kwargs)
  File "C:\Users\user\OneDrive\Desktop\Projects\databases_v1\venv\lib\site-packages\django\views\decorators\cache.py", line 44, in _wrapped_view_func
    response = view_func(request, *args, **kwargs)
  File "C:\Users\user\OneDrive\Desktop\Projects\databases_v1\venv\lib\site-packages\django\contrib\admin\sites.py", line 398, in login
    **self.each_context(request),
  File "C:\Users\user\OneDrive\Desktop\Projects\databases_v1\venv\lib\site-packages\django\contrib\admin\sites.py", line 316, in each_context
    'available_apps': self.get_app_list(request),
  File "C:\Users\user\OneDrive\Desktop\Projects\databases_v1\venv\lib\site-packages\django\contrib\admin\sites.py", line 506, in get_app_list
    app_dict = self._build_app_dict(request)
  File "C:\Users\user\OneDrive\Desktop\Projects\databases_v1\venv\lib\site-packages\django\contrib\admin\sites.py", line 451, in _build_app_dict
    has_module_perms = model_admin.has_module_permission(request)
  File "C:\Users\user\OneDrive\Desktop\Projects\databases_v1\venv\lib\site-packages\django\contrib\admin\options.py", line 548, in has_module_permission
    return request.user.has_module_perms(self.opts.app_label)
  File "C:\Users\user\OneDrive\Desktop\Projects\databases_v1\venv\lib\site-packages\django\contrib\auth\models.py", line 458, in has_module_perms
    return _user_has_module_perms(self, module)
  File "C:\Users\user\OneDrive\Desktop\Projects\databases_v1\venv\lib\site-packages\django\contrib\auth\models.py", line 221, in _user_has_module_perms
    for backend in auth.get_backends():
  File "C:\Users\user\OneDrive\Desktop\Projects\databases_v1\venv\lib\site-packages\django\contrib\auth\__init__.py", line 38, in get_backends
    return _get_backends(return_tuples=False)
  File "C:\Users\user\OneDrive\Desktop\Projects\databases_v1\venv\lib\site-packages\django\contrib\auth\__init__.py", line 27, in _get_backends
    backend = load_backend(backend_path)
  File "C:\Users\user\OneDrive\Desktop\Projects\databases_v1\venv\lib\site-packages\django\contrib\auth\__init__.py", line 21, in load_backend
    return import_string(path)()
  File "C:\Users\user\OneDrive\Desktop\Projects\databases_v1\venv\lib\site-packages\django\utils\module_loading.py", line 15, in import_string
    raise ImportError("%s doesn't look like a module path" % dotted_path) from err
ImportError: C doesn't look like a module path
ERROR django.request Internal Server Error: /admin/login/ 2021-09-07 13:17:35,941
Traceback (most recent call last):
  File "C:\Users\user\OneDrive\Desktop\Projects\databases_v1\venv\lib\site-packages\django\utils\module_loading.py", line 13, in import_string
    module_path, class_name = dotted_path.rsplit('.', 1)
ValueError: not enough values to unpack (expected 2, got 1)

The above exception was the direct cause of the following exception:

Traceback (most recent call last):
  File "C:\Users\user\OneDrive\Desktop\Projects\databases_v1\venv\lib\site-packages\django\core\handlers\exception.py", line 47, in inner
    response = get_response(request)
  File "C:\Users\user\OneDrive\Desktop\Projects\databases_v1\venv\lib\site-packages\django\core\handlers\base.py", line 181, in _get_response
    response = wrapped_callback(request, *callback_args, **callback_kwargs)
  File "C:\Users\user\OneDrive\Desktop\Projects\databases_v1\venv\lib\site-packages\django\views\decorators\cache.py", line 44, in _wrapped_view_func
    response = view_func(request, *args, **kwargs)
  File "C:\Users\user\OneDrive\Desktop\Projects\databases_v1\venv\lib\site-packages\django\contrib\admin\sites.py", line 398, in login
    **self.each_context(request),
  File "C:\Users\user\OneDrive\Desktop\Projects\databases_v1\venv\lib\site-packages\django\contrib\admin\sites.py", line 316, in each_context
    'available_apps': self.get_app_list(request),
  File "C:\Users\user\OneDrive\Desktop\Projects\databases_v1\venv\lib\site-packages\django\contrib\admin\sites.py", line 506, in get_app_list
    app_dict = self._build_app_dict(request)
  File "C:\Users\user\OneDrive\Desktop\Projects\databases_v1\venv\lib\site-packages\django\contrib\admin\sites.py", line 451, in _build_app_dict
    has_module_perms = model_admin.has_module_permission(request)
  File "C:\Users\user\OneDrive\Desktop\Projects\databases_v1\venv\lib\site-packages\django\contrib\admin\options.py", line 548, in has_module_permission
    return request.user.has_module_perms(self.opts.app_label)
  File "C:\Users\user\OneDrive\Desktop\Projects\databases_v1\venv\lib\site-packages\django\contrib\auth\models.py", line 458, in has_module_perms
    return _user_has_module_perms(self, module)
  File "C:\Users\user\OneDrive\Desktop\Projects\databases_v1\venv\lib\site-packages\django\contrib\auth\models.py", line 221, in _user_has_module_perms
    for backend in auth.get_backends():
  File "C:\Users\user\OneDrive\Desktop\Projects\databases_v1\venv\lib\site-packages\django\contrib\auth\__init__.py", line 38, in get_backends
    return _get_backends(return_tuples=False)
  File "C:\Users\user\OneDrive\Desktop\Projects\databases_v1\venv\lib\site-packages\django\contrib\auth\__init__.py", line 27, in _get_backends
    backend = load_backend(backend_path)
  File "C:\Users\user\OneDrive\Desktop\Projects\databases_v1\venv\lib\site-packages\django\contrib\auth\__init__.py", line 21, in load_backend
    return import_string(path)()
  File "C:\Users\user\OneDrive\Desktop\Projects\databases_v1\venv\lib\site-packages\django\utils\module_loading.py", line 15, in import_string
    raise ImportError("%s doesn't look like a module path" % dotted_path) from err
ImportError: C doesn't look like a module path
ERROR django.server "GET /admin/login/?next=/admin/ HTTP/1.1" 500 117555 2021-09-07 13:17:35,950
ERROR django.request Internal Server Error: /admin/login/ 2021-09-07 13:17:36,475
Traceback (most recent call last):
  File "C:\Users\user\OneDrive\Desktop\Projects\databases_v1\venv\lib\site-packages\django\utils\module_loading.py", line 13, in import_string
    module_path, class_name = dotted_path.rsplit('.', 1)
ValueError: not enough values to unpack (expected 2, got 1)

The above exception was the direct cause of the following exception:

Traceback (most recent call last):
  File "C:\Users\user\OneDrive\Desktop\Projects\databases_v1\venv\lib\site-packages\django\core\handlers\exception.py", line 47, in inner
    response = get_response(request)
  File "C:\Users\user\OneDrive\Desktop\Projects\databases_v1\venv\lib\site-packages\django\core\handlers\base.py", line 181, in _get_response
    response = wrapped_callback(request, *callback_args, **callback_kwargs)
  File "C:\Users\user\OneDrive\Desktop\Projects\databases_v1\venv\lib\site-packages\django\views\decorators\cache.py", line 44, in _wrapped_view_func
    response = view_func(request, *args, **kwargs)
  File "C:\Users\user\OneDrive\Desktop\Projects\databases_v1\venv\lib\site-packages\django\contrib\admin\sites.py", line 398, in login
    **self.each_context(request),
  File "C:\Users\user\OneDrive\Desktop\Projects\databases_v1\venv\lib\site-packages\django\contrib\admin\sites.py", line 316, in each_context
    'available_apps': self.get_app_list(request),
  File "C:\Users\user\OneDrive\Desktop\Projects\databases_v1\venv\lib\site-packages\django\contrib\admin\sites.py", line 506, in get_app_list
    app_dict = self._build_app_dict(request)
  File "C:\Users\user\OneDrive\Desktop\Projects\databases_v1\venv\lib\site-packages\django\contrib\admin\sites.py", line 451, in _build_app_dict
    has_module_perms = model_admin.has_module_permission(request)
  File "C:\Users\user\OneDrive\Desktop\Projects\databases_v1\venv\lib\site-packages\django\contrib\admin\options.py", line 548, in has_module_permission
    return request.user.has_module_perms(self.opts.app_label)
  File "C:\Users\user\OneDrive\Desktop\Projects\databases_v1\venv\lib\site-packages\django\contrib\auth\models.py", line 458, in has_module_perms
    return _user_has_module_perms(self, module)
  File "C:\Users\user\OneDrive\Desktop\Projects\databases_v1\venv\lib\site-packages\django\contrib\auth\models.py", line 221, in _user_has_module_perms
    for backend in auth.get_backends():
  File "C:\Users\user\OneDrive\Desktop\Projects\databases_v1\venv\lib\site-packages\django\contrib\auth\__init__.py", line 38, in get_backends
    return _get_backends(return_tuples=False)
  File "C:\Users\user\OneDrive\Desktop\Projects\databases_v1\venv\lib\site-packages\django\contrib\auth\__init__.py", line 27, in _get_backends
    backend = load_backend(backend_path)
  File "C:\Users\user\OneDrive\Desktop\Projects\databases_v1\venv\lib\site-packages\django\contrib\auth\__init__.py", line 21, in load_backend
    return import_string(path)()
  File "C:\Users\user\OneDrive\Desktop\Projects\databases_v1\venv\lib\site-packages\django\utils\module_loading.py", line 15, in import_string
    raise ImportError("%s doesn't look like a module path" % dotted_path) from err
ImportError: C doesn't look like a module path
ERROR django.server "GET /admin/login/?next=/admin/ HTTP/1.1" 500 117555 2021-09-07 13:17:36,480
ERROR django.request Internal Server Error: /admin/login/ 2021-09-07 13:18:03,722
Traceback (most recent call last):
  File "C:\Users\user\OneDrive\Desktop\Projects\databases_v1\venv\lib\site-packages\django\utils\module_loading.py", line 13, in import_string
    module_path, class_name = dotted_path.rsplit('.', 1)
ValueError: not enough values to unpack (expected 2, got 1)

The above exception was the direct cause of the following exception:

Traceback (most recent call last):
  File "C:\Users\user\OneDrive\Desktop\Projects\databases_v1\venv\lib\site-packages\django\core\handlers\exception.py", line 47, in inner
    response = get_response(request)
  File "C:\Users\user\OneDrive\Desktop\Projects\databases_v1\venv\lib\site-packages\django\core\handlers\base.py", line 181, in _get_response
    response = wrapped_callback(request, *callback_args, **callback_kwargs)
  File "C:\Users\user\OneDrive\Desktop\Projects\databases_v1\venv\lib\site-packages\django\views\decorators\cache.py", line 44, in _wrapped_view_func
    response = view_func(request, *args, **kwargs)
  File "C:\Users\user\OneDrive\Desktop\Projects\databases_v1\venv\lib\site-packages\django\contrib\admin\sites.py", line 398, in login
    **self.each_context(request),
  File "C:\Users\user\OneDrive\Desktop\Projects\databases_v1\venv\lib\site-packages\django\contrib\admin\sites.py", line 316, in each_context
    'available_apps': self.get_app_list(request),
  File "C:\Users\user\OneDrive\Desktop\Projects\databases_v1\venv\lib\site-packages\django\contrib\admin\sites.py", line 506, in get_app_list
    app_dict = self._build_app_dict(request)
  File "C:\Users\user\OneDrive\Desktop\Projects\databases_v1\venv\lib\site-packages\django\contrib\admin\sites.py", line 451, in _build_app_dict
    has_module_perms = model_admin.has_module_permission(request)
  File "C:\Users\user\OneDrive\Desktop\Projects\databases_v1\venv\lib\site-packages\django\contrib\admin\options.py", line 548, in has_module_permission
    return request.user.has_module_perms(self.opts.app_label)
  File "C:\Users\user\OneDrive\Desktop\Projects\databases_v1\venv\lib\site-packages\django\contrib\auth\models.py", line 458, in has_module_perms
    return _user_has_module_perms(self, module)
  File "C:\Users\user\OneDrive\Desktop\Projects\databases_v1\venv\lib\site-packages\django\contrib\auth\models.py", line 221, in _user_has_module_perms
    for backend in auth.get_backends():
  File "C:\Users\user\OneDrive\Desktop\Projects\databases_v1\venv\lib\site-packages\django\contrib\auth\__init__.py", line 38, in get_backends
    return _get_backends(return_tuples=False)
  File "C:\Users\user\OneDrive\Desktop\Projects\databases_v1\venv\lib\site-packages\django\contrib\auth\__init__.py", line 27, in _get_backends
    backend = load_backend(backend_path)
  File "C:\Users\user\OneDrive\Desktop\Projects\databases_v1\venv\lib\site-packages\django\contrib\auth\__init__.py", line 21, in load_backend
    return import_string(path)()
  File "C:\Users\user\OneDrive\Desktop\Projects\databases_v1\venv\lib\site-packages\django\utils\module_loading.py", line 15, in import_string
    raise ImportError("%s doesn't look like a module path" % dotted_path) from err
ImportError: C doesn't look like a module path
ERROR django.server "GET /admin/login/?next=/admin/ HTTP/1.1" 500 117546 2021-09-07 13:18:03,733
ERROR django.request Internal Server Error: /admin/login/ 2021-09-07 13:18:03,901
Traceback (most recent call last):
  File "C:\Users\user\OneDrive\Desktop\Projects\databases_v1\venv\lib\site-packages\django\utils\module_loading.py", line 13, in import_string
    module_path, class_name = dotted_path.rsplit('.', 1)
ValueError: not enough values to unpack (expected 2, got 1)

The above exception was the direct cause of the following exception:

Traceback (most recent call last):
  File "C:\Users\user\OneDrive\Desktop\Projects\databases_v1\venv\lib\site-packages\django\core\handlers\exception.py", line 47, in inner
    response = get_response(request)
  File "C:\Users\user\OneDrive\Desktop\Projects\databases_v1\venv\lib\site-packages\django\core\handlers\base.py", line 181, in _get_response
    response = wrapped_callback(request, *callback_args, **callback_kwargs)
  File "C:\Users\user\OneDrive\Desktop\Projects\databases_v1\venv\lib\site-packages\django\views\decorators\cache.py", line 44, in _wrapped_view_func
    response = view_func(request, *args, **kwargs)
  File "C:\Users\user\OneDrive\Desktop\Projects\databases_v1\venv\lib\site-packages\django\contrib\admin\sites.py", line 398, in login
    **self.each_context(request),
  File "C:\Users\user\OneDrive\Desktop\Projects\databases_v1\venv\lib\site-packages\django\contrib\admin\sites.py", line 316, in each_context
    'available_apps': self.get_app_list(request),
  File "C:\Users\user\OneDrive\Desktop\Projects\databases_v1\venv\lib\site-packages\django\contrib\admin\sites.py", line 506, in get_app_list
    app_dict = self._build_app_dict(request)
  File "C:\Users\user\OneDrive\Desktop\Projects\databases_v1\venv\lib\site-packages\django\contrib\admin\sites.py", line 451, in _build_app_dict
    has_module_perms = model_admin.has_module_permission(request)
  File "C:\Users\user\OneDrive\Desktop\Projects\databases_v1\venv\lib\site-packages\django\contrib\admin\options.py", line 548, in has_module_permission
    return request.user.has_module_perms(self.opts.app_label)
  File "C:\Users\user\OneDrive\Desktop\Projects\databases_v1\venv\lib\site-packages\django\contrib\auth\models.py", line 458, in has_module_perms
    return _user_has_module_perms(self, module)
  File "C:\Users\user\OneDrive\Desktop\Projects\databases_v1\venv\lib\site-packages\django\contrib\auth\models.py", line 221, in _user_has_module_perms
    for backend in auth.get_backends():
  File "C:\Users\user\OneDrive\Desktop\Projects\databases_v1\venv\lib\site-packages\django\contrib\auth\__init__.py", line 38, in get_backends
    return _get_backends(return_tuples=False)
  File "C:\Users\user\OneDrive\Desktop\Projects\databases_v1\venv\lib\site-packages\django\contrib\auth\__init__.py", line 27, in _get_backends
    backend = load_backend(backend_path)
  File "C:\Users\user\OneDrive\Desktop\Projects\databases_v1\venv\lib\site-packages\django\contrib\auth\__init__.py", line 21, in load_backend
    return import_string(path)()
  File "C:\Users\user\OneDrive\Desktop\Projects\databases_v1\venv\lib\site-packages\django\utils\module_loading.py", line 15, in import_string
    raise ImportError("%s doesn't look like a module path" % dotted_path) from err
ImportError: C doesn't look like a module path
ERROR django.server "GET /admin/login/?next=/admin/ HTTP/1.1" 500 117546 2021-09-07 13:18:03,905
ERROR django.request Internal Server Error: /admin/login/ 2021-09-07 13:18:19,241
Traceback (most recent call last):
  File "C:\Users\user\OneDrive\Desktop\Projects\databases_v1\venv\lib\site-packages\django\utils\module_loading.py", line 13, in import_string
    module_path, class_name = dotted_path.rsplit('.', 1)
ValueError: not enough values to unpack (expected 2, got 1)

The above exception was the direct cause of the following exception:

Traceback (most recent call last):
  File "C:\Users\user\OneDrive\Desktop\Projects\databases_v1\venv\lib\site-packages\django\core\handlers\exception.py", line 47, in inner
    response = get_response(request)
  File "C:\Users\user\OneDrive\Desktop\Projects\databases_v1\venv\lib\site-packages\django\core\handlers\base.py", line 181, in _get_response
    response = wrapped_callback(request, *callback_args, **callback_kwargs)
  File "C:\Users\user\OneDrive\Desktop\Projects\databases_v1\venv\lib\site-packages\django\views\decorators\cache.py", line 44, in _wrapped_view_func
    response = view_func(request, *args, **kwargs)
  File "C:\Users\user\OneDrive\Desktop\Projects\databases_v1\venv\lib\site-packages\django\contrib\admin\sites.py", line 398, in login
    **self.each_context(request),
  File "C:\Users\user\OneDrive\Desktop\Projects\databases_v1\venv\lib\site-packages\django\contrib\admin\sites.py", line 316, in each_context
    'available_apps': self.get_app_list(request),
  File "C:\Users\user\OneDrive\Desktop\Projects\databases_v1\venv\lib\site-packages\django\contrib\admin\sites.py", line 506, in get_app_list
    app_dict = self._build_app_dict(request)
  File "C:\Users\user\OneDrive\Desktop\Projects\databases_v1\venv\lib\site-packages\django\contrib\admin\sites.py", line 451, in _build_app_dict
    has_module_perms = model_admin.has_module_permission(request)
  File "C:\Users\user\OneDrive\Desktop\Projects\databases_v1\venv\lib\site-packages\django\contrib\admin\options.py", line 548, in has_module_permission
    return request.user.has_module_perms(self.opts.app_label)
  File "C:\Users\user\OneDrive\Desktop\Projects\databases_v1\venv\lib\site-packages\django\contrib\auth\models.py", line 458, in has_module_perms
    return _user_has_module_perms(self, module)
  File "C:\Users\user\OneDrive\Desktop\Projects\databases_v1\venv\lib\site-packages\django\contrib\auth\models.py", line 221, in _user_has_module_perms
    for backend in auth.get_backends():
  File "C:\Users\user\OneDrive\Desktop\Projects\databases_v1\venv\lib\site-packages\django\contrib\auth\__init__.py", line 38, in get_backends
    return _get_backends(return_tuples=False)
  File "C:\Users\user\OneDrive\Desktop\Projects\databases_v1\venv\lib\site-packages\django\contrib\auth\__init__.py", line 27, in _get_backends
    backend = load_backend(backend_path)
  File "C:\Users\user\OneDrive\Desktop\Projects\databases_v1\venv\lib\site-packages\django\contrib\auth\__init__.py", line 21, in load_backend
    return import_string(path)()
  File "C:\Users\user\OneDrive\Desktop\Projects\databases_v1\venv\lib\site-packages\django\utils\module_loading.py", line 15, in import_string
    raise ImportError("%s doesn't look like a module path" % dotted_path) from err
ImportError: d doesn't look like a module path
ERROR django.server "GET /admin/login/?next=/admin/ HTTP/1.1" 500 117493 2021-09-07 13:18:19,246
ERROR django.request Internal Server Error: /admin/login/ 2021-09-07 13:18:35,021
Traceback (most recent call last):
  File "C:\Users\user\OneDrive\Desktop\Projects\databases_v1\venv\lib\site-packages\django\utils\module_loading.py", line 13, in import_string
    module_path, class_name = dotted_path.rsplit('.', 1)
ValueError: not enough values to unpack (expected 2, got 1)

The above exception was the direct cause of the following exception:

Traceback (most recent call last):
  File "C:\Users\user\OneDrive\Desktop\Projects\databases_v1\venv\lib\site-packages\django\core\handlers\exception.py", line 47, in inner
    response = get_response(request)
  File "C:\Users\user\OneDrive\Desktop\Projects\databases_v1\venv\lib\site-packages\django\core\handlers\base.py", line 181, in _get_response
    response = wrapped_callback(request, *callback_args, **callback_kwargs)
  File "C:\Users\user\OneDrive\Desktop\Projects\databases_v1\venv\lib\site-packages\django\views\decorators\cache.py", line 44, in _wrapped_view_func
    response = view_func(request, *args, **kwargs)
  File "C:\Users\user\OneDrive\Desktop\Projects\databases_v1\venv\lib\site-packages\django\contrib\admin\sites.py", line 398, in login
    **self.each_context(request),
  File "C:\Users\user\OneDrive\Desktop\Projects\databases_v1\venv\lib\site-packages\django\contrib\admin\sites.py", line 316, in each_context
    'available_apps': self.get_app_list(request),
  File "C:\Users\user\OneDrive\Desktop\Projects\databases_v1\venv\lib\site-packages\django\contrib\admin\sites.py", line 506, in get_app_list
    app_dict = self._build_app_dict(request)
  File "C:\Users\user\OneDrive\Desktop\Projects\databases_v1\venv\lib\site-packages\django\contrib\admin\sites.py", line 451, in _build_app_dict
    has_module_perms = model_admin.has_module_permission(request)
  File "C:\Users\user\OneDrive\Desktop\Projects\databases_v1\venv\lib\site-packages\django\contrib\admin\options.py", line 548, in has_module_permission
    return request.user.has_module_perms(self.opts.app_label)
  File "C:\Users\user\OneDrive\Desktop\Projects\databases_v1\venv\lib\site-packages\django\contrib\auth\models.py", line 458, in has_module_perms
    return _user_has_module_perms(self, module)
  File "C:\Users\user\OneDrive\Desktop\Projects\databases_v1\venv\lib\site-packages\django\contrib\auth\models.py", line 221, in _user_has_module_perms
    for backend in auth.get_backends():
  File "C:\Users\user\OneDrive\Desktop\Projects\databases_v1\venv\lib\site-packages\django\contrib\auth\__init__.py", line 38, in get_backends
    return _get_backends(return_tuples=False)
  File "C:\Users\user\OneDrive\Desktop\Projects\databases_v1\venv\lib\site-packages\django\contrib\auth\__init__.py", line 27, in _get_backends
    backend = load_backend(backend_path)
  File "C:\Users\user\OneDrive\Desktop\Projects\databases_v1\venv\lib\site-packages\django\contrib\auth\__init__.py", line 21, in load_backend
    return import_string(path)()
  File "C:\Users\user\OneDrive\Desktop\Projects\databases_v1\venv\lib\site-packages\django\utils\module_loading.py", line 15, in import_string
    raise ImportError("%s doesn't look like a module path" % dotted_path) from err
ImportError: d doesn't look like a module path
ERROR django.server "GET /admin/login/?next=/admin/ HTTP/1.1" 500 117539 2021-09-07 13:18:35,034
ERROR django.request Internal Server Error: /admin/login/ 2021-09-07 13:18:35,326
Traceback (most recent call last):
  File "C:\Users\user\OneDrive\Desktop\Projects\databases_v1\venv\lib\site-packages\django\utils\module_loading.py", line 13, in import_string
    module_path, class_name = dotted_path.rsplit('.', 1)
ValueError: not enough values to unpack (expected 2, got 1)

The above exception was the direct cause of the following exception:

Traceback (most recent call last):
  File "C:\Users\user\OneDrive\Desktop\Projects\databases_v1\venv\lib\site-packages\django\core\handlers\exception.py", line 47, in inner
    response = get_response(request)
  File "C:\Users\user\OneDrive\Desktop\Projects\databases_v1\venv\lib\site-packages\django\core\handlers\base.py", line 181, in _get_response
    response = wrapped_callback(request, *callback_args, **callback_kwargs)
  File "C:\Users\user\OneDrive\Desktop\Projects\databases_v1\venv\lib\site-packages\django\views\decorators\cache.py", line 44, in _wrapped_view_func
    response = view_func(request, *args, **kwargs)
  File "C:\Users\user\OneDrive\Desktop\Projects\databases_v1\venv\lib\site-packages\django\contrib\admin\sites.py", line 398, in login
    **self.each_context(request),
  File "C:\Users\user\OneDrive\Desktop\Projects\databases_v1\venv\lib\site-packages\django\contrib\admin\sites.py", line 316, in each_context
    'available_apps': self.get_app_list(request),
  File "C:\Users\user\OneDrive\Desktop\Projects\databases_v1\venv\lib\site-packages\django\contrib\admin\sites.py", line 506, in get_app_list
    app_dict = self._build_app_dict(request)
  File "C:\Users\user\OneDrive\Desktop\Projects\databases_v1\venv\lib\site-packages\django\contrib\admin\sites.py", line 451, in _build_app_dict
    has_module_perms = model_admin.has_module_permission(request)
  File "C:\Users\user\OneDrive\Desktop\Projects\databases_v1\venv\lib\site-packages\django\contrib\admin\options.py", line 548, in has_module_permission
    return request.user.has_module_perms(self.opts.app_label)
  File "C:\Users\user\OneDrive\Desktop\Projects\databases_v1\venv\lib\site-packages\django\contrib\auth\models.py", line 458, in has_module_perms
    return _user_has_module_perms(self, module)
  File "C:\Users\user\OneDrive\Desktop\Projects\databases_v1\venv\lib\site-packages\django\contrib\auth\models.py", line 221, in _user_has_module_perms
    for backend in auth.get_backends():
  File "C:\Users\user\OneDrive\Desktop\Projects\databases_v1\venv\lib\site-packages\django\contrib\auth\__init__.py", line 38, in get_backends
    return _get_backends(return_tuples=False)
  File "C:\Users\user\OneDrive\Desktop\Projects\databases_v1\venv\lib\site-packages\django\contrib\auth\__init__.py", line 27, in _get_backends
    backend = load_backend(backend_path)
  File "C:\Users\user\OneDrive\Desktop\Projects\databases_v1\venv\lib\site-packages\django\contrib\auth\__init__.py", line 21, in load_backend
    return import_string(path)()
  File "C:\Users\user\OneDrive\Desktop\Projects\databases_v1\venv\lib\site-packages\django\utils\module_loading.py", line 15, in import_string
    raise ImportError("%s doesn't look like a module path" % dotted_path) from err
ImportError: d doesn't look like a module path
ERROR django.server "GET /admin/login/?next=/admin/ HTTP/1.1" 500 117539 2021-09-07 13:18:35,331
