ERROR django.request Internal Server Error: /work/add/ 2021-11-05 11:02:05,399
Traceback (most recent call last):
  File "D:\Users\ntabyldieva\Desktop\databases_v1\env\lib\site-packages\django\core\handlers\exception.py", line 47, in inner
    response = get_response(request)
  File "D:\Users\ntabyldieva\Desktop\databases_v1\env\lib\site-packages\django\core\handlers\base.py", line 181, in _get_response
    response = wrapped_callback(request, *callback_args, **callback_kwargs)
  File "D:\Users\ntabyldieva\Desktop\databases_v1\env\lib\site-packages\django\contrib\auth\decorators.py", line 21, in _wrapped_view
    return view_func(request, *args, **kwargs)
  File "D:\Users\ntabyldieva\Desktop\databases_v1\work\views.py", line 122, in add_case
    individualFormSet.save()
  File "D:\Users\ntabyldieva\Desktop\databases_v1\env\lib\site-packages\django\forms\models.py", line 681, in save
    return self.save_existing_objects(commit) + self.save_new_objects(commit)
  File "D:\Users\ntabyldieva\Desktop\databases_v1\env\lib\site-packages\django\forms\models.py", line 819, in save_new_objects
    self.new_objects.append(self.save_new(form, commit=commit))
  File "D:\Users\ntabyldieva\Desktop\databases_v1\env\lib\site-packages\django\forms\models.py", line 658, in save_new
    return form.save(commit=commit)
  File "D:\Users\ntabyldieva\Desktop\databases_v1\env\lib\site-packages\django\forms\models.py", line 460, in save
    raise ValueError(
ValueError: The IndividualInfo could not be created because the data didn't validate.
ERROR django.server "POST /work/add/ HTTP/1.1" 500 111509 2021-11-05 11:02:05,404
ERROR django.request Internal Server Error: /work/add/ 2021-11-05 12:05:48,624
Traceback (most recent call last):
  File "D:\Users\ntabyldieva\Desktop\databases_v1\env\lib\site-packages\django\core\handlers\exception.py", line 47, in inner
    response = get_response(request)
  File "D:\Users\ntabyldieva\Desktop\databases_v1\env\lib\site-packages\django\core\handlers\base.py", line 181, in _get_response
    response = wrapped_callback(request, *callback_args, **callback_kwargs)
  File "D:\Users\ntabyldieva\Desktop\databases_v1\env\lib\site-packages\django\contrib\auth\decorators.py", line 21, in _wrapped_view
    return view_func(request, *args, **kwargs)
  File "D:\Users\ntabyldieva\Desktop\databases_v1\work\views.py", line 123, in add_case
    individualFormSet.save()
  File "D:\Users\ntabyldieva\Desktop\databases_v1\env\lib\site-packages\django\forms\models.py", line 681, in save
    return self.save_existing_objects(commit) + self.save_new_objects(commit)
  File "D:\Users\ntabyldieva\Desktop\databases_v1\env\lib\site-packages\django\forms\models.py", line 819, in save_new_objects
    self.new_objects.append(self.save_new(form, commit=commit))
  File "D:\Users\ntabyldieva\Desktop\databases_v1\env\lib\site-packages\django\forms\models.py", line 658, in save_new
    return form.save(commit=commit)
  File "D:\Users\ntabyldieva\Desktop\databases_v1\env\lib\site-packages\django\forms\models.py", line 460, in save
    raise ValueError(
ValueError: The IndividualInfo could not be created because the data didn't validate.
ERROR django.server "POST /work/add/ HTTP/1.1" 500 111573 2021-11-05 12:05:48,629
WARNING django.request Not Found: /favicon.ico 2021-11-05 12:25:14,563
WARNING django.server "GET /favicon.ico HTTP/1.1" 404 3524 2021-11-05 12:25:14,563
WARNING django.request Not Found: /favicon.ico 2021-11-05 13:40:16,684
WARNING django.server "GET /favicon.ico HTTP/1.1" 404 3524 2021-11-05 13:40:16,685
ERROR django.request Internal Server Error: /work/add/ 2021-11-05 13:51:42,006
Traceback (most recent call last):
  File "D:\Users\ntabyldieva\Desktop\databases_v1\env\lib\site-packages\django\core\handlers\exception.py", line 47, in inner
    response = get_response(request)
  File "D:\Users\ntabyldieva\Desktop\databases_v1\env\lib\site-packages\django\core\handlers\base.py", line 181, in _get_response
    response = wrapped_callback(request, *callback_args, **callback_kwargs)
  File "D:\Users\ntabyldieva\Desktop\databases_v1\env\lib\site-packages\django\contrib\auth\decorators.py", line 21, in _wrapped_view
    return view_func(request, *args, **kwargs)
  File "D:\Users\ntabyldieva\Desktop\databases_v1\work\views.py", line 158, in add_case
    pprint(ind)
TypeError: 'module' object is not callable
ERROR django.server "POST /work/add/ HTTP/1.1" 500 95432 2021-11-05 13:51:42,010
WARNING django.request Not Found: /favicon.ico 2021-11-05 14:50:31,750
WARNING django.server "GET /favicon.ico HTTP/1.1" 404 3524 2021-11-05 14:50:31,750
WARNING django.request Not Found: /favicon.ico 2021-11-05 14:53:38,537
WARNING django.server "GET /favicon.ico HTTP/1.1" 404 3524 2021-11-05 14:53:38,537
WARNING django.request Not Found: /favicon.ico 2021-11-05 15:05:04,018
WARNING django.server "GET /favicon.ico HTTP/1.1" 404 3524 2021-11-05 15:05:04,019
WARNING django.request Not Found: /favicon.ico 2021-11-05 15:17:49,092
WARNING django.server "GET /favicon.ico HTTP/1.1" 404 3524 2021-11-05 15:17:49,092
WARNING django.request Not Found: /favicon.ico 2021-11-05 15:19:06,749
WARNING django.server "GET /favicon.ico HTTP/1.1" 404 3524 2021-11-05 15:19:06,750
ERROR django.request Internal Server Error: /work/add/ 2021-11-05 15:19:16,148
Traceback (most recent call last):
  File "D:\Users\ntabyldieva\Desktop\databases_v1\env\lib\site-packages\django\core\handlers\exception.py", line 47, in inner
    response = get_response(request)
  File "D:\Users\ntabyldieva\Desktop\databases_v1\env\lib\site-packages\django\core\handlers\base.py", line 181, in _get_response
    response = wrapped_callback(request, *callback_args, **callback_kwargs)
  File "D:\Users\ntabyldieva\Desktop\databases_v1\env\lib\site-packages\django\contrib\auth\decorators.py", line 21, in _wrapped_view
    return view_func(request, *args, **kwargs)
  File "D:\Users\ntabyldieva\Desktop\databases_v1\work\views.py", line 154, in add_case
    individualForm = IndividualForm
NameError: name 'IndividualForm' is not defined
ERROR django.server "GET /work/add/ HTTP/1.1" 500 73544 2021-11-05 15:19:16,151
ERROR django.request Internal Server Error: /work/add/ 2021-11-05 15:19:46,465
Traceback (most recent call last):
  File "D:\Users\ntabyldieva\Desktop\databases_v1\env\lib\site-packages\django\core\handlers\exception.py", line 47, in inner
    response = get_response(request)
  File "D:\Users\ntabyldieva\Desktop\databases_v1\env\lib\site-packages\django\core\handlers\base.py", line 181, in _get_response
    response = wrapped_callback(request, *callback_args, **callback_kwargs)
  File "D:\Users\ntabyldieva\Desktop\databases_v1\env\lib\site-packages\django\contrib\auth\decorators.py", line 21, in _wrapped_view
    return view_func(request, *args, **kwargs)
  File "D:\Users\ntabyldieva\Desktop\databases_v1\work\views.py", line 154, in add_case
    individualForm = IndividualForm
NameError: name 'IndividualForm' is not defined
ERROR django.server "GET /work/add/ HTTP/1.1" 500 73551 2021-11-05 15:19:46,467
ERROR django.request Internal Server Error: /work/add/ 2021-11-05 15:29:08,411
Traceback (most recent call last):
  File "D:\Users\ntabyldieva\Desktop\databases_v1\env\lib\site-packages\django\core\handlers\exception.py", line 47, in inner
    response = get_response(request)
  File "D:\Users\ntabyldieva\Desktop\databases_v1\env\lib\site-packages\django\core\handlers\base.py", line 181, in _get_response
    response = wrapped_callback(request, *callback_args, **callback_kwargs)
  File "D:\Users\ntabyldieva\Desktop\databases_v1\env\lib\site-packages\django\contrib\auth\decorators.py", line 21, in _wrapped_view
    return view_func(request, *args, **kwargs)
  File "D:\Users\ntabyldieva\Desktop\databases_v1\work\views.py", line 114, in add_case
    individualFormSet = modelformset_factory(IndividualInfo, fields='__all__', forms=IndividualForm, exclude=['case'], )
TypeError: modelformset_factory() got an unexpected keyword argument 'forms'
ERROR django.server "GET /work/add/ HTTP/1.1" 500 73288 2021-11-05 15:29:08,414
ERROR django.request Internal Server Error: /work/add/ 2021-11-05 15:31:07,347
Traceback (most recent call last):
  File "D:\Users\ntabyldieva\Desktop\databases_v1\env\lib\site-packages\django\core\handlers\exception.py", line 47, in inner
    response = get_response(request)
  File "D:\Users\ntabyldieva\Desktop\databases_v1\env\lib\site-packages\django\core\handlers\base.py", line 181, in _get_response
    response = wrapped_callback(request, *callback_args, **callback_kwargs)
  File "D:\Users\ntabyldieva\Desktop\databases_v1\env\lib\site-packages\django\contrib\auth\decorators.py", line 21, in _wrapped_view
    return view_func(request, *args, **kwargs)
  File "D:\Users\ntabyldieva\Desktop\databases_v1\work\views.py", line 114, in add_case
    individualFormSet = modelformset_factory(IndividualInfo, fields='__all__', form=IndividualForm, exclude=['case'], )
TypeError: modelformset_factory() got an unexpected keyword argument 'forms'
ERROR django.server "GET /work/add/ HTTP/1.1" 500 73286 2021-11-05 15:31:07,350
ERROR django.request Internal Server Error: /work/add/ 2021-11-05 15:31:10,146
Traceback (most recent call last):
  File "D:\Users\ntabyldieva\Desktop\databases_v1\env\lib\site-packages\django\core\handlers\exception.py", line 47, in inner
    response = get_response(request)
  File "D:\Users\ntabyldieva\Desktop\databases_v1\env\lib\site-packages\django\core\handlers\base.py", line 181, in _get_response
    response = wrapped_callback(request, *callback_args, **callback_kwargs)
  File "D:\Users\ntabyldieva\Desktop\databases_v1\env\lib\site-packages\django\contrib\auth\decorators.py", line 21, in _wrapped_view
    return view_func(request, *args, **kwargs)
  File "D:\Users\ntabyldieva\Desktop\databases_v1\work\views.py", line 166, in add_case
    'individualFormSet': forms,
UnboundLocalError: local variable 'forms' referenced before assignment
ERROR django.server "GET /work/add/ HTTP/1.1" 500 75042 2021-11-05 15:31:10,149
ERROR django.request Internal Server Error: /work/add/ 2021-11-05 15:32:14,454
Traceback (most recent call last):
  File "D:\Users\ntabyldieva\Desktop\databases_v1\env\lib\site-packages\django\core\handlers\exception.py", line 47, in inner
    response = get_response(request)
  File "D:\Users\ntabyldieva\Desktop\databases_v1\env\lib\site-packages\django\core\handlers\base.py", line 181, in _get_response
    response = wrapped_callback(request, *callback_args, **callback_kwargs)
  File "D:\Users\ntabyldieva\Desktop\databases_v1\env\lib\site-packages\django\contrib\auth\decorators.py", line 21, in _wrapped_view
    return view_func(request, *args, **kwargs)
  File "D:\Users\ntabyldieva\Desktop\databases_v1\work\views.py", line 166, in add_case
    'individualFormSet': individualFormSet,
UnboundLocalError: local variable 'forms' referenced before assignment
ERROR django.server "GET /work/add/ HTTP/1.1" 500 75066 2021-11-05 15:32:14,457
ERROR django.request Internal Server Error: /work/add/ 2021-11-05 15:33:17,517
Traceback (most recent call last):
  File "D:\Users\ntabyldieva\Desktop\databases_v1\env\lib\site-packages\django\core\handlers\exception.py", line 47, in inner
    response = get_response(request)
  File "D:\Users\ntabyldieva\Desktop\databases_v1\env\lib\site-packages\django\core\handlers\base.py", line 181, in _get_response
    response = wrapped_callback(request, *callback_args, **callback_kwargs)
  File "D:\Users\ntabyldieva\Desktop\databases_v1\env\lib\site-packages\django\contrib\auth\decorators.py", line 21, in _wrapped_view
    return view_func(request, *args, **kwargs)
  File "D:\Users\ntabyldieva\Desktop\databases_v1\work\views.py", line 136, in add_case
    if individualFormSet.is_valid():
TypeError: is_valid() missing 1 required positional argument: 'self'
ERROR django.server "POST /work/add/ HTTP/1.1" 500 94178 2021-11-05 15:33:17,520
ERROR django.request Internal Server Error: /work/add/ 2021-11-05 15:35:04,647
Traceback (most recent call last):
  File "D:\Users\ntabyldieva\Desktop\databases_v1\env\lib\site-packages\django\core\handlers\exception.py", line 47, in inner
    response = get_response(request)
  File "D:\Users\ntabyldieva\Desktop\databases_v1\env\lib\site-packages\django\core\handlers\base.py", line 181, in _get_response
    response = wrapped_callback(request, *callback_args, **callback_kwargs)
  File "D:\Users\ntabyldieva\Desktop\databases_v1\env\lib\site-packages\django\contrib\auth\decorators.py", line 21, in _wrapped_view
    return view_func(request, *args, **kwargs)
  File "D:\Users\ntabyldieva\Desktop\databases_v1\work\views.py", line 120, in add_case
    isinstances = forms.save(commit=False)
  File "D:\Users\ntabyldieva\Desktop\databases_v1\env\lib\site-packages\django\forms\models.py", line 681, in save
    return self.save_existing_objects(commit) + self.save_new_objects(commit)
  File "D:\Users\ntabyldieva\Desktop\databases_v1\env\lib\site-packages\django\forms\models.py", line 819, in save_new_objects
    self.new_objects.append(self.save_new(form, commit=commit))
  File "D:\Users\ntabyldieva\Desktop\databases_v1\env\lib\site-packages\django\forms\models.py", line 658, in save_new
    return form.save(commit=commit)
  File "D:\Users\ntabyldieva\Desktop\databases_v1\env\lib\site-packages\django\forms\models.py", line 460, in save
    raise ValueError(
ValueError: The IndividualInfo could not be created because the data didn't validate.
ERROR django.server "POST /work/add/ HTTP/1.1" 500 111593 2021-11-05 15:35:04,652
ERROR django.request Internal Server Error: /work/add/ 2021-11-05 15:37:29,885
Traceback (most recent call last):
  File "D:\Users\ntabyldieva\Desktop\databases_v1\env\lib\site-packages\django\core\handlers\exception.py", line 47, in inner
    response = get_response(request)
  File "D:\Users\ntabyldieva\Desktop\databases_v1\env\lib\site-packages\django\core\handlers\base.py", line 181, in _get_response
    response = wrapped_callback(request, *callback_args, **callback_kwargs)
  File "D:\Users\ntabyldieva\Desktop\databases_v1\env\lib\site-packages\django\contrib\auth\decorators.py", line 21, in _wrapped_view
    return view_func(request, *args, **kwargs)
  File "D:\Users\ntabyldieva\Desktop\databases_v1\work\views.py", line 144, in add_case
    isinstance.save()
  File "D:\Users\ntabyldieva\Desktop\databases_v1\env\lib\site-packages\django\forms\models.py", line 460, in save
    raise ValueError(
ValueError: The IndividualInfo could not be created because the data didn't validate.
ERROR django.server "POST /work/add/ HTTP/1.1" 500 100391 2021-11-05 15:37:29,888
WARNING django.request Not Found: /favicon.ico 2021-11-05 16:02:48,814
WARNING django.server "GET /favicon.ico HTTP/1.1" 404 3524 2021-11-05 16:02:48,815
WARNING django.request Not Found: /favicon.ico 2021-11-05 16:03:47,814
WARNING django.server "GET /favicon.ico HTTP/1.1" 404 3524 2021-11-05 16:03:47,816
WARNING django.request Not Found: /favicon.ico 2021-11-05 16:21:36,379
WARNING django.server "GET /favicon.ico HTTP/1.1" 404 3524 2021-11-05 16:21:36,380
WARNING django.request Not Found: /favicon.ico 2021-11-05 18:01:17,923
WARNING django.server "GET /favicon.ico HTTP/1.1" 404 3524 2021-11-05 18:01:17,924
WARNING django.request Not Found: /favicon.ico 2021-11-05 18:10:56,525
WARNING django.server "GET /favicon.ico HTTP/1.1" 404 3524 2021-11-05 18:10:56,526
WARNING django.request Not Found: /favicon.ico 2021-11-05 18:10:57,823
WARNING django.server "GET /favicon.ico HTTP/1.1" 404 3524 2021-11-05 18:10:57,824
ERROR django.request Internal Server Error: /work/update/194/ 2021-11-05 18:34:59,125
Traceback (most recent call last):
  File "D:\Users\ntabyldieva\Desktop\databases_v1\env\lib\site-packages\django\core\handlers\exception.py", line 47, in inner
    response = get_response(request)
  File "D:\Users\ntabyldieva\Desktop\databases_v1\env\lib\site-packages\django\core\handlers\base.py", line 181, in _get_response
    response = wrapped_callback(request, *callback_args, **callback_kwargs)
  File "D:\Users\ntabyldieva\Desktop\databases_v1\env\lib\site-packages\django\contrib\auth\decorators.py", line 21, in _wrapped_view
    return view_func(request, *args, **kwargs)
  File "D:\Users\ntabyldieva\Desktop\databases_v1\work\views.py", line 201, in update_case
    ind = individual.save(commit=False)
  File "D:\Users\ntabyldieva\Desktop\databases_v1\env\lib\site-packages\django\forms\models.py", line 460, in save
    raise ValueError(
ValueError: The IndividualInfo could not be created because the data didn't validate.
ERROR django.server "POST /work/update/194/ HTTP/1.1" 500 100142 2021-11-05 18:34:59,129
