WARNING django.request Not Found: /favicon.ico 2021-09-02 12:39:12,050
WARNING django.server "GET /favicon.ico HTTP/1.1" 404 3524 2021-09-02 12:39:12,050
WARNING django.request Not Found: /favicon.ico 2021-09-02 12:51:34,103
WARNING django.server "GET /favicon.ico HTTP/1.1" 404 13991 2021-09-02 12:51:34,104
WARNING django.request Not Found: /favicon.ico 2021-09-02 12:52:34,581
WARNING django.server "GET /favicon.ico HTTP/1.1" 404 13991 2021-09-02 12:52:34,582
WARNING django.request Not Found: /admin/strike/case/export/ 2021-09-02 12:54:25,242
WARNING django.server "GET /admin/strike/case/export/? HTTP/1.1" 404 15345 2021-09-02 12:54:25,244
WARNING django.request Not Found: /favicon.ico 2021-09-02 12:55:05,085
WARNING django.server "GET /favicon.ico HTTP/1.1" 404 13991 2021-09-02 12:55:05,087
WARNING django.request Not Found: /favicon.ico 2021-09-02 12:55:08,272
WARNING django.server "GET /favicon.ico HTTP/1.1" 404 13991 2021-09-02 12:55:08,273
ERROR django.request Internal Server Error: /admin/work/case/ 2021-09-02 13:01:32,177
Traceback (most recent call last):
  File "C:\Users\user\OneDrive\Desktop\Projects\databases_v1\venv\lib\site-packages\django\core\handlers\exception.py", line 47, in inner
    response = get_response(request)
  File "C:\Users\user\OneDrive\Desktop\Projects\databases_v1\venv\lib\site-packages\django\core\handlers\base.py", line 181, in _get_response
    response = wrapped_callback(request, *callback_args, **callback_kwargs)
  File "C:\Users\user\OneDrive\Desktop\Projects\databases_v1\venv\lib\site-packages\django\contrib\admin\options.py", line 616, in wrapper
    return self.admin_site.admin_view(view)(*args, **kwargs)
  File "C:\Users\user\OneDrive\Desktop\Projects\databases_v1\venv\lib\site-packages\django\utils\decorators.py", line 130, in _wrapped_view
    response = view_func(request, *args, **kwargs)
  File "C:\Users\user\OneDrive\Desktop\Projects\databases_v1\venv\lib\site-packages\django\views\decorators\cache.py", line 44, in _wrapped_view_func
    response = view_func(request, *args, **kwargs)
  File "C:\Users\user\OneDrive\Desktop\Projects\databases_v1\venv\lib\site-packages\django\contrib\admin\sites.py", line 232, in inner
    return view(request, *args, **kwargs)
  File "C:\Users\user\OneDrive\Desktop\Projects\databases_v1\venv\lib\site-packages\import_export\admin.py", line 341, in changelist_view
    return super().changelist_view(request, extra_context)
  File "C:\Users\user\OneDrive\Desktop\Projects\databases_v1\venv\lib\site-packages\import_export\admin.py", line 504, in changelist_view
    return super().changelist_view(request, extra_context)
  File "C:\Users\user\OneDrive\Desktop\Projects\databases_v1\venv\lib\site-packages\django\utils\decorators.py", line 43, in _wrapper
    return bound_method(*args, **kwargs)
  File "C:\Users\user\OneDrive\Desktop\Projects\databases_v1\venv\lib\site-packages\django\utils\decorators.py", line 130, in _wrapped_view
    response = view_func(request, *args, **kwargs)
  File "C:\Users\user\OneDrive\Desktop\Projects\databases_v1\venv\lib\site-packages\django\contrib\admin\options.py", line 1723, in changelist_view
    response = self.response_action(request, queryset=cl.get_queryset(request))
  File "C:\Users\user\OneDrive\Desktop\Projects\databases_v1\venv\lib\site-packages\django\contrib\admin\options.py", line 1408, in response_action
    response = func(self, request, queryset)
  File "C:\Users\user\OneDrive\Desktop\Projects\databases_v1\venv\lib\site-packages\django\contrib\admin\actions.py", line 33, in delete_selected
    deletable_objects, model_count, perms_needed, protected = modeladmin.get_deleted_objects(queryset, request)
  File "C:\Users\user\OneDrive\Desktop\Projects\databases_v1\venv\lib\site-packages\django\contrib\admin\options.py", line 1846, in get_deleted_objects
    return get_deleted_objects(objs, request, self.admin_site)
  File "C:\Users\user\OneDrive\Desktop\Projects\databases_v1\venv\lib\site-packages\django\contrib\admin\utils.py", line 152, in get_deleted_objects
    to_delete = collector.nested(format_callback)
  File "C:\Users\user\OneDrive\Desktop\Projects\databases_v1\venv\lib\site-packages\django\contrib\admin\utils.py", line 214, in nested
    roots.extend(self._nested(root, seen, format_callback))
  File "C:\Users\user\OneDrive\Desktop\Projects\databases_v1\venv\lib\site-packages\django\contrib\admin\utils.py", line 198, in _nested
    children.extend(self._nested(child, seen, format_callback))
  File "C:\Users\user\OneDrive\Desktop\Projects\databases_v1\venv\lib\site-packages\django\contrib\admin\utils.py", line 200, in _nested
    ret = [format_callback(obj)]
  File "C:\Users\user\OneDrive\Desktop\Projects\databases_v1\venv\lib\site-packages\django\contrib\admin\utils.py", line 127, in format_callback
    no_edit_link = '%s: %s' % (capfirst(opts.verbose_name), obj)
TypeError: __str__ returned non-string (type FieldFile)
ERROR django.server "POST /admin/work/case/ HTTP/1.1" 500 147434 2021-09-02 13:01:32,183
ERROR django.request Internal Server Error: /admin/work/case/ 2021-09-02 13:01:47,062
Traceback (most recent call last):
  File "C:\Users\user\OneDrive\Desktop\Projects\databases_v1\venv\lib\site-packages\django\core\handlers\exception.py", line 47, in inner
    response = get_response(request)
  File "C:\Users\user\OneDrive\Desktop\Projects\databases_v1\venv\lib\site-packages\django\core\handlers\base.py", line 181, in _get_response
    response = wrapped_callback(request, *callback_args, **callback_kwargs)
  File "C:\Users\user\OneDrive\Desktop\Projects\databases_v1\venv\lib\site-packages\django\contrib\admin\options.py", line 616, in wrapper
    return self.admin_site.admin_view(view)(*args, **kwargs)
  File "C:\Users\user\OneDrive\Desktop\Projects\databases_v1\venv\lib\site-packages\django\utils\decorators.py", line 130, in _wrapped_view
    response = view_func(request, *args, **kwargs)
  File "C:\Users\user\OneDrive\Desktop\Projects\databases_v1\venv\lib\site-packages\django\views\decorators\cache.py", line 44, in _wrapped_view_func
    response = view_func(request, *args, **kwargs)
  File "C:\Users\user\OneDrive\Desktop\Projects\databases_v1\venv\lib\site-packages\django\contrib\admin\sites.py", line 232, in inner
    return view(request, *args, **kwargs)
  File "C:\Users\user\OneDrive\Desktop\Projects\databases_v1\venv\lib\site-packages\import_export\admin.py", line 341, in changelist_view
    return super().changelist_view(request, extra_context)
  File "C:\Users\user\OneDrive\Desktop\Projects\databases_v1\venv\lib\site-packages\import_export\admin.py", line 504, in changelist_view
    return super().changelist_view(request, extra_context)
  File "C:\Users\user\OneDrive\Desktop\Projects\databases_v1\venv\lib\site-packages\django\utils\decorators.py", line 43, in _wrapper
    return bound_method(*args, **kwargs)
  File "C:\Users\user\OneDrive\Desktop\Projects\databases_v1\venv\lib\site-packages\django\utils\decorators.py", line 130, in _wrapped_view
    response = view_func(request, *args, **kwargs)
  File "C:\Users\user\OneDrive\Desktop\Projects\databases_v1\venv\lib\site-packages\django\contrib\admin\options.py", line 1723, in changelist_view
    response = self.response_action(request, queryset=cl.get_queryset(request))
  File "C:\Users\user\OneDrive\Desktop\Projects\databases_v1\venv\lib\site-packages\django\contrib\admin\options.py", line 1408, in response_action
    response = func(self, request, queryset)
  File "C:\Users\user\OneDrive\Desktop\Projects\databases_v1\venv\lib\site-packages\django\contrib\admin\actions.py", line 33, in delete_selected
    deletable_objects, model_count, perms_needed, protected = modeladmin.get_deleted_objects(queryset, request)
  File "C:\Users\user\OneDrive\Desktop\Projects\databases_v1\venv\lib\site-packages\django\contrib\admin\options.py", line 1846, in get_deleted_objects
    return get_deleted_objects(objs, request, self.admin_site)
  File "C:\Users\user\OneDrive\Desktop\Projects\databases_v1\venv\lib\site-packages\django\contrib\admin\utils.py", line 152, in get_deleted_objects
    to_delete = collector.nested(format_callback)
  File "C:\Users\user\OneDrive\Desktop\Projects\databases_v1\venv\lib\site-packages\django\contrib\admin\utils.py", line 214, in nested
    roots.extend(self._nested(root, seen, format_callback))
  File "C:\Users\user\OneDrive\Desktop\Projects\databases_v1\venv\lib\site-packages\django\contrib\admin\utils.py", line 198, in _nested
    children.extend(self._nested(child, seen, format_callback))
  File "C:\Users\user\OneDrive\Desktop\Projects\databases_v1\venv\lib\site-packages\django\contrib\admin\utils.py", line 200, in _nested
    ret = [format_callback(obj)]
  File "C:\Users\user\OneDrive\Desktop\Projects\databases_v1\venv\lib\site-packages\django\contrib\admin\utils.py", line 127, in format_callback
    no_edit_link = '%s: %s' % (capfirst(opts.verbose_name), obj)
TypeError: __str__ returned non-string (type FieldFile)
ERROR django.server "POST /admin/work/case/ HTTP/1.1" 500 146972 2021-09-02 13:01:47,066
ERROR django.request Internal Server Error: /admin/work/case/4/delete/ 2021-09-02 13:02:01,488
Traceback (most recent call last):
  File "C:\Users\user\OneDrive\Desktop\Projects\databases_v1\venv\lib\site-packages\django\core\handlers\exception.py", line 47, in inner
    response = get_response(request)
  File "C:\Users\user\OneDrive\Desktop\Projects\databases_v1\venv\lib\site-packages\django\core\handlers\base.py", line 181, in _get_response
    response = wrapped_callback(request, *callback_args, **callback_kwargs)
  File "C:\Users\user\OneDrive\Desktop\Projects\databases_v1\venv\lib\site-packages\django\contrib\admin\options.py", line 616, in wrapper
    return self.admin_site.admin_view(view)(*args, **kwargs)
  File "C:\Users\user\OneDrive\Desktop\Projects\databases_v1\venv\lib\site-packages\django\utils\decorators.py", line 130, in _wrapped_view
    response = view_func(request, *args, **kwargs)
  File "C:\Users\user\OneDrive\Desktop\Projects\databases_v1\venv\lib\site-packages\django\views\decorators\cache.py", line 44, in _wrapped_view_func
    response = view_func(request, *args, **kwargs)
  File "C:\Users\user\OneDrive\Desktop\Projects\databases_v1\venv\lib\site-packages\django\contrib\admin\sites.py", line 232, in inner
    return view(request, *args, **kwargs)
  File "C:\Users\user\OneDrive\Desktop\Projects\databases_v1\venv\lib\site-packages\django\utils\decorators.py", line 43, in _wrapper
    return bound_method(*args, **kwargs)
  File "C:\Users\user\OneDrive\Desktop\Projects\databases_v1\venv\lib\site-packages\django\utils\decorators.py", line 130, in _wrapped_view
    response = view_func(request, *args, **kwargs)
  File "C:\Users\user\OneDrive\Desktop\Projects\databases_v1\venv\lib\site-packages\django\contrib\admin\options.py", line 1851, in delete_view
    return self._delete_view(request, object_id, extra_context)
  File "C:\Users\user\OneDrive\Desktop\Projects\databases_v1\venv\lib\site-packages\django\contrib\admin\options.py", line 1872, in _delete_view
    deleted_objects, model_count, perms_needed, protected = self.get_deleted_objects([obj], request)
  File "C:\Users\user\OneDrive\Desktop\Projects\databases_v1\venv\lib\site-packages\django\contrib\admin\options.py", line 1846, in get_deleted_objects
    return get_deleted_objects(objs, request, self.admin_site)
  File "C:\Users\user\OneDrive\Desktop\Projects\databases_v1\venv\lib\site-packages\django\contrib\admin\utils.py", line 152, in get_deleted_objects
    to_delete = collector.nested(format_callback)
  File "C:\Users\user\OneDrive\Desktop\Projects\databases_v1\venv\lib\site-packages\django\contrib\admin\utils.py", line 214, in nested
    roots.extend(self._nested(root, seen, format_callback))
  File "C:\Users\user\OneDrive\Desktop\Projects\databases_v1\venv\lib\site-packages\django\contrib\admin\utils.py", line 198, in _nested
    children.extend(self._nested(child, seen, format_callback))
  File "C:\Users\user\OneDrive\Desktop\Projects\databases_v1\venv\lib\site-packages\django\contrib\admin\utils.py", line 200, in _nested
    ret = [format_callback(obj)]
  File "C:\Users\user\OneDrive\Desktop\Projects\databases_v1\venv\lib\site-packages\django\contrib\admin\utils.py", line 127, in format_callback
    no_edit_link = '%s: %s' % (capfirst(opts.verbose_name), obj)
TypeError: __str__ returned non-string (type FieldFile)
ERROR django.server "GET /admin/work/case/4/delete/ HTTP/1.1" 500 130356 2021-09-02 13:02:01,490
ERROR django.request Internal Server Error: /work/delete/2/ 2021-09-02 13:03:06,137
Traceback (most recent call last):
  File "C:\Users\user\OneDrive\Desktop\Projects\databases_v1\venv\lib\site-packages\django\db\backends\base\base.py", line 242, in _commit
    return self.connection.commit()
sqlite3.IntegrityError: FOREIGN KEY constraint failed

The above exception was the direct cause of the following exception:

Traceback (most recent call last):
  File "C:\Users\user\OneDrive\Desktop\Projects\databases_v1\venv\lib\site-packages\django\core\handlers\exception.py", line 47, in inner
    response = get_response(request)
  File "C:\Users\user\OneDrive\Desktop\Projects\databases_v1\venv\lib\site-packages\django\core\handlers\base.py", line 181, in _get_response
    response = wrapped_callback(request, *callback_args, **callback_kwargs)
  File "C:\Users\user\OneDrive\Desktop\Projects\databases_v1\databases_v1\work\views.py", line 278, in delete_case
    case = Case.objects.get(id=pk).delete()
  File "C:\Users\user\OneDrive\Desktop\Projects\databases_v1\venv\lib\site-packages\django\db\models\base.py", line 954, in delete
    return collector.delete()
  File "C:\Users\user\OneDrive\Desktop\Projects\databases_v1\venv\lib\site-packages\django\db\models\deletion.py", line 435, in delete
    signals.post_delete.send(
  File "C:\Users\user\OneDrive\Desktop\Projects\databases_v1\venv\lib\site-packages\django\db\transaction.py", line 246, in __exit__
    connection.commit()
  File "C:\Users\user\OneDrive\Desktop\Projects\databases_v1\venv\lib\site-packages\django\utils\asyncio.py", line 26, in inner
    return func(*args, **kwargs)
  File "C:\Users\user\OneDrive\Desktop\Projects\databases_v1\venv\lib\site-packages\django\db\backends\base\base.py", line 266, in commit
    self._commit()
  File "C:\Users\user\OneDrive\Desktop\Projects\databases_v1\venv\lib\site-packages\django\db\backends\base\base.py", line 242, in _commit
    return self.connection.commit()
  File "C:\Users\user\OneDrive\Desktop\Projects\databases_v1\venv\lib\site-packages\django\db\utils.py", line 90, in __exit__
    raise dj_exc_value.with_traceback(traceback) from exc_value
  File "C:\Users\user\OneDrive\Desktop\Projects\databases_v1\venv\lib\site-packages\django\db\backends\base\base.py", line 242, in _commit
    return self.connection.commit()
django.db.utils.IntegrityError: FOREIGN KEY constraint failed
ERROR django.server "GET /work/delete/2/ HTTP/1.1" 500 107313 2021-09-02 13:03:06,145
ERROR django.request Internal Server Error: /work/delete/2/ 2021-09-02 13:03:23,826
Traceback (most recent call last):
  File "C:\Users\user\OneDrive\Desktop\Projects\databases_v1\venv\lib\site-packages\django\db\backends\base\base.py", line 242, in _commit
    return self.connection.commit()
sqlite3.IntegrityError: FOREIGN KEY constraint failed

The above exception was the direct cause of the following exception:

Traceback (most recent call last):
  File "C:\Users\user\OneDrive\Desktop\Projects\databases_v1\venv\lib\site-packages\django\core\handlers\exception.py", line 47, in inner
    response = get_response(request)
  File "C:\Users\user\OneDrive\Desktop\Projects\databases_v1\venv\lib\site-packages\django\core\handlers\base.py", line 181, in _get_response
    response = wrapped_callback(request, *callback_args, **callback_kwargs)
  File "C:\Users\user\OneDrive\Desktop\Projects\databases_v1\databases_v1\work\views.py", line 278, in delete_case
    case = Case.objects.get(id=pk).delete()
  File "C:\Users\user\OneDrive\Desktop\Projects\databases_v1\venv\lib\site-packages\django\db\models\base.py", line 954, in delete
    return collector.delete()
  File "C:\Users\user\OneDrive\Desktop\Projects\databases_v1\venv\lib\site-packages\django\db\models\deletion.py", line 435, in delete
    signals.post_delete.send(
  File "C:\Users\user\OneDrive\Desktop\Projects\databases_v1\venv\lib\site-packages\django\db\transaction.py", line 246, in __exit__
    connection.commit()
  File "C:\Users\user\OneDrive\Desktop\Projects\databases_v1\venv\lib\site-packages\django\utils\asyncio.py", line 26, in inner
    return func(*args, **kwargs)
  File "C:\Users\user\OneDrive\Desktop\Projects\databases_v1\venv\lib\site-packages\django\db\backends\base\base.py", line 266, in commit
    self._commit()
  File "C:\Users\user\OneDrive\Desktop\Projects\databases_v1\venv\lib\site-packages\django\db\backends\base\base.py", line 242, in _commit
    return self.connection.commit()
  File "C:\Users\user\OneDrive\Desktop\Projects\databases_v1\venv\lib\site-packages\django\db\utils.py", line 90, in __exit__
    raise dj_exc_value.with_traceback(traceback) from exc_value
  File "C:\Users\user\OneDrive\Desktop\Projects\databases_v1\venv\lib\site-packages\django\db\backends\base\base.py", line 242, in _commit
    return self.connection.commit()
django.db.utils.IntegrityError: FOREIGN KEY constraint failed
ERROR django.server "GET /work/delete/2/ HTTP/1.1" 500 107313 2021-09-02 13:03:23,828
ERROR django.request Internal Server Error: /work/delete/2/ 2021-09-02 13:05:19,680
Traceback (most recent call last):
  File "C:\Users\user\OneDrive\Desktop\Projects\databases_v1\venv\lib\site-packages\django\db\backends\base\base.py", line 242, in _commit
    return self.connection.commit()
sqlite3.IntegrityError: FOREIGN KEY constraint failed

The above exception was the direct cause of the following exception:

Traceback (most recent call last):
  File "C:\Users\user\OneDrive\Desktop\Projects\databases_v1\venv\lib\site-packages\django\core\handlers\exception.py", line 47, in inner
    response = get_response(request)
  File "C:\Users\user\OneDrive\Desktop\Projects\databases_v1\venv\lib\site-packages\django\core\handlers\base.py", line 181, in _get_response
    response = wrapped_callback(request, *callback_args, **callback_kwargs)
  File "C:\Users\user\OneDrive\Desktop\Projects\databases_v1\databases_v1\work\views.py", line 278, in delete_case
    case = Case.objects.get(id=pk).delete()
  File "C:\Users\user\OneDrive\Desktop\Projects\databases_v1\venv\lib\site-packages\django\db\models\base.py", line 954, in delete
    return collector.delete()
  File "C:\Users\user\OneDrive\Desktop\Projects\databases_v1\venv\lib\site-packages\django\db\models\deletion.py", line 435, in delete
    signals.post_delete.send(
  File "C:\Users\user\OneDrive\Desktop\Projects\databases_v1\venv\lib\site-packages\django\db\transaction.py", line 246, in __exit__
    connection.commit()
  File "C:\Users\user\OneDrive\Desktop\Projects\databases_v1\venv\lib\site-packages\django\utils\asyncio.py", line 26, in inner
    return func(*args, **kwargs)
  File "C:\Users\user\OneDrive\Desktop\Projects\databases_v1\venv\lib\site-packages\django\db\backends\base\base.py", line 266, in commit
    self._commit()
  File "C:\Users\user\OneDrive\Desktop\Projects\databases_v1\venv\lib\site-packages\django\db\backends\base\base.py", line 242, in _commit
    return self.connection.commit()
  File "C:\Users\user\OneDrive\Desktop\Projects\databases_v1\venv\lib\site-packages\django\db\utils.py", line 90, in __exit__
    raise dj_exc_value.with_traceback(traceback) from exc_value
  File "C:\Users\user\OneDrive\Desktop\Projects\databases_v1\venv\lib\site-packages\django\db\backends\base\base.py", line 242, in _commit
    return self.connection.commit()
django.db.utils.IntegrityError: FOREIGN KEY constraint failed
ERROR django.server "GET /work/delete/2/ HTTP/1.1" 500 107067 2021-09-02 13:05:19,683
ERROR django.request Internal Server Error: /work/delete/2/ 2021-09-02 13:06:14,372
Traceback (most recent call last):
  File "C:\Users\user\OneDrive\Desktop\Projects\databases_v1\venv\lib\site-packages\django\db\backends\base\base.py", line 242, in _commit
    return self.connection.commit()
sqlite3.IntegrityError: FOREIGN KEY constraint failed

The above exception was the direct cause of the following exception:

Traceback (most recent call last):
  File "C:\Users\user\OneDrive\Desktop\Projects\databases_v1\venv\lib\site-packages\django\core\handlers\exception.py", line 47, in inner
    response = get_response(request)
  File "C:\Users\user\OneDrive\Desktop\Projects\databases_v1\venv\lib\site-packages\django\core\handlers\base.py", line 181, in _get_response
    response = wrapped_callback(request, *callback_args, **callback_kwargs)
  File "C:\Users\user\OneDrive\Desktop\Projects\databases_v1\databases_v1\work\views.py", line 278, in delete_case
    case = Case.objects.get(id=pk).delete()
  File "C:\Users\user\OneDrive\Desktop\Projects\databases_v1\venv\lib\site-packages\django\db\models\base.py", line 954, in delete
    return collector.delete()
  File "C:\Users\user\OneDrive\Desktop\Projects\databases_v1\venv\lib\site-packages\django\db\models\deletion.py", line 435, in delete
    signals.post_delete.send(
  File "C:\Users\user\OneDrive\Desktop\Projects\databases_v1\venv\lib\site-packages\django\db\transaction.py", line 246, in __exit__
    connection.commit()
  File "C:\Users\user\OneDrive\Desktop\Projects\databases_v1\venv\lib\site-packages\django\utils\asyncio.py", line 26, in inner
    return func(*args, **kwargs)
  File "C:\Users\user\OneDrive\Desktop\Projects\databases_v1\venv\lib\site-packages\django\db\backends\base\base.py", line 266, in commit
    self._commit()
  File "C:\Users\user\OneDrive\Desktop\Projects\databases_v1\venv\lib\site-packages\django\db\backends\base\base.py", line 242, in _commit
    return self.connection.commit()
  File "C:\Users\user\OneDrive\Desktop\Projects\databases_v1\venv\lib\site-packages\django\db\utils.py", line 90, in __exit__
    raise dj_exc_value.with_traceback(traceback) from exc_value
  File "C:\Users\user\OneDrive\Desktop\Projects\databases_v1\venv\lib\site-packages\django\db\backends\base\base.py", line 242, in _commit
    return self.connection.commit()
django.db.utils.IntegrityError: FOREIGN KEY constraint failed
ERROR django.server "GET /work/delete/2/ HTTP/1.1" 500 107067 2021-09-02 13:06:14,375
