WARNING django.request Not Found: /favicon.ico 2022-01-31 11:20:24,144
WARNING django.server "GET /favicon.ico HTTP/1.1" 404 3524 2022-01-31 11:20:24,146
ERROR django.request Internal Server Error: /strike/word/24/ 2022-01-31 11:20:47,032
Traceback (most recent call last):
  File "D:\Users\ntabyldieva\Desktop\databases_v1\env\lib\site-packages\django\core\handlers\exception.py", line 47, in inner
    response = get_response(request)
  File "D:\Users\ntabyldieva\Desktop\databases_v1\env\lib\site-packages\django\core\handlers\base.py", line 181, in _get_response
    response = wrapped_callback(request, *callback_args, **callback_kwargs)
  File "D:\Users\ntabyldieva\Desktop\databases_v1\strike\views.py", line 546, in strike_word_generate
    card_sources = Source.objects.filter(card__pk=pk)
  File "D:\Users\ntabyldieva\Desktop\databases_v1\env\lib\site-packages\django\db\models\manager.py", line 85, in manager_method
    return getattr(self.get_queryset(), name)(*args, **kwargs)
  File "D:\Users\ntabyldieva\Desktop\databases_v1\env\lib\site-packages\django\db\models\query.py", line 941, in filter
    return self._filter_or_exclude(False, args, kwargs)
  File "D:\Users\ntabyldieva\Desktop\databases_v1\env\lib\site-packages\django\db\models\query.py", line 961, in _filter_or_exclude
    clone._filter_or_exclude_inplace(negate, args, kwargs)
  File "D:\Users\ntabyldieva\Desktop\databases_v1\env\lib\site-packages\django\db\models\query.py", line 968, in _filter_or_exclude_inplace
    self._query.add_q(Q(*args, **kwargs))
  File "D:\Users\ntabyldieva\Desktop\databases_v1\env\lib\site-packages\django\db\models\sql\query.py", line 1391, in add_q
    clause, _ = self._add_q(q_object, self.used_aliases)
  File "D:\Users\ntabyldieva\Desktop\databases_v1\env\lib\site-packages\django\db\models\sql\query.py", line 1410, in _add_q
    child_clause, needed_inner = self.build_filter(
  File "D:\Users\ntabyldieva\Desktop\databases_v1\env\lib\site-packages\django\db\models\sql\query.py", line 1284, in build_filter
    lookups, parts, reffed_expression = self.solve_lookup_type(arg)
  File "D:\Users\ntabyldieva\Desktop\databases_v1\env\lib\site-packages\django\db\models\sql\query.py", line 1110, in solve_lookup_type
    _, field, _, lookup_parts = self.names_to_path(lookup_splitted, self.get_meta())
  File "D:\Users\ntabyldieva\Desktop\databases_v1\env\lib\site-packages\django\db\models\sql\query.py", line 1537, in names_to_path
    raise FieldError("Cannot resolve keyword '%s' into field. "
django.core.exceptions.FieldError: Cannot resolve keyword 'card' into field. Choices are: active, id, name, source
ERROR django.server "GET /strike/word/24/ HTTP/1.1" 500 113607 2022-01-31 11:20:47,036
ERROR django.request Internal Server Error: /strike/word/24/ 2022-01-31 11:23:56,265
Traceback (most recent call last):
  File "D:\Users\ntabyldieva\Desktop\databases_v1\env\lib\site-packages\django\core\handlers\exception.py", line 47, in inner
    response = get_response(request)
  File "D:\Users\ntabyldieva\Desktop\databases_v1\env\lib\site-packages\django\core\handlers\base.py", line 181, in _get_response
    response = wrapped_callback(request, *callback_args, **callback_kwargs)
  File "D:\Users\ntabyldieva\Desktop\databases_v1\strike\views.py", line 546, in strike_word_generate
    card_sources = Source.objects.filter(id=card.source.id)
AttributeError: 'Card' object has no attribute 'source'
ERROR django.server "GET /strike/word/24/ HTTP/1.1" 500 68697 2022-01-31 11:23:56,266
ERROR django.request Internal Server Error: /strike/word/24/ 2022-01-31 11:25:13,420
Traceback (most recent call last):
  File "D:\Users\ntabyldieva\Desktop\databases_v1\env\lib\site-packages\django\core\handlers\exception.py", line 47, in inner
    response = get_response(request)
  File "D:\Users\ntabyldieva\Desktop\databases_v1\env\lib\site-packages\django\core\handlers\base.py", line 181, in _get_response
    response = wrapped_callback(request, *callback_args, **callback_kwargs)
  File "D:\Users\ntabyldieva\Desktop\databases_v1\strike\views.py", line 546, in strike_word_generate
    card_sources = Source.objects.filter(card__pk=pk)
  File "D:\Users\ntabyldieva\Desktop\databases_v1\env\lib\site-packages\django\db\models\manager.py", line 85, in manager_method
    return getattr(self.get_queryset(), name)(*args, **kwargs)
  File "D:\Users\ntabyldieva\Desktop\databases_v1\env\lib\site-packages\django\db\models\query.py", line 941, in filter
    return self._filter_or_exclude(False, args, kwargs)
  File "D:\Users\ntabyldieva\Desktop\databases_v1\env\lib\site-packages\django\db\models\query.py", line 961, in _filter_or_exclude
    clone._filter_or_exclude_inplace(negate, args, kwargs)
  File "D:\Users\ntabyldieva\Desktop\databases_v1\env\lib\site-packages\django\db\models\query.py", line 968, in _filter_or_exclude_inplace
    self._query.add_q(Q(*args, **kwargs))
  File "D:\Users\ntabyldieva\Desktop\databases_v1\env\lib\site-packages\django\db\models\sql\query.py", line 1391, in add_q
    clause, _ = self._add_q(q_object, self.used_aliases)
  File "D:\Users\ntabyldieva\Desktop\databases_v1\env\lib\site-packages\django\db\models\sql\query.py", line 1410, in _add_q
    child_clause, needed_inner = self.build_filter(
  File "D:\Users\ntabyldieva\Desktop\databases_v1\env\lib\site-packages\django\db\models\sql\query.py", line 1284, in build_filter
    lookups, parts, reffed_expression = self.solve_lookup_type(arg)
  File "D:\Users\ntabyldieva\Desktop\databases_v1\env\lib\site-packages\django\db\models\sql\query.py", line 1110, in solve_lookup_type
    _, field, _, lookup_parts = self.names_to_path(lookup_splitted, self.get_meta())
  File "D:\Users\ntabyldieva\Desktop\databases_v1\env\lib\site-packages\django\db\models\sql\query.py", line 1537, in names_to_path
    raise FieldError("Cannot resolve keyword '%s' into field. "
django.core.exceptions.FieldError: Cannot resolve keyword 'card' into field. Choices are: active, id, name, source
ERROR django.server "GET /strike/word/24/ HTTP/1.1" 500 113744 2022-01-31 11:25:13,423
ERROR django.request Internal Server Error: /strike/word/1/ 2022-01-31 11:30:26,842
Traceback (most recent call last):
  File "D:\Users\ntabyldieva\Desktop\databases_v1\env\lib\site-packages\django\core\handlers\exception.py", line 47, in inner
    response = get_response(request)
  File "D:\Users\ntabyldieva\Desktop\databases_v1\env\lib\site-packages\django\core\handlers\base.py", line 181, in _get_response
    response = wrapped_callback(request, *callback_args, **callback_kwargs)
  File "D:\Users\ntabyldieva\Desktop\databases_v1\strike\views.py", line 546, in strike_word_generate
    card_sources = Source.objects.filter(card__pk=pk)
  File "D:\Users\ntabyldieva\Desktop\databases_v1\env\lib\site-packages\django\db\models\manager.py", line 85, in manager_method
    return getattr(self.get_queryset(), name)(*args, **kwargs)
  File "D:\Users\ntabyldieva\Desktop\databases_v1\env\lib\site-packages\django\db\models\query.py", line 941, in filter
    return self._filter_or_exclude(False, args, kwargs)
  File "D:\Users\ntabyldieva\Desktop\databases_v1\env\lib\site-packages\django\db\models\query.py", line 961, in _filter_or_exclude
    clone._filter_or_exclude_inplace(negate, args, kwargs)
  File "D:\Users\ntabyldieva\Desktop\databases_v1\env\lib\site-packages\django\db\models\query.py", line 968, in _filter_or_exclude_inplace
    self._query.add_q(Q(*args, **kwargs))
  File "D:\Users\ntabyldieva\Desktop\databases_v1\env\lib\site-packages\django\db\models\sql\query.py", line 1391, in add_q
    clause, _ = self._add_q(q_object, self.used_aliases)
  File "D:\Users\ntabyldieva\Desktop\databases_v1\env\lib\site-packages\django\db\models\sql\query.py", line 1410, in _add_q
    child_clause, needed_inner = self.build_filter(
  File "D:\Users\ntabyldieva\Desktop\databases_v1\env\lib\site-packages\django\db\models\sql\query.py", line 1284, in build_filter
    lookups, parts, reffed_expression = self.solve_lookup_type(arg)
  File "D:\Users\ntabyldieva\Desktop\databases_v1\env\lib\site-packages\django\db\models\sql\query.py", line 1110, in solve_lookup_type
    _, field, _, lookup_parts = self.names_to_path(lookup_splitted, self.get_meta())
  File "D:\Users\ntabyldieva\Desktop\databases_v1\env\lib\site-packages\django\db\models\sql\query.py", line 1537, in names_to_path
    raise FieldError("Cannot resolve keyword '%s' into field. "
django.core.exceptions.FieldError: Cannot resolve keyword 'card' into field. Choices are: active, id, name, source
ERROR django.server "GET /strike/word/1/ HTTP/1.1" 500 113583 2022-01-31 11:30:26,844
ERROR django.request Internal Server Error: /strike/word/7/ 2022-01-31 11:31:12,733
Traceback (most recent call last):
  File "D:\Users\ntabyldieva\Desktop\databases_v1\env\lib\site-packages\django\core\handlers\exception.py", line 47, in inner
    response = get_response(request)
  File "D:\Users\ntabyldieva\Desktop\databases_v1\env\lib\site-packages\django\core\handlers\base.py", line 181, in _get_response
    response = wrapped_callback(request, *callback_args, **callback_kwargs)
  File "D:\Users\ntabyldieva\Desktop\databases_v1\strike\views.py", line 546, in strike_word_generate
    card_sources = Source.objects.filter(card__id=pk)
  File "D:\Users\ntabyldieva\Desktop\databases_v1\env\lib\site-packages\django\db\models\manager.py", line 85, in manager_method
    return getattr(self.get_queryset(), name)(*args, **kwargs)
  File "D:\Users\ntabyldieva\Desktop\databases_v1\env\lib\site-packages\django\db\models\query.py", line 941, in filter
    return self._filter_or_exclude(False, args, kwargs)
  File "D:\Users\ntabyldieva\Desktop\databases_v1\env\lib\site-packages\django\db\models\query.py", line 961, in _filter_or_exclude
    clone._filter_or_exclude_inplace(negate, args, kwargs)
  File "D:\Users\ntabyldieva\Desktop\databases_v1\env\lib\site-packages\django\db\models\query.py", line 968, in _filter_or_exclude_inplace
    self._query.add_q(Q(*args, **kwargs))
  File "D:\Users\ntabyldieva\Desktop\databases_v1\env\lib\site-packages\django\db\models\sql\query.py", line 1391, in add_q
    clause, _ = self._add_q(q_object, self.used_aliases)
  File "D:\Users\ntabyldieva\Desktop\databases_v1\env\lib\site-packages\django\db\models\sql\query.py", line 1410, in _add_q
    child_clause, needed_inner = self.build_filter(
  File "D:\Users\ntabyldieva\Desktop\databases_v1\env\lib\site-packages\django\db\models\sql\query.py", line 1284, in build_filter
    lookups, parts, reffed_expression = self.solve_lookup_type(arg)
  File "D:\Users\ntabyldieva\Desktop\databases_v1\env\lib\site-packages\django\db\models\sql\query.py", line 1110, in solve_lookup_type
    _, field, _, lookup_parts = self.names_to_path(lookup_splitted, self.get_meta())
  File "D:\Users\ntabyldieva\Desktop\databases_v1\env\lib\site-packages\django\db\models\sql\query.py", line 1537, in names_to_path
    raise FieldError("Cannot resolve keyword '%s' into field. "
django.core.exceptions.FieldError: Cannot resolve keyword 'card' into field. Choices are: active, id, name, source
ERROR django.server "GET /strike/word/7/ HTTP/1.1" 500 113586 2022-01-31 11:31:12,737
ERROR django.request Internal Server Error: /strike/word/7/ 2022-01-31 11:32:01,340
Traceback (most recent call last):
  File "D:\Users\ntabyldieva\Desktop\databases_v1\env\lib\site-packages\django\core\handlers\exception.py", line 47, in inner
    response = get_response(request)
  File "D:\Users\ntabyldieva\Desktop\databases_v1\env\lib\site-packages\django\core\handlers\base.py", line 181, in _get_response
    response = wrapped_callback(request, *callback_args, **callback_kwargs)
  File "D:\Users\ntabyldieva\Desktop\databases_v1\strike\views.py", line 546, in strike_word_generate
    card_sources = Source.objects.filter(card__pk=pk)
  File "D:\Users\ntabyldieva\Desktop\databases_v1\env\lib\site-packages\django\db\models\manager.py", line 85, in manager_method
    return getattr(self.get_queryset(), name)(*args, **kwargs)
  File "D:\Users\ntabyldieva\Desktop\databases_v1\env\lib\site-packages\django\db\models\query.py", line 941, in filter
    return self._filter_or_exclude(False, args, kwargs)
  File "D:\Users\ntabyldieva\Desktop\databases_v1\env\lib\site-packages\django\db\models\query.py", line 961, in _filter_or_exclude
    clone._filter_or_exclude_inplace(negate, args, kwargs)
  File "D:\Users\ntabyldieva\Desktop\databases_v1\env\lib\site-packages\django\db\models\query.py", line 968, in _filter_or_exclude_inplace
    self._query.add_q(Q(*args, **kwargs))
  File "D:\Users\ntabyldieva\Desktop\databases_v1\env\lib\site-packages\django\db\models\sql\query.py", line 1391, in add_q
    clause, _ = self._add_q(q_object, self.used_aliases)
  File "D:\Users\ntabyldieva\Desktop\databases_v1\env\lib\site-packages\django\db\models\sql\query.py", line 1410, in _add_q
    child_clause, needed_inner = self.build_filter(
  File "D:\Users\ntabyldieva\Desktop\databases_v1\env\lib\site-packages\django\db\models\sql\query.py", line 1284, in build_filter
    lookups, parts, reffed_expression = self.solve_lookup_type(arg)
  File "D:\Users\ntabyldieva\Desktop\databases_v1\env\lib\site-packages\django\db\models\sql\query.py", line 1110, in solve_lookup_type
    _, field, _, lookup_parts = self.names_to_path(lookup_splitted, self.get_meta())
  File "D:\Users\ntabyldieva\Desktop\databases_v1\env\lib\site-packages\django\db\models\sql\query.py", line 1537, in names_to_path
    raise FieldError("Cannot resolve keyword '%s' into field. "
django.core.exceptions.FieldError: Cannot resolve keyword 'card' into field. Choices are: active, id, name, source
ERROR django.server "GET /strike/word/7/ HTTP/1.1" 500 113723 2022-01-31 11:32:01,345
ERROR django.request Internal Server Error: /strike/word/7/ 2022-01-31 11:32:02,966
Traceback (most recent call last):
  File "D:\Users\ntabyldieva\Desktop\databases_v1\env\lib\site-packages\django\core\handlers\exception.py", line 47, in inner
    response = get_response(request)
  File "D:\Users\ntabyldieva\Desktop\databases_v1\env\lib\site-packages\django\core\handlers\base.py", line 181, in _get_response
    response = wrapped_callback(request, *callback_args, **callback_kwargs)
  File "D:\Users\ntabyldieva\Desktop\databases_v1\strike\views.py", line 546, in strike_word_generate
    card_sources = Source.objects.filter(card__pk=pk)
  File "D:\Users\ntabyldieva\Desktop\databases_v1\env\lib\site-packages\django\db\models\manager.py", line 85, in manager_method
    return getattr(self.get_queryset(), name)(*args, **kwargs)
  File "D:\Users\ntabyldieva\Desktop\databases_v1\env\lib\site-packages\django\db\models\query.py", line 941, in filter
    return self._filter_or_exclude(False, args, kwargs)
  File "D:\Users\ntabyldieva\Desktop\databases_v1\env\lib\site-packages\django\db\models\query.py", line 961, in _filter_or_exclude
    clone._filter_or_exclude_inplace(negate, args, kwargs)
  File "D:\Users\ntabyldieva\Desktop\databases_v1\env\lib\site-packages\django\db\models\query.py", line 968, in _filter_or_exclude_inplace
    self._query.add_q(Q(*args, **kwargs))
  File "D:\Users\ntabyldieva\Desktop\databases_v1\env\lib\site-packages\django\db\models\sql\query.py", line 1391, in add_q
    clause, _ = self._add_q(q_object, self.used_aliases)
  File "D:\Users\ntabyldieva\Desktop\databases_v1\env\lib\site-packages\django\db\models\sql\query.py", line 1410, in _add_q
    child_clause, needed_inner = self.build_filter(
  File "D:\Users\ntabyldieva\Desktop\databases_v1\env\lib\site-packages\django\db\models\sql\query.py", line 1284, in build_filter
    lookups, parts, reffed_expression = self.solve_lookup_type(arg)
  File "D:\Users\ntabyldieva\Desktop\databases_v1\env\lib\site-packages\django\db\models\sql\query.py", line 1110, in solve_lookup_type
    _, field, _, lookup_parts = self.names_to_path(lookup_splitted, self.get_meta())
  File "D:\Users\ntabyldieva\Desktop\databases_v1\env\lib\site-packages\django\db\models\sql\query.py", line 1537, in names_to_path
    raise FieldError("Cannot resolve keyword '%s' into field. "
django.core.exceptions.FieldError: Cannot resolve keyword 'card' into field. Choices are: active, id, name, source
ERROR django.server "GET /strike/word/7/ HTTP/1.1" 500 113723 2022-01-31 11:32:02,971
ERROR django.request Internal Server Error: /strike/word/7/ 2022-01-31 11:32:04,010
Traceback (most recent call last):
  File "D:\Users\ntabyldieva\Desktop\databases_v1\env\lib\site-packages\django\core\handlers\exception.py", line 47, in inner
    response = get_response(request)
  File "D:\Users\ntabyldieva\Desktop\databases_v1\env\lib\site-packages\django\core\handlers\base.py", line 181, in _get_response
    response = wrapped_callback(request, *callback_args, **callback_kwargs)
  File "D:\Users\ntabyldieva\Desktop\databases_v1\strike\views.py", line 546, in strike_word_generate
    card_sources = Source.objects.filter(card__pk=pk)
  File "D:\Users\ntabyldieva\Desktop\databases_v1\env\lib\site-packages\django\db\models\manager.py", line 85, in manager_method
    return getattr(self.get_queryset(), name)(*args, **kwargs)
  File "D:\Users\ntabyldieva\Desktop\databases_v1\env\lib\site-packages\django\db\models\query.py", line 941, in filter
    return self._filter_or_exclude(False, args, kwargs)
  File "D:\Users\ntabyldieva\Desktop\databases_v1\env\lib\site-packages\django\db\models\query.py", line 961, in _filter_or_exclude
    clone._filter_or_exclude_inplace(negate, args, kwargs)
  File "D:\Users\ntabyldieva\Desktop\databases_v1\env\lib\site-packages\django\db\models\query.py", line 968, in _filter_or_exclude_inplace
    self._query.add_q(Q(*args, **kwargs))
  File "D:\Users\ntabyldieva\Desktop\databases_v1\env\lib\site-packages\django\db\models\sql\query.py", line 1391, in add_q
    clause, _ = self._add_q(q_object, self.used_aliases)
  File "D:\Users\ntabyldieva\Desktop\databases_v1\env\lib\site-packages\django\db\models\sql\query.py", line 1410, in _add_q
    child_clause, needed_inner = self.build_filter(
  File "D:\Users\ntabyldieva\Desktop\databases_v1\env\lib\site-packages\django\db\models\sql\query.py", line 1284, in build_filter
    lookups, parts, reffed_expression = self.solve_lookup_type(arg)
  File "D:\Users\ntabyldieva\Desktop\databases_v1\env\lib\site-packages\django\db\models\sql\query.py", line 1110, in solve_lookup_type
    _, field, _, lookup_parts = self.names_to_path(lookup_splitted, self.get_meta())
  File "D:\Users\ntabyldieva\Desktop\databases_v1\env\lib\site-packages\django\db\models\sql\query.py", line 1537, in names_to_path
    raise FieldError("Cannot resolve keyword '%s' into field. "
django.core.exceptions.FieldError: Cannot resolve keyword 'card' into field. Choices are: active, id, name, source
ERROR django.server "GET /strike/word/7/ HTTP/1.1" 500 113723 2022-01-31 11:32:04,012
