ERROR django.request Internal Server Error: /analytic/migrant-detail/1/ 2022-01-11 14:27:18,626
Traceback (most recent call last):
  File "D:\Users\ntabyldieva\Desktop\crm\databases_v1\venv\lib\site-packages\django\core\handlers\exception.py", line 47, in inner
    response = get_response(request)
  File "D:\Users\ntabyldieva\Desktop\crm\databases_v1\venv\lib\site-packages\django\core\handlers\base.py", line 181, in _get_response
    response = wrapped_callback(request, *callback_args, **callback_kwargs)
  File "D:\Users\ntabyldieva\Desktop\crm\databases_v1\statistica\views.py", line 198, in case_migrant_detail
    return render(request, 'statistica/detail_migrant.html', locals())
  File "D:\Users\ntabyldieva\Desktop\crm\databases_v1\venv\lib\site-packages\django\shortcuts.py", line 19, in render
    content = loader.render_to_string(template_name, context, request, using=using)
  File "D:\Users\ntabyldieva\Desktop\crm\databases_v1\venv\lib\site-packages\django\template\loader.py", line 62, in render_to_string
    return template.render(context, request)
  File "D:\Users\ntabyldieva\Desktop\crm\databases_v1\venv\lib\site-packages\django\template\backends\django.py", line 61, in render
    return self.template.render(context)
  File "D:\Users\ntabyldieva\Desktop\crm\databases_v1\venv\lib\site-packages\django\template\base.py", line 170, in render
    return self._render(context)
  File "D:\Users\ntabyldieva\Desktop\crm\databases_v1\venv\lib\site-packages\django\test\utils.py", line 100, in instrumented_test_render
    return self.nodelist.render(context)
  File "D:\Users\ntabyldieva\Desktop\crm\databases_v1\venv\lib\site-packages\django\template\base.py", line 938, in render
    bit = node.render_annotated(context)
  File "D:\Users\ntabyldieva\Desktop\crm\databases_v1\venv\lib\site-packages\django\template\base.py", line 905, in render_annotated
    return self.render(context)
  File "D:\Users\ntabyldieva\Desktop\crm\databases_v1\venv\lib\site-packages\django\template\defaulttags.py", line 312, in render
    return nodelist.render(context)
  File "D:\Users\ntabyldieva\Desktop\crm\databases_v1\venv\lib\site-packages\django\template\base.py", line 938, in render
    bit = node.render_annotated(context)
  File "D:\Users\ntabyldieva\Desktop\crm\databases_v1\venv\lib\site-packages\django\template\base.py", line 905, in render_annotated
    return self.render(context)
  File "D:\Users\ntabyldieva\Desktop\crm\databases_v1\venv\lib\site-packages\django\template\base.py", line 988, in render
    output = self.filter_expression.resolve(context)
  File "D:\Users\ntabyldieva\Desktop\crm\databases_v1\venv\lib\site-packages\django\template\base.py", line 698, in resolve
    new_obj = func(obj, *arg_vals)
  File "D:\Users\ntabyldieva\Desktop\crm\databases_v1\venv\lib\site-packages\django\template\defaultfilters.py", line 717, in date
    return formats.date_format(value, arg)
  File "D:\Users\ntabyldieva\Desktop\crm\databases_v1\venv\lib\site-packages\django\utils\formats.py", line 152, in date_format
    return dateformat.format(value, get_format(format or 'DATE_FORMAT', use_l10n=use_l10n))
  File "D:\Users\ntabyldieva\Desktop\crm\databases_v1\venv\lib\site-packages\django\utils\dateformat.py", line 327, in format
    return df.format(format_string)
  File "D:\Users\ntabyldieva\Desktop\crm\databases_v1\venv\lib\site-packages\django\utils\dateformat.py", line 38, in format
    raise TypeError(
TypeError: The format for date objects may not contain time-related format specifiers (found 'H').
ERROR django.server "GET /analytic/migrant-detail/1/ HTTP/1.1" 500 160705 2022-01-11 14:27:18,631
ERROR django.request Internal Server Error: /analytic/migrant-detail/1/ 2022-01-11 14:47:55,887
Traceback (most recent call last):
  File "D:\Users\ntabyldieva\Desktop\crm\databases_v1\venv\lib\site-packages\django\template\smartif.py", line 175, in translate_token
    op = OPERATORS[token]
KeyError: 'case.decision||length'

During handling of the above exception, another exception occurred:

Traceback (most recent call last):
  File "D:\Users\ntabyldieva\Desktop\crm\databases_v1\venv\lib\site-packages\django\core\handlers\exception.py", line 47, in inner
    response = get_response(request)
  File "D:\Users\ntabyldieva\Desktop\crm\databases_v1\venv\lib\site-packages\django\core\handlers\base.py", line 181, in _get_response
    response = wrapped_callback(request, *callback_args, **callback_kwargs)
  File "D:\Users\ntabyldieva\Desktop\crm\databases_v1\statistica\views.py", line 198, in case_migrant_detail
    return render(request, 'statistica/detail_migrant.html', locals())
  File "D:\Users\ntabyldieva\Desktop\crm\databases_v1\venv\lib\site-packages\django\shortcuts.py", line 19, in render
    content = loader.render_to_string(template_name, context, request, using=using)
  File "D:\Users\ntabyldieva\Desktop\crm\databases_v1\venv\lib\site-packages\django\template\loader.py", line 61, in render_to_string
    template = get_template(template_name, using=using)
  File "D:\Users\ntabyldieva\Desktop\crm\databases_v1\venv\lib\site-packages\django\template\loader.py", line 15, in get_template
    return engine.get_template(template_name)
  File "D:\Users\ntabyldieva\Desktop\crm\databases_v1\venv\lib\site-packages\django\template\backends\django.py", line 34, in get_template
    return Template(self.engine.get_template(template_name), self)
  File "D:\Users\ntabyldieva\Desktop\crm\databases_v1\venv\lib\site-packages\django\template\engine.py", line 143, in get_template
    template, origin = self.find_template(template_name)
  File "D:\Users\ntabyldieva\Desktop\crm\databases_v1\venv\lib\site-packages\django\template\engine.py", line 125, in find_template
    template = loader.get_template(name, skip=skip)
  File "D:\Users\ntabyldieva\Desktop\crm\databases_v1\venv\lib\site-packages\django\template\loaders\base.py", line 29, in get_template
    return Template(
  File "D:\Users\ntabyldieva\Desktop\crm\databases_v1\venv\lib\site-packages\django\template\base.py", line 155, in __init__
    self.nodelist = self.compile_nodelist()
  File "D:\Users\ntabyldieva\Desktop\crm\databases_v1\venv\lib\site-packages\django\template\base.py", line 193, in compile_nodelist
    return parser.parse()
  File "D:\Users\ntabyldieva\Desktop\crm\databases_v1\venv\lib\site-packages\django\template\base.py", line 478, in parse
    raise self.error(token, e)
  File "D:\Users\ntabyldieva\Desktop\crm\databases_v1\venv\lib\site-packages\django\template\base.py", line 476, in parse
    compiled_result = compile_func(self, token)
  File "D:\Users\ntabyldieva\Desktop\crm\databases_v1\venv\lib\site-packages\django\template\defaulttags.py", line 964, in do_if
    condition = TemplateIfParser(parser, bits).parse()
  File "D:\Users\ntabyldieva\Desktop\crm\databases_v1\venv\lib\site-packages\django\template\defaulttags.py", line 897, in __init__
    super().__init__(*args, **kwargs)
  File "D:\Users\ntabyldieva\Desktop\crm\databases_v1\venv\lib\site-packages\django\template\smartif.py", line 166, in __init__
    mapped_tokens.append(self.translate_token(token))
  File "D:\Users\ntabyldieva\Desktop\crm\databases_v1\venv\lib\site-packages\django\template\smartif.py", line 177, in translate_token
    return self.create_var(token)
  File "D:\Users\ntabyldieva\Desktop\crm\databases_v1\venv\lib\site-packages\django\template\defaulttags.py", line 900, in create_var
    return TemplateLiteral(self.template_parser.compile_filter(value), value)
  File "D:\Users\ntabyldieva\Desktop\crm\databases_v1\venv\lib\site-packages\django\template\base.py", line 563, in compile_filter
    return FilterExpression(token, self)
  File "D:\Users\ntabyldieva\Desktop\crm\databases_v1\venv\lib\site-packages\django\template\base.py", line 633, in __init__
    raise TemplateSyntaxError("Could not parse some characters: "
django.template.exceptions.TemplateSyntaxError: Could not parse some characters: case.decision||||length
ERROR django.server "GET /analytic/migrant-detail/1/ HTTP/1.1" 500 186592 2022-01-11 14:47:55,892
ERROR django.request Internal Server Error: /analytic/migrant-detail/1/ 2022-01-11 14:47:57,626
Traceback (most recent call last):
  File "D:\Users\ntabyldieva\Desktop\crm\databases_v1\venv\lib\site-packages\django\template\smartif.py", line 175, in translate_token
    op = OPERATORS[token]
KeyError: 'case.decision||length'

During handling of the above exception, another exception occurred:

Traceback (most recent call last):
  File "D:\Users\ntabyldieva\Desktop\crm\databases_v1\venv\lib\site-packages\django\core\handlers\exception.py", line 47, in inner
    response = get_response(request)
  File "D:\Users\ntabyldieva\Desktop\crm\databases_v1\venv\lib\site-packages\django\core\handlers\base.py", line 181, in _get_response
    response = wrapped_callback(request, *callback_args, **callback_kwargs)
  File "D:\Users\ntabyldieva\Desktop\crm\databases_v1\statistica\views.py", line 198, in case_migrant_detail
    return render(request, 'statistica/detail_migrant.html', locals())
  File "D:\Users\ntabyldieva\Desktop\crm\databases_v1\venv\lib\site-packages\django\shortcuts.py", line 19, in render
    content = loader.render_to_string(template_name, context, request, using=using)
  File "D:\Users\ntabyldieva\Desktop\crm\databases_v1\venv\lib\site-packages\django\template\loader.py", line 61, in render_to_string
    template = get_template(template_name, using=using)
  File "D:\Users\ntabyldieva\Desktop\crm\databases_v1\venv\lib\site-packages\django\template\loader.py", line 15, in get_template
    return engine.get_template(template_name)
  File "D:\Users\ntabyldieva\Desktop\crm\databases_v1\venv\lib\site-packages\django\template\backends\django.py", line 34, in get_template
    return Template(self.engine.get_template(template_name), self)
  File "D:\Users\ntabyldieva\Desktop\crm\databases_v1\venv\lib\site-packages\django\template\engine.py", line 143, in get_template
    template, origin = self.find_template(template_name)
  File "D:\Users\ntabyldieva\Desktop\crm\databases_v1\venv\lib\site-packages\django\template\engine.py", line 125, in find_template
    template = loader.get_template(name, skip=skip)
  File "D:\Users\ntabyldieva\Desktop\crm\databases_v1\venv\lib\site-packages\django\template\loaders\base.py", line 29, in get_template
    return Template(
  File "D:\Users\ntabyldieva\Desktop\crm\databases_v1\venv\lib\site-packages\django\template\base.py", line 155, in __init__
    self.nodelist = self.compile_nodelist()
  File "D:\Users\ntabyldieva\Desktop\crm\databases_v1\venv\lib\site-packages\django\template\base.py", line 193, in compile_nodelist
    return parser.parse()
  File "D:\Users\ntabyldieva\Desktop\crm\databases_v1\venv\lib\site-packages\django\template\base.py", line 478, in parse
    raise self.error(token, e)
  File "D:\Users\ntabyldieva\Desktop\crm\databases_v1\venv\lib\site-packages\django\template\base.py", line 476, in parse
    compiled_result = compile_func(self, token)
  File "D:\Users\ntabyldieva\Desktop\crm\databases_v1\venv\lib\site-packages\django\template\defaulttags.py", line 964, in do_if
    condition = TemplateIfParser(parser, bits).parse()
  File "D:\Users\ntabyldieva\Desktop\crm\databases_v1\venv\lib\site-packages\django\template\defaulttags.py", line 897, in __init__
    super().__init__(*args, **kwargs)
  File "D:\Users\ntabyldieva\Desktop\crm\databases_v1\venv\lib\site-packages\django\template\smartif.py", line 166, in __init__
    mapped_tokens.append(self.translate_token(token))
  File "D:\Users\ntabyldieva\Desktop\crm\databases_v1\venv\lib\site-packages\django\template\smartif.py", line 177, in translate_token
    return self.create_var(token)
  File "D:\Users\ntabyldieva\Desktop\crm\databases_v1\venv\lib\site-packages\django\template\defaulttags.py", line 900, in create_var
    return TemplateLiteral(self.template_parser.compile_filter(value), value)
  File "D:\Users\ntabyldieva\Desktop\crm\databases_v1\venv\lib\site-packages\django\template\base.py", line 563, in compile_filter
    return FilterExpression(token, self)
  File "D:\Users\ntabyldieva\Desktop\crm\databases_v1\venv\lib\site-packages\django\template\base.py", line 633, in __init__
    raise TemplateSyntaxError("Could not parse some characters: "
django.template.exceptions.TemplateSyntaxError: Could not parse some characters: case.decision||||length
ERROR django.server "GET /analytic/migrant-detail/1/ HTTP/1.1" 500 186592 2022-01-11 14:47:57,631
ERROR django.request Internal Server Error: /analytic/strike-detail/3/ 2022-01-11 15:08:34,266
Traceback (most recent call last):
  File "D:\Users\ntabyldieva\Desktop\crm\databases_v1\venv\lib\site-packages\django\core\handlers\exception.py", line 47, in inner
    response = get_response(request)
  File "D:\Users\ntabyldieva\Desktop\crm\databases_v1\venv\lib\site-packages\django\core\handlers\base.py", line 181, in _get_response
    response = wrapped_callback(request, *callback_args, **callback_kwargs)
  File "D:\Users\ntabyldieva\Desktop\crm\databases_v1\statistica\views.py", line 189, in card_strike_detail
    return render(request, 'statistica/detail_card_strike.html', locals())
  File "D:\Users\ntabyldieva\Desktop\crm\databases_v1\venv\lib\site-packages\django\shortcuts.py", line 19, in render
    content = loader.render_to_string(template_name, context, request, using=using)
  File "D:\Users\ntabyldieva\Desktop\crm\databases_v1\venv\lib\site-packages\django\template\loader.py", line 62, in render_to_string
    return template.render(context, request)
  File "D:\Users\ntabyldieva\Desktop\crm\databases_v1\venv\lib\site-packages\django\template\backends\django.py", line 61, in render
    return self.template.render(context)
  File "D:\Users\ntabyldieva\Desktop\crm\databases_v1\venv\lib\site-packages\django\template\base.py", line 170, in render
    return self._render(context)
  File "D:\Users\ntabyldieva\Desktop\crm\databases_v1\venv\lib\site-packages\django\test\utils.py", line 100, in instrumented_test_render
    return self.nodelist.render(context)
  File "D:\Users\ntabyldieva\Desktop\crm\databases_v1\venv\lib\site-packages\django\template\base.py", line 938, in render
    bit = node.render_annotated(context)
  File "D:\Users\ntabyldieva\Desktop\crm\databases_v1\venv\lib\site-packages\django\template\base.py", line 905, in render_annotated
    return self.render(context)
  File "D:\Users\ntabyldieva\Desktop\crm\databases_v1\venv\lib\site-packages\django\template\defaulttags.py", line 312, in render
    return nodelist.render(context)
  File "D:\Users\ntabyldieva\Desktop\crm\databases_v1\venv\lib\site-packages\django\template\base.py", line 938, in render
    bit = node.render_annotated(context)
  File "D:\Users\ntabyldieva\Desktop\crm\databases_v1\venv\lib\site-packages\django\template\base.py", line 905, in render_annotated
    return self.render(context)
  File "D:\Users\ntabyldieva\Desktop\crm\databases_v1\venv\lib\site-packages\django\template\base.py", line 988, in render
    output = self.filter_expression.resolve(context)
  File "D:\Users\ntabyldieva\Desktop\crm\databases_v1\venv\lib\site-packages\django\template\base.py", line 698, in resolve
    new_obj = func(obj, *arg_vals)
  File "D:\Users\ntabyldieva\Desktop\crm\databases_v1\venv\lib\site-packages\django\template\defaultfilters.py", line 717, in date
    return formats.date_format(value, arg)
  File "D:\Users\ntabyldieva\Desktop\crm\databases_v1\venv\lib\site-packages\django\utils\formats.py", line 152, in date_format
    return dateformat.format(value, get_format(format or 'DATE_FORMAT', use_l10n=use_l10n))
  File "D:\Users\ntabyldieva\Desktop\crm\databases_v1\venv\lib\site-packages\django\utils\dateformat.py", line 327, in format
    return df.format(format_string)
  File "D:\Users\ntabyldieva\Desktop\crm\databases_v1\venv\lib\site-packages\django\utils\dateformat.py", line 38, in format
    raise TypeError(
TypeError: The format for date objects may not contain time-related format specifiers (found 'H').
ERROR django.server "GET /analytic/strike-detail/3/ HTTP/1.1" 500 158818 2022-01-11 15:08:34,271
